Workbook

Sheet Scoring
B2: ='Info.'!B1&" "&'Info.'!B4 -> Wright Stuff C | E2: Check-In & Flight Log | H2: Flight Time | AN2: Breakdown | AX2: Rank for this team with row() bump | AY2: Rank for this team with same ranks split | AZ2: Team Number of this team | BA2: Name of this school | BB2: Name of this team | BC2: Tier for this Team | BD2: Score for this team | BE2: Actual Rank for this team | BF2: Final Rankings
E3: Plane A | F3: Plane B | G3: 3. Flight Log (Complete / Partial / Not present) | H3: 4. Met All Comp Params (T/F) | I3: Flight 1 | L3: Flight 2 | O3: 9. Disqualify (T/F) | Q3: =E4 -> 1. Met All Const Params (T/F) | R3: =F4 -> 2. Met All Const Params (T/F) | S3: =G3 -> 3. Flight Log (Complete / Partial / Not present) | T3: =H3 -> 4. Met All Comp Params (T/F) | U3: =I4 -> 5. Plane (A/B) | V3: =J4 -> 6. Median Flight Time | W3: =L4 -> 7. Plane (A/B) | X3: =M4 -> 8. Median Flight Time | Y3: =O3 -> 9. Disqualify (T/F) | AN3: Scored Flight | AO3: Log Multiplier | AP3: Score | AQ3: Tier | AR3: Tiebreaker | AS3: Rank | AT3: Points | BF3: Rank | BG3: Team # | BH3: School Name | BI3: Team Name | BJ3: Tier | BK3: Score
B4: ="Event Scoresheet - "&'Info.'!B5&IF('Info.'!B8="T"," The scoresheet has been updated; please download version v"&'Info.'!B7&" from soinc.org/scoresheets.","") -> Event Scoresheet - 2027 | E4: 1. Met All Const Params (T/F) | F4: 2. Met All Const Params (T/F) | I4: 5. Plane (A/B) | J4: 6. Median Flight Time | L4: 7. Plane (A/B) | M4: 8. Median Flight Time
B6: ="Last Updated: "&TEXT('Info.'!B2, "mm/dd/yyyy")&" (v"&'Info.'!B3&") Direct all questions to scoresheets@soinc.org." -> Last Updated: 10/01/2026 (v0.1.0) Direct all questions to scoresheets@soinc.org.
B7: Team # | C7: School Name | D7: Team Name | J7: Mins | K7: Seconds | M7: Mins | N7: Seconds | Z7: Status | AA7: Tier | AB7: Flight 1 (s) | AC7: Flight 2 (s) | AD7: Scored Flight # | AE7: Best Flight (s) | AF7: Score | AG7: Score Rank | AH7: Rank | AI7: TB1 (Non-Scored Flight Score) | AJ7: TB1 Rank | AK7: Rank w/ TB | AL7: Rank Diff | AV7: =SUM(AV8:AV507) -> 0
Q8: =IF(ISBLANK($C8),"",IF(E8=Constants!$B$2, TRUE(), IF(E8=Constants!$B$3, FALSE(), TRUE()))) | R8: =IF(ISBLANK($C8),"",IF(F8=Constants!$B$2, TRUE(), IF(F8=Constants!$B$3, FALSE(), TRUE()))) | S8: =IF(ISBLANK($C8),"",IF(G8=Constants!$B$15,Constants!$B$8,IF(G8=Constants!$B$16,Constants!$B$9,Constants!$B$10))) | T8: =IF(ISBLANK($C8),"",IF(H8=Constants!$B$2, TRUE(), IF(H8=Constants!$B$3, FALSE(), TRUE()))) | U8: =IF(ISBLANK($C8),"",IF(I8=Constants!$B$19,Constants!$B$19,Constants!$B$18)) | V8: =IF(ISBLANK($C8),"",IF(COUNTA(J8:K8)=0,"",IF(AND(OR(ISBLANK(J8),AND(ISNUMBER(J8),J8>=0)),OR(ISBLANK(K8),AND(ISNUMBER(K8),K8>=0))),60*IF(ISBLANK(J8),0,J8)+IF(ISBLANK(K8),0,K8),""))) | W8: =IF(ISBLANK($C8),"",IF(L8=Constants!$B$19,Constants!$B$19,Constants!$B$18)) | X8: =IF(ISBLANK($C8),"",IF(COUNTA(M8:N8)=0,"",IF(AND(OR(ISBLANK(M8),AND(ISNUMBER(M8),M8>=0)),OR(ISBLANK(N8),AND(ISNUMBER(N8),N8>=0))),60*IF(ISBLANK(M8),0,M8)+IF(ISBLANK(N8),0,N8),""))) | Y8: =IF(ISBLANK($C8),"",IF(O8=Constants!$B$2, TRUE(), IF(O8=Constants!$B$3, FALSE(), FALSE()))) | Z8: =IF(ISBLANK($C8),"",IF(Y8,Constants!$B$4,IF(COUNTA(E8:N8)=0,Constants!$B$5,IF(COUNTA(J8:K8,M8:N8)=0,Constants!$B$6,Constants!$B$7)))) | AA8: =IF(ISBLANK($C8),"",IF($Z8<>Constants!$B$7,$Z8,IF(OR(NOT(T8),AND(NOT(Q8),COUNTIFS(U8:W8,Constants!$B$18,V8:X8,">=0")>0),AND(NOT(R8),COUNTIFS(U8:W8,Constants!$B$19,V8:X8,">=0")>0)),Constants!$B$12,Constants!$B$11))) | AB8: =IF($Z8=Constants!$B$7,IF(V8="",Constants!$B$13,V8),"") | AC8: =IF($Z8=Constants!$B$7,IF(X8="",Constants!$B$13,X8),"") | AD8: =IF($Z8=Constants!$B$7,IF($AB8>=$AC8,1,2),"") | AE8: =IF($Z8=Constants!$B$7,LARGE(AB8:AC8,1),"") | AF8: =IF(ISBLANK($C8),"",IF($Z8<>Constants!$B$7,$Z8,AE8*S8)) | AG8: =IF(ISBLANK($C8),"",IF($Z8=Constants!$B$7,IF(ISNUMBER(AF8),RANK(AF8,$AF$8:$AF$507),Constants!$B$14),$Z8)) | AH8: =IF(ISBLANK($C8),"",IF($Z8=Constants!$B$7,IF(ISNUMBER(AG8),COUNTIFS($AA$8:$AA$507,"<"&$AA8)+COUNTIFS($AA$8:$AA$507,$AA8,$AG$8:$AG$507,"<"&$AG8)+1,Constants!$B$14),$Z8)) | AI8: =IF(ISBLANK($C8),"",IF($Z8=Constants!$B$7,LARGE(AB8:AC8,2)*S8,"")) | AJ8: =IF(ISBLANK($C8),"",IF($Z8=Constants!$B$7,RANK(AI8,$AI$8:$AI$507),$Z8)) | AK8: =IF(ISBLANK($C8),"",IF($Z8=Constants!$B$7,IF(ISNUMBER(AG8),COUNTIFS($AA$8:$AA$507,"<"&$AA8)+COUNTIFS($AA$8:$AA$507,$AA8,$AG$8:$AG$507,"<"&$AG8)+COUNTIFS($AA$8:$AA$507,$AA8,$AG$8:$AG$507,$AG8,$AJ$8:$AJ$507,"<"&$AJ8)+1,Constants!$B$14),$Z8)) | AL8: =IF(ISBLANK($C8),"",IF($Z8=Constants!$B$7,IF(ISNUMBER(AH8),AH8-AK8,Constants!$B$14),$Z8)) | AN8: =IF(ISBLANK($C8),"",IF($Z8<>Constants!$B$7,$Z8,AD8)) | AO8: =IF(ISBLANK($C8),"",IF($Z8<>Constants!$B$7,$Z8,S8)) | AP8: =IF(ISBLANK($C8),"",IF($Z8<>Constants!$B$7,$Z8,AF8)) | AQ8: =IF(ISBLANK($C8),"",IF($Z8<>Constants!$B$7,$Z8,AA8)) | AR8: =IF(ISBLANK($C8),"",AL8) | AS8: =IF(ISBLANK($C8),"",AK8) | AT8: =IF(ISBLANK($C8),"",IF(AS8=Constants!$B$4,COUNTA($C$8:$C$507)+2,IF(AS8=Constants!$B$5,COUNTA($C$8:$C$507)+1,IF(AS8=Constants!$B$6,COUNTA($C$8:$C$507),AS8)))) | AV8: =IF(OR(ISNUMBER(AS8),AS8=Constants!$B$4,AS8=Constants!$B$6,AS8=Constants!$B$5),1,0) -> 0 | AW8: 1 | AX8: =IF(ISBLANK($C8),"",IF(ISNUMBER(AT8),AT8+ROW($B8)/1000,"")) | AY8: =IF(ISNUMBER(AX8),RANK(AX8,$AX$8:$AX$507,1),"") | AZ8: =IF(ISBLANK($C8),"",$B8) | BA8: =IF(ISBLANK($C8),"",$C8) | BB8: =IF(ISBLANK($C8),"",$D8) | BC8: =AQ8 | BD8: =AP8 | BE8: =IF(ISBLANK($C8),"",AS8) | BF8: =IF($AW8>$AV$7,"",VLOOKUP($AW8,$AY$8:$BE$507,7,FALSE())) | BG8: =IF($AW8>$AV$7,"",VLOOKUP($AW8,$AY$8:$BE$507,2,FALSE())) | BH8: =IF($AW8>$AV$7,"",VLOOKUP($AW8,$AY$8:$BE$507,3,FALSE())) | BI8: =IF($AW8>$AV$7,"",VLOOKUP($AW8,$AY$8:$BE$507,4,FALSE())) | BJ8: =IF($AW8>$AV$7,"",VLOOKUP($AW8,$AY$8:$BE$507,5,FALSE())) | BK8: =IF($AW8>$AV$7,"",VLOOKUP($AW8,$AY$8:$BE$507,6,FALSE()))
Q9: =IF(ISBLANK($C9),"",IF(E9=Constants!$B$2, TRUE(), IF(E9=Constants!$B$3, FALSE(), TRUE()))) | R9: =IF(ISBLANK($C9),"",IF(F9=Constants!$B$2, TRUE(), IF(F9=Constants!$B$3, FALSE(), TRUE()))) | S9: =IF(ISBLANK($C9),"",IF(G9=Constants!$B$15,Constants!$B$8,IF(G9=Constants!$B$16,Constants!$B$9,Constants!$B$10))) | T9: =IF(ISBLANK($C9),"",IF(H9=Constants!$B$2, TRUE(), IF(H9=Constants!$B$3, FALSE(), TRUE()))) | U9: =IF(ISBLANK($C9),"",IF(I9=Constants!$B$19,Constants!$B$19,Constants!$B$18)) | V9: =IF(ISBLANK($C9),"",IF(COUNTA(J9:K9)=0,"",IF(AND(OR(ISBLANK(J9),AND(ISNUMBER(J9),J9>=0)),OR(ISBLANK(K9),AND(ISNUMBER(K9),K9>=0))),60*IF(ISBLANK(J9),0,J9)+IF(ISBLANK(K9),0,K9),""))) | W9: =IF(ISBLANK($C9),"",IF(L9=Constants!$B$19,Constants!$B$19,Constants!$B$18)) | X9: =IF(ISBLANK($C9),"",IF(COUNTA(M9:N9)=0,"",IF(AND(OR(ISBLANK(M9),AND(ISNUMBER(M9),M9>=0)),OR(ISBLANK(N9),AND(ISNUMBER(N9),N9>=0))),60*IF(ISBLANK(M9),0,M9)+IF(ISBLANK(N9),0,N9),""))) | Y9: =IF(ISBLANK($C9),"",IF(O9=Constants!$B$2, TRUE(), IF(O9=Constants!$B$3, FALSE(), FALSE()))) | Z9: =IF(ISBLANK($C9),"",IF(Y9,Constants!$B$4,IF(COUNTA(E9:N9)=0,Constants!$B$5,IF(COUNTA(J9:K9,M9:N9)=0,Constants!$B$6,Constants!$B$7)))) | AA9: =IF(ISBLANK($C9),"",IF($Z9<>Constants!$B$7,$Z9,IF(OR(NOT(T9),AND(NOT(Q9),COUNTIFS(U9:W9,Constants!$B$18,V9:X9,">=0")>0),AND(NOT(R9),COUNTIFS(U9:W9,Constants!$B$19,V9:X9,">=0")>0)),Constants!$B$12,Constants!$B$11))) | AB9: =IF($Z9=Constants!$B$7,IF(V9="",Constants!$B$13,V9),"") | AC9: =IF($Z9=Constants!$B$7,IF(X9="",Constants!$B$13,X9),"") | AD9: =IF($Z9=Constants!$B$7,IF($AB9>=$AC9,1,2),"") | AE9: =IF($Z9=Constants!$B$7,LARGE(AB9:AC9,1),"") | AF9: =IF(ISBLANK($C9),"",IF($Z9<>Constants!$B$7,$Z9,AE9*S9)) | AG9: =IF(ISBLANK($C9),"",IF($Z9=Constants!$B$7,IF(ISNUMBER(AF9),RANK(AF9,$AF$8:$AF$507),Constants!$B$14),$Z9)) | AH9: =IF(ISBLANK($C9),"",IF($Z9=Constants!$B$7,IF(ISNUMBER(AG9),COUNTIFS($AA$8:$AA$507,"<"&$AA9)+COUNTIFS($AA$8:$AA$507,$AA9,$AG$8:$AG$507,"<"&$AG9)+1,Constants!$B$14),$Z9)) | AI9: =IF(ISBLANK($C9),"",IF($Z9=Constants!$B$7,LARGE(AB9:AC9,2)*S9,"")) | AJ9: =IF(ISBLANK($C9),"",IF($Z9=Constants!$B$7,RANK(AI9,$AI$8:$AI$507),$Z9)) | AK9: =IF(ISBLANK($C9),"",IF($Z9=Constants!$B$7,IF(ISNUMBER(AG9),COUNTIFS($AA$8:$AA$507,"<"&$AA9)+COUNTIFS($AA$8:$AA$507,$AA9,$AG$8:$AG$507,"<"&$AG9)+COUNTIFS($AA$8:$AA$507,$AA9,$AG$8:$AG$507,$AG9,$AJ$8:$AJ$507,"<"&$AJ9)+1,Constants!$B$14),$Z9)) | AL9: =IF(ISBLANK($C9),"",IF($Z9=Constants!$B$7,IF(ISNUMBER(AH9),AH9-AK9,Constants!$B$14),$Z9)) | AN9: =IF(ISBLANK($C9),"",IF($Z9<>Constants!$B$7,$Z9,AD9)) | AO9: =IF(ISBLANK($C9),"",IF($Z9<>Constants!$B$7,$Z9,S9)) | AP9: =IF(ISBLANK($C9),"",IF($Z9<>Constants!$B$7,$Z9,AF9)) | AQ9: =IF(ISBLANK($C9),"",IF($Z9<>Constants!$B$7,$Z9,AA9)) | AR9: =IF(ISBLANK($C9),"",AL9) | AS9: =IF(ISBLANK($C9),"",AK9) | AT9: =IF(ISBLANK($C9),"",IF(AS9=Constants!$B$4,COUNTA($C$8:$C$507)+2,IF(AS9=Constants!$B$5,COUNTA($C$8:$C$507)+1,IF(AS9=Constants!$B$6,COUNTA($C$8:$C$507),AS9)))) | AV9: =IF(OR(ISNUMBER(AS9),AS9=Constants!$B$4,AS9=Constants!$B$6,AS9=Constants!$B$5),1,0) -> 0 | AW9: 2 | AX9: =IF(ISBLANK($C9),"",IF(ISNUMBER(AT9),AT9+ROW($B9)/1000,"")) | AY9: =IF(ISNUMBER(AX9),RANK(AX9,$AX$8:$AX$507,1),"") | AZ9: =IF(ISBLANK($C9),"",$B9) | BA9: =IF(ISBLANK($C9),"",$C9) | BB9: =IF(ISBLANK($C9),"",$D9) | BC9: =AQ9 | BD9: =AP9 | BE9: =IF(ISBLANK($C9),"",AS9) | BF9: =IF($AW9>$AV$7,"",VLOOKUP($AW9,$AY$8:$BE$507,7,FALSE())) | BG9: =IF($AW9>$AV$7,"",VLOOKUP($AW9,$AY$8:$BE$507,2,FALSE())) | BH9: =IF($AW9>$AV$7,"",VLOOKUP($AW9,$AY$8:$BE$507,3,FALSE())) | BI9: =IF($AW9>$AV$7,"",VLOOKUP($AW9,$AY$8:$BE$507,4,FALSE())) | BJ9: =IF($AW9>$AV$7,"",VLOOKUP($AW9,$AY$8:$BE$507,5,FALSE())) | BK9: =IF($AW9>$AV$7,"",VLOOKUP($AW9,$AY$8:$BE$507,6,FALSE()))
Q10: =IF(ISBLANK($C10),"",IF(E10=Constants!$B$2, TRUE(), IF(E10=Constants!$B$3, FALSE(), TRUE()))) | R10: =IF(ISBLANK($C10),"",IF(F10=Constants!$B$2, TRUE(), IF(F10=Constants!$B$3, FALSE(), TRUE()))) | S10: =IF(ISBLANK($C10),"",IF(G10=Constants!$B$15,Constants!$B$8,IF(G10=Constants!$B$16,Constants!$B$9,Constants!$B$10))) | T10: =IF(ISBLANK($C10),"",IF(H10=Constants!$B$2, TRUE(), IF(H10=Constants!$B$3, FALSE(), TRUE()))) | U10: =IF(ISBLANK($C10),"",IF(I10=Constants!$B$19,Constants!$B$19,Constants!$B$18)) | V10: =IF(ISBLANK($C10),"",IF(COUNTA(J10:K10)=0,"",IF(AND(OR(ISBLANK(J10),AND(ISNUMBER(J10),J10>=0)),OR(ISBLANK(K10),AND(ISNUMBER(K10),K10>=0))),60*IF(ISBLANK(J10),0,J10)+IF(ISBLANK(K10),0,K10),""))) | W10: =IF(ISBLANK($C10),"",IF(L10=Constants!$B$19,Constants!$B$19,Constants!$B$18)) | X10: =IF(ISBLANK($C10),"",IF(COUNTA(M10:N10)=0,"",IF(AND(OR(ISBLANK(M10),AND(ISNUMBER(M10),M10>=0)),OR(ISBLANK(N10),AND(ISNUMBER(N10),N10>=0))),60*IF(ISBLANK(M10),0,M10)+IF(ISBLANK(N10),0,N10),""))) | Y10: =IF(ISBLANK($C10),"",IF(O10=Constants!$B$2, TRUE(), IF(O10=Constants!$B$3, FALSE(), FALSE()))) | Z10: =IF(ISBLANK($C10),"",IF(Y10,Constants!$B$4,IF(COUNTA(E10:N10)=0,Constants!$B$5,IF(COUNTA(J10:K10,M10:N10)=0,Constants!$B$6,Constants!$B$7)))) | AA10: =IF(ISBLANK($C10),"",IF($Z10<>Constants!$B$7,$Z10,IF(OR(NOT(T10),AND(NOT(Q10),COUNTIFS(U10:W10,Constants!$B$18,V10:X10,">=0")>0),AND(NOT(R10),COUNTIFS(U10:W10,Constants!$B$19,V10:X10,">=0")>0)),Constants!$B$12,Constants!$B$11))) | AB10: =IF($Z10=Constants!$B$7,IF(V10="",Constants!$B$13,V10),"") | AC10: =IF($Z10=Constants!$B$7,IF(X10="",Constants!$B$13,X10),"") | AD10: =IF($Z10=Constants!$B$7,IF($AB10>=$AC10,1,2),"") | AE10: =IF($Z10=Constants!$B$7,LARGE(AB10:AC10,1),"") | AF10: =IF(ISBLANK($C10),"",IF($Z10<>Constants!$B$7,$Z10,AE10*S10)) | AG10: =IF(ISBLANK($C10),"",IF($Z10=Constants!$B$7,IF(ISNUMBER(AF10),RANK(AF10,$AF$8:$AF$507),Constants!$B$14),$Z10)) | AH10: =IF(ISBLANK($C10),"",IF($Z10=Constants!$B$7,IF(ISNUMBER(AG10),COUNTIFS($AA$8:$AA$507,"<"&$AA10)+COUNTIFS($AA$8:$AA$507,$AA10,$AG$8:$AG$507,"<"&$AG10)+1,Constants!$B$14),$Z10)) | AI10: =IF(ISBLANK($C10),"",IF($Z10=Constants!$B$7,LARGE(AB10:AC10,2)*S10,"")) | AJ10: =IF(ISBLANK($C10),"",IF($Z10=Constants!$B$7,RANK(AI10,$AI$8:$AI$507),$Z10)) | AK10: =IF(ISBLANK($C10),"",IF($Z10=Constants!$B$7,IF(ISNUMBER(AG10),COUNTIFS($AA$8:$AA$507,"<"&$AA10)+COUNTIFS($AA$8:$AA$507,$AA10,$AG$8:$AG$507,"<"&$AG10)+COUNTIFS($AA$8:$AA$507,$AA10,$AG$8:$AG$507,$AG10,$AJ$8:$AJ$507,"<"&$AJ10)+1,Constants!$B$14),$Z10)) | AL10: =IF(ISBLANK($C10),"",IF($Z10=Constants!$B$7,IF(ISNUMBER(AH10),AH10-AK10,Constants!$B$14),$Z10)) | AN10: =IF(ISBLANK($C10),"",IF($Z10<>Constants!$B$7,$Z10,AD10)) | AO10: =IF(ISBLANK($C10),"",IF($Z10<>Constants!$B$7,$Z10,S10)) | AP10: =IF(ISBLANK($C10),"",IF($Z10<>Constants!$B$7,$Z10,AF10)) | AQ10: =IF(ISBLANK($C10),"",IF($Z10<>Constants!$B$7,$Z10,AA10)) | AR10: =IF(ISBLANK($C10),"",AL10) | AS10: =IF(ISBLANK($C10),"",AK10) | AT10: =IF(ISBLANK($C10),"",IF(AS10=Constants!$B$4,COUNTA($C$8:$C$507)+2,IF(AS10=Constants!$B$5,COUNTA($C$8:$C$507)+1,IF(AS10=Constants!$B$6,COUNTA($C$8:$C$507),AS10)))) | AV10: =IF(OR(ISNUMBER(AS10),AS10=Constants!$B$4,AS10=Constants!$B$6,AS10=Constants!$B$5),1,0) -> 0 | AW10: 3 | AX10: =IF(ISBLANK($C10),"",IF(ISNUMBER(AT10),AT10+ROW($B10)/1000,"")) | AY10: =IF(ISNUMBER(AX10),RANK(AX10,$AX$8:$AX$507,1),"") | AZ10: =IF(ISBLANK($C10),"",$B10) | BA10: =IF(ISBLANK($C10),"",$C10) | BB10: =IF(ISBLANK($C10),"",$D10) | BC10: =AQ10 | BD10: =AP10 | BE10: =IF(ISBLANK($C10),"",AS10) | BF10: =IF($AW10>$AV$7,"",VLOOKUP($AW10,$AY$8:$BE$507,7,FALSE())) | BG10: =IF($AW10>$AV$7,"",VLOOKUP($AW10,$AY$8:$BE$507,2,FALSE())) | BH10: =IF($AW10>$AV$7,"",VLOOKUP($AW10,$AY$8:$BE$507,3,FALSE())) | BI10: =IF($AW10>$AV$7,"",VLOOKUP($AW10,$AY$8:$BE$507,4,FALSE())) | BJ10: =IF($AW10>$AV$7,"",VLOOKUP($AW10,$AY$8:$BE$507,5,FALSE())) | BK10: =IF($AW10>$AV$7,"",VLOOKUP($AW10,$AY$8:$BE$507,6,FALSE()))
Q11: =IF(ISBLANK($C11),"",IF(E11=Constants!$B$2, TRUE(), IF(E11=Constants!$B$3, FALSE(), TRUE()))) | R11: =IF(ISBLANK($C11),"",IF(F11=Constants!$B$2, TRUE(), IF(F11=Constants!$B$3, FALSE(), TRUE()))) | S11: =IF(ISBLANK($C11),"",IF(G11=Constants!$B$15,Constants!$B$8,IF(G11=Constants!$B$16,Constants!$B$9,Constants!$B$10))) | T11: =IF(ISBLANK($C11),"",IF(H11=Constants!$B$2, TRUE(), IF(H11=Constants!$B$3, FALSE(), TRUE()))) | U11: =IF(ISBLANK($C11),"",IF(I11=Constants!$B$19,Constants!$B$19,Constants!$B$18)) | V11: =IF(ISBLANK($C11),"",IF(COUNTA(J11:K11)=0,"",IF(AND(OR(ISBLANK(J11),AND(ISNUMBER(J11),J11>=0)),OR(ISBLANK(K11),AND(ISNUMBER(K11),K11>=0))),60*IF(ISBLANK(J11),0,J11)+IF(ISBLANK(K11),0,K11),""))) | W11: =IF(ISBLANK($C11),"",IF(L11=Constants!$B$19,Constants!$B$19,Constants!$B$18)) | X11: =IF(ISBLANK($C11),"",IF(COUNTA(M11:N11)=0,"",IF(AND(OR(ISBLANK(M11),AND(ISNUMBER(M11),M11>=0)),OR(ISBLANK(N11),AND(ISNUMBER(N11),N11>=0))),60*IF(ISBLANK(M11),0,M11)+IF(ISBLANK(N11),0,N11),""))) | Y11: =IF(ISBLANK($C11),"",IF(O11=Constants!$B$2, TRUE(), IF(O11=Constants!$B$3, FALSE(), FALSE()))) | Z11: =IF(ISBLANK($C11),"",IF(Y11,Constants!$B$4,IF(COUNTA(E11:N11)=0,Constants!$B$5,IF(COUNTA(J11:K11,M11:N11)=0,Constants!$B$6,Constants!$B$7)))) | AA11: =IF(ISBLANK($C11),"",IF($Z11<>Constants!$B$7,$Z11,IF(OR(NOT(T11),AND(NOT(Q11),COUNTIFS(U11:W11,Constants!$B$18,V11:X11,">=0")>0),AND(NOT(R11),COUNTIFS(U11:W11,Constants!$B$19,V11:X11,">=0")>0)),Constants!$B$12,Constants!$B$11))) | AB11: =IF($Z11=Constants!$B$7,IF(V11="",Constants!$B$13,V11),"") | AC11: =IF($Z11=Constants!$B$7,IF(X11="",Constants!$B$13,X11),"") | AD11: =IF($Z11=Constants!$B$7,IF($AB11>=$AC11,1,2),"") | AE11: =IF($Z11=Constants!$B$7,LARGE(AB11:AC11,1),"") | AF11: =IF(ISBLANK($C11),"",IF($Z11<>Constants!$B$7,$Z11,AE11*S11)) | AG11: =IF(ISBLANK($C11),"",IF($Z11=Constants!$B$7,IF(ISNUMBER(AF11),RANK(AF11,$AF$8:$AF$507),Constants!$B$14),$Z11)) | AH11: =IF(ISBLANK($C11),"",IF($Z11=Constants!$B$7,IF(ISNUMBER(AG11),COUNTIFS($AA$8:$AA$507,"<"&$AA11)+COUNTIFS($AA$8:$AA$507,$AA11,$AG$8:$AG$507,"<"&$AG11)+1,Constants!$B$14),$Z11)) | AI11: =IF(ISBLANK($C11),"",IF($Z11=Constants!$B$7,LARGE(AB11:AC11,2)*S11,"")) | AJ11: =IF(ISBLANK($C11),"",IF($Z11=Constants!$B$7,RANK(AI11,$AI$8:$AI$507),$Z11)) | AK11: =IF(ISBLANK($C11),"",IF($Z11=Constants!$B$7,IF(ISNUMBER(AG11),COUNTIFS($AA$8:$AA$507,"<"&$AA11)+COUNTIFS($AA$8:$AA$507,$AA11,$AG$8:$AG$507,"<"&$AG11)+COUNTIFS($AA$8:$AA$507,$AA11,$AG$8:$AG$507,$AG11,$AJ$8:$AJ$507,"<"&$AJ11)+1,Constants!$B$14),$Z11)) | AL11: =IF(ISBLANK($C11),"",IF($Z11=Constants!$B$7,IF(ISNUMBER(AH11),AH11-AK11,Constants!$B$14),$Z11)) | AN11: =IF(ISBLANK($C11),"",IF($Z11<>Constants!$B$7,$Z11,AD11)) | AO11: =IF(ISBLANK($C11),"",IF($Z11<>Constants!$B$7,$Z11,S11)) | AP11: =IF(ISBLANK($C11),"",IF($Z11<>Constants!$B$7,$Z11,AF11)) | AQ11: =IF(ISBLANK($C11),"",IF($Z11<>Constants!$B$7,$Z11,AA11)) | AR11: =IF(ISBLANK($C11),"",AL11) | AS11: =IF(ISBLANK($C11),"",AK11) | AT11: =IF(ISBLANK($C11),"",IF(AS11=Constants!$B$4,COUNTA($C$8:$C$507)+2,IF(AS11=Constants!$B$5,COUNTA($C$8:$C$507)+1,IF(AS11=Constants!$B$6,COUNTA($C$8:$C$507),AS11)))) | AV11: =IF(OR(ISNUMBER(AS11),AS11=Constants!$B$4,AS11=Constants!$B$6,AS11=Constants!$B$5),1,0) -> 0 | AW11: 4 | AX11: =IF(ISBLANK($C11),"",IF(ISNUMBER(AT11),AT11+ROW($B11)/1000,"")) | AY11: =IF(ISNUMBER(AX11),RANK(AX11,$AX$8:$AX$507,1),"") | AZ11: =IF(ISBLANK($C11),"",$B11) | BA11: =IF(ISBLANK($C11),"",$C11) | BB11: =IF(ISBLANK($C11),"",$D11) | BC11: =AQ11 | BD11: =AP11 | BE11: =IF(ISBLANK($C11),"",AS11) | BF11: =IF($AW11>$AV$7,"",VLOOKUP($AW11,$AY$8:$BE$507,7,FALSE())) | BG11: =IF($AW11>$AV$7,"",VLOOKUP($AW11,$AY$8:$BE$507,2,FALSE())) | BH11: =IF($AW11>$AV$7,"",VLOOKUP($AW11,$AY$8:$BE$507,3,FALSE())) | BI11: =IF($AW11>$AV$7,"",VLOOKUP($AW11,$AY$8:$BE$507,4,FALSE())) | BJ11: =IF($AW11>$AV$7,"",VLOOKUP($AW11,$AY$8:$BE$507,5,FALSE())) | BK11: =IF($AW11>$AV$7,"",VLOOKUP($AW11,$AY$8:$BE$507,6,FALSE()))
Q12: =IF(ISBLANK($C12),"",IF(E12=Constants!$B$2, TRUE(), IF(E12=Constants!$B$3, FALSE(), TRUE()))) | R12: =IF(ISBLANK($C12),"",IF(F12=Constants!$B$2, TRUE(), IF(F12=Constants!$B$3, FALSE(), TRUE()))) | S12: =IF(ISBLANK($C12),"",IF(G12=Constants!$B$15,Constants!$B$8,IF(G12=Constants!$B$16,Constants!$B$9,Constants!$B$10))) | T12: =IF(ISBLANK($C12),"",IF(H12=Constants!$B$2, TRUE(), IF(H12=Constants!$B$3, FALSE(), TRUE()))) | U12: =IF(ISBLANK($C12),"",IF(I12=Constants!$B$19,Constants!$B$19,Constants!$B$18)) | V12: =IF(ISBLANK($C12),"",IF(COUNTA(J12:K12)=0,"",IF(AND(OR(ISBLANK(J12),AND(ISNUMBER(J12),J12>=0)),OR(ISBLANK(K12),AND(ISNUMBER(K12),K12>=0))),60*IF(ISBLANK(J12),0,J12)+IF(ISBLANK(K12),0,K12),""))) | W12: =IF(ISBLANK($C12),"",IF(L12=Constants!$B$19,Constants!$B$19,Constants!$B$18)) | X12: =IF(ISBLANK($C12),"",IF(COUNTA(M12:N12)=0,"",IF(AND(OR(ISBLANK(M12),AND(ISNUMBER(M12),M12>=0)),OR(ISBLANK(N12),AND(ISNUMBER(N12),N12>=0))),60*IF(ISBLANK(M12),0,M12)+IF(ISBLANK(N12),0,N12),""))) | Y12: =IF(ISBLANK($C12),"",IF(O12=Constants!$B$2, TRUE(), IF(O12=Constants!$B$3, FALSE(), FALSE()))) | Z12: =IF(ISBLANK($C12),"",IF(Y12,Constants!$B$4,IF(COUNTA(E12:N12)=0,Constants!$B$5,IF(COUNTA(J12:K12,M12:N12)=0,Constants!$B$6,Constants!$B$7)))) | AA12: =IF(ISBLANK($C12),"",IF($Z12<>Constants!$B$7,$Z12,IF(OR(NOT(T12),AND(NOT(Q12),COUNTIFS(U12:W12,Constants!$B$18,V12:X12,">=0")>0),AND(NOT(R12),COUNTIFS(U12:W12,Constants!$B$19,V12:X12,">=0")>0)),Constants!$B$12,Constants!$B$11))) | AB12: =IF($Z12=Constants!$B$7,IF(V12="",Constants!$B$13,V12),"") | AC12: =IF($Z12=Constants!$B$7,IF(X12="",Constants!$B$13,X12),"") | AD12: =IF($Z12=Constants!$B$7,IF($AB12>=$AC12,1,2),"") | AE12: =IF($Z12=Constants!$B$7,LARGE(AB12:AC12,1),"") | AF12: =IF(ISBLANK($C12),"",IF($Z12<>Constants!$B$7,$Z12,AE12*S12)) | AG12: =IF(ISBLANK($C12),"",IF($Z12=Constants!$B$7,IF(ISNUMBER(AF12),RANK(AF12,$AF$8:$AF$507),Constants!$B$14),$Z12)) | AH12: =IF(ISBLANK($C12),"",IF($Z12=Constants!$B$7,IF(ISNUMBER(AG12),COUNTIFS($AA$8:$AA$507,"<"&$AA12)+COUNTIFS($AA$8:$AA$507,$AA12,$AG$8:$AG$507,"<"&$AG12)+1,Constants!$B$14),$Z12)) | AI12: =IF(ISBLANK($C12),"",IF($Z12=Constants!$B$7,LARGE(AB12:AC12,2)*S12,"")) | AJ12: =IF(ISBLANK($C12),"",IF($Z12=Constants!$B$7,RANK(AI12,$AI$8:$AI$507),$Z12)) | AK12: =IF(ISBLANK($C12),"",IF($Z12=Constants!$B$7,IF(ISNUMBER(AG12),COUNTIFS($AA$8:$AA$507,"<"&$AA12)+COUNTIFS($AA$8:$AA$507,$AA12,$AG$8:$AG$507,"<"&$AG12)+COUNTIFS($AA$8:$AA$507,$AA12,$AG$8:$AG$507,$AG12,$AJ$8:$AJ$507,"<"&$AJ12)+1,Constants!$B$14),$Z12)) | AL12: =IF(ISBLANK($C12),"",IF($Z12=Constants!$B$7,IF(ISNUMBER(AH12),AH12-AK12,Constants!$B$14),$Z12)) | AN12: =IF(ISBLANK($C12),"",IF($Z12<>Constants!$B$7,$Z12,AD12)) | AO12: =IF(ISBLANK($C12),"",IF($Z12<>Constants!$B$7,$Z12,S12)) | AP12: =IF(ISBLANK($C12),"",IF($Z12<>Constants!$B$7,$Z12,AF12)) | AQ12: =IF(ISBLANK($C12),"",IF($Z12<>Constants!$B$7,$Z12,AA12)) | AR12: =IF(ISBLANK($C12),"",AL12) | AS12: =IF(ISBLANK($C12),"",AK12) | AT12: =IF(ISBLANK($C12),"",IF(AS12=Constants!$B$4,COUNTA($C$8:$C$507)+2,IF(AS12=Constants!$B$5,COUNTA($C$8:$C$507)+1,IF(AS12=Constants!$B$6,COUNTA($C$8:$C$507),AS12)))) | AV12: =IF(OR(ISNUMBER(AS12),AS12=Constants!$B$4,AS12=Constants!$B$6,AS12=Constants!$B$5),1,0) -> 0 | AW12: 5 | AX12: =IF(ISBLANK($C12),"",IF(ISNUMBER(AT12),AT12+ROW($B12)/1000,"")) | AY12: =IF(ISNUMBER(AX12),RANK(AX12,$AX$8:$AX$507,1),"") | AZ12: =IF(ISBLANK($C12),"",$B12) | BA12: =IF(ISBLANK($C12),"",$C12) | BB12: =IF(ISBLANK($C12),"",$D12) | BC12: =AQ12 | BD12: =AP12 | BE12: =IF(ISBLANK($C12),"",AS12) | BF12: =IF($AW12>$AV$7,"",VLOOKUP($AW12,$AY$8:$BE$507,7,FALSE())) | BG12: =IF($AW12>$AV$7,"",VLOOKUP($AW12,$AY$8:$BE$507,2,FALSE())) | BH12: =IF($AW12>$AV$7,"",VLOOKUP($AW12,$AY$8:$BE$507,3,FALSE())) | BI12: =IF($AW12>$AV$7,"",VLOOKUP($AW12,$AY$8:$BE$507,4,FALSE())) | BJ12: =IF($AW12>$AV$7,"",VLOOKUP($AW12,$AY$8:$BE$507,5,FALSE())) | BK12: =IF($AW12>$AV$7,"",VLOOKUP($AW12,$AY$8:$BE$507,6,FALSE()))
Q13: =IF(ISBLANK($C13),"",IF(E13=Constants!$B$2, TRUE(), IF(E13=Constants!$B$3, FALSE(), TRUE()))) | R13: =IF(ISBLANK($C13),"",IF(F13=Constants!$B$2, TRUE(), IF(F13=Constants!$B$3, FALSE(), TRUE()))) | S13: =IF(ISBLANK($C13),"",IF(G13=Constants!$B$15,Constants!$B$8,IF(G13=Constants!$B$16,Constants!$B$9,Constants!$B$10))) | T13: =IF(ISBLANK($C13),"",IF(H13=Constants!$B$2, TRUE(), IF(H13=Constants!$B$3, FALSE(), TRUE()))) | U13: =IF(ISBLANK($C13),"",IF(I13=Constants!$B$19,Constants!$B$19,Constants!$B$18)) | V13: =IF(ISBLANK($C13),"",IF(COUNTA(J13:K13)=0,"",IF(AND(OR(ISBLANK(J13),AND(ISNUMBER(J13),J13>=0)),OR(ISBLANK(K13),AND(ISNUMBER(K13),K13>=0))),60*IF(ISBLANK(J13),0,J13)+IF(ISBLANK(K13),0,K13),""))) | W13: =IF(ISBLANK($C13),"",IF(L13=Constants!$B$19,Constants!$B$19,Constants!$B$18)) | X13: =IF(ISBLANK($C13),"",IF(COUNTA(M13:N13)=0,"",IF(AND(OR(ISBLANK(M13),AND(ISNUMBER(M13),M13>=0)),OR(ISBLANK(N13),AND(ISNUMBER(N13),N13>=0))),60*IF(ISBLANK(M13),0,M13)+IF(ISBLANK(N13),0,N13),""))) | Y13: =IF(ISBLANK($C13),"",IF(O13=Constants!$B$2, TRUE(), IF(O13=Constants!$B$3, FALSE(), FALSE()))) | Z13: =IF(ISBLANK($C13),"",IF(Y13,Constants!$B$4,IF(COUNTA(E13:N13)=0,Constants!$B$5,IF(COUNTA(J13:K13,M13:N13)=0,Constants!$B$6,Constants!$B$7)))) | AA13: =IF(ISBLANK($C13),"",IF($Z13<>Constants!$B$7,$Z13,IF(OR(NOT(T13),AND(NOT(Q13),COUNTIFS(U13:W13,Constants!$B$18,V13:X13,">=0")>0),AND(NOT(R13),COUNTIFS(U13:W13,Constants!$B$19,V13:X13,">=0")>0)),Constants!$B$12,Constants!$B$11))) | AB13: =IF($Z13=Constants!$B$7,IF(V13="",Constants!$B$13,V13),"") | AC13: =IF($Z13=Constants!$B$7,IF(X13="",Constants!$B$13,X13),"") | AD13: =IF($Z13=Constants!$B$7,IF($AB13>=$AC13,1,2),"") | AE13: =IF($Z13=Constants!$B$7,LARGE(AB13:AC13,1),"") | AF13: =IF(ISBLANK($C13),"",IF($Z13<>Constants!$B$7,$Z13,AE13*S13)) | AG13: =IF(ISBLANK($C13),"",IF($Z13=Constants!$B$7,IF(ISNUMBER(AF13),RANK(AF13,$AF$8:$AF$507),Constants!$B$14),$Z13)) | AH13: =IF(ISBLANK($C13),"",IF($Z13=Constants!$B$7,IF(ISNUMBER(AG13),COUNTIFS($AA$8:$AA$507,"<"&$AA13)+COUNTIFS($AA$8:$AA$507,$AA13,$AG$8:$AG$507,"<"&$AG13)+1,Constants!$B$14),$Z13)) | AI13: =IF(ISBLANK($C13),"",IF($Z13=Constants!$B$7,LARGE(AB13:AC13,2)*S13,"")) | AJ13: =IF(ISBLANK($C13),"",IF($Z13=Constants!$B$7,RANK(AI13,$AI$8:$AI$507),$Z13)) | AK13: =IF(ISBLANK($C13),"",IF($Z13=Constants!$B$7,IF(ISNUMBER(AG13),COUNTIFS($AA$8:$AA$507,"<"&$AA13)+COUNTIFS($AA$8:$AA$507,$AA13,$AG$8:$AG$507,"<"&$AG13)+COUNTIFS($AA$8:$AA$507,$AA13,$AG$8:$AG$507,$AG13,$AJ$8:$AJ$507,"<"&$AJ13)+1,Constants!$B$14),$Z13)) | AL13: =IF(ISBLANK($C13),"",IF($Z13=Constants!$B$7,IF(ISNUMBER(AH13),AH13-AK13,Constants!$B$14),$Z13)) | AN13: =IF(ISBLANK($C13),"",IF($Z13<>Constants!$B$7,$Z13,AD13)) | AO13: =IF(ISBLANK($C13),"",IF($Z13<>Constants!$B$7,$Z13,S13)) | AP13: =IF(ISBLANK($C13),"",IF($Z13<>Constants!$B$7,$Z13,AF13)) | AQ13: =IF(ISBLANK($C13),"",IF($Z13<>Constants!$B$7,$Z13,AA13)) | AR13: =IF(ISBLANK($C13),"",AL13) | AS13: =IF(ISBLANK($C13),"",AK13) | AT13: =IF(ISBLANK($C13),"",IF(AS13=Constants!$B$4,COUNTA($C$8:$C$507)+2,IF(AS13=Constants!$B$5,COUNTA($C$8:$C$507)+1,IF(AS13=Constants!$B$6,COUNTA($C$8:$C$507),AS13)))) | AV13: =IF(OR(ISNUMBER(AS13),AS13=Constants!$B$4,AS13=Constants!$B$6,AS13=Constants!$B$5),1,0) -> 0 | AW13: 6 | AX13: =IF(ISBLANK($C13),"",IF(ISNUMBER(AT13),AT13+ROW($B13)/1000,"")) | AY13: =IF(ISNUMBER(AX13),RANK(AX13,$AX$8:$AX$507,1),"") | AZ13: =IF(ISBLANK($C13),"",$B13) | BA13: =IF(ISBLANK($C13),"",$C13) | BB13: =IF(ISBLANK($C13),"",$D13) | BC13: =AQ13 | BD13: =AP13 | BE13: =IF(ISBLANK($C13),"",AS13) | BF13: =IF($AW13>$AV$7,"",VLOOKUP($AW13,$AY$8:$BE$507,7,FALSE())) | BG13: =IF($AW13>$AV$7,"",VLOOKUP($AW13,$AY$8:$BE$507,2,FALSE())) | BH13: =IF($AW13>$AV$7,"",VLOOKUP($AW13,$AY$8:$BE$507,3,FALSE())) | BI13: =IF($AW13>$AV$7,"",VLOOKUP($AW13,$AY$8:$BE$507,4,FALSE())) | BJ13: =IF($AW13>$AV$7,"",VLOOKUP($AW13,$AY$8:$BE$507,5,FALSE())) | BK13: =IF($AW13>$AV$7,"",VLOOKUP($AW13,$AY$8:$BE$507,6,FALSE()))
Q14: =IF(ISBLANK($C14),"",IF(E14=Constants!$B$2, TRUE(), IF(E14=Constants!$B$3, FALSE(), TRUE()))) | R14: =IF(ISBLANK($C14),"",IF(F14=Constants!$B$2, TRUE(), IF(F14=Constants!$B$3, FALSE(), TRUE()))) | S14: =IF(ISBLANK($C14),"",IF(G14=Constants!$B$15,Constants!$B$8,IF(G14=Constants!$B$16,Constants!$B$9,Constants!$B$10))) | T14: =IF(ISBLANK($C14),"",IF(H14=Constants!$B$2, TRUE(), IF(H14=Constants!$B$3, FALSE(), TRUE()))) | U14: =IF(ISBLANK($C14),"",IF(I14=Constants!$B$19,Constants!$B$19,Constants!$B$18)) | V14: =IF(ISBLANK($C14),"",IF(COUNTA(J14:K14)=0,"",IF(AND(OR(ISBLANK(J14),AND(ISNUMBER(J14),J14>=0)),OR(ISBLANK(K14),AND(ISNUMBER(K14),K14>=0))),60*IF(ISBLANK(J14),0,J14)+IF(ISBLANK(K14),0,K14),""))) | W14: =IF(ISBLANK($C14),"",IF(L14=Constants!$B$19,Constants!$B$19,Constants!$B$18)) | X14: =IF(ISBLANK($C14),"",IF(COUNTA(M14:N14)=0,"",IF(AND(OR(ISBLANK(M14),AND(ISNUMBER(M14),M14>=0)),OR(ISBLANK(N14),AND(ISNUMBER(N14),N14>=0))),60*IF(ISBLANK(M14),0,M14)+IF(ISBLANK(N14),0,N14),""))) | Y14: =IF(ISBLANK($C14),"",IF(O14=Constants!$B$2, TRUE(), IF(O14=Constants!$B$3, FALSE(), FALSE()))) | Z14: =IF(ISBLANK($C14),"",IF(Y14,Constants!$B$4,IF(COUNTA(E14:N14)=0,Constants!$B$5,IF(COUNTA(J14:K14,M14:N14)=0,Constants!$B$6,Constants!$B$7)))) | AA14: =IF(ISBLANK($C14),"",IF($Z14<>Constants!$B$7,$Z14,IF(OR(NOT(T14),AND(NOT(Q14),COUNTIFS(U14:W14,Constants!$B$18,V14:X14,">=0")>0),AND(NOT(R14),COUNTIFS(U14:W14,Constants!$B$19,V14:X14,">=0")>0)),Constants!$B$12,Constants!$B$11))) | AB14: =IF($Z14=Constants!$B$7,IF(V14="",Constants!$B$13,V14),"") | AC14: =IF($Z14=Constants!$B$7,IF(X14="",Constants!$B$13,X14),"") | AD14: =IF($Z14=Constants!$B$7,IF($AB14>=$AC14,1,2),"") | AE14: =IF($Z14=Constants!$B$7,LARGE(AB14:AC14,1),"") | AF14: =IF(ISBLANK($C14),"",IF($Z14<>Constants!$B$7,$Z14,AE14*S14)) | AG14: =IF(ISBLANK($C14),"",IF($Z14=Constants!$B$7,IF(ISNUMBER(AF14),RANK(AF14,$AF$8:$AF$507),Constants!$B$14),$Z14)) | AH14: =IF(ISBLANK($C14),"",IF($Z14=Constants!$B$7,IF(ISNUMBER(AG14),COUNTIFS($AA$8:$AA$507,"<"&$AA14)+COUNTIFS($AA$8:$AA$507,$AA14,$AG$8:$AG$507,"<"&$AG14)+1,Constants!$B$14),$Z14)) | AI14: =IF(ISBLANK($C14),"",IF($Z14=Constants!$B$7,LARGE(AB14:AC14,2)*S14,"")) | AJ14: =IF(ISBLANK($C14),"",IF($Z14=Constants!$B$7,RANK(AI14,$AI$8:$AI$507),$Z14)) | AK14: =IF(ISBLANK($C14),"",IF($Z14=Constants!$B$7,IF(ISNUMBER(AG14),COUNTIFS($AA$8:$AA$507,"<"&$AA14)+COUNTIFS($AA$8:$AA$507,$AA14,$AG$8:$AG$507,"<"&$AG14)+COUNTIFS($AA$8:$AA$507,$AA14,$AG$8:$AG$507,$AG14,$AJ$8:$AJ$507,"<"&$AJ14)+1,Constants!$B$14),$Z14)) | AL14: =IF(ISBLANK($C14),"",IF($Z14=Constants!$B$7,IF(ISNUMBER(AH14),AH14-AK14,Constants!$B$14),$Z14)) | AN14: =IF(ISBLANK($C14),"",IF($Z14<>Constants!$B$7,$Z14,AD14)) | AO14: =IF(ISBLANK($C14),"",IF($Z14<>Constants!$B$7,$Z14,S14)) | AP14: =IF(ISBLANK($C14),"",IF($Z14<>Constants!$B$7,$Z14,AF14)) | AQ14: =IF(ISBLANK($C14),"",IF($Z14<>Constants!$B$7,$Z14,AA14)) | AR14: =IF(ISBLANK($C14),"",AL14) | AS14: =IF(ISBLANK($C14),"",AK14) | AT14: =IF(ISBLANK($C14),"",IF(AS14=Constants!$B$4,COUNTA($C$8:$C$507)+2,IF(AS14=Constants!$B$5,COUNTA($C$8:$C$507)+1,IF(AS14=Constants!$B$6,COUNTA($C$8:$C$507),AS14)))) | AV14: =IF(OR(ISNUMBER(AS14),AS14=Constants!$B$4,AS14=Constants!$B$6,AS14=Constants!$B$5),1,0) -> 0 | AW14: 7 | AX14: =IF(ISBLANK($C14),"",IF(ISNUMBER(AT14),AT14+ROW($B14)/1000,"")) | AY14: =IF(ISNUMBER(AX14),RANK(AX14,$AX$8:$AX$507,1),"") | AZ14: =IF(ISBLANK($C14),"",$B14) | BA14: =IF(ISBLANK($C14),"",$C14) | BB14: =IF(ISBLANK($C14),"",$D14) | BC14: =AQ14 | BD14: =AP14 | BE14: =IF(ISBLANK($C14),"",AS14) | BF14: =IF($AW14>$AV$7,"",VLOOKUP($AW14,$AY$8:$BE$507,7,FALSE())) | BG14: =IF($AW14>$AV$7,"",VLOOKUP($AW14,$AY$8:$BE$507,2,FALSE())) | BH14: =IF($AW14>$AV$7,"",VLOOKUP($AW14,$AY$8:$BE$507,3,FALSE())) | BI14: =IF($AW14>$AV$7,"",VLOOKUP($AW14,$AY$8:$BE$507,4,FALSE())) | BJ14: =IF($AW14>$AV$7,"",VLOOKUP($AW14,$AY$8:$BE$507,5,FALSE())) | BK14: =IF($AW14>$AV$7,"",VLOOKUP($AW14,$AY$8:$BE$507,6,FALSE()))
Q15: =IF(ISBLANK($C15),"",IF(E15=Constants!$B$2, TRUE(), IF(E15=Constants!$B$3, FALSE(), TRUE()))) | R15: =IF(ISBLANK($C15),"",IF(F15=Constants!$B$2, TRUE(), IF(F15=Constants!$B$3, FALSE(), TRUE()))) | S15: =IF(ISBLANK($C15),"",IF(G15=Constants!$B$15,Constants!$B$8,IF(G15=Constants!$B$16,Constants!$B$9,Constants!$B$10))) | T15: =IF(ISBLANK($C15),"",IF(H15=Constants!$B$2, TRUE(), IF(H15=Constants!$B$3, FALSE(), TRUE()))) | U15: =IF(ISBLANK($C15),"",IF(I15=Constants!$B$19,Constants!$B$19,Constants!$B$18)) | V15: =IF(ISBLANK($C15),"",IF(COUNTA(J15:K15)=0,"",IF(AND(OR(ISBLANK(J15),AND(ISNUMBER(J15),J15>=0)),OR(ISBLANK(K15),AND(ISNUMBER(K15),K15>=0))),60*IF(ISBLANK(J15),0,J15)+IF(ISBLANK(K15),0,K15),""))) | W15: =IF(ISBLANK($C15),"",IF(L15=Constants!$B$19,Constants!$B$19,Constants!$B$18)) | X15: =IF(ISBLANK($C15),"",IF(COUNTA(M15:N15)=0,"",IF(AND(OR(ISBLANK(M15),AND(ISNUMBER(M15),M15>=0)),OR(ISBLANK(N15),AND(ISNUMBER(N15),N15>=0))),60*IF(ISBLANK(M15),0,M15)+IF(ISBLANK(N15),0,N15),""))) | Y15: =IF(ISBLANK($C15),"",IF(O15=Constants!$B$2, TRUE(), IF(O15=Constants!$B$3, FALSE(), FALSE()))) | Z15: =IF(ISBLANK($C15),"",IF(Y15,Constants!$B$4,IF(COUNTA(E15:N15)=0,Constants!$B$5,IF(COUNTA(J15:K15,M15:N15)=0,Constants!$B$6,Constants!$B$7)))) | AA15: =IF(ISBLANK($C15),"",IF($Z15<>Constants!$B$7,$Z15,IF(OR(NOT(T15),AND(NOT(Q15),COUNTIFS(U15:W15,Constants!$B$18,V15:X15,">=0")>0),AND(NOT(R15),COUNTIFS(U15:W15,Constants!$B$19,V15:X15,">=0")>0)),Constants!$B$12,Constants!$B$11))) | AB15: =IF($Z15=Constants!$B$7,IF(V15="",Constants!$B$13,V15),"") | AC15: =IF($Z15=Constants!$B$7,IF(X15="",Constants!$B$13,X15),"") | AD15: =IF($Z15=Constants!$B$7,IF($AB15>=$AC15,1,2),"") | AE15: =IF($Z15=Constants!$B$7,LARGE(AB15:AC15,1),"") | AF15: =IF(ISBLANK($C15),"",IF($Z15<>Constants!$B$7,$Z15,AE15*S15)) | AG15: =IF(ISBLANK($C15),"",IF($Z15=Constants!$B$7,IF(ISNUMBER(AF15),RANK(AF15,$AF$8:$AF$507),Constants!$B$14),$Z15)) | AH15: =IF(ISBLANK($C15),"",IF($Z15=Constants!$B$7,IF(ISNUMBER(AG15),COUNTIFS($AA$8:$AA$507,"<"&$AA15)+COUNTIFS($AA$8:$AA$507,$AA15,$AG$8:$AG$507,"<"&$AG15)+1,Constants!$B$14),$Z15)) | AI15: =IF(ISBLANK($C15),"",IF($Z15=Constants!$B$7,LARGE(AB15:AC15,2)*S15,"")) | AJ15: =IF(ISBLANK($C15),"",IF($Z15=Constants!$B$7,RANK(AI15,$AI$8:$AI$507),$Z15)) | AK15: =IF(ISBLANK($C15),"",IF($Z15=Constants!$B$7,IF(ISNUMBER(AG15),COUNTIFS($AA$8:$AA$507,"<"&$AA15)+COUNTIFS($AA$8:$AA$507,$AA15,$AG$8:$AG$507,"<"&$AG15)+COUNTIFS($AA$8:$AA$507,$AA15,$AG$8:$AG$507,$AG15,$AJ$8:$AJ$507,"<"&$AJ15)+1,Constants!$B$14),$Z15)) | AL15: =IF(ISBLANK($C15),"",IF($Z15=Constants!$B$7,IF(ISNUMBER(AH15),AH15-AK15,Constants!$B$14),$Z15)) | AN15: =IF(ISBLANK($C15),"",IF($Z15<>Constants!$B$7,$Z15,AD15)) | AO15: =IF(ISBLANK($C15),"",IF($Z15<>Constants!$B$7,$Z15,S15)) | AP15: =IF(ISBLANK($C15),"",IF($Z15<>Constants!$B$7,$Z15,AF15)) | AQ15: =IF(ISBLANK($C15),"",IF($Z15<>Constants!$B$7,$Z15,AA15)) | AR15: =IF(ISBLANK($C15),"",AL15) | AS15: =IF(ISBLANK($C15),"",AK15) | AT15: =IF(ISBLANK($C15),"",IF(AS15=Constants!$B$4,COUNTA($C$8:$C$507)+2,IF(AS15=Constants!$B$5,COUNTA($C$8:$C$507)+1,IF(AS15=Constants!$B$6,COUNTA($C$8:$C$507),AS15)))) | AV15: =IF(OR(ISNUMBER(AS15),AS15=Constants!$B$4,AS15=Constants!$B$6,AS15=Constants!$B$5),1,0) -> 0 | AW15: 8 | AX15: =IF(ISBLANK($C15),"",IF(ISNUMBER(AT15),AT15+ROW($B15)/1000,"")) | AY15: =IF(ISNUMBER(AX15),RANK(AX15,$AX$8:$AX$507,1),"") | AZ15: =IF(ISBLANK($C15),"",$B15) | BA15: =IF(ISBLANK($C15),"",$C15) | BB15: =IF(ISBLANK($C15),"",$D15) | BC15: =AQ15 | BD15: =AP15 | BE15: =IF(ISBLANK($C15),"",AS15) | BF15: =IF($AW15>$AV$7,"",VLOOKUP($AW15,$AY$8:$BE$507,7,FALSE())) | BG15: =IF($AW15>$AV$7,"",VLOOKUP($AW15,$AY$8:$BE$507,2,FALSE())) | BH15: =IF($AW15>$AV$7,"",VLOOKUP($AW15,$AY$8:$BE$507,3,FALSE())) | BI15: =IF($AW15>$AV$7,"",VLOOKUP($AW15,$AY$8:$BE$507,4,FALSE())) | BJ15: =IF($AW15>$AV$7,"",VLOOKUP($AW15,$AY$8:$BE$507,5,FALSE())) | BK15: =IF($AW15>$AV$7,"",VLOOKUP($AW15,$AY$8:$BE$507,6,FALSE()))
Q16: =IF(ISBLANK($C16),"",IF(E16=Constants!$B$2, TRUE(), IF(E16=Constants!$B$3, FALSE(), TRUE()))) | R16: =IF(ISBLANK($C16),"",IF(F16=Constants!$B$2, TRUE(), IF(F16=Constants!$B$3, FALSE(), TRUE()))) | S16: =IF(ISBLANK($C16),"",IF(G16=Constants!$B$15,Constants!$B$8,IF(G16=Constants!$B$16,Constants!$B$9,Constants!$B$10))) | T16: =IF(ISBLANK($C16),"",IF(H16=Constants!$B$2, TRUE(), IF(H16=Constants!$B$3, FALSE(), TRUE()))) | U16: =IF(ISBLANK($C16),"",IF(I16=Constants!$B$19,Constants!$B$19,Constants!$B$18)) | V16: =IF(ISBLANK($C16),"",IF(COUNTA(J16:K16)=0,"",IF(AND(OR(ISBLANK(J16),AND(ISNUMBER(J16),J16>=0)),OR(ISBLANK(K16),AND(ISNUMBER(K16),K16>=0))),60*IF(ISBLANK(J16),0,J16)+IF(ISBLANK(K16),0,K16),""))) | W16: =IF(ISBLANK($C16),"",IF(L16=Constants!$B$19,Constants!$B$19,Constants!$B$18)) | X16: =IF(ISBLANK($C16),"",IF(COUNTA(M16:N16)=0,"",IF(AND(OR(ISBLANK(M16),AND(ISNUMBER(M16),M16>=0)),OR(ISBLANK(N16),AND(ISNUMBER(N16),N16>=0))),60*IF(ISBLANK(M16),0,M16)+IF(ISBLANK(N16),0,N16),""))) | Y16: =IF(ISBLANK($C16),"",IF(O16=Constants!$B$2, TRUE(), IF(O16=Constants!$B$3, FALSE(), FALSE()))) | Z16: =IF(ISBLANK($C16),"",IF(Y16,Constants!$B$4,IF(COUNTA(E16:N16)=0,Constants!$B$5,IF(COUNTA(J16:K16,M16:N16)=0,Constants!$B$6,Constants!$B$7)))) | AA16: =IF(ISBLANK($C16),"",IF($Z16<>Constants!$B$7,$Z16,IF(OR(NOT(T16),AND(NOT(Q16),COUNTIFS(U16:W16,Constants!$B$18,V16:X16,">=0")>0),AND(NOT(R16),COUNTIFS(U16:W16,Constants!$B$19,V16:X16,">=0")>0)),Constants!$B$12,Constants!$B$11))) | AB16: =IF($Z16=Constants!$B$7,IF(V16="",Constants!$B$13,V16),"") | AC16: =IF($Z16=Constants!$B$7,IF(X16="",Constants!$B$13,X16),"") | AD16: =IF($Z16=Constants!$B$7,IF($AB16>=$AC16,1,2),"") | AE16: =IF($Z16=Constants!$B$7,LARGE(AB16:AC16,1),"") | AF16: =IF(ISBLANK($C16),"",IF($Z16<>Constants!$B$7,$Z16,AE16*S16)) | AG16: =IF(ISBLANK($C16),"",IF($Z16=Constants!$B$7,IF(ISNUMBER(AF16),RANK(AF16,$AF$8:$AF$507),Constants!$B$14),$Z16)) | AH16: =IF(ISBLANK($C16),"",IF($Z16=Constants!$B$7,IF(ISNUMBER(AG16),COUNTIFS($AA$8:$AA$507,"<"&$AA16)+COUNTIFS($AA$8:$AA$507,$AA16,$AG$8:$AG$507,"<"&$AG16)+1,Constants!$B$14),$Z16)) | AI16: =IF(ISBLANK($C16),"",IF($Z16=Constants!$B$7,LARGE(AB16:AC16,2)*S16,"")) | AJ16: =IF(ISBLANK($C16),"",IF($Z16=Constants!$B$7,RANK(AI16,$AI$8:$AI$507),$Z16)) | AK16: =IF(ISBLANK($C16),"",IF($Z16=Constants!$B$7,IF(ISNUMBER(AG16),COUNTIFS($AA$8:$AA$507,"<"&$AA16)+COUNTIFS($AA$8:$AA$507,$AA16,$AG$8:$AG$507,"<"&$AG16)+COUNTIFS($AA$8:$AA$507,$AA16,$AG$8:$AG$507,$AG16,$AJ$8:$AJ$507,"<"&$AJ16)+1,Constants!$B$14),$Z16)) | AL16: =IF(ISBLANK($C16),"",IF($Z16=Constants!$B$7,IF(ISNUMBER(AH16),AH16-AK16,Constants!$B$14),$Z16)) | AN16: =IF(ISBLANK($C16),"",IF($Z16<>Constants!$B$7,$Z16,AD16)) | AO16: =IF(ISBLANK($C16),"",IF($Z16<>Constants!$B$7,$Z16,S16)) | AP16: =IF(ISBLANK($C16),"",IF($Z16<>Constants!$B$7,$Z16,AF16)) | AQ16: =IF(ISBLANK($C16),"",IF($Z16<>Constants!$B$7,$Z16,AA16)) | AR16: =IF(ISBLANK($C16),"",AL16) | AS16: =IF(ISBLANK($C16),"",AK16) | AT16: =IF(ISBLANK($C16),"",IF(AS16=Constants!$B$4,COUNTA($C$8:$C$507)+2,IF(AS16=Constants!$B$5,COUNTA($C$8:$C$507)+1,IF(AS16=Constants!$B$6,COUNTA($C$8:$C$507),AS16)))) | AV16: =IF(OR(ISNUMBER(AS16),AS16=Constants!$B$4,AS16=Constants!$B$6,AS16=Constants!$B$5),1,0) -> 0 | AW16: 9 | AX16: =IF(ISBLANK($C16),"",IF(ISNUMBER(AT16),AT16+ROW($B16)/1000,"")) | AY16: =IF(ISNUMBER(AX16),RANK(AX16,$AX$8:$AX$507,1),"") | AZ16: =IF(ISBLANK($C16),"",$B16) | BA16: =IF(ISBLANK($C16),"",$C16) | BB16: =IF(ISBLANK($C16),"",$D16) | BC16: =AQ16 | BD16: =AP16 | BE16: =IF(ISBLANK($C16),"",AS16) | BF16: =IF($AW16>$AV$7,"",VLOOKUP($AW16,$AY$8:$BE$507,7,FALSE())) | BG16: =IF($AW16>$AV$7,"",VLOOKUP($AW16,$AY$8:$BE$507,2,FALSE())) | BH16: =IF($AW16>$AV$7,"",VLOOKUP($AW16,$AY$8:$BE$507,3,FALSE())) | BI16: =IF($AW16>$AV$7,"",VLOOKUP($AW16,$AY$8:$BE$507,4,FALSE())) | BJ16: =IF($AW16>$AV$7,"",VLOOKUP($AW16,$AY$8:$BE$507,5,FALSE())) | BK16: =IF($AW16>$AV$7,"",VLOOKUP($AW16,$AY$8:$BE$507,6,FALSE()))
Q17: =IF(ISBLANK($C17),"",IF(E17=Constants!$B$2, TRUE(), IF(E17=Constants!$B$3, FALSE(), TRUE()))) | R17: =IF(ISBLANK($C17),"",IF(F17=Constants!$B$2, TRUE(), IF(F17=Constants!$B$3, FALSE(), TRUE()))) | S17: =IF(ISBLANK($C17),"",IF(G17=Constants!$B$15,Constants!$B$8,IF(G17=Constants!$B$16,Constants!$B$9,Constants!$B$10))) | T17: =IF(ISBLANK($C17),"",IF(H17=Constants!$B$2, TRUE(), IF(H17=Constants!$B$3, FALSE(), TRUE()))) | U17: =IF(ISBLANK($C17),"",IF(I17=Constants!$B$19,Constants!$B$19,Constants!$B$18)) | V17: =IF(ISBLANK($C17),"",IF(COUNTA(J17:K17)=0,"",IF(AND(OR(ISBLANK(J17),AND(ISNUMBER(J17),J17>=0)),OR(ISBLANK(K17),AND(ISNUMBER(K17),K17>=0))),60*IF(ISBLANK(J17),0,J17)+IF(ISBLANK(K17),0,K17),""))) | W17: =IF(ISBLANK($C17),"",IF(L17=Constants!$B$19,Constants!$B$19,Constants!$B$18)) | X17: =IF(ISBLANK($C17),"",IF(COUNTA(M17:N17)=0,"",IF(AND(OR(ISBLANK(M17),AND(ISNUMBER(M17),M17>=0)),OR(ISBLANK(N17),AND(ISNUMBER(N17),N17>=0))),60*IF(ISBLANK(M17),0,M17)+IF(ISBLANK(N17),0,N17),""))) | Y17: =IF(ISBLANK($C17),"",IF(O17=Constants!$B$2, TRUE(), IF(O17=Constants!$B$3, FALSE(), FALSE()))) | Z17: =IF(ISBLANK($C17),"",IF(Y17,Constants!$B$4,IF(COUNTA(E17:N17)=0,Constants!$B$5,IF(COUNTA(J17:K17,M17:N17)=0,Constants!$B$6,Constants!$B$7)))) | AA17: =IF(ISBLANK($C17),"",IF($Z17<>Constants!$B$7,$Z17,IF(OR(NOT(T17),AND(NOT(Q17),COUNTIFS(U17:W17,Constants!$B$18,V17:X17,">=0")>0),AND(NOT(R17),COUNTIFS(U17:W17,Constants!$B$19,V17:X17,">=0")>0)),Constants!$B$12,Constants!$B$11))) | AB17: =IF($Z17=Constants!$B$7,IF(V17="",Constants!$B$13,V17),"") | AC17: =IF($Z17=Constants!$B$7,IF(X17="",Constants!$B$13,X17),"") | AD17: =IF($Z17=Constants!$B$7,IF($AB17>=$AC17,1,2),"") | AE17: =IF($Z17=Constants!$B$7,LARGE(AB17:AC17,1),"") | AF17: =IF(ISBLANK($C17),"",IF($Z17<>Constants!$B$7,$Z17,AE17*S17)) | AG17: =IF(ISBLANK($C17),"",IF($Z17=Constants!$B$7,IF(ISNUMBER(AF17),RANK(AF17,$AF$8:$AF$507),Constants!$B$14),$Z17)) | AH17: =IF(ISBLANK($C17),"",IF($Z17=Constants!$B$7,IF(ISNUMBER(AG17),COUNTIFS($AA$8:$AA$507,"<"&$AA17)+COUNTIFS($AA$8:$AA$507,$AA17,$AG$8:$AG$507,"<"&$AG17)+1,Constants!$B$14),$Z17)) | AI17: =IF(ISBLANK($C17),"",IF($Z17=Constants!$B$7,LARGE(AB17:AC17,2)*S17,"")) | AJ17: =IF(ISBLANK($C17),"",IF($Z17=Constants!$B$7,RANK(AI17,$AI$8:$AI$507),$Z17)) | AK17: =IF(ISBLANK($C17),"",IF($Z17=Constants!$B$7,IF(ISNUMBER(AG17),COUNTIFS($AA$8:$AA$507,"<"&$AA17)+COUNTIFS($AA$8:$AA$507,$AA17,$AG$8:$AG$507,"<"&$AG17)+COUNTIFS($AA$8:$AA$507,$AA17,$AG$8:$AG$507,$AG17,$AJ$8:$AJ$507,"<"&$AJ17)+1,Constants!$B$14),$Z17)) | AL17: =IF(ISBLANK($C17),"",IF($Z17=Constants!$B$7,IF(ISNUMBER(AH17),AH17-AK17,Constants!$B$14),$Z17)) | AN17: =IF(ISBLANK($C17),"",IF($Z17<>Constants!$B$7,$Z17,AD17)) | AO17: =IF(ISBLANK($C17),"",IF($Z17<>Constants!$B$7,$Z17,S17)) | AP17: =IF(ISBLANK($C17),"",IF($Z17<>Constants!$B$7,$Z17,AF17)) | AQ17: =IF(ISBLANK($C17),"",IF($Z17<>Constants!$B$7,$Z17,AA17)) | AR17: =IF(ISBLANK($C17),"",AL17) | AS17: =IF(ISBLANK($C17),"",AK17) | AT17: =IF(ISBLANK($C17),"",IF(AS17=Constants!$B$4,COUNTA($C$8:$C$507)+2,IF(AS17=Constants!$B$5,COUNTA($C$8:$C$507)+1,IF(AS17=Constants!$B$6,COUNTA($C$8:$C$507),AS17)))) | AV17: =IF(OR(ISNUMBER(AS17),AS17=Constants!$B$4,AS17=Constants!$B$6,AS17=Constants!$B$5),1,0) -> 0 | AW17: 10 | AX17: =IF(ISBLANK($C17),"",IF(ISNUMBER(AT17),AT17+ROW($B17)/1000,"")) | AY17: =IF(ISNUMBER(AX17),RANK(AX17,$AX$8:$AX$507,1),"") | AZ17: =IF(ISBLANK($C17),"",$B17) | BA17: =IF(ISBLANK($C17),"",$C17) | BB17: =IF(ISBLANK($C17),"",$D17) | BC17: =AQ17 | BD17: =AP17 | BE17: =IF(ISBLANK($C17),"",AS17) | BF17: =IF($AW17>$AV$7,"",VLOOKUP($AW17,$AY$8:$BE$507,7,FALSE())) | BG17: =IF($AW17>$AV$7,"",VLOOKUP($AW17,$AY$8:$BE$507,2,FALSE())) | BH17: =IF($AW17>$AV$7,"",VLOOKUP($AW17,$AY$8:$BE$507,3,FALSE())) | BI17: =IF($AW17>$AV$7,"",VLOOKUP($AW17,$AY$8:$BE$507,4,FALSE())) | BJ17: =IF($AW17>$AV$7,"",VLOOKUP($AW17,$AY$8:$BE$507,5,FALSE())) | BK17: =IF($AW17>$AV$7,"",VLOOKUP($AW17,$AY$8:$BE$507,6,FALSE()))
Q18: =IF(ISBLANK($C18),"",IF(E18=Constants!$B$2, TRUE(), IF(E18=Constants!$B$3, FALSE(), TRUE()))) | R18: =IF(ISBLANK($C18),"",IF(F18=Constants!$B$2, TRUE(), IF(F18=Constants!$B$3, FALSE(), TRUE()))) | S18: =IF(ISBLANK($C18),"",IF(G18=Constants!$B$15,Constants!$B$8,IF(G18=Constants!$B$16,Constants!$B$9,Constants!$B$10))) | T18: =IF(ISBLANK($C18),"",IF(H18=Constants!$B$2, TRUE(), IF(H18=Constants!$B$3, FALSE(), TRUE()))) | U18: =IF(ISBLANK($C18),"",IF(I18=Constants!$B$19,Constants!$B$19,Constants!$B$18)) | V18: =IF(ISBLANK($C18),"",IF(COUNTA(J18:K18)=0,"",IF(AND(OR(ISBLANK(J18),AND(ISNUMBER(J18),J18>=0)),OR(ISBLANK(K18),AND(ISNUMBER(K18),K18>=0))),60*IF(ISBLANK(J18),0,J18)+IF(ISBLANK(K18),0,K18),""))) | W18: =IF(ISBLANK($C18),"",IF(L18=Constants!$B$19,Constants!$B$19,Constants!$B$18)) | X18: =IF(ISBLANK($C18),"",IF(COUNTA(M18:N18)=0,"",IF(AND(OR(ISBLANK(M18),AND(ISNUMBER(M18),M18>=0)),OR(ISBLANK(N18),AND(ISNUMBER(N18),N18>=0))),60*IF(ISBLANK(M18),0,M18)+IF(ISBLANK(N18),0,N18),""))) | Y18: =IF(ISBLANK($C18),"",IF(O18=Constants!$B$2, TRUE(), IF(O18=Constants!$B$3, FALSE(), FALSE()))) | Z18: =IF(ISBLANK($C18),"",IF(Y18,Constants!$B$4,IF(COUNTA(E18:N18)=0,Constants!$B$5,IF(COUNTA(J18:K18,M18:N18)=0,Constants!$B$6,Constants!$B$7)))) | AA18: =IF(ISBLANK($C18),"",IF($Z18<>Constants!$B$7,$Z18,IF(OR(NOT(T18),AND(NOT(Q18),COUNTIFS(U18:W18,Constants!$B$18,V18:X18,">=0")>0),AND(NOT(R18),COUNTIFS(U18:W18,Constants!$B$19,V18:X18,">=0")>0)),Constants!$B$12,Constants!$B$11))) | AB18: =IF($Z18=Constants!$B$7,IF(V18="",Constants!$B$13,V18),"") | AC18: =IF($Z18=Constants!$B$7,IF(X18="",Constants!$B$13,X18),"") | AD18: =IF($Z18=Constants!$B$7,IF($AB18>=$AC18,1,2),"") | AE18: =IF($Z18=Constants!$B$7,LARGE(AB18:AC18,1),"") | AF18: =IF(ISBLANK($C18),"",IF($Z18<>Constants!$B$7,$Z18,AE18*S18)) | AG18: =IF(ISBLANK($C18),"",IF($Z18=Constants!$B$7,IF(ISNUMBER(AF18),RANK(AF18,$AF$8:$AF$507),Constants!$B$14),$Z18)) | AH18: =IF(ISBLANK($C18),"",IF($Z18=Constants!$B$7,IF(ISNUMBER(AG18),COUNTIFS($AA$8:$AA$507,"<"&$AA18)+COUNTIFS($AA$8:$AA$507,$AA18,$AG$8:$AG$507,"<"&$AG18)+1,Constants!$B$14),$Z18)) | AI18: =IF(ISBLANK($C18),"",IF($Z18=Constants!$B$7,LARGE(AB18:AC18,2)*S18,"")) | AJ18: =IF(ISBLANK($C18),"",IF($Z18=Constants!$B$7,RANK(AI18,$AI$8:$AI$507),$Z18)) | AK18: =IF(ISBLANK($C18),"",IF($Z18=Constants!$B$7,IF(ISNUMBER(AG18),COUNTIFS($AA$8:$AA$507,"<"&$AA18)+COUNTIFS($AA$8:$AA$507,$AA18,$AG$8:$AG$507,"<"&$AG18)+COUNTIFS($AA$8:$AA$507,$AA18,$AG$8:$AG$507,$AG18,$AJ$8:$AJ$507,"<"&$AJ18)+1,Constants!$B$14),$Z18)) | AL18: =IF(ISBLANK($C18),"",IF($Z18=Constants!$B$7,IF(ISNUMBER(AH18),AH18-AK18,Constants!$B$14),$Z18)) | AN18: =IF(ISBLANK($C18),"",IF($Z18<>Constants!$B$7,$Z18,AD18)) | AO18: =IF(ISBLANK($C18),"",IF($Z18<>Constants!$B$7,$Z18,S18)) | AP18: =IF(ISBLANK($C18),"",IF($Z18<>Constants!$B$7,$Z18,AF18)) | AQ18: =IF(ISBLANK($C18),"",IF($Z18<>Constants!$B$7,$Z18,AA18)) | AR18: =IF(ISBLANK($C18),"",AL18) | AS18: =IF(ISBLANK($C18),"",AK18) | AT18: =IF(ISBLANK($C18),"",IF(AS18=Constants!$B$4,COUNTA($C$8:$C$507)+2,IF(AS18=Constants!$B$5,COUNTA($C$8:$C$507)+1,IF(AS18=Constants!$B$6,COUNTA($C$8:$C$507),AS18)))) | AV18: =IF(OR(ISNUMBER(AS18),AS18=Constants!$B$4,AS18=Constants!$B$6,AS18=Constants!$B$5),1,0) -> 0 | AW18: 11 | AX18: =IF(ISBLANK($C18),"",IF(ISNUMBER(AT18),AT18+ROW($B18)/1000,"")) | AY18: =IF(ISNUMBER(AX18),RANK(AX18,$AX$8:$AX$507,1),"") | AZ18: =IF(ISBLANK($C18),"",$B18) | BA18: =IF(ISBLANK($C18),"",$C18) | BB18: =IF(ISBLANK($C18),"",$D18) | BC18: =AQ18 | BD18: =AP18 | BE18: =IF(ISBLANK($C18),"",AS18) | BF18: =IF($AW18>$AV$7,"",VLOOKUP($AW18,$AY$8:$BE$507,7,FALSE())) | BG18: =IF($AW18>$AV$7,"",VLOOKUP($AW18,$AY$8:$BE$507,2,FALSE())) | BH18: =IF($AW18>$AV$7,"",VLOOKUP($AW18,$AY$8:$BE$507,3,FALSE())) | BI18: =IF($AW18>$AV$7,"",VLOOKUP($AW18,$AY$8:$BE$507,4,FALSE())) | BJ18: =IF($AW18>$AV$7,"",VLOOKUP($AW18,$AY$8:$BE$507,5,FALSE())) | BK18: =IF($AW18>$AV$7,"",VLOOKUP($AW18,$AY$8:$BE$507,6,FALSE()))
Q19: =IF(ISBLANK($C19),"",IF(E19=Constants!$B$2, TRUE(), IF(E19=Constants!$B$3, FALSE(), TRUE()))) | R19: =IF(ISBLANK($C19),"",IF(F19=Constants!$B$2, TRUE(), IF(F19=Constants!$B$3, FALSE(), TRUE()))) | S19: =IF(ISBLANK($C19),"",IF(G19=Constants!$B$15,Constants!$B$8,IF(G19=Constants!$B$16,Constants!$B$9,Constants!$B$10))) | T19: =IF(ISBLANK($C19),"",IF(H19=Constants!$B$2, TRUE(), IF(H19=Constants!$B$3, FALSE(), TRUE()))) | U19: =IF(ISBLANK($C19),"",IF(I19=Constants!$B$19,Constants!$B$19,Constants!$B$18)) | V19: =IF(ISBLANK($C19),"",IF(COUNTA(J19:K19)=0,"",IF(AND(OR(ISBLANK(J19),AND(ISNUMBER(J19),J19>=0)),OR(ISBLANK(K19),AND(ISNUMBER(K19),K19>=0))),60*IF(ISBLANK(J19),0,J19)+IF(ISBLANK(K19),0,K19),""))) | W19: =IF(ISBLANK($C19),"",IF(L19=Constants!$B$19,Constants!$B$19,Constants!$B$18)) | X19: =IF(ISBLANK($C19),"",IF(COUNTA(M19:N19)=0,"",IF(AND(OR(ISBLANK(M19),AND(ISNUMBER(M19),M19>=0)),OR(ISBLANK(N19),AND(ISNUMBER(N19),N19>=0))),60*IF(ISBLANK(M19),0,M19)+IF(ISBLANK(N19),0,N19),""))) | Y19: =IF(ISBLANK($C19),"",IF(O19=Constants!$B$2, TRUE(), IF(O19=Constants!$B$3, FALSE(), FALSE()))) | Z19: =IF(ISBLANK($C19),"",IF(Y19,Constants!$B$4,IF(COUNTA(E19:N19)=0,Constants!$B$5,IF(COUNTA(J19:K19,M19:N19)=0,Constants!$B$6,Constants!$B$7)))) | AA19: =IF(ISBLANK($C19),"",IF($Z19<>Constants!$B$7,$Z19,IF(OR(NOT(T19),AND(NOT(Q19),COUNTIFS(U19:W19,Constants!$B$18,V19:X19,">=0")>0),AND(NOT(R19),COUNTIFS(U19:W19,Constants!$B$19,V19:X19,">=0")>0)),Constants!$B$12,Constants!$B$11))) | AB19: =IF($Z19=Constants!$B$7,IF(V19="",Constants!$B$13,V19),"") | AC19: =IF($Z19=Constants!$B$7,IF(X19="",Constants!$B$13,X19),"") | AD19: =IF($Z19=Constants!$B$7,IF($AB19>=$AC19,1,2),"") | AE19: =IF($Z19=Constants!$B$7,LARGE(AB19:AC19,1),"") | AF19: =IF(ISBLANK($C19),"",IF($Z19<>Constants!$B$7,$Z19,AE19*S19)) | AG19: =IF(ISBLANK($C19),"",IF($Z19=Constants!$B$7,IF(ISNUMBER(AF19),RANK(AF19,$AF$8:$AF$507),Constants!$B$14),$Z19)) | AH19: =IF(ISBLANK($C19),"",IF($Z19=Constants!$B$7,IF(ISNUMBER(AG19),COUNTIFS($AA$8:$AA$507,"<"&$AA19)+COUNTIFS($AA$8:$AA$507,$AA19,$AG$8:$AG$507,"<"&$AG19)+1,Constants!$B$14),$Z19)) | AI19: =IF(ISBLANK($C19),"",IF($Z19=Constants!$B$7,LARGE(AB19:AC19,2)*S19,"")) | AJ19: =IF(ISBLANK($C19),"",IF($Z19=Constants!$B$7,RANK(AI19,$AI$8:$AI$507),$Z19)) | AK19: =IF(ISBLANK($C19),"",IF($Z19=Constants!$B$7,IF(ISNUMBER(AG19),COUNTIFS($AA$8:$AA$507,"<"&$AA19)+COUNTIFS($AA$8:$AA$507,$AA19,$AG$8:$AG$507,"<"&$AG19)+COUNTIFS($AA$8:$AA$507,$AA19,$AG$8:$AG$507,$AG19,$AJ$8:$AJ$507,"<"&$AJ19)+1,Constants!$B$14),$Z19)) | AL19: =IF(ISBLANK($C19),"",IF($Z19=Constants!$B$7,IF(ISNUMBER(AH19),AH19-AK19,Constants!$B$14),$Z19)) | AN19: =IF(ISBLANK($C19),"",IF($Z19<>Constants!$B$7,$Z19,AD19)) | AO19: =IF(ISBLANK($C19),"",IF($Z19<>Constants!$B$7,$Z19,S19)) | AP19: =IF(ISBLANK($C19),"",IF($Z19<>Constants!$B$7,$Z19,AF19)) | AQ19: =IF(ISBLANK($C19),"",IF($Z19<>Constants!$B$7,$Z19,AA19)) | AR19: =IF(ISBLANK($C19),"",AL19) | AS19: =IF(ISBLANK($C19),"",AK19) | AT19: =IF(ISBLANK($C19),"",IF(AS19=Constants!$B$4,COUNTA($C$8:$C$507)+2,IF(AS19=Constants!$B$5,COUNTA($C$8:$C$507)+1,IF(AS19=Constants!$B$6,COUNTA($C$8:$C$507),AS19)))) | AV19: =IF(OR(ISNUMBER(AS19),AS19=Constants!$B$4,AS19=Constants!$B$6,AS19=Constants!$B$5),1,0) -> 0 | AW19: 12 | AX19: =IF(ISBLANK($C19),"",IF(ISNUMBER(AT19),AT19+ROW($B19)/1000,"")) | AY19: =IF(ISNUMBER(AX19),RANK(AX19,$AX$8:$AX$507,1),"") | AZ19: =IF(ISBLANK($C19),"",$B19) | BA19: =IF(ISBLANK($C19),"",$C19) | BB19: =IF(ISBLANK($C19),"",$D19) | BC19: =AQ19 | BD19: =AP19 | BE19: =IF(ISBLANK($C19),"",AS19) | BF19: =IF($AW19>$AV$7,"",VLOOKUP($AW19,$AY$8:$BE$507,7,FALSE())) | BG19: =IF($AW19>$AV$7,"",VLOOKUP($AW19,$AY$8:$BE$507,2,FALSE())) | BH19: =IF($AW19>$AV$7,"",VLOOKUP($AW19,$AY$8:$BE$507,3,FALSE())) | BI19: =IF($AW19>$AV$7,"",VLOOKUP($AW19,$AY$8:$BE$507,4,FALSE())) | BJ19: =IF($AW19>$AV$7,"",VLOOKUP($AW19,$AY$8:$BE$507,5,FALSE())) | BK19: =IF($AW19>$AV$7,"",VLOOKUP($AW19,$AY$8:$BE$507,6,FALSE()))
... Q507: =IF(ISBLANK($C507),"",IF(E507=Constants!$B$2, TRUE(), IF(E507=Constants!$B$3, FALSE(), TRUE()))) | R507: =IF(ISBLANK($C507),"",IF(F507=Constants!$B$2, TRUE(), IF(F507=Constants!$B$3, FALSE(), TRUE()))) | S507: =IF(ISBLANK($C507),"",IF(G507=Constants!$B$15,Constants!$B$8,IF(G507=Constants!$B$16,Constants!$B$9,Constants!$B$10))) | T507: =IF(ISBLANK($C507),"",IF(H507=Constants!$B$2, TRUE(), IF(H507=Constants!$B$3, FALSE(), TRUE()))) | U507: =IF(ISBLANK($C507),"",IF(I507=Constants!$B$19,Constants!$B$19,Constants!$B$18)) | V507: =IF(ISBLANK($C507),"",IF(COUNTA(J507:K507)=0,"",IF(AND(OR(ISBLANK(J507),AND(ISNUMBER(J507),J507>=0)),OR(ISBLANK(K507),AND(ISNUMBER(K507),K507>=0))),60*IF(ISBLANK(J507),0,J507)+IF(ISBLANK(K507),0,K507),""))) | W507: =IF(ISBLANK($C507),"",IF(L507=Constants!$B$19,Constants!$B$19,Constants!$B$18)) | X507: =IF(ISBLANK($C507),"",IF(COUNTA(M507:N507)=0,"",IF(AND(OR(ISBLANK(M507),AND(ISNUMBER(M507),M507>=0)),OR(ISBLANK(N507),AND(ISNUMBER(N507),N507>=0))),60*IF(ISBLANK(M507),0,M507)+IF(ISBLANK(N507),0,N507),""))) | Y507: =IF(ISBLANK($C507),"",IF(O507=Constants!$B$2, TRUE(), IF(O507=Constants!$B$3, FALSE(), FALSE()))) | Z507: =IF(ISBLANK($C507),"",IF(Y507,Constants!$B$4,IF(COUNTA(E507:N507)=0,Constants!$B$5,IF(COUNTA(J507:K507,M507:N507)=0,Constants!$B$6,Constants!$B$7)))) | AA507: =IF(ISBLANK($C507),"",IF($Z507<>Constants!$B$7,$Z507,IF(OR(NOT(T507),AND(NOT(Q507),COUNTIFS(U507:W507,Constants!$B$18,V507:X507,">=0")>0),AND(NOT(R507),COUNTIFS(U507:W507,Constants!$B$19,V507:X507,">=0")>0)),Constants!$B$12,Constants!$B$11))) | AB507: =IF($Z507=Constants!$B$7,IF(V507="",Constants!$B$13,V507),"") | AC507: =IF($Z507=Constants!$B$7,IF(X507="",Constants!$B$13,X507),"") | AD507: =IF($Z507=Constants!$B$7,IF($AB507>=$AC507,1,2),"") | AE507: =IF($Z507=Constants!$B$7,LARGE(AB507:AC507,1),"") | AF507: =IF(ISBLANK($C507),"",IF($Z507<>Constants!$B$7,$Z507,AE507*S507)) | AG507: =IF(ISBLANK($C507),"",IF($Z507=Constants!$B$7,IF(ISNUMBER(AF507),RANK(AF507,$AF$8:$AF$507),Constants!$B$14),$Z507)) | AH507: =IF(ISBLANK($C507),"",IF($Z507=Constants!$B$7,IF(ISNUMBER(AG507),COUNTIFS($AA$8:$AA$507,"<"&$AA507)+COUNTIFS($AA$8:$AA$507,$AA507,$AG$8:$AG$507,"<"&$AG507)+1,Constants!$B$14),$Z507)) | AI507: =IF(ISBLANK($C507),"",IF($Z507=Constants!$B$7,LARGE(AB507:AC507,2)*S507,"")) | AJ507: =IF(ISBLANK($C507),"",IF($Z507=Constants!$B$7,RANK(AI507,$AI$8:$AI$507),$Z507)) | AK507: =IF(ISBLANK($C507),"",IF($Z507=Constants!$B$7,IF(ISNUMBER(AG507),COUNTIFS($AA$8:$AA$507,"<"&$AA507)+COUNTIFS($AA$8:$AA$507,$AA507,$AG$8:$AG$507,"<"&$AG507)+COUNTIFS($AA$8:$AA$507,$AA507,$AG$8:$AG$507,$AG507,$AJ$8:$AJ$507,"<"&$AJ507)+1,Constants!$B$14),$Z507)) | AL507: =IF(ISBLANK($C507),"",IF($Z507=Constants!$B$7,IF(ISNUMBER(AH507),AH507-AK507,Constants!$B$14),$Z507)) | AN507: =IF(ISBLANK($C507),"",IF($Z507<>Constants!$B$7,$Z507,AD507)) | AO507: =IF(ISBLANK($C507),"",IF($Z507<>Constants!$B$7,$Z507,S507)) | AP507: =IF(ISBLANK($C507),"",IF($Z507<>Constants!$B$7,$Z507,AF507)) | AQ507: =IF(ISBLANK($C507),"",IF($Z507<>Constants!$B$7,$Z507,AA507)) | AR507: =IF(ISBLANK($C507),"",AL507) | AS507: =IF(ISBLANK($C507),"",AK507) | AT507: =IF(ISBLANK($C507),"",IF(AS507=Constants!$B$4,COUNTA($C$8:$C$507)+2,IF(AS507=Constants!$B$5,COUNTA($C$8:$C$507)+1,IF(AS507=Constants!$B$6,COUNTA($C$8:$C$507),AS507)))) | AV507: =IF(OR(ISNUMBER(AS507),AS507=Constants!$B$4,AS507=Constants!$B$6,AS507=Constants!$B$5),1,0) -> 0 | AW507: 500 | AX507: =IF(ISBLANK($C507),"",IF(ISNUMBER(AT507),AT507+ROW($B507)/1000,"")) | AY507: =IF(ISNUMBER(AX507),RANK(AX507,$AX$8:$AX$507,1),"") | AZ507: =IF(ISBLANK($C507),"",$B507) | BA507: =IF(ISBLANK($C507),"",$C507) | BB507: =IF(ISBLANK($C507),"",$D507) | BC507: =AQ507 | BD507: =AP507 | BE507: =IF(ISBLANK($C507),"",AS507) | BF507: =IF($AW507>$AV$7,"",VLOOKUP($AW507,$AY$8:$BE$507,7,FALSE())) | BG507: =IF($AW507>$AV$7,"",VLOOKUP($AW507,$AY$8:$BE$507,2,FALSE())) | BH507: =IF($AW507>$AV$7,"",VLOOKUP($AW507,$AY$8:$BE$507,3,FALSE())) | BI507: =IF($AW507>$AV$7,"",VLOOKUP($AW507,$AY$8:$BE$507,4,FALSE())) | BJ507: =IF($AW507>$AV$7,"",VLOOKUP($AW507,$AY$8:$BE$507,5,FALSE())) | BK507: =IF($AW507>$AV$7,"",VLOOKUP($AW507,$AY$8:$BE$507,6,FALSE()))

Sheet Constants
A1: Name Desc | B1: Value
A2: =TRUE() -> TRUE | B2: T
A3: =FALSE() -> FALSE | B3: F
A4: Disqualified | B4: DQ
A5: No-Show | B5: NS
A6: Participated | B6: P
A7: Competed | B7: C
A8: Complete Flight Log Multiplier | B8: 1.2
A9: Partial Flight Log Multiplier | B9: 1.1
A10: No Flight Log Multiplier | B10: 1
A11: Tier 1 (all parameters met) | B11: 1
A12: Tier 2 (construction/competition violation) | B12: 2
A13: Seconds Assessed for a Missing Flight | B13: 0
A14: Error Status | B14: ERR
A15: Flight Log: Complete | B15: Complete
A16: Flight Log: Partial | B16: Partial
A17: Flight Log: Not Present | B17: Not present
A18: Plane A | B18: A
A19: Plane B | B19: B

Sheet Export
A1: Team # | B1: School Name | C1: Team Name | D1: Status | E1: Score | F1: Tiebreaker | G1: Tier | H1: Points | I1: Rank
A2: =ExportRaw!$F2 -> 0 | B2: =ExportRaw!$C2 -> 0 | C2: =ExportRaw!$G2 -> 0 | D2: =ExportRaw!$E2 | E2: =ExportRaw!$D2 | F2: =ExportRaw!$H2 | G2: =ExportRaw!$I2 | H2: =ExportRaw!$A2 | I2: =ExportRaw!$B2
A3: =ExportRaw!$F3 -> 0 | B3: =ExportRaw!$C3 -> 0 | C3: =ExportRaw!$G3 -> 0 | D3: =ExportRaw!$E3 | E3: =ExportRaw!$D3 | F3: =ExportRaw!$H3 | G3: =ExportRaw!$I3 | H3: =ExportRaw!$A3 | I3: =ExportRaw!$B3
A4: =ExportRaw!$F4 -> 0 | B4: =ExportRaw!$C4 -> 0 | C4: =ExportRaw!$G4 -> 0 | D4: =ExportRaw!$E4 | E4: =ExportRaw!$D4 | F4: =ExportRaw!$H4 | G4: =ExportRaw!$I4 | H4: =ExportRaw!$A4 | I4: =ExportRaw!$B4
A5: =ExportRaw!$F5 -> 0 | B5: =ExportRaw!$C5 -> 0 | C5: =ExportRaw!$G5 -> 0 | D5: =ExportRaw!$E5 | E5: =ExportRaw!$D5 | F5: =ExportRaw!$H5 | G5: =ExportRaw!$I5 | H5: =ExportRaw!$A5 | I5: =ExportRaw!$B5
A6: =ExportRaw!$F6 -> 0 | B6: =ExportRaw!$C6 -> 0 | C6: =ExportRaw!$G6 -> 0 | D6: =ExportRaw!$E6 | E6: =ExportRaw!$D6 | F6: =ExportRaw!$H6 | G6: =ExportRaw!$I6 | H6: =ExportRaw!$A6 | I6: =ExportRaw!$B6
A7: =ExportRaw!$F7 -> 0 | B7: =ExportRaw!$C7 -> 0 | C7: =ExportRaw!$G7 -> 0 | D7: =ExportRaw!$E7 | E7: =ExportRaw!$D7 | F7: =ExportRaw!$H7 | G7: =ExportRaw!$I7 | H7: =ExportRaw!$A7 | I7: =ExportRaw!$B7
A8: =ExportRaw!$F8 -> 0 | B8: =ExportRaw!$C8 -> 0 | C8: =ExportRaw!$G8 -> 0 | D8: =ExportRaw!$E8 | E8: =ExportRaw!$D8 | F8: =ExportRaw!$H8 | G8: =ExportRaw!$I8 | H8: =ExportRaw!$A8 | I8: =ExportRaw!$B8
A9: =ExportRaw!$F9 -> 0 | B9: =ExportRaw!$C9 -> 0 | C9: =ExportRaw!$G9 -> 0 | D9: =ExportRaw!$E9 | E9: =ExportRaw!$D9 | F9: =ExportRaw!$H9 | G9: =ExportRaw!$I9 | H9: =ExportRaw!$A9 | I9: =ExportRaw!$B9
A10: =ExportRaw!$F10 -> 0 | B10: =ExportRaw!$C10 -> 0 | C10: =ExportRaw!$G10 -> 0 | D10: =ExportRaw!$E10 | E10: =ExportRaw!$D10 | F10: =ExportRaw!$H10 | G10: =ExportRaw!$I10 | H10: =ExportRaw!$A10 | I10: =ExportRaw!$B10
A11: =ExportRaw!$F11 -> 0 | B11: =ExportRaw!$C11 -> 0 | C11: =ExportRaw!$G11 -> 0 | D11: =ExportRaw!$E11 | E11: =ExportRaw!$D11 | F11: =ExportRaw!$H11 | G11: =ExportRaw!$I11 | H11: =ExportRaw!$A11 | I11: =ExportRaw!$B11
A12: =ExportRaw!$F12 -> 0 | B12: =ExportRaw!$C12 -> 0 | C12: =ExportRaw!$G12 -> 0 | D12: =ExportRaw!$E12 | E12: =ExportRaw!$D12 | F12: =ExportRaw!$H12 | G12: =ExportRaw!$I12 | H12: =ExportRaw!$A12 | I12: =ExportRaw!$B12
A13: =ExportRaw!$F13 -> 0 | B13: =ExportRaw!$C13 -> 0 | C13: =ExportRaw!$G13 -> 0 | D13: =ExportRaw!$E13 | E13: =ExportRaw!$D13 | F13: =ExportRaw!$H13 | G13: =ExportRaw!$I13 | H13: =ExportRaw!$A13 | I13: =ExportRaw!$B13
... A501: =ExportRaw!$F501 -> 0 | B501: =ExportRaw!$C501 -> 0 | C501: =ExportRaw!$G501 -> 0 | D501: =ExportRaw!$E501 | E501: =ExportRaw!$D501 | F501: =ExportRaw!$H501 | G501: =ExportRaw!$I501 | H501: =ExportRaw!$A501 | I501: =ExportRaw!$B501

Sheet Changelog
A1: Date | B1: Version # | C1: Change

Sheet Vers
A21: =IF(ISBLANK(B21),"",B21&"|"&C21)
A22: =IF(ISBLANK(B22),"",B22&"|"&C22)
A23: =IF(ISBLANK(B23),"",B23&"|"&C23)
A24: =IF(ISBLANK(B24),"",B24&"|"&C24)
A25: =IF(ISBLANK(B25),"",B25&"|"&C25)
A26: =IF(ISBLANK(B26),"",B26&"|"&C26)
A27: =IF(ISBLANK(B27),"",B27&"|"&C27)
A28: =IF(ISBLANK(B28),"",B28&"|"&C28)
A29: =IF(ISBLANK(B29),"",B29&"|"&C29)
A30: =IF(ISBLANK(B30),"",B30&"|"&C30)
A31: =IF(ISBLANK(B31),"",B31&"|"&C31)
A32: =IF(ISBLANK(B32),"",B32&"|"&C32)
... A1000: =IF(ISBLANK(B1000),"",B1000&"|"&C1000)

Sheet Info.
A1: Event | B1: Wright Stuff
A2: Last Updated | B2: 46296 | D2: Idx of first . | E2: Idx of second . | F2: Major Version | G2: Minor Version | H2: Minor Patch
A3: Version | B3: 0.1.0 | D3: =FIND(".",B3) -> 2 | E3: =FIND(".",B3,D3+1) -> 4 | F3: =LEFT(B3,D3-1) -> 0 | G3: =MID(B3,D3+1,E3-D3-1) -> 1 | H3: =RIGHT(B3,LEN(B3)-E3) -> 0
A4: Division | B4: C
A5: Year | B5: 2027
A6: VLook | B6: =B1&"|"&B4 -> Wright Stuff|C
A7: Latest Version | D7: =FIND(".",B7) -> #VALUE! | E7: =FIND(".",B7,D7+1) -> #VALUE! | F7: =LEFT(B7,D7-1) -> #VALUE! | G7: =MID(B7,D7+1,E7-D7-1) -> #VALUE! | H7: =RIGHT(B7,LEN(B7)-E7) -> #VALUE!
A8: Outdated?

Sheet Dropdowns
A1: Compliant | B1: Complete | C1: Points
A2: Incomplete | B2: Incomplete | C2: Rank
A3: Non-Compliant | B3: No Log | C3: School Name
A4: No Log | C4: Score
C5: Status
C6: Team #
C7: Team Name
C8: Tiebreaker
C9: Tier

Sheet ExportRaw
A1: Points | B1: Rank | C1: School Name | D1: Score | E1: Status | F1: Team # | G1: Team Name | H1: Tiebreaker | I1: Tier
A2: =Scoring!AT8 | B2: =Scoring!AS8 | C2: =Scoring!C8 -> 0 | D2: =Scoring!AP8 | E2: =Scoring!Z8 | F2: =Scoring!B8 -> 0 | G2: =Scoring!D8 -> 0 | H2: =Scoring!AR8 | I2: =Scoring!AQ8
A3: =Scoring!AT9 | B3: =Scoring!AS9 | C3: =Scoring!C9 -> 0 | D3: =Scoring!AP9 | E3: =Scoring!Z9 | F3: =Scoring!B9 -> 0 | G3: =Scoring!D9 -> 0 | H3: =Scoring!AR9 | I3: =Scoring!AQ9
A4: =Scoring!AT10 | B4: =Scoring!AS10 | C4: =Scoring!C10 -> 0 | D4: =Scoring!AP10 | E4: =Scoring!Z10 | F4: =Scoring!B10 -> 0 | G4: =Scoring!D10 -> 0 | H4: =Scoring!AR10 | I4: =Scoring!AQ10
A5: =Scoring!AT11 | B5: =Scoring!AS11 | C5: =Scoring!C11 -> 0 | D5: =Scoring!AP11 | E5: =Scoring!Z11 | F5: =Scoring!B11 -> 0 | G5: =Scoring!D11 -> 0 | H5: =Scoring!AR11 | I5: =Scoring!AQ11
A6: =Scoring!AT12 | B6: =Scoring!AS12 | C6: =Scoring!C12 -> 0 | D6: =Scoring!AP12 | E6: =Scoring!Z12 | F6: =Scoring!B12 -> 0 | G6: =Scoring!D12 -> 0 | H6: =Scoring!AR12 | I6: =Scoring!AQ12
A7: =Scoring!AT13 | B7: =Scoring!AS13 | C7: =Scoring!C13 -> 0 | D7: =Scoring!AP13 | E7: =Scoring!Z13 | F7: =Scoring!B13 -> 0 | G7: =Scoring!D13 -> 0 | H7: =Scoring!AR13 | I7: =Scoring!AQ13
A8: =Scoring!AT14 | B8: =Scoring!AS14 | C8: =Scoring!C14 -> 0 | D8: =Scoring!AP14 | E8: =Scoring!Z14 | F8: =Scoring!B14 -> 0 | G8: =Scoring!D14 -> 0 | H8: =Scoring!AR14 | I8: =Scoring!AQ14
A9: =Scoring!AT15 | B9: =Scoring!AS15 | C9: =Scoring!C15 -> 0 | D9: =Scoring!AP15 | E9: =Scoring!Z15 | F9: =Scoring!B15 -> 0 | G9: =Scoring!D15 -> 0 | H9: =Scoring!AR15 | I9: =Scoring!AQ15
A10: =Scoring!AT16 | B10: =Scoring!AS16 | C10: =Scoring!C16 -> 0 | D10: =Scoring!AP16 | E10: =Scoring!Z16 | F10: =Scoring!B16 -> 0 | G10: =Scoring!D16 -> 0 | H10: =Scoring!AR16 | I10: =Scoring!AQ16
