Workbook

Sheet Scoring
B2: ='Info.'!B1&" "&'Info.'!B4 -> Hovercraft B/C | E2: Scoring | AQ2: Req* | AY2: Req* | BG2: Req* | BK2: Req* if certain fields are conflicting | DL2: Breakdown | DX2: Rank for this team with row() bump | DY2: Rank for this team with same ranks split | DZ2: Team Number of this team | EA2: Name of this schoo | EB2: Name of this team | EC2: Tier for this Team | ED2: Score for this team | EE2: Actual Rank for this team | EF2: Final Rankings
E3: 1. Impound (T/F) | F3: 2. All Safety Construction Parameters Met (T/F) | G3: Run 1 | P3: Run 2 | Y3: Run 3 | AH3: 12. Disqualify (T/F) | AJ3: =E3 -> 1. Impound (T/F) | AK3: =F3 -> 2. All Safety Construction Parameters Met (T/F) | AL3: Run 1 Filled Out? | AM3: =G4 -> 3A. # of Construction Parameters Violated | AN3: =H4 -> 4A. # of Competition Params Violated | AO3: =J4 -> 6A. No touching/interfering after start (T/F) | AP3: =I4 -> 5A. Ramp Not Used? (T/F) | AQ3: =K4 -> 7A. Complete / Incomplete (C/I) | AR3: =L4 -> 8A. # of nickel rolls | AS3: =M4 -> 9A. # of loose nickels | AT3: Run 2 Filled Out? | AU3: =P4 -> 3B. # of Construction Parameters Violated | AV3: =Q4 -> 4B. # of Competition Params Violated | AW3: =S4 -> 6B. No touching/interfering after start (T/F) | AX3: =R4 -> 5B. Ramp Not Used? (T/F) | AY3: =T4 -> 7B. Complete / Incomplete (C/I) | AZ3: =U4 -> 8B. # of nickel rolls | BA3: =V4 -> 9B. # of loose nickels | BB3: Run 3 Filled Out? | BC3: =Y4 -> 3C. # of Construction Parameters Violated | BD3: =Z4 -> 4C. # of Competition Params Violated | BE3: =AB4 -> 6C. No touching/interfering after start (T/F) | BF3: =AA4 -> 5C. Ramp Not Used? (T/F) | BG3: =AC4 -> 7C. Complete / Incomplete (C/I) | BH3: =AD4 -> 8C. # of nickel rolls | BI3: =AE4 -> 9C. # of loose nickels | BJ3: =AH3 -> 12. Disqualify (T/F)
B4: ="Event Scoresheet - "&'Info.'!B5&IF('Info.'!B8="T"," The scoresheet has been updated; please download version v"&'Info.'!B7&" from soinc.org/scoresheets.","") -> Event Scoresheet - 2027 | G4: 3A. # of Construction Parameters Violated | H4: 4A. # of Competition Params Violated | I4: 5A. Ramp Not Used? (T/F) | J4: 6A. No touching/interfering after start (T/F) | K4: 7A. Complete / Incomplete (C/I) | L4: 8A. # of nickel rolls | M4: 9A. # of loose nickels | N4: 10A. Vehicle Distance (cm) | O4: 11A. Run Time (s) | P4: 3B. # of Construction Parameters Violated | Q4: 4B. # of Competition Params Violated | R4: 5B. Ramp Not Used? (T/F) | S4: 6B. No touching/interfering after start (T/F) | T4: 7B. Complete / Incomplete (C/I) | U4: 8B. # of nickel rolls | V4: 9B. # of loose nickels | W4: 10B. Vehicle Distance (cm) | X4: 11B. Run Time (s) | Y4: 3C. # of Construction Parameters Violated | Z4: 4C. # of Competition Params Violated | AA4: 5C. Ramp Not Used? (T/F) | AB4: 6C. No touching/interfering after start (T/F) | AC4: 7C. Complete / Incomplete (C/I) | AD4: 8C. # of nickel rolls | AE4: 9C. # of loose nickels | AF4: 10C. Vehicle Distance (cm) | AG4: 11C. Run Time (s) | DL4: Scored Run | DM4: Scored DS | DN4: Scored TS | DO4: Scored MS | DP4: Score | DQ4: Tier | DR4: Tiebreaker | DS4: Rank | DT4: Points | EF4: Rank | EG4: Team # | EH4: School Name | EI4: Team Name | EJ4: Score
B7: ="Last Updated: "&TEXT('Info.'!B2, "mm/dd/yyyy")&" (v"&'Info.'!B3&") Direct all questions to scoresheets@soinc.org." -> Last Updated: 10/01/2026 (v1.0.0) Direct all questions to scoresheets@soinc.org.
B8: Target Time (sec):
BM9: Globals | BN9: Run 1 | BX9: Run 2 | CH9: Run 3 | CS9: Run Scores | CY9: Tiebreakers
B10: Team # | C10: School Name | D10: Team Name | BK10: Status | BL10: Tier | BM10: TT Sanitized | BN10: Run 1 Completed? | BO10: Run 1 Calculable? | BP10: Penalty Multiplier | BQ10: DS w/o Penalties | BR10: DS | BS10: TS w/o Penalties | BT10: TS | BU10: MS w/o Penalties | BV10: MS | BW10: Run 1 Score | BX10: Run 2 Completed? | BY10: Run 2 Calculable? | BZ10: Penalty Multiplier | CA10: DS w/o Penalties | CB10: DS | CC10: TS w/o Penalties | CD10: TS | CE10: MS w/o Penalties | CF10: MS | CG10: Run 2 Score | CH10: Compute Run 3? (runs 1-2 not both C or both I) | CI10: Run 3 Completed? | CJ10: Run 3 Calculable? | CK10: Penalty Multiplier | CL10: DS w/o Penalties | CM10: DS | CN10: TS w/o Penalties | CO10: TS | CP10: MS w/o Penalties | CQ10: MS | CR10: Run 3 Score | CS10: Run 1 Score | CT10: Run 2 Score | CU10: Run 3 Score | CV10: Best Run Score | CW10: Score | CX10: Rank | CY10: Best TS over all runs (TB1) | CZ10: TB1 Rank | DA10: Fewest Const Violations (TB2) | DB10: TB2 Rank | DC10: Best MS (TB3) | DD10: TB3 Rank | DE10: 2nd Best Run Score (TB4) | DF10: TB4 Rank | DG10: Rank w/ TB | DH10: Rank Diff | DK10: Errors | DV10: =SUM(DV11:DV510) -> 0
AJ11: =IF(ISBLANK($C11), "", IF(E11=Constants!$B$7, TRUE(), IF(E11=Constants!$B$8, FALSE(), TRUE() ))) | AK11: =IF(ISBLANK($C11),"",IF(F11=Constants!$B$8,FALSE(),TRUE())) | AL11: =IF(ISBLANK($C11),"",COUNTA($G11:$O11)>0) | AM11: =IF(OR(ISBLANK($C11),$AL11<>TRUE()),"",IF(ISBLANK(G11),Constants!$B$27,MAX(0,G11))) | AN11: =IF(OR(ISBLANK($C11),$AL11<>TRUE()),"",IF(ISBLANK(H11),Constants!$B$28,MAX(0,H11))) | AO11: =IF(OR(ISBLANK($C11),$AL11<>TRUE()),"",IF(J11=Constants!$B$7,TRUE(),IF(J11=Constants!$B$8,FALSE(),TRUE()))) | AP11: =IF(OR(ISBLANK($C11),$AL11<>TRUE()),"",IF(I11=Constants!$B$7,TRUE(),IF(I11=Constants!$B$8,FALSE(),TRUE()))) | AQ11: =IF(OR(ISBLANK($C11),$AL11<>TRUE()),"",IF(K11=Constants!$B$33,TRUE(),IF(K11=Constants!$B$34,FALSE(),IF(AND(ISNUMBER(O11),OR(ISBLANK(N11),N11=0)),TRUE(),IF(AND(ISBLANK(O11),ISNUMBER(N11),N11<>0),FALSE(),""))))) | AR11: =IF(OR(ISBLANK($C11),$AL11<>TRUE()),"",IF(ISBLANK(L11),Constants!$B$35,MAX(0,MIN(Constants!$B$31,L11)))) | AS11: =IF(OR(ISBLANK($C11),$AL11<>TRUE()),"",IF(ISBLANK(M11),Constants!$B$35,MAX(0,MIN(Constants!$B$32,M11)))) | AT11: =IF(ISBLANK($C11),"",COUNTA($P11:$X11)>0) | AU11: =IF(OR(ISBLANK($C11),$AT11<>TRUE()),"",IF(ISBLANK(P11),Constants!$B$27,MAX(0,P11))) | AV11: =IF(OR(ISBLANK($C11),$AT11<>TRUE()),"",IF(ISBLANK(Q11),Constants!$B$28,MAX(0,Q11))) | AW11: =IF(OR(ISBLANK($C11),$AT11<>TRUE()),"",IF(S11=Constants!$B$7,TRUE(),IF(S11=Constants!$B$8,FALSE(),TRUE()))) | AX11: =IF(OR(ISBLANK($C11),$AT11<>TRUE()),"",IF(R11=Constants!$B$7,TRUE(),IF(R11=Constants!$B$8,FALSE(),TRUE()))) | AY11: =IF(OR(ISBLANK($C11),$AT11<>TRUE()),"",IF(T11=Constants!$B$33,TRUE(),IF(T11=Constants!$B$34,FALSE(),IF(AND(ISNUMBER(X11),OR(ISBLANK(W11),W11=0)),TRUE(),IF(AND(ISBLANK(X11),ISNUMBER(W11),W11<>0),FALSE(),""))))) | AZ11: =IF(OR(ISBLANK($C11),$AT11<>TRUE()),"",IF(ISBLANK(U11),Constants!$B$35,MAX(0,MIN(Constants!$B$31,U11)))) | BA11: =IF(OR(ISBLANK($C11),$AT11<>TRUE()),"",IF(ISBLANK(V11),Constants!$B$35,MAX(0,MIN(Constants!$B$32,V11)))) | BB11: =IF(ISBLANK($C11),"",COUNTA($Y11:$AG11)>0) | BC11: =IF(OR(ISBLANK($C11),$BB11<>TRUE()),"",IF(ISBLANK(Y11),Constants!$B$27,MAX(0,Y11))) | BD11: =IF(OR(ISBLANK($C11),$BB11<>TRUE()),"",IF(ISBLANK(Z11),Constants!$B$28,MAX(0,Z11))) | BE11: =IF(OR(ISBLANK($C11),$BB11<>TRUE()),"",IF(AB11=Constants!$B$7,TRUE(),IF(AB11=Constants!$B$8,FALSE(),TRUE()))) | BF11: =IF(OR(ISBLANK($C11),$BB11<>TRUE()),"",IF(AA11=Constants!$B$7,TRUE(),IF(AA11=Constants!$B$8,FALSE(),TRUE()))) | BG11: =IF(OR(ISBLANK($C11),$BB11<>TRUE()),"",IF(AC11=Constants!$B$33,TRUE(),IF(AC11=Constants!$B$34,FALSE(),IF(AND(ISNUMBER(AG11),OR(ISBLANK(AF11),AF11=0)),TRUE(),IF(AND(ISBLANK(AG11),ISNUMBER(AF11),AF11<>0),FALSE(),""))))) | BH11: =IF(OR(ISBLANK($C11),$BB11<>TRUE()),"",IF(ISBLANK(AD11),Constants!$B$35,MAX(0,MIN(Constants!$B$31,AD11)))) | BI11: =IF(OR(ISBLANK($C11),$BB11<>TRUE()),"",IF(ISBLANK(AE11),Constants!$B$35,MAX(0,MIN(Constants!$B$32,AE11)))) | BJ11: =IF(ISBLANK($C11), "", IF(AH11=Constants!$B$7, TRUE(), IF(AH11=Constants!$B$8, FALSE(), FALSE() ))) | BK11: =IF(ISBLANK($C11),"",IF($BJ11,Constants!$B$9,IF(COUNTA($E11:$AH11)=0,Constants!$B$10,IF(NOT($AK11),Constants!$B$11,IF(AND(NOT(ISNUMBER($BM11)),COUNTA($O11,$X11,$AG11)>0),Constants!$B$13,Constants!$B$12))))) | BL11: =IF(ISBLANK($C11),"",IF($BK11<>Constants!$B$12,$BK11,Constants!$B$4)) | BM11: =IF(OR(ISBLANK($D$8), NOT(ISNUMBER($D$8))), Constants!$B$17,$D$8) -> ERROR: Set Target Time in cell D8 | BN11: =IF(OR($BK11<>Constants!$B$12,$AL11<>TRUE()),"",IF(NOT($AO11),TRUE(),IF($AQ11="","",$AQ11))) | BO11: =IF(BN11="",FALSE(),IF(NOT($AO11),TRUE(),IF($AQ11,ISNUMBER(O11),ISNUMBER(N11)))) -> FALSE | BP11: =IF(BO11,IF($AJ11,1,Constants!$B$22)*POWER(Constants!$B$23,MAX($AM11,0))*POWER(Constants!$B$24,MAX($AN11,0)),"") | BQ11: =IF(OR($BK11<>Constants!$B$12,NOT($BO11)),"",IF(NOT($AO11),0,Constants!$B$19*IF($AQ11,1,MAX(0,MIN(1,(Constants!$B$20-N11)/Constants!$B$20))))) | BR11: =IF(BQ11="","",BQ11*IF($AP11,1,Constants!$B$25)*BP11) | BS11: =IF(OR($BK11<>Constants!$B$12,NOT($BO11)),"",IF(NOT($AO11),0,IF(NOT($AQ11),0,MAX(0,Constants!$B$21*(1-ABS(O11-$BM11)/$BM11))))) | BT11: =IF(BS11="","",BS11*BP11) | BU11: =IF(OR($BK11<>Constants!$B$12,NOT($BO11)),"",IF(OR(NOT($AO11),NOT($AP11)),0,MIN(Constants!$B$18,(Constants!$B$29*$AR11+Constants!$B$30*$AS11)*IF($AQ11,1,MAX(0,MIN(1,(Constants!$B$20-N11)/Constants!$B$20)))))) | BV11: =IF(BU11="","",BU11*BP11) | BW11: =IF(OR($BK11<>Constants!$B$12,NOT($BO11)),"",BR11+BT11+BV11) | BX11: =IF(OR($BK11<>Constants!$B$12,$AT11<>TRUE()),"",IF(NOT($AW11),TRUE(),IF($AY11="","",$AY11))) | BY11: =IF(BX11="",FALSE(),IF(NOT($AW11),TRUE(),IF($AY11,ISNUMBER(X11),ISNUMBER(W11)))) -> FALSE | BZ11: =IF(BY11,IF($AJ11,1,Constants!$B$22)*POWER(Constants!$B$23,MAX($AU11,0))*POWER(Constants!$B$24,MAX($AV11,0)),"") | CA11: =IF(OR($BK11<>Constants!$B$12,NOT($BY11)),"",IF(NOT($AW11),0,Constants!$B$19*IF($AY11,1,MAX(0,MIN(1,(Constants!$B$20-W11)/Constants!$B$20))))) | CB11: =IF(CA11="","",CA11*IF($AX11,1,Constants!$B$25)*BZ11) | CC11: =IF(OR($BK11<>Constants!$B$12,NOT($BY11)),"",IF(NOT($AW11),0,IF(NOT($AY11),0,MAX(0,Constants!$B$21*(1-ABS(X11-$BM11)/$BM11))))) | CD11: =IF(CC11="","",CC11*BZ11) | CE11: =IF(OR($BK11<>Constants!$B$12,NOT($BY11)),"",IF(OR(NOT($AW11),NOT($AX11)),0,MIN(Constants!$B$18,(Constants!$B$29*$AZ11+Constants!$B$30*$BA11)*IF($AY11,1,MAX(0,MIN(1,(Constants!$B$20-W11)/Constants!$B$20)))))) | CF11: =IF(CE11="","",CE11*BZ11) | CG11: =IF(OR($BK11<>Constants!$B$12,NOT($BY11)),"",CB11+CD11+CF11) | CH11: =IF(OR(BN11="",BX11=""),TRUE(),BN11<>BX11) -> TRUE | CI11: =IF(OR($BK11<>Constants!$B$12,$BB11<>TRUE(),NOT($CH11)),"",IF(NOT($BE11),TRUE(),IF($BG11="","",$BG11))) | CJ11: =IF(CI11="",FALSE(),IF(NOT($BE11),TRUE(),IF($BG11,ISNUMBER(AG11),ISNUMBER(AF11)))) -> FALSE | CK11: =IF(CJ11,IF($AJ11,1,Constants!$B$22)*POWER(Constants!$B$23,MAX($BC11,0))*POWER(Constants!$B$24,MAX($BD11,0)),"") | CL11: =IF(OR($BK11<>Constants!$B$12,NOT($CJ11)),"",IF(NOT($BE11),0,Constants!$B$19*IF($BG11,1,MAX(0,MIN(1,(Constants!$B$20-AF11)/Constants!$B$20))))) | CM11: =IF(CL11="","",CL11*IF($BF11,1,Constants!$B$25)*CK11) | CN11: =IF(OR($BK11<>Constants!$B$12,NOT($CJ11)),"",IF(NOT($BE11),0,IF(NOT($BG11),0,MAX(0,Constants!$B$21*(1-ABS(AG11-$BM11)/$BM11))))) | CO11: =IF(CN11="","",CN11*CK11) | CP11: =IF(OR($BK11<>Constants!$B$12,NOT($CJ11)),"",IF(OR(NOT($BE11),NOT($BF11)),0,MIN(Constants!$B$18,(Constants!$B$29*$BH11+Constants!$B$30*$BI11)*IF($BG11,1,MAX(0,MIN(1,(Constants!$B$20-AF11)/Constants!$B$20)))))) | CQ11: =IF(CP11="","",CP11*CK11) | CR11: =IF(OR($BK11<>Constants!$B$12,NOT($CJ11)),"",CM11+CO11+CQ11) | CS11: =IF(OR($BK11<>Constants!$B$12,ISBLANK($C11)),"",BW11) | CT11: =IF(OR($BK11<>Constants!$B$12,ISBLANK($C11)),"",CG11) | CU11: =IF(OR($BK11<>Constants!$B$12,ISBLANK($C11)),"",CR11) | CV11: =IF(OR($BK11<>Constants!$B$12,ISBLANK($C11)),"",IF(COUNT(CS11:CU11)=0,0,MAX(CS11:CU11))) | CW11: =IF($BK11<>Constants!$B$12,"",CV11) | CX11: =IF(ISNUMBER(CW11), RANK(CW11,$CW$11:$CW$510), "") | CY11: =IF(OR($BK11<>Constants!$B$12,ISBLANK($C11)),"",MAX(BT11,CD11,CO11)) | CZ11: =IF(ISNUMBER(CY11), RANK(CY11,CY$11:CY$510), "") | DA11: =IF(OR($BK11<>Constants!$B$12,ISBLANK($C11)),"",MAX(AM11,AU11,IF($CH11,BC11,0))) | DB11: =IF(ISNUMBER(DA11), RANK(DA11,DA$11:DA$510,1), "") | DC11: =IF(OR($BK11<>Constants!$B$12,ISBLANK($C11)),"",MAX(BV11,CF11,CQ11)) | DD11: =IF(ISNUMBER(DC11),RANK(DC11,DC$11:DC$510),"") | DE11: =IFERROR(IF(OR($BK11<>Constants!$B$12, ISBLANK($C11)),"",LARGE(CS11:CU11,2)), 0) | DF11: =IF(ISNUMBER(DE11), RANK(DE11,DE$11:DE$510), "") | DG11: =IF(ISBLANK($C11),"",IF(BK11=Constants!$B$12,RANK($CX11, $CX$11:$CX$510, 1)+ SUMPRODUCT(--($CX$11:$CX$510=$CX11),--($CZ11>$CZ$11:$CZ$510))+ SUMPRODUCT(--($CX$11:$CX$510=$CX11),--($CZ11=$CZ$11:$CZ$510),--($DB11>$DB$11:$DB$510))+ SUMPRODUCT(--($CX$11:$CX$510=$CX11),--($CZ11=$CZ$11:$CZ$510),--($DB11=$DB$11:$DB$510), --($DD11>$DD$11:$DD$510))+ SUMPRODUCT(--($CX$11:$CX$510=$CX11),--($CZ11=$CZ$11:$CZ$510),--($DB11=$DB$11:$DB$510), --($DD11=$DD$11:$DD$510), --($DF11>$DF$11:$DF$510)) ,BK11) ) | DH11: =IF(ISBLANK(C11),"",IF(BK11<>Constants!$B$12, BK11, CX11-DG11)) | DK11: =IF(ISBLANK($C11),"",IF($BK11=Constants!$B$13,$BM11,"")) | DL11: =IF(ISBLANK($C11),"",IF($BK11<>Constants!$B$12,"",IF(COUNT($CS11:$CU11)=0,"",MATCH($CV11,$CS11:$CU11,0)))) | DM11: =IF(ISNUMBER($DL11),CHOOSE($DL11,$BR11,$CB11,$CM11),"") | DN11: =IF(ISNUMBER($DL11),CHOOSE($DL11,$BT11,$CD11,$CO11),"") | DO11: =IF(ISNUMBER($DL11),CHOOSE($DL11,$BV11,$CF11,$CQ11),"") | DP11: =IF(ISBLANK(C11),"",IF(BK11<>Constants!$B$12, BK11 ,CW11)) | DQ11: =IF(ISBLANK($C11),"",IF($BK11<>Constants!$B$12,$BK11,$BL11)) | DR11: =IF(ISBLANK(C11),"",DH11) | DS11: =IF(ISBLANK(C11),"",DG11) | DT11: =IF(ISBLANK(C11), "", IF(DS11=Constants!$B$9,COUNTA($C$11:$C510)+2,IF(DS11=Constants!$B$10,COUNTA($C$11:$C510)+1,IF(DS11=Constants!$B$11,COUNTA($C$11:$C510),DS11)))) | DV11: =IF(OR(ISNUMBER(DS11),DS11="DQ",DS11="P",DS11="NS"), 1, 0 ) -> 0 | DW11: 1 | DX11: =IF(ISBLANK($C11),"",IF(ISNUMBER(DT11),DT11+ROW($B11)/1000,"")) | DY11: =IF(ISNUMBER(DX11), RANK(DX11,DX$11:DX$510,1), "") | DZ11: =IF(ISBLANK($C11), "", $B11 ) | EA11: =IF(ISBLANK($C11), "", $C11 ) | EB11: =IF(ISBLANK($C11), "", $D11 ) | EC11: =IF(ISBLANK($C11),"",$DQ11) | ED11: =DP11 | EE11: =IF(ISBLANK($C11), "", DS11 ) | EF11: =IF(DW11>DV$10, "", VLOOKUP(DW11,DY$11:EE510,7,FALSE()) ) | EG11: =IF(DW11>DV$10, "", VLOOKUP(DW11,DY$11:EE510,2,FALSE()) ) | EH11: =IF(DW11>DV$10, "", VLOOKUP(DW11,DY$11:EE510,3,FALSE()) ) | EI11: =IF(DW11>DV$10, "", VLOOKUP(DW11,DY$11:EE510,4,FALSE()) ) | EJ11: =IF(DW11>DV$10, "", VLOOKUP(DW11,DY$11:EE510,6,FALSE()) )
AJ12: =IF(ISBLANK($C12), "", IF(E12=Constants!$B$7, TRUE(), IF(E12=Constants!$B$8, FALSE(), TRUE() ))) | AK12: =IF(ISBLANK($C12),"",IF(F12=Constants!$B$8,FALSE(),TRUE())) | AL12: =IF(ISBLANK($C12),"",COUNTA($G12:$O12)>0) | AM12: =IF(OR(ISBLANK($C12),$AL12<>TRUE()),"",IF(ISBLANK(G12),Constants!$B$27,MAX(0,G12))) | AN12: =IF(OR(ISBLANK($C12),$AL12<>TRUE()),"",IF(ISBLANK(H12),Constants!$B$28,MAX(0,H12))) | AO12: =IF(OR(ISBLANK($C12),$AL12<>TRUE()),"",IF(J12=Constants!$B$7,TRUE(),IF(J12=Constants!$B$8,FALSE(),TRUE()))) | AP12: =IF(OR(ISBLANK($C12),$AL12<>TRUE()),"",IF(I12=Constants!$B$7,TRUE(),IF(I12=Constants!$B$8,FALSE(),TRUE()))) | AQ12: =IF(OR(ISBLANK($C12),$AL12<>TRUE()),"",IF(K12=Constants!$B$33,TRUE(),IF(K12=Constants!$B$34,FALSE(),IF(AND(ISNUMBER(O12),OR(ISBLANK(N12),N12=0)),TRUE(),IF(AND(ISBLANK(O12),ISNUMBER(N12),N12<>0),FALSE(),""))))) | AR12: =IF(OR(ISBLANK($C12),$AL12<>TRUE()),"",IF(ISBLANK(L12),Constants!$B$35,MAX(0,MIN(Constants!$B$31,L12)))) | AS12: =IF(OR(ISBLANK($C12),$AL12<>TRUE()),"",IF(ISBLANK(M12),Constants!$B$35,MAX(0,MIN(Constants!$B$32,M12)))) | AT12: =IF(ISBLANK($C12),"",COUNTA($P12:$X12)>0) | AU12: =IF(OR(ISBLANK($C12),$AT12<>TRUE()),"",IF(ISBLANK(P12),Constants!$B$27,MAX(0,P12))) | AV12: =IF(OR(ISBLANK($C12),$AT12<>TRUE()),"",IF(ISBLANK(Q12),Constants!$B$28,MAX(0,Q12))) | AW12: =IF(OR(ISBLANK($C12),$AT12<>TRUE()),"",IF(S12=Constants!$B$7,TRUE(),IF(S12=Constants!$B$8,FALSE(),TRUE()))) | AX12: =IF(OR(ISBLANK($C12),$AT12<>TRUE()),"",IF(R12=Constants!$B$7,TRUE(),IF(R12=Constants!$B$8,FALSE(),TRUE()))) | AY12: =IF(OR(ISBLANK($C12),$AT12<>TRUE()),"",IF(T12=Constants!$B$33,TRUE(),IF(T12=Constants!$B$34,FALSE(),IF(AND(ISNUMBER(X12),OR(ISBLANK(W12),W12=0)),TRUE(),IF(AND(ISBLANK(X12),ISNUMBER(W12),W12<>0),FALSE(),""))))) | AZ12: =IF(OR(ISBLANK($C12),$AT12<>TRUE()),"",IF(ISBLANK(U12),Constants!$B$35,MAX(0,MIN(Constants!$B$31,U12)))) | BA12: =IF(OR(ISBLANK($C12),$AT12<>TRUE()),"",IF(ISBLANK(V12),Constants!$B$35,MAX(0,MIN(Constants!$B$32,V12)))) | BB12: =IF(ISBLANK($C12),"",COUNTA($Y12:$AG12)>0) | BC12: =IF(OR(ISBLANK($C12),$BB12<>TRUE()),"",IF(ISBLANK(Y12),Constants!$B$27,MAX(0,Y12))) | BD12: =IF(OR(ISBLANK($C12),$BB12<>TRUE()),"",IF(ISBLANK(Z12),Constants!$B$28,MAX(0,Z12))) | BE12: =IF(OR(ISBLANK($C12),$BB12<>TRUE()),"",IF(AB12=Constants!$B$7,TRUE(),IF(AB12=Constants!$B$8,FALSE(),TRUE()))) | BF12: =IF(OR(ISBLANK($C12),$BB12<>TRUE()),"",IF(AA12=Constants!$B$7,TRUE(),IF(AA12=Constants!$B$8,FALSE(),TRUE()))) | BG12: =IF(OR(ISBLANK($C12),$BB12<>TRUE()),"",IF(AC12=Constants!$B$33,TRUE(),IF(AC12=Constants!$B$34,FALSE(),IF(AND(ISNUMBER(AG12),OR(ISBLANK(AF12),AF12=0)),TRUE(),IF(AND(ISBLANK(AG12),ISNUMBER(AF12),AF12<>0),FALSE(),""))))) | BH12: =IF(OR(ISBLANK($C12),$BB12<>TRUE()),"",IF(ISBLANK(AD12),Constants!$B$35,MAX(0,MIN(Constants!$B$31,AD12)))) | BI12: =IF(OR(ISBLANK($C12),$BB12<>TRUE()),"",IF(ISBLANK(AE12),Constants!$B$35,MAX(0,MIN(Constants!$B$32,AE12)))) | BJ12: =IF(ISBLANK($C12), "", IF(AH12=Constants!$B$7, TRUE(), IF(AH12=Constants!$B$8, FALSE(), FALSE() ))) | BK12: =IF(ISBLANK($C12),"",IF($BJ12,Constants!$B$9,IF(COUNTA($E12:$AH12)=0,Constants!$B$10,IF(NOT($AK12),Constants!$B$11,IF(AND(NOT(ISNUMBER($BM12)),COUNTA($O12,$X12,$AG12)>0),Constants!$B$13,Constants!$B$12))))) | BL12: =IF(ISBLANK($C12),"",IF($BK12<>Constants!$B$12,$BK12,Constants!$B$4)) | BM12: =IF(OR(ISBLANK($D$8), NOT(ISNUMBER($D$8))), Constants!$B$17,$D$8) -> ERROR: Set Target Time in cell D8 | BN12: =IF(OR($BK12<>Constants!$B$12,$AL12<>TRUE()),"",IF(NOT($AO12),TRUE(),IF($AQ12="","",$AQ12))) | BO12: =IF(BN12="",FALSE(),IF(NOT($AO12),TRUE(),IF($AQ12,ISNUMBER(O12),ISNUMBER(N12)))) -> FALSE | BP12: =IF(BO12,IF($AJ12,1,Constants!$B$22)*POWER(Constants!$B$23,MAX($AM12,0))*POWER(Constants!$B$24,MAX($AN12,0)),"") | BQ12: =IF(OR($BK12<>Constants!$B$12,NOT($BO12)),"",IF(NOT($AO12),0,Constants!$B$19*IF($AQ12,1,MAX(0,MIN(1,(Constants!$B$20-N12)/Constants!$B$20))))) | BR12: =IF(BQ12="","",BQ12*IF($AP12,1,Constants!$B$25)*BP12) | BS12: =IF(OR($BK12<>Constants!$B$12,NOT($BO12)),"",IF(NOT($AO12),0,IF(NOT($AQ12),0,MAX(0,Constants!$B$21*(1-ABS(O12-$BM12)/$BM12))))) | BT12: =IF(BS12="","",BS12*BP12) | BU12: =IF(OR($BK12<>Constants!$B$12,NOT($BO12)),"",IF(OR(NOT($AO12),NOT($AP12)),0,MIN(Constants!$B$18,(Constants!$B$29*$AR12+Constants!$B$30*$AS12)*IF($AQ12,1,MAX(0,MIN(1,(Constants!$B$20-N12)/Constants!$B$20)))))) | BV12: =IF(BU12="","",BU12*BP12) | BW12: =IF(OR($BK12<>Constants!$B$12,NOT($BO12)),"",BR12+BT12+BV12) | BX12: =IF(OR($BK12<>Constants!$B$12,$AT12<>TRUE()),"",IF(NOT($AW12),TRUE(),IF($AY12="","",$AY12))) | BY12: =IF(BX12="",FALSE(),IF(NOT($AW12),TRUE(),IF($AY12,ISNUMBER(X12),ISNUMBER(W12)))) -> FALSE | BZ12: =IF(BY12,IF($AJ12,1,Constants!$B$22)*POWER(Constants!$B$23,MAX($AU12,0))*POWER(Constants!$B$24,MAX($AV12,0)),"") | CA12: =IF(OR($BK12<>Constants!$B$12,NOT($BY12)),"",IF(NOT($AW12),0,Constants!$B$19*IF($AY12,1,MAX(0,MIN(1,(Constants!$B$20-W12)/Constants!$B$20))))) | CB12: =IF(CA12="","",CA12*IF($AX12,1,Constants!$B$25)*BZ12) | CC12: =IF(OR($BK12<>Constants!$B$12,NOT($BY12)),"",IF(NOT($AW12),0,IF(NOT($AY12),0,MAX(0,Constants!$B$21*(1-ABS(X12-$BM12)/$BM12))))) | CD12: =IF(CC12="","",CC12*BZ12) | CE12: =IF(OR($BK12<>Constants!$B$12,NOT($BY12)),"",IF(OR(NOT($AW12),NOT($AX12)),0,MIN(Constants!$B$18,(Constants!$B$29*$AZ12+Constants!$B$30*$BA12)*IF($AY12,1,MAX(0,MIN(1,(Constants!$B$20-W12)/Constants!$B$20)))))) | CF12: =IF(CE12="","",CE12*BZ12) | CG12: =IF(OR($BK12<>Constants!$B$12,NOT($BY12)),"",CB12+CD12+CF12) | CH12: =IF(OR(BN12="",BX12=""),TRUE(),BN12<>BX12) -> TRUE | CI12: =IF(OR($BK12<>Constants!$B$12,$BB12<>TRUE(),NOT($CH12)),"",IF(NOT($BE12),TRUE(),IF($BG12="","",$BG12))) | CJ12: =IF(CI12="",FALSE(),IF(NOT($BE12),TRUE(),IF($BG12,ISNUMBER(AG12),ISNUMBER(AF12)))) -> FALSE | CK12: =IF(CJ12,IF($AJ12,1,Constants!$B$22)*POWER(Constants!$B$23,MAX($BC12,0))*POWER(Constants!$B$24,MAX($BD12,0)),"") | CL12: =IF(OR($BK12<>Constants!$B$12,NOT($CJ12)),"",IF(NOT($BE12),0,Constants!$B$19*IF($BG12,1,MAX(0,MIN(1,(Constants!$B$20-AF12)/Constants!$B$20))))) | CM12: =IF(CL12="","",CL12*IF($BF12,1,Constants!$B$25)*CK12) | CN12: =IF(OR($BK12<>Constants!$B$12,NOT($CJ12)),"",IF(NOT($BE12),0,IF(NOT($BG12),0,MAX(0,Constants!$B$21*(1-ABS(AG12-$BM12)/$BM12))))) | CO12: =IF(CN12="","",CN12*CK12) | CP12: =IF(OR($BK12<>Constants!$B$12,NOT($CJ12)),"",IF(OR(NOT($BE12),NOT($BF12)),0,MIN(Constants!$B$18,(Constants!$B$29*$BH12+Constants!$B$30*$BI12)*IF($BG12,1,MAX(0,MIN(1,(Constants!$B$20-AF12)/Constants!$B$20)))))) | CQ12: =IF(CP12="","",CP12*CK12) | CR12: =IF(OR($BK12<>Constants!$B$12,NOT($CJ12)),"",CM12+CO12+CQ12) | CS12: =IF(OR($BK12<>Constants!$B$12,ISBLANK($C12)),"",BW12) | CT12: =IF(OR($BK12<>Constants!$B$12,ISBLANK($C12)),"",CG12) | CU12: =IF(OR($BK12<>Constants!$B$12,ISBLANK($C12)),"",CR12) | CV12: =IF(OR($BK12<>Constants!$B$12,ISBLANK($C12)),"",IF(COUNT(CS12:CU12)=0,0,MAX(CS12:CU12))) | CW12: =IF($BK12<>Constants!$B$12,"",CV12) | CX12: =IF(ISNUMBER(CW12), RANK(CW12,$CW$11:$CW$510), "") | CY12: =IF(OR($BK12<>Constants!$B$12,ISBLANK($C12)),"",MAX(BT12,CD12,CO12)) | CZ12: =IF(ISNUMBER(CY12), RANK(CY12,CY$11:CY$510), "") | DA12: =IF(OR($BK12<>Constants!$B$12,ISBLANK($C12)),"",MAX(AM12,AU12,IF($CH12,BC12,0))) | DB12: =IF(ISNUMBER(DA12), RANK(DA12,DA$11:DA$510,1), "") | DC12: =IF(OR($BK12<>Constants!$B$12,ISBLANK($C12)),"",MAX(BV12,CF12,CQ12)) | DD12: =IF(ISNUMBER(DC12),RANK(DC12,DC$11:DC$510),"") | DE12: =IFERROR(IF(OR($BK12<>Constants!$B$12, ISBLANK($C12)),"",LARGE(CS12:CU12,2)), 0) | DF12: =IF(ISNUMBER(DE12), RANK(DE12,DE$11:DE$510), "") | DG12: =IF(ISBLANK($C12),"",IF(BK12=Constants!$B$12,RANK($CX12, $CX$11:$CX$510, 1)+ SUMPRODUCT(--($CX$11:$CX$510=$CX12),--($CZ12>$CZ$11:$CZ$510))+ SUMPRODUCT(--($CX$11:$CX$510=$CX12),--($CZ12=$CZ$11:$CZ$510),--($DB12>$DB$11:$DB$510))+ SUMPRODUCT(--($CX$11:$CX$510=$CX12),--($CZ12=$CZ$11:$CZ$510),--($DB12=$DB$11:$DB$510), --($DD12>$DD$11:$DD$510))+ SUMPRODUCT(--($CX$11:$CX$510=$CX12),--($CZ12=$CZ$11:$CZ$510),--($DB12=$DB$11:$DB$510), --($DD12=$DD$11:$DD$510), --($DF12>$DF$11:$DF$510)) ,BK12) ) | DH12: =IF(ISBLANK(C12),"",IF(BK12<>Constants!$B$12, BK12, CX12-DG12)) | DK12: =IF(ISBLANK($C12),"",IF($BK12=Constants!$B$13,$BM12,"")) | DL12: =IF(ISBLANK($C12),"",IF($BK12<>Constants!$B$12,"",IF(COUNT($CS12:$CU12)=0,"",MATCH($CV12,$CS12:$CU12,0)))) | DM12: =IF(ISNUMBER($DL12),CHOOSE($DL12,$BR12,$CB12,$CM12),"") | DN12: =IF(ISNUMBER($DL12),CHOOSE($DL12,$BT12,$CD12,$CO12),"") | DO12: =IF(ISNUMBER($DL12),CHOOSE($DL12,$BV12,$CF12,$CQ12),"") | DP12: =IF(ISBLANK(C12),"",IF(BK12<>Constants!$B$12, BK12 ,CW12)) | DQ12: =IF(ISBLANK($C12),"",IF($BK12<>Constants!$B$12,$BK12,$BL12)) | DR12: =IF(ISBLANK(C12),"",DH12) | DS12: =IF(ISBLANK(C12),"",DG12) | DT12: =IF(ISBLANK(C12), "", IF(DS12=Constants!$B$9,COUNTA($C$11:$C510)+2,IF(DS12=Constants!$B$10,COUNTA($C$11:$C510)+1,IF(DS12=Constants!$B$11,COUNTA($C$11:$C510),DS12)))) | DV12: =IF(OR(ISNUMBER(DS12),DS12="DQ",DS12="P",DS12="NS"), 1, 0 ) -> 0 | DW12: 2 | DX12: =IF(ISBLANK($C12),"",IF(ISNUMBER(DT12),DT12+ROW($B12)/1000,"")) | DY12: =IF(ISNUMBER(DX12), RANK(DX12,DX$11:DX$510,1), "") | DZ12: =IF(ISBLANK($C12), "", $B12 ) | EA12: =IF(ISBLANK($C12), "", $C12 ) | EB12: =IF(ISBLANK($C12), "", $D12 ) | EC12: =IF(ISBLANK($C12),"",$DQ12) | ED12: =DP12 | EE12: =IF(ISBLANK($C12), "", DS12 ) | EF12: =IF(DW12>DV$10, "", VLOOKUP(DW12,DY$11:EE510,7,FALSE()) ) | EG12: =IF(DW12>DV$10, "", VLOOKUP(DW12,DY$11:EE510,2,FALSE()) ) | EH12: =IF(DW12>DV$10, "", VLOOKUP(DW12,DY$11:EE510,3,FALSE()) ) | EI12: =IF(DW12>DV$10, "", VLOOKUP(DW12,DY$11:EE510,4,FALSE()) ) | EJ12: =IF(DW12>DV$10, "", VLOOKUP(DW12,DY$11:EE510,6,FALSE()) )
AJ13: =IF(ISBLANK($C13), "", IF(E13=Constants!$B$7, TRUE(), IF(E13=Constants!$B$8, FALSE(), TRUE() ))) | AK13: =IF(ISBLANK($C13),"",IF(F13=Constants!$B$8,FALSE(),TRUE())) | AL13: =IF(ISBLANK($C13),"",COUNTA($G13:$O13)>0) | AM13: =IF(OR(ISBLANK($C13),$AL13<>TRUE()),"",IF(ISBLANK(G13),Constants!$B$27,MAX(0,G13))) | AN13: =IF(OR(ISBLANK($C13),$AL13<>TRUE()),"",IF(ISBLANK(H13),Constants!$B$28,MAX(0,H13))) | AO13: =IF(OR(ISBLANK($C13),$AL13<>TRUE()),"",IF(J13=Constants!$B$7,TRUE(),IF(J13=Constants!$B$8,FALSE(),TRUE()))) | AP13: =IF(OR(ISBLANK($C13),$AL13<>TRUE()),"",IF(I13=Constants!$B$7,TRUE(),IF(I13=Constants!$B$8,FALSE(),TRUE()))) | AQ13: =IF(OR(ISBLANK($C13),$AL13<>TRUE()),"",IF(K13=Constants!$B$33,TRUE(),IF(K13=Constants!$B$34,FALSE(),IF(AND(ISNUMBER(O13),OR(ISBLANK(N13),N13=0)),TRUE(),IF(AND(ISBLANK(O13),ISNUMBER(N13),N13<>0),FALSE(),""))))) | AR13: =IF(OR(ISBLANK($C13),$AL13<>TRUE()),"",IF(ISBLANK(L13),Constants!$B$35,MAX(0,MIN(Constants!$B$31,L13)))) | AS13: =IF(OR(ISBLANK($C13),$AL13<>TRUE()),"",IF(ISBLANK(M13),Constants!$B$35,MAX(0,MIN(Constants!$B$32,M13)))) | AT13: =IF(ISBLANK($C13),"",COUNTA($P13:$X13)>0) | AU13: =IF(OR(ISBLANK($C13),$AT13<>TRUE()),"",IF(ISBLANK(P13),Constants!$B$27,MAX(0,P13))) | AV13: =IF(OR(ISBLANK($C13),$AT13<>TRUE()),"",IF(ISBLANK(Q13),Constants!$B$28,MAX(0,Q13))) | AW13: =IF(OR(ISBLANK($C13),$AT13<>TRUE()),"",IF(S13=Constants!$B$7,TRUE(),IF(S13=Constants!$B$8,FALSE(),TRUE()))) | AX13: =IF(OR(ISBLANK($C13),$AT13<>TRUE()),"",IF(R13=Constants!$B$7,TRUE(),IF(R13=Constants!$B$8,FALSE(),TRUE()))) | AY13: =IF(OR(ISBLANK($C13),$AT13<>TRUE()),"",IF(T13=Constants!$B$33,TRUE(),IF(T13=Constants!$B$34,FALSE(),IF(AND(ISNUMBER(X13),OR(ISBLANK(W13),W13=0)),TRUE(),IF(AND(ISBLANK(X13),ISNUMBER(W13),W13<>0),FALSE(),""))))) | AZ13: =IF(OR(ISBLANK($C13),$AT13<>TRUE()),"",IF(ISBLANK(U13),Constants!$B$35,MAX(0,MIN(Constants!$B$31,U13)))) | BA13: =IF(OR(ISBLANK($C13),$AT13<>TRUE()),"",IF(ISBLANK(V13),Constants!$B$35,MAX(0,MIN(Constants!$B$32,V13)))) | BB13: =IF(ISBLANK($C13),"",COUNTA($Y13:$AG13)>0) | BC13: =IF(OR(ISBLANK($C13),$BB13<>TRUE()),"",IF(ISBLANK(Y13),Constants!$B$27,MAX(0,Y13))) | BD13: =IF(OR(ISBLANK($C13),$BB13<>TRUE()),"",IF(ISBLANK(Z13),Constants!$B$28,MAX(0,Z13))) | BE13: =IF(OR(ISBLANK($C13),$BB13<>TRUE()),"",IF(AB13=Constants!$B$7,TRUE(),IF(AB13=Constants!$B$8,FALSE(),TRUE()))) | BF13: =IF(OR(ISBLANK($C13),$BB13<>TRUE()),"",IF(AA13=Constants!$B$7,TRUE(),IF(AA13=Constants!$B$8,FALSE(),TRUE()))) | BG13: =IF(OR(ISBLANK($C13),$BB13<>TRUE()),"",IF(AC13=Constants!$B$33,TRUE(),IF(AC13=Constants!$B$34,FALSE(),IF(AND(ISNUMBER(AG13),OR(ISBLANK(AF13),AF13=0)),TRUE(),IF(AND(ISBLANK(AG13),ISNUMBER(AF13),AF13<>0),FALSE(),""))))) | BH13: =IF(OR(ISBLANK($C13),$BB13<>TRUE()),"",IF(ISBLANK(AD13),Constants!$B$35,MAX(0,MIN(Constants!$B$31,AD13)))) | BI13: =IF(OR(ISBLANK($C13),$BB13<>TRUE()),"",IF(ISBLANK(AE13),Constants!$B$35,MAX(0,MIN(Constants!$B$32,AE13)))) | BJ13: =IF(ISBLANK($C13), "", IF(AH13=Constants!$B$7, TRUE(), IF(AH13=Constants!$B$8, FALSE(), FALSE() ))) | BK13: =IF(ISBLANK($C13),"",IF($BJ13,Constants!$B$9,IF(COUNTA($E13:$AH13)=0,Constants!$B$10,IF(NOT($AK13),Constants!$B$11,IF(AND(NOT(ISNUMBER($BM13)),COUNTA($O13,$X13,$AG13)>0),Constants!$B$13,Constants!$B$12))))) | BL13: =IF(ISBLANK($C13),"",IF($BK13<>Constants!$B$12,$BK13,Constants!$B$4)) | BM13: =IF(OR(ISBLANK($D$8), NOT(ISNUMBER($D$8))), Constants!$B$17,$D$8) -> ERROR: Set Target Time in cell D8 | BN13: =IF(OR($BK13<>Constants!$B$12,$AL13<>TRUE()),"",IF(NOT($AO13),TRUE(),IF($AQ13="","",$AQ13))) | BO13: =IF(BN13="",FALSE(),IF(NOT($AO13),TRUE(),IF($AQ13,ISNUMBER(O13),ISNUMBER(N13)))) -> FALSE | BP13: =IF(BO13,IF($AJ13,1,Constants!$B$22)*POWER(Constants!$B$23,MAX($AM13,0))*POWER(Constants!$B$24,MAX($AN13,0)),"") | BQ13: =IF(OR($BK13<>Constants!$B$12,NOT($BO13)),"",IF(NOT($AO13),0,Constants!$B$19*IF($AQ13,1,MAX(0,MIN(1,(Constants!$B$20-N13)/Constants!$B$20))))) | BR13: =IF(BQ13="","",BQ13*IF($AP13,1,Constants!$B$25)*BP13) | BS13: =IF(OR($BK13<>Constants!$B$12,NOT($BO13)),"",IF(NOT($AO13),0,IF(NOT($AQ13),0,MAX(0,Constants!$B$21*(1-ABS(O13-$BM13)/$BM13))))) | BT13: =IF(BS13="","",BS13*BP13) | BU13: =IF(OR($BK13<>Constants!$B$12,NOT($BO13)),"",IF(OR(NOT($AO13),NOT($AP13)),0,MIN(Constants!$B$18,(Constants!$B$29*$AR13+Constants!$B$30*$AS13)*IF($AQ13,1,MAX(0,MIN(1,(Constants!$B$20-N13)/Constants!$B$20)))))) | BV13: =IF(BU13="","",BU13*BP13) | BW13: =IF(OR($BK13<>Constants!$B$12,NOT($BO13)),"",BR13+BT13+BV13) | BX13: =IF(OR($BK13<>Constants!$B$12,$AT13<>TRUE()),"",IF(NOT($AW13),TRUE(),IF($AY13="","",$AY13))) | BY13: =IF(BX13="",FALSE(),IF(NOT($AW13),TRUE(),IF($AY13,ISNUMBER(X13),ISNUMBER(W13)))) -> FALSE | BZ13: =IF(BY13,IF($AJ13,1,Constants!$B$22)*POWER(Constants!$B$23,MAX($AU13,0))*POWER(Constants!$B$24,MAX($AV13,0)),"") | CA13: =IF(OR($BK13<>Constants!$B$12,NOT($BY13)),"",IF(NOT($AW13),0,Constants!$B$19*IF($AY13,1,MAX(0,MIN(1,(Constants!$B$20-W13)/Constants!$B$20))))) | CB13: =IF(CA13="","",CA13*IF($AX13,1,Constants!$B$25)*BZ13) | CC13: =IF(OR($BK13<>Constants!$B$12,NOT($BY13)),"",IF(NOT($AW13),0,IF(NOT($AY13),0,MAX(0,Constants!$B$21*(1-ABS(X13-$BM13)/$BM13))))) | CD13: =IF(CC13="","",CC13*BZ13) | CE13: =IF(OR($BK13<>Constants!$B$12,NOT($BY13)),"",IF(OR(NOT($AW13),NOT($AX13)),0,MIN(Constants!$B$18,(Constants!$B$29*$AZ13+Constants!$B$30*$BA13)*IF($AY13,1,MAX(0,MIN(1,(Constants!$B$20-W13)/Constants!$B$20)))))) | CF13: =IF(CE13="","",CE13*BZ13) | CG13: =IF(OR($BK13<>Constants!$B$12,NOT($BY13)),"",CB13+CD13+CF13) | CH13: =IF(OR(BN13="",BX13=""),TRUE(),BN13<>BX13) -> TRUE | CI13: =IF(OR($BK13<>Constants!$B$12,$BB13<>TRUE(),NOT($CH13)),"",IF(NOT($BE13),TRUE(),IF($BG13="","",$BG13))) | CJ13: =IF(CI13="",FALSE(),IF(NOT($BE13),TRUE(),IF($BG13,ISNUMBER(AG13),ISNUMBER(AF13)))) -> FALSE | CK13: =IF(CJ13,IF($AJ13,1,Constants!$B$22)*POWER(Constants!$B$23,MAX($BC13,0))*POWER(Constants!$B$24,MAX($BD13,0)),"") | CL13: =IF(OR($BK13<>Constants!$B$12,NOT($CJ13)),"",IF(NOT($BE13),0,Constants!$B$19*IF($BG13,1,MAX(0,MIN(1,(Constants!$B$20-AF13)/Constants!$B$20))))) | CM13: =IF(CL13="","",CL13*IF($BF13,1,Constants!$B$25)*CK13) | CN13: =IF(OR($BK13<>Constants!$B$12,NOT($CJ13)),"",IF(NOT($BE13),0,IF(NOT($BG13),0,MAX(0,Constants!$B$21*(1-ABS(AG13-$BM13)/$BM13))))) | CO13: =IF(CN13="","",CN13*CK13) | CP13: =IF(OR($BK13<>Constants!$B$12,NOT($CJ13)),"",IF(OR(NOT($BE13),NOT($BF13)),0,MIN(Constants!$B$18,(Constants!$B$29*$BH13+Constants!$B$30*$BI13)*IF($BG13,1,MAX(0,MIN(1,(Constants!$B$20-AF13)/Constants!$B$20)))))) | CQ13: =IF(CP13="","",CP13*CK13) | CR13: =IF(OR($BK13<>Constants!$B$12,NOT($CJ13)),"",CM13+CO13+CQ13) | CS13: =IF(OR($BK13<>Constants!$B$12,ISBLANK($C13)),"",BW13) | CT13: =IF(OR($BK13<>Constants!$B$12,ISBLANK($C13)),"",CG13) | CU13: =IF(OR($BK13<>Constants!$B$12,ISBLANK($C13)),"",CR13) | CV13: =IF(OR($BK13<>Constants!$B$12,ISBLANK($C13)),"",IF(COUNT(CS13:CU13)=0,0,MAX(CS13:CU13))) | CW13: =IF($BK13<>Constants!$B$12,"",CV13) | CX13: =IF(ISNUMBER(CW13), RANK(CW13,$CW$11:$CW$510), "") | CY13: =IF(OR($BK13<>Constants!$B$12,ISBLANK($C13)),"",MAX(BT13,CD13,CO13)) | CZ13: =IF(ISNUMBER(CY13), RANK(CY13,CY$11:CY$510), "") | DA13: =IF(OR($BK13<>Constants!$B$12,ISBLANK($C13)),"",MAX(AM13,AU13,IF($CH13,BC13,0))) | DB13: =IF(ISNUMBER(DA13), RANK(DA13,DA$11:DA$510,1), "") | DC13: =IF(OR($BK13<>Constants!$B$12,ISBLANK($C13)),"",MAX(BV13,CF13,CQ13)) | DD13: =IF(ISNUMBER(DC13),RANK(DC13,DC$11:DC$510),"") | DE13: =IFERROR(IF(OR($BK13<>Constants!$B$12, ISBLANK($C13)),"",LARGE(CS13:CU13,2)), 0) | DF13: =IF(ISNUMBER(DE13), RANK(DE13,DE$11:DE$510), "") | DG13: =IF(ISBLANK($C13),"",IF(BK13=Constants!$B$12,RANK($CX13, $CX$11:$CX$510, 1)+ SUMPRODUCT(--($CX$11:$CX$510=$CX13),--($CZ13>$CZ$11:$CZ$510))+ SUMPRODUCT(--($CX$11:$CX$510=$CX13),--($CZ13=$CZ$11:$CZ$510),--($DB13>$DB$11:$DB$510))+ SUMPRODUCT(--($CX$11:$CX$510=$CX13),--($CZ13=$CZ$11:$CZ$510),--($DB13=$DB$11:$DB$510), --($DD13>$DD$11:$DD$510))+ SUMPRODUCT(--($CX$11:$CX$510=$CX13),--($CZ13=$CZ$11:$CZ$510),--($DB13=$DB$11:$DB$510), --($DD13=$DD$11:$DD$510), --($DF13>$DF$11:$DF$510)) ,BK13) ) | DH13: =IF(ISBLANK(C13),"",IF(BK13<>Constants!$B$12, BK13, CX13-DG13)) | DK13: =IF(ISBLANK($C13),"",IF($BK13=Constants!$B$13,$BM13,"")) | DL13: =IF(ISBLANK($C13),"",IF($BK13<>Constants!$B$12,"",IF(COUNT($CS13:$CU13)=0,"",MATCH($CV13,$CS13:$CU13,0)))) | DM13: =IF(ISNUMBER($DL13),CHOOSE($DL13,$BR13,$CB13,$CM13),"") | DN13: =IF(ISNUMBER($DL13),CHOOSE($DL13,$BT13,$CD13,$CO13),"") | DO13: =IF(ISNUMBER($DL13),CHOOSE($DL13,$BV13,$CF13,$CQ13),"") | DP13: =IF(ISBLANK(C13),"",IF(BK13<>Constants!$B$12, BK13 ,CW13)) | DQ13: =IF(ISBLANK($C13),"",IF($BK13<>Constants!$B$12,$BK13,$BL13)) | DR13: =IF(ISBLANK(C13),"",DH13) | DS13: =IF(ISBLANK(C13),"",DG13) | DT13: =IF(ISBLANK(C13), "", IF(DS13=Constants!$B$9,COUNTA($C$11:$C510)+2,IF(DS13=Constants!$B$10,COUNTA($C$11:$C510)+1,IF(DS13=Constants!$B$11,COUNTA($C$11:$C510),DS13)))) | DV13: =IF(OR(ISNUMBER(DS13),DS13="DQ",DS13="P",DS13="NS"), 1, 0 ) -> 0 | DW13: 3 | DX13: =IF(ISBLANK($C13),"",IF(ISNUMBER(DT13),DT13+ROW($B13)/1000,"")) | DY13: =IF(ISNUMBER(DX13), RANK(DX13,DX$11:DX$510,1), "") | DZ13: =IF(ISBLANK($C13), "", $B13 ) | EA13: =IF(ISBLANK($C13), "", $C13 ) | EB13: =IF(ISBLANK($C13), "", $D13 ) | EC13: =IF(ISBLANK($C13),"",$DQ13) | ED13: =DP13 | EE13: =IF(ISBLANK($C13), "", DS13 ) | EF13: =IF(DW13>DV$10, "", VLOOKUP(DW13,DY$11:EE511,7,FALSE()) ) | EG13: =IF(DW13>DV$10, "", VLOOKUP(DW13,DY$11:EE511,2,FALSE()) ) | EH13: =IF(DW13>DV$10, "", VLOOKUP(DW13,DY$11:EE511,3,FALSE()) ) | EI13: =IF(DW13>DV$10, "", VLOOKUP(DW13,DY$11:EE511,4,FALSE()) ) | EJ13: =IF(DW13>DV$10, "", VLOOKUP(DW13,DY$11:EE511,6,FALSE()) )
AJ14: =IF(ISBLANK($C14), "", IF(E14=Constants!$B$7, TRUE(), IF(E14=Constants!$B$8, FALSE(), TRUE() ))) | AK14: =IF(ISBLANK($C14),"",IF(F14=Constants!$B$8,FALSE(),TRUE())) | AL14: =IF(ISBLANK($C14),"",COUNTA($G14:$O14)>0) | AM14: =IF(OR(ISBLANK($C14),$AL14<>TRUE()),"",IF(ISBLANK(G14),Constants!$B$27,MAX(0,G14))) | AN14: =IF(OR(ISBLANK($C14),$AL14<>TRUE()),"",IF(ISBLANK(H14),Constants!$B$28,MAX(0,H14))) | AO14: =IF(OR(ISBLANK($C14),$AL14<>TRUE()),"",IF(J14=Constants!$B$7,TRUE(),IF(J14=Constants!$B$8,FALSE(),TRUE()))) | AP14: =IF(OR(ISBLANK($C14),$AL14<>TRUE()),"",IF(I14=Constants!$B$7,TRUE(),IF(I14=Constants!$B$8,FALSE(),TRUE()))) | AQ14: =IF(OR(ISBLANK($C14),$AL14<>TRUE()),"",IF(K14=Constants!$B$33,TRUE(),IF(K14=Constants!$B$34,FALSE(),IF(AND(ISNUMBER(O14),OR(ISBLANK(N14),N14=0)),TRUE(),IF(AND(ISBLANK(O14),ISNUMBER(N14),N14<>0),FALSE(),""))))) | AR14: =IF(OR(ISBLANK($C14),$AL14<>TRUE()),"",IF(ISBLANK(L14),Constants!$B$35,MAX(0,MIN(Constants!$B$31,L14)))) | AS14: =IF(OR(ISBLANK($C14),$AL14<>TRUE()),"",IF(ISBLANK(M14),Constants!$B$35,MAX(0,MIN(Constants!$B$32,M14)))) | AT14: =IF(ISBLANK($C14),"",COUNTA($P14:$X14)>0) | AU14: =IF(OR(ISBLANK($C14),$AT14<>TRUE()),"",IF(ISBLANK(P14),Constants!$B$27,MAX(0,P14))) | AV14: =IF(OR(ISBLANK($C14),$AT14<>TRUE()),"",IF(ISBLANK(Q14),Constants!$B$28,MAX(0,Q14))) | AW14: =IF(OR(ISBLANK($C14),$AT14<>TRUE()),"",IF(S14=Constants!$B$7,TRUE(),IF(S14=Constants!$B$8,FALSE(),TRUE()))) | AX14: =IF(OR(ISBLANK($C14),$AT14<>TRUE()),"",IF(R14=Constants!$B$7,TRUE(),IF(R14=Constants!$B$8,FALSE(),TRUE()))) | AY14: =IF(OR(ISBLANK($C14),$AT14<>TRUE()),"",IF(T14=Constants!$B$33,TRUE(),IF(T14=Constants!$B$34,FALSE(),IF(AND(ISNUMBER(X14),OR(ISBLANK(W14),W14=0)),TRUE(),IF(AND(ISBLANK(X14),ISNUMBER(W14),W14<>0),FALSE(),""))))) | AZ14: =IF(OR(ISBLANK($C14),$AT14<>TRUE()),"",IF(ISBLANK(U14),Constants!$B$35,MAX(0,MIN(Constants!$B$31,U14)))) | BA14: =IF(OR(ISBLANK($C14),$AT14<>TRUE()),"",IF(ISBLANK(V14),Constants!$B$35,MAX(0,MIN(Constants!$B$32,V14)))) | BB14: =IF(ISBLANK($C14),"",COUNTA($Y14:$AG14)>0) | BC14: =IF(OR(ISBLANK($C14),$BB14<>TRUE()),"",IF(ISBLANK(Y14),Constants!$B$27,MAX(0,Y14))) | BD14: =IF(OR(ISBLANK($C14),$BB14<>TRUE()),"",IF(ISBLANK(Z14),Constants!$B$28,MAX(0,Z14))) | BE14: =IF(OR(ISBLANK($C14),$BB14<>TRUE()),"",IF(AB14=Constants!$B$7,TRUE(),IF(AB14=Constants!$B$8,FALSE(),TRUE()))) | BF14: =IF(OR(ISBLANK($C14),$BB14<>TRUE()),"",IF(AA14=Constants!$B$7,TRUE(),IF(AA14=Constants!$B$8,FALSE(),TRUE()))) | BG14: =IF(OR(ISBLANK($C14),$BB14<>TRUE()),"",IF(AC14=Constants!$B$33,TRUE(),IF(AC14=Constants!$B$34,FALSE(),IF(AND(ISNUMBER(AG14),OR(ISBLANK(AF14),AF14=0)),TRUE(),IF(AND(ISBLANK(AG14),ISNUMBER(AF14),AF14<>0),FALSE(),""))))) | BH14: =IF(OR(ISBLANK($C14),$BB14<>TRUE()),"",IF(ISBLANK(AD14),Constants!$B$35,MAX(0,MIN(Constants!$B$31,AD14)))) | BI14: =IF(OR(ISBLANK($C14),$BB14<>TRUE()),"",IF(ISBLANK(AE14),Constants!$B$35,MAX(0,MIN(Constants!$B$32,AE14)))) | BJ14: =IF(ISBLANK($C14), "", IF(AH14=Constants!$B$7, TRUE(), IF(AH14=Constants!$B$8, FALSE(), FALSE() ))) | BK14: =IF(ISBLANK($C14),"",IF($BJ14,Constants!$B$9,IF(COUNTA($E14:$AH14)=0,Constants!$B$10,IF(NOT($AK14),Constants!$B$11,IF(AND(NOT(ISNUMBER($BM14)),COUNTA($O14,$X14,$AG14)>0),Constants!$B$13,Constants!$B$12))))) | BL14: =IF(ISBLANK($C14),"",IF($BK14<>Constants!$B$12,$BK14,Constants!$B$4)) | BM14: =IF(OR(ISBLANK($D$8), NOT(ISNUMBER($D$8))), Constants!$B$17,$D$8) -> ERROR: Set Target Time in cell D8 | BN14: =IF(OR($BK14<>Constants!$B$12,$AL14<>TRUE()),"",IF(NOT($AO14),TRUE(),IF($AQ14="","",$AQ14))) | BO14: =IF(BN14="",FALSE(),IF(NOT($AO14),TRUE(),IF($AQ14,ISNUMBER(O14),ISNUMBER(N14)))) -> 0 | BP14: =IF(BO14,IF($AJ14,1,Constants!$B$22)*POWER(Constants!$B$23,MAX($AM14,0))*POWER(Constants!$B$24,MAX($AN14,0)),"") | BQ14: =IF(OR($BK14<>Constants!$B$12,NOT($BO14)),"",IF(NOT($AO14),0,Constants!$B$19*IF($AQ14,1,MAX(0,MIN(1,(Constants!$B$20-N14)/Constants!$B$20))))) | BR14: =IF(BQ14="","",BQ14*IF($AP14,1,Constants!$B$25)*BP14) | BS14: =IF(OR($BK14<>Constants!$B$12,NOT($BO14)),"",IF(NOT($AO14),0,IF(NOT($AQ14),0,MAX(0,Constants!$B$21*(1-ABS(O14-$BM14)/$BM14))))) | BT14: =IF(BS14="","",BS14*BP14) | BU14: =IF(OR($BK14<>Constants!$B$12,NOT($BO14)),"",IF(OR(NOT($AO14),NOT($AP14)),0,MIN(Constants!$B$18,(Constants!$B$29*$AR14+Constants!$B$30*$AS14)*IF($AQ14,1,MAX(0,MIN(1,(Constants!$B$20-N14)/Constants!$B$20)))))) | BV14: =IF(BU14="","",BU14*BP14) | BW14: =IF(OR($BK14<>Constants!$B$12,NOT($BO14)),"",BR14+BT14+BV14) | BX14: =IF(OR($BK14<>Constants!$B$12,$AT14<>TRUE()),"",IF(NOT($AW14),TRUE(),IF($AY14="","",$AY14))) | BY14: =IF(BX14="",FALSE(),IF(NOT($AW14),TRUE(),IF($AY14,ISNUMBER(X14),ISNUMBER(W14)))) -> 0 | BZ14: =IF(BY14,IF($AJ14,1,Constants!$B$22)*POWER(Constants!$B$23,MAX($AU14,0))*POWER(Constants!$B$24,MAX($AV14,0)),"") | CA14: =IF(OR($BK14<>Constants!$B$12,NOT($BY14)),"",IF(NOT($AW14),0,Constants!$B$19*IF($AY14,1,MAX(0,MIN(1,(Constants!$B$20-W14)/Constants!$B$20))))) | CB14: =IF(CA14="","",CA14*IF($AX14,1,Constants!$B$25)*BZ14) | CC14: =IF(OR($BK14<>Constants!$B$12,NOT($BY14)),"",IF(NOT($AW14),0,IF(NOT($AY14),0,MAX(0,Constants!$B$21*(1-ABS(X14-$BM14)/$BM14))))) | CD14: =IF(CC14="","",CC14*BZ14) | CE14: =IF(OR($BK14<>Constants!$B$12,NOT($BY14)),"",IF(OR(NOT($AW14),NOT($AX14)),0,MIN(Constants!$B$18,(Constants!$B$29*$AZ14+Constants!$B$30*$BA14)*IF($AY14,1,MAX(0,MIN(1,(Constants!$B$20-W14)/Constants!$B$20)))))) | CF14: =IF(CE14="","",CE14*BZ14) | CG14: =IF(OR($BK14<>Constants!$B$12,NOT($BY14)),"",CB14+CD14+CF14) | CH14: =IF(OR(BN14="",BX14=""),TRUE(),BN14<>BX14) -> 1 | CI14: =IF(OR($BK14<>Constants!$B$12,$BB14<>TRUE(),NOT($CH14)),"",IF(NOT($BE14),TRUE(),IF($BG14="","",$BG14))) | CJ14: =IF(CI14="",FALSE(),IF(NOT($BE14),TRUE(),IF($BG14,ISNUMBER(AG14),ISNUMBER(AF14)))) -> 0 | CK14: =IF(CJ14,IF($AJ14,1,Constants!$B$22)*POWER(Constants!$B$23,MAX($BC14,0))*POWER(Constants!$B$24,MAX($BD14,0)),"") | CL14: =IF(OR($BK14<>Constants!$B$12,NOT($CJ14)),"",IF(NOT($BE14),0,Constants!$B$19*IF($BG14,1,MAX(0,MIN(1,(Constants!$B$20-AF14)/Constants!$B$20))))) | CM14: =IF(CL14="","",CL14*IF($BF14,1,Constants!$B$25)*CK14) | CN14: =IF(OR($BK14<>Constants!$B$12,NOT($CJ14)),"",IF(NOT($BE14),0,IF(NOT($BG14),0,MAX(0,Constants!$B$21*(1-ABS(AG14-$BM14)/$BM14))))) | CO14: =IF(CN14="","",CN14*CK14) | CP14: =IF(OR($BK14<>Constants!$B$12,NOT($CJ14)),"",IF(OR(NOT($BE14),NOT($BF14)),0,MIN(Constants!$B$18,(Constants!$B$29*$BH14+Constants!$B$30*$BI14)*IF($BG14,1,MAX(0,MIN(1,(Constants!$B$20-AF14)/Constants!$B$20)))))) | CQ14: =IF(CP14="","",CP14*CK14) | CR14: =IF(OR($BK14<>Constants!$B$12,NOT($CJ14)),"",CM14+CO14+CQ14) | CS14: =IF(OR($BK14<>Constants!$B$12,ISBLANK($C14)),"",BW14) | CT14: =IF(OR($BK14<>Constants!$B$12,ISBLANK($C14)),"",CG14) | CU14: =IF(OR($BK14<>Constants!$B$12,ISBLANK($C14)),"",CR14) | CV14: =IF(OR($BK14<>Constants!$B$12,ISBLANK($C14)),"",IF(COUNT(CS14:CU14)=0,0,MAX(CS14:CU14))) | CW14: =IF($BK14<>Constants!$B$12,"",CV14) | CX14: =IF(ISNUMBER(CW14), RANK(CW14,$CW$11:$CW$510), "") | CY14: =IF(OR($BK14<>Constants!$B$12,ISBLANK($C14)),"",MAX(BT14,CD14,CO14)) | CZ14: =IF(ISNUMBER(CY14), RANK(CY14,CY$11:CY$510), "") | DA14: =IF(OR($BK14<>Constants!$B$12,ISBLANK($C14)),"",MAX(AM14,AU14,IF($CH14,BC14,0))) | DB14: =IF(ISNUMBER(DA14), RANK(DA14,DA$11:DA$510,1), "") | DC14: =IF(OR($BK14<>Constants!$B$12,ISBLANK($C14)),"",MAX(BV14,CF14,CQ14)) | DD14: =IF(ISNUMBER(DC14),RANK(DC14,DC$11:DC$510),"") | DE14: =IFERROR(IF(OR($BK14<>Constants!$B$12, ISBLANK($C14)),"",LARGE(CS14:CU14,2)), 0) | DF14: =IF(ISNUMBER(DE14), RANK(DE14,DE$11:DE$510), "") | DG14: =IF(ISBLANK($C14),"",IF(BK14=Constants!$B$12,RANK($CX14, $CX$11:$CX$510, 1)+ SUMPRODUCT(--($CX$11:$CX$510=$CX14),--($CZ14>$CZ$11:$CZ$510))+ SUMPRODUCT(--($CX$11:$CX$510=$CX14),--($CZ14=$CZ$11:$CZ$510),--($DB14>$DB$11:$DB$510))+ SUMPRODUCT(--($CX$11:$CX$510=$CX14),--($CZ14=$CZ$11:$CZ$510),--($DB14=$DB$11:$DB$510), --($DD14>$DD$11:$DD$510))+ SUMPRODUCT(--($CX$11:$CX$510=$CX14),--($CZ14=$CZ$11:$CZ$510),--($DB14=$DB$11:$DB$510), --($DD14=$DD$11:$DD$510), --($DF14>$DF$11:$DF$510)) ,BK14) ) | DH14: =IF(ISBLANK(C14),"",IF(BK14<>Constants!$B$12, BK14, CX14-DG14)) | DK14: =IF(ISBLANK($C14),"",IF($BK14=Constants!$B$13,$BM14,"")) | DL14: =IF(ISBLANK($C14),"",IF($BK14<>Constants!$B$12,"",IF(COUNT($CS14:$CU14)=0,"",MATCH($CV14,$CS14:$CU14,0)))) | DM14: =IF(ISNUMBER($DL14),CHOOSE($DL14,$BR14,$CB14,$CM14),"") | DN14: =IF(ISNUMBER($DL14),CHOOSE($DL14,$BT14,$CD14,$CO14),"") | DO14: =IF(ISNUMBER($DL14),CHOOSE($DL14,$BV14,$CF14,$CQ14),"") | DP14: =IF(ISBLANK(C14),"",IF(BK14<>Constants!$B$12, BK14 ,CW14)) | DQ14: =IF(ISBLANK($C14),"",IF($BK14<>Constants!$B$12,$BK14,$BL14)) | DR14: =IF(ISBLANK(C14),"",DH14) | DS14: =IF(ISBLANK(C14),"",DG14) | DT14: =IF(ISBLANK(C14), "", IF(DS14=Constants!$B$9,COUNTA($C$11:$C510)+2,IF(DS14=Constants!$B$10,COUNTA($C$11:$C510)+1,IF(DS14=Constants!$B$11,COUNTA($C$11:$C510),DS14)))) | DV14: =IF(OR(ISNUMBER(DS14),DS14="DQ",DS14="P",DS14="NS"), 1, 0 ) -> 0 | DW14: 4 | DX14: =IF(ISBLANK($C14),"",IF(ISNUMBER(DT14),DT14+ROW($B14)/1000,"")) | DY14: =IF(ISNUMBER(DX14), RANK(DX14,DX$11:DX$510,1), "") | DZ14: =IF(ISBLANK($C14), "", $B14 ) | EA14: =IF(ISBLANK($C14), "", $C14 ) | EB14: =IF(ISBLANK($C14), "", $D14 ) | EC14: =IF(ISBLANK($C14),"",$DQ14) | ED14: =DP14 | EE14: =IF(ISBLANK($C14), "", DS14 ) | EF14: =IF(DW14>DV$10, "", VLOOKUP(DW14,DY$11:EE512,7,FALSE()) ) | EG14: =IF(DW14>DV$10, "", VLOOKUP(DW14,DY$11:EE512,2,FALSE()) ) | EH14: =IF(DW14>DV$10, "", VLOOKUP(DW14,DY$11:EE512,3,FALSE()) ) | EI14: =IF(DW14>DV$10, "", VLOOKUP(DW14,DY$11:EE512,4,FALSE()) ) | EJ14: =IF(DW14>DV$10, "", VLOOKUP(DW14,DY$11:EE512,6,FALSE()) )
AJ15: =IF(ISBLANK($C15), "", IF(E15=Constants!$B$7, TRUE(), IF(E15=Constants!$B$8, FALSE(), TRUE() ))) | AK15: =IF(ISBLANK($C15),"",IF(F15=Constants!$B$8,FALSE(),TRUE())) | AL15: =IF(ISBLANK($C15),"",COUNTA($G15:$O15)>0) | AM15: =IF(OR(ISBLANK($C15),$AL15<>TRUE()),"",IF(ISBLANK(G15),Constants!$B$27,MAX(0,G15))) | AN15: =IF(OR(ISBLANK($C15),$AL15<>TRUE()),"",IF(ISBLANK(H15),Constants!$B$28,MAX(0,H15))) | AO15: =IF(OR(ISBLANK($C15),$AL15<>TRUE()),"",IF(J15=Constants!$B$7,TRUE(),IF(J15=Constants!$B$8,FALSE(),TRUE()))) | AP15: =IF(OR(ISBLANK($C15),$AL15<>TRUE()),"",IF(I15=Constants!$B$7,TRUE(),IF(I15=Constants!$B$8,FALSE(),TRUE()))) | AQ15: =IF(OR(ISBLANK($C15),$AL15<>TRUE()),"",IF(K15=Constants!$B$33,TRUE(),IF(K15=Constants!$B$34,FALSE(),IF(AND(ISNUMBER(O15),OR(ISBLANK(N15),N15=0)),TRUE(),IF(AND(ISBLANK(O15),ISNUMBER(N15),N15<>0),FALSE(),""))))) | AR15: =IF(OR(ISBLANK($C15),$AL15<>TRUE()),"",IF(ISBLANK(L15),Constants!$B$35,MAX(0,MIN(Constants!$B$31,L15)))) | AS15: =IF(OR(ISBLANK($C15),$AL15<>TRUE()),"",IF(ISBLANK(M15),Constants!$B$35,MAX(0,MIN(Constants!$B$32,M15)))) | AT15: =IF(ISBLANK($C15),"",COUNTA($P15:$X15)>0) | AU15: =IF(OR(ISBLANK($C15),$AT15<>TRUE()),"",IF(ISBLANK(P15),Constants!$B$27,MAX(0,P15))) | AV15: =IF(OR(ISBLANK($C15),$AT15<>TRUE()),"",IF(ISBLANK(Q15),Constants!$B$28,MAX(0,Q15))) | AW15: =IF(OR(ISBLANK($C15),$AT15<>TRUE()),"",IF(S15=Constants!$B$7,TRUE(),IF(S15=Constants!$B$8,FALSE(),TRUE()))) | AX15: =IF(OR(ISBLANK($C15),$AT15<>TRUE()),"",IF(R15=Constants!$B$7,TRUE(),IF(R15=Constants!$B$8,FALSE(),TRUE()))) | AY15: =IF(OR(ISBLANK($C15),$AT15<>TRUE()),"",IF(T15=Constants!$B$33,TRUE(),IF(T15=Constants!$B$34,FALSE(),IF(AND(ISNUMBER(X15),OR(ISBLANK(W15),W15=0)),TRUE(),IF(AND(ISBLANK(X15),ISNUMBER(W15),W15<>0),FALSE(),""))))) | AZ15: =IF(OR(ISBLANK($C15),$AT15<>TRUE()),"",IF(ISBLANK(U15),Constants!$B$35,MAX(0,MIN(Constants!$B$31,U15)))) | BA15: =IF(OR(ISBLANK($C15),$AT15<>TRUE()),"",IF(ISBLANK(V15),Constants!$B$35,MAX(0,MIN(Constants!$B$32,V15)))) | BB15: =IF(ISBLANK($C15),"",COUNTA($Y15:$AG15)>0) | BC15: =IF(OR(ISBLANK($C15),$BB15<>TRUE()),"",IF(ISBLANK(Y15),Constants!$B$27,MAX(0,Y15))) | BD15: =IF(OR(ISBLANK($C15),$BB15<>TRUE()),"",IF(ISBLANK(Z15),Constants!$B$28,MAX(0,Z15))) | BE15: =IF(OR(ISBLANK($C15),$BB15<>TRUE()),"",IF(AB15=Constants!$B$7,TRUE(),IF(AB15=Constants!$B$8,FALSE(),TRUE()))) | BF15: =IF(OR(ISBLANK($C15),$BB15<>TRUE()),"",IF(AA15=Constants!$B$7,TRUE(),IF(AA15=Constants!$B$8,FALSE(),TRUE()))) | BG15: =IF(OR(ISBLANK($C15),$BB15<>TRUE()),"",IF(AC15=Constants!$B$33,TRUE(),IF(AC15=Constants!$B$34,FALSE(),IF(AND(ISNUMBER(AG15),OR(ISBLANK(AF15),AF15=0)),TRUE(),IF(AND(ISBLANK(AG15),ISNUMBER(AF15),AF15<>0),FALSE(),""))))) | BH15: =IF(OR(ISBLANK($C15),$BB15<>TRUE()),"",IF(ISBLANK(AD15),Constants!$B$35,MAX(0,MIN(Constants!$B$31,AD15)))) | BI15: =IF(OR(ISBLANK($C15),$BB15<>TRUE()),"",IF(ISBLANK(AE15),Constants!$B$35,MAX(0,MIN(Constants!$B$32,AE15)))) | BJ15: =IF(ISBLANK($C15), "", IF(AH15=Constants!$B$7, TRUE(), IF(AH15=Constants!$B$8, FALSE(), FALSE() ))) | BK15: =IF(ISBLANK($C15),"",IF($BJ15,Constants!$B$9,IF(COUNTA($E15:$AH15)=0,Constants!$B$10,IF(NOT($AK15),Constants!$B$11,IF(AND(NOT(ISNUMBER($BM15)),COUNTA($O15,$X15,$AG15)>0),Constants!$B$13,Constants!$B$12))))) | BL15: =IF(ISBLANK($C15),"",IF($BK15<>Constants!$B$12,$BK15,Constants!$B$4)) | BM15: =IF(OR(ISBLANK($D$8), NOT(ISNUMBER($D$8))), Constants!$B$17,$D$8) -> ERROR: Set Target Time in cell D8 | BN15: =IF(OR($BK15<>Constants!$B$12,$AL15<>TRUE()),"",IF(NOT($AO15),TRUE(),IF($AQ15="","",$AQ15))) | BO15: =IF(BN15="",FALSE(),IF(NOT($AO15),TRUE(),IF($AQ15,ISNUMBER(O15),ISNUMBER(N15)))) -> 0 | BP15: =IF(BO15,IF($AJ15,1,Constants!$B$22)*POWER(Constants!$B$23,MAX($AM15,0))*POWER(Constants!$B$24,MAX($AN15,0)),"") | BQ15: =IF(OR($BK15<>Constants!$B$12,NOT($BO15)),"",IF(NOT($AO15),0,Constants!$B$19*IF($AQ15,1,MAX(0,MIN(1,(Constants!$B$20-N15)/Constants!$B$20))))) | BR15: =IF(BQ15="","",BQ15*IF($AP15,1,Constants!$B$25)*BP15) | BS15: =IF(OR($BK15<>Constants!$B$12,NOT($BO15)),"",IF(NOT($AO15),0,IF(NOT($AQ15),0,MAX(0,Constants!$B$21*(1-ABS(O15-$BM15)/$BM15))))) | BT15: =IF(BS15="","",BS15*BP15) | BU15: =IF(OR($BK15<>Constants!$B$12,NOT($BO15)),"",IF(OR(NOT($AO15),NOT($AP15)),0,MIN(Constants!$B$18,(Constants!$B$29*$AR15+Constants!$B$30*$AS15)*IF($AQ15,1,MAX(0,MIN(1,(Constants!$B$20-N15)/Constants!$B$20)))))) | BV15: =IF(BU15="","",BU15*BP15) | BW15: =IF(OR($BK15<>Constants!$B$12,NOT($BO15)),"",BR15+BT15+BV15) | BX15: =IF(OR($BK15<>Constants!$B$12,$AT15<>TRUE()),"",IF(NOT($AW15),TRUE(),IF($AY15="","",$AY15))) | BY15: =IF(BX15="",FALSE(),IF(NOT($AW15),TRUE(),IF($AY15,ISNUMBER(X15),ISNUMBER(W15)))) -> 0 | BZ15: =IF(BY15,IF($AJ15,1,Constants!$B$22)*POWER(Constants!$B$23,MAX($AU15,0))*POWER(Constants!$B$24,MAX($AV15,0)),"") | CA15: =IF(OR($BK15<>Constants!$B$12,NOT($BY15)),"",IF(NOT($AW15),0,Constants!$B$19*IF($AY15,1,MAX(0,MIN(1,(Constants!$B$20-W15)/Constants!$B$20))))) | CB15: =IF(CA15="","",CA15*IF($AX15,1,Constants!$B$25)*BZ15) | CC15: =IF(OR($BK15<>Constants!$B$12,NOT($BY15)),"",IF(NOT($AW15),0,IF(NOT($AY15),0,MAX(0,Constants!$B$21*(1-ABS(X15-$BM15)/$BM15))))) | CD15: =IF(CC15="","",CC15*BZ15) | CE15: =IF(OR($BK15<>Constants!$B$12,NOT($BY15)),"",IF(OR(NOT($AW15),NOT($AX15)),0,MIN(Constants!$B$18,(Constants!$B$29*$AZ15+Constants!$B$30*$BA15)*IF($AY15,1,MAX(0,MIN(1,(Constants!$B$20-W15)/Constants!$B$20)))))) | CF15: =IF(CE15="","",CE15*BZ15) | CG15: =IF(OR($BK15<>Constants!$B$12,NOT($BY15)),"",CB15+CD15+CF15) | CH15: =IF(OR(BN15="",BX15=""),TRUE(),BN15<>BX15) -> 1 | CI15: =IF(OR($BK15<>Constants!$B$12,$BB15<>TRUE(),NOT($CH15)),"",IF(NOT($BE15),TRUE(),IF($BG15="","",$BG15))) | CJ15: =IF(CI15="",FALSE(),IF(NOT($BE15),TRUE(),IF($BG15,ISNUMBER(AG15),ISNUMBER(AF15)))) -> 0 | CK15: =IF(CJ15,IF($AJ15,1,Constants!$B$22)*POWER(Constants!$B$23,MAX($BC15,0))*POWER(Constants!$B$24,MAX($BD15,0)),"") | CL15: =IF(OR($BK15<>Constants!$B$12,NOT($CJ15)),"",IF(NOT($BE15),0,Constants!$B$19*IF($BG15,1,MAX(0,MIN(1,(Constants!$B$20-AF15)/Constants!$B$20))))) | CM15: =IF(CL15="","",CL15*IF($BF15,1,Constants!$B$25)*CK15) | CN15: =IF(OR($BK15<>Constants!$B$12,NOT($CJ15)),"",IF(NOT($BE15),0,IF(NOT($BG15),0,MAX(0,Constants!$B$21*(1-ABS(AG15-$BM15)/$BM15))))) | CO15: =IF(CN15="","",CN15*CK15) | CP15: =IF(OR($BK15<>Constants!$B$12,NOT($CJ15)),"",IF(OR(NOT($BE15),NOT($BF15)),0,MIN(Constants!$B$18,(Constants!$B$29*$BH15+Constants!$B$30*$BI15)*IF($BG15,1,MAX(0,MIN(1,(Constants!$B$20-AF15)/Constants!$B$20)))))) | CQ15: =IF(CP15="","",CP15*CK15) | CR15: =IF(OR($BK15<>Constants!$B$12,NOT($CJ15)),"",CM15+CO15+CQ15) | CS15: =IF(OR($BK15<>Constants!$B$12,ISBLANK($C15)),"",BW15) | CT15: =IF(OR($BK15<>Constants!$B$12,ISBLANK($C15)),"",CG15) | CU15: =IF(OR($BK15<>Constants!$B$12,ISBLANK($C15)),"",CR15) | CV15: =IF(OR($BK15<>Constants!$B$12,ISBLANK($C15)),"",IF(COUNT(CS15:CU15)=0,0,MAX(CS15:CU15))) | CW15: =IF($BK15<>Constants!$B$12,"",CV15) | CX15: =IF(ISNUMBER(CW15), RANK(CW15,$CW$11:$CW$510), "") | CY15: =IF(OR($BK15<>Constants!$B$12,ISBLANK($C15)),"",MAX(BT15,CD15,CO15)) | CZ15: =IF(ISNUMBER(CY15), RANK(CY15,CY$11:CY$510), "") | DA15: =IF(OR($BK15<>Constants!$B$12,ISBLANK($C15)),"",MAX(AM15,AU15,IF($CH15,BC15,0))) | DB15: =IF(ISNUMBER(DA15), RANK(DA15,DA$11:DA$510,1), "") | DC15: =IF(OR($BK15<>Constants!$B$12,ISBLANK($C15)),"",MAX(BV15,CF15,CQ15)) | DD15: =IF(ISNUMBER(DC15),RANK(DC15,DC$11:DC$510),"") | DE15: =IFERROR(IF(OR($BK15<>Constants!$B$12, ISBLANK($C15)),"",LARGE(CS15:CU15,2)), 0) | DF15: =IF(ISNUMBER(DE15), RANK(DE15,DE$11:DE$510), "") | DG15: =IF(ISBLANK($C15),"",IF(BK15=Constants!$B$12,RANK($CX15, $CX$11:$CX$510, 1)+ SUMPRODUCT(--($CX$11:$CX$510=$CX15),--($CZ15>$CZ$11:$CZ$510))+ SUMPRODUCT(--($CX$11:$CX$510=$CX15),--($CZ15=$CZ$11:$CZ$510),--($DB15>$DB$11:$DB$510))+ SUMPRODUCT(--($CX$11:$CX$510=$CX15),--($CZ15=$CZ$11:$CZ$510),--($DB15=$DB$11:$DB$510), --($DD15>$DD$11:$DD$510))+ SUMPRODUCT(--($CX$11:$CX$510=$CX15),--($CZ15=$CZ$11:$CZ$510),--($DB15=$DB$11:$DB$510), --($DD15=$DD$11:$DD$510), --($DF15>$DF$11:$DF$510)) ,BK15) ) | DH15: =IF(ISBLANK(C15),"",IF(BK15<>Constants!$B$12, BK15, CX15-DG15)) | DK15: =IF(ISBLANK($C15),"",IF($BK15=Constants!$B$13,$BM15,"")) | DL15: =IF(ISBLANK($C15),"",IF($BK15<>Constants!$B$12,"",IF(COUNT($CS15:$CU15)=0,"",MATCH($CV15,$CS15:$CU15,0)))) | DM15: =IF(ISNUMBER($DL15),CHOOSE($DL15,$BR15,$CB15,$CM15),"") | DN15: =IF(ISNUMBER($DL15),CHOOSE($DL15,$BT15,$CD15,$CO15),"") | DO15: =IF(ISNUMBER($DL15),CHOOSE($DL15,$BV15,$CF15,$CQ15),"") | DP15: =IF(ISBLANK(C15),"",IF(BK15<>Constants!$B$12, BK15 ,CW15)) | DQ15: =IF(ISBLANK($C15),"",IF($BK15<>Constants!$B$12,$BK15,$BL15)) | DR15: =IF(ISBLANK(C15),"",DH15) | DS15: =IF(ISBLANK(C15),"",DG15) | DT15: =IF(ISBLANK(C15), "", IF(DS15=Constants!$B$9,COUNTA($C$11:$C510)+2,IF(DS15=Constants!$B$10,COUNTA($C$11:$C510)+1,IF(DS15=Constants!$B$11,COUNTA($C$11:$C510),DS15)))) | DV15: =IF(OR(ISNUMBER(DS15),DS15="DQ",DS15="P",DS15="NS"), 1, 0 ) -> 0 | DW15: 5 | DX15: =IF(ISBLANK($C15),"",IF(ISNUMBER(DT15),DT15+ROW($B15)/1000,"")) | DY15: =IF(ISNUMBER(DX15), RANK(DX15,DX$11:DX$510,1), "") | DZ15: =IF(ISBLANK($C15), "", $B15 ) | EA15: =IF(ISBLANK($C15), "", $C15 ) | EB15: =IF(ISBLANK($C15), "", $D15 ) | EC15: =IF(ISBLANK($C15),"",$DQ15) | ED15: =DP15 | EE15: =IF(ISBLANK($C15), "", DS15 ) | EF15: =IF(DW15>DV$10, "", VLOOKUP(DW15,DY$11:EE513,7,FALSE()) ) | EG15: =IF(DW15>DV$10, "", VLOOKUP(DW15,DY$11:EE513,2,FALSE()) ) | EH15: =IF(DW15>DV$10, "", VLOOKUP(DW15,DY$11:EE513,3,FALSE()) ) | EI15: =IF(DW15>DV$10, "", VLOOKUP(DW15,DY$11:EE513,4,FALSE()) ) | EJ15: =IF(DW15>DV$10, "", VLOOKUP(DW15,DY$11:EE513,6,FALSE()) )
