Workbook

Sheet Scoring
B2: ='Info.'!B1&" "&'Info.'!B4 -> Mission Possible C | E2: Impound | G2: Check-In | P2: Set-Up and ASL | U2: Actions and Devices | AH2: Sanitised Inputs | BH2: Scoring | CS2: Breakdown | DG2: Rank for this team with row() bump | DH2: Rank for this team with same ranks split | DI2: Team Number of this team | DJ2: Name of this schoo | DK2: Name of this team | DL2: Tier for this Team | DM2: Score for this team | DN2: Actual Rank for this team | DO2: Final Rankings
E3: 1. State/Nats Only: Device Impounded (T/F) | F3: 2. ASL Impounded (T/F) | G3: 3. Eye Protection (T/F) | H3: 4. Device is safe (T/F) | I3: 5. Dimension 1 (cm) | J3: 6. Dimension 2 (cm) | K3: 7. Dimension 3 (cm) | L3: 8. Top & 2+ vertical walls transparent/open (T/F) | M3: 9. All const params met (T/F) | N3: 10. Not Remote Controlled (T/F) | O3: 11. Team able to answer questions (T/F) | P3: 12. <= 30 min to set up (T/F) | Q3: 13. State/Nats Only: <= 15 min to set up (T/F) | R3: 14. ASL proper format (T/F) | S3: 15. All actions included and accurate (T/F) | T3: 16. ASL # properly labelled (T/F) | U3: 17. Start Action (# of coins or Touch) | V3: 18. # of successful actions | W3: 19. Water Timer (sec) | X3: 20. No Touches leading to Final Action (T/F) | Y3: 21. Final Action Satisfied (T/F) | Z3: 22. Adjustments/Touches | AA3: 23. No electricity used after 30 s (T/F) | AB3: 24. No Solid/liquid leaving (T/F) | AC3: 25. Device Time (s) | AD3: 26. Disqualify (T/F) | AF3: Global: Target Time | AG3: Is valid Target Time? (copied as data validation script for D7) | AH3: =E3 -> 1. State/Nats Only: Device Impounded (T/F) | AI3: =F3 -> 2. ASL Impounded (T/F) | AJ3: =G3 -> 3. Eye Protection (T/F) | AK3: =H3 -> 4. Device is safe (T/F) | AL3: =I3 -> 5. Dimension 1 (cm) | AM3: =J3 -> 6. Dimension 2 (cm) | AN3: =K3 -> 7. Dimension 3 (cm) | AO3: =L3 -> 8. Top & 2+ vertical walls transparent/open (T/F) | ... BG3: =AD3 -> 26. Disqualify (T/F) | CS3: Set-Up & ASL | CT3: Actions | CU3: Time Score | CV3: Bonus | CW3: Device Size | CX3: Penalties | CY3: Score | CZ3: Tier | DA3: Tiebreaker | DB3: Rank | DC3: Points | DO3: Rank | DP3: Team # | DQ3: School Name | DR3: Team Name | DS3: Tier | DT3: Score
B4: ="Event Scoresheet - "&'Info.'!B5&IF('Info.'!B8="T"," The scoresheet has been updated; please download version v"&'Info.'!B7&" from soinc.org/scoresheets.","") -> Event Scoresheet - 2027
CI5: ERROR: Set Target Time in cell D7
B6: ="Last Updated: "&TEXT('Info.'!B2, "mm/dd/yyyy")&" (v"&'Info.'!B3&") Direct all questions to scoresheets@soinc.org." -> Last Updated: 09/27/2026 (v0.1.0) Direct all questions to scoresheets@soinc.org. | CI6: ERROR: Target Time in cell D7 must be a number
B7: Target Time (s): | BK7: Awards | BT7: Penalties (points deducted) | CB7: Ranking and Tiebreaks | CI7: Input Checks (Target Time message in row 5/6; other checks flag the red input cell)
B8: Team # | C8: School Name | D8: Team Name | BH8: Status | BI8: Tier | BJ8: Touches (box 22) | BK8: Set-Up Score | BL8: ASL Score | BM8: Start Action Score | BN8: Scorable Actions Score | BO8: Final Action Score | BP8: Time Score | BQ8: Water Timer Bonus | BR8: No Adjustments Bonus | BS8: Device Size Score | BT8: Overtime | BU8: Dimensions over 80 cm | BV8: Top/Walls not open | BW8: Touches | BX8: Solid/Liquid leaving | BY8: Electricity after 30 s | BZ8: Penalty Points (TB1) | CA8: Final Score | CB8: Score Rank | CC8: Rank (Tier, Score) | CD8: TB1 Rank | CE8: Device Size L+W+H (TB2) | CF8: TB2 Rank | CG8: Rank w/ TB | CH8: Rank Diff | CI8: Target Time Error | CJ8: Dimension Error | CK8: Start Action Error | CL8: Scorable Actions Error | CM8: Water Timer Error | CN8: Touches Error | CO8: Device Time Error | CR8: Errors | DE8: =SUM($DE$9:$DE$508) -> 0
AF9: =IF(ISNUMBER($D$7),$D$7,"") | AG9: =IF(ISBLANK($D$7),"",IF(NOT(ISNUMBER($D$7)),FALSE(),IF($D$7<Constants!$B$38,FALSE(),IF($D$7>Constants!$B$39,FALSE(),MOD($D$7,Constants!$B$40)=0)))) | AH9: =IF(ISBLANK($C9),"",IF($E9=Constants!$B$2,TRUE(),IF($E9=Constants!$B$3,FALSE(),TRUE()))) | AI9: =IF(ISBLANK($C9),"",IF($F9=Constants!$B$2,TRUE(),IF($F9=Constants!$B$3,FALSE(),FALSE()))) | AJ9: =IF(ISBLANK($C9),"",IF($G9=Constants!$B$2,TRUE(),IF($G9=Constants!$B$3,FALSE(),TRUE()))) | AK9: =IF(ISBLANK($C9),"",IF($H9=Constants!$B$2,TRUE(),IF($H9=Constants!$B$3,FALSE(),TRUE()))) | AL9: =IF(ISBLANK($C9),"",IF(ISNUMBER($I9),IF($I9>=0,$I9,""),"")) | AM9: =IF(ISBLANK($C9),"",IF(ISNUMBER($J9),IF($J9>=0,$J9,""),"")) | AN9: =IF(ISBLANK($C9),"",IF(ISNUMBER($K9),IF($K9>=0,$K9,""),"")) | AO9: =IF(ISBLANK($C9),"",IF($L9=Constants!$B$2,TRUE(),IF($L9=Constants!$B$3,FALSE(),TRUE()))) | AP9: =IF(ISBLANK($C9),"",IF($M9=Constants!$B$2,TRUE(),IF($M9=Constants!$B$3,FALSE(),TRUE()))) | AQ9: =IF(ISBLANK($C9),"",IF($N9=Constants!$B$2,TRUE(),IF($N9=Constants!$B$3,FALSE(),FALSE()))) | AR9: =IF(ISBLANK($C9),"",IF($O9=Constants!$B$2,TRUE(),IF($O9=Constants!$B$3,FALSE(),TRUE()))) | AS9: =IF(ISBLANK($C9),"",IF($P9=Constants!$B$2,TRUE(),IF($P9=Constants!$B$3,FALSE(),FALSE()))) | AT9: =IF(ISBLANK($C9),"",IF($Q9=Constants!$B$2,TRUE(),IF($Q9=Constants!$B$3,FALSE(),FALSE()))) | AU9: =IF(ISBLANK($C9),"",IF($R9=Constants!$B$2,TRUE(),IF($R9=Constants!$B$3,FALSE(),FALSE()))) | AV9: =IF(ISBLANK($C9),"",IF($S9=Constants!$B$2,TRUE(),IF($S9=Constants!$B$3,FALSE(),FALSE()))) | AW9: =IF(ISBLANK($C9),"",IF($T9=Constants!$B$2,TRUE(),IF($T9=Constants!$B$3,FALSE(),FALSE()))) | AX9: =IF(ISBLANK($C9),"",IF(OR($U9&""="1",$U9&""="2",$U9&""="3",$U9&""="4"),VALUE($U9&""),IF($U9=Constants!$B$12,Constants!$B$12,""))) | AY9: =IF(ISBLANK($C9),"",IF(ISBLANK($V9),0,IF(ISNUMBER($V9),IF(AND($V9>=0,$V9<=Constants!$B$21,$V9=INT($V9)),$V9,""),""))) | AZ9: =IF(ISBLANK($C9),"",IF(ISBLANK($W9),0,IF(ISNUMBER($W9),IF($W9>=0,$W9,""),""))) | BA9: =IF(ISBLANK($C9),"",IF($X9=Constants!$B$2,TRUE(),IF($X9=Constants!$B$3,FALSE(),TRUE()))) | BB9: =IF(ISBLANK($C9),"",IF($Y9=Constants!$B$2,TRUE(),IF($Y9=Constants!$B$3,FALSE(),FALSE()))) | BC9: =IF(ISBLANK($C9),"",IF(ISBLANK($Z9),0,IF(ISNUMBER($Z9),IF(AND($Z9>=0,$Z9<=Constants!$B$35,$Z9=INT($Z9)),$Z9,""),""))) | BD9: =IF(ISBLANK($C9),"",IF($AA9=Constants!$B$2,TRUE(),IF($AA9=Constants!$B$3,FALSE(),TRUE()))) | BE9: =IF(ISBLANK($C9),"",IF($AB9=Constants!$B$2,TRUE(),IF($AB9=Constants!$B$3,FALSE(),TRUE()))) | BF9: =IF(ISBLANK($C9),"",IF(ISNUMBER($AC9),IF($AC9>=0,$AC9,""),"")) | BG9: =IF(ISBLANK($C9),"",IF($AD9=Constants!$B$2,TRUE(),IF($AD9=Constants!$B$3,FALSE(),FALSE()))) | BH9: =IF(ISBLANK($C9),"",IF($BG9,Constants!$B$7,IF(COUNTA($E9:$AC9)=0,Constants!$B$6,IF(OR(COUNTA($G9:$AC9)=0,NOT($AK9),$AQ9),Constants!$B$5,IF(OR($CI9<>"",$CJ9,$CK9,$CL9,$CM9,$CN9,$CO9),Constants!$B$8,Constants!$B$4))))) | BI9: =IF(ISBLANK($C9),"",IF($BH9<>Constants!$B$4,$BH9,IF(OR(NOT($AH9),NOT($AJ9),NOT($AR9)),Constants!$B$11,IF(OR(NOT($AP9),MAX($AL9,$AM9,$AN9)>Constants!$B$30),Constants!$B$10,Constants!$B$9)))) | BJ9: =IF($BH9<>Constants!$B$4,"",IF(NOT($AJ9),0,MIN(Constants!$B$35,$BC9))) | BK9: =IF($BH9<>Constants!$B$4,"",IF(NOT($AJ9),0,IF($AT9,Constants!$B$18,IF($AS9,Constants!$B$17,0)))) | BL9: =IF($BH9<>Constants!$B$4,"",IF(NOT($AJ9),0,Constants!$B$19*($AI9+$AU9+$AV9+$AW9))) | BM9: =IF($BH9<>Constants!$B$4,"",IF(OR(NOT($AJ9),NOT(ISNUMBER($AX9))),0,CHOOSE($AX9,Constants!$B$13,Constants!$B$14,Constants!$B$15,Constants!$B$16))) | BN9: =IF($BH9<>Constants!$B$4,"",IF(NOT($AJ9),0,Constants!$B$20*$AY9)) | BO9: =IF($BH9<>Constants!$B$4,"",IF(AND($AJ9,$BA9,$BB9),Constants!$B$22,0)) | BP9: =IF($BH9<>Constants!$B$4,"",IF(OR(NOT($AJ9),NOT($BA9)),0,IF($BF9>=2*$AF$9,0,Constants!$B$23*INT(ROUND(MIN($BF9,$AF$9),6))))) | BQ9: =IF($BH9<>Constants!$B$4,"",IF(NOT($AJ9),0,Constants!$B$24*INT(ROUND(MIN($AZ9,$AF$9),6)))) | BR9: =IF($BH9<>Constants!$B$4,"",IF(AND($AJ9,$BJ9=0),Constants!$B$25,0)) | BS9: =IF($BH9<>Constants!$B$4,"",MIN(Constants!$B$29,MAX(0,Constants!$B$27*Constants!$B$28*INT(ROUND((Constants!$B$26-$AL9)/Constants!$B$28,6))))+MIN(Constants!$B$29,MAX(0,Constants!$B$27*Constants!$B$28*INT(ROUND((Constants!$B$26-$AM9)/Constants!$B$28,6))))+MIN(Constants!$B$29,MAX(0,Constants!$B$27*Constants!$B$28*INT(ROUND((Constants!$B$26-$AN9)/Constants!$B$28,6))))) | BT9: =IF($BH9<>Constants!$B$4,"",IF(NOT($AJ9),0,Constants!$B$31*INT(ROUND(MAX(0,MIN($BF9,2*$AF$9)-$AF$9),6)))) | BU9: =IF($BH9<>Constants!$B$4,"",Constants!$B$32*(($AL9>Constants!$B$26)+($AM9>Constants!$B$26)+($AN9>Constants!$B$26))) | BV9: =IF($BH9<>Constants!$B$4,"",IF(OR(NOT($AJ9),$AO9),0,Constants!$B$33)) | BW9: =IF($BH9<>Constants!$B$4,"",Constants!$B$34*$BJ9) | BX9: =IF($BH9<>Constants!$B$4,"",IF(OR(NOT($AJ9),$BE9),0,Constants!$B$36)) | BY9: =IF($BH9<>Constants!$B$4,"",IF(OR(NOT($AJ9),$BD9),0,Constants!$B$37)) | BZ9: =IF($BH9<>Constants!$B$4,"",SUM($BT9:$BY9)) | CA9: =IF(ISBLANK($C9),"",IF($BH9<>Constants!$B$4,$BH9,SUM($BK9:$BS9)-$BZ9)) | CB9: =IF(ISBLANK($C9),"",IF($BH9<>Constants!$B$4,$BH9,RANK($CA9,$CA$9:$CA$508))) | CC9: =IF(ISBLANK($C9),"",IF($BH9<>Constants!$B$4,$BH9,COUNTIFS($BI$9:$BI$508,"<"&$BI9)+COUNTIFS($BI$9:$BI$508,$BI9,$CB$9:$CB$508,"<"&$CB9)+1)) | CD9: =IF(ISBLANK($C9),"",IF($BH9<>Constants!$B$4,$BH9,RANK($BZ9,$BZ$9:$BZ$508,1))) | CE9: =IF($BH9<>Constants!$B$4,"",$AL9+$AM9+$AN9) | CF9: =IF(ISBLANK($C9),"",IF($BH9<>Constants!$B$4,$BH9,RANK($CE9,$CE$9:$CE$508,1))) | CG9: =IF(ISBLANK($C9),"",IF($BH9<>Constants!$B$4,$BH9,COUNTIFS($BI$9:$BI$508,"<"&$BI9)+COUNTIFS($BI$9:$BI$508,$BI9,$CB$9:$CB$508,"<"&$CB9)+COUNTIFS($BI$9:$BI$508,$BI9,$CB$9:$CB$508,$CB9,$CD$9:$CD$508,"<"&$CD9)+COUNTIFS($BI$9:$BI$508,$BI9,$CB$9:$CB$508,$CB9,$CD$9:$CD$508,$CD9,$CF$9:$CF$508,"<"&$CF9)+1)) | CH9: =IF(ISBLANK($C9),"",IF($BH9<>Constants!$B$4,$BH9,$CC9-$CG9)) | CI9: =IF(ISBLANK($C9),"",IF(NOT($AJ9),"",IF(ISBLANK($D$7),$CI$5,IF(NOT(ISNUMBER($D$7)),$CI$6,"")))) | CJ9: =IF(ISBLANK($C9),"",OR($AL9="",$AM9="",$AN9="")) | CK9: =IF(ISBLANK($C9),"",AND($AJ9,$AX9="")) | CL9: =IF(ISBLANK($C9),"",AND($AJ9,$AY9="")) | CM9: =IF(ISBLANK($C9),"",AND($AJ9,$AZ9="")) | CN9: =IF(ISBLANK($C9),"",AND($AJ9,$BC9="")) | CO9: =IF(ISBLANK($C9),"",AND($AJ9,$BF9="")) | CR9: =IF(ISBLANK($C9),"",IF($BH9=Constants!$B$8,$CI9,"")) | CS9: =IF(ISBLANK($C9),"",IF($BH9<>Constants!$B$4,"",$BK9+$BL9)) | CT9: =IF(ISBLANK($C9),"",IF($BH9<>Constants!$B$4,"",$BM9+$BN9+$BO9)) | CU9: =IF(ISBLANK($C9),"",IF($BH9<>Constants!$B$4,"",$BP9)) | CV9: =IF(ISBLANK($C9),"",IF($BH9<>Constants!$B$4,"",$BQ9+$BR9)) | CW9: =IF(ISBLANK($C9),"",IF($BH9<>Constants!$B$4,"",$BS9)) | CX9: =IF(ISBLANK($C9),"",IF($BH9<>Constants!$B$4,"",-$BZ9)) | CY9: =IF(ISBLANK($C9),"",$CA9) | CZ9: =IF(ISBLANK($C9),"",$BI9) | DA9: =IF(ISBLANK($C9),"",$CH9) | DB9: =IF(ISBLANK($C9),"",$CG9) | DC9: =IF(ISBLANK($C9),"",IFERROR(_xlfn.SWITCH($DB9,Constants!$B$7,COUNTA($C$9:$C$508)+2,Constants!$B$6,COUNTA($C$9:$C$508)+1,Constants!$B$5,COUNTA($C$9:$C$508)),$DB9)) | DE9: =IF(OR(ISNUMBER($DB9),$DB9=Constants!$B$7,$DB9=Constants!$B$5,$DB9=Constants!$B$6),1,0) -> 0 | DF9: 1 | DG9: =IF(ISBLANK($C9),"",IF(ISNUMBER($DC9),$DC9+ROW($B9)/1000,"")) | DH9: =IF(ISNUMBER($DG9),RANK($DG9,$DG$9:$DG$508,1),"") | DI9: =IF(ISBLANK($C9),"",$B9) | DJ9: =IF(ISBLANK($C9),"",$C9) | DK9: =IF(ISBLANK($C9),"",$D9) | DL9: =$CZ9 | DM9: =$CY9 | DN9: =IF(ISBLANK($C9),"",$DB9) | DO9: =IF($DF9>$DE$8,"",VLOOKUP($DF9,$DH$9:$DN$508,7,FALSE())) | DP9: =IF($DF9>$DE$8,"",VLOOKUP($DF9,$DH$9:$DN$508,2,FALSE())) | DQ9: =IF($DF9>$DE$8,"",VLOOKUP($DF9,$DH$9:$DN$508,3,FALSE())) | DR9: =IF($DF9>$DE$8,"",VLOOKUP($DF9,$DH$9:$DN$508,4,FALSE())) | DS9: =IF($DF9>$DE$8,"",VLOOKUP($DF9,$DH$9:$DN$508,5,FALSE())) | DT9: =IF($DF9>$DE$8,"",VLOOKUP($DF9,$DH$9:$DN$508,6,FALSE()))
AH10: =IF(ISBLANK($C10),"",IF($E10=Constants!$B$2,TRUE(),IF($E10=Constants!$B$3,FALSE(),TRUE()))) | AI10: =IF(ISBLANK($C10),"",IF($F10=Constants!$B$2,TRUE(),IF($F10=Constants!$B$3,FALSE(),FALSE()))) | AJ10: =IF(ISBLANK($C10),"",IF($G10=Constants!$B$2,TRUE(),IF($G10=Constants!$B$3,FALSE(),TRUE()))) | AK10: =IF(ISBLANK($C10),"",IF($H10=Constants!$B$2,TRUE(),IF($H10=Constants!$B$3,FALSE(),TRUE()))) | AL10: =IF(ISBLANK($C10),"",IF(ISNUMBER($I10),IF($I10>=0,$I10,""),"")) | AM10: =IF(ISBLANK($C10),"",IF(ISNUMBER($J10),IF($J10>=0,$J10,""),"")) | AN10: =IF(ISBLANK($C10),"",IF(ISNUMBER($K10),IF($K10>=0,$K10,""),"")) | AO10: =IF(ISBLANK($C10),"",IF($L10=Constants!$B$2,TRUE(),IF($L10=Constants!$B$3,FALSE(),TRUE()))) | AP10: =IF(ISBLANK($C10),"",IF($M10=Constants!$B$2,TRUE(),IF($M10=Constants!$B$3,FALSE(),TRUE()))) | AQ10: =IF(ISBLANK($C10),"",IF($N10=Constants!$B$2,TRUE(),IF($N10=Constants!$B$3,FALSE(),FALSE()))) | AR10: =IF(ISBLANK($C10),"",IF($O10=Constants!$B$2,TRUE(),IF($O10=Constants!$B$3,FALSE(),TRUE()))) | AS10: =IF(ISBLANK($C10),"",IF($P10=Constants!$B$2,TRUE(),IF($P10=Constants!$B$3,FALSE(),FALSE()))) | AT10: =IF(ISBLANK($C10),"",IF($Q10=Constants!$B$2,TRUE(),IF($Q10=Constants!$B$3,FALSE(),FALSE()))) | AU10: =IF(ISBLANK($C10),"",IF($R10=Constants!$B$2,TRUE(),IF($R10=Constants!$B$3,FALSE(),FALSE()))) | AV10: =IF(ISBLANK($C10),"",IF($S10=Constants!$B$2,TRUE(),IF($S10=Constants!$B$3,FALSE(),FALSE()))) | AW10: =IF(ISBLANK($C10),"",IF($T10=Constants!$B$2,TRUE(),IF($T10=Constants!$B$3,FALSE(),FALSE()))) | AX10: =IF(ISBLANK($C10),"",IF(OR($U10&""="1",$U10&""="2",$U10&""="3",$U10&""="4"),VALUE($U10&""),IF($U10=Constants!$B$12,Constants!$B$12,""))) | AY10: =IF(ISBLANK($C10),"",IF(ISBLANK($V10),0,IF(ISNUMBER($V10),IF(AND($V10>=0,$V10<=Constants!$B$21,$V10=INT($V10)),$V10,""),""))) | AZ10: =IF(ISBLANK($C10),"",IF(ISBLANK($W10),0,IF(ISNUMBER($W10),IF($W10>=0,$W10,""),""))) | BA10: =IF(ISBLANK($C10),"",IF($X10=Constants!$B$2,TRUE(),IF($X10=Constants!$B$3,FALSE(),TRUE()))) | BB10: =IF(ISBLANK($C10),"",IF($Y10=Constants!$B$2,TRUE(),IF($Y10=Constants!$B$3,FALSE(),FALSE()))) | BC10: =IF(ISBLANK($C10),"",IF(ISBLANK($Z10),0,IF(ISNUMBER($Z10),IF(AND($Z10>=0,$Z10<=Constants!$B$35,$Z10=INT($Z10)),$Z10,""),""))) | BD10: =IF(ISBLANK($C10),"",IF($AA10=Constants!$B$2,TRUE(),IF($AA10=Constants!$B$3,FALSE(),TRUE()))) | BE10: =IF(ISBLANK($C10),"",IF($AB10=Constants!$B$2,TRUE(),IF($AB10=Constants!$B$3,FALSE(),TRUE()))) | BF10: =IF(ISBLANK($C10),"",IF(ISNUMBER($AC10),IF($AC10>=0,$AC10,""),"")) | BG10: =IF(ISBLANK($C10),"",IF($AD10=Constants!$B$2,TRUE(),IF($AD10=Constants!$B$3,FALSE(),FALSE()))) | BH10: =IF(ISBLANK($C10),"",IF($BG10,Constants!$B$7,IF(COUNTA($E10:$AC10)=0,Constants!$B$6,IF(OR(COUNTA($G10:$AC10)=0,NOT($AK10),$AQ10),Constants!$B$5,IF(OR($CI10<>"",$CJ10,$CK10,$CL10,$CM10,$CN10,$CO10),Constants!$B$8,Constants!$B$4))))) | BI10: =IF(ISBLANK($C10),"",IF($BH10<>Constants!$B$4,$BH10,IF(OR(NOT($AH10),NOT($AJ10),NOT($AR10)),Constants!$B$11,IF(OR(NOT($AP10),MAX($AL10,$AM10,$AN10)>Constants!$B$30),Constants!$B$10,Constants!$B$9)))) | BJ10: =IF($BH10<>Constants!$B$4,"",IF(NOT($AJ10),0,MIN(Constants!$B$35,$BC10))) | BK10: =IF($BH10<>Constants!$B$4,"",IF(NOT($AJ10),0,IF($AT10,Constants!$B$18,IF($AS10,Constants!$B$17,0)))) | BL10: =IF($BH10<>Constants!$B$4,"",IF(NOT($AJ10),0,Constants!$B$19*($AI10+$AU10+$AV10+$AW10))) | BM10: =IF($BH10<>Constants!$B$4,"",IF(OR(NOT($AJ10),NOT(ISNUMBER($AX10))),0,CHOOSE($AX10,Constants!$B$13,Constants!$B$14,Constants!$B$15,Constants!$B$16))) | BN10: =IF($BH10<>Constants!$B$4,"",IF(NOT($AJ10),0,Constants!$B$20*$AY10)) | BO10: =IF($BH10<>Constants!$B$4,"",IF(AND($AJ10,$BA10,$BB10),Constants!$B$22,0)) | BP10: =IF($BH10<>Constants!$B$4,"",IF(OR(NOT($AJ10),NOT($BA10)),0,IF($BF10>=2*$AF$9,0,Constants!$B$23*INT(ROUND(MIN($BF10,$AF$9),6))))) | BQ10: =IF($BH10<>Constants!$B$4,"",IF(NOT($AJ10),0,Constants!$B$24*INT(ROUND(MIN($AZ10,$AF$9),6)))) | BR10: =IF($BH10<>Constants!$B$4,"",IF(AND($AJ10,$BJ10=0),Constants!$B$25,0)) | BS10: =IF($BH10<>Constants!$B$4,"",MIN(Constants!$B$29,MAX(0,Constants!$B$27*Constants!$B$28*INT(ROUND((Constants!$B$26-$AL10)/Constants!$B$28,6))))+MIN(Constants!$B$29,MAX(0,Constants!$B$27*Constants!$B$28*INT(ROUND((Constants!$B$26-$AM10)/Constants!$B$28,6))))+MIN(Constants!$B$29,MAX(0,Constants!$B$27*Constants!$B$28*INT(ROUND((Constants!$B$26-$AN10)/Constants!$B$28,6))))) | BT10: =IF($BH10<>Constants!$B$4,"",IF(NOT($AJ10),0,Constants!$B$31*INT(ROUND(MAX(0,MIN($BF10,2*$AF$9)-$AF$9),6)))) | BU10: =IF($BH10<>Constants!$B$4,"",Constants!$B$32*(($AL10>Constants!$B$26)+($AM10>Constants!$B$26)+($AN10>Constants!$B$26))) | BV10: =IF($BH10<>Constants!$B$4,"",IF(OR(NOT($AJ10),$AO10),0,Constants!$B$33)) | BW10: =IF($BH10<>Constants!$B$4,"",Constants!$B$34*$BJ10) | BX10: =IF($BH10<>Constants!$B$4,"",IF(OR(NOT($AJ10),$BE10),0,Constants!$B$36)) | BY10: =IF($BH10<>Constants!$B$4,"",IF(OR(NOT($AJ10),$BD10),0,Constants!$B$37)) | BZ10: =IF($BH10<>Constants!$B$4,"",SUM($BT10:$BY10)) | CA10: =IF(ISBLANK($C10),"",IF($BH10<>Constants!$B$4,$BH10,SUM($BK10:$BS10)-$BZ10)) | CB10: =IF(ISBLANK($C10),"",IF($BH10<>Constants!$B$4,$BH10,RANK($CA10,$CA$9:$CA$508))) | CC10: =IF(ISBLANK($C10),"",IF($BH10<>Constants!$B$4,$BH10,COUNTIFS($BI$9:$BI$508,"<"&$BI10)+COUNTIFS($BI$9:$BI$508,$BI10,$CB$9:$CB$508,"<"&$CB10)+1)) | CD10: =IF(ISBLANK($C10),"",IF($BH10<>Constants!$B$4,$BH10,RANK($BZ10,$BZ$9:$BZ$508,1))) | CE10: =IF($BH10<>Constants!$B$4,"",$AL10+$AM10+$AN10) | CF10: =IF(ISBLANK($C10),"",IF($BH10<>Constants!$B$4,$BH10,RANK($CE10,$CE$9:$CE$508,1))) | CG10: =IF(ISBLANK($C10),"",IF($BH10<>Constants!$B$4,$BH10,COUNTIFS($BI$9:$BI$508,"<"&$BI10)+COUNTIFS($BI$9:$BI$508,$BI10,$CB$9:$CB$508,"<"&$CB10)+COUNTIFS($BI$9:$BI$508,$BI10,$CB$9:$CB$508,$CB10,$CD$9:$CD$508,"<"&$CD10)+COUNTIFS($BI$9:$BI$508,$BI10,$CB$9:$CB$508,$CB10,$CD$9:$CD$508,$CD10,$CF$9:$CF$508,"<"&$CF10)+1)) | CH10: =IF(ISBLANK($C10),"",IF($BH10<>Constants!$B$4,$BH10,$CC10-$CG10)) | CI10: =IF(ISBLANK($C10),"",IF(NOT($AJ10),"",IF(ISBLANK($D$7),$CI$5,IF(NOT(ISNUMBER($D$7)),$CI$6,"")))) | CJ10: =IF(ISBLANK($C10),"",OR($AL10="",$AM10="",$AN10="")) | CK10: =IF(ISBLANK($C10),"",AND($AJ10,$AX10="")) | CL10: =IF(ISBLANK($C10),"",AND($AJ10,$AY10="")) | CM10: =IF(ISBLANK($C10),"",AND($AJ10,$AZ10="")) | CN10: =IF(ISBLANK($C10),"",AND($AJ10,$BC10="")) | CO10: =IF(ISBLANK($C10),"",AND($AJ10,$BF10="")) | CR10: =IF(ISBLANK($C10),"",IF($BH10=Constants!$B$8,$CI10,"")) | CS10: =IF(ISBLANK($C10),"",IF($BH10<>Constants!$B$4,"",$BK10+$BL10)) | CT10: =IF(ISBLANK($C10),"",IF($BH10<>Constants!$B$4,"",$BM10+$BN10+$BO10)) | CU10: =IF(ISBLANK($C10),"",IF($BH10<>Constants!$B$4,"",$BP10)) | CV10: =IF(ISBLANK($C10),"",IF($BH10<>Constants!$B$4,"",$BQ10+$BR10)) | CW10: =IF(ISBLANK($C10),"",IF($BH10<>Constants!$B$4,"",$BS10)) | CX10: =IF(ISBLANK($C10),"",IF($BH10<>Constants!$B$4,"",-$BZ10)) | CY10: =IF(ISBLANK($C10),"",$CA10) | CZ10: =IF(ISBLANK($C10),"",$BI10) | DA10: =IF(ISBLANK($C10),"",$CH10) | DB10: =IF(ISBLANK($C10),"",$CG10) | DC10: =IF(ISBLANK($C10),"",IFERROR(_xlfn.SWITCH($DB10,Constants!$B$7,COUNTA($C$9:$C$508)+2,Constants!$B$6,COUNTA($C$9:$C$508)+1,Constants!$B$5,COUNTA($C$9:$C$508)),$DB10)) | DE10: =IF(OR(ISNUMBER($DB10),$DB10=Constants!$B$7,$DB10=Constants!$B$5,$DB10=Constants!$B$6),1,0) -> 0 | DF10: 2 | DG10: =IF(ISBLANK($C10),"",IF(ISNUMBER($DC10),$DC10+ROW($B10)/1000,"")) | DH10: =IF(ISNUMBER($DG10),RANK($DG10,$DG$9:$DG$508,1),"") | DI10: =IF(ISBLANK($C10),"",$B10) | DJ10: =IF(ISBLANK($C10),"",$C10) | DK10: =IF(ISBLANK($C10),"",$D10) | DL10: =$CZ10 | DM10: =$CY10 | DN10: =IF(ISBLANK($C10),"",$DB10) | DO10: =IF($DF10>$DE$8,"",VLOOKUP($DF10,$DH$9:$DN$508,7,FALSE())) | DP10: =IF($DF10>$DE$8,"",VLOOKUP($DF10,$DH$9:$DN$508,2,FALSE())) | DQ10: =IF($DF10>$DE$8,"",VLOOKUP($DF10,$DH$9:$DN$508,3,FALSE())) | DR10: =IF($DF10>$DE$8,"",VLOOKUP($DF10,$DH$9:$DN$508,4,FALSE())) | DS10: =IF($DF10>$DE$8,"",VLOOKUP($DF10,$DH$9:$DN$508,5,FALSE())) | DT10: =IF($DF10>$DE$8,"",VLOOKUP($DF10,$DH$9:$DN$508,6,FALSE()))
AH11: =IF(ISBLANK($C11),"",IF($E11=Constants!$B$2,TRUE(),IF($E11=Constants!$B$3,FALSE(),TRUE()))) | AI11: =IF(ISBLANK($C11),"",IF($F11=Constants!$B$2,TRUE(),IF($F11=Constants!$B$3,FALSE(),FALSE()))) | AJ11: =IF(ISBLANK($C11),"",IF($G11=Constants!$B$2,TRUE(),IF($G11=Constants!$B$3,FALSE(),TRUE()))) | AK11: =IF(ISBLANK($C11),"",IF($H11=Constants!$B$2,TRUE(),IF($H11=Constants!$B$3,FALSE(),TRUE()))) | AL11: =IF(ISBLANK($C11),"",IF(ISNUMBER($I11),IF($I11>=0,$I11,""),"")) | AM11: =IF(ISBLANK($C11),"",IF(ISNUMBER($J11),IF($J11>=0,$J11,""),"")) | AN11: =IF(ISBLANK($C11),"",IF(ISNUMBER($K11),IF($K11>=0,$K11,""),"")) | AO11: =IF(ISBLANK($C11),"",IF($L11=Constants!$B$2,TRUE(),IF($L11=Constants!$B$3,FALSE(),TRUE()))) | AP11: =IF(ISBLANK($C11),"",IF($M11=Constants!$B$2,TRUE(),IF($M11=Constants!$B$3,FALSE(),TRUE()))) | AQ11: =IF(ISBLANK($C11),"",IF($N11=Constants!$B$2,TRUE(),IF($N11=Constants!$B$3,FALSE(),FALSE()))) | AR11: =IF(ISBLANK($C11),"",IF($O11=Constants!$B$2,TRUE(),IF($O11=Constants!$B$3,FALSE(),TRUE()))) | AS11: =IF(ISBLANK($C11),"",IF($P11=Constants!$B$2,TRUE(),IF($P11=Constants!$B$3,FALSE(),FALSE()))) | AT11: =IF(ISBLANK($C11),"",IF($Q11=Constants!$B$2,TRUE(),IF($Q11=Constants!$B$3,FALSE(),FALSE()))) | AU11: =IF(ISBLANK($C11),"",IF($R11=Constants!$B$2,TRUE(),IF($R11=Constants!$B$3,FALSE(),FALSE()))) | AV11: =IF(ISBLANK($C11),"",IF($S11=Constants!$B$2,TRUE(),IF($S11=Constants!$B$3,FALSE(),FALSE()))) | AW11: =IF(ISBLANK($C11),"",IF($T11=Constants!$B$2,TRUE(),IF($T11=Constants!$B$3,FALSE(),FALSE()))) | AX11: =IF(ISBLANK($C11),"",IF(OR($U11&""="1",$U11&""="2",$U11&""="3",$U11&""="4"),VALUE($U11&""),IF($U11=Constants!$B$12,Constants!$B$12,""))) | AY11: =IF(ISBLANK($C11),"",IF(ISBLANK($V11),0,IF(ISNUMBER($V11),IF(AND($V11>=0,$V11<=Constants!$B$21,$V11=INT($V11)),$V11,""),""))) | AZ11: =IF(ISBLANK($C11),"",IF(ISBLANK($W11),0,IF(ISNUMBER($W11),IF($W11>=0,$W11,""),""))) | BA11: =IF(ISBLANK($C11),"",IF($X11=Constants!$B$2,TRUE(),IF($X11=Constants!$B$3,FALSE(),TRUE()))) | BB11: =IF(ISBLANK($C11),"",IF($Y11=Constants!$B$2,TRUE(),IF($Y11=Constants!$B$3,FALSE(),FALSE()))) | BC11: =IF(ISBLANK($C11),"",IF(ISBLANK($Z11),0,IF(ISNUMBER($Z11),IF(AND($Z11>=0,$Z11<=Constants!$B$35,$Z11=INT($Z11)),$Z11,""),""))) | BD11: =IF(ISBLANK($C11),"",IF($AA11=Constants!$B$2,TRUE(),IF($AA11=Constants!$B$3,FALSE(),TRUE()))) | BE11: =IF(ISBLANK($C11),"",IF($AB11=Constants!$B$2,TRUE(),IF($AB11=Constants!$B$3,FALSE(),TRUE()))) | BF11: =IF(ISBLANK($C11),"",IF(ISNUMBER($AC11),IF($AC11>=0,$AC11,""),"")) | BG11: =IF(ISBLANK($C11),"",IF($AD11=Constants!$B$2,TRUE(),IF($AD11=Constants!$B$3,FALSE(),FALSE()))) | BH11: =IF(ISBLANK($C11),"",IF($BG11,Constants!$B$7,IF(COUNTA($E11:$AC11)=0,Constants!$B$6,IF(OR(COUNTA($G11:$AC11)=0,NOT($AK11),$AQ11),Constants!$B$5,IF(OR($CI11<>"",$CJ11,$CK11,$CL11,$CM11,$CN11,$CO11),Constants!$B$8,Constants!$B$4))))) | BI11: =IF(ISBLANK($C11),"",IF($BH11<>Constants!$B$4,$BH11,IF(OR(NOT($AH11),NOT($AJ11),NOT($AR11)),Constants!$B$11,IF(OR(NOT($AP11),MAX($AL11,$AM11,$AN11)>Constants!$B$30),Constants!$B$10,Constants!$B$9)))) | BJ11: =IF($BH11<>Constants!$B$4,"",IF(NOT($AJ11),0,MIN(Constants!$B$35,$BC11))) | BK11: =IF($BH11<>Constants!$B$4,"",IF(NOT($AJ11),0,IF($AT11,Constants!$B$18,IF($AS11,Constants!$B$17,0)))) | BL11: =IF($BH11<>Constants!$B$4,"",IF(NOT($AJ11),0,Constants!$B$19*($AI11+$AU11+$AV11+$AW11))) | BM11: =IF($BH11<>Constants!$B$4,"",IF(OR(NOT($AJ11),NOT(ISNUMBER($AX11))),0,CHOOSE($AX11,Constants!$B$13,Constants!$B$14,Constants!$B$15,Constants!$B$16))) | BN11: =IF($BH11<>Constants!$B$4,"",IF(NOT($AJ11),0,Constants!$B$20*$AY11)) | BO11: =IF($BH11<>Constants!$B$4,"",IF(AND($AJ11,$BA11,$BB11),Constants!$B$22,0)) | BP11: =IF($BH11<>Constants!$B$4,"",IF(OR(NOT($AJ11),NOT($BA11)),0,IF($BF11>=2*$AF$9,0,Constants!$B$23*INT(ROUND(MIN($BF11,$AF$9),6))))) | BQ11: =IF($BH11<>Constants!$B$4,"",IF(NOT($AJ11),0,Constants!$B$24*INT(ROUND(MIN($AZ11,$AF$9),6)))) | BR11: =IF($BH11<>Constants!$B$4,"",IF(AND($AJ11,$BJ11=0),Constants!$B$25,0)) | BS11: =IF($BH11<>Constants!$B$4,"",MIN(Constants!$B$29,MAX(0,Constants!$B$27*Constants!$B$28*INT(ROUND((Constants!$B$26-$AL11)/Constants!$B$28,6))))+MIN(Constants!$B$29,MAX(0,Constants!$B$27*Constants!$B$28*INT(ROUND((Constants!$B$26-$AM11)/Constants!$B$28,6))))+MIN(Constants!$B$29,MAX(0,Constants!$B$27*Constants!$B$28*INT(ROUND((Constants!$B$26-$AN11)/Constants!$B$28,6))))) | BT11: =IF($BH11<>Constants!$B$4,"",IF(NOT($AJ11),0,Constants!$B$31*INT(ROUND(MAX(0,MIN($BF11,2*$AF$9)-$AF$9),6)))) | BU11: =IF($BH11<>Constants!$B$4,"",Constants!$B$32*(($AL11>Constants!$B$26)+($AM11>Constants!$B$26)+($AN11>Constants!$B$26))) | BV11: =IF($BH11<>Constants!$B$4,"",IF(OR(NOT($AJ11),$AO11),0,Constants!$B$33)) | BW11: =IF($BH11<>Constants!$B$4,"",Constants!$B$34*$BJ11) | BX11: =IF($BH11<>Constants!$B$4,"",IF(OR(NOT($AJ11),$BE11),0,Constants!$B$36)) | BY11: =IF($BH11<>Constants!$B$4,"",IF(OR(NOT($AJ11),$BD11),0,Constants!$B$37)) | BZ11: =IF($BH11<>Constants!$B$4,"",SUM($BT11:$BY11)) | CA11: =IF(ISBLANK($C11),"",IF($BH11<>Constants!$B$4,$BH11,SUM($BK11:$BS11)-$BZ11)) | CB11: =IF(ISBLANK($C11),"",IF($BH11<>Constants!$B$4,$BH11,RANK($CA11,$CA$9:$CA$508))) | CC11: =IF(ISBLANK($C11),"",IF($BH11<>Constants!$B$4,$BH11,COUNTIFS($BI$9:$BI$508,"<"&$BI11)+COUNTIFS($BI$9:$BI$508,$BI11,$CB$9:$CB$508,"<"&$CB11)+1)) | CD11: =IF(ISBLANK($C11),"",IF($BH11<>Constants!$B$4,$BH11,RANK($BZ11,$BZ$9:$BZ$508,1))) | CE11: =IF($BH11<>Constants!$B$4,"",$AL11+$AM11+$AN11) | CF11: =IF(ISBLANK($C11),"",IF($BH11<>Constants!$B$4,$BH11,RANK($CE11,$CE$9:$CE$508,1))) | CG11: =IF(ISBLANK($C11),"",IF($BH11<>Constants!$B$4,$BH11,COUNTIFS($BI$9:$BI$508,"<"&$BI11)+COUNTIFS($BI$9:$BI$508,$BI11,$CB$9:$CB$508,"<"&$CB11)+COUNTIFS($BI$9:$BI$508,$BI11,$CB$9:$CB$508,$CB11,$CD$9:$CD$508,"<"&$CD11)+COUNTIFS($BI$9:$BI$508,$BI11,$CB$9:$CB$508,$CB11,$CD$9:$CD$508,$CD11,$CF$9:$CF$508,"<"&$CF11)+1)) | CH11: =IF(ISBLANK($C11),"",IF($BH11<>Constants!$B$4,$BH11,$CC11-$CG11)) | CI11: =IF(ISBLANK($C11),"",IF(NOT($AJ11),"",IF(ISBLANK($D$7),$CI$5,IF(NOT(ISNUMBER($D$7)),$CI$6,"")))) | CJ11: =IF(ISBLANK($C11),"",OR($AL11="",$AM11="",$AN11="")) | CK11: =IF(ISBLANK($C11),"",AND($AJ11,$AX11="")) | CL11: =IF(ISBLANK($C11),"",AND($AJ11,$AY11="")) | CM11: =IF(ISBLANK($C11),"",AND($AJ11,$AZ11="")) | CN11: =IF(ISBLANK($C11),"",AND($AJ11,$BC11="")) | CO11: =IF(ISBLANK($C11),"",AND($AJ11,$BF11="")) | CR11: =IF(ISBLANK($C11),"",IF($BH11=Constants!$B$8,$CI11,"")) | CS11: =IF(ISBLANK($C11),"",IF($BH11<>Constants!$B$4,"",$BK11+$BL11)) | CT11: =IF(ISBLANK($C11),"",IF($BH11<>Constants!$B$4,"",$BM11+$BN11+$BO11)) | CU11: =IF(ISBLANK($C11),"",IF($BH11<>Constants!$B$4,"",$BP11)) | CV11: =IF(ISBLANK($C11),"",IF($BH11<>Constants!$B$4,"",$BQ11+$BR11)) | CW11: =IF(ISBLANK($C11),"",IF($BH11<>Constants!$B$4,"",$BS11)) | CX11: =IF(ISBLANK($C11),"",IF($BH11<>Constants!$B$4,"",-$BZ11)) | CY11: =IF(ISBLANK($C11),"",$CA11) | CZ11: =IF(ISBLANK($C11),"",$BI11) | DA11: =IF(ISBLANK($C11),"",$CH11) | DB11: =IF(ISBLANK($C11),"",$CG11) | DC11: =IF(ISBLANK($C11),"",IFERROR(_xlfn.SWITCH($DB11,Constants!$B$7,COUNTA($C$9:$C$508)+2,Constants!$B$6,COUNTA($C$9:$C$508)+1,Constants!$B$5,COUNTA($C$9:$C$508)),$DB11)) | DE11: =IF(OR(ISNUMBER($DB11),$DB11=Constants!$B$7,$DB11=Constants!$B$5,$DB11=Constants!$B$6),1,0) -> 0 | DF11: 3 | DG11: =IF(ISBLANK($C11),"",IF(ISNUMBER($DC11),$DC11+ROW($B11)/1000,"")) | DH11: =IF(ISNUMBER($DG11),RANK($DG11,$DG$9:$DG$508,1),"") | DI11: =IF(ISBLANK($C11),"",$B11) | DJ11: =IF(ISBLANK($C11),"",$C11) | DK11: =IF(ISBLANK($C11),"",$D11) | DL11: =$CZ11 | DM11: =$CY11 | DN11: =IF(ISBLANK($C11),"",$DB11) | DO11: =IF($DF11>$DE$8,"",VLOOKUP($DF11,$DH$9:$DN$508,7,FALSE())) | DP11: =IF($DF11>$DE$8,"",VLOOKUP($DF11,$DH$9:$DN$508,2,FALSE())) | DQ11: =IF($DF11>$DE$8,"",VLOOKUP($DF11,$DH$9:$DN$508,3,FALSE())) | DR11: =IF($DF11>$DE$8,"",VLOOKUP($DF11,$DH$9:$DN$508,4,FALSE())) | DS11: =IF($DF11>$DE$8,"",VLOOKUP($DF11,$DH$9:$DN$508,5,FALSE())) | DT11: =IF($DF11>$DE$8,"",VLOOKUP($DF11,$DH$9:$DN$508,6,FALSE()))
AH12: =IF(ISBLANK($C12),"",IF($E12=Constants!$B$2,TRUE(),IF($E12=Constants!$B$3,FALSE(),TRUE()))) | AI12: =IF(ISBLANK($C12),"",IF($F12=Constants!$B$2,TRUE(),IF($F12=Constants!$B$3,FALSE(),FALSE()))) | AJ12: =IF(ISBLANK($C12),"",IF($G12=Constants!$B$2,TRUE(),IF($G12=Constants!$B$3,FALSE(),TRUE()))) | AK12: =IF(ISBLANK($C12),"",IF($H12=Constants!$B$2,TRUE(),IF($H12=Constants!$B$3,FALSE(),TRUE()))) | AL12: =IF(ISBLANK($C12),"",IF(ISNUMBER($I12),IF($I12>=0,$I12,""),"")) | AM12: =IF(ISBLANK($C12),"",IF(ISNUMBER($J12),IF($J12>=0,$J12,""),"")) | AN12: =IF(ISBLANK($C12),"",IF(ISNUMBER($K12),IF($K12>=0,$K12,""),"")) | AO12: =IF(ISBLANK($C12),"",IF($L12=Constants!$B$2,TRUE(),IF($L12=Constants!$B$3,FALSE(),TRUE()))) | AP12: =IF(ISBLANK($C12),"",IF($M12=Constants!$B$2,TRUE(),IF($M12=Constants!$B$3,FALSE(),TRUE()))) | AQ12: =IF(ISBLANK($C12),"",IF($N12=Constants!$B$2,TRUE(),IF($N12=Constants!$B$3,FALSE(),FALSE()))) | AR12: =IF(ISBLANK($C12),"",IF($O12=Constants!$B$2,TRUE(),IF($O12=Constants!$B$3,FALSE(),TRUE()))) | AS12: =IF(ISBLANK($C12),"",IF($P12=Constants!$B$2,TRUE(),IF($P12=Constants!$B$3,FALSE(),FALSE()))) | AT12: =IF(ISBLANK($C12),"",IF($Q12=Constants!$B$2,TRUE(),IF($Q12=Constants!$B$3,FALSE(),FALSE()))) | AU12: =IF(ISBLANK($C12),"",IF($R12=Constants!$B$2,TRUE(),IF($R12=Constants!$B$3,FALSE(),FALSE()))) | AV12: =IF(ISBLANK($C12),"",IF($S12=Constants!$B$2,TRUE(),IF($S12=Constants!$B$3,FALSE(),FALSE()))) | AW12: =IF(ISBLANK($C12),"",IF($T12=Constants!$B$2,TRUE(),IF($T12=Constants!$B$3,FALSE(),FALSE()))) | AX12: =IF(ISBLANK($C12),"",IF(OR($U12&""="1",$U12&""="2",$U12&""="3",$U12&""="4"),VALUE($U12&""),IF($U12=Constants!$B$12,Constants!$B$12,""))) | AY12: =IF(ISBLANK($C12),"",IF(ISBLANK($V12),0,IF(ISNUMBER($V12),IF(AND($V12>=0,$V12<=Constants!$B$21,$V12=INT($V12)),$V12,""),""))) | AZ12: =IF(ISBLANK($C12),"",IF(ISBLANK($W12),0,IF(ISNUMBER($W12),IF($W12>=0,$W12,""),""))) | BA12: =IF(ISBLANK($C12),"",IF($X12=Constants!$B$2,TRUE(),IF($X12=Constants!$B$3,FALSE(),TRUE()))) | BB12: =IF(ISBLANK($C12),"",IF($Y12=Constants!$B$2,TRUE(),IF($Y12=Constants!$B$3,FALSE(),FALSE()))) | BC12: =IF(ISBLANK($C12),"",IF(ISBLANK($Z12),0,IF(ISNUMBER($Z12),IF(AND($Z12>=0,$Z12<=Constants!$B$35,$Z12=INT($Z12)),$Z12,""),""))) | BD12: =IF(ISBLANK($C12),"",IF($AA12=Constants!$B$2,TRUE(),IF($AA12=Constants!$B$3,FALSE(),TRUE()))) | BE12: =IF(ISBLANK($C12),"",IF($AB12=Constants!$B$2,TRUE(),IF($AB12=Constants!$B$3,FALSE(),TRUE()))) | BF12: =IF(ISBLANK($C12),"",IF(ISNUMBER($AC12),IF($AC12>=0,$AC12,""),"")) | BG12: =IF(ISBLANK($C12),"",IF($AD12=Constants!$B$2,TRUE(),IF($AD12=Constants!$B$3,FALSE(),FALSE()))) | BH12: =IF(ISBLANK($C12),"",IF($BG12,Constants!$B$7,IF(COUNTA($E12:$AC12)=0,Constants!$B$6,IF(OR(COUNTA($G12:$AC12)=0,NOT($AK12),$AQ12),Constants!$B$5,IF(OR($CI12<>"",$CJ12,$CK12,$CL12,$CM12,$CN12,$CO12),Constants!$B$8,Constants!$B$4))))) | BI12: =IF(ISBLANK($C12),"",IF($BH12<>Constants!$B$4,$BH12,IF(OR(NOT($AH12),NOT($AJ12),NOT($AR12)),Constants!$B$11,IF(OR(NOT($AP12),MAX($AL12,$AM12,$AN12)>Constants!$B$30),Constants!$B$10,Constants!$B$9)))) | BJ12: =IF($BH12<>Constants!$B$4,"",IF(NOT($AJ12),0,MIN(Constants!$B$35,$BC12))) | BK12: =IF($BH12<>Constants!$B$4,"",IF(NOT($AJ12),0,IF($AT12,Constants!$B$18,IF($AS12,Constants!$B$17,0)))) | BL12: =IF($BH12<>Constants!$B$4,"",IF(NOT($AJ12),0,Constants!$B$19*($AI12+$AU12+$AV12+$AW12))) | BM12: =IF($BH12<>Constants!$B$4,"",IF(OR(NOT($AJ12),NOT(ISNUMBER($AX12))),0,CHOOSE($AX12,Constants!$B$13,Constants!$B$14,Constants!$B$15,Constants!$B$16))) | BN12: =IF($BH12<>Constants!$B$4,"",IF(NOT($AJ12),0,Constants!$B$20*$AY12)) | BO12: =IF($BH12<>Constants!$B$4,"",IF(AND($AJ12,$BA12,$BB12),Constants!$B$22,0)) | BP12: =IF($BH12<>Constants!$B$4,"",IF(OR(NOT($AJ12),NOT($BA12)),0,IF($BF12>=2*$AF$9,0,Constants!$B$23*INT(ROUND(MIN($BF12,$AF$9),6))))) | BQ12: =IF($BH12<>Constants!$B$4,"",IF(NOT($AJ12),0,Constants!$B$24*INT(ROUND(MIN($AZ12,$AF$9),6)))) | BR12: =IF($BH12<>Constants!$B$4,"",IF(AND($AJ12,$BJ12=0),Constants!$B$25,0)) | BS12: =IF($BH12<>Constants!$B$4,"",MIN(Constants!$B$29,MAX(0,Constants!$B$27*Constants!$B$28*INT(ROUND((Constants!$B$26-$AL12)/Constants!$B$28,6))))+MIN(Constants!$B$29,MAX(0,Constants!$B$27*Constants!$B$28*INT(ROUND((Constants!$B$26-$AM12)/Constants!$B$28,6))))+MIN(Constants!$B$29,MAX(0,Constants!$B$27*Constants!$B$28*INT(ROUND((Constants!$B$26-$AN12)/Constants!$B$28,6))))) | BT12: =IF($BH12<>Constants!$B$4,"",IF(NOT($AJ12),0,Constants!$B$31*INT(ROUND(MAX(0,MIN($BF12,2*$AF$9)-$AF$9),6)))) | BU12: =IF($BH12<>Constants!$B$4,"",Constants!$B$32*(($AL12>Constants!$B$26)+($AM12>Constants!$B$26)+($AN12>Constants!$B$26))) | BV12: =IF($BH12<>Constants!$B$4,"",IF(OR(NOT($AJ12),$AO12),0,Constants!$B$33)) | BW12: =IF($BH12<>Constants!$B$4,"",Constants!$B$34*$BJ12) | BX12: =IF($BH12<>Constants!$B$4,"",IF(OR(NOT($AJ12),$BE12),0,Constants!$B$36)) | BY12: =IF($BH12<>Constants!$B$4,"",IF(OR(NOT($AJ12),$BD12),0,Constants!$B$37)) | BZ12: =IF($BH12<>Constants!$B$4,"",SUM($BT12:$BY12)) | CA12: =IF(ISBLANK($C12),"",IF($BH12<>Constants!$B$4,$BH12,SUM($BK12:$BS12)-$BZ12)) | CB12: =IF(ISBLANK($C12),"",IF($BH12<>Constants!$B$4,$BH12,RANK($CA12,$CA$9:$CA$508))) | CC12: =IF(ISBLANK($C12),"",IF($BH12<>Constants!$B$4,$BH12,COUNTIFS($BI$9:$BI$508,"<"&$BI12)+COUNTIFS($BI$9:$BI$508,$BI12,$CB$9:$CB$508,"<"&$CB12)+1)) | CD12: =IF(ISBLANK($C12),"",IF($BH12<>Constants!$B$4,$BH12,RANK($BZ12,$BZ$9:$BZ$508,1))) | CE12: =IF($BH12<>Constants!$B$4,"",$AL12+$AM12+$AN12) | CF12: =IF(ISBLANK($C12),"",IF($BH12<>Constants!$B$4,$BH12,RANK($CE12,$CE$9:$CE$508,1))) | CG12: =IF(ISBLANK($C12),"",IF($BH12<>Constants!$B$4,$BH12,COUNTIFS($BI$9:$BI$508,"<"&$BI12)+COUNTIFS($BI$9:$BI$508,$BI12,$CB$9:$CB$508,"<"&$CB12)+COUNTIFS($BI$9:$BI$508,$BI12,$CB$9:$CB$508,$CB12,$CD$9:$CD$508,"<"&$CD12)+COUNTIFS($BI$9:$BI$508,$BI12,$CB$9:$CB$508,$CB12,$CD$9:$CD$508,$CD12,$CF$9:$CF$508,"<"&$CF12)+1)) | CH12: =IF(ISBLANK($C12),"",IF($BH12<>Constants!$B$4,$BH12,$CC12-$CG12)) | CI12: =IF(ISBLANK($C12),"",IF(NOT($AJ12),"",IF(ISBLANK($D$7),$CI$5,IF(NOT(ISNUMBER($D$7)),$CI$6,"")))) | CJ12: =IF(ISBLANK($C12),"",OR($AL12="",$AM12="",$AN12="")) | CK12: =IF(ISBLANK($C12),"",AND($AJ12,$AX12="")) | CL12: =IF(ISBLANK($C12),"",AND($AJ12,$AY12="")) | CM12: =IF(ISBLANK($C12),"",AND($AJ12,$AZ12="")) | CN12: =IF(ISBLANK($C12),"",AND($AJ12,$BC12="")) | CO12: =IF(ISBLANK($C12),"",AND($AJ12,$BF12="")) | CR12: =IF(ISBLANK($C12),"",IF($BH12=Constants!$B$8,$CI12,"")) | CS12: =IF(ISBLANK($C12),"",IF($BH12<>Constants!$B$4,"",$BK12+$BL12)) | CT12: =IF(ISBLANK($C12),"",IF($BH12<>Constants!$B$4,"",$BM12+$BN12+$BO12)) | CU12: =IF(ISBLANK($C12),"",IF($BH12<>Constants!$B$4,"",$BP12)) | CV12: =IF(ISBLANK($C12),"",IF($BH12<>Constants!$B$4,"",$BQ12+$BR12)) | CW12: =IF(ISBLANK($C12),"",IF($BH12<>Constants!$B$4,"",$BS12)) | CX12: =IF(ISBLANK($C12),"",IF($BH12<>Constants!$B$4,"",-$BZ12)) | CY12: =IF(ISBLANK($C12),"",$CA12) | CZ12: =IF(ISBLANK($C12),"",$BI12) | DA12: =IF(ISBLANK($C12),"",$CH12) | DB12: =IF(ISBLANK($C12),"",$CG12) | DC12: =IF(ISBLANK($C12),"",IFERROR(_xlfn.SWITCH($DB12,Constants!$B$7,COUNTA($C$9:$C$508)+2,Constants!$B$6,COUNTA($C$9:$C$508)+1,Constants!$B$5,COUNTA($C$9:$C$508)),$DB12)) | DE12: =IF(OR(ISNUMBER($DB12),$DB12=Constants!$B$7,$DB12=Constants!$B$5,$DB12=Constants!$B$6),1,0) -> 0 | DF12: 4 | DG12: =IF(ISBLANK($C12),"",IF(ISNUMBER($DC12),$DC12+ROW($B12)/1000,"")) | DH12: =IF(ISNUMBER($DG12),RANK($DG12,$DG$9:$DG$508,1),"") | DI12: =IF(ISBLANK($C12),"",$B12) | DJ12: =IF(ISBLANK($C12),"",$C12) | DK12: =IF(ISBLANK($C12),"",$D12) | DL12: =$CZ12 | DM12: =$CY12 | DN12: =IF(ISBLANK($C12),"",$DB12) | DO12: =IF($DF12>$DE$8,"",VLOOKUP($DF12,$DH$9:$DN$508,7,FALSE())) | DP12: =IF($DF12>$DE$8,"",VLOOKUP($DF12,$DH$9:$DN$508,2,FALSE())) | DQ12: =IF($DF12>$DE$8,"",VLOOKUP($DF12,$DH$9:$DN$508,3,FALSE())) | DR12: =IF($DF12>$DE$8,"",VLOOKUP($DF12,$DH$9:$DN$508,4,FALSE())) | DS12: =IF($DF12>$DE$8,"",VLOOKUP($DF12,$DH$9:$DN$508,5,FALSE())) | DT12: =IF($DF12>$DE$8,"",VLOOKUP($DF12,$DH$9:$DN$508,6,FALSE()))
AH13: =IF(ISBLANK($C13),"",IF($E13=Constants!$B$2,TRUE(),IF($E13=Constants!$B$3,FALSE(),TRUE()))) | AI13: =IF(ISBLANK($C13),"",IF($F13=Constants!$B$2,TRUE(),IF($F13=Constants!$B$3,FALSE(),FALSE()))) | AJ13: =IF(ISBLANK($C13),"",IF($G13=Constants!$B$2,TRUE(),IF($G13=Constants!$B$3,FALSE(),TRUE()))) | AK13: =IF(ISBLANK($C13),"",IF($H13=Constants!$B$2,TRUE(),IF($H13=Constants!$B$3,FALSE(),TRUE()))) | AL13: =IF(ISBLANK($C13),"",IF(ISNUMBER($I13),IF($I13>=0,$I13,""),"")) | AM13: =IF(ISBLANK($C13),"",IF(ISNUMBER($J13),IF($J13>=0,$J13,""),"")) | AN13: =IF(ISBLANK($C13),"",IF(ISNUMBER($K13),IF($K13>=0,$K13,""),"")) | AO13: =IF(ISBLANK($C13),"",IF($L13=Constants!$B$2,TRUE(),IF($L13=Constants!$B$3,FALSE(),TRUE()))) | AP13: =IF(ISBLANK($C13),"",IF($M13=Constants!$B$2,TRUE(),IF($M13=Constants!$B$3,FALSE(),TRUE()))) | AQ13: =IF(ISBLANK($C13),"",IF($N13=Constants!$B$2,TRUE(),IF($N13=Constants!$B$3,FALSE(),FALSE()))) | AR13: =IF(ISBLANK($C13),"",IF($O13=Constants!$B$2,TRUE(),IF($O13=Constants!$B$3,FALSE(),TRUE()))) | AS13: =IF(ISBLANK($C13),"",IF($P13=Constants!$B$2,TRUE(),IF($P13=Constants!$B$3,FALSE(),FALSE()))) | AT13: =IF(ISBLANK($C13),"",IF($Q13=Constants!$B$2,TRUE(),IF($Q13=Constants!$B$3,FALSE(),FALSE()))) | AU13: =IF(ISBLANK($C13),"",IF($R13=Constants!$B$2,TRUE(),IF($R13=Constants!$B$3,FALSE(),FALSE()))) | AV13: =IF(ISBLANK($C13),"",IF($S13=Constants!$B$2,TRUE(),IF($S13=Constants!$B$3,FALSE(),FALSE()))) | AW13: =IF(ISBLANK($C13),"",IF($T13=Constants!$B$2,TRUE(),IF($T13=Constants!$B$3,FALSE(),FALSE()))) | AX13: =IF(ISBLANK($C13),"",IF(OR($U13&""="1",$U13&""="2",$U13&""="3",$U13&""="4"),VALUE($U13&""),IF($U13=Constants!$B$12,Constants!$B$12,""))) | AY13: =IF(ISBLANK($C13),"",IF(ISBLANK($V13),0,IF(ISNUMBER($V13),IF(AND($V13>=0,$V13<=Constants!$B$21,$V13=INT($V13)),$V13,""),""))) | AZ13: =IF(ISBLANK($C13),"",IF(ISBLANK($W13),0,IF(ISNUMBER($W13),IF($W13>=0,$W13,""),""))) | BA13: =IF(ISBLANK($C13),"",IF($X13=Constants!$B$2,TRUE(),IF($X13=Constants!$B$3,FALSE(),TRUE()))) | BB13: =IF(ISBLANK($C13),"",IF($Y13=Constants!$B$2,TRUE(),IF($Y13=Constants!$B$3,FALSE(),FALSE()))) | BC13: =IF(ISBLANK($C13),"",IF(ISBLANK($Z13),0,IF(ISNUMBER($Z13),IF(AND($Z13>=0,$Z13<=Constants!$B$35,$Z13=INT($Z13)),$Z13,""),""))) | BD13: =IF(ISBLANK($C13),"",IF($AA13=Constants!$B$2,TRUE(),IF($AA13=Constants!$B$3,FALSE(),TRUE()))) | BE13: =IF(ISBLANK($C13),"",IF($AB13=Constants!$B$2,TRUE(),IF($AB13=Constants!$B$3,FALSE(),TRUE()))) | BF13: =IF(ISBLANK($C13),"",IF(ISNUMBER($AC13),IF($AC13>=0,$AC13,""),"")) | BG13: =IF(ISBLANK($C13),"",IF($AD13=Constants!$B$2,TRUE(),IF($AD13=Constants!$B$3,FALSE(),FALSE()))) | BH13: =IF(ISBLANK($C13),"",IF($BG13,Constants!$B$7,IF(COUNTA($E13:$AC13)=0,Constants!$B$6,IF(OR(COUNTA($G13:$AC13)=0,NOT($AK13),$AQ13),Constants!$B$5,IF(OR($CI13<>"",$CJ13,$CK13,$CL13,$CM13,$CN13,$CO13),Constants!$B$8,Constants!$B$4))))) | BI13: =IF(ISBLANK($C13),"",IF($BH13<>Constants!$B$4,$BH13,IF(OR(NOT($AH13),NOT($AJ13),NOT($AR13)),Constants!$B$11,IF(OR(NOT($AP13),MAX($AL13,$AM13,$AN13)>Constants!$B$30),Constants!$B$10,Constants!$B$9)))) | BJ13: =IF($BH13<>Constants!$B$4,"",IF(NOT($AJ13),0,MIN(Constants!$B$35,$BC13))) | BK13: =IF($BH13<>Constants!$B$4,"",IF(NOT($AJ13),0,IF($AT13,Constants!$B$18,IF($AS13,Constants!$B$17,0)))) | BL13: =IF($BH13<>Constants!$B$4,"",IF(NOT($AJ13),0,Constants!$B$19*($AI13+$AU13+$AV13+$AW13))) | BM13: =IF($BH13<>Constants!$B$4,"",IF(OR(NOT($AJ13),NOT(ISNUMBER($AX13))),0,CHOOSE($AX13,Constants!$B$13,Constants!$B$14,Constants!$B$15,Constants!$B$16))) | BN13: =IF($BH13<>Constants!$B$4,"",IF(NOT($AJ13),0,Constants!$B$20*$AY13)) | BO13: =IF($BH13<>Constants!$B$4,"",IF(AND($AJ13,$BA13,$BB13),Constants!$B$22,0)) | BP13: =IF($BH13<>Constants!$B$4,"",IF(OR(NOT($AJ13),NOT($BA13)),0,IF($BF13>=2*$AF$9,0,Constants!$B$23*INT(ROUND(MIN($BF13,$AF$9),6))))) | BQ13: =IF($BH13<>Constants!$B$4,"",IF(NOT($AJ13),0,Constants!$B$24*INT(ROUND(MIN($AZ13,$AF$9),6)))) | BR13: =IF($BH13<>Constants!$B$4,"",IF(AND($AJ13,$BJ13=0),Constants!$B$25,0)) | BS13: =IF($BH13<>Constants!$B$4,"",MIN(Constants!$B$29,MAX(0,Constants!$B$27*Constants!$B$28*INT(ROUND((Constants!$B$26-$AL13)/Constants!$B$28,6))))+MIN(Constants!$B$29,MAX(0,Constants!$B$27*Constants!$B$28*INT(ROUND((Constants!$B$26-$AM13)/Constants!$B$28,6))))+MIN(Constants!$B$29,MAX(0,Constants!$B$27*Constants!$B$28*INT(ROUND((Constants!$B$26-$AN13)/Constants!$B$28,6))))) | BT13: =IF($BH13<>Constants!$B$4,"",IF(NOT($AJ13),0,Constants!$B$31*INT(ROUND(MAX(0,MIN($BF13,2*$AF$9)-$AF$9),6)))) | BU13: =IF($BH13<>Constants!$B$4,"",Constants!$B$32*(($AL13>Constants!$B$26)+($AM13>Constants!$B$26)+($AN13>Constants!$B$26))) | BV13: =IF($BH13<>Constants!$B$4,"",IF(OR(NOT($AJ13),$AO13),0,Constants!$B$33)) | BW13: =IF($BH13<>Constants!$B$4,"",Constants!$B$34*$BJ13) | BX13: =IF($BH13<>Constants!$B$4,"",IF(OR(NOT($AJ13),$BE13),0,Constants!$B$36)) | BY13: =IF($BH13<>Constants!$B$4,"",IF(OR(NOT($AJ13),$BD13),0,Constants!$B$37)) | BZ13: =IF($BH13<>Constants!$B$4,"",SUM($BT13:$BY13)) | CA13: =IF(ISBLANK($C13),"",IF($BH13<>Constants!$B$4,$BH13,SUM($BK13:$BS13)-$BZ13)) | CB13: =IF(ISBLANK($C13),"",IF($BH13<>Constants!$B$4,$BH13,RANK($CA13,$CA$9:$CA$508))) | CC13: =IF(ISBLANK($C13),"",IF($BH13<>Constants!$B$4,$BH13,COUNTIFS($BI$9:$BI$508,"<"&$BI13)+COUNTIFS($BI$9:$BI$508,$BI13,$CB$9:$CB$508,"<"&$CB13)+1)) | CD13: =IF(ISBLANK($C13),"",IF($BH13<>Constants!$B$4,$BH13,RANK($BZ13,$BZ$9:$BZ$508,1))) | CE13: =IF($BH13<>Constants!$B$4,"",$AL13+$AM13+$AN13) | CF13: =IF(ISBLANK($C13),"",IF($BH13<>Constants!$B$4,$BH13,RANK($CE13,$CE$9:$CE$508,1))) | CG13: =IF(ISBLANK($C13),"",IF($BH13<>Constants!$B$4,$BH13,COUNTIFS($BI$9:$BI$508,"<"&$BI13)+COUNTIFS($BI$9:$BI$508,$BI13,$CB$9:$CB$508,"<"&$CB13)+COUNTIFS($BI$9:$BI$508,$BI13,$CB$9:$CB$508,$CB13,$CD$9:$CD$508,"<"&$CD13)+COUNTIFS($BI$9:$BI$508,$BI13,$CB$9:$CB$508,$CB13,$CD$9:$CD$508,$CD13,$CF$9:$CF$508,"<"&$CF13)+1)) | CH13: =IF(ISBLANK($C13),"",IF($BH13<>Constants!$B$4,$BH13,$CC13-$CG13)) | CI13: =IF(ISBLANK($C13),"",IF(NOT($AJ13),"",IF(ISBLANK($D$7),$CI$5,IF(NOT(ISNUMBER($D$7)),$CI$6,"")))) | CJ13: =IF(ISBLANK($C13),"",OR($AL13="",$AM13="",$AN13="")) | CK13: =IF(ISBLANK($C13),"",AND($AJ13,$AX13="")) | CL13: =IF(ISBLANK($C13),"",AND($AJ13,$AY13="")) | CM13: =IF(ISBLANK($C13),"",AND($AJ13,$AZ13="")) | CN13: =IF(ISBLANK($C13),"",AND($AJ13,$BC13="")) | CO13: =IF(ISBLANK($C13),"",AND($AJ13,$BF13="")) | CR13: =IF(ISBLANK($C13),"",IF($BH13=Constants!$B$8,$CI13,"")) | CS13: =IF(ISBLANK($C13),"",IF($BH13<>Constants!$B$4,"",$BK13+$BL13)) | CT13: =IF(ISBLANK($C13),"",IF($BH13<>Constants!$B$4,"",$BM13+$BN13+$BO13)) | CU13: =IF(ISBLANK($C13),"",IF($BH13<>Constants!$B$4,"",$BP13)) | CV13: =IF(ISBLANK($C13),"",IF($BH13<>Constants!$B$4,"",$BQ13+$BR13)) | CW13: =IF(ISBLANK($C13),"",IF($BH13<>Constants!$B$4,"",$BS13)) | CX13: =IF(ISBLANK($C13),"",IF($BH13<>Constants!$B$4,"",-$BZ13)) | CY13: =IF(ISBLANK($C13),"",$CA13) | CZ13: =IF(ISBLANK($C13),"",$BI13) | DA13: =IF(ISBLANK($C13),"",$CH13) | DB13: =IF(ISBLANK($C13),"",$CG13) | DC13: =IF(ISBLANK($C13),"",IFERROR(_xlfn.SWITCH($DB13,Constants!$B$7,COUNTA($C$9:$C$508)+2,Constants!$B$6,COUNTA($C$9:$C$508)+1,Constants!$B$5,COUNTA($C$9:$C$508)),$DB13)) | DE13: =IF(OR(ISNUMBER($DB13),$DB13=Constants!$B$7,$DB13=Constants!$B$5,$DB13=Constants!$B$6),1,0) -> 0 | DF13: 5 | DG13: =IF(ISBLANK($C13),"",IF(ISNUMBER($DC13),$DC13+ROW($B13)/1000,"")) | DH13: =IF(ISNUMBER($DG13),RANK($DG13,$DG$9:$DG$508,1),"") | DI13: =IF(ISBLANK($C13),"",$B13) | DJ13: =IF(ISBLANK($C13),"",$C13) | DK13: =IF(ISBLANK($C13),"",$D13) | DL13: =$CZ13 | DM13: =$CY13 | DN13: =IF(ISBLANK($C13),"",$DB13) | DO13: =IF($DF13>$DE$8,"",VLOOKUP($DF13,$DH$9:$DN$508,7,FALSE())) | DP13: =IF($DF13>$DE$8,"",VLOOKUP($DF13,$DH$9:$DN$508,2,FALSE())) | DQ13: =IF($DF13>$DE$8,"",VLOOKUP($DF13,$DH$9:$DN$508,3,FALSE())) | DR13: =IF($DF13>$DE$8,"",VLOOKUP($DF13,$DH$9:$DN$508,4,FALSE())) | DS13: =IF($DF13>$DE$8,"",VLOOKUP($DF13,$DH$9:$DN$508,5,FALSE())) | DT13: =IF($DF13>$DE$8,"",VLOOKUP($DF13,$DH$9:$DN$508,6,FALSE()))
AH14: =IF(ISBLANK($C14),"",IF($E14=Constants!$B$2,TRUE(),IF($E14=Constants!$B$3,FALSE(),TRUE()))) | AI14: =IF(ISBLANK($C14),"",IF($F14=Constants!$B$2,TRUE(),IF($F14=Constants!$B$3,FALSE(),FALSE()))) | AJ14: =IF(ISBLANK($C14),"",IF($G14=Constants!$B$2,TRUE(),IF($G14=Constants!$B$3,FALSE(),TRUE()))) | AK14: =IF(ISBLANK($C14),"",IF($H14=Constants!$B$2,TRUE(),IF($H14=Constants!$B$3,FALSE(),TRUE()))) | AL14: =IF(ISBLANK($C14),"",IF(ISNUMBER($I14),IF($I14>=0,$I14,""),"")) | AM14: =IF(ISBLANK($C14),"",IF(ISNUMBER($J14),IF($J14>=0,$J14,""),"")) | AN14: =IF(ISBLANK($C14),"",IF(ISNUMBER($K14),IF($K14>=0,$K14,""),"")) | AO14: =IF(ISBLANK($C14),"",IF($L14=Constants!$B$2,TRUE(),IF($L14=Constants!$B$3,FALSE(),TRUE()))) | AP14: =IF(ISBLANK($C14),"",IF($M14=Constants!$B$2,TRUE(),IF($M14=Constants!$B$3,FALSE(),TRUE()))) | AQ14: =IF(ISBLANK($C14),"",IF($N14=Constants!$B$2,TRUE(),IF($N14=Constants!$B$3,FALSE(),FALSE()))) | AR14: =IF(ISBLANK($C14),"",IF($O14=Constants!$B$2,TRUE(),IF($O14=Constants!$B$3,FALSE(),TRUE()))) | AS14: =IF(ISBLANK($C14),"",IF($P14=Constants!$B$2,TRUE(),IF($P14=Constants!$B$3,FALSE(),FALSE()))) | AT14: =IF(ISBLANK($C14),"",IF($Q14=Constants!$B$2,TRUE(),IF($Q14=Constants!$B$3,FALSE(),FALSE()))) | AU14: =IF(ISBLANK($C14),"",IF($R14=Constants!$B$2,TRUE(),IF($R14=Constants!$B$3,FALSE(),FALSE()))) | AV14: =IF(ISBLANK($C14),"",IF($S14=Constants!$B$2,TRUE(),IF($S14=Constants!$B$3,FALSE(),FALSE()))) | AW14: =IF(ISBLANK($C14),"",IF($T14=Constants!$B$2,TRUE(),IF($T14=Constants!$B$3,FALSE(),FALSE()))) | AX14: =IF(ISBLANK($C14),"",IF(OR($U14&""="1",$U14&""="2",$U14&""="3",$U14&""="4"),VALUE($U14&""),IF($U14=Constants!$B$12,Constants!$B$12,""))) | AY14: =IF(ISBLANK($C14),"",IF(ISBLANK($V14),0,IF(ISNUMBER($V14),IF(AND($V14>=0,$V14<=Constants!$B$21,$V14=INT($V14)),$V14,""),""))) | AZ14: =IF(ISBLANK($C14),"",IF(ISBLANK($W14),0,IF(ISNUMBER($W14),IF($W14>=0,$W14,""),""))) | BA14: =IF(ISBLANK($C14),"",IF($X14=Constants!$B$2,TRUE(),IF($X14=Constants!$B$3,FALSE(),TRUE()))) | BB14: =IF(ISBLANK($C14),"",IF($Y14=Constants!$B$2,TRUE(),IF($Y14=Constants!$B$3,FALSE(),FALSE()))) | BC14: =IF(ISBLANK($C14),"",IF(ISBLANK($Z14),0,IF(ISNUMBER($Z14),IF(AND($Z14>=0,$Z14<=Constants!$B$35,$Z14=INT($Z14)),$Z14,""),""))) | BD14: =IF(ISBLANK($C14),"",IF($AA14=Constants!$B$2,TRUE(),IF($AA14=Constants!$B$3,FALSE(),TRUE()))) | BE14: =IF(ISBLANK($C14),"",IF($AB14=Constants!$B$2,TRUE(),IF($AB14=Constants!$B$3,FALSE(),TRUE()))) | BF14: =IF(ISBLANK($C14),"",IF(ISNUMBER($AC14),IF($AC14>=0,$AC14,""),"")) | BG14: =IF(ISBLANK($C14),"",IF($AD14=Constants!$B$2,TRUE(),IF($AD14=Constants!$B$3,FALSE(),FALSE()))) | BH14: =IF(ISBLANK($C14),"",IF($BG14,Constants!$B$7,IF(COUNTA($E14:$AC14)=0,Constants!$B$6,IF(OR(COUNTA($G14:$AC14)=0,NOT($AK14),$AQ14),Constants!$B$5,IF(OR($CI14<>"",$CJ14,$CK14,$CL14,$CM14,$CN14,$CO14),Constants!$B$8,Constants!$B$4))))) | BI14: =IF(ISBLANK($C14),"",IF($BH14<>Constants!$B$4,$BH14,IF(OR(NOT($AH14),NOT($AJ14),NOT($AR14)),Constants!$B$11,IF(OR(NOT($AP14),MAX($AL14,$AM14,$AN14)>Constants!$B$30),Constants!$B$10,Constants!$B$9)))) | BJ14: =IF($BH14<>Constants!$B$4,"",IF(NOT($AJ14),0,MIN(Constants!$B$35,$BC14))) | BK14: =IF($BH14<>Constants!$B$4,"",IF(NOT($AJ14),0,IF($AT14,Constants!$B$18,IF($AS14,Constants!$B$17,0)))) | BL14: =IF($BH14<>Constants!$B$4,"",IF(NOT($AJ14),0,Constants!$B$19*($AI14+$AU14+$AV14+$AW14))) | BM14: =IF($BH14<>Constants!$B$4,"",IF(OR(NOT($AJ14),NOT(ISNUMBER($AX14))),0,CHOOSE($AX14,Constants!$B$13,Constants!$B$14,Constants!$B$15,Constants!$B$16))) | BN14: =IF($BH14<>Constants!$B$4,"",IF(NOT($AJ14),0,Constants!$B$20*$AY14)) | BO14: =IF($BH14<>Constants!$B$4,"",IF(AND($AJ14,$BA14,$BB14),Constants!$B$22,0)) | BP14: =IF($BH14<>Constants!$B$4,"",IF(OR(NOT($AJ14),NOT($BA14)),0,IF($BF14>=2*$AF$9,0,Constants!$B$23*INT(ROUND(MIN($BF14,$AF$9),6))))) | BQ14: =IF($BH14<>Constants!$B$4,"",IF(NOT($AJ14),0,Constants!$B$24*INT(ROUND(MIN($AZ14,$AF$9),6)))) | BR14: =IF($BH14<>Constants!$B$4,"",IF(AND($AJ14,$BJ14=0),Constants!$B$25,0)) | BS14: =IF($BH14<>Constants!$B$4,"",MIN(Constants!$B$29,MAX(0,Constants!$B$27*Constants!$B$28*INT(ROUND((Constants!$B$26-$AL14)/Constants!$B$28,6))))+MIN(Constants!$B$29,MAX(0,Constants!$B$27*Constants!$B$28*INT(ROUND((Constants!$B$26-$AM14)/Constants!$B$28,6))))+MIN(Constants!$B$29,MAX(0,Constants!$B$27*Constants!$B$28*INT(ROUND((Constants!$B$26-$AN14)/Constants!$B$28,6))))) | BT14: =IF($BH14<>Constants!$B$4,"",IF(NOT($AJ14),0,Constants!$B$31*INT(ROUND(MAX(0,MIN($BF14,2*$AF$9)-$AF$9),6)))) | BU14: =IF($BH14<>Constants!$B$4,"",Constants!$B$32*(($AL14>Constants!$B$26)+($AM14>Constants!$B$26)+($AN14>Constants!$B$26))) | BV14: =IF($BH14<>Constants!$B$4,"",IF(OR(NOT($AJ14),$AO14),0,Constants!$B$33)) | BW14: =IF($BH14<>Constants!$B$4,"",Constants!$B$34*$BJ14) | BX14: =IF($BH14<>Constants!$B$4,"",IF(OR(NOT($AJ14),$BE14),0,Constants!$B$36)) | BY14: =IF($BH14<>Constants!$B$4,"",IF(OR(NOT($AJ14),$BD14),0,Constants!$B$37)) | BZ14: =IF($BH14<>Constants!$B$4,"",SUM($BT14:$BY14)) | CA14: =IF(ISBLANK($C14),"",IF($BH14<>Constants!$B$4,$BH14,SUM($BK14:$BS14)-$BZ14)) | CB14: =IF(ISBLANK($C14),"",IF($BH14<>Constants!$B$4,$BH14,RANK($CA14,$CA$9:$CA$508))) | CC14: =IF(ISBLANK($C14),"",IF($BH14<>Constants!$B$4,$BH14,COUNTIFS($BI$9:$BI$508,"<"&$BI14)+COUNTIFS($BI$9:$BI$508,$BI14,$CB$9:$CB$508,"<"&$CB14)+1)) | CD14: =IF(ISBLANK($C14),"",IF($BH14<>Constants!$B$4,$BH14,RANK($BZ14,$BZ$9:$BZ$508,1))) | CE14: =IF($BH14<>Constants!$B$4,"",$AL14+$AM14+$AN14) | CF14: =IF(ISBLANK($C14),"",IF($BH14<>Constants!$B$4,$BH14,RANK($CE14,$CE$9:$CE$508,1))) | CG14: =IF(ISBLANK($C14),"",IF($BH14<>Constants!$B$4,$BH14,COUNTIFS($BI$9:$BI$508,"<"&$BI14)+COUNTIFS($BI$9:$BI$508,$BI14,$CB$9:$CB$508,"<"&$CB14)+COUNTIFS($BI$9:$BI$508,$BI14,$CB$9:$CB$508,$CB14,$CD$9:$CD$508,"<"&$CD14)+COUNTIFS($BI$9:$BI$508,$BI14,$CB$9:$CB$508,$CB14,$CD$9:$CD$508,$CD14,$CF$9:$CF$508,"<"&$CF14)+1)) | CH14: =IF(ISBLANK($C14),"",IF($BH14<>Constants!$B$4,$BH14,$CC14-$CG14)) | CI14: =IF(ISBLANK($C14),"",IF(NOT($AJ14),"",IF(ISBLANK($D$7),$CI$5,IF(NOT(ISNUMBER($D$7)),$CI$6,"")))) | CJ14: =IF(ISBLANK($C14),"",OR($AL14="",$AM14="",$AN14="")) | CK14: =IF(ISBLANK($C14),"",AND($AJ14,$AX14="")) | CL14: =IF(ISBLANK($C14),"",AND($AJ14,$AY14="")) | CM14: =IF(ISBLANK($C14),"",AND($AJ14,$AZ14="")) | CN14: =IF(ISBLANK($C14),"",AND($AJ14,$BC14="")) | CO14: =IF(ISBLANK($C14),"",AND($AJ14,$BF14="")) | CR14: =IF(ISBLANK($C14),"",IF($BH14=Constants!$B$8,$CI14,"")) | CS14: =IF(ISBLANK($C14),"",IF($BH14<>Constants!$B$4,"",$BK14+$BL14)) | CT14: =IF(ISBLANK($C14),"",IF($BH14<>Constants!$B$4,"",$BM14+$BN14+$BO14)) | CU14: =IF(ISBLANK($C14),"",IF($BH14<>Constants!$B$4,"",$BP14)) | CV14: =IF(ISBLANK($C14),"",IF($BH14<>Constants!$B$4,"",$BQ14+$BR14)) | CW14: =IF(ISBLANK($C14),"",IF($BH14<>Constants!$B$4,"",$BS14)) | CX14: =IF(ISBLANK($C14),"",IF($BH14<>Constants!$B$4,"",-$BZ14)) | CY14: =IF(ISBLANK($C14),"",$CA14) | CZ14: =IF(ISBLANK($C14),"",$BI14) | DA14: =IF(ISBLANK($C14),"",$CH14) | DB14: =IF(ISBLANK($C14),"",$CG14) | DC14: =IF(ISBLANK($C14),"",IFERROR(_xlfn.SWITCH($DB14,Constants!$B$7,COUNTA($C$9:$C$508)+2,Constants!$B$6,COUNTA($C$9:$C$508)+1,Constants!$B$5,COUNTA($C$9:$C$508)),$DB14)) | DE14: =IF(OR(ISNUMBER($DB14),$DB14=Constants!$B$7,$DB14=Constants!$B$5,$DB14=Constants!$B$6),1,0) -> 0 | DF14: 6 | DG14: =IF(ISBLANK($C14),"",IF(ISNUMBER($DC14),$DC14+ROW($B14)/1000,"")) | DH14: =IF(ISNUMBER($DG14),RANK($DG14,$DG$9:$DG$508,1),"") | DI14: =IF(ISBLANK($C14),"",$B14) | DJ14: =IF(ISBLANK($C14),"",$C14) | DK14: =IF(ISBLANK($C14),"",$D14) | DL14: =$CZ14 | DM14: =$CY14 | DN14: =IF(ISBLANK($C14),"",$DB14) | DO14: =IF($DF14>$DE$8,"",VLOOKUP($DF14,$DH$9:$DN$508,7,FALSE())) | DP14: =IF($DF14>$DE$8,"",VLOOKUP($DF14,$DH$9:$DN$508,2,FALSE())) | DQ14: =IF($DF14>$DE$8,"",VLOOKUP($DF14,$DH$9:$DN$508,3,FALSE())) | DR14: =IF($DF14>$DE$8,"",VLOOKUP($DF14,$DH$9:$DN$508,4,FALSE())) | DS14: =IF($DF14>$DE$8,"",VLOOKUP($DF14,$DH$9:$DN$508,5,FALSE())) | DT14: =IF($DF14>$DE$8,"",VLOOKUP($DF14,$DH$9:$DN$508,6,FALSE()))
AH15: =IF(ISBLANK($C15),"",IF($E15=Constants!$B$2,TRUE(),IF($E15=Constants!$B$3,FALSE(),TRUE()))) | AI15: =IF(ISBLANK($C15),"",IF($F15=Constants!$B$2,TRUE(),IF($F15=Constants!$B$3,FALSE(),FALSE()))) | AJ15: =IF(ISBLANK($C15),"",IF($G15=Constants!$B$2,TRUE(),IF($G15=Constants!$B$3,FALSE(),TRUE()))) | AK15: =IF(ISBLANK($C15),"",IF($H15=Constants!$B$2,TRUE(),IF($H15=Constants!$B$3,FALSE(),TRUE()))) | AL15: =IF(ISBLANK($C15),"",IF(ISNUMBER($I15),IF($I15>=0,$I15,""),"")) | AM15: =IF(ISBLANK($C15),"",IF(ISNUMBER($J15),IF($J15>=0,$J15,""),"")) | AN15: =IF(ISBLANK($C15),"",IF(ISNUMBER($K15),IF($K15>=0,$K15,""),"")) | AO15: =IF(ISBLANK($C15),"",IF($L15=Constants!$B$2,TRUE(),IF($L15=Constants!$B$3,FALSE(),TRUE()))) | AP15: =IF(ISBLANK($C15),"",IF($M15=Constants!$B$2,TRUE(),IF($M15=Constants!$B$3,FALSE(),TRUE()))) | AQ15: =IF(ISBLANK($C15),"",IF($N15=Constants!$B$2,TRUE(),IF($N15=Constants!$B$3,FALSE(),FALSE()))) | AR15: =IF(ISBLANK($C15),"",IF($O15=Constants!$B$2,TRUE(),IF($O15=Constants!$B$3,FALSE(),TRUE()))) | AS15: =IF(ISBLANK($C15),"",IF($P15=Constants!$B$2,TRUE(),IF($P15=Constants!$B$3,FALSE(),FALSE()))) | AT15: =IF(ISBLANK($C15),"",IF($Q15=Constants!$B$2,TRUE(),IF($Q15=Constants!$B$3,FALSE(),FALSE()))) | AU15: =IF(ISBLANK($C15),"",IF($R15=Constants!$B$2,TRUE(),IF($R15=Constants!$B$3,FALSE(),FALSE()))) | AV15: =IF(ISBLANK($C15),"",IF($S15=Constants!$B$2,TRUE(),IF($S15=Constants!$B$3,FALSE(),FALSE()))) | AW15: =IF(ISBLANK($C15),"",IF($T15=Constants!$B$2,TRUE(),IF($T15=Constants!$B$3,FALSE(),FALSE()))) | AX15: =IF(ISBLANK($C15),"",IF(OR($U15&""="1",$U15&""="2",$U15&""="3",$U15&""="4"),VALUE($U15&""),IF($U15=Constants!$B$12,Constants!$B$12,""))) | AY15: =IF(ISBLANK($C15),"",IF(ISBLANK($V15),0,IF(ISNUMBER($V15),IF(AND($V15>=0,$V15<=Constants!$B$21,$V15=INT($V15)),$V15,""),""))) | AZ15: =IF(ISBLANK($C15),"",IF(ISBLANK($W15),0,IF(ISNUMBER($W15),IF($W15>=0,$W15,""),""))) | BA15: =IF(ISBLANK($C15),"",IF($X15=Constants!$B$2,TRUE(),IF($X15=Constants!$B$3,FALSE(),TRUE()))) | BB15: =IF(ISBLANK($C15),"",IF($Y15=Constants!$B$2,TRUE(),IF($Y15=Constants!$B$3,FALSE(),FALSE()))) | BC15: =IF(ISBLANK($C15),"",IF(ISBLANK($Z15),0,IF(ISNUMBER($Z15),IF(AND($Z15>=0,$Z15<=Constants!$B$35,$Z15=INT($Z15)),$Z15,""),""))) | BD15: =IF(ISBLANK($C15),"",IF($AA15=Constants!$B$2,TRUE(),IF($AA15=Constants!$B$3,FALSE(),TRUE()))) | BE15: =IF(ISBLANK($C15),"",IF($AB15=Constants!$B$2,TRUE(),IF($AB15=Constants!$B$3,FALSE(),TRUE()))) | BF15: =IF(ISBLANK($C15),"",IF(ISNUMBER($AC15),IF($AC15>=0,$AC15,""),"")) | BG15: =IF(ISBLANK($C15),"",IF($AD15=Constants!$B$2,TRUE(),IF($AD15=Constants!$B$3,FALSE(),FALSE()))) | BH15: =IF(ISBLANK($C15),"",IF($BG15,Constants!$B$7,IF(COUNTA($E15:$AC15)=0,Constants!$B$6,IF(OR(COUNTA($G15:$AC15)=0,NOT($AK15),$AQ15),Constants!$B$5,IF(OR($CI15<>"",$CJ15,$CK15,$CL15,$CM15,$CN15,$CO15),Constants!$B$8,Constants!$B$4))))) | BI15: =IF(ISBLANK($C15),"",IF($BH15<>Constants!$B$4,$BH15,IF(OR(NOT($AH15),NOT($AJ15),NOT($AR15)),Constants!$B$11,IF(OR(NOT($AP15),MAX($AL15,$AM15,$AN15)>Constants!$B$30),Constants!$B$10,Constants!$B$9)))) | BJ15: =IF($BH15<>Constants!$B$4,"",IF(NOT($AJ15),0,MIN(Constants!$B$35,$BC15))) | BK15: =IF($BH15<>Constants!$B$4,"",IF(NOT($AJ15),0,IF($AT15,Constants!$B$18,IF($AS15,Constants!$B$17,0)))) | BL15: =IF($BH15<>Constants!$B$4,"",IF(NOT($AJ15),0,Constants!$B$19*($AI15+$AU15+$AV15+$AW15))) | BM15: =IF($BH15<>Constants!$B$4,"",IF(OR(NOT($AJ15),NOT(ISNUMBER($AX15))),0,CHOOSE($AX15,Constants!$B$13,Constants!$B$14,Constants!$B$15,Constants!$B$16))) | BN15: =IF($BH15<>Constants!$B$4,"",IF(NOT($AJ15),0,Constants!$B$20*$AY15)) | BO15: =IF($BH15<>Constants!$B$4,"",IF(AND($AJ15,$BA15,$BB15),Constants!$B$22,0)) | BP15: =IF($BH15<>Constants!$B$4,"",IF(OR(NOT($AJ15),NOT($BA15)),0,IF($BF15>=2*$AF$9,0,Constants!$B$23*INT(ROUND(MIN($BF15,$AF$9),6))))) | BQ15: =IF($BH15<>Constants!$B$4,"",IF(NOT($AJ15),0,Constants!$B$24*INT(ROUND(MIN($AZ15,$AF$9),6)))) | BR15: =IF($BH15<>Constants!$B$4,"",IF(AND($AJ15,$BJ15=0),Constants!$B$25,0)) | BS15: =IF($BH15<>Constants!$B$4,"",MIN(Constants!$B$29,MAX(0,Constants!$B$27*Constants!$B$28*INT(ROUND((Constants!$B$26-$AL15)/Constants!$B$28,6))))+MIN(Constants!$B$29,MAX(0,Constants!$B$27*Constants!$B$28*INT(ROUND((Constants!$B$26-$AM15)/Constants!$B$28,6))))+MIN(Constants!$B$29,MAX(0,Constants!$B$27*Constants!$B$28*INT(ROUND((Constants!$B$26-$AN15)/Constants!$B$28,6))))) | BT15: =IF($BH15<>Constants!$B$4,"",IF(NOT($AJ15),0,Constants!$B$31*INT(ROUND(MAX(0,MIN($BF15,2*$AF$9)-$AF$9),6)))) | BU15: =IF($BH15<>Constants!$B$4,"",Constants!$B$32*(($AL15>Constants!$B$26)+($AM15>Constants!$B$26)+($AN15>Constants!$B$26))) | BV15: =IF($BH15<>Constants!$B$4,"",IF(OR(NOT($AJ15),$AO15),0,Constants!$B$33)) | BW15: =IF($BH15<>Constants!$B$4,"",Constants!$B$34*$BJ15) | BX15: =IF($BH15<>Constants!$B$4,"",IF(OR(NOT($AJ15),$BE15),0,Constants!$B$36)) | BY15: =IF($BH15<>Constants!$B$4,"",IF(OR(NOT($AJ15),$BD15),0,Constants!$B$37)) | BZ15: =IF($BH15<>Constants!$B$4,"",SUM($BT15:$BY15)) | CA15: =IF(ISBLANK($C15),"",IF($BH15<>Constants!$B$4,$BH15,SUM($BK15:$BS15)-$BZ15)) | CB15: =IF(ISBLANK($C15),"",IF($BH15<>Constants!$B$4,$BH15,RANK($CA15,$CA$9:$CA$508))) | CC15: =IF(ISBLANK($C15),"",IF($BH15<>Constants!$B$4,$BH15,COUNTIFS($BI$9:$BI$508,"<"&$BI15)+COUNTIFS($BI$9:$BI$508,$BI15,$CB$9:$CB$508,"<"&$CB15)+1)) | CD15: =IF(ISBLANK($C15),"",IF($BH15<>Constants!$B$4,$BH15,RANK($BZ15,$BZ$9:$BZ$508,1))) | CE15: =IF($BH15<>Constants!$B$4,"",$AL15+$AM15+$AN15) | CF15: =IF(ISBLANK($C15),"",IF($BH15<>Constants!$B$4,$BH15,RANK($CE15,$CE$9:$CE$508,1))) | CG15: =IF(ISBLANK($C15),"",IF($BH15<>Constants!$B$4,$BH15,COUNTIFS($BI$9:$BI$508,"<"&$BI15)+COUNTIFS($BI$9:$BI$508,$BI15,$CB$9:$CB$508,"<"&$CB15)+COUNTIFS($BI$9:$BI$508,$BI15,$CB$9:$CB$508,$CB15,$CD$9:$CD$508,"<"&$CD15)+COUNTIFS($BI$9:$BI$508,$BI15,$CB$9:$CB$508,$CB15,$CD$9:$CD$508,$CD15,$CF$9:$CF$508,"<"&$CF15)+1)) | CH15: =IF(ISBLANK($C15),"",IF($BH15<>Constants!$B$4,$BH15,$CC15-$CG15)) | CI15: =IF(ISBLANK($C15),"",IF(NOT($AJ15),"",IF(ISBLANK($D$7),$CI$5,IF(NOT(ISNUMBER($D$7)),$CI$6,"")))) | CJ15: =IF(ISBLANK($C15),"",OR($AL15="",$AM15="",$AN15="")) | CK15: =IF(ISBLANK($C15),"",AND($AJ15,$AX15="")) | CL15: =IF(ISBLANK($C15),"",AND($AJ15,$AY15="")) | CM15: =IF(ISBLANK($C15),"",AND($AJ15,$AZ15="")) | CN15: =IF(ISBLANK($C15),"",AND($AJ15,$BC15="")) | CO15: =IF(ISBLANK($C15),"",AND($AJ15,$BF15="")) | CR15: =IF(ISBLANK($C15),"",IF($BH15=Constants!$B$8,$CI15,"")) | CS15: =IF(ISBLANK($C15),"",IF($BH15<>Constants!$B$4,"",$BK15+$BL15)) | CT15: =IF(ISBLANK($C15),"",IF($BH15<>Constants!$B$4,"",$BM15+$BN15+$BO15)) | CU15: =IF(ISBLANK($C15),"",IF($BH15<>Constants!$B$4,"",$BP15)) | CV15: =IF(ISBLANK($C15),"",IF($BH15<>Constants!$B$4,"",$BQ15+$BR15)) | CW15: =IF(ISBLANK($C15),"",IF($BH15<>Constants!$B$4,"",$BS15)) | CX15: =IF(ISBLANK($C15),"",IF($BH15<>Constants!$B$4,"",-$BZ15)) | CY15: =IF(ISBLANK($C15),"",$CA15) | CZ15: =IF(ISBLANK($C15),"",$BI15) | DA15: =IF(ISBLANK($C15),"",$CH15) | DB15: =IF(ISBLANK($C15),"",$CG15) | DC15: =IF(ISBLANK($C15),"",IFERROR(_xlfn.SWITCH($DB15,Constants!$B$7,COUNTA($C$9:$C$508)+2,Constants!$B$6,COUNTA($C$9:$C$508)+1,Constants!$B$5,COUNTA($C$9:$C$508)),$DB15)) | DE15: =IF(OR(ISNUMBER($DB15),$DB15=Constants!$B$7,$DB15=Constants!$B$5,$DB15=Constants!$B$6),1,0) -> 0 | DF15: 7 | DG15: =IF(ISBLANK($C15),"",IF(ISNUMBER($DC15),$DC15+ROW($B15)/1000,"")) | DH15: =IF(ISNUMBER($DG15),RANK($DG15,$DG$9:$DG$508,1),"") | DI15: =IF(ISBLANK($C15),"",$B15) | DJ15: =IF(ISBLANK($C15),"",$C15) | DK15: =IF(ISBLANK($C15),"",$D15) | DL15: =$CZ15 | DM15: =$CY15 | DN15: =IF(ISBLANK($C15),"",$DB15) | DO15: =IF($DF15>$DE$8,"",VLOOKUP($DF15,$DH$9:$DN$508,7,FALSE())) | DP15: =IF($DF15>$DE$8,"",VLOOKUP($DF15,$DH$9:$DN$508,2,FALSE())) | DQ15: =IF($DF15>$DE$8,"",VLOOKUP($DF15,$DH$9:$DN$508,3,FALSE())) | DR15: =IF($DF15>$DE$8,"",VLOOKUP($DF15,$DH$9:$DN$508,4,FALSE())) | DS15: =IF($DF15>$DE$8,"",VLOOKUP($DF15,$DH$9:$DN$508,5,FALSE())) | DT15: =IF($DF15>$DE$8,"",VLOOKUP($DF15,$DH$9:$DN$508,6,FALSE()))
