Workbook

Sheet Scoring
B2: ='Info.'!B1&" "&'Info.'!B4 -> Ping Pong Parachute B/C | E2: Check-In & Practice Log | H2: Flight Time | AW2: Breakdown | BH2: Rank for this team with row() bump | BI2: Rank for this team with same ranks split | BJ2: Team Number of this team | BK2: Name of this school | BL2: Name of this team | BM2: Tier for this Team | BN2: Score for this team | BO2: Actual Rank for this team | BP2: Final Rankings
E3: Rocket A | F3: Rocket B | G3: 3. Practice Log (Complete / Incomplete / Not present) | H3: Flight 1 | L3: Flight 2 | P3: 12. Disqualify (T/F) | R3: =E4 -> 1. Met All Const Params (T/F) | S3: =F4 -> 2. Met All Const Params (T/F) | T3: =G3 -> 3. Practice Log (Complete / Incomplete / Not present) | U3: =H4 -> 4. Rocket (A/B) | V3: =I4 -> 5. Median Flight Time (s) | W3: =J4 -> 6. Parachute successfully separates from rocket (T/F) | X3: =K4 -> 7. No part of rocket and parachute touches ceiling (T/F) | Y3: =L4 -> 8. Rocket (A/B) | Z3: =M4 -> 9. Median Flight Time (s) | AA3: =N4 -> 10. Parachute successfully separates from rocket (T/F) | AB3: =O4 -> 11. No part of rocket and parachute touches ceiling (T/F) | AC3: =P3 -> 12. Disqualify (T/F) | AW3: Scored Flight | AX3: Raw Time | AY3: Flight Multiplier | AZ3: Score | BA3: Tier | BB3: Tiebreaker | BC3: Rank | BD3: Points | BP3: Rank | BQ3: Team # | BR3: School Name | BS3: Team Name | BT3: Tier | BU3: Score
B4: ="Event Scoresheet - "&'Info.'!B5&IF('Info.'!B8="T"," The scoresheet has been updated; please download version v"&'Info.'!B7&" from soinc.org/scoresheets.","") -> Event Scoresheet - 2027 | E4: 1. Met All Const Params (T/F) | F4: 2. Met All Const Params (T/F) | H4: 4. Rocket (A/B) | I4: 5. Median Flight Time (s) | J4: 6. Parachute successfully separates from rocket (T/F) | K4: 7. No part of rocket and parachute touches ceiling (T/F) | L4: 8. Rocket (A/B) | M4: 9. Median Flight Time (s) | N4: 10. Parachute successfully separates from rocket (T/F) | O4: 11. No part of rocket and parachute touches ceiling (T/F)
B6: ="Last Updated: "&TEXT('Info.'!B2, "mm/dd/yyyy")&" (v"&'Info.'!B3&") Direct all questions to scoresheets@soinc.org." -> Last Updated: 09/23/2026 (v0.1.0) Direct all questions to scoresheets@soinc.org. | AG6: Hidden since event has no tiers | AH6: Flight 1 | AK6: Flight 2
B7: Team # | C7: School Name | D7: Team Name | AD7: Flight 1 Scoreable? | AE7: Flight 2 Scoreable? | AF7: Status | AG7: Tier | AH7: Flight 1 (s) | AI7: Flight 1 Mult | AJ7: Flight 1 Score | AK7: Flight 2 (s) | AL7: Flight 2 Mult | AM7: Flight 2 Score | AN7: Scored Flight # | AO7: Non-scored Flight # | AP7: Score | AQ7: Rank | AR7: TB1 (Non-scored Flight Score) | AS7: TB1 Rank | AT7: Rank w/ TB | AU7: Rank Diff | BF7: =SUM(BF8:BF507) -> 0
R8: =IF(ISBLANK($C8),"",IF(E8=Constants!$B$2, TRUE(), IF(E8=Constants!$B$3, FALSE(), TRUE()))) | S8: =IF(ISBLANK($C8),"",IF(F8=Constants!$B$2, TRUE(), IF(F8=Constants!$B$3, FALSE(), TRUE()))) | T8: =IF(ISBLANK($C8),"",IF(G8=Constants!$B$16,Constants!$B$9,IF(G8=Constants!$B$17,Constants!$B$10,Constants!$B$8))) | U8: =IF(ISBLANK($C8),"",IF(H8=Constants!$B$19,Constants!$B$19,Constants!$B$18)) | V8: =IF(ISBLANK($C8),"",IF(ISNUMBER(I8),IF(I8>=0,I8,""),"")) | W8: =IF(ISBLANK($C8),"",IF(J8=Constants!$B$2, TRUE(), IF(J8=Constants!$B$3, FALSE(), TRUE()))) | X8: =IF(ISBLANK($C8),"",IF(K8=Constants!$B$2, TRUE(), IF(K8=Constants!$B$3, FALSE(), TRUE()))) | Y8: =IF(ISBLANK($C8),"",IF(L8=Constants!$B$19,Constants!$B$19,Constants!$B$18)) | Z8: =IF(ISBLANK($C8),"",IF(ISNUMBER(M8),IF(M8>=0,M8,""),"")) | AA8: =IF(ISBLANK($C8),"",IF(N8=Constants!$B$2, TRUE(), IF(N8=Constants!$B$3, FALSE(), TRUE()))) | AB8: =IF(ISBLANK($C8),"",IF(O8=Constants!$B$2, TRUE(), IF(O8=Constants!$B$3, FALSE(), TRUE()))) | AC8: =IF(ISBLANK($C8),"",IF(P8=Constants!$B$2, TRUE(), IF(P8=Constants!$B$3, FALSE(), FALSE()))) | AD8: =IF(ISBLANK($C8),"",AND(V8<>"",IF(U8=Constants!$B$19,S8,R8))) | AE8: =IF(ISBLANK($C8),"",AND(Z8<>"",IF(Y8=Constants!$B$19,S8,R8))) | AF8: =IF(ISBLANK($C8),"",IF(AC8,Constants!$B$4,IF(COUNTA(E8:O8)=0,Constants!$B$5,IF(AND(NOT(AD8),NOT(AE8)),Constants!$B$6,Constants!$B$7)))) | AG8: =IF(ISBLANK($C8),"",IF($AF8<>Constants!$B$7,$AF8,Constants!$B$20)) | AH8: =IF($AF8=Constants!$B$7,IF(AD8,V8,Constants!$B$13),"") | AI8: =IF($AF8=Constants!$B$7,IF(AD8,T8*IF(W8, 1, Constants!$B$11)*IF(X8, 1, Constants!$B$12),Constants!$B$13),"") | AJ8: =IF($AF8=Constants!$B$7,AH8*AI8,"") | AK8: =IF($AF8=Constants!$B$7,IF(AE8,Z8,Constants!$B$13),"") | AL8: =IF($AF8=Constants!$B$7,IF(AE8,T8*IF(AA8, 1, Constants!$B$11)*IF(AB8, 1, Constants!$B$12),Constants!$B$13),"") | AM8: =IF($AF8=Constants!$B$7,AK8*AL8,"") | AN8: =IF($AF8=Constants!$B$7,IF(AM8>AJ8,2,1),"") | AO8: =IF($AF8=Constants!$B$7,IF(AN8=1,2,1),"") | AP8: =IF(ISBLANK($C8),"",IF($AF8<>Constants!$B$7,$AF8,IF(AN8=1,AJ8,AM8))) | AQ8: =IF(ISBLANK($C8),"",IF($AF8=Constants!$B$7,IF(ISNUMBER(AP8),RANK(AP8,$AP$8:$AP$507),Constants!$B$14),$AF8)) | AR8: =IF(ISBLANK($C8),"",IF($AF8=Constants!$B$7,IF(AO8=1,AJ8,AM8),"")) | AS8: =IF(ISBLANK($C8),"",IF($AF8=Constants!$B$7,RANK(AR8,$AR$8:$AR$507),$AF8)) | AT8: =IF(ISBLANK($C8),"",IF($AF8=Constants!$B$7,IF(ISNUMBER(AQ8),COUNTIFS($AQ$8:$AQ$507,"<"&$AQ8)+COUNTIFS($AQ$8:$AQ$507,$AQ8,$AS$8:$AS$507,"<"&$AS8)+1,Constants!$B$14),$AF8)) | AU8: =IF(ISBLANK($C8),"",IF($AF8=Constants!$B$7,IF(ISNUMBER(AQ8),AQ8-AT8,Constants!$B$14),$AF8)) | AW8: =IF(ISBLANK($C8),"",IF($AF8<>Constants!$B$7,"",AN8)) | AX8: =IF(ISBLANK($C8),"",IF($AF8<>Constants!$B$7,"",IF(AN8=1,AH8,AK8))) | AY8: =IF(ISBLANK($C8),"",IF($AF8<>Constants!$B$7,"",IF(AN8=1,AI8,AL8))) | AZ8: =IF(ISBLANK($C8),"",IF($AF8<>Constants!$B$7,$AF8,AP8)) | BA8: =IF(ISBLANK($C8),"",IF($AF8<>Constants!$B$7,$AF8,AG8)) | BB8: =IF(ISBLANK($C8),"",AU8) | BC8: =IF(ISBLANK($C8),"",AT8) | BD8: =IF(ISBLANK($C8),"",IFERROR(_xlfn.SWITCH(BC8,Constants!$B$4,COUNTA($C$8:$C$507)+2,Constants!$B$5,COUNTA($C$8:$C$507)+1,Constants!$B$6,COUNTA($C$8:$C$507)),BC8)) | BF8: =IF(OR(ISNUMBER(BC8),BC8=Constants!$B$4,BC8=Constants!$B$6,BC8=Constants!$B$5),1,0) -> 0 | BG8: 1 | BH8: =IF(ISBLANK($C8),"",IF(ISNUMBER(BD8),BD8+ROW($B8)/1000,"")) | BI8: =IF(ISNUMBER(BH8),RANK(BH8,$BH$8:$BH$507,1),"") | BJ8: =IF(ISBLANK($C8),"",$B8) | BK8: =IF(ISBLANK($C8),"",$C8) | BL8: =IF(ISBLANK($C8),"",$D8) | BM8: =BA8 | BN8: =AZ8 | BO8: =IF(ISBLANK($C8),"",BC8) | BP8: =IF($BG8>$BF$7,"",VLOOKUP($BG8,$BI$8:$BO$507,7,FALSE())) | BQ8: =IF($BG8>$BF$7,"",VLOOKUP($BG8,$BI$8:$BO$507,2,FALSE())) | BR8: =IF($BG8>$BF$7,"",VLOOKUP($BG8,$BI$8:$BO$507,3,FALSE())) | BS8: =IF($BG8>$BF$7,"",VLOOKUP($BG8,$BI$8:$BO$507,4,FALSE())) | BT8: =IF($BG8>$BF$7,"",VLOOKUP($BG8,$BI$8:$BO$507,5,FALSE())) | BU8: =IF($BG8>$BF$7,"",VLOOKUP($BG8,$BI$8:$BO$507,6,FALSE()))
R9: =IF(ISBLANK($C9),"",IF(E9=Constants!$B$2, TRUE(), IF(E9=Constants!$B$3, FALSE(), TRUE()))) | S9: =IF(ISBLANK($C9),"",IF(F9=Constants!$B$2, TRUE(), IF(F9=Constants!$B$3, FALSE(), TRUE()))) | T9: =IF(ISBLANK($C9),"",IF(G9=Constants!$B$16,Constants!$B$9,IF(G9=Constants!$B$17,Constants!$B$10,Constants!$B$8))) | U9: =IF(ISBLANK($C9),"",IF(H9=Constants!$B$19,Constants!$B$19,Constants!$B$18)) | V9: =IF(ISBLANK($C9),"",IF(ISNUMBER(I9),IF(I9>=0,I9,""),"")) | W9: =IF(ISBLANK($C9),"",IF(J9=Constants!$B$2, TRUE(), IF(J9=Constants!$B$3, FALSE(), TRUE()))) | X9: =IF(ISBLANK($C9),"",IF(K9=Constants!$B$2, TRUE(), IF(K9=Constants!$B$3, FALSE(), TRUE()))) | Y9: =IF(ISBLANK($C9),"",IF(L9=Constants!$B$19,Constants!$B$19,Constants!$B$18)) | Z9: =IF(ISBLANK($C9),"",IF(ISNUMBER(M9),IF(M9>=0,M9,""),"")) | AA9: =IF(ISBLANK($C9),"",IF(N9=Constants!$B$2, TRUE(), IF(N9=Constants!$B$3, FALSE(), TRUE()))) | AB9: =IF(ISBLANK($C9),"",IF(O9=Constants!$B$2, TRUE(), IF(O9=Constants!$B$3, FALSE(), TRUE()))) | AC9: =IF(ISBLANK($C9),"",IF(P9=Constants!$B$2, TRUE(), IF(P9=Constants!$B$3, FALSE(), FALSE()))) | AD9: =IF(ISBLANK($C9),"",AND(V9<>"",IF(U9=Constants!$B$19,S9,R9))) | AE9: =IF(ISBLANK($C9),"",AND(Z9<>"",IF(Y9=Constants!$B$19,S9,R9))) | AF9: =IF(ISBLANK($C9),"",IF(AC9,Constants!$B$4,IF(COUNTA(E9:O9)=0,Constants!$B$5,IF(AND(NOT(AD9),NOT(AE9)),Constants!$B$6,Constants!$B$7)))) | AG9: =IF(ISBLANK($C9),"",IF($AF9<>Constants!$B$7,$AF9,Constants!$B$20)) | AH9: =IF($AF9=Constants!$B$7,IF(AD9,V9,Constants!$B$13),"") | AI9: =IF($AF9=Constants!$B$7,IF(AD9,T9*IF(W9, 1, Constants!$B$11)*IF(X9, 1, Constants!$B$12),Constants!$B$13),"") | AJ9: =IF($AF9=Constants!$B$7,AH9*AI9,"") | AK9: =IF($AF9=Constants!$B$7,IF(AE9,Z9,Constants!$B$13),"") | AL9: =IF($AF9=Constants!$B$7,IF(AE9,T9*IF(AA9, 1, Constants!$B$11)*IF(AB9, 1, Constants!$B$12),Constants!$B$13),"") | AM9: =IF($AF9=Constants!$B$7,AK9*AL9,"") | AN9: =IF($AF9=Constants!$B$7,IF(AM9>AJ9,2,1),"") | AO9: =IF($AF9=Constants!$B$7,IF(AN9=1,2,1),"") | AP9: =IF(ISBLANK($C9),"",IF($AF9<>Constants!$B$7,$AF9,IF(AN9=1,AJ9,AM9))) | AQ9: =IF(ISBLANK($C9),"",IF($AF9=Constants!$B$7,IF(ISNUMBER(AP9),RANK(AP9,$AP$8:$AP$507),Constants!$B$14),$AF9)) | AR9: =IF(ISBLANK($C9),"",IF($AF9=Constants!$B$7,IF(AO9=1,AJ9,AM9),"")) | AS9: =IF(ISBLANK($C9),"",IF($AF9=Constants!$B$7,RANK(AR9,$AR$8:$AR$507),$AF9)) | AT9: =IF(ISBLANK($C9),"",IF($AF9=Constants!$B$7,IF(ISNUMBER(AQ9),COUNTIFS($AQ$8:$AQ$507,"<"&$AQ9)+COUNTIFS($AQ$8:$AQ$507,$AQ9,$AS$8:$AS$507,"<"&$AS9)+1,Constants!$B$14),$AF9)) | AU9: =IF(ISBLANK($C9),"",IF($AF9=Constants!$B$7,IF(ISNUMBER(AQ9),AQ9-AT9,Constants!$B$14),$AF9)) | AW9: =IF(ISBLANK($C9),"",IF($AF9<>Constants!$B$7,"",AN9)) | AX9: =IF(ISBLANK($C9),"",IF($AF9<>Constants!$B$7,"",IF(AN9=1,AH9,AK9))) | AY9: =IF(ISBLANK($C9),"",IF($AF9<>Constants!$B$7,"",IF(AN9=1,AI9,AL9))) | AZ9: =IF(ISBLANK($C9),"",IF($AF9<>Constants!$B$7,$AF9,AP9)) | BA9: =IF(ISBLANK($C9),"",IF($AF9<>Constants!$B$7,$AF9,AG9)) | BB9: =IF(ISBLANK($C9),"",AU9) | BC9: =IF(ISBLANK($C9),"",AT9) | BD9: =IF(ISBLANK($C9),"",IFERROR(_xlfn.SWITCH(BC9,Constants!$B$4,COUNTA($C$8:$C$507)+2,Constants!$B$5,COUNTA($C$8:$C$507)+1,Constants!$B$6,COUNTA($C$8:$C$507)),BC9)) | BF9: =IF(OR(ISNUMBER(BC9),BC9=Constants!$B$4,BC9=Constants!$B$6,BC9=Constants!$B$5),1,0) -> 0 | BG9: 2 | BH9: =IF(ISBLANK($C9),"",IF(ISNUMBER(BD9),BD9+ROW($B9)/1000,"")) | BI9: =IF(ISNUMBER(BH9),RANK(BH9,$BH$8:$BH$507,1),"") | BJ9: =IF(ISBLANK($C9),"",$B9) | BK9: =IF(ISBLANK($C9),"",$C9) | BL9: =IF(ISBLANK($C9),"",$D9) | BM9: =BA9 | BN9: =AZ9 | BO9: =IF(ISBLANK($C9),"",BC9) | BP9: =IF($BG9>$BF$7,"",VLOOKUP($BG9,$BI$8:$BO$507,7,FALSE())) | BQ9: =IF($BG9>$BF$7,"",VLOOKUP($BG9,$BI$8:$BO$507,2,FALSE())) | BR9: =IF($BG9>$BF$7,"",VLOOKUP($BG9,$BI$8:$BO$507,3,FALSE())) | BS9: =IF($BG9>$BF$7,"",VLOOKUP($BG9,$BI$8:$BO$507,4,FALSE())) | BT9: =IF($BG9>$BF$7,"",VLOOKUP($BG9,$BI$8:$BO$507,5,FALSE())) | BU9: =IF($BG9>$BF$7,"",VLOOKUP($BG9,$BI$8:$BO$507,6,FALSE()))
R10: =IF(ISBLANK($C10),"",IF(E10=Constants!$B$2, TRUE(), IF(E10=Constants!$B$3, FALSE(), TRUE()))) | S10: =IF(ISBLANK($C10),"",IF(F10=Constants!$B$2, TRUE(), IF(F10=Constants!$B$3, FALSE(), TRUE()))) | T10: =IF(ISBLANK($C10),"",IF(G10=Constants!$B$16,Constants!$B$9,IF(G10=Constants!$B$17,Constants!$B$10,Constants!$B$8))) | U10: =IF(ISBLANK($C10),"",IF(H10=Constants!$B$19,Constants!$B$19,Constants!$B$18)) | V10: =IF(ISBLANK($C10),"",IF(ISNUMBER(I10),IF(I10>=0,I10,""),"")) | W10: =IF(ISBLANK($C10),"",IF(J10=Constants!$B$2, TRUE(), IF(J10=Constants!$B$3, FALSE(), TRUE()))) | X10: =IF(ISBLANK($C10),"",IF(K10=Constants!$B$2, TRUE(), IF(K10=Constants!$B$3, FALSE(), TRUE()))) | Y10: =IF(ISBLANK($C10),"",IF(L10=Constants!$B$19,Constants!$B$19,Constants!$B$18)) | Z10: =IF(ISBLANK($C10),"",IF(ISNUMBER(M10),IF(M10>=0,M10,""),"")) | AA10: =IF(ISBLANK($C10),"",IF(N10=Constants!$B$2, TRUE(), IF(N10=Constants!$B$3, FALSE(), TRUE()))) | AB10: =IF(ISBLANK($C10),"",IF(O10=Constants!$B$2, TRUE(), IF(O10=Constants!$B$3, FALSE(), TRUE()))) | AC10: =IF(ISBLANK($C10),"",IF(P10=Constants!$B$2, TRUE(), IF(P10=Constants!$B$3, FALSE(), FALSE()))) | AD10: =IF(ISBLANK($C10),"",AND(V10<>"",IF(U10=Constants!$B$19,S10,R10))) | AE10: =IF(ISBLANK($C10),"",AND(Z10<>"",IF(Y10=Constants!$B$19,S10,R10))) | AF10: =IF(ISBLANK($C10),"",IF(AC10,Constants!$B$4,IF(COUNTA(E10:O10)=0,Constants!$B$5,IF(AND(NOT(AD10),NOT(AE10)),Constants!$B$6,Constants!$B$7)))) | AG10: =IF(ISBLANK($C10),"",IF($AF10<>Constants!$B$7,$AF10,Constants!$B$20)) | AH10: =IF($AF10=Constants!$B$7,IF(AD10,V10,Constants!$B$13),"") | AI10: =IF($AF10=Constants!$B$7,IF(AD10,T10*IF(W10, 1, Constants!$B$11)*IF(X10, 1, Constants!$B$12),Constants!$B$13),"") | AJ10: =IF($AF10=Constants!$B$7,AH10*AI10,"") | AK10: =IF($AF10=Constants!$B$7,IF(AE10,Z10,Constants!$B$13),"") | AL10: =IF($AF10=Constants!$B$7,IF(AE10,T10*IF(AA10, 1, Constants!$B$11)*IF(AB10, 1, Constants!$B$12),Constants!$B$13),"") | AM10: =IF($AF10=Constants!$B$7,AK10*AL10,"") | AN10: =IF($AF10=Constants!$B$7,IF(AM10>AJ10,2,1),"") | AO10: =IF($AF10=Constants!$B$7,IF(AN10=1,2,1),"") | AP10: =IF(ISBLANK($C10),"",IF($AF10<>Constants!$B$7,$AF10,IF(AN10=1,AJ10,AM10))) | AQ10: =IF(ISBLANK($C10),"",IF($AF10=Constants!$B$7,IF(ISNUMBER(AP10),RANK(AP10,$AP$8:$AP$507),Constants!$B$14),$AF10)) | AR10: =IF(ISBLANK($C10),"",IF($AF10=Constants!$B$7,IF(AO10=1,AJ10,AM10),"")) | AS10: =IF(ISBLANK($C10),"",IF($AF10=Constants!$B$7,RANK(AR10,$AR$8:$AR$507),$AF10)) | AT10: =IF(ISBLANK($C10),"",IF($AF10=Constants!$B$7,IF(ISNUMBER(AQ10),COUNTIFS($AQ$8:$AQ$507,"<"&$AQ10)+COUNTIFS($AQ$8:$AQ$507,$AQ10,$AS$8:$AS$507,"<"&$AS10)+1,Constants!$B$14),$AF10)) | AU10: =IF(ISBLANK($C10),"",IF($AF10=Constants!$B$7,IF(ISNUMBER(AQ10),AQ10-AT10,Constants!$B$14),$AF10)) | AW10: =IF(ISBLANK($C10),"",IF($AF10<>Constants!$B$7,"",AN10)) | AX10: =IF(ISBLANK($C10),"",IF($AF10<>Constants!$B$7,"",IF(AN10=1,AH10,AK10))) | AY10: =IF(ISBLANK($C10),"",IF($AF10<>Constants!$B$7,"",IF(AN10=1,AI10,AL10))) | AZ10: =IF(ISBLANK($C10),"",IF($AF10<>Constants!$B$7,$AF10,AP10)) | BA10: =IF(ISBLANK($C10),"",IF($AF10<>Constants!$B$7,$AF10,AG10)) | BB10: =IF(ISBLANK($C10),"",AU10) | BC10: =IF(ISBLANK($C10),"",AT10) | BD10: =IF(ISBLANK($C10),"",IFERROR(_xlfn.SWITCH(BC10,Constants!$B$4,COUNTA($C$8:$C$507)+2,Constants!$B$5,COUNTA($C$8:$C$507)+1,Constants!$B$6,COUNTA($C$8:$C$507)),BC10)) | BF10: =IF(OR(ISNUMBER(BC10),BC10=Constants!$B$4,BC10=Constants!$B$6,BC10=Constants!$B$5),1,0) -> 0 | BG10: 3 | BH10: =IF(ISBLANK($C10),"",IF(ISNUMBER(BD10),BD10+ROW($B10)/1000,"")) | BI10: =IF(ISNUMBER(BH10),RANK(BH10,$BH$8:$BH$507,1),"") | BJ10: =IF(ISBLANK($C10),"",$B10) | BK10: =IF(ISBLANK($C10),"",$C10) | BL10: =IF(ISBLANK($C10),"",$D10) | BM10: =BA10 | BN10: =AZ10 | BO10: =IF(ISBLANK($C10),"",BC10) | BP10: =IF($BG10>$BF$7,"",VLOOKUP($BG10,$BI$8:$BO$507,7,FALSE())) | BQ10: =IF($BG10>$BF$7,"",VLOOKUP($BG10,$BI$8:$BO$507,2,FALSE())) | BR10: =IF($BG10>$BF$7,"",VLOOKUP($BG10,$BI$8:$BO$507,3,FALSE())) | BS10: =IF($BG10>$BF$7,"",VLOOKUP($BG10,$BI$8:$BO$507,4,FALSE())) | BT10: =IF($BG10>$BF$7,"",VLOOKUP($BG10,$BI$8:$BO$507,5,FALSE())) | BU10: =IF($BG10>$BF$7,"",VLOOKUP($BG10,$BI$8:$BO$507,6,FALSE()))
R11: =IF(ISBLANK($C11),"",IF(E11=Constants!$B$2, TRUE(), IF(E11=Constants!$B$3, FALSE(), TRUE()))) | S11: =IF(ISBLANK($C11),"",IF(F11=Constants!$B$2, TRUE(), IF(F11=Constants!$B$3, FALSE(), TRUE()))) | T11: =IF(ISBLANK($C11),"",IF(G11=Constants!$B$16,Constants!$B$9,IF(G11=Constants!$B$17,Constants!$B$10,Constants!$B$8))) | U11: =IF(ISBLANK($C11),"",IF(H11=Constants!$B$19,Constants!$B$19,Constants!$B$18)) | V11: =IF(ISBLANK($C11),"",IF(ISNUMBER(I11),IF(I11>=0,I11,""),"")) | W11: =IF(ISBLANK($C11),"",IF(J11=Constants!$B$2, TRUE(), IF(J11=Constants!$B$3, FALSE(), TRUE()))) | X11: =IF(ISBLANK($C11),"",IF(K11=Constants!$B$2, TRUE(), IF(K11=Constants!$B$3, FALSE(), TRUE()))) | Y11: =IF(ISBLANK($C11),"",IF(L11=Constants!$B$19,Constants!$B$19,Constants!$B$18)) | Z11: =IF(ISBLANK($C11),"",IF(ISNUMBER(M11),IF(M11>=0,M11,""),"")) | AA11: =IF(ISBLANK($C11),"",IF(N11=Constants!$B$2, TRUE(), IF(N11=Constants!$B$3, FALSE(), TRUE()))) | AB11: =IF(ISBLANK($C11),"",IF(O11=Constants!$B$2, TRUE(), IF(O11=Constants!$B$3, FALSE(), TRUE()))) | AC11: =IF(ISBLANK($C11),"",IF(P11=Constants!$B$2, TRUE(), IF(P11=Constants!$B$3, FALSE(), FALSE()))) | AD11: =IF(ISBLANK($C11),"",AND(V11<>"",IF(U11=Constants!$B$19,S11,R11))) | AE11: =IF(ISBLANK($C11),"",AND(Z11<>"",IF(Y11=Constants!$B$19,S11,R11))) | AF11: =IF(ISBLANK($C11),"",IF(AC11,Constants!$B$4,IF(COUNTA(E11:O11)=0,Constants!$B$5,IF(AND(NOT(AD11),NOT(AE11)),Constants!$B$6,Constants!$B$7)))) | AG11: =IF(ISBLANK($C11),"",IF($AF11<>Constants!$B$7,$AF11,Constants!$B$20)) | AH11: =IF($AF11=Constants!$B$7,IF(AD11,V11,Constants!$B$13),"") | AI11: =IF($AF11=Constants!$B$7,IF(AD11,T11*IF(W11, 1, Constants!$B$11)*IF(X11, 1, Constants!$B$12),Constants!$B$13),"") | AJ11: =IF($AF11=Constants!$B$7,AH11*AI11,"") | AK11: =IF($AF11=Constants!$B$7,IF(AE11,Z11,Constants!$B$13),"") | AL11: =IF($AF11=Constants!$B$7,IF(AE11,T11*IF(AA11, 1, Constants!$B$11)*IF(AB11, 1, Constants!$B$12),Constants!$B$13),"") | AM11: =IF($AF11=Constants!$B$7,AK11*AL11,"") | AN11: =IF($AF11=Constants!$B$7,IF(AM11>AJ11,2,1),"") | AO11: =IF($AF11=Constants!$B$7,IF(AN11=1,2,1),"") | AP11: =IF(ISBLANK($C11),"",IF($AF11<>Constants!$B$7,$AF11,IF(AN11=1,AJ11,AM11))) | AQ11: =IF(ISBLANK($C11),"",IF($AF11=Constants!$B$7,IF(ISNUMBER(AP11),RANK(AP11,$AP$8:$AP$507),Constants!$B$14),$AF11)) | AR11: =IF(ISBLANK($C11),"",IF($AF11=Constants!$B$7,IF(AO11=1,AJ11,AM11),"")) | AS11: =IF(ISBLANK($C11),"",IF($AF11=Constants!$B$7,RANK(AR11,$AR$8:$AR$507),$AF11)) | AT11: =IF(ISBLANK($C11),"",IF($AF11=Constants!$B$7,IF(ISNUMBER(AQ11),COUNTIFS($AQ$8:$AQ$507,"<"&$AQ11)+COUNTIFS($AQ$8:$AQ$507,$AQ11,$AS$8:$AS$507,"<"&$AS11)+1,Constants!$B$14),$AF11)) | AU11: =IF(ISBLANK($C11),"",IF($AF11=Constants!$B$7,IF(ISNUMBER(AQ11),AQ11-AT11,Constants!$B$14),$AF11)) | AW11: =IF(ISBLANK($C11),"",IF($AF11<>Constants!$B$7,"",AN11)) | AX11: =IF(ISBLANK($C11),"",IF($AF11<>Constants!$B$7,"",IF(AN11=1,AH11,AK11))) | AY11: =IF(ISBLANK($C11),"",IF($AF11<>Constants!$B$7,"",IF(AN11=1,AI11,AL11))) | AZ11: =IF(ISBLANK($C11),"",IF($AF11<>Constants!$B$7,$AF11,AP11)) | BA11: =IF(ISBLANK($C11),"",IF($AF11<>Constants!$B$7,$AF11,AG11)) | BB11: =IF(ISBLANK($C11),"",AU11) | BC11: =IF(ISBLANK($C11),"",AT11) | BD11: =IF(ISBLANK($C11),"",IFERROR(_xlfn.SWITCH(BC11,Constants!$B$4,COUNTA($C$8:$C$507)+2,Constants!$B$5,COUNTA($C$8:$C$507)+1,Constants!$B$6,COUNTA($C$8:$C$507)),BC11)) | BF11: =IF(OR(ISNUMBER(BC11),BC11=Constants!$B$4,BC11=Constants!$B$6,BC11=Constants!$B$5),1,0) -> 0 | BG11: 4 | BH11: =IF(ISBLANK($C11),"",IF(ISNUMBER(BD11),BD11+ROW($B11)/1000,"")) | BI11: =IF(ISNUMBER(BH11),RANK(BH11,$BH$8:$BH$507,1),"") | BJ11: =IF(ISBLANK($C11),"",$B11) | BK11: =IF(ISBLANK($C11),"",$C11) | BL11: =IF(ISBLANK($C11),"",$D11) | BM11: =BA11 | BN11: =AZ11 | BO11: =IF(ISBLANK($C11),"",BC11) | BP11: =IF($BG11>$BF$7,"",VLOOKUP($BG11,$BI$8:$BO$507,7,FALSE())) | BQ11: =IF($BG11>$BF$7,"",VLOOKUP($BG11,$BI$8:$BO$507,2,FALSE())) | BR11: =IF($BG11>$BF$7,"",VLOOKUP($BG11,$BI$8:$BO$507,3,FALSE())) | BS11: =IF($BG11>$BF$7,"",VLOOKUP($BG11,$BI$8:$BO$507,4,FALSE())) | BT11: =IF($BG11>$BF$7,"",VLOOKUP($BG11,$BI$8:$BO$507,5,FALSE())) | BU11: =IF($BG11>$BF$7,"",VLOOKUP($BG11,$BI$8:$BO$507,6,FALSE()))
R12: =IF(ISBLANK($C12),"",IF(E12=Constants!$B$2, TRUE(), IF(E12=Constants!$B$3, FALSE(), TRUE()))) | S12: =IF(ISBLANK($C12),"",IF(F12=Constants!$B$2, TRUE(), IF(F12=Constants!$B$3, FALSE(), TRUE()))) | T12: =IF(ISBLANK($C12),"",IF(G12=Constants!$B$16,Constants!$B$9,IF(G12=Constants!$B$17,Constants!$B$10,Constants!$B$8))) | U12: =IF(ISBLANK($C12),"",IF(H12=Constants!$B$19,Constants!$B$19,Constants!$B$18)) | V12: =IF(ISBLANK($C12),"",IF(ISNUMBER(I12),IF(I12>=0,I12,""),"")) | W12: =IF(ISBLANK($C12),"",IF(J12=Constants!$B$2, TRUE(), IF(J12=Constants!$B$3, FALSE(), TRUE()))) | X12: =IF(ISBLANK($C12),"",IF(K12=Constants!$B$2, TRUE(), IF(K12=Constants!$B$3, FALSE(), TRUE()))) | Y12: =IF(ISBLANK($C12),"",IF(L12=Constants!$B$19,Constants!$B$19,Constants!$B$18)) | Z12: =IF(ISBLANK($C12),"",IF(ISNUMBER(M12),IF(M12>=0,M12,""),"")) | AA12: =IF(ISBLANK($C12),"",IF(N12=Constants!$B$2, TRUE(), IF(N12=Constants!$B$3, FALSE(), TRUE()))) | AB12: =IF(ISBLANK($C12),"",IF(O12=Constants!$B$2, TRUE(), IF(O12=Constants!$B$3, FALSE(), TRUE()))) | AC12: =IF(ISBLANK($C12),"",IF(P12=Constants!$B$2, TRUE(), IF(P12=Constants!$B$3, FALSE(), FALSE()))) | AD12: =IF(ISBLANK($C12),"",AND(V12<>"",IF(U12=Constants!$B$19,S12,R12))) | AE12: =IF(ISBLANK($C12),"",AND(Z12<>"",IF(Y12=Constants!$B$19,S12,R12))) | AF12: =IF(ISBLANK($C12),"",IF(AC12,Constants!$B$4,IF(COUNTA(E12:O12)=0,Constants!$B$5,IF(AND(NOT(AD12),NOT(AE12)),Constants!$B$6,Constants!$B$7)))) | AG12: =IF(ISBLANK($C12),"",IF($AF12<>Constants!$B$7,$AF12,Constants!$B$20)) | AH12: =IF($AF12=Constants!$B$7,IF(AD12,V12,Constants!$B$13),"") | AI12: =IF($AF12=Constants!$B$7,IF(AD12,T12*IF(W12, 1, Constants!$B$11)*IF(X12, 1, Constants!$B$12),Constants!$B$13),"") | AJ12: =IF($AF12=Constants!$B$7,AH12*AI12,"") | AK12: =IF($AF12=Constants!$B$7,IF(AE12,Z12,Constants!$B$13),"") | AL12: =IF($AF12=Constants!$B$7,IF(AE12,T12*IF(AA12, 1, Constants!$B$11)*IF(AB12, 1, Constants!$B$12),Constants!$B$13),"") | AM12: =IF($AF12=Constants!$B$7,AK12*AL12,"") | AN12: =IF($AF12=Constants!$B$7,IF(AM12>AJ12,2,1),"") | AO12: =IF($AF12=Constants!$B$7,IF(AN12=1,2,1),"") | AP12: =IF(ISBLANK($C12),"",IF($AF12<>Constants!$B$7,$AF12,IF(AN12=1,AJ12,AM12))) | AQ12: =IF(ISBLANK($C12),"",IF($AF12=Constants!$B$7,IF(ISNUMBER(AP12),RANK(AP12,$AP$8:$AP$507),Constants!$B$14),$AF12)) | AR12: =IF(ISBLANK($C12),"",IF($AF12=Constants!$B$7,IF(AO12=1,AJ12,AM12),"")) | AS12: =IF(ISBLANK($C12),"",IF($AF12=Constants!$B$7,RANK(AR12,$AR$8:$AR$507),$AF12)) | AT12: =IF(ISBLANK($C12),"",IF($AF12=Constants!$B$7,IF(ISNUMBER(AQ12),COUNTIFS($AQ$8:$AQ$507,"<"&$AQ12)+COUNTIFS($AQ$8:$AQ$507,$AQ12,$AS$8:$AS$507,"<"&$AS12)+1,Constants!$B$14),$AF12)) | AU12: =IF(ISBLANK($C12),"",IF($AF12=Constants!$B$7,IF(ISNUMBER(AQ12),AQ12-AT12,Constants!$B$14),$AF12)) | AW12: =IF(ISBLANK($C12),"",IF($AF12<>Constants!$B$7,"",AN12)) | AX12: =IF(ISBLANK($C12),"",IF($AF12<>Constants!$B$7,"",IF(AN12=1,AH12,AK12))) | AY12: =IF(ISBLANK($C12),"",IF($AF12<>Constants!$B$7,"",IF(AN12=1,AI12,AL12))) | AZ12: =IF(ISBLANK($C12),"",IF($AF12<>Constants!$B$7,$AF12,AP12)) | BA12: =IF(ISBLANK($C12),"",IF($AF12<>Constants!$B$7,$AF12,AG12)) | BB12: =IF(ISBLANK($C12),"",AU12) | BC12: =IF(ISBLANK($C12),"",AT12) | BD12: =IF(ISBLANK($C12),"",IFERROR(_xlfn.SWITCH(BC12,Constants!$B$4,COUNTA($C$8:$C$507)+2,Constants!$B$5,COUNTA($C$8:$C$507)+1,Constants!$B$6,COUNTA($C$8:$C$507)),BC12)) | BF12: =IF(OR(ISNUMBER(BC12),BC12=Constants!$B$4,BC12=Constants!$B$6,BC12=Constants!$B$5),1,0) -> 0 | BG12: 5 | BH12: =IF(ISBLANK($C12),"",IF(ISNUMBER(BD12),BD12+ROW($B12)/1000,"")) | BI12: =IF(ISNUMBER(BH12),RANK(BH12,$BH$8:$BH$507,1),"") | BJ12: =IF(ISBLANK($C12),"",$B12) | BK12: =IF(ISBLANK($C12),"",$C12) | BL12: =IF(ISBLANK($C12),"",$D12) | BM12: =BA12 | BN12: =AZ12 | BO12: =IF(ISBLANK($C12),"",BC12) | BP12: =IF($BG12>$BF$7,"",VLOOKUP($BG12,$BI$8:$BO$507,7,FALSE())) | BQ12: =IF($BG12>$BF$7,"",VLOOKUP($BG12,$BI$8:$BO$507,2,FALSE())) | BR12: =IF($BG12>$BF$7,"",VLOOKUP($BG12,$BI$8:$BO$507,3,FALSE())) | BS12: =IF($BG12>$BF$7,"",VLOOKUP($BG12,$BI$8:$BO$507,4,FALSE())) | BT12: =IF($BG12>$BF$7,"",VLOOKUP($BG12,$BI$8:$BO$507,5,FALSE())) | BU12: =IF($BG12>$BF$7,"",VLOOKUP($BG12,$BI$8:$BO$507,6,FALSE()))
R13: =IF(ISBLANK($C13),"",IF(E13=Constants!$B$2, TRUE(), IF(E13=Constants!$B$3, FALSE(), TRUE()))) | S13: =IF(ISBLANK($C13),"",IF(F13=Constants!$B$2, TRUE(), IF(F13=Constants!$B$3, FALSE(), TRUE()))) | T13: =IF(ISBLANK($C13),"",IF(G13=Constants!$B$16,Constants!$B$9,IF(G13=Constants!$B$17,Constants!$B$10,Constants!$B$8))) | U13: =IF(ISBLANK($C13),"",IF(H13=Constants!$B$19,Constants!$B$19,Constants!$B$18)) | V13: =IF(ISBLANK($C13),"",IF(ISNUMBER(I13),IF(I13>=0,I13,""),"")) | W13: =IF(ISBLANK($C13),"",IF(J13=Constants!$B$2, TRUE(), IF(J13=Constants!$B$3, FALSE(), TRUE()))) | X13: =IF(ISBLANK($C13),"",IF(K13=Constants!$B$2, TRUE(), IF(K13=Constants!$B$3, FALSE(), TRUE()))) | Y13: =IF(ISBLANK($C13),"",IF(L13=Constants!$B$19,Constants!$B$19,Constants!$B$18)) | Z13: =IF(ISBLANK($C13),"",IF(ISNUMBER(M13),IF(M13>=0,M13,""),"")) | AA13: =IF(ISBLANK($C13),"",IF(N13=Constants!$B$2, TRUE(), IF(N13=Constants!$B$3, FALSE(), TRUE()))) | AB13: =IF(ISBLANK($C13),"",IF(O13=Constants!$B$2, TRUE(), IF(O13=Constants!$B$3, FALSE(), TRUE()))) | AC13: =IF(ISBLANK($C13),"",IF(P13=Constants!$B$2, TRUE(), IF(P13=Constants!$B$3, FALSE(), FALSE()))) | AD13: =IF(ISBLANK($C13),"",AND(V13<>"",IF(U13=Constants!$B$19,S13,R13))) | AE13: =IF(ISBLANK($C13),"",AND(Z13<>"",IF(Y13=Constants!$B$19,S13,R13))) | AF13: =IF(ISBLANK($C13),"",IF(AC13,Constants!$B$4,IF(COUNTA(E13:O13)=0,Constants!$B$5,IF(AND(NOT(AD13),NOT(AE13)),Constants!$B$6,Constants!$B$7)))) | AG13: =IF(ISBLANK($C13),"",IF($AF13<>Constants!$B$7,$AF13,Constants!$B$20)) | AH13: =IF($AF13=Constants!$B$7,IF(AD13,V13,Constants!$B$13),"") | AI13: =IF($AF13=Constants!$B$7,IF(AD13,T13*IF(W13, 1, Constants!$B$11)*IF(X13, 1, Constants!$B$12),Constants!$B$13),"") | AJ13: =IF($AF13=Constants!$B$7,AH13*AI13,"") | AK13: =IF($AF13=Constants!$B$7,IF(AE13,Z13,Constants!$B$13),"") | AL13: =IF($AF13=Constants!$B$7,IF(AE13,T13*IF(AA13, 1, Constants!$B$11)*IF(AB13, 1, Constants!$B$12),Constants!$B$13),"") | AM13: =IF($AF13=Constants!$B$7,AK13*AL13,"") | AN13: =IF($AF13=Constants!$B$7,IF(AM13>AJ13,2,1),"") | AO13: =IF($AF13=Constants!$B$7,IF(AN13=1,2,1),"") | AP13: =IF(ISBLANK($C13),"",IF($AF13<>Constants!$B$7,$AF13,IF(AN13=1,AJ13,AM13))) | AQ13: =IF(ISBLANK($C13),"",IF($AF13=Constants!$B$7,IF(ISNUMBER(AP13),RANK(AP13,$AP$8:$AP$507),Constants!$B$14),$AF13)) | AR13: =IF(ISBLANK($C13),"",IF($AF13=Constants!$B$7,IF(AO13=1,AJ13,AM13),"")) | AS13: =IF(ISBLANK($C13),"",IF($AF13=Constants!$B$7,RANK(AR13,$AR$8:$AR$507),$AF13)) | AT13: =IF(ISBLANK($C13),"",IF($AF13=Constants!$B$7,IF(ISNUMBER(AQ13),COUNTIFS($AQ$8:$AQ$507,"<"&$AQ13)+COUNTIFS($AQ$8:$AQ$507,$AQ13,$AS$8:$AS$507,"<"&$AS13)+1,Constants!$B$14),$AF13)) | AU13: =IF(ISBLANK($C13),"",IF($AF13=Constants!$B$7,IF(ISNUMBER(AQ13),AQ13-AT13,Constants!$B$14),$AF13)) | AW13: =IF(ISBLANK($C13),"",IF($AF13<>Constants!$B$7,"",AN13)) | AX13: =IF(ISBLANK($C13),"",IF($AF13<>Constants!$B$7,"",IF(AN13=1,AH13,AK13))) | AY13: =IF(ISBLANK($C13),"",IF($AF13<>Constants!$B$7,"",IF(AN13=1,AI13,AL13))) | AZ13: =IF(ISBLANK($C13),"",IF($AF13<>Constants!$B$7,$AF13,AP13)) | BA13: =IF(ISBLANK($C13),"",IF($AF13<>Constants!$B$7,$AF13,AG13)) | BB13: =IF(ISBLANK($C13),"",AU13) | BC13: =IF(ISBLANK($C13),"",AT13) | BD13: =IF(ISBLANK($C13),"",IFERROR(_xlfn.SWITCH(BC13,Constants!$B$4,COUNTA($C$8:$C$507)+2,Constants!$B$5,COUNTA($C$8:$C$507)+1,Constants!$B$6,COUNTA($C$8:$C$507)),BC13)) | BF13: =IF(OR(ISNUMBER(BC13),BC13=Constants!$B$4,BC13=Constants!$B$6,BC13=Constants!$B$5),1,0) -> 0 | BG13: 6 | BH13: =IF(ISBLANK($C13),"",IF(ISNUMBER(BD13),BD13+ROW($B13)/1000,"")) | BI13: =IF(ISNUMBER(BH13),RANK(BH13,$BH$8:$BH$507,1),"") | BJ13: =IF(ISBLANK($C13),"",$B13) | BK13: =IF(ISBLANK($C13),"",$C13) | BL13: =IF(ISBLANK($C13),"",$D13) | BM13: =BA13 | BN13: =AZ13 | BO13: =IF(ISBLANK($C13),"",BC13) | BP13: =IF($BG13>$BF$7,"",VLOOKUP($BG13,$BI$8:$BO$507,7,FALSE())) | BQ13: =IF($BG13>$BF$7,"",VLOOKUP($BG13,$BI$8:$BO$507,2,FALSE())) | BR13: =IF($BG13>$BF$7,"",VLOOKUP($BG13,$BI$8:$BO$507,3,FALSE())) | BS13: =IF($BG13>$BF$7,"",VLOOKUP($BG13,$BI$8:$BO$507,4,FALSE())) | BT13: =IF($BG13>$BF$7,"",VLOOKUP($BG13,$BI$8:$BO$507,5,FALSE())) | BU13: =IF($BG13>$BF$7,"",VLOOKUP($BG13,$BI$8:$BO$507,6,FALSE()))
R14: =IF(ISBLANK($C14),"",IF(E14=Constants!$B$2, TRUE(), IF(E14=Constants!$B$3, FALSE(), TRUE()))) | S14: =IF(ISBLANK($C14),"",IF(F14=Constants!$B$2, TRUE(), IF(F14=Constants!$B$3, FALSE(), TRUE()))) | T14: =IF(ISBLANK($C14),"",IF(G14=Constants!$B$16,Constants!$B$9,IF(G14=Constants!$B$17,Constants!$B$10,Constants!$B$8))) | U14: =IF(ISBLANK($C14),"",IF(H14=Constants!$B$19,Constants!$B$19,Constants!$B$18)) | V14: =IF(ISBLANK($C14),"",IF(ISNUMBER(I14),IF(I14>=0,I14,""),"")) | W14: =IF(ISBLANK($C14),"",IF(J14=Constants!$B$2, TRUE(), IF(J14=Constants!$B$3, FALSE(), TRUE()))) | X14: =IF(ISBLANK($C14),"",IF(K14=Constants!$B$2, TRUE(), IF(K14=Constants!$B$3, FALSE(), TRUE()))) | Y14: =IF(ISBLANK($C14),"",IF(L14=Constants!$B$19,Constants!$B$19,Constants!$B$18)) | Z14: =IF(ISBLANK($C14),"",IF(ISNUMBER(M14),IF(M14>=0,M14,""),"")) | AA14: =IF(ISBLANK($C14),"",IF(N14=Constants!$B$2, TRUE(), IF(N14=Constants!$B$3, FALSE(), TRUE()))) | AB14: =IF(ISBLANK($C14),"",IF(O14=Constants!$B$2, TRUE(), IF(O14=Constants!$B$3, FALSE(), TRUE()))) | AC14: =IF(ISBLANK($C14),"",IF(P14=Constants!$B$2, TRUE(), IF(P14=Constants!$B$3, FALSE(), FALSE()))) | AD14: =IF(ISBLANK($C14),"",AND(V14<>"",IF(U14=Constants!$B$19,S14,R14))) | AE14: =IF(ISBLANK($C14),"",AND(Z14<>"",IF(Y14=Constants!$B$19,S14,R14))) | AF14: =IF(ISBLANK($C14),"",IF(AC14,Constants!$B$4,IF(COUNTA(E14:O14)=0,Constants!$B$5,IF(AND(NOT(AD14),NOT(AE14)),Constants!$B$6,Constants!$B$7)))) | AG14: =IF(ISBLANK($C14),"",IF($AF14<>Constants!$B$7,$AF14,Constants!$B$20)) | AH14: =IF($AF14=Constants!$B$7,IF(AD14,V14,Constants!$B$13),"") | AI14: =IF($AF14=Constants!$B$7,IF(AD14,T14*IF(W14, 1, Constants!$B$11)*IF(X14, 1, Constants!$B$12),Constants!$B$13),"") | AJ14: =IF($AF14=Constants!$B$7,AH14*AI14,"") | AK14: =IF($AF14=Constants!$B$7,IF(AE14,Z14,Constants!$B$13),"") | AL14: =IF($AF14=Constants!$B$7,IF(AE14,T14*IF(AA14, 1, Constants!$B$11)*IF(AB14, 1, Constants!$B$12),Constants!$B$13),"") | AM14: =IF($AF14=Constants!$B$7,AK14*AL14,"") | AN14: =IF($AF14=Constants!$B$7,IF(AM14>AJ14,2,1),"") | AO14: =IF($AF14=Constants!$B$7,IF(AN14=1,2,1),"") | AP14: =IF(ISBLANK($C14),"",IF($AF14<>Constants!$B$7,$AF14,IF(AN14=1,AJ14,AM14))) | AQ14: =IF(ISBLANK($C14),"",IF($AF14=Constants!$B$7,IF(ISNUMBER(AP14),RANK(AP14,$AP$8:$AP$507),Constants!$B$14),$AF14)) | AR14: =IF(ISBLANK($C14),"",IF($AF14=Constants!$B$7,IF(AO14=1,AJ14,AM14),"")) | AS14: =IF(ISBLANK($C14),"",IF($AF14=Constants!$B$7,RANK(AR14,$AR$8:$AR$507),$AF14)) | AT14: =IF(ISBLANK($C14),"",IF($AF14=Constants!$B$7,IF(ISNUMBER(AQ14),COUNTIFS($AQ$8:$AQ$507,"<"&$AQ14)+COUNTIFS($AQ$8:$AQ$507,$AQ14,$AS$8:$AS$507,"<"&$AS14)+1,Constants!$B$14),$AF14)) | AU14: =IF(ISBLANK($C14),"",IF($AF14=Constants!$B$7,IF(ISNUMBER(AQ14),AQ14-AT14,Constants!$B$14),$AF14)) | AW14: =IF(ISBLANK($C14),"",IF($AF14<>Constants!$B$7,"",AN14)) | AX14: =IF(ISBLANK($C14),"",IF($AF14<>Constants!$B$7,"",IF(AN14=1,AH14,AK14))) | AY14: =IF(ISBLANK($C14),"",IF($AF14<>Constants!$B$7,"",IF(AN14=1,AI14,AL14))) | AZ14: =IF(ISBLANK($C14),"",IF($AF14<>Constants!$B$7,$AF14,AP14)) | BA14: =IF(ISBLANK($C14),"",IF($AF14<>Constants!$B$7,$AF14,AG14)) | BB14: =IF(ISBLANK($C14),"",AU14) | BC14: =IF(ISBLANK($C14),"",AT14) | BD14: =IF(ISBLANK($C14),"",IFERROR(_xlfn.SWITCH(BC14,Constants!$B$4,COUNTA($C$8:$C$507)+2,Constants!$B$5,COUNTA($C$8:$C$507)+1,Constants!$B$6,COUNTA($C$8:$C$507)),BC14)) | BF14: =IF(OR(ISNUMBER(BC14),BC14=Constants!$B$4,BC14=Constants!$B$6,BC14=Constants!$B$5),1,0) -> 0 | BG14: 7 | BH14: =IF(ISBLANK($C14),"",IF(ISNUMBER(BD14),BD14+ROW($B14)/1000,"")) | BI14: =IF(ISNUMBER(BH14),RANK(BH14,$BH$8:$BH$507,1),"") | BJ14: =IF(ISBLANK($C14),"",$B14) | BK14: =IF(ISBLANK($C14),"",$C14) | BL14: =IF(ISBLANK($C14),"",$D14) | BM14: =BA14 | BN14: =AZ14 | BO14: =IF(ISBLANK($C14),"",BC14) | BP14: =IF($BG14>$BF$7,"",VLOOKUP($BG14,$BI$8:$BO$507,7,FALSE())) | BQ14: =IF($BG14>$BF$7,"",VLOOKUP($BG14,$BI$8:$BO$507,2,FALSE())) | BR14: =IF($BG14>$BF$7,"",VLOOKUP($BG14,$BI$8:$BO$507,3,FALSE())) | BS14: =IF($BG14>$BF$7,"",VLOOKUP($BG14,$BI$8:$BO$507,4,FALSE())) | BT14: =IF($BG14>$BF$7,"",VLOOKUP($BG14,$BI$8:$BO$507,5,FALSE())) | BU14: =IF($BG14>$BF$7,"",VLOOKUP($BG14,$BI$8:$BO$507,6,FALSE()))
R15: =IF(ISBLANK($C15),"",IF(E15=Constants!$B$2, TRUE(), IF(E15=Constants!$B$3, FALSE(), TRUE()))) | S15: =IF(ISBLANK($C15),"",IF(F15=Constants!$B$2, TRUE(), IF(F15=Constants!$B$3, FALSE(), TRUE()))) | T15: =IF(ISBLANK($C15),"",IF(G15=Constants!$B$16,Constants!$B$9,IF(G15=Constants!$B$17,Constants!$B$10,Constants!$B$8))) | U15: =IF(ISBLANK($C15),"",IF(H15=Constants!$B$19,Constants!$B$19,Constants!$B$18)) | V15: =IF(ISBLANK($C15),"",IF(ISNUMBER(I15),IF(I15>=0,I15,""),"")) | W15: =IF(ISBLANK($C15),"",IF(J15=Constants!$B$2, TRUE(), IF(J15=Constants!$B$3, FALSE(), TRUE()))) | X15: =IF(ISBLANK($C15),"",IF(K15=Constants!$B$2, TRUE(), IF(K15=Constants!$B$3, FALSE(), TRUE()))) | Y15: =IF(ISBLANK($C15),"",IF(L15=Constants!$B$19,Constants!$B$19,Constants!$B$18)) | Z15: =IF(ISBLANK($C15),"",IF(ISNUMBER(M15),IF(M15>=0,M15,""),"")) | AA15: =IF(ISBLANK($C15),"",IF(N15=Constants!$B$2, TRUE(), IF(N15=Constants!$B$3, FALSE(), TRUE()))) | AB15: =IF(ISBLANK($C15),"",IF(O15=Constants!$B$2, TRUE(), IF(O15=Constants!$B$3, FALSE(), TRUE()))) | AC15: =IF(ISBLANK($C15),"",IF(P15=Constants!$B$2, TRUE(), IF(P15=Constants!$B$3, FALSE(), FALSE()))) | AD15: =IF(ISBLANK($C15),"",AND(V15<>"",IF(U15=Constants!$B$19,S15,R15))) | AE15: =IF(ISBLANK($C15),"",AND(Z15<>"",IF(Y15=Constants!$B$19,S15,R15))) | AF15: =IF(ISBLANK($C15),"",IF(AC15,Constants!$B$4,IF(COUNTA(E15:O15)=0,Constants!$B$5,IF(AND(NOT(AD15),NOT(AE15)),Constants!$B$6,Constants!$B$7)))) | AG15: =IF(ISBLANK($C15),"",IF($AF15<>Constants!$B$7,$AF15,Constants!$B$20)) | AH15: =IF($AF15=Constants!$B$7,IF(AD15,V15,Constants!$B$13),"") | AI15: =IF($AF15=Constants!$B$7,IF(AD15,T15*IF(W15, 1, Constants!$B$11)*IF(X15, 1, Constants!$B$12),Constants!$B$13),"") | AJ15: =IF($AF15=Constants!$B$7,AH15*AI15,"") | AK15: =IF($AF15=Constants!$B$7,IF(AE15,Z15,Constants!$B$13),"") | AL15: =IF($AF15=Constants!$B$7,IF(AE15,T15*IF(AA15, 1, Constants!$B$11)*IF(AB15, 1, Constants!$B$12),Constants!$B$13),"") | AM15: =IF($AF15=Constants!$B$7,AK15*AL15,"") | AN15: =IF($AF15=Constants!$B$7,IF(AM15>AJ15,2,1),"") | AO15: =IF($AF15=Constants!$B$7,IF(AN15=1,2,1),"") | AP15: =IF(ISBLANK($C15),"",IF($AF15<>Constants!$B$7,$AF15,IF(AN15=1,AJ15,AM15))) | AQ15: =IF(ISBLANK($C15),"",IF($AF15=Constants!$B$7,IF(ISNUMBER(AP15),RANK(AP15,$AP$8:$AP$507),Constants!$B$14),$AF15)) | AR15: =IF(ISBLANK($C15),"",IF($AF15=Constants!$B$7,IF(AO15=1,AJ15,AM15),"")) | AS15: =IF(ISBLANK($C15),"",IF($AF15=Constants!$B$7,RANK(AR15,$AR$8:$AR$507),$AF15)) | AT15: =IF(ISBLANK($C15),"",IF($AF15=Constants!$B$7,IF(ISNUMBER(AQ15),COUNTIFS($AQ$8:$AQ$507,"<"&$AQ15)+COUNTIFS($AQ$8:$AQ$507,$AQ15,$AS$8:$AS$507,"<"&$AS15)+1,Constants!$B$14),$AF15)) | AU15: =IF(ISBLANK($C15),"",IF($AF15=Constants!$B$7,IF(ISNUMBER(AQ15),AQ15-AT15,Constants!$B$14),$AF15)) | AW15: =IF(ISBLANK($C15),"",IF($AF15<>Constants!$B$7,"",AN15)) | AX15: =IF(ISBLANK($C15),"",IF($AF15<>Constants!$B$7,"",IF(AN15=1,AH15,AK15))) | AY15: =IF(ISBLANK($C15),"",IF($AF15<>Constants!$B$7,"",IF(AN15=1,AI15,AL15))) | AZ15: =IF(ISBLANK($C15),"",IF($AF15<>Constants!$B$7,$AF15,AP15)) | BA15: =IF(ISBLANK($C15),"",IF($AF15<>Constants!$B$7,$AF15,AG15)) | BB15: =IF(ISBLANK($C15),"",AU15) | BC15: =IF(ISBLANK($C15),"",AT15) | BD15: =IF(ISBLANK($C15),"",IFERROR(_xlfn.SWITCH(BC15,Constants!$B$4,COUNTA($C$8:$C$507)+2,Constants!$B$5,COUNTA($C$8:$C$507)+1,Constants!$B$6,COUNTA($C$8:$C$507)),BC15)) | BF15: =IF(OR(ISNUMBER(BC15),BC15=Constants!$B$4,BC15=Constants!$B$6,BC15=Constants!$B$5),1,0) -> 0 | BG15: 8 | BH15: =IF(ISBLANK($C15),"",IF(ISNUMBER(BD15),BD15+ROW($B15)/1000,"")) | BI15: =IF(ISNUMBER(BH15),RANK(BH15,$BH$8:$BH$507,1),"") | BJ15: =IF(ISBLANK($C15),"",$B15) | BK15: =IF(ISBLANK($C15),"",$C15) | BL15: =IF(ISBLANK($C15),"",$D15) | BM15: =BA15 | BN15: =AZ15 | BO15: =IF(ISBLANK($C15),"",BC15) | BP15: =IF($BG15>$BF$7,"",VLOOKUP($BG15,$BI$8:$BO$507,7,FALSE())) | BQ15: =IF($BG15>$BF$7,"",VLOOKUP($BG15,$BI$8:$BO$507,2,FALSE())) | BR15: =IF($BG15>$BF$7,"",VLOOKUP($BG15,$BI$8:$BO$507,3,FALSE())) | BS15: =IF($BG15>$BF$7,"",VLOOKUP($BG15,$BI$8:$BO$507,4,FALSE())) | BT15: =IF($BG15>$BF$7,"",VLOOKUP($BG15,$BI$8:$BO$507,5,FALSE())) | BU15: =IF($BG15>$BF$7,"",VLOOKUP($BG15,$BI$8:$BO$507,6,FALSE()))
R16: =IF(ISBLANK($C16),"",IF(E16=Constants!$B$2, TRUE(), IF(E16=Constants!$B$3, FALSE(), TRUE()))) | S16: =IF(ISBLANK($C16),"",IF(F16=Constants!$B$2, TRUE(), IF(F16=Constants!$B$3, FALSE(), TRUE()))) | T16: =IF(ISBLANK($C16),"",IF(G16=Constants!$B$16,Constants!$B$9,IF(G16=Constants!$B$17,Constants!$B$10,Constants!$B$8))) | U16: =IF(ISBLANK($C16),"",IF(H16=Constants!$B$19,Constants!$B$19,Constants!$B$18)) | V16: =IF(ISBLANK($C16),"",IF(ISNUMBER(I16),IF(I16>=0,I16,""),"")) | W16: =IF(ISBLANK($C16),"",IF(J16=Constants!$B$2, TRUE(), IF(J16=Constants!$B$3, FALSE(), TRUE()))) | X16: =IF(ISBLANK($C16),"",IF(K16=Constants!$B$2, TRUE(), IF(K16=Constants!$B$3, FALSE(), TRUE()))) | Y16: =IF(ISBLANK($C16),"",IF(L16=Constants!$B$19,Constants!$B$19,Constants!$B$18)) | Z16: =IF(ISBLANK($C16),"",IF(ISNUMBER(M16),IF(M16>=0,M16,""),"")) | AA16: =IF(ISBLANK($C16),"",IF(N16=Constants!$B$2, TRUE(), IF(N16=Constants!$B$3, FALSE(), TRUE()))) | AB16: =IF(ISBLANK($C16),"",IF(O16=Constants!$B$2, TRUE(), IF(O16=Constants!$B$3, FALSE(), TRUE()))) | AC16: =IF(ISBLANK($C16),"",IF(P16=Constants!$B$2, TRUE(), IF(P16=Constants!$B$3, FALSE(), FALSE()))) | AD16: =IF(ISBLANK($C16),"",AND(V16<>"",IF(U16=Constants!$B$19,S16,R16))) | AE16: =IF(ISBLANK($C16),"",AND(Z16<>"",IF(Y16=Constants!$B$19,S16,R16))) | AF16: =IF(ISBLANK($C16),"",IF(AC16,Constants!$B$4,IF(COUNTA(E16:O16)=0,Constants!$B$5,IF(AND(NOT(AD16),NOT(AE16)),Constants!$B$6,Constants!$B$7)))) | AG16: =IF(ISBLANK($C16),"",IF($AF16<>Constants!$B$7,$AF16,Constants!$B$20)) | AH16: =IF($AF16=Constants!$B$7,IF(AD16,V16,Constants!$B$13),"") | AI16: =IF($AF16=Constants!$B$7,IF(AD16,T16*IF(W16, 1, Constants!$B$11)*IF(X16, 1, Constants!$B$12),Constants!$B$13),"") | AJ16: =IF($AF16=Constants!$B$7,AH16*AI16,"") | AK16: =IF($AF16=Constants!$B$7,IF(AE16,Z16,Constants!$B$13),"") | AL16: =IF($AF16=Constants!$B$7,IF(AE16,T16*IF(AA16, 1, Constants!$B$11)*IF(AB16, 1, Constants!$B$12),Constants!$B$13),"") | AM16: =IF($AF16=Constants!$B$7,AK16*AL16,"") | AN16: =IF($AF16=Constants!$B$7,IF(AM16>AJ16,2,1),"") | AO16: =IF($AF16=Constants!$B$7,IF(AN16=1,2,1),"") | AP16: =IF(ISBLANK($C16),"",IF($AF16<>Constants!$B$7,$AF16,IF(AN16=1,AJ16,AM16))) | AQ16: =IF(ISBLANK($C16),"",IF($AF16=Constants!$B$7,IF(ISNUMBER(AP16),RANK(AP16,$AP$8:$AP$507),Constants!$B$14),$AF16)) | AR16: =IF(ISBLANK($C16),"",IF($AF16=Constants!$B$7,IF(AO16=1,AJ16,AM16),"")) | AS16: =IF(ISBLANK($C16),"",IF($AF16=Constants!$B$7,RANK(AR16,$AR$8:$AR$507),$AF16)) | AT16: =IF(ISBLANK($C16),"",IF($AF16=Constants!$B$7,IF(ISNUMBER(AQ16),COUNTIFS($AQ$8:$AQ$507,"<"&$AQ16)+COUNTIFS($AQ$8:$AQ$507,$AQ16,$AS$8:$AS$507,"<"&$AS16)+1,Constants!$B$14),$AF16)) | AU16: =IF(ISBLANK($C16),"",IF($AF16=Constants!$B$7,IF(ISNUMBER(AQ16),AQ16-AT16,Constants!$B$14),$AF16)) | AW16: =IF(ISBLANK($C16),"",IF($AF16<>Constants!$B$7,"",AN16)) | AX16: =IF(ISBLANK($C16),"",IF($AF16<>Constants!$B$7,"",IF(AN16=1,AH16,AK16))) | AY16: =IF(ISBLANK($C16),"",IF($AF16<>Constants!$B$7,"",IF(AN16=1,AI16,AL16))) | AZ16: =IF(ISBLANK($C16),"",IF($AF16<>Constants!$B$7,$AF16,AP16)) | BA16: =IF(ISBLANK($C16),"",IF($AF16<>Constants!$B$7,$AF16,AG16)) | BB16: =IF(ISBLANK($C16),"",AU16) | BC16: =IF(ISBLANK($C16),"",AT16) | BD16: =IF(ISBLANK($C16),"",IFERROR(_xlfn.SWITCH(BC16,Constants!$B$4,COUNTA($C$8:$C$507)+2,Constants!$B$5,COUNTA($C$8:$C$507)+1,Constants!$B$6,COUNTA($C$8:$C$507)),BC16)) | BF16: =IF(OR(ISNUMBER(BC16),BC16=Constants!$B$4,BC16=Constants!$B$6,BC16=Constants!$B$5),1,0) -> 0 | BG16: 9 | BH16: =IF(ISBLANK($C16),"",IF(ISNUMBER(BD16),BD16+ROW($B16)/1000,"")) | BI16: =IF(ISNUMBER(BH16),RANK(BH16,$BH$8:$BH$507,1),"") | BJ16: =IF(ISBLANK($C16),"",$B16) | BK16: =IF(ISBLANK($C16),"",$C16) | BL16: =IF(ISBLANK($C16),"",$D16) | BM16: =BA16 | BN16: =AZ16 | BO16: =IF(ISBLANK($C16),"",BC16) | BP16: =IF($BG16>$BF$7,"",VLOOKUP($BG16,$BI$8:$BO$507,7,FALSE())) | BQ16: =IF($BG16>$BF$7,"",VLOOKUP($BG16,$BI$8:$BO$507,2,FALSE())) | BR16: =IF($BG16>$BF$7,"",VLOOKUP($BG16,$BI$8:$BO$507,3,FALSE())) | BS16: =IF($BG16>$BF$7,"",VLOOKUP($BG16,$BI$8:$BO$507,4,FALSE())) | BT16: =IF($BG16>$BF$7,"",VLOOKUP($BG16,$BI$8:$BO$507,5,FALSE())) | BU16: =IF($BG16>$BF$7,"",VLOOKUP($BG16,$BI$8:$BO$507,6,FALSE()))
R17: =IF(ISBLANK($C17),"",IF(E17=Constants!$B$2, TRUE(), IF(E17=Constants!$B$3, FALSE(), TRUE()))) | S17: =IF(ISBLANK($C17),"",IF(F17=Constants!$B$2, TRUE(), IF(F17=Constants!$B$3, FALSE(), TRUE()))) | T17: =IF(ISBLANK($C17),"",IF(G17=Constants!$B$16,Constants!$B$9,IF(G17=Constants!$B$17,Constants!$B$10,Constants!$B$8))) | U17: =IF(ISBLANK($C17),"",IF(H17=Constants!$B$19,Constants!$B$19,Constants!$B$18)) | V17: =IF(ISBLANK($C17),"",IF(ISNUMBER(I17),IF(I17>=0,I17,""),"")) | W17: =IF(ISBLANK($C17),"",IF(J17=Constants!$B$2, TRUE(), IF(J17=Constants!$B$3, FALSE(), TRUE()))) | X17: =IF(ISBLANK($C17),"",IF(K17=Constants!$B$2, TRUE(), IF(K17=Constants!$B$3, FALSE(), TRUE()))) | Y17: =IF(ISBLANK($C17),"",IF(L17=Constants!$B$19,Constants!$B$19,Constants!$B$18)) | Z17: =IF(ISBLANK($C17),"",IF(ISNUMBER(M17),IF(M17>=0,M17,""),"")) | AA17: =IF(ISBLANK($C17),"",IF(N17=Constants!$B$2, TRUE(), IF(N17=Constants!$B$3, FALSE(), TRUE()))) | AB17: =IF(ISBLANK($C17),"",IF(O17=Constants!$B$2, TRUE(), IF(O17=Constants!$B$3, FALSE(), TRUE()))) | AC17: =IF(ISBLANK($C17),"",IF(P17=Constants!$B$2, TRUE(), IF(P17=Constants!$B$3, FALSE(), FALSE()))) | AD17: =IF(ISBLANK($C17),"",AND(V17<>"",IF(U17=Constants!$B$19,S17,R17))) | AE17: =IF(ISBLANK($C17),"",AND(Z17<>"",IF(Y17=Constants!$B$19,S17,R17))) | AF17: =IF(ISBLANK($C17),"",IF(AC17,Constants!$B$4,IF(COUNTA(E17:O17)=0,Constants!$B$5,IF(AND(NOT(AD17),NOT(AE17)),Constants!$B$6,Constants!$B$7)))) | AG17: =IF(ISBLANK($C17),"",IF($AF17<>Constants!$B$7,$AF17,Constants!$B$20)) | AH17: =IF($AF17=Constants!$B$7,IF(AD17,V17,Constants!$B$13),"") | AI17: =IF($AF17=Constants!$B$7,IF(AD17,T17*IF(W17, 1, Constants!$B$11)*IF(X17, 1, Constants!$B$12),Constants!$B$13),"") | AJ17: =IF($AF17=Constants!$B$7,AH17*AI17,"") | AK17: =IF($AF17=Constants!$B$7,IF(AE17,Z17,Constants!$B$13),"") | AL17: =IF($AF17=Constants!$B$7,IF(AE17,T17*IF(AA17, 1, Constants!$B$11)*IF(AB17, 1, Constants!$B$12),Constants!$B$13),"") | AM17: =IF($AF17=Constants!$B$7,AK17*AL17,"") | AN17: =IF($AF17=Constants!$B$7,IF(AM17>AJ17,2,1),"") | AO17: =IF($AF17=Constants!$B$7,IF(AN17=1,2,1),"") | AP17: =IF(ISBLANK($C17),"",IF($AF17<>Constants!$B$7,$AF17,IF(AN17=1,AJ17,AM17))) | AQ17: =IF(ISBLANK($C17),"",IF($AF17=Constants!$B$7,IF(ISNUMBER(AP17),RANK(AP17,$AP$8:$AP$507),Constants!$B$14),$AF17)) | AR17: =IF(ISBLANK($C17),"",IF($AF17=Constants!$B$7,IF(AO17=1,AJ17,AM17),"")) | AS17: =IF(ISBLANK($C17),"",IF($AF17=Constants!$B$7,RANK(AR17,$AR$8:$AR$507),$AF17)) | AT17: =IF(ISBLANK($C17),"",IF($AF17=Constants!$B$7,IF(ISNUMBER(AQ17),COUNTIFS($AQ$8:$AQ$507,"<"&$AQ17)+COUNTIFS($AQ$8:$AQ$507,$AQ17,$AS$8:$AS$507,"<"&$AS17)+1,Constants!$B$14),$AF17)) | AU17: =IF(ISBLANK($C17),"",IF($AF17=Constants!$B$7,IF(ISNUMBER(AQ17),AQ17-AT17,Constants!$B$14),$AF17)) | AW17: =IF(ISBLANK($C17),"",IF($AF17<>Constants!$B$7,"",AN17)) | AX17: =IF(ISBLANK($C17),"",IF($AF17<>Constants!$B$7,"",IF(AN17=1,AH17,AK17))) | AY17: =IF(ISBLANK($C17),"",IF($AF17<>Constants!$B$7,"",IF(AN17=1,AI17,AL17))) | AZ17: =IF(ISBLANK($C17),"",IF($AF17<>Constants!$B$7,$AF17,AP17)) | BA17: =IF(ISBLANK($C17),"",IF($AF17<>Constants!$B$7,$AF17,AG17)) | BB17: =IF(ISBLANK($C17),"",AU17) | BC17: =IF(ISBLANK($C17),"",AT17) | BD17: =IF(ISBLANK($C17),"",IFERROR(_xlfn.SWITCH(BC17,Constants!$B$4,COUNTA($C$8:$C$507)+2,Constants!$B$5,COUNTA($C$8:$C$507)+1,Constants!$B$6,COUNTA($C$8:$C$507)),BC17)) | BF17: =IF(OR(ISNUMBER(BC17),BC17=Constants!$B$4,BC17=Constants!$B$6,BC17=Constants!$B$5),1,0) -> 0 | BG17: 10 | BH17: =IF(ISBLANK($C17),"",IF(ISNUMBER(BD17),BD17+ROW($B17)/1000,"")) | BI17: =IF(ISNUMBER(BH17),RANK(BH17,$BH$8:$BH$507,1),"") | BJ17: =IF(ISBLANK($C17),"",$B17) | BK17: =IF(ISBLANK($C17),"",$C17) | BL17: =IF(ISBLANK($C17),"",$D17) | BM17: =BA17 | BN17: =AZ17 | BO17: =IF(ISBLANK($C17),"",BC17) | BP17: =IF($BG17>$BF$7,"",VLOOKUP($BG17,$BI$8:$BO$507,7,FALSE())) | BQ17: =IF($BG17>$BF$7,"",VLOOKUP($BG17,$BI$8:$BO$507,2,FALSE())) | BR17: =IF($BG17>$BF$7,"",VLOOKUP($BG17,$BI$8:$BO$507,3,FALSE())) | BS17: =IF($BG17>$BF$7,"",VLOOKUP($BG17,$BI$8:$BO$507,4,FALSE())) | BT17: =IF($BG17>$BF$7,"",VLOOKUP($BG17,$BI$8:$BO$507,5,FALSE())) | BU17: =IF($BG17>$BF$7,"",VLOOKUP($BG17,$BI$8:$BO$507,6,FALSE()))
R18: =IF(ISBLANK($C18),"",IF(E18=Constants!$B$2, TRUE(), IF(E18=Constants!$B$3, FALSE(), TRUE()))) | S18: =IF(ISBLANK($C18),"",IF(F18=Constants!$B$2, TRUE(), IF(F18=Constants!$B$3, FALSE(), TRUE()))) | T18: =IF(ISBLANK($C18),"",IF(G18=Constants!$B$16,Constants!$B$9,IF(G18=Constants!$B$17,Constants!$B$10,Constants!$B$8))) | U18: =IF(ISBLANK($C18),"",IF(H18=Constants!$B$19,Constants!$B$19,Constants!$B$18)) | V18: =IF(ISBLANK($C18),"",IF(ISNUMBER(I18),IF(I18>=0,I18,""),"")) | W18: =IF(ISBLANK($C18),"",IF(J18=Constants!$B$2, TRUE(), IF(J18=Constants!$B$3, FALSE(), TRUE()))) | X18: =IF(ISBLANK($C18),"",IF(K18=Constants!$B$2, TRUE(), IF(K18=Constants!$B$3, FALSE(), TRUE()))) | Y18: =IF(ISBLANK($C18),"",IF(L18=Constants!$B$19,Constants!$B$19,Constants!$B$18)) | Z18: =IF(ISBLANK($C18),"",IF(ISNUMBER(M18),IF(M18>=0,M18,""),"")) | AA18: =IF(ISBLANK($C18),"",IF(N18=Constants!$B$2, TRUE(), IF(N18=Constants!$B$3, FALSE(), TRUE()))) | AB18: =IF(ISBLANK($C18),"",IF(O18=Constants!$B$2, TRUE(), IF(O18=Constants!$B$3, FALSE(), TRUE()))) | AC18: =IF(ISBLANK($C18),"",IF(P18=Constants!$B$2, TRUE(), IF(P18=Constants!$B$3, FALSE(), FALSE()))) | AD18: =IF(ISBLANK($C18),"",AND(V18<>"",IF(U18=Constants!$B$19,S18,R18))) | AE18: =IF(ISBLANK($C18),"",AND(Z18<>"",IF(Y18=Constants!$B$19,S18,R18))) | AF18: =IF(ISBLANK($C18),"",IF(AC18,Constants!$B$4,IF(COUNTA(E18:O18)=0,Constants!$B$5,IF(AND(NOT(AD18),NOT(AE18)),Constants!$B$6,Constants!$B$7)))) | AG18: =IF(ISBLANK($C18),"",IF($AF18<>Constants!$B$7,$AF18,Constants!$B$20)) | AH18: =IF($AF18=Constants!$B$7,IF(AD18,V18,Constants!$B$13),"") | AI18: =IF($AF18=Constants!$B$7,IF(AD18,T18*IF(W18, 1, Constants!$B$11)*IF(X18, 1, Constants!$B$12),Constants!$B$13),"") | AJ18: =IF($AF18=Constants!$B$7,AH18*AI18,"") | AK18: =IF($AF18=Constants!$B$7,IF(AE18,Z18,Constants!$B$13),"") | AL18: =IF($AF18=Constants!$B$7,IF(AE18,T18*IF(AA18, 1, Constants!$B$11)*IF(AB18, 1, Constants!$B$12),Constants!$B$13),"") | AM18: =IF($AF18=Constants!$B$7,AK18*AL18,"") | AN18: =IF($AF18=Constants!$B$7,IF(AM18>AJ18,2,1),"") | AO18: =IF($AF18=Constants!$B$7,IF(AN18=1,2,1),"") | AP18: =IF(ISBLANK($C18),"",IF($AF18<>Constants!$B$7,$AF18,IF(AN18=1,AJ18,AM18))) | AQ18: =IF(ISBLANK($C18),"",IF($AF18=Constants!$B$7,IF(ISNUMBER(AP18),RANK(AP18,$AP$8:$AP$507),Constants!$B$14),$AF18)) | AR18: =IF(ISBLANK($C18),"",IF($AF18=Constants!$B$7,IF(AO18=1,AJ18,AM18),"")) | AS18: =IF(ISBLANK($C18),"",IF($AF18=Constants!$B$7,RANK(AR18,$AR$8:$AR$507),$AF18)) | AT18: =IF(ISBLANK($C18),"",IF($AF18=Constants!$B$7,IF(ISNUMBER(AQ18),COUNTIFS($AQ$8:$AQ$507,"<"&$AQ18)+COUNTIFS($AQ$8:$AQ$507,$AQ18,$AS$8:$AS$507,"<"&$AS18)+1,Constants!$B$14),$AF18)) | AU18: =IF(ISBLANK($C18),"",IF($AF18=Constants!$B$7,IF(ISNUMBER(AQ18),AQ18-AT18,Constants!$B$14),$AF18)) | AW18: =IF(ISBLANK($C18),"",IF($AF18<>Constants!$B$7,"",AN18)) | AX18: =IF(ISBLANK($C18),"",IF($AF18<>Constants!$B$7,"",IF(AN18=1,AH18,AK18))) | AY18: =IF(ISBLANK($C18),"",IF($AF18<>Constants!$B$7,"",IF(AN18=1,AI18,AL18))) | AZ18: =IF(ISBLANK($C18),"",IF($AF18<>Constants!$B$7,$AF18,AP18)) | BA18: =IF(ISBLANK($C18),"",IF($AF18<>Constants!$B$7,$AF18,AG18)) | BB18: =IF(ISBLANK($C18),"",AU18) | BC18: =IF(ISBLANK($C18),"",AT18) | BD18: =IF(ISBLANK($C18),"",IFERROR(_xlfn.SWITCH(BC18,Constants!$B$4,COUNTA($C$8:$C$507)+2,Constants!$B$5,COUNTA($C$8:$C$507)+1,Constants!$B$6,COUNTA($C$8:$C$507)),BC18)) | BF18: =IF(OR(ISNUMBER(BC18),BC18=Constants!$B$4,BC18=Constants!$B$6,BC18=Constants!$B$5),1,0) -> 0 | BG18: 11 | BH18: =IF(ISBLANK($C18),"",IF(ISNUMBER(BD18),BD18+ROW($B18)/1000,"")) | BI18: =IF(ISNUMBER(BH18),RANK(BH18,$BH$8:$BH$507,1),"") | BJ18: =IF(ISBLANK($C18),"",$B18) | BK18: =IF(ISBLANK($C18),"",$C18) | BL18: =IF(ISBLANK($C18),"",$D18) | BM18: =BA18 | BN18: =AZ18 | BO18: =IF(ISBLANK($C18),"",BC18) | BP18: =IF($BG18>$BF$7,"",VLOOKUP($BG18,$BI$8:$BO$507,7,FALSE())) | BQ18: =IF($BG18>$BF$7,"",VLOOKUP($BG18,$BI$8:$BO$507,2,FALSE())) | BR18: =IF($BG18>$BF$7,"",VLOOKUP($BG18,$BI$8:$BO$507,3,FALSE())) | BS18: =IF($BG18>$BF$7,"",VLOOKUP($BG18,$BI$8:$BO$507,4,FALSE())) | BT18: =IF($BG18>$BF$7,"",VLOOKUP($BG18,$BI$8:$BO$507,5,FALSE())) | BU18: =IF($BG18>$BF$7,"",VLOOKUP($BG18,$BI$8:$BO$507,6,FALSE()))
R19: =IF(ISBLANK($C19),"",IF(E19=Constants!$B$2, TRUE(), IF(E19=Constants!$B$3, FALSE(), TRUE()))) | S19: =IF(ISBLANK($C19),"",IF(F19=Constants!$B$2, TRUE(), IF(F19=Constants!$B$3, FALSE(), TRUE()))) | T19: =IF(ISBLANK($C19),"",IF(G19=Constants!$B$16,Constants!$B$9,IF(G19=Constants!$B$17,Constants!$B$10,Constants!$B$8))) | U19: =IF(ISBLANK($C19),"",IF(H19=Constants!$B$19,Constants!$B$19,Constants!$B$18)) | V19: =IF(ISBLANK($C19),"",IF(ISNUMBER(I19),IF(I19>=0,I19,""),"")) | W19: =IF(ISBLANK($C19),"",IF(J19=Constants!$B$2, TRUE(), IF(J19=Constants!$B$3, FALSE(), TRUE()))) | X19: =IF(ISBLANK($C19),"",IF(K19=Constants!$B$2, TRUE(), IF(K19=Constants!$B$3, FALSE(), TRUE()))) | Y19: =IF(ISBLANK($C19),"",IF(L19=Constants!$B$19,Constants!$B$19,Constants!$B$18)) | Z19: =IF(ISBLANK($C19),"",IF(ISNUMBER(M19),IF(M19>=0,M19,""),"")) | AA19: =IF(ISBLANK($C19),"",IF(N19=Constants!$B$2, TRUE(), IF(N19=Constants!$B$3, FALSE(), TRUE()))) | AB19: =IF(ISBLANK($C19),"",IF(O19=Constants!$B$2, TRUE(), IF(O19=Constants!$B$3, FALSE(), TRUE()))) | AC19: =IF(ISBLANK($C19),"",IF(P19=Constants!$B$2, TRUE(), IF(P19=Constants!$B$3, FALSE(), FALSE()))) | AD19: =IF(ISBLANK($C19),"",AND(V19<>"",IF(U19=Constants!$B$19,S19,R19))) | AE19: =IF(ISBLANK($C19),"",AND(Z19<>"",IF(Y19=Constants!$B$19,S19,R19))) | AF19: =IF(ISBLANK($C19),"",IF(AC19,Constants!$B$4,IF(COUNTA(E19:O19)=0,Constants!$B$5,IF(AND(NOT(AD19),NOT(AE19)),Constants!$B$6,Constants!$B$7)))) | AG19: =IF(ISBLANK($C19),"",IF($AF19<>Constants!$B$7,$AF19,Constants!$B$20)) | AH19: =IF($AF19=Constants!$B$7,IF(AD19,V19,Constants!$B$13),"") | AI19: =IF($AF19=Constants!$B$7,IF(AD19,T19*IF(W19, 1, Constants!$B$11)*IF(X19, 1, Constants!$B$12),Constants!$B$13),"") | AJ19: =IF($AF19=Constants!$B$7,AH19*AI19,"") | AK19: =IF($AF19=Constants!$B$7,IF(AE19,Z19,Constants!$B$13),"") | AL19: =IF($AF19=Constants!$B$7,IF(AE19,T19*IF(AA19, 1, Constants!$B$11)*IF(AB19, 1, Constants!$B$12),Constants!$B$13),"") | AM19: =IF($AF19=Constants!$B$7,AK19*AL19,"") | AN19: =IF($AF19=Constants!$B$7,IF(AM19>AJ19,2,1),"") | AO19: =IF($AF19=Constants!$B$7,IF(AN19=1,2,1),"") | AP19: =IF(ISBLANK($C19),"",IF($AF19<>Constants!$B$7,$AF19,IF(AN19=1,AJ19,AM19))) | AQ19: =IF(ISBLANK($C19),"",IF($AF19=Constants!$B$7,IF(ISNUMBER(AP19),RANK(AP19,$AP$8:$AP$507),Constants!$B$14),$AF19)) | AR19: =IF(ISBLANK($C19),"",IF($AF19=Constants!$B$7,IF(AO19=1,AJ19,AM19),"")) | AS19: =IF(ISBLANK($C19),"",IF($AF19=Constants!$B$7,RANK(AR19,$AR$8:$AR$507),$AF19)) | AT19: =IF(ISBLANK($C19),"",IF($AF19=Constants!$B$7,IF(ISNUMBER(AQ19),COUNTIFS($AQ$8:$AQ$507,"<"&$AQ19)+COUNTIFS($AQ$8:$AQ$507,$AQ19,$AS$8:$AS$507,"<"&$AS19)+1,Constants!$B$14),$AF19)) | AU19: =IF(ISBLANK($C19),"",IF($AF19=Constants!$B$7,IF(ISNUMBER(AQ19),AQ19-AT19,Constants!$B$14),$AF19)) | AW19: =IF(ISBLANK($C19),"",IF($AF19<>Constants!$B$7,"",AN19)) | AX19: =IF(ISBLANK($C19),"",IF($AF19<>Constants!$B$7,"",IF(AN19=1,AH19,AK19))) | AY19: =IF(ISBLANK($C19),"",IF($AF19<>Constants!$B$7,"",IF(AN19=1,AI19,AL19))) | AZ19: =IF(ISBLANK($C19),"",IF($AF19<>Constants!$B$7,$AF19,AP19)) | BA19: =IF(ISBLANK($C19),"",IF($AF19<>Constants!$B$7,$AF19,AG19)) | BB19: =IF(ISBLANK($C19),"",AU19) | BC19: =IF(ISBLANK($C19),"",AT19) | BD19: =IF(ISBLANK($C19),"",IFERROR(_xlfn.SWITCH(BC19,Constants!$B$4,COUNTA($C$8:$C$507)+2,Constants!$B$5,COUNTA($C$8:$C$507)+1,Constants!$B$6,COUNTA($C$8:$C$507)),BC19)) | BF19: =IF(OR(ISNUMBER(BC19),BC19=Constants!$B$4,BC19=Constants!$B$6,BC19=Constants!$B$5),1,0) -> 0 | BG19: 12 | BH19: =IF(ISBLANK($C19),"",IF(ISNUMBER(BD19),BD19+ROW($B19)/1000,"")) | BI19: =IF(ISNUMBER(BH19),RANK(BH19,$BH$8:$BH$507,1),"") | BJ19: =IF(ISBLANK($C19),"",$B19) | BK19: =IF(ISBLANK($C19),"",$C19) | BL19: =IF(ISBLANK($C19),"",$D19) | BM19: =BA19 | BN19: =AZ19 | BO19: =IF(ISBLANK($C19),"",BC19) | BP19: =IF($BG19>$BF$7,"",VLOOKUP($BG19,$BI$8:$BO$507,7,FALSE())) | BQ19: =IF($BG19>$BF$7,"",VLOOKUP($BG19,$BI$8:$BO$507,2,FALSE())) | BR19: =IF($BG19>$BF$7,"",VLOOKUP($BG19,$BI$8:$BO$507,3,FALSE())) | BS19: =IF($BG19>$BF$7,"",VLOOKUP($BG19,$BI$8:$BO$507,4,FALSE())) | BT19: =IF($BG19>$BF$7,"",VLOOKUP($BG19,$BI$8:$BO$507,5,FALSE())) | BU19: =IF($BG19>$BF$7,"",VLOOKUP($BG19,$BI$8:$BO$507,6,FALSE()))
... R507: =IF(ISBLANK($C507),"",IF(E507=Constants!$B$2, TRUE(), IF(E507=Constants!$B$3, FALSE(), TRUE()))) | S507: =IF(ISBLANK($C507),"",IF(F507=Constants!$B$2, TRUE(), IF(F507=Constants!$B$3, FALSE(), TRUE()))) | T507: =IF(ISBLANK($C507),"",IF(G507=Constants!$B$16,Constants!$B$9,IF(G507=Constants!$B$17,Constants!$B$10,Constants!$B$8))) | U507: =IF(ISBLANK($C507),"",IF(H507=Constants!$B$19,Constants!$B$19,Constants!$B$18)) | V507: =IF(ISBLANK($C507),"",IF(ISNUMBER(I507),IF(I507>=0,I507,""),"")) | W507: =IF(ISBLANK($C507),"",IF(J507=Constants!$B$2, TRUE(), IF(J507=Constants!$B$3, FALSE(), TRUE()))) | X507: =IF(ISBLANK($C507),"",IF(K507=Constants!$B$2, TRUE(), IF(K507=Constants!$B$3, FALSE(), TRUE()))) | Y507: =IF(ISBLANK($C507),"",IF(L507=Constants!$B$19,Constants!$B$19,Constants!$B$18)) | Z507: =IF(ISBLANK($C507),"",IF(ISNUMBER(M507),IF(M507>=0,M507,""),"")) | AA507: =IF(ISBLANK($C507),"",IF(N507=Constants!$B$2, TRUE(), IF(N507=Constants!$B$3, FALSE(), TRUE()))) | AB507: =IF(ISBLANK($C507),"",IF(O507=Constants!$B$2, TRUE(), IF(O507=Constants!$B$3, FALSE(), TRUE()))) | AC507: =IF(ISBLANK($C507),"",IF(P507=Constants!$B$2, TRUE(), IF(P507=Constants!$B$3, FALSE(), FALSE()))) | AD507: =IF(ISBLANK($C507),"",AND(V507<>"",IF(U507=Constants!$B$19,S507,R507))) | AE507: =IF(ISBLANK($C507),"",AND(Z507<>"",IF(Y507=Constants!$B$19,S507,R507))) | AF507: =IF(ISBLANK($C507),"",IF(AC507,Constants!$B$4,IF(COUNTA(E507:O507)=0,Constants!$B$5,IF(AND(NOT(AD507),NOT(AE507)),Constants!$B$6,Constants!$B$7)))) | AG507: =IF(ISBLANK($C507),"",IF($AF507<>Constants!$B$7,$AF507,Constants!$B$20)) | AH507: =IF($AF507=Constants!$B$7,IF(AD507,V507,Constants!$B$13),"") | AI507: =IF($AF507=Constants!$B$7,IF(AD507,T507*IF(W507, 1, Constants!$B$11)*IF(X507, 1, Constants!$B$12),Constants!$B$13),"") | AJ507: =IF($AF507=Constants!$B$7,AH507*AI507,"") | AK507: =IF($AF507=Constants!$B$7,IF(AE507,Z507,Constants!$B$13),"") | AL507: =IF($AF507=Constants!$B$7,IF(AE507,T507*IF(AA507, 1, Constants!$B$11)*IF(AB507, 1, Constants!$B$12),Constants!$B$13),"") | AM507: =IF($AF507=Constants!$B$7,AK507*AL507,"") | AN507: =IF($AF507=Constants!$B$7,IF(AM507>AJ507,2,1),"") | AO507: =IF($AF507=Constants!$B$7,IF(AN507=1,2,1),"") | AP507: =IF(ISBLANK($C507),"",IF($AF507<>Constants!$B$7,$AF507,IF(AN507=1,AJ507,AM507))) | AQ507: =IF(ISBLANK($C507),"",IF($AF507=Constants!$B$7,IF(ISNUMBER(AP507),RANK(AP507,$AP$8:$AP$507),Constants!$B$14),$AF507)) | AR507: =IF(ISBLANK($C507),"",IF($AF507=Constants!$B$7,IF(AO507=1,AJ507,AM507),"")) | AS507: =IF(ISBLANK($C507),"",IF($AF507=Constants!$B$7,RANK(AR507,$AR$8:$AR$507),$AF507)) | AT507: =IF(ISBLANK($C507),"",IF($AF507=Constants!$B$7,IF(ISNUMBER(AQ507),COUNTIFS($AQ$8:$AQ$507,"<"&$AQ507)+COUNTIFS($AQ$8:$AQ$507,$AQ507,$AS$8:$AS$507,"<"&$AS507)+1,Constants!$B$14),$AF507)) | AU507: =IF(ISBLANK($C507),"",IF($AF507=Constants!$B$7,IF(ISNUMBER(AQ507),AQ507-AT507,Constants!$B$14),$AF507)) | AW507: =IF(ISBLANK($C507),"",IF($AF507<>Constants!$B$7,"",AN507)) | AX507: =IF(ISBLANK($C507),"",IF($AF507<>Constants!$B$7,"",IF(AN507=1,AH507,AK507))) | AY507: =IF(ISBLANK($C507),"",IF($AF507<>Constants!$B$7,"",IF(AN507=1,AI507,AL507))) | AZ507: =IF(ISBLANK($C507),"",IF($AF507<>Constants!$B$7,$AF507,AP507)) | BA507: =IF(ISBLANK($C507),"",IF($AF507<>Constants!$B$7,$AF507,AG507)) | BB507: =IF(ISBLANK($C507),"",AU507) | BC507: =IF(ISBLANK($C507),"",AT507) | BD507: =IF(ISBLANK($C507),"",IFERROR(_xlfn.SWITCH(BC507,Constants!$B$4,COUNTA($C$8:$C$507)+2,Constants!$B$5,COUNTA($C$8:$C$507)+1,Constants!$B$6,COUNTA($C$8:$C$507)),BC507)) | BF507: =IF(OR(ISNUMBER(BC507),BC507=Constants!$B$4,BC507=Constants!$B$6,BC507=Constants!$B$5),1,0) -> 0 | BG507: 500 | BH507: =IF(ISBLANK($C507),"",IF(ISNUMBER(BD507),BD507+ROW($B507)/1000,"")) | BI507: =IF(ISNUMBER(BH507),RANK(BH507,$BH$8:$BH$507,1),"") | BJ507: =IF(ISBLANK($C507),"",$B507) | BK507: =IF(ISBLANK($C507),"",$C507) | BL507: =IF(ISBLANK($C507),"",$D507) | BM507: =BA507 | BN507: =AZ507 | BO507: =IF(ISBLANK($C507),"",BC507) | BP507: =IF($BG507>$BF$7,"",VLOOKUP($BG507,$BI$8:$BO$507,7,FALSE())) | BQ507: =IF($BG507>$BF$7,"",VLOOKUP($BG507,$BI$8:$BO$507,2,FALSE())) | BR507: =IF($BG507>$BF$7,"",VLOOKUP($BG507,$BI$8:$BO$507,3,FALSE())) | BS507: =IF($BG507>$BF$7,"",VLOOKUP($BG507,$BI$8:$BO$507,4,FALSE())) | BT507: =IF($BG507>$BF$7,"",VLOOKUP($BG507,$BI$8:$BO$507,5,FALSE())) | BU507: =IF($BG507>$BF$7,"",VLOOKUP($BG507,$BI$8:$BO$507,6,FALSE()))

Sheet Constants
A1: Name Desc | B1: Value
A2: =TRUE() -> TRUE | B2: T
A3: =FALSE() -> FALSE | B3: F
A4: Disqualified | B4: DQ
A5: No-Show | B5: NS
A6: Participated | B6: P
A7: Competed | B7: C
A8: Complete Flight Log Multiplier | B8: 1
A9: Incomplete Flight Log Multiplier | B9: 0.85
A10: No Flight Log Multiplier | B10: 0.7
A11: Parachute Separate Multipler | B11: 0.9
A12: Ceiling Touch Multiplier | B12: 0.25
A13: Seconds Assessed for a Missing Flight | B13: 0
A14: Error Status | B14: ERR
A15: Flight Log: Complete | B15: Complete
A16: Flight Log: Incomplete | B16: Incomplete
A17: Flight Log: Not Present | B17: Not present
A18: Rocket A | B18: A
A19: Rocket B | B19: B
A20: Tier (event has no tiering) | B20: 1

Sheet Export
A1: Team # | B1: School Name | C1: Team Name | D1: Status | E1: Score | F1: Tiebreaker | G1: Tier | H1: Points | I1: Rank
A2: =ExportRaw!$F2 -> 0 | B2: =ExportRaw!$C2 -> 0 | C2: =ExportRaw!$G2 -> 0 | D2: =ExportRaw!$E2 | E2: =ExportRaw!$D2 | F2: =ExportRaw!$H2 | G2: =ExportRaw!$I2 | H2: =ExportRaw!$A2 | I2: =ExportRaw!$B2
A3: =ExportRaw!$F3 -> 0 | B3: =ExportRaw!$C3 -> 0 | C3: =ExportRaw!$G3 -> 0 | D3: =ExportRaw!$E3 | E3: =ExportRaw!$D3 | F3: =ExportRaw!$H3 | G3: =ExportRaw!$I3 | H3: =ExportRaw!$A3 | I3: =ExportRaw!$B3
A4: =ExportRaw!$F4 -> 0 | B4: =ExportRaw!$C4 -> 0 | C4: =ExportRaw!$G4 -> 0 | D4: =ExportRaw!$E4 | E4: =ExportRaw!$D4 | F4: =ExportRaw!$H4 | G4: =ExportRaw!$I4 | H4: =ExportRaw!$A4 | I4: =ExportRaw!$B4
A5: =ExportRaw!$F5 -> 0 | B5: =ExportRaw!$C5 -> 0 | C5: =ExportRaw!$G5 -> 0 | D5: =ExportRaw!$E5 | E5: =ExportRaw!$D5 | F5: =ExportRaw!$H5 | G5: =ExportRaw!$I5 | H5: =ExportRaw!$A5 | I5: =ExportRaw!$B5
A6: =ExportRaw!$F6 -> 0 | B6: =ExportRaw!$C6 -> 0 | C6: =ExportRaw!$G6 -> 0 | D6: =ExportRaw!$E6 | E6: =ExportRaw!$D6 | F6: =ExportRaw!$H6 | G6: =ExportRaw!$I6 | H6: =ExportRaw!$A6 | I6: =ExportRaw!$B6
A7: =ExportRaw!$F7 -> 0 | B7: =ExportRaw!$C7 -> 0 | C7: =ExportRaw!$G7 -> 0 | D7: =ExportRaw!$E7 | E7: =ExportRaw!$D7 | F7: =ExportRaw!$H7 | G7: =ExportRaw!$I7 | H7: =ExportRaw!$A7 | I7: =ExportRaw!$B7
A8: =ExportRaw!$F8 -> 0 | B8: =ExportRaw!$C8 -> 0 | C8: =ExportRaw!$G8 -> 0 | D8: =ExportRaw!$E8 | E8: =ExportRaw!$D8 | F8: =ExportRaw!$H8 | G8: =ExportRaw!$I8 | H8: =ExportRaw!$A8 | I8: =ExportRaw!$B8
A9: =ExportRaw!$F9 -> 0 | B9: =ExportRaw!$C9 -> 0 | C9: =ExportRaw!$G9 -> 0 | D9: =ExportRaw!$E9 | E9: =ExportRaw!$D9 | F9: =ExportRaw!$H9 | G9: =ExportRaw!$I9 | H9: =ExportRaw!$A9 | I9: =ExportRaw!$B9
A10: =ExportRaw!$F10 -> 0 | B10: =ExportRaw!$C10 -> 0 | C10: =ExportRaw!$G10 -> 0 | D10: =ExportRaw!$E10 | E10: =ExportRaw!$D10 | F10: =ExportRaw!$H10 | G10: =ExportRaw!$I10 | H10: =ExportRaw!$A10 | I10: =ExportRaw!$B10
A11: =ExportRaw!$F11 -> 0 | B11: =ExportRaw!$C11 -> 0 | C11: =ExportRaw!$G11 -> 0 | D11: =ExportRaw!$E11 | E11: =ExportRaw!$D11 | F11: =ExportRaw!$H11 | G11: =ExportRaw!$I11 | H11: =ExportRaw!$A11 | I11: =ExportRaw!$B11
A12: =ExportRaw!$F12 -> 0 | B12: =ExportRaw!$C12 -> 0 | C12: =ExportRaw!$G12 -> 0 | D12: =ExportRaw!$E12 | E12: =ExportRaw!$D12 | F12: =ExportRaw!$H12 | G12: =ExportRaw!$I12 | H12: =ExportRaw!$A12 | I12: =ExportRaw!$B12
