Workbook

Sheet Scoring
B2: ='Info.'!B1&" "&'Info.'!B4 -> Thermodynamics B/C | G2: Impound | H2: Check-in | J2: Device Testing | P2: Part I | AA2: Req* | AC2: Req* | AG2: *Required only if device is allowed to run | BD2: Breakdown | BO2: Rank for this team with row() bump | BP2: Rank for this team with same ranks split | BQ2: Team Number of this team | BR2: Name of this schoo | BS2: Name of this team | BT2: Tier for this Team | BU2: Score for this team | BV2: Actual Rank for this team | BW2: Final Rankings
E3: Actual Ratio 1 | F3: Actual Ratio 2 | G3: 1. Device Impounded (T/F) | H3: 2. Device does not contain hazardous materials (T/F) | I3: 3. No energy sources (T/F) | J3: 4. # of Construction Violations | K3: 5. Team does not touch their setup during the Heating Time (T/F) | L3: 6. # of Competition Violations | M3: 7. Starting Water Temp | N3: 8. Predicted Final Temp | O3: 9. Actual Final Temp | P3: 10. Part I Raw Score | Q3: 11. Tiebreak 3 Ranking (If blank, assumes rank 1) | R3: 12. Disqualify (T/F) | U3: =G3 -> 1. Device Impounded (T/F) | V3: =H3 -> 2. Device does not contain hazardous materials (T/F) | W3: =I3 -> 3. No energy sources (T/F) | X3: =J3 -> 4. # of Construction Violations | Y3: =K3 -> 5. Team does not touch their setup during the Heating Time (T/F) | Z3: =L3 -> 6. # of Competition Violations | AA3: =M3 -> 7. Starting Water Temp | AB3: =N3 -> 8. Predicted Final Temp | ... AF3: =R3 -> 12. Disqualify (T/F) | BC3: Errors | BD3: ES | BE3: TS | BF3: PS | BG3: Score | BH3: Tier | BI3: Tiebreaker | BJ3: Rank | BK3: Points | BW3: Rank | BX3: Team # | BY3: School Name | BZ3: Team Name | CA3: Tier | CB3: Score
B4: ="Event Scoresheet - "&'Info.'!B5&IF('Info.'!B8="T"," The scoresheet has been updated; please download version v"&'Info.'!B7&" from soinc.org/scoresheets.","") -> Event Scoresheet - 2027 | AJ4: Highest TG | AN4: Highest PE | AR4: Part I Highest Raw Score
B6: ="Last Updated: "&TEXT('Info.'!B2, "mm/dd/yyyy")&" (v"&'Info.'!B3&") Direct all questions to scoresheets@soinc.org." -> Last Updated: 10/01/2026 (v0.1.0) Direct all questions to scoresheets@soinc.org. | AJ6: =MAX(AJ8:AJ507) -> 0 | AK6: Box 7 or Box 9 is missing. | AN6: =MAX(AN8:AN507) -> 0 | AO6: Box 9 cannot be 0. | AR6: =MAX(AD8:AD507) -> 0
B7: Team # | C7: School Name | D7: Team Name | AG7: Status | AH7: Tier | AI7: TS/PS Multiplier | AJ7: TG | AK7: TG Error Check | AL7: Raw TS | AM7: TS | AN7: PE | AO7: PE Error Check | AP7: Raw PS | AQ7: PS | AR7: ES | AS7: Score | AT7: Rank | AU7: TB1 (Best TS) | AV7: TB1 Rank | AW7: TB2 (Best ES) | AX7: TB2 Rank | AY7: TB3 Rank | AZ7: Rank w/ TB | BA7: Rank Diff | BC7: =IF(COUNTIF($BC$8:$BC$507,"?*")=0,"No input errors",COUNTIF($BC$8:$BC$507,"?*")&" row(s) need attention") -> No input errors | BM7: =SUM(BM8:BM507) -> 0
U8: =IF(ISBLANK($C8),"",IF(G8=Constants!$B$2, TRUE(), IF(G8=Constants!$B$3, FALSE(), TRUE()))) | V8: =IF(ISBLANK($C8),"",IF(H8=Constants!$B$2, TRUE(), IF(H8=Constants!$B$3, FALSE(), TRUE()))) | W8: =IF(ISBLANK($C8),"",IF(I8=Constants!$B$2, TRUE(), IF(I8=Constants!$B$3, FALSE(), TRUE()))) | X8: =IF(ISBLANK($C8),"",IF(AND(ISNUMBER(J8),J8>0),INT(J8),0)) | Y8: =IF(ISBLANK($C8),"",IF(K8=Constants!$B$2, TRUE(), IF(K8=Constants!$B$3, FALSE(), TRUE()))) | Z8: =IF(ISBLANK($C8),"",IF(AND(ISNUMBER(L8),L8>0),INT(L8),0)) | AA8: =IF(ISBLANK($C8),"",IF(ISNUMBER(M8), M8, "")) | AB8: =IF(ISBLANK($C8),"",IF(ISNUMBER(N8), N8, "")) | AC8: =IF(ISBLANK($C8),"",IF(ISNUMBER(O8), O8, "")) | AD8: =IF(ISBLANK($C8),"",IF(ISNUMBER(P8), P8, "")) | AE8: =IF(ISBLANK($C8),"",IF(ISNUMBER(Q8), Q8, Constants!$B$13)) | AF8: =IF(ISBLANK($C8),"",IF(R8=Constants!$B$2, TRUE(), IF(R8=Constants!$B$3, FALSE(), FALSE()))) | AG8: =IF(ISBLANK(C8), "", IF(AF8, Constants!$B$4,IF(COUNTA(G8:P8)=0, Constants!$B$5, Constants!$B$7))) | AH8: =IF(ISBLANK($C8), "",IF($AG8=Constants!$B$7,1,$AG8)) | AI8: =IF($AG8=Constants!$B$7,POWER(Constants!$B$11,X8)*POWER(Constants!$B$12,Z8),"") | AJ8: =IF(AND($AG8=Constants!$B$7, U8, V8) ,IF(OR($AA8="",$AC8=""),"",MAX(0, $AC8-$AA8)),"") | AK8: =IF(AND($AG8=Constants!$B$7, U8, V8),IF(OR($AA8="",$AC8=""),$AK$6,""),"") | AL8: =IF($AG8=Constants!$B$7,IF(AND(U8,V8,W8,Y8),IF($AJ8="",0,IF($AJ$6=0,Constants!$B$9,Constants!$B$9*AJ8/$AJ$6)), 0),"") | AM8: =IF(AL8<>"", AL8*AI8,"") | AN8: =IF(AND($AG8=Constants!$B$7, U8, V8) ,IF($AB8="", "", IF(OR($AC8="",$AC8=0),"",MAX(0,1-ABS($AC8-$AB8)/$AC8))),"") | AO8: =IF(AND($AG8=Constants!$B$7, U8, V8),IF(AND($AA8<>"",$AB8<>"",$AC8=0),$AO$6,""),"") | AP8: =IF($AG8=Constants!$B$7 ,IF(AND(U8,V8,W8,Y8,ISNUMBER(AB8)),IF($AN8="",0,IF($AN$6=0,Constants!$B$10,Constants!$B$10*AN8/$AN$6)), 0),"") | AQ8: =IF(AP8<>"", AP8*AI8,"") | AR8: =IF($AG8=Constants!$B$7,IF($AD8="",0,IF($AR$6=0,Constants!$B$8,Constants!$B$8*AD8/$AR$6)),"") | AS8: =IF($AG8<>Constants!$B$7,$AG8,IF(AK8&AO8<>"",Constants!$B$14,AM8+AQ8+AR8)) | AT8: =IF(ISBLANK($C8),"",IF($AG8=Constants!$B$7,IF(ISNUMBER(AS8),RANK(AS8,$AS$8:$AS$507),Constants!$B$14),$AG8)) | AU8: =IF(ISBLANK($C8), "",AM8) | AV8: =IF(ISBLANK($C8),"",IF($AG8=Constants!$B$7,RANK(AU8,AU$8:AU$507),$AG8)) | AW8: =IF(ISBLANK($C8), "",AR8) | AX8: =IF(ISBLANK($C8),"",IF($AG8=Constants!$B$7,RANK(AW8,AW$8:AW$507),$AG8)) | AY8: =IF(ISBLANK($C8), "",AE8) | AZ8: =IF(ISBLANK($C8),"", IF($AG8=Constants!$B$7, IF(ISNUMBER(AT8), COUNTIFS($AT$8:$AT$507,"<"&$AT8) + COUNTIFS($AT$8:$AT$507,$AT8,$AV$8:$AV$507,"<"&$AV8) + COUNTIFS($AT$8:$AT$507,$AT8,$AV$8:$AV$507,$AV8,$AX$8:$AX$507,"<"&$AX8) + COUNTIFS($AT$8:$AT$507,$AT8,$AV$8:$AV$507,$AV8,$AX$8:$AX$507,$AX8,$AY$8:$AY$507,"<"&$AY8) + 1, Constants!$B$14), $AG8)) | BA8: =IF(ISBLANK(C8),"",IF($AG8=Constants!$B$7, IF(ISNUMBER(AT8),AT8-AZ8,Constants!$B$14),$AG8)) | BC8: =IF(ISBLANK($C8),"",TRIM(AK8&" "&AO8)) | BD8: =IF(ISBLANK($C8),"",IF($AG8<>Constants!$B$7,$AG8,AR8)) | BE8: =IF(ISBLANK($C8),"",IF($AG8<>Constants!$B$7,$AG8,AM8)) | BF8: =IF(ISBLANK($C8),"",IF($AG8<>Constants!$B$7,$AG8,AQ8)) | BG8: =IF(ISBLANK($C8),"",IF($AG8<>Constants!$B$7, $AG8 ,AS8)) | BH8: =IF(ISBLANK($C8),"",IF($AG8<>Constants!$B$7, $AG8 ,AH8)) | BI8: =IF(ISBLANK(C8),"",BA8) | BJ8: =IF(ISBLANK(C8),"",AZ8) | BK8: =IF(ISBLANK(C8),"",IFERROR(_xlfn.SWITCH(BJ8, Constants!$B$4, COUNTA($C$8:$C507)+2, Constants!$B$5, COUNTA($C$8:$C507)+1, Constants!$B$6, COUNTA($C$8:$C507)),BJ8)) | BM8: =IF(OR(ISNUMBER(BJ8),BJ8="DQ",BJ8="P",BJ8="NS"), 1, 0 ) -> 0 | BN8: 1 | BO8: =IF(ISBLANK($C8),"",IF(ISNUMBER(BK8),BK8+ROW($B8)/1000,"")) | BP8: =IF(ISNUMBER(BO8), RANK(BO8,BO$8:BO$507,1), "") | BQ8: =IF(ISBLANK($C8), "", $B8 ) | BR8: =IF(ISBLANK($C8), "", $C8 ) | BS8: =IF(ISBLANK($C8), "", $D8 ) | BT8: =BH8 | BU8: =BG8 | BV8: =IF(ISBLANK($C8), "", BJ8 ) | BW8: =IF(BN8>BM$7, "", VLOOKUP(BN8,BP$8:BV507,7,FALSE()) ) | BX8: =IF(BN8>BM$7, "", VLOOKUP(BN8,BP$8:BV507,2,FALSE()) ) | BY8: =IF(BN8>BM$7, "", VLOOKUP(BN8,BP$8:BV507,3,FALSE()) ) | BZ8: =IF(BN8>BM$7, "", VLOOKUP(BN8,BP$8:BV507,4,FALSE()) ) | CA8: =IF(BN8>BM$7, "", VLOOKUP(BN8,BP$8:BV507,5,FALSE()) ) | CB8: =IF(BN8>BM$7, "", VLOOKUP(BN8,BP$8:BV507,6,FALSE()) )
U9: =IF(ISBLANK($C9),"",IF(G9=Constants!$B$2, TRUE(), IF(G9=Constants!$B$3, FALSE(), TRUE()))) | V9: =IF(ISBLANK($C9),"",IF(H9=Constants!$B$2, TRUE(), IF(H9=Constants!$B$3, FALSE(), TRUE()))) | W9: =IF(ISBLANK($C9),"",IF(I9=Constants!$B$2, TRUE(), IF(I9=Constants!$B$3, FALSE(), TRUE()))) | X9: =IF(ISBLANK($C9),"",IF(AND(ISNUMBER(J9),J9>0),INT(J9),0)) | Y9: =IF(ISBLANK($C9),"",IF(K9=Constants!$B$2, TRUE(), IF(K9=Constants!$B$3, FALSE(), TRUE()))) | Z9: =IF(ISBLANK($C9),"",IF(AND(ISNUMBER(L9),L9>0),INT(L9),0)) | AA9: =IF(ISBLANK($C9),"",IF(ISNUMBER(M9), M9, "")) | AB9: =IF(ISBLANK($C9),"",IF(ISNUMBER(N9), N9, "")) | AC9: =IF(ISBLANK($C9),"",IF(ISNUMBER(O9), O9, "")) | AD9: =IF(ISBLANK($C9),"",IF(ISNUMBER(P9), P9, "")) | AE9: =IF(ISBLANK($C9),"",IF(ISNUMBER(Q9), Q9, Constants!$B$13)) | AF9: =IF(ISBLANK($C9),"",IF(R9=Constants!$B$2, TRUE(), IF(R9=Constants!$B$3, FALSE(), FALSE()))) | AG9: =IF(ISBLANK(C9), "", IF(AF9, Constants!$B$4,IF(COUNTA(G9:P9)=0, Constants!$B$5, Constants!$B$7))) | AH9: =IF(ISBLANK($C9), "",IF($AG9=Constants!$B$7,1,$AG9)) | AI9: =IF($AG9=Constants!$B$7,POWER(Constants!$B$11,X9)*POWER(Constants!$B$12,Z9),"") | AJ9: =IF(AND($AG9=Constants!$B$7, U9, V9) ,IF(OR($AA9="",$AC9=""),"",MAX(0, $AC9-$AA9)),"") | AK9: =IF(AND($AG9=Constants!$B$7, U9, V9),IF(OR($AA9="",$AC9=""),$AK$6,""),"") | AL9: =IF($AG9=Constants!$B$7,IF(AND(U9,V9,W9,Y9),IF($AJ9="",0,IF($AJ$6=0,Constants!$B$9,Constants!$B$9*AJ9/$AJ$6)), 0),"") | AM9: =IF(AL9<>"", AL9*AI9,"") | AN9: =IF(AND($AG9=Constants!$B$7, U9, V9) ,IF($AB9="", "", IF(OR($AC9="",$AC9=0),"",MAX(0,1-ABS($AC9-$AB9)/$AC9))),"") | AO9: =IF(AND($AG9=Constants!$B$7, U9, V9),IF(AND($AA9<>"",$AB9<>"",$AC9=0),$AO$6,""),"") | AP9: =IF($AG9=Constants!$B$7 ,IF(AND(U9,V9,W9,Y9,ISNUMBER(AB9)),IF($AN9="",0,IF($AN$6=0,Constants!$B$10,Constants!$B$10*AN9/$AN$6)), 0),"") | AQ9: =IF(AP9<>"", AP9*AI9,"") | AR9: =IF($AG9=Constants!$B$7,IF($AD9="",0,IF($AR$6=0,Constants!$B$8,Constants!$B$8*AD9/$AR$6)),"") | AS9: =IF($AG9<>Constants!$B$7,$AG9,IF(AK9&AO9<>"",Constants!$B$14,AM9+AQ9+AR9)) | AT9: =IF(ISBLANK($C9),"",IF($AG9=Constants!$B$7,IF(ISNUMBER(AS9),RANK(AS9,$AS$8:$AS$507),Constants!$B$14),$AG9)) | AU9: =IF(ISBLANK($C9), "",AM9) | AV9: =IF(ISBLANK($C9),"",IF($AG9=Constants!$B$7,RANK(AU9,AU$8:AU$507),$AG9)) | AW9: =IF(ISBLANK($C9), "",AR9) | AX9: =IF(ISBLANK($C9),"",IF($AG9=Constants!$B$7,RANK(AW9,AW$8:AW$507),$AG9)) | AY9: =IF(ISBLANK($C9), "",AE9) | AZ9: =IF(ISBLANK($C9),"", IF($AG9=Constants!$B$7, IF(ISNUMBER(AT9), COUNTIFS($AT$8:$AT$507,"<"&$AT9) + COUNTIFS($AT$8:$AT$507,$AT9,$AV$8:$AV$507,"<"&$AV9) + COUNTIFS($AT$8:$AT$507,$AT9,$AV$8:$AV$507,$AV9,$AX$8:$AX$507,"<"&$AX9) + COUNTIFS($AT$8:$AT$507,$AT9,$AV$8:$AV$507,$AV9,$AX$8:$AX$507,$AX9,$AY$8:$AY$507,"<"&$AY9) + 1, Constants!$B$14), $AG9)) | BA9: =IF(ISBLANK(C9),"",IF($AG9=Constants!$B$7, IF(ISNUMBER(AT9),AT9-AZ9,Constants!$B$14),$AG9)) | BC9: =IF(ISBLANK($C9),"",TRIM(AK9&" "&AO9)) | BD9: =IF(ISBLANK($C9),"",IF($AG9<>Constants!$B$7,$AG9,AR9)) | BE9: =IF(ISBLANK($C9),"",IF($AG9<>Constants!$B$7,$AG9,AM9)) | BF9: =IF(ISBLANK($C9),"",IF($AG9<>Constants!$B$7,$AG9,AQ9)) | BG9: =IF(ISBLANK($C9),"",IF($AG9<>Constants!$B$7, $AG9 ,AS9)) | BH9: =IF(ISBLANK($C9),"",IF($AG9<>Constants!$B$7, $AG9 ,AH9)) | BI9: =IF(ISBLANK(C9),"",BA9) | BJ9: =IF(ISBLANK(C9),"",AZ9) | BK9: =IF(ISBLANK(C9),"",IFERROR(_xlfn.SWITCH(BJ9, Constants!$B$4, COUNTA($C$8:$C508)+2, Constants!$B$5, COUNTA($C$8:$C508)+1, Constants!$B$6, COUNTA($C$8:$C508)),BJ9)) | BM9: =IF(OR(ISNUMBER(BJ9),BJ9="DQ",BJ9="P",BJ9="NS"), 1, 0 ) -> 0 | BN9: 2 | BO9: =IF(ISBLANK($C9),"",IF(ISNUMBER(BK9),BK9+ROW($B9)/1000,"")) | BP9: =IF(ISNUMBER(BO9), RANK(BO9,BO$8:BO$507,1), "") | BQ9: =IF(ISBLANK($C9), "", $B9 ) | BR9: =IF(ISBLANK($C9), "", $C9 ) | BS9: =IF(ISBLANK($C9), "", $D9 ) | BT9: =BH9 | BU9: =BG9 | BV9: =IF(ISBLANK($C9), "", BJ9 ) | BW9: =IF(BN9>BM$7, "", VLOOKUP(BN9,BP$8:BV508,7,FALSE()) ) | BX9: =IF(BN9>BM$7, "", VLOOKUP(BN9,BP$8:BV508,2,FALSE()) ) | BY9: =IF(BN9>BM$7, "", VLOOKUP(BN9,BP$8:BV508,3,FALSE()) ) | BZ9: =IF(BN9>BM$7, "", VLOOKUP(BN9,BP$8:BV508,4,FALSE()) ) | CA9: =IF(BN9>BM$7, "", VLOOKUP(BN9,BP$8:BV508,5,FALSE()) ) | CB9: =IF(BN9>BM$7, "", VLOOKUP(BN9,BP$8:BV508,6,FALSE()) )
U10: =IF(ISBLANK($C10),"",IF(G10=Constants!$B$2, TRUE(), IF(G10=Constants!$B$3, FALSE(), TRUE()))) | V10: =IF(ISBLANK($C10),"",IF(H10=Constants!$B$2, TRUE(), IF(H10=Constants!$B$3, FALSE(), TRUE()))) | W10: =IF(ISBLANK($C10),"",IF(I10=Constants!$B$2, TRUE(), IF(I10=Constants!$B$3, FALSE(), TRUE()))) | X10: =IF(ISBLANK($C10),"",IF(AND(ISNUMBER(J10),J10>0),INT(J10),0)) | Y10: =IF(ISBLANK($C10),"",IF(K10=Constants!$B$2, TRUE(), IF(K10=Constants!$B$3, FALSE(), TRUE()))) | Z10: =IF(ISBLANK($C10),"",IF(AND(ISNUMBER(L10),L10>0),INT(L10),0)) | AA10: =IF(ISBLANK($C10),"",IF(ISNUMBER(M10), M10, "")) | AB10: =IF(ISBLANK($C10),"",IF(ISNUMBER(N10), N10, "")) | AC10: =IF(ISBLANK($C10),"",IF(ISNUMBER(O10), O10, "")) | AD10: =IF(ISBLANK($C10),"",IF(ISNUMBER(P10), P10, "")) | AE10: =IF(ISBLANK($C10),"",IF(ISNUMBER(Q10), Q10, Constants!$B$13)) | AF10: =IF(ISBLANK($C10),"",IF(R10=Constants!$B$2, TRUE(), IF(R10=Constants!$B$3, FALSE(), FALSE()))) | AG10: =IF(ISBLANK(C10), "", IF(AF10, Constants!$B$4,IF(COUNTA(G10:P10)=0, Constants!$B$5, Constants!$B$7))) | AH10: =IF(ISBLANK($C10), "",IF($AG10=Constants!$B$7,1,$AG10)) | AI10: =IF($AG10=Constants!$B$7,POWER(Constants!$B$11,X10)*POWER(Constants!$B$12,Z10),"") | AJ10: =IF(AND($AG10=Constants!$B$7, U10, V10) ,IF(OR($AA10="",$AC10=""),"",MAX(0, $AC10-$AA10)),"") | AK10: =IF(AND($AG10=Constants!$B$7, U10, V10),IF(OR($AA10="",$AC10=""),$AK$6,""),"") | AL10: =IF($AG10=Constants!$B$7,IF(AND(U10,V10,W10,Y10),IF($AJ10="",0,IF($AJ$6=0,Constants!$B$9,Constants!$B$9*AJ10/$AJ$6)), 0),"") | AM10: =IF(AL10<>"", AL10*AI10,"") | AN10: =IF(AND($AG10=Constants!$B$7, U10, V10) ,IF($AB10="", "", IF(OR($AC10="",$AC10=0),"",MAX(0,1-ABS($AC10-$AB10)/$AC10))),"") | AO10: =IF(AND($AG10=Constants!$B$7, U10, V10),IF(AND($AA10<>"",$AB10<>"",$AC10=0),$AO$6,""),"") | AP10: =IF($AG10=Constants!$B$7 ,IF(AND(U10,V10,W10,Y10,ISNUMBER(AB10)),IF($AN10="",0,IF($AN$6=0,Constants!$B$10,Constants!$B$10*AN10/$AN$6)), 0),"") | AQ10: =IF(AP10<>"", AP10*AI10,"") | AR10: =IF($AG10=Constants!$B$7,IF($AD10="",0,IF($AR$6=0,Constants!$B$8,Constants!$B$8*AD10/$AR$6)),"") | AS10: =IF($AG10<>Constants!$B$7,$AG10,IF(AK10&AO10<>"",Constants!$B$14,AM10+AQ10+AR10)) | AT10: =IF(ISBLANK($C10),"",IF($AG10=Constants!$B$7,IF(ISNUMBER(AS10),RANK(AS10,$AS$8:$AS$507),Constants!$B$14),$AG10)) | AU10: =IF(ISBLANK($C10), "",AM10) | AV10: =IF(ISBLANK($C10),"",IF($AG10=Constants!$B$7,RANK(AU10,AU$8:AU$507),$AG10)) | AW10: =IF(ISBLANK($C10), "",AR10) | AX10: =IF(ISBLANK($C10),"",IF($AG10=Constants!$B$7,RANK(AW10,AW$8:AW$507),$AG10)) | AY10: =IF(ISBLANK($C10), "",AE10) | AZ10: =IF(ISBLANK($C10),"", IF($AG10=Constants!$B$7, IF(ISNUMBER(AT10), COUNTIFS($AT$8:$AT$507,"<"&$AT10) + COUNTIFS($AT$8:$AT$507,$AT10,$AV$8:$AV$507,"<"&$AV10) + COUNTIFS($AT$8:$AT$507,$AT10,$AV$8:$AV$507,$AV10,$AX$8:$AX$507,"<"&$AX10) + COUNTIFS($AT$8:$AT$507,$AT10,$AV$8:$AV$507,$AV10,$AX$8:$AX$507,$AX10,$AY$8:$AY$507,"<"&$AY10) + 1, Constants!$B$14), $AG10)) | BA10: =IF(ISBLANK(C10),"",IF($AG10=Constants!$B$7, IF(ISNUMBER(AT10),AT10-AZ10,Constants!$B$14),$AG10)) | BC10: =IF(ISBLANK($C10),"",TRIM(AK10&" "&AO10)) | BD10: =IF(ISBLANK($C10),"",IF($AG10<>Constants!$B$7,$AG10,AR10)) | BE10: =IF(ISBLANK($C10),"",IF($AG10<>Constants!$B$7,$AG10,AM10)) | BF10: =IF(ISBLANK($C10),"",IF($AG10<>Constants!$B$7,$AG10,AQ10)) | BG10: =IF(ISBLANK($C10),"",IF($AG10<>Constants!$B$7, $AG10 ,AS10)) | BH10: =IF(ISBLANK($C10),"",IF($AG10<>Constants!$B$7, $AG10 ,AH10)) | BI10: =IF(ISBLANK(C10),"",BA10) | BJ10: =IF(ISBLANK(C10),"",AZ10) | BK10: =IF(ISBLANK(C10),"",IFERROR(_xlfn.SWITCH(BJ10, Constants!$B$4, COUNTA($C$8:$C509)+2, Constants!$B$5, COUNTA($C$8:$C509)+1, Constants!$B$6, COUNTA($C$8:$C509)),BJ10)) | BM10: =IF(OR(ISNUMBER(BJ10),BJ10="DQ",BJ10="P",BJ10="NS"), 1, 0 ) -> 0 | BN10: 3 | BO10: =IF(ISBLANK($C10),"",IF(ISNUMBER(BK10),BK10+ROW($B10)/1000,"")) | BP10: =IF(ISNUMBER(BO10), RANK(BO10,BO$8:BO$507,1), "") | BQ10: =IF(ISBLANK($C10), "", $B10 ) | BR10: =IF(ISBLANK($C10), "", $C10 ) | BS10: =IF(ISBLANK($C10), "", $D10 ) | BT10: =BH10 | BU10: =BG10 | BV10: =IF(ISBLANK($C10), "", BJ10 ) | BW10: =IF(BN10>BM$7, "", VLOOKUP(BN10,BP$8:BV509,7,FALSE()) ) | BX10: =IF(BN10>BM$7, "", VLOOKUP(BN10,BP$8:BV509,2,FALSE()) ) | BY10: =IF(BN10>BM$7, "", VLOOKUP(BN10,BP$8:BV509,3,FALSE()) ) | BZ10: =IF(BN10>BM$7, "", VLOOKUP(BN10,BP$8:BV509,4,FALSE()) ) | CA10: =IF(BN10>BM$7, "", VLOOKUP(BN10,BP$8:BV509,5,FALSE()) ) | CB10: =IF(BN10>BM$7, "", VLOOKUP(BN10,BP$8:BV509,6,FALSE()) )
U11: =IF(ISBLANK($C11),"",IF(G11=Constants!$B$2, TRUE(), IF(G11=Constants!$B$3, FALSE(), TRUE()))) | V11: =IF(ISBLANK($C11),"",IF(H11=Constants!$B$2, TRUE(), IF(H11=Constants!$B$3, FALSE(), TRUE()))) | W11: =IF(ISBLANK($C11),"",IF(I11=Constants!$B$2, TRUE(), IF(I11=Constants!$B$3, FALSE(), TRUE()))) | X11: =IF(ISBLANK($C11),"",IF(AND(ISNUMBER(J11),J11>0),INT(J11),0)) | Y11: =IF(ISBLANK($C11),"",IF(K11=Constants!$B$2, TRUE(), IF(K11=Constants!$B$3, FALSE(), TRUE()))) | Z11: =IF(ISBLANK($C11),"",IF(AND(ISNUMBER(L11),L11>0),INT(L11),0)) | AA11: =IF(ISBLANK($C11),"",IF(ISNUMBER(M11), M11, "")) | AB11: =IF(ISBLANK($C11),"",IF(ISNUMBER(N11), N11, "")) | AC11: =IF(ISBLANK($C11),"",IF(ISNUMBER(O11), O11, "")) | AD11: =IF(ISBLANK($C11),"",IF(ISNUMBER(P11), P11, "")) | AE11: =IF(ISBLANK($C11),"",IF(ISNUMBER(Q11), Q11, Constants!$B$13)) | AF11: =IF(ISBLANK($C11),"",IF(R11=Constants!$B$2, TRUE(), IF(R11=Constants!$B$3, FALSE(), FALSE()))) | AG11: =IF(ISBLANK(C11), "", IF(AF11, Constants!$B$4,IF(COUNTA(G11:P11)=0, Constants!$B$5, Constants!$B$7))) | AH11: =IF(ISBLANK($C11), "",IF($AG11=Constants!$B$7,1,$AG11)) | AI11: =IF($AG11=Constants!$B$7,POWER(Constants!$B$11,X11)*POWER(Constants!$B$12,Z11),"") | AJ11: =IF(AND($AG11=Constants!$B$7, U11, V11) ,IF(OR($AA11="",$AC11=""),"",MAX(0, $AC11-$AA11)),"") | AK11: =IF(AND($AG11=Constants!$B$7, U11, V11),IF(OR($AA11="",$AC11=""),$AK$6,""),"") | AL11: =IF($AG11=Constants!$B$7,IF(AND(U11,V11,W11,Y11),IF($AJ11="",0,IF($AJ$6=0,Constants!$B$9,Constants!$B$9*AJ11/$AJ$6)), 0),"") | AM11: =IF(AL11<>"", AL11*AI11,"") | AN11: =IF(AND($AG11=Constants!$B$7, U11, V11) ,IF($AB11="", "", IF(OR($AC11="",$AC11=0),"",MAX(0,1-ABS($AC11-$AB11)/$AC11))),"") | AO11: =IF(AND($AG11=Constants!$B$7, U11, V11),IF(AND($AA11<>"",$AB11<>"",$AC11=0),$AO$6,""),"") | AP11: =IF($AG11=Constants!$B$7 ,IF(AND(U11,V11,W11,Y11,ISNUMBER(AB11)),IF($AN11="",0,IF($AN$6=0,Constants!$B$10,Constants!$B$10*AN11/$AN$6)), 0),"") | AQ11: =IF(AP11<>"", AP11*AI11,"") | AR11: =IF($AG11=Constants!$B$7,IF($AD11="",0,IF($AR$6=0,Constants!$B$8,Constants!$B$8*AD11/$AR$6)),"") | AS11: =IF($AG11<>Constants!$B$7,$AG11,IF(AK11&AO11<>"",Constants!$B$14,AM11+AQ11+AR11)) | AT11: =IF(ISBLANK($C11),"",IF($AG11=Constants!$B$7,IF(ISNUMBER(AS11),RANK(AS11,$AS$8:$AS$507),Constants!$B$14),$AG11)) | AU11: =IF(ISBLANK($C11), "",AM11) | AV11: =IF(ISBLANK($C11),"",IF($AG11=Constants!$B$7,RANK(AU11,AU$8:AU$507),$AG11)) | AW11: =IF(ISBLANK($C11), "",AR11) | AX11: =IF(ISBLANK($C11),"",IF($AG11=Constants!$B$7,RANK(AW11,AW$8:AW$507),$AG11)) | AY11: =IF(ISBLANK($C11), "",AE11) | AZ11: =IF(ISBLANK($C11),"", IF($AG11=Constants!$B$7, IF(ISNUMBER(AT11), COUNTIFS($AT$8:$AT$507,"<"&$AT11) + COUNTIFS($AT$8:$AT$507,$AT11,$AV$8:$AV$507,"<"&$AV11) + COUNTIFS($AT$8:$AT$507,$AT11,$AV$8:$AV$507,$AV11,$AX$8:$AX$507,"<"&$AX11) + COUNTIFS($AT$8:$AT$507,$AT11,$AV$8:$AV$507,$AV11,$AX$8:$AX$507,$AX11,$AY$8:$AY$507,"<"&$AY11) + 1, Constants!$B$14), $AG11)) | BA11: =IF(ISBLANK(C11),"",IF($AG11=Constants!$B$7, IF(ISNUMBER(AT11),AT11-AZ11,Constants!$B$14),$AG11)) | BC11: =IF(ISBLANK($C11),"",TRIM(AK11&" "&AO11)) | BD11: =IF(ISBLANK($C11),"",IF($AG11<>Constants!$B$7,$AG11,AR11)) | BE11: =IF(ISBLANK($C11),"",IF($AG11<>Constants!$B$7,$AG11,AM11)) | BF11: =IF(ISBLANK($C11),"",IF($AG11<>Constants!$B$7,$AG11,AQ11)) | BG11: =IF(ISBLANK($C11),"",IF($AG11<>Constants!$B$7, $AG11 ,AS11)) | BH11: =IF(ISBLANK($C11),"",IF($AG11<>Constants!$B$7, $AG11 ,AH11)) | BI11: =IF(ISBLANK(C11),"",BA11) | BJ11: =IF(ISBLANK(C11),"",AZ11) | BK11: =IF(ISBLANK(C11),"",IFERROR(_xlfn.SWITCH(BJ11, Constants!$B$4, COUNTA($C$8:$C510)+2, Constants!$B$5, COUNTA($C$8:$C510)+1, Constants!$B$6, COUNTA($C$8:$C510)),BJ11)) | BM11: =IF(OR(ISNUMBER(BJ11),BJ11="DQ",BJ11="P",BJ11="NS"), 1, 0 ) -> 0 | BN11: 4 | BO11: =IF(ISBLANK($C11),"",IF(ISNUMBER(BK11),BK11+ROW($B11)/1000,"")) | BP11: =IF(ISNUMBER(BO11), RANK(BO11,BO$8:BO$507,1), "") | BQ11: =IF(ISBLANK($C11), "", $B11 ) | BR11: =IF(ISBLANK($C11), "", $C11 ) | BS11: =IF(ISBLANK($C11), "", $D11 ) | BT11: =BH11 | BU11: =BG11 | BV11: =IF(ISBLANK($C11), "", BJ11 ) | BW11: =IF(BN11>BM$7, "", VLOOKUP(BN11,BP$8:BV510,7,FALSE()) ) | BX11: =IF(BN11>BM$7, "", VLOOKUP(BN11,BP$8:BV510,2,FALSE()) ) | BY11: =IF(BN11>BM$7, "", VLOOKUP(BN11,BP$8:BV510,3,FALSE()) ) | BZ11: =IF(BN11>BM$7, "", VLOOKUP(BN11,BP$8:BV510,4,FALSE()) ) | CA11: =IF(BN11>BM$7, "", VLOOKUP(BN11,BP$8:BV510,5,FALSE()) ) | CB11: =IF(BN11>BM$7, "", VLOOKUP(BN11,BP$8:BV510,6,FALSE()) )
U12: =IF(ISBLANK($C12),"",IF(G12=Constants!$B$2, TRUE(), IF(G12=Constants!$B$3, FALSE(), TRUE()))) | V12: =IF(ISBLANK($C12),"",IF(H12=Constants!$B$2, TRUE(), IF(H12=Constants!$B$3, FALSE(), TRUE()))) | W12: =IF(ISBLANK($C12),"",IF(I12=Constants!$B$2, TRUE(), IF(I12=Constants!$B$3, FALSE(), TRUE()))) | X12: =IF(ISBLANK($C12),"",IF(AND(ISNUMBER(J12),J12>0),INT(J12),0)) | Y12: =IF(ISBLANK($C12),"",IF(K12=Constants!$B$2, TRUE(), IF(K12=Constants!$B$3, FALSE(), TRUE()))) | Z12: =IF(ISBLANK($C12),"",IF(AND(ISNUMBER(L12),L12>0),INT(L12),0)) | AA12: =IF(ISBLANK($C12),"",IF(ISNUMBER(M12), M12, "")) | AB12: =IF(ISBLANK($C12),"",IF(ISNUMBER(N12), N12, "")) | AC12: =IF(ISBLANK($C12),"",IF(ISNUMBER(O12), O12, "")) | AD12: =IF(ISBLANK($C12),"",IF(ISNUMBER(P12), P12, "")) | AE12: =IF(ISBLANK($C12),"",IF(ISNUMBER(Q12), Q12, Constants!$B$13)) | AF12: =IF(ISBLANK($C12),"",IF(R12=Constants!$B$2, TRUE(), IF(R12=Constants!$B$3, FALSE(), FALSE()))) | AG12: =IF(ISBLANK(C12), "", IF(AF12, Constants!$B$4,IF(COUNTA(G12:P12)=0, Constants!$B$5, Constants!$B$7))) | AH12: =IF(ISBLANK($C12), "",IF($AG12=Constants!$B$7,1,$AG12)) | AI12: =IF($AG12=Constants!$B$7,POWER(Constants!$B$11,X12)*POWER(Constants!$B$12,Z12),"") | AJ12: =IF(AND($AG12=Constants!$B$7, U12, V12) ,IF(OR($AA12="",$AC12=""),"",MAX(0, $AC12-$AA12)),"") | AK12: =IF(AND($AG12=Constants!$B$7, U12, V12),IF(OR($AA12="",$AC12=""),$AK$6,""),"") | AL12: =IF($AG12=Constants!$B$7,IF(AND(U12,V12,W12,Y12),IF($AJ12="",0,IF($AJ$6=0,Constants!$B$9,Constants!$B$9*AJ12/$AJ$6)), 0),"") | AM12: =IF(AL12<>"", AL12*AI12,"") | AN12: =IF(AND($AG12=Constants!$B$7, U12, V12) ,IF($AB12="", "", IF(OR($AC12="",$AC12=0),"",MAX(0,1-ABS($AC12-$AB12)/$AC12))),"") | AO12: =IF(AND($AG12=Constants!$B$7, U12, V12),IF(AND($AA12<>"",$AB12<>"",$AC12=0),$AO$6,""),"") | AP12: =IF($AG12=Constants!$B$7 ,IF(AND(U12,V12,W12,Y12,ISNUMBER(AB12)),IF($AN12="",0,IF($AN$6=0,Constants!$B$10,Constants!$B$10*AN12/$AN$6)), 0),"") | AQ12: =IF(AP12<>"", AP12*AI12,"") | AR12: =IF($AG12=Constants!$B$7,IF($AD12="",0,IF($AR$6=0,Constants!$B$8,Constants!$B$8*AD12/$AR$6)),"") | AS12: =IF($AG12<>Constants!$B$7,$AG12,IF(AK12&AO12<>"",Constants!$B$14,AM12+AQ12+AR12)) | AT12: =IF(ISBLANK($C12),"",IF($AG12=Constants!$B$7,IF(ISNUMBER(AS12),RANK(AS12,$AS$8:$AS$507),Constants!$B$14),$AG12)) | AU12: =IF(ISBLANK($C12), "",AM12) | AV12: =IF(ISBLANK($C12),"",IF($AG12=Constants!$B$7,RANK(AU12,AU$8:AU$507),$AG12)) | AW12: =IF(ISBLANK($C12), "",AR12) | AX12: =IF(ISBLANK($C12),"",IF($AG12=Constants!$B$7,RANK(AW12,AW$8:AW$507),$AG12)) | AY12: =IF(ISBLANK($C12), "",AE12) | AZ12: =IF(ISBLANK($C12),"", IF($AG12=Constants!$B$7, IF(ISNUMBER(AT12), COUNTIFS($AT$8:$AT$507,"<"&$AT12) + COUNTIFS($AT$8:$AT$507,$AT12,$AV$8:$AV$507,"<"&$AV12) + COUNTIFS($AT$8:$AT$507,$AT12,$AV$8:$AV$507,$AV12,$AX$8:$AX$507,"<"&$AX12) + COUNTIFS($AT$8:$AT$507,$AT12,$AV$8:$AV$507,$AV12,$AX$8:$AX$507,$AX12,$AY$8:$AY$507,"<"&$AY12) + 1, Constants!$B$14), $AG12)) | BA12: =IF(ISBLANK(C12),"",IF($AG12=Constants!$B$7, IF(ISNUMBER(AT12),AT12-AZ12,Constants!$B$14),$AG12)) | BC12: =IF(ISBLANK($C12),"",TRIM(AK12&" "&AO12)) | BD12: =IF(ISBLANK($C12),"",IF($AG12<>Constants!$B$7,$AG12,AR12)) | BE12: =IF(ISBLANK($C12),"",IF($AG12<>Constants!$B$7,$AG12,AM12)) | BF12: =IF(ISBLANK($C12),"",IF($AG12<>Constants!$B$7,$AG12,AQ12)) | BG12: =IF(ISBLANK($C12),"",IF($AG12<>Constants!$B$7, $AG12 ,AS12)) | BH12: =IF(ISBLANK($C12),"",IF($AG12<>Constants!$B$7, $AG12 ,AH12)) | BI12: =IF(ISBLANK(C12),"",BA12) | BJ12: =IF(ISBLANK(C12),"",AZ12) | BK12: =IF(ISBLANK(C12),"",IFERROR(_xlfn.SWITCH(BJ12, Constants!$B$4, COUNTA($C$8:$C511)+2, Constants!$B$5, COUNTA($C$8:$C511)+1, Constants!$B$6, COUNTA($C$8:$C511)),BJ12)) | BM12: =IF(OR(ISNUMBER(BJ12),BJ12="DQ",BJ12="P",BJ12="NS"), 1, 0 ) -> 0 | BN12: 5 | BO12: =IF(ISBLANK($C12),"",IF(ISNUMBER(BK12),BK12+ROW($B12)/1000,"")) | BP12: =IF(ISNUMBER(BO12), RANK(BO12,BO$8:BO$507,1), "") | BQ12: =IF(ISBLANK($C12), "", $B12 ) | BR12: =IF(ISBLANK($C12), "", $C12 ) | BS12: =IF(ISBLANK($C12), "", $D12 ) | BT12: =BH12 | BU12: =BG12 | BV12: =IF(ISBLANK($C12), "", BJ12 ) | BW12: =IF(BN12>BM$7, "", VLOOKUP(BN12,BP$8:BV511,7,FALSE()) ) | BX12: =IF(BN12>BM$7, "", VLOOKUP(BN12,BP$8:BV511,2,FALSE()) ) | BY12: =IF(BN12>BM$7, "", VLOOKUP(BN12,BP$8:BV511,3,FALSE()) ) | BZ12: =IF(BN12>BM$7, "", VLOOKUP(BN12,BP$8:BV511,4,FALSE()) ) | CA12: =IF(BN12>BM$7, "", VLOOKUP(BN12,BP$8:BV511,5,FALSE()) ) | CB12: =IF(BN12>BM$7, "", VLOOKUP(BN12,BP$8:BV511,6,FALSE()) )
U13: =IF(ISBLANK($C13),"",IF(G13=Constants!$B$2, TRUE(), IF(G13=Constants!$B$3, FALSE(), TRUE()))) | V13: =IF(ISBLANK($C13),"",IF(H13=Constants!$B$2, TRUE(), IF(H13=Constants!$B$3, FALSE(), TRUE()))) | W13: =IF(ISBLANK($C13),"",IF(I13=Constants!$B$2, TRUE(), IF(I13=Constants!$B$3, FALSE(), TRUE()))) | X13: =IF(ISBLANK($C13),"",IF(AND(ISNUMBER(J13),J13>0),INT(J13),0)) | Y13: =IF(ISBLANK($C13),"",IF(K13=Constants!$B$2, TRUE(), IF(K13=Constants!$B$3, FALSE(), TRUE()))) | Z13: =IF(ISBLANK($C13),"",IF(AND(ISNUMBER(L13),L13>0),INT(L13),0)) | AA13: =IF(ISBLANK($C13),"",IF(ISNUMBER(M13), M13, "")) | AB13: =IF(ISBLANK($C13),"",IF(ISNUMBER(N13), N13, "")) | AC13: =IF(ISBLANK($C13),"",IF(ISNUMBER(O13), O13, "")) | AD13: =IF(ISBLANK($C13),"",IF(ISNUMBER(P13), P13, "")) | AE13: =IF(ISBLANK($C13),"",IF(ISNUMBER(Q13), Q13, Constants!$B$13)) | AF13: =IF(ISBLANK($C13),"",IF(R13=Constants!$B$2, TRUE(), IF(R13=Constants!$B$3, FALSE(), FALSE()))) | AG13: =IF(ISBLANK(C13), "", IF(AF13, Constants!$B$4,IF(COUNTA(G13:P13)=0, Constants!$B$5, Constants!$B$7))) | AH13: =IF(ISBLANK($C13), "",IF($AG13=Constants!$B$7,1,$AG13)) | AI13: =IF($AG13=Constants!$B$7,POWER(Constants!$B$11,X13)*POWER(Constants!$B$12,Z13),"") | AJ13: =IF(AND($AG13=Constants!$B$7, U13, V13) ,IF(OR($AA13="",$AC13=""),"",MAX(0, $AC13-$AA13)),"") | AK13: =IF(AND($AG13=Constants!$B$7, U13, V13),IF(OR($AA13="",$AC13=""),$AK$6,""),"") | AL13: =IF($AG13=Constants!$B$7,IF(AND(U13,V13,W13,Y13),IF($AJ13="",0,IF($AJ$6=0,Constants!$B$9,Constants!$B$9*AJ13/$AJ$6)), 0),"") | AM13: =IF(AL13<>"", AL13*AI13,"") | AN13: =IF(AND($AG13=Constants!$B$7, U13, V13) ,IF($AB13="", "", IF(OR($AC13="",$AC13=0),"",MAX(0,1-ABS($AC13-$AB13)/$AC13))),"") | AO13: =IF(AND($AG13=Constants!$B$7, U13, V13),IF(AND($AA13<>"",$AB13<>"",$AC13=0),$AO$6,""),"") | AP13: =IF($AG13=Constants!$B$7 ,IF(AND(U13,V13,W13,Y13,ISNUMBER(AB13)),IF($AN13="",0,IF($AN$6=0,Constants!$B$10,Constants!$B$10*AN13/$AN$6)), 0),"") | AQ13: =IF(AP13<>"", AP13*AI13,"") | AR13: =IF($AG13=Constants!$B$7,IF($AD13="",0,IF($AR$6=0,Constants!$B$8,Constants!$B$8*AD13/$AR$6)),"") | AS13: =IF($AG13<>Constants!$B$7,$AG13,IF(AK13&AO13<>"",Constants!$B$14,AM13+AQ13+AR13)) | AT13: =IF(ISBLANK($C13),"",IF($AG13=Constants!$B$7,IF(ISNUMBER(AS13),RANK(AS13,$AS$8:$AS$507),Constants!$B$14),$AG13)) | AU13: =IF(ISBLANK($C13), "",AM13) | AV13: =IF(ISBLANK($C13),"",IF($AG13=Constants!$B$7,RANK(AU13,AU$8:AU$507),$AG13)) | AW13: =IF(ISBLANK($C13), "",AR13) | AX13: =IF(ISBLANK($C13),"",IF($AG13=Constants!$B$7,RANK(AW13,AW$8:AW$507),$AG13)) | AY13: =IF(ISBLANK($C13), "",AE13) | AZ13: =IF(ISBLANK($C13),"", IF($AG13=Constants!$B$7, IF(ISNUMBER(AT13), COUNTIFS($AT$8:$AT$507,"<"&$AT13) + COUNTIFS($AT$8:$AT$507,$AT13,$AV$8:$AV$507,"<"&$AV13) + COUNTIFS($AT$8:$AT$507,$AT13,$AV$8:$AV$507,$AV13,$AX$8:$AX$507,"<"&$AX13) + COUNTIFS($AT$8:$AT$507,$AT13,$AV$8:$AV$507,$AV13,$AX$8:$AX$507,$AX13,$AY$8:$AY$507,"<"&$AY13) + 1, Constants!$B$14), $AG13)) | BA13: =IF(ISBLANK(C13),"",IF($AG13=Constants!$B$7, IF(ISNUMBER(AT13),AT13-AZ13,Constants!$B$14),$AG13)) | BC13: =IF(ISBLANK($C13),"",TRIM(AK13&" "&AO13)) | BD13: =IF(ISBLANK($C13),"",IF($AG13<>Constants!$B$7,$AG13,AR13)) | BE13: =IF(ISBLANK($C13),"",IF($AG13<>Constants!$B$7,$AG13,AM13)) | BF13: =IF(ISBLANK($C13),"",IF($AG13<>Constants!$B$7,$AG13,AQ13)) | BG13: =IF(ISBLANK($C13),"",IF($AG13<>Constants!$B$7, $AG13 ,AS13)) | BH13: =IF(ISBLANK($C13),"",IF($AG13<>Constants!$B$7, $AG13 ,AH13)) | BI13: =IF(ISBLANK(C13),"",BA13) | BJ13: =IF(ISBLANK(C13),"",AZ13) | BK13: =IF(ISBLANK(C13),"",IFERROR(_xlfn.SWITCH(BJ13, Constants!$B$4, COUNTA($C$8:$C512)+2, Constants!$B$5, COUNTA($C$8:$C512)+1, Constants!$B$6, COUNTA($C$8:$C512)),BJ13)) | BM13: =IF(OR(ISNUMBER(BJ13),BJ13="DQ",BJ13="P",BJ13="NS"), 1, 0 ) -> 0 | BN13: 6 | BO13: =IF(ISBLANK($C13),"",IF(ISNUMBER(BK13),BK13+ROW($B13)/1000,"")) | BP13: =IF(ISNUMBER(BO13), RANK(BO13,BO$8:BO$507,1), "") | BQ13: =IF(ISBLANK($C13), "", $B13 ) | BR13: =IF(ISBLANK($C13), "", $C13 ) | BS13: =IF(ISBLANK($C13), "", $D13 ) | BT13: =BH13 | BU13: =BG13 | BV13: =IF(ISBLANK($C13), "", BJ13 ) | BW13: =IF(BN13>BM$7, "", VLOOKUP(BN13,BP$8:BV512,7,FALSE()) ) | BX13: =IF(BN13>BM$7, "", VLOOKUP(BN13,BP$8:BV512,2,FALSE()) ) | BY13: =IF(BN13>BM$7, "", VLOOKUP(BN13,BP$8:BV512,3,FALSE()) ) | BZ13: =IF(BN13>BM$7, "", VLOOKUP(BN13,BP$8:BV512,4,FALSE()) ) | CA13: =IF(BN13>BM$7, "", VLOOKUP(BN13,BP$8:BV512,5,FALSE()) ) | CB13: =IF(BN13>BM$7, "", VLOOKUP(BN13,BP$8:BV512,6,FALSE()) )
U14: =IF(ISBLANK($C14),"",IF(G14=Constants!$B$2, TRUE(), IF(G14=Constants!$B$3, FALSE(), TRUE()))) | V14: =IF(ISBLANK($C14),"",IF(H14=Constants!$B$2, TRUE(), IF(H14=Constants!$B$3, FALSE(), TRUE()))) | W14: =IF(ISBLANK($C14),"",IF(I14=Constants!$B$2, TRUE(), IF(I14=Constants!$B$3, FALSE(), TRUE()))) | X14: =IF(ISBLANK($C14),"",IF(AND(ISNUMBER(J14),J14>0),INT(J14),0)) | Y14: =IF(ISBLANK($C14),"",IF(K14=Constants!$B$2, TRUE(), IF(K14=Constants!$B$3, FALSE(), TRUE()))) | Z14: =IF(ISBLANK($C14),"",IF(AND(ISNUMBER(L14),L14>0),INT(L14),0)) | AA14: =IF(ISBLANK($C14),"",IF(ISNUMBER(M14), M14, "")) | AB14: =IF(ISBLANK($C14),"",IF(ISNUMBER(N14), N14, "")) | AC14: =IF(ISBLANK($C14),"",IF(ISNUMBER(O14), O14, "")) | AD14: =IF(ISBLANK($C14),"",IF(ISNUMBER(P14), P14, "")) | AE14: =IF(ISBLANK($C14),"",IF(ISNUMBER(Q14), Q14, Constants!$B$13)) | AF14: =IF(ISBLANK($C14),"",IF(R14=Constants!$B$2, TRUE(), IF(R14=Constants!$B$3, FALSE(), FALSE()))) | AG14: =IF(ISBLANK(C14), "", IF(AF14, Constants!$B$4,IF(COUNTA(G14:P14)=0, Constants!$B$5, Constants!$B$7))) | AH14: =IF(ISBLANK($C14), "",IF($AG14=Constants!$B$7,1,$AG14)) | AI14: =IF($AG14=Constants!$B$7,POWER(Constants!$B$11,X14)*POWER(Constants!$B$12,Z14),"") | AJ14: =IF(AND($AG14=Constants!$B$7, U14, V14) ,IF(OR($AA14="",$AC14=""),"",MAX(0, $AC14-$AA14)),"") | AK14: =IF(AND($AG14=Constants!$B$7, U14, V14),IF(OR($AA14="",$AC14=""),$AK$6,""),"") | AL14: =IF($AG14=Constants!$B$7,IF(AND(U14,V14,W14,Y14),IF($AJ14="",0,IF($AJ$6=0,Constants!$B$9,Constants!$B$9*AJ14/$AJ$6)), 0),"") | AM14: =IF(AL14<>"", AL14*AI14,"") | AN14: =IF(AND($AG14=Constants!$B$7, U14, V14) ,IF($AB14="", "", IF(OR($AC14="",$AC14=0),"",MAX(0,1-ABS($AC14-$AB14)/$AC14))),"") | AO14: =IF(AND($AG14=Constants!$B$7, U14, V14),IF(AND($AA14<>"",$AB14<>"",$AC14=0),$AO$6,""),"") | AP14: =IF($AG14=Constants!$B$7 ,IF(AND(U14,V14,W14,Y14,ISNUMBER(AB14)),IF($AN14="",0,IF($AN$6=0,Constants!$B$10,Constants!$B$10*AN14/$AN$6)), 0),"") | AQ14: =IF(AP14<>"", AP14*AI14,"") | AR14: =IF($AG14=Constants!$B$7,IF($AD14="",0,IF($AR$6=0,Constants!$B$8,Constants!$B$8*AD14/$AR$6)),"") | AS14: =IF($AG14<>Constants!$B$7,$AG14,IF(AK14&AO14<>"",Constants!$B$14,AM14+AQ14+AR14)) | AT14: =IF(ISBLANK($C14),"",IF($AG14=Constants!$B$7,IF(ISNUMBER(AS14),RANK(AS14,$AS$8:$AS$507),Constants!$B$14),$AG14)) | AU14: =IF(ISBLANK($C14), "",AM14) | AV14: =IF(ISBLANK($C14),"",IF($AG14=Constants!$B$7,RANK(AU14,AU$8:AU$507),$AG14)) | AW14: =IF(ISBLANK($C14), "",AR14) | AX14: =IF(ISBLANK($C14),"",IF($AG14=Constants!$B$7,RANK(AW14,AW$8:AW$507),$AG14)) | AY14: =IF(ISBLANK($C14), "",AE14) | AZ14: =IF(ISBLANK($C14),"", IF($AG14=Constants!$B$7, IF(ISNUMBER(AT14), COUNTIFS($AT$8:$AT$507,"<"&$AT14) + COUNTIFS($AT$8:$AT$507,$AT14,$AV$8:$AV$507,"<"&$AV14) + COUNTIFS($AT$8:$AT$507,$AT14,$AV$8:$AV$507,$AV14,$AX$8:$AX$507,"<"&$AX14) + COUNTIFS($AT$8:$AT$507,$AT14,$AV$8:$AV$507,$AV14,$AX$8:$AX$507,$AX14,$AY$8:$AY$507,"<"&$AY14) + 1, Constants!$B$14), $AG14)) | BA14: =IF(ISBLANK(C14),"",IF($AG14=Constants!$B$7, IF(ISNUMBER(AT14),AT14-AZ14,Constants!$B$14),$AG14)) | BC14: =IF(ISBLANK($C14),"",TRIM(AK14&" "&AO14)) | BD14: =IF(ISBLANK($C14),"",IF($AG14<>Constants!$B$7,$AG14,AR14)) | BE14: =IF(ISBLANK($C14),"",IF($AG14<>Constants!$B$7,$AG14,AM14)) | BF14: =IF(ISBLANK($C14),"",IF($AG14<>Constants!$B$7,$AG14,AQ14)) | BG14: =IF(ISBLANK($C14),"",IF($AG14<>Constants!$B$7, $AG14 ,AS14)) | BH14: =IF(ISBLANK($C14),"",IF($AG14<>Constants!$B$7, $AG14 ,AH14)) | BI14: =IF(ISBLANK(C14),"",BA14) | BJ14: =IF(ISBLANK(C14),"",AZ14) | BK14: =IF(ISBLANK(C14),"",IFERROR(_xlfn.SWITCH(BJ14, Constants!$B$4, COUNTA($C$8:$C513)+2, Constants!$B$5, COUNTA($C$8:$C513)+1, Constants!$B$6, COUNTA($C$8:$C513)),BJ14)) | BM14: =IF(OR(ISNUMBER(BJ14),BJ14="DQ",BJ14="P",BJ14="NS"), 1, 0 ) -> 0 | BN14: 7 | BO14: =IF(ISBLANK($C14),"",IF(ISNUMBER(BK14),BK14+ROW($B14)/1000,"")) | BP14: =IF(ISNUMBER(BO14), RANK(BO14,BO$8:BO$507,1), "") | BQ14: =IF(ISBLANK($C14), "", $B14 ) | BR14: =IF(ISBLANK($C14), "", $C14 ) | BS14: =IF(ISBLANK($C14), "", $D14 ) | BT14: =BH14 | BU14: =BG14 | BV14: =IF(ISBLANK($C14), "", BJ14 ) | BW14: =IF(BN14>BM$7, "", VLOOKUP(BN14,BP$8:BV513,7,FALSE()) ) | BX14: =IF(BN14>BM$7, "", VLOOKUP(BN14,BP$8:BV513,2,FALSE()) ) | BY14: =IF(BN14>BM$7, "", VLOOKUP(BN14,BP$8:BV513,3,FALSE()) ) | BZ14: =IF(BN14>BM$7, "", VLOOKUP(BN14,BP$8:BV513,4,FALSE()) ) | CA14: =IF(BN14>BM$7, "", VLOOKUP(BN14,BP$8:BV513,5,FALSE()) ) | CB14: =IF(BN14>BM$7, "", VLOOKUP(BN14,BP$8:BV513,6,FALSE()) )
U15: =IF(ISBLANK($C15),"",IF(G15=Constants!$B$2, TRUE(), IF(G15=Constants!$B$3, FALSE(), TRUE()))) | V15: =IF(ISBLANK($C15),"",IF(H15=Constants!$B$2, TRUE(), IF(H15=Constants!$B$3, FALSE(), TRUE()))) | W15: =IF(ISBLANK($C15),"",IF(I15=Constants!$B$2, TRUE(), IF(I15=Constants!$B$3, FALSE(), TRUE()))) | X15: =IF(ISBLANK($C15),"",IF(AND(ISNUMBER(J15),J15>0),INT(J15),0)) | Y15: =IF(ISBLANK($C15),"",IF(K15=Constants!$B$2, TRUE(), IF(K15=Constants!$B$3, FALSE(), TRUE()))) | Z15: =IF(ISBLANK($C15),"",IF(AND(ISNUMBER(L15),L15>0),INT(L15),0)) | AA15: =IF(ISBLANK($C15),"",IF(ISNUMBER(M15), M15, "")) | AB15: =IF(ISBLANK($C15),"",IF(ISNUMBER(N15), N15, "")) | AC15: =IF(ISBLANK($C15),"",IF(ISNUMBER(O15), O15, "")) | AD15: =IF(ISBLANK($C15),"",IF(ISNUMBER(P15), P15, "")) | AE15: =IF(ISBLANK($C15),"",IF(ISNUMBER(Q15), Q15, Constants!$B$13)) | AF15: =IF(ISBLANK($C15),"",IF(R15=Constants!$B$2, TRUE(), IF(R15=Constants!$B$3, FALSE(), FALSE()))) | AG15: =IF(ISBLANK(C15), "", IF(AF15, Constants!$B$4,IF(COUNTA(G15:P15)=0, Constants!$B$5, Constants!$B$7))) | AH15: =IF(ISBLANK($C15), "",IF($AG15=Constants!$B$7,1,$AG15)) | AI15: =IF($AG15=Constants!$B$7,POWER(Constants!$B$11,X15)*POWER(Constants!$B$12,Z15),"") | AJ15: =IF(AND($AG15=Constants!$B$7, U15, V15) ,IF(OR($AA15="",$AC15=""),"",MAX(0, $AC15-$AA15)),"") | AK15: =IF(AND($AG15=Constants!$B$7, U15, V15),IF(OR($AA15="",$AC15=""),$AK$6,""),"") | AL15: =IF($AG15=Constants!$B$7,IF(AND(U15,V15,W15,Y15),IF($AJ15="",0,IF($AJ$6=0,Constants!$B$9,Constants!$B$9*AJ15/$AJ$6)), 0),"") | AM15: =IF(AL15<>"", AL15*AI15,"") | AN15: =IF(AND($AG15=Constants!$B$7, U15, V15) ,IF($AB15="", "", IF(OR($AC15="",$AC15=0),"",MAX(0,1-ABS($AC15-$AB15)/$AC15))),"") | AO15: =IF(AND($AG15=Constants!$B$7, U15, V15),IF(AND($AA15<>"",$AB15<>"",$AC15=0),$AO$6,""),"") | AP15: =IF($AG15=Constants!$B$7 ,IF(AND(U15,V15,W15,Y15,ISNUMBER(AB15)),IF($AN15="",0,IF($AN$6=0,Constants!$B$10,Constants!$B$10*AN15/$AN$6)), 0),"") | AQ15: =IF(AP15<>"", AP15*AI15,"") | AR15: =IF($AG15=Constants!$B$7,IF($AD15="",0,IF($AR$6=0,Constants!$B$8,Constants!$B$8*AD15/$AR$6)),"") | AS15: =IF($AG15<>Constants!$B$7,$AG15,IF(AK15&AO15<>"",Constants!$B$14,AM15+AQ15+AR15)) | AT15: =IF(ISBLANK($C15),"",IF($AG15=Constants!$B$7,IF(ISNUMBER(AS15),RANK(AS15,$AS$8:$AS$507),Constants!$B$14),$AG15)) | AU15: =IF(ISBLANK($C15), "",AM15) | AV15: =IF(ISBLANK($C15),"",IF($AG15=Constants!$B$7,RANK(AU15,AU$8:AU$507),$AG15)) | AW15: =IF(ISBLANK($C15), "",AR15) | AX15: =IF(ISBLANK($C15),"",IF($AG15=Constants!$B$7,RANK(AW15,AW$8:AW$507),$AG15)) | AY15: =IF(ISBLANK($C15), "",AE15) | AZ15: =IF(ISBLANK($C15),"", IF($AG15=Constants!$B$7, IF(ISNUMBER(AT15), COUNTIFS($AT$8:$AT$507,"<"&$AT15) + COUNTIFS($AT$8:$AT$507,$AT15,$AV$8:$AV$507,"<"&$AV15) + COUNTIFS($AT$8:$AT$507,$AT15,$AV$8:$AV$507,$AV15,$AX$8:$AX$507,"<"&$AX15) + COUNTIFS($AT$8:$AT$507,$AT15,$AV$8:$AV$507,$AV15,$AX$8:$AX$507,$AX15,$AY$8:$AY$507,"<"&$AY15) + 1, Constants!$B$14), $AG15)) | BA15: =IF(ISBLANK(C15),"",IF($AG15=Constants!$B$7, IF(ISNUMBER(AT15),AT15-AZ15,Constants!$B$14),$AG15)) | BC15: =IF(ISBLANK($C15),"",TRIM(AK15&" "&AO15)) | BD15: =IF(ISBLANK($C15),"",IF($AG15<>Constants!$B$7,$AG15,AR15)) | BE15: =IF(ISBLANK($C15),"",IF($AG15<>Constants!$B$7,$AG15,AM15)) | BF15: =IF(ISBLANK($C15),"",IF($AG15<>Constants!$B$7,$AG15,AQ15)) | BG15: =IF(ISBLANK($C15),"",IF($AG15<>Constants!$B$7, $AG15 ,AS15)) | BH15: =IF(ISBLANK($C15),"",IF($AG15<>Constants!$B$7, $AG15 ,AH15)) | BI15: =IF(ISBLANK(C15),"",BA15) | BJ15: =IF(ISBLANK(C15),"",AZ15) | BK15: =IF(ISBLANK(C15),"",IFERROR(_xlfn.SWITCH(BJ15, Constants!$B$4, COUNTA($C$8:$C514)+2, Constants!$B$5, COUNTA($C$8:$C514)+1, Constants!$B$6, COUNTA($C$8:$C514)),BJ15)) | BM15: =IF(OR(ISNUMBER(BJ15),BJ15="DQ",BJ15="P",BJ15="NS"), 1, 0 ) -> 0 | BN15: 8 | BO15: =IF(ISBLANK($C15),"",IF(ISNUMBER(BK15),BK15+ROW($B15)/1000,"")) | BP15: =IF(ISNUMBER(BO15), RANK(BO15,BO$8:BO$507,1), "") | BQ15: =IF(ISBLANK($C15), "", $B15 ) | BR15: =IF(ISBLANK($C15), "", $C15 ) | BS15: =IF(ISBLANK($C15), "", $D15 ) | BT15: =BH15 | BU15: =BG15 | BV15: =IF(ISBLANK($C15), "", BJ15 ) | BW15: =IF(BN15>BM$7, "", VLOOKUP(BN15,BP$8:BV514,7,FALSE()) ) | BX15: =IF(BN15>BM$7, "", VLOOKUP(BN15,BP$8:BV514,2,FALSE()) ) | BY15: =IF(BN15>BM$7, "", VLOOKUP(BN15,BP$8:BV514,3,FALSE()) ) | BZ15: =IF(BN15>BM$7, "", VLOOKUP(BN15,BP$8:BV514,4,FALSE()) ) | CA15: =IF(BN15>BM$7, "", VLOOKUP(BN15,BP$8:BV514,5,FALSE()) ) | CB15: =IF(BN15>BM$7, "", VLOOKUP(BN15,BP$8:BV514,6,FALSE()) )
U16: =IF(ISBLANK($C16),"",IF(G16=Constants!$B$2, TRUE(), IF(G16=Constants!$B$3, FALSE(), TRUE()))) | V16: =IF(ISBLANK($C16),"",IF(H16=Constants!$B$2, TRUE(), IF(H16=Constants!$B$3, FALSE(), TRUE()))) | W16: =IF(ISBLANK($C16),"",IF(I16=Constants!$B$2, TRUE(), IF(I16=Constants!$B$3, FALSE(), TRUE()))) | X16: =IF(ISBLANK($C16),"",IF(AND(ISNUMBER(J16),J16>0),INT(J16),0)) | Y16: =IF(ISBLANK($C16),"",IF(K16=Constants!$B$2, TRUE(), IF(K16=Constants!$B$3, FALSE(), TRUE()))) | Z16: =IF(ISBLANK($C16),"",IF(AND(ISNUMBER(L16),L16>0),INT(L16),0)) | AA16: =IF(ISBLANK($C16),"",IF(ISNUMBER(M16), M16, "")) | AB16: =IF(ISBLANK($C16),"",IF(ISNUMBER(N16), N16, "")) | AC16: =IF(ISBLANK($C16),"",IF(ISNUMBER(O16), O16, "")) | AD16: =IF(ISBLANK($C16),"",IF(ISNUMBER(P16), P16, "")) | AE16: =IF(ISBLANK($C16),"",IF(ISNUMBER(Q16), Q16, Constants!$B$13)) | AF16: =IF(ISBLANK($C16),"",IF(R16=Constants!$B$2, TRUE(), IF(R16=Constants!$B$3, FALSE(), FALSE()))) | AG16: =IF(ISBLANK(C16), "", IF(AF16, Constants!$B$4,IF(COUNTA(G16:P16)=0, Constants!$B$5, Constants!$B$7))) | AH16: =IF(ISBLANK($C16), "",IF($AG16=Constants!$B$7,1,$AG16)) | AI16: =IF($AG16=Constants!$B$7,POWER(Constants!$B$11,X16)*POWER(Constants!$B$12,Z16),"") | AJ16: =IF(AND($AG16=Constants!$B$7, U16, V16) ,IF(OR($AA16="",$AC16=""),"",MAX(0, $AC16-$AA16)),"") | AK16: =IF(AND($AG16=Constants!$B$7, U16, V16),IF(OR($AA16="",$AC16=""),$AK$6,""),"") | AL16: =IF($AG16=Constants!$B$7,IF(AND(U16,V16,W16,Y16),IF($AJ16="",0,IF($AJ$6=0,Constants!$B$9,Constants!$B$9*AJ16/$AJ$6)), 0),"") | AM16: =IF(AL16<>"", AL16*AI16,"") | AN16: =IF(AND($AG16=Constants!$B$7, U16, V16) ,IF($AB16="", "", IF(OR($AC16="",$AC16=0),"",MAX(0,1-ABS($AC16-$AB16)/$AC16))),"") | AO16: =IF(AND($AG16=Constants!$B$7, U16, V16),IF(AND($AA16<>"",$AB16<>"",$AC16=0),$AO$6,""),"") | AP16: =IF($AG16=Constants!$B$7 ,IF(AND(U16,V16,W16,Y16,ISNUMBER(AB16)),IF($AN16="",0,IF($AN$6=0,Constants!$B$10,Constants!$B$10*AN16/$AN$6)), 0),"") | AQ16: =IF(AP16<>"", AP16*AI16,"") | AR16: =IF($AG16=Constants!$B$7,IF($AD16="",0,IF($AR$6=0,Constants!$B$8,Constants!$B$8*AD16/$AR$6)),"") | AS16: =IF($AG16<>Constants!$B$7,$AG16,IF(AK16&AO16<>"",Constants!$B$14,AM16+AQ16+AR16)) | AT16: =IF(ISBLANK($C16),"",IF($AG16=Constants!$B$7,IF(ISNUMBER(AS16),RANK(AS16,$AS$8:$AS$507),Constants!$B$14),$AG16)) | AU16: =IF(ISBLANK($C16), "",AM16) | AV16: =IF(ISBLANK($C16),"",IF($AG16=Constants!$B$7,RANK(AU16,AU$8:AU$507),$AG16)) | AW16: =IF(ISBLANK($C16), "",AR16) | AX16: =IF(ISBLANK($C16),"",IF($AG16=Constants!$B$7,RANK(AW16,AW$8:AW$507),$AG16)) | AY16: =IF(ISBLANK($C16), "",AE16) | AZ16: =IF(ISBLANK($C16),"", IF($AG16=Constants!$B$7, IF(ISNUMBER(AT16), COUNTIFS($AT$8:$AT$507,"<"&$AT16) + COUNTIFS($AT$8:$AT$507,$AT16,$AV$8:$AV$507,"<"&$AV16) + COUNTIFS($AT$8:$AT$507,$AT16,$AV$8:$AV$507,$AV16,$AX$8:$AX$507,"<"&$AX16) + COUNTIFS($AT$8:$AT$507,$AT16,$AV$8:$AV$507,$AV16,$AX$8:$AX$507,$AX16,$AY$8:$AY$507,"<"&$AY16) + 1, Constants!$B$14), $AG16)) | BA16: =IF(ISBLANK(C16),"",IF($AG16=Constants!$B$7, IF(ISNUMBER(AT16),AT16-AZ16,Constants!$B$14),$AG16)) | BC16: =IF(ISBLANK($C16),"",TRIM(AK16&" "&AO16)) | BD16: =IF(ISBLANK($C16),"",IF($AG16<>Constants!$B$7,$AG16,AR16)) | BE16: =IF(ISBLANK($C16),"",IF($AG16<>Constants!$B$7,$AG16,AM16)) | BF16: =IF(ISBLANK($C16),"",IF($AG16<>Constants!$B$7,$AG16,AQ16)) | BG16: =IF(ISBLANK($C16),"",IF($AG16<>Constants!$B$7, $AG16 ,AS16)) | BH16: =IF(ISBLANK($C16),"",IF($AG16<>Constants!$B$7, $AG16 ,AH16)) | BI16: =IF(ISBLANK(C16),"",BA16) | BJ16: =IF(ISBLANK(C16),"",AZ16) | BK16: =IF(ISBLANK(C16),"",IFERROR(_xlfn.SWITCH(BJ16, Constants!$B$4, COUNTA($C$8:$C515)+2, Constants!$B$5, COUNTA($C$8:$C515)+1, Constants!$B$6, COUNTA($C$8:$C515)),BJ16)) | BM16: =IF(OR(ISNUMBER(BJ16),BJ16="DQ",BJ16="P",BJ16="NS"), 1, 0 ) -> 0 | BN16: 9 | BO16: =IF(ISBLANK($C16),"",IF(ISNUMBER(BK16),BK16+ROW($B16)/1000,"")) | BP16: =IF(ISNUMBER(BO16), RANK(BO16,BO$8:BO$507,1), "") | BQ16: =IF(ISBLANK($C16), "", $B16 ) | BR16: =IF(ISBLANK($C16), "", $C16 ) | BS16: =IF(ISBLANK($C16), "", $D16 ) | BT16: =BH16 | BU16: =BG16 | BV16: =IF(ISBLANK($C16), "", BJ16 ) | BW16: =IF(BN16>BM$7, "", VLOOKUP(BN16,BP$8:BV515,7,FALSE()) ) | BX16: =IF(BN16>BM$7, "", VLOOKUP(BN16,BP$8:BV515,2,FALSE()) ) | BY16: =IF(BN16>BM$7, "", VLOOKUP(BN16,BP$8:BV515,3,FALSE()) ) | BZ16: =IF(BN16>BM$7, "", VLOOKUP(BN16,BP$8:BV515,4,FALSE()) ) | CA16: =IF(BN16>BM$7, "", VLOOKUP(BN16,BP$8:BV515,5,FALSE()) ) | CB16: =IF(BN16>BM$7, "", VLOOKUP(BN16,BP$8:BV515,6,FALSE()) )
U17: =IF(ISBLANK($C17),"",IF(G17=Constants!$B$2, TRUE(), IF(G17=Constants!$B$3, FALSE(), TRUE()))) | V17: =IF(ISBLANK($C17),"",IF(H17=Constants!$B$2, TRUE(), IF(H17=Constants!$B$3, FALSE(), TRUE()))) | W17: =IF(ISBLANK($C17),"",IF(I17=Constants!$B$2, TRUE(), IF(I17=Constants!$B$3, FALSE(), TRUE()))) | X17: =IF(ISBLANK($C17),"",IF(AND(ISNUMBER(J17),J17>0),INT(J17),0)) | Y17: =IF(ISBLANK($C17),"",IF(K17=Constants!$B$2, TRUE(), IF(K17=Constants!$B$3, FALSE(), TRUE()))) | Z17: =IF(ISBLANK($C17),"",IF(AND(ISNUMBER(L17),L17>0),INT(L17),0)) | AA17: =IF(ISBLANK($C17),"",IF(ISNUMBER(M17), M17, "")) | AB17: =IF(ISBLANK($C17),"",IF(ISNUMBER(N17), N17, "")) | AC17: =IF(ISBLANK($C17),"",IF(ISNUMBER(O17), O17, "")) | AD17: =IF(ISBLANK($C17),"",IF(ISNUMBER(P17), P17, "")) | AE17: =IF(ISBLANK($C17),"",IF(ISNUMBER(Q17), Q17, Constants!$B$13)) | AF17: =IF(ISBLANK($C17),"",IF(R17=Constants!$B$2, TRUE(), IF(R17=Constants!$B$3, FALSE(), FALSE()))) | AG17: =IF(ISBLANK(C17), "", IF(AF17, Constants!$B$4,IF(COUNTA(G17:P17)=0, Constants!$B$5, Constants!$B$7))) | AH17: =IF(ISBLANK($C17), "",IF($AG17=Constants!$B$7,1,$AG17)) | AI17: =IF($AG17=Constants!$B$7,POWER(Constants!$B$11,X17)*POWER(Constants!$B$12,Z17),"") | AJ17: =IF(AND($AG17=Constants!$B$7, U17, V17) ,IF(OR($AA17="",$AC17=""),"",MAX(0, $AC17-$AA17)),"") | AK17: =IF(AND($AG17=Constants!$B$7, U17, V17),IF(OR($AA17="",$AC17=""),$AK$6,""),"") | AL17: =IF($AG17=Constants!$B$7,IF(AND(U17,V17,W17,Y17),IF($AJ17="",0,IF($AJ$6=0,Constants!$B$9,Constants!$B$9*AJ17/$AJ$6)), 0),"") | AM17: =IF(AL17<>"", AL17*AI17,"") | AN17: =IF(AND($AG17=Constants!$B$7, U17, V17) ,IF($AB17="", "", IF(OR($AC17="",$AC17=0),"",MAX(0,1-ABS($AC17-$AB17)/$AC17))),"") | AO17: =IF(AND($AG17=Constants!$B$7, U17, V17),IF(AND($AA17<>"",$AB17<>"",$AC17=0),$AO$6,""),"") | AP17: =IF($AG17=Constants!$B$7 ,IF(AND(U17,V17,W17,Y17,ISNUMBER(AB17)),IF($AN17="",0,IF($AN$6=0,Constants!$B$10,Constants!$B$10*AN17/$AN$6)), 0),"") | AQ17: =IF(AP17<>"", AP17*AI17,"") | AR17: =IF($AG17=Constants!$B$7,IF($AD17="",0,IF($AR$6=0,Constants!$B$8,Constants!$B$8*AD17/$AR$6)),"") | AS17: =IF($AG17<>Constants!$B$7,$AG17,IF(AK17&AO17<>"",Constants!$B$14,AM17+AQ17+AR17)) | AT17: =IF(ISBLANK($C17),"",IF($AG17=Constants!$B$7,IF(ISNUMBER(AS17),RANK(AS17,$AS$8:$AS$507),Constants!$B$14),$AG17)) | AU17: =IF(ISBLANK($C17), "",AM17) | AV17: =IF(ISBLANK($C17),"",IF($AG17=Constants!$B$7,RANK(AU17,AU$8:AU$507),$AG17)) | AW17: =IF(ISBLANK($C17), "",AR17) | AX17: =IF(ISBLANK($C17),"",IF($AG17=Constants!$B$7,RANK(AW17,AW$8:AW$507),$AG17)) | AY17: =IF(ISBLANK($C17), "",AE17) | AZ17: =IF(ISBLANK($C17),"", IF($AG17=Constants!$B$7, IF(ISNUMBER(AT17), COUNTIFS($AT$8:$AT$507,"<"&$AT17) + COUNTIFS($AT$8:$AT$507,$AT17,$AV$8:$AV$507,"<"&$AV17) + COUNTIFS($AT$8:$AT$507,$AT17,$AV$8:$AV$507,$AV17,$AX$8:$AX$507,"<"&$AX17) + COUNTIFS($AT$8:$AT$507,$AT17,$AV$8:$AV$507,$AV17,$AX$8:$AX$507,$AX17,$AY$8:$AY$507,"<"&$AY17) + 1, Constants!$B$14), $AG17)) | BA17: =IF(ISBLANK(C17),"",IF($AG17=Constants!$B$7, IF(ISNUMBER(AT17),AT17-AZ17,Constants!$B$14),$AG17)) | BC17: =IF(ISBLANK($C17),"",TRIM(AK17&" "&AO17)) | BD17: =IF(ISBLANK($C17),"",IF($AG17<>Constants!$B$7,$AG17,AR17)) | BE17: =IF(ISBLANK($C17),"",IF($AG17<>Constants!$B$7,$AG17,AM17)) | BF17: =IF(ISBLANK($C17),"",IF($AG17<>Constants!$B$7,$AG17,AQ17)) | BG17: =IF(ISBLANK($C17),"",IF($AG17<>Constants!$B$7, $AG17 ,AS17)) | BH17: =IF(ISBLANK($C17),"",IF($AG17<>Constants!$B$7, $AG17 ,AH17)) | BI17: =IF(ISBLANK(C17),"",BA17) | BJ17: =IF(ISBLANK(C17),"",AZ17) | BK17: =IF(ISBLANK(C17),"",IFERROR(_xlfn.SWITCH(BJ17, Constants!$B$4, COUNTA($C$8:$C516)+2, Constants!$B$5, COUNTA($C$8:$C516)+1, Constants!$B$6, COUNTA($C$8:$C516)),BJ17)) | BM17: =IF(OR(ISNUMBER(BJ17),BJ17="DQ",BJ17="P",BJ17="NS"), 1, 0 ) -> 0 | BN17: 10 | BO17: =IF(ISBLANK($C17),"",IF(ISNUMBER(BK17),BK17+ROW($B17)/1000,"")) | BP17: =IF(ISNUMBER(BO17), RANK(BO17,BO$8:BO$507,1), "") | BQ17: =IF(ISBLANK($C17), "", $B17 ) | BR17: =IF(ISBLANK($C17), "", $C17 ) | BS17: =IF(ISBLANK($C17), "", $D17 ) | BT17: =BH17 | BU17: =BG17 | BV17: =IF(ISBLANK($C17), "", BJ17 ) | BW17: =IF(BN17>BM$7, "", VLOOKUP(BN17,BP$8:BV516,7,FALSE()) ) | BX17: =IF(BN17>BM$7, "", VLOOKUP(BN17,BP$8:BV516,2,FALSE()) ) | BY17: =IF(BN17>BM$7, "", VLOOKUP(BN17,BP$8:BV516,3,FALSE()) ) | BZ17: =IF(BN17>BM$7, "", VLOOKUP(BN17,BP$8:BV516,4,FALSE()) ) | CA17: =IF(BN17>BM$7, "", VLOOKUP(BN17,BP$8:BV516,5,FALSE()) ) | CB17: =IF(BN17>BM$7, "", VLOOKUP(BN17,BP$8:BV516,6,FALSE()) )
U18: =IF(ISBLANK($C18),"",IF(G18=Constants!$B$2, TRUE(), IF(G18=Constants!$B$3, FALSE(), TRUE()))) | V18: =IF(ISBLANK($C18),"",IF(H18=Constants!$B$2, TRUE(), IF(H18=Constants!$B$3, FALSE(), TRUE()))) | W18: =IF(ISBLANK($C18),"",IF(I18=Constants!$B$2, TRUE(), IF(I18=Constants!$B$3, FALSE(), TRUE()))) | X18: =IF(ISBLANK($C18),"",IF(AND(ISNUMBER(J18),J18>0),INT(J18),0)) | Y18: =IF(ISBLANK($C18),"",IF(K18=Constants!$B$2, TRUE(), IF(K18=Constants!$B$3, FALSE(), TRUE()))) | Z18: =IF(ISBLANK($C18),"",IF(AND(ISNUMBER(L18),L18>0),INT(L18),0)) | AA18: =IF(ISBLANK($C18),"",IF(ISNUMBER(M18), M18, "")) | AB18: =IF(ISBLANK($C18),"",IF(ISNUMBER(N18), N18, "")) | AC18: =IF(ISBLANK($C18),"",IF(ISNUMBER(O18), O18, "")) | AD18: =IF(ISBLANK($C18),"",IF(ISNUMBER(P18), P18, "")) | AE18: =IF(ISBLANK($C18),"",IF(ISNUMBER(Q18), Q18, Constants!$B$13)) | AF18: =IF(ISBLANK($C18),"",IF(R18=Constants!$B$2, TRUE(), IF(R18=Constants!$B$3, FALSE(), FALSE()))) | AG18: =IF(ISBLANK(C18), "", IF(AF18, Constants!$B$4,IF(COUNTA(G18:P18)=0, Constants!$B$5, Constants!$B$7))) | AH18: =IF(ISBLANK($C18), "",IF($AG18=Constants!$B$7,1,$AG18)) | AI18: =IF($AG18=Constants!$B$7,POWER(Constants!$B$11,X18)*POWER(Constants!$B$12,Z18),"") | AJ18: =IF(AND($AG18=Constants!$B$7, U18, V18) ,IF(OR($AA18="",$AC18=""),"",MAX(0, $AC18-$AA18)),"") | AK18: =IF(AND($AG18=Constants!$B$7, U18, V18),IF(OR($AA18="",$AC18=""),$AK$6,""),"") | AL18: =IF($AG18=Constants!$B$7,IF(AND(U18,V18,W18,Y18),IF($AJ18="",0,IF($AJ$6=0,Constants!$B$9,Constants!$B$9*AJ18/$AJ$6)), 0),"") | AM18: =IF(AL18<>"", AL18*AI18,"") | AN18: =IF(AND($AG18=Constants!$B$7, U18, V18) ,IF($AB18="", "", IF(OR($AC18="",$AC18=0),"",MAX(0,1-ABS($AC18-$AB18)/$AC18))),"") | AO18: =IF(AND($AG18=Constants!$B$7, U18, V18),IF(AND($AA18<>"",$AB18<>"",$AC18=0),$AO$6,""),"") | AP18: =IF($AG18=Constants!$B$7 ,IF(AND(U18,V18,W18,Y18,ISNUMBER(AB18)),IF($AN18="",0,IF($AN$6=0,Constants!$B$10,Constants!$B$10*AN18/$AN$6)), 0),"") | AQ18: =IF(AP18<>"", AP18*AI18,"") | AR18: =IF($AG18=Constants!$B$7,IF($AD18="",0,IF($AR$6=0,Constants!$B$8,Constants!$B$8*AD18/$AR$6)),"") | AS18: =IF($AG18<>Constants!$B$7,$AG18,IF(AK18&AO18<>"",Constants!$B$14,AM18+AQ18+AR18)) | AT18: =IF(ISBLANK($C18),"",IF($AG18=Constants!$B$7,IF(ISNUMBER(AS18),RANK(AS18,$AS$8:$AS$507),Constants!$B$14),$AG18)) | AU18: =IF(ISBLANK($C18), "",AM18) | AV18: =IF(ISBLANK($C18),"",IF($AG18=Constants!$B$7,RANK(AU18,AU$8:AU$507),$AG18)) | AW18: =IF(ISBLANK($C18), "",AR18) | AX18: =IF(ISBLANK($C18),"",IF($AG18=Constants!$B$7,RANK(AW18,AW$8:AW$507),$AG18)) | AY18: =IF(ISBLANK($C18), "",AE18) | AZ18: =IF(ISBLANK($C18),"", IF($AG18=Constants!$B$7, IF(ISNUMBER(AT18), COUNTIFS($AT$8:$AT$507,"<"&$AT18) + COUNTIFS($AT$8:$AT$507,$AT18,$AV$8:$AV$507,"<"&$AV18) + COUNTIFS($AT$8:$AT$507,$AT18,$AV$8:$AV$507,$AV18,$AX$8:$AX$507,"<"&$AX18) + COUNTIFS($AT$8:$AT$507,$AT18,$AV$8:$AV$507,$AV18,$AX$8:$AX$507,$AX18,$AY$8:$AY$507,"<"&$AY18) + 1, Constants!$B$14), $AG18)) | BA18: =IF(ISBLANK(C18),"",IF($AG18=Constants!$B$7, IF(ISNUMBER(AT18),AT18-AZ18,Constants!$B$14),$AG18)) | BC18: =IF(ISBLANK($C18),"",TRIM(AK18&" "&AO18)) | BD18: =IF(ISBLANK($C18),"",IF($AG18<>Constants!$B$7,$AG18,AR18)) | BE18: =IF(ISBLANK($C18),"",IF($AG18<>Constants!$B$7,$AG18,AM18)) | BF18: =IF(ISBLANK($C18),"",IF($AG18<>Constants!$B$7,$AG18,AQ18)) | BG18: =IF(ISBLANK($C18),"",IF($AG18<>Constants!$B$7, $AG18 ,AS18)) | BH18: =IF(ISBLANK($C18),"",IF($AG18<>Constants!$B$7, $AG18 ,AH18)) | BI18: =IF(ISBLANK(C18),"",BA18) | BJ18: =IF(ISBLANK(C18),"",AZ18) | BK18: =IF(ISBLANK(C18),"",IFERROR(_xlfn.SWITCH(BJ18, Constants!$B$4, COUNTA($C$8:$C517)+2, Constants!$B$5, COUNTA($C$8:$C517)+1, Constants!$B$6, COUNTA($C$8:$C517)),BJ18)) | BM18: =IF(OR(ISNUMBER(BJ18),BJ18="DQ",BJ18="P",BJ18="NS"), 1, 0 ) -> 0 | BN18: 11 | BO18: =IF(ISBLANK($C18),"",IF(ISNUMBER(BK18),BK18+ROW($B18)/1000,"")) | BP18: =IF(ISNUMBER(BO18), RANK(BO18,BO$8:BO$507,1), "") | BQ18: =IF(ISBLANK($C18), "", $B18 ) | BR18: =IF(ISBLANK($C18), "", $C18 ) | BS18: =IF(ISBLANK($C18), "", $D18 ) | BT18: =BH18 | BU18: =BG18 | BV18: =IF(ISBLANK($C18), "", BJ18 ) | BW18: =IF(BN18>BM$7, "", VLOOKUP(BN18,BP$8:BV517,7,FALSE()) ) | BX18: =IF(BN18>BM$7, "", VLOOKUP(BN18,BP$8:BV517,2,FALSE()) ) | BY18: =IF(BN18>BM$7, "", VLOOKUP(BN18,BP$8:BV517,3,FALSE()) ) | BZ18: =IF(BN18>BM$7, "", VLOOKUP(BN18,BP$8:BV517,4,FALSE()) ) | CA18: =IF(BN18>BM$7, "", VLOOKUP(BN18,BP$8:BV517,5,FALSE()) ) | CB18: =IF(BN18>BM$7, "", VLOOKUP(BN18,BP$8:BV517,6,FALSE()) )
U19: =IF(ISBLANK($C19),"",IF(G19=Constants!$B$2, TRUE(), IF(G19=Constants!$B$3, FALSE(), TRUE()))) | V19: =IF(ISBLANK($C19),"",IF(H19=Constants!$B$2, TRUE(), IF(H19=Constants!$B$3, FALSE(), TRUE()))) | W19: =IF(ISBLANK($C19),"",IF(I19=Constants!$B$2, TRUE(), IF(I19=Constants!$B$3, FALSE(), TRUE()))) | X19: =IF(ISBLANK($C19),"",IF(AND(ISNUMBER(J19),J19>0),INT(J19),0)) | Y19: =IF(ISBLANK($C19),"",IF(K19=Constants!$B$2, TRUE(), IF(K19=Constants!$B$3, FALSE(), TRUE()))) | Z19: =IF(ISBLANK($C19),"",IF(AND(ISNUMBER(L19),L19>0),INT(L19),0)) | AA19: =IF(ISBLANK($C19),"",IF(ISNUMBER(M19), M19, "")) | AB19: =IF(ISBLANK($C19),"",IF(ISNUMBER(N19), N19, "")) | AC19: =IF(ISBLANK($C19),"",IF(ISNUMBER(O19), O19, "")) | AD19: =IF(ISBLANK($C19),"",IF(ISNUMBER(P19), P19, "")) | AE19: =IF(ISBLANK($C19),"",IF(ISNUMBER(Q19), Q19, Constants!$B$13)) | AF19: =IF(ISBLANK($C19),"",IF(R19=Constants!$B$2, TRUE(), IF(R19=Constants!$B$3, FALSE(), FALSE()))) | AG19: =IF(ISBLANK(C19), "", IF(AF19, Constants!$B$4,IF(COUNTA(G19:P19)=0, Constants!$B$5, Constants!$B$7))) | AH19: =IF(ISBLANK($C19), "",IF($AG19=Constants!$B$7,1,$AG19)) | AI19: =IF($AG19=Constants!$B$7,POWER(Constants!$B$11,X19)*POWER(Constants!$B$12,Z19),"") | AJ19: =IF(AND($AG19=Constants!$B$7, U19, V19) ,IF(OR($AA19="",$AC19=""),"",MAX(0, $AC19-$AA19)),"") | AK19: =IF(AND($AG19=Constants!$B$7, U19, V19),IF(OR($AA19="",$AC19=""),$AK$6,""),"") | AL19: =IF($AG19=Constants!$B$7,IF(AND(U19,V19,W19,Y19),IF($AJ19="",0,IF($AJ$6=0,Constants!$B$9,Constants!$B$9*AJ19/$AJ$6)), 0),"") | AM19: =IF(AL19<>"", AL19*AI19,"") | AN19: =IF(AND($AG19=Constants!$B$7, U19, V19) ,IF($AB19="", "", IF(OR($AC19="",$AC19=0),"",MAX(0,1-ABS($AC19-$AB19)/$AC19))),"") | AO19: =IF(AND($AG19=Constants!$B$7, U19, V19),IF(AND($AA19<>"",$AB19<>"",$AC19=0),$AO$6,""),"") | AP19: =IF($AG19=Constants!$B$7 ,IF(AND(U19,V19,W19,Y19,ISNUMBER(AB19)),IF($AN19="",0,IF($AN$6=0,Constants!$B$10,Constants!$B$10*AN19/$AN$6)), 0),"") | AQ19: =IF(AP19<>"", AP19*AI19,"") | AR19: =IF($AG19=Constants!$B$7,IF($AD19="",0,IF($AR$6=0,Constants!$B$8,Constants!$B$8*AD19/$AR$6)),"") | AS19: =IF($AG19<>Constants!$B$7,$AG19,IF(AK19&AO19<>"",Constants!$B$14,AM19+AQ19+AR19)) | AT19: =IF(ISBLANK($C19),"",IF($AG19=Constants!$B$7,IF(ISNUMBER(AS19),RANK(AS19,$AS$8:$AS$507),Constants!$B$14),$AG19)) | AU19: =IF(ISBLANK($C19), "",AM19) | AV19: =IF(ISBLANK($C19),"",IF($AG19=Constants!$B$7,RANK(AU19,AU$8:AU$507),$AG19)) | AW19: =IF(ISBLANK($C19), "",AR19) | AX19: =IF(ISBLANK($C19),"",IF($AG19=Constants!$B$7,RANK(AW19,AW$8:AW$507),$AG19)) | AY19: =IF(ISBLANK($C19), "",AE19) | AZ19: =IF(ISBLANK($C19),"", IF($AG19=Constants!$B$7, IF(ISNUMBER(AT19), COUNTIFS($AT$8:$AT$507,"<"&$AT19) + COUNTIFS($AT$8:$AT$507,$AT19,$AV$8:$AV$507,"<"&$AV19) + COUNTIFS($AT$8:$AT$507,$AT19,$AV$8:$AV$507,$AV19,$AX$8:$AX$507,"<"&$AX19) + COUNTIFS($AT$8:$AT$507,$AT19,$AV$8:$AV$507,$AV19,$AX$8:$AX$507,$AX19,$AY$8:$AY$507,"<"&$AY19) + 1, Constants!$B$14), $AG19)) | BA19: =IF(ISBLANK(C19),"",IF($AG19=Constants!$B$7, IF(ISNUMBER(AT19),AT19-AZ19,Constants!$B$14),$AG19)) | BC19: =IF(ISBLANK($C19),"",TRIM(AK19&" "&AO19)) | BD19: =IF(ISBLANK($C19),"",IF($AG19<>Constants!$B$7,$AG19,AR19)) | BE19: =IF(ISBLANK($C19),"",IF($AG19<>Constants!$B$7,$AG19,AM19)) | BF19: =IF(ISBLANK($C19),"",IF($AG19<>Constants!$B$7,$AG19,AQ19)) | BG19: =IF(ISBLANK($C19),"",IF($AG19<>Constants!$B$7, $AG19 ,AS19)) | BH19: =IF(ISBLANK($C19),"",IF($AG19<>Constants!$B$7, $AG19 ,AH19)) | BI19: =IF(ISBLANK(C19),"",BA19) | BJ19: =IF(ISBLANK(C19),"",AZ19) | BK19: =IF(ISBLANK(C19),"",IFERROR(_xlfn.SWITCH(BJ19, Constants!$B$4, COUNTA($C$8:$C518)+2, Constants!$B$5, COUNTA($C$8:$C518)+1, Constants!$B$6, COUNTA($C$8:$C518)),BJ19)) | BM19: =IF(OR(ISNUMBER(BJ19),BJ19="DQ",BJ19="P",BJ19="NS"), 1, 0 ) -> 0 | BN19: 12 | BO19: =IF(ISBLANK($C19),"",IF(ISNUMBER(BK19),BK19+ROW($B19)/1000,"")) | BP19: =IF(ISNUMBER(BO19), RANK(BO19,BO$8:BO$507,1), "") | BQ19: =IF(ISBLANK($C19), "", $B19 ) | BR19: =IF(ISBLANK($C19), "", $C19 ) | BS19: =IF(ISBLANK($C19), "", $D19 ) | BT19: =BH19 | BU19: =BG19 | BV19: =IF(ISBLANK($C19), "", BJ19 ) | BW19: =IF(BN19>BM$7, "", VLOOKUP(BN19,BP$8:BV518,7,FALSE()) ) | BX19: =IF(BN19>BM$7, "", VLOOKUP(BN19,BP$8:BV518,2,FALSE()) ) | BY19: =IF(BN19>BM$7, "", VLOOKUP(BN19,BP$8:BV518,3,FALSE()) ) | BZ19: =IF(BN19>BM$7, "", VLOOKUP(BN19,BP$8:BV518,4,FALSE()) ) | CA19: =IF(BN19>BM$7, "", VLOOKUP(BN19,BP$8:BV518,5,FALSE()) ) | CB19: =IF(BN19>BM$7, "", VLOOKUP(BN19,BP$8:BV518,6,FALSE()) )
