Workbook

Sheet Scoring
B2: ='Info.'!B1&" "&'Info.'!B4 -> Elastic Launched Glider B | E2: Check-In & Flight Log | H2: Flight Time | BC2: Breakdown | BM2: Rank for this team with row() bump | BN2: Rank for this team with same ranks split | BO2: Team Number of this team | BP2: Name of this school | BQ2: Name of this team | BR2: Tier for this Team | BS2: Score for this team | BT2: Actual Rank for this team | BU2: Final Rankings
E3: Glider A | F3: Glider B | G3: 3. Flight Log (Complete / Partial / Not present) | H3: 4. Met All Comp Params (T/F) | I3: Flight 1 | K3: Flight 2 | M3: Flight 3 | O3: Flight 4 | Q3: Flight 5 | S3: 15. Disqualify (T/F) | U3: =E4 -> 1. Met All Const Params (T/F) | V3: =F4 -> 2. Met All Const Params (T/F) | W3: =G3 -> 3. Flight Log (Complete / Partial / Not present) | X3: =H3 -> 4. Met All Comp Params (T/F) | Y3: =I4 -> 5. Glider (A/B) | Z3: =J4 -> 6. Median Flight Time (s) | AA3: =K4 -> 7. Glider (A/B) | AB3: =L4 -> 8. Median Flight Time (s) | AC3: =M4 -> 9. Glider (A/B) | AD3: =N4 -> 10. Median Flight Time (s) | AE3: =O4 -> 11. Glider (A/B) | AF3: =P4 -> 12. Median Flight Time (s) | ... AH3: =R4 -> 14. Median Flight Time (s) | AI3: =S3 -> 15. Disqualify (T/F) | BC3: Scored Flights | BD3: Log Multiplier | BE3: Score | BF3: Tier | BG3: Tiebreaker | BH3: Rank | BI3: Points | BU3: Rank | BV3: Team # | BW3: School Name | BX3: Team Name | BY3: Tier | BZ3: Score
B4: ="Event Scoresheet - "&'Info.'!B5&IF('Info.'!B8="T"," The scoresheet has been updated; please download version v"&'Info.'!B7&" from soinc.org/scoresheets.","") -> Event Scoresheet - 2027 | E4: 1. Met All Const Params (T/F) | F4: 2. Met All Const Params (T/F) | I4: 5. Glider (A/B) | J4: 6. Median Flight Time (s) | K4: 7. Glider (A/B) | L4: 8. Median Flight Time (s) | M4: 9. Glider (A/B) | N4: 10. Median Flight Time (s) | O4: 11. Glider (A/B) | P4: 12. Median Flight Time (s) | Q4: 13. Glider (A/B) | R4: 14. Median Flight Time (s)
B6: ="Last Updated: "&TEXT('Info.'!B2, "mm/dd/yyyy")&" (v"&'Info.'!B3&") Direct all questions to scoresheets@soinc.org." -> Last Updated: 10/01/2026 (v0.1.0) Direct all questions to scoresheets@soinc.org.
B7: Team # | C7: School Name | D7: Team Name | AJ7: Status | AK7: Tier | AL7: Flight 1 (s) | AM7: Flight 2 (s) | AN7: Flight 3 (s) | AO7: Flight 4 (s) | AP7: Flight 5 (s) | AQ7: Longest Flight # | AR7: 2nd Longest Flight # | AS7: 3rd Longest Flight # | AT7: Best 3 Total (s) | AU7: Score | AV7: Score Rank | AW7: Rank | AX7: TB1 (Best Non-Scored Flight) | AY7: TB1 Rank | AZ7: Rank w/ TB | BA7: Rank Diff | BK7: =SUM(BK8:BK507) -> 0
U8: =IF(ISBLANK($C8),"",IF(E8=Constants!$B$2, TRUE(), IF(E8=Constants!$B$3, FALSE(), TRUE()))) | V8: =IF(ISBLANK($C8),"",IF(F8=Constants!$B$2, TRUE(), IF(F8=Constants!$B$3, FALSE(), TRUE()))) | W8: =IF(ISBLANK($C8),"",IF(G8=Constants!$B$15,Constants!$B$8,IF(G8=Constants!$B$16,Constants!$B$9,Constants!$B$10))) | X8: =IF(ISBLANK($C8),"",IF(H8=Constants!$B$2, TRUE(), IF(H8=Constants!$B$3, FALSE(), TRUE()))) | Y8: =IF(ISBLANK($C8),"",IF(I8=Constants!$B$19,Constants!$B$19,Constants!$B$18)) | Z8: =IF(ISBLANK($C8),"",IF(ISNUMBER(J8),IF(J8>=0,J8,""),"")) | AA8: =IF(ISBLANK($C8),"",IF(K8=Constants!$B$19,Constants!$B$19,Constants!$B$18)) | AB8: =IF(ISBLANK($C8),"",IF(ISNUMBER(L8),IF(L8>=0,L8,""),"")) | AC8: =IF(ISBLANK($C8),"",IF(M8=Constants!$B$19,Constants!$B$19,Constants!$B$18)) | AD8: =IF(ISBLANK($C8),"",IF(ISNUMBER(N8),IF(N8>=0,N8,""),"")) | AE8: =IF(ISBLANK($C8),"",IF(O8=Constants!$B$19,Constants!$B$19,Constants!$B$18)) | AF8: =IF(ISBLANK($C8),"",IF(ISNUMBER(P8),IF(P8>=0,P8,""),"")) | AG8: =IF(ISBLANK($C8),"",IF(Q8=Constants!$B$19,Constants!$B$19,Constants!$B$18)) | AH8: =IF(ISBLANK($C8),"",IF(ISNUMBER(R8),IF(R8>=0,R8,""),"")) | AI8: =IF(ISBLANK($C8),"",IF(S8=Constants!$B$2, TRUE(), IF(S8=Constants!$B$3, FALSE(), FALSE()))) | AJ8: =IF(ISBLANK($C8),"",IF(AI8,Constants!$B$4,IF(COUNTA(E8:R8)=0,Constants!$B$5,IF(COUNTA(J8,L8,N8,P8,R8)=0,Constants!$B$6,Constants!$B$7)))) | AK8: =IF(ISBLANK($C8),"",IF($AJ8<>Constants!$B$7,$AJ8,IF(OR(NOT(X8),AND(NOT(U8),COUNTIFS(Y8:AG8,Constants!$B$18,Z8:AH8,">=0")>0),AND(NOT(V8),COUNTIFS(Y8:AG8,Constants!$B$19,Z8:AH8,">=0")>0)),Constants!$B$12,Constants!$B$11))) | AL8: =IF($AJ8=Constants!$B$7,IF(Z8="",Constants!$B$13,Z8),"") | AM8: =IF($AJ8=Constants!$B$7,IF(AB8="",Constants!$B$13,AB8),"") | AN8: =IF($AJ8=Constants!$B$7,IF(AD8="",Constants!$B$13,AD8),"") | AO8: =IF($AJ8=Constants!$B$7,IF(AF8="",Constants!$B$13,AF8),"") | AP8: =IF($AJ8=Constants!$B$7,IF(AH8="",Constants!$B$13,AH8),"") | AQ8: =IF($AJ8=Constants!$B$7,IF(SUMPRODUCT(--($AL8:$AP8>AL8))+SUMPRODUCT(--($AL8:AL8=AL8))=1,1,IF(SUMPRODUCT(--($AL8:$AP8>AM8))+SUMPRODUCT(--($AL8:AM8=AM8))=1,2,IF(SUMPRODUCT(--($AL8:$AP8>AN8))+SUMPRODUCT(--($AL8:AN8=AN8))=1,3,IF(SUMPRODUCT(--($AL8:$AP8>AO8))+SUMPRODUCT(--($AL8:AO8=AO8))=1,4,5)))),"") | AR8: =IF($AJ8=Constants!$B$7,IF(SUMPRODUCT(--($AL8:$AP8>AL8))+SUMPRODUCT(--($AL8:AL8=AL8))=2,1,IF(SUMPRODUCT(--($AL8:$AP8>AM8))+SUMPRODUCT(--($AL8:AM8=AM8))=2,2,IF(SUMPRODUCT(--($AL8:$AP8>AN8))+SUMPRODUCT(--($AL8:AN8=AN8))=2,3,IF(SUMPRODUCT(--($AL8:$AP8>AO8))+SUMPRODUCT(--($AL8:AO8=AO8))=2,4,5)))),"") | AS8: =IF($AJ8=Constants!$B$7,IF(SUMPRODUCT(--($AL8:$AP8>AL8))+SUMPRODUCT(--($AL8:AL8=AL8))=3,1,IF(SUMPRODUCT(--($AL8:$AP8>AM8))+SUMPRODUCT(--($AL8:AM8=AM8))=3,2,IF(SUMPRODUCT(--($AL8:$AP8>AN8))+SUMPRODUCT(--($AL8:AN8=AN8))=3,3,IF(SUMPRODUCT(--($AL8:$AP8>AO8))+SUMPRODUCT(--($AL8:AO8=AO8))=3,4,5)))),"") | AT8: =IF($AJ8=Constants!$B$7,LARGE(AL8:AP8,1)+LARGE(AL8:AP8,2)+LARGE(AL8:AP8,3),"") | AU8: =IF(ISBLANK($C8),"",IF($AJ8<>Constants!$B$7,$AJ8,AT8*W8)) | AV8: =IF(ISBLANK($C8),"",IF($AJ8=Constants!$B$7,IF(ISNUMBER(AU8),RANK(AU8,$AU$8:$AU$507),Constants!$B$14),$AJ8)) | AW8: =IF(ISBLANK($C8),"",IF($AJ8=Constants!$B$7,IF(ISNUMBER(AV8),COUNTIFS($AK$8:$AK$507,"<"&$AK8)+COUNTIFS($AK$8:$AK$507,$AK8,$AV$8:$AV$507,"<"&$AV8)+1,Constants!$B$14),$AJ8)) | AX8: =IF(ISBLANK($C8),"",IF($AJ8=Constants!$B$7,LARGE(AL8:AP8,4)*W8,"")) | AY8: =IF(ISBLANK($C8),"",IF($AJ8=Constants!$B$7,RANK(AX8,$AX$8:$AX$507),$AJ8)) | AZ8: =IF(ISBLANK($C8),"",IF($AJ8=Constants!$B$7,IF(ISNUMBER(AV8),COUNTIFS($AK$8:$AK$507,"<"&$AK8)+COUNTIFS($AK$8:$AK$507,$AK8,$AV$8:$AV$507,"<"&$AV8)+COUNTIFS($AK$8:$AK$507,$AK8,$AV$8:$AV$507,$AV8,$AY$8:$AY$507,"<"&$AY8)+1,Constants!$B$14),$AJ8)) | BA8: =IF(ISBLANK($C8),"",IF($AJ8=Constants!$B$7,IF(ISNUMBER(AW8),AW8-AZ8,Constants!$B$14),$AJ8)) | BC8: =IF(ISBLANK($C8),"",IF($AJ8<>Constants!$B$7,$AJ8,SMALL(AQ8:AS8,1)&", "&SMALL(AQ8:AS8,2)&", "&SMALL(AQ8:AS8,3))) | BD8: =IF(ISBLANK($C8),"",IF($AJ8<>Constants!$B$7,$AJ8,W8)) | BE8: =IF(ISBLANK($C8),"",IF($AJ8<>Constants!$B$7,$AJ8,AU8)) | BF8: =IF(ISBLANK($C8),"",IF($AJ8<>Constants!$B$7,$AJ8,AK8)) | BG8: =IF(ISBLANK($C8),"",BA8) | BH8: =IF(ISBLANK($C8),"",AZ8) | BI8: =IF(ISBLANK($C8),"",IF(BH8=Constants!$B$4,COUNTA($C$8:$C$507)+2,IF(BH8=Constants!$B$5,COUNTA($C$8:$C$507)+1,IF(BH8=Constants!$B$6,COUNTA($C$8:$C$507),BH8)))) | BK8: =IF(OR(ISNUMBER(BH8),BH8=Constants!$B$4,BH8=Constants!$B$6,BH8=Constants!$B$5),1,0) -> 0 | BL8: 1 | BM8: =IF(ISBLANK($C8),"",IF(ISNUMBER(BI8),BI8+ROW($B8)/1000,"")) | BN8: =IF(ISNUMBER(BM8),RANK(BM8,$BM$8:$BM$507,1),"") | BO8: =IF(ISBLANK($C8),"",$B8) | BP8: =IF(ISBLANK($C8),"",$C8) | BQ8: =IF(ISBLANK($C8),"",$D8) | BR8: =BF8 | BS8: =BE8 | BT8: =IF(ISBLANK($C8),"",BH8) | BU8: =IF($BL8>$BK$7,"",VLOOKUP($BL8,$BN$8:$BT$507,7,FALSE())) | BV8: =IF($BL8>$BK$7,"",VLOOKUP($BL8,$BN$8:$BT$507,2,FALSE())) | BW8: =IF($BL8>$BK$7,"",VLOOKUP($BL8,$BN$8:$BT$507,3,FALSE())) | BX8: =IF($BL8>$BK$7,"",VLOOKUP($BL8,$BN$8:$BT$507,4,FALSE())) | BY8: =IF($BL8>$BK$7,"",VLOOKUP($BL8,$BN$8:$BT$507,5,FALSE())) | BZ8: =IF($BL8>$BK$7,"",VLOOKUP($BL8,$BN$8:$BT$507,6,FALSE()))
U9: =IF(ISBLANK($C9),"",IF(E9=Constants!$B$2, TRUE(), IF(E9=Constants!$B$3, FALSE(), TRUE()))) | V9: =IF(ISBLANK($C9),"",IF(F9=Constants!$B$2, TRUE(), IF(F9=Constants!$B$3, FALSE(), TRUE()))) | W9: =IF(ISBLANK($C9),"",IF(G9=Constants!$B$15,Constants!$B$8,IF(G9=Constants!$B$16,Constants!$B$9,Constants!$B$10))) | X9: =IF(ISBLANK($C9),"",IF(H9=Constants!$B$2, TRUE(), IF(H9=Constants!$B$3, FALSE(), TRUE()))) | Y9: =IF(ISBLANK($C9),"",IF(I9=Constants!$B$19,Constants!$B$19,Constants!$B$18)) | Z9: =IF(ISBLANK($C9),"",IF(ISNUMBER(J9),IF(J9>=0,J9,""),"")) | AA9: =IF(ISBLANK($C9),"",IF(K9=Constants!$B$19,Constants!$B$19,Constants!$B$18)) | AB9: =IF(ISBLANK($C9),"",IF(ISNUMBER(L9),IF(L9>=0,L9,""),"")) | AC9: =IF(ISBLANK($C9),"",IF(M9=Constants!$B$19,Constants!$B$19,Constants!$B$18)) | AD9: =IF(ISBLANK($C9),"",IF(ISNUMBER(N9),IF(N9>=0,N9,""),"")) | AE9: =IF(ISBLANK($C9),"",IF(O9=Constants!$B$19,Constants!$B$19,Constants!$B$18)) | AF9: =IF(ISBLANK($C9),"",IF(ISNUMBER(P9),IF(P9>=0,P9,""),"")) | AG9: =IF(ISBLANK($C9),"",IF(Q9=Constants!$B$19,Constants!$B$19,Constants!$B$18)) | AH9: =IF(ISBLANK($C9),"",IF(ISNUMBER(R9),IF(R9>=0,R9,""),"")) | AI9: =IF(ISBLANK($C9),"",IF(S9=Constants!$B$2, TRUE(), IF(S9=Constants!$B$3, FALSE(), FALSE()))) | AJ9: =IF(ISBLANK($C9),"",IF(AI9,Constants!$B$4,IF(COUNTA(E9:R9)=0,Constants!$B$5,IF(COUNTA(J9,L9,N9,P9,R9)=0,Constants!$B$6,Constants!$B$7)))) | AK9: =IF(ISBLANK($C9),"",IF($AJ9<>Constants!$B$7,$AJ9,IF(OR(NOT(X9),AND(NOT(U9),COUNTIFS(Y9:AG9,Constants!$B$18,Z9:AH9,">=0")>0),AND(NOT(V9),COUNTIFS(Y9:AG9,Constants!$B$19,Z9:AH9,">=0")>0)),Constants!$B$12,Constants!$B$11))) | AL9: =IF($AJ9=Constants!$B$7,IF(Z9="",Constants!$B$13,Z9),"") | AM9: =IF($AJ9=Constants!$B$7,IF(AB9="",Constants!$B$13,AB9),"") | AN9: =IF($AJ9=Constants!$B$7,IF(AD9="",Constants!$B$13,AD9),"") | AO9: =IF($AJ9=Constants!$B$7,IF(AF9="",Constants!$B$13,AF9),"") | AP9: =IF($AJ9=Constants!$B$7,IF(AH9="",Constants!$B$13,AH9),"") | AQ9: =IF($AJ9=Constants!$B$7,IF(SUMPRODUCT(--($AL9:$AP9>AL9))+SUMPRODUCT(--($AL9:AL9=AL9))=1,1,IF(SUMPRODUCT(--($AL9:$AP9>AM9))+SUMPRODUCT(--($AL9:AM9=AM9))=1,2,IF(SUMPRODUCT(--($AL9:$AP9>AN9))+SUMPRODUCT(--($AL9:AN9=AN9))=1,3,IF(SUMPRODUCT(--($AL9:$AP9>AO9))+SUMPRODUCT(--($AL9:AO9=AO9))=1,4,5)))),"") | AR9: =IF($AJ9=Constants!$B$7,IF(SUMPRODUCT(--($AL9:$AP9>AL9))+SUMPRODUCT(--($AL9:AL9=AL9))=2,1,IF(SUMPRODUCT(--($AL9:$AP9>AM9))+SUMPRODUCT(--($AL9:AM9=AM9))=2,2,IF(SUMPRODUCT(--($AL9:$AP9>AN9))+SUMPRODUCT(--($AL9:AN9=AN9))=2,3,IF(SUMPRODUCT(--($AL9:$AP9>AO9))+SUMPRODUCT(--($AL9:AO9=AO9))=2,4,5)))),"") | AS9: =IF($AJ9=Constants!$B$7,IF(SUMPRODUCT(--($AL9:$AP9>AL9))+SUMPRODUCT(--($AL9:AL9=AL9))=3,1,IF(SUMPRODUCT(--($AL9:$AP9>AM9))+SUMPRODUCT(--($AL9:AM9=AM9))=3,2,IF(SUMPRODUCT(--($AL9:$AP9>AN9))+SUMPRODUCT(--($AL9:AN9=AN9))=3,3,IF(SUMPRODUCT(--($AL9:$AP9>AO9))+SUMPRODUCT(--($AL9:AO9=AO9))=3,4,5)))),"") | AT9: =IF($AJ9=Constants!$B$7,LARGE(AL9:AP9,1)+LARGE(AL9:AP9,2)+LARGE(AL9:AP9,3),"") | AU9: =IF(ISBLANK($C9),"",IF($AJ9<>Constants!$B$7,$AJ9,AT9*W9)) | AV9: =IF(ISBLANK($C9),"",IF($AJ9=Constants!$B$7,IF(ISNUMBER(AU9),RANK(AU9,$AU$8:$AU$507),Constants!$B$14),$AJ9)) | AW9: =IF(ISBLANK($C9),"",IF($AJ9=Constants!$B$7,IF(ISNUMBER(AV9),COUNTIFS($AK$8:$AK$507,"<"&$AK9)+COUNTIFS($AK$8:$AK$507,$AK9,$AV$8:$AV$507,"<"&$AV9)+1,Constants!$B$14),$AJ9)) | AX9: =IF(ISBLANK($C9),"",IF($AJ9=Constants!$B$7,LARGE(AL9:AP9,4)*W9,"")) | AY9: =IF(ISBLANK($C9),"",IF($AJ9=Constants!$B$7,RANK(AX9,$AX$8:$AX$507),$AJ9)) | AZ9: =IF(ISBLANK($C9),"",IF($AJ9=Constants!$B$7,IF(ISNUMBER(AV9),COUNTIFS($AK$8:$AK$507,"<"&$AK9)+COUNTIFS($AK$8:$AK$507,$AK9,$AV$8:$AV$507,"<"&$AV9)+COUNTIFS($AK$8:$AK$507,$AK9,$AV$8:$AV$507,$AV9,$AY$8:$AY$507,"<"&$AY9)+1,Constants!$B$14),$AJ9)) | BA9: =IF(ISBLANK($C9),"",IF($AJ9=Constants!$B$7,IF(ISNUMBER(AW9),AW9-AZ9,Constants!$B$14),$AJ9)) | BC9: =IF(ISBLANK($C9),"",IF($AJ9<>Constants!$B$7,$AJ9,SMALL(AQ9:AS9,1)&", "&SMALL(AQ9:AS9,2)&", "&SMALL(AQ9:AS9,3))) | BD9: =IF(ISBLANK($C9),"",IF($AJ9<>Constants!$B$7,$AJ9,W9)) | BE9: =IF(ISBLANK($C9),"",IF($AJ9<>Constants!$B$7,$AJ9,AU9)) | BF9: =IF(ISBLANK($C9),"",IF($AJ9<>Constants!$B$7,$AJ9,AK9)) | BG9: =IF(ISBLANK($C9),"",BA9) | BH9: =IF(ISBLANK($C9),"",AZ9) | BI9: =IF(ISBLANK($C9),"",IF(BH9=Constants!$B$4,COUNTA($C$8:$C$507)+2,IF(BH9=Constants!$B$5,COUNTA($C$8:$C$507)+1,IF(BH9=Constants!$B$6,COUNTA($C$8:$C$507),BH9)))) | BK9: =IF(OR(ISNUMBER(BH9),BH9=Constants!$B$4,BH9=Constants!$B$6,BH9=Constants!$B$5),1,0) -> 0 | BL9: 2 | BM9: =IF(ISBLANK($C9),"",IF(ISNUMBER(BI9),BI9+ROW($B9)/1000,"")) | BN9: =IF(ISNUMBER(BM9),RANK(BM9,$BM$8:$BM$507,1),"") | BO9: =IF(ISBLANK($C9),"",$B9) | BP9: =IF(ISBLANK($C9),"",$C9) | BQ9: =IF(ISBLANK($C9),"",$D9) | BR9: =BF9 | BS9: =BE9 | BT9: =IF(ISBLANK($C9),"",BH9) | BU9: =IF($BL9>$BK$7,"",VLOOKUP($BL9,$BN$8:$BT$507,7,FALSE())) | BV9: =IF($BL9>$BK$7,"",VLOOKUP($BL9,$BN$8:$BT$507,2,FALSE())) | BW9: =IF($BL9>$BK$7,"",VLOOKUP($BL9,$BN$8:$BT$507,3,FALSE())) | BX9: =IF($BL9>$BK$7,"",VLOOKUP($BL9,$BN$8:$BT$507,4,FALSE())) | BY9: =IF($BL9>$BK$7,"",VLOOKUP($BL9,$BN$8:$BT$507,5,FALSE())) | BZ9: =IF($BL9>$BK$7,"",VLOOKUP($BL9,$BN$8:$BT$507,6,FALSE()))
U10: =IF(ISBLANK($C10),"",IF(E10=Constants!$B$2, TRUE(), IF(E10=Constants!$B$3, FALSE(), TRUE()))) | V10: =IF(ISBLANK($C10),"",IF(F10=Constants!$B$2, TRUE(), IF(F10=Constants!$B$3, FALSE(), TRUE()))) | W10: =IF(ISBLANK($C10),"",IF(G10=Constants!$B$15,Constants!$B$8,IF(G10=Constants!$B$16,Constants!$B$9,Constants!$B$10))) | X10: =IF(ISBLANK($C10),"",IF(H10=Constants!$B$2, TRUE(), IF(H10=Constants!$B$3, FALSE(), TRUE()))) | Y10: =IF(ISBLANK($C10),"",IF(I10=Constants!$B$19,Constants!$B$19,Constants!$B$18)) | Z10: =IF(ISBLANK($C10),"",IF(ISNUMBER(J10),IF(J10>=0,J10,""),"")) | AA10: =IF(ISBLANK($C10),"",IF(K10=Constants!$B$19,Constants!$B$19,Constants!$B$18)) | AB10: =IF(ISBLANK($C10),"",IF(ISNUMBER(L10),IF(L10>=0,L10,""),"")) | AC10: =IF(ISBLANK($C10),"",IF(M10=Constants!$B$19,Constants!$B$19,Constants!$B$18)) | AD10: =IF(ISBLANK($C10),"",IF(ISNUMBER(N10),IF(N10>=0,N10,""),"")) | AE10: =IF(ISBLANK($C10),"",IF(O10=Constants!$B$19,Constants!$B$19,Constants!$B$18)) | AF10: =IF(ISBLANK($C10),"",IF(ISNUMBER(P10),IF(P10>=0,P10,""),"")) | AG10: =IF(ISBLANK($C10),"",IF(Q10=Constants!$B$19,Constants!$B$19,Constants!$B$18)) | AH10: =IF(ISBLANK($C10),"",IF(ISNUMBER(R10),IF(R10>=0,R10,""),"")) | AI10: =IF(ISBLANK($C10),"",IF(S10=Constants!$B$2, TRUE(), IF(S10=Constants!$B$3, FALSE(), FALSE()))) | AJ10: =IF(ISBLANK($C10),"",IF(AI10,Constants!$B$4,IF(COUNTA(E10:R10)=0,Constants!$B$5,IF(COUNTA(J10,L10,N10,P10,R10)=0,Constants!$B$6,Constants!$B$7)))) | AK10: =IF(ISBLANK($C10),"",IF($AJ10<>Constants!$B$7,$AJ10,IF(OR(NOT(X10),AND(NOT(U10),COUNTIFS(Y10:AG10,Constants!$B$18,Z10:AH10,">=0")>0),AND(NOT(V10),COUNTIFS(Y10:AG10,Constants!$B$19,Z10:AH10,">=0")>0)),Constants!$B$12,Constants!$B$11))) | AL10: =IF($AJ10=Constants!$B$7,IF(Z10="",Constants!$B$13,Z10),"") | AM10: =IF($AJ10=Constants!$B$7,IF(AB10="",Constants!$B$13,AB10),"") | AN10: =IF($AJ10=Constants!$B$7,IF(AD10="",Constants!$B$13,AD10),"") | AO10: =IF($AJ10=Constants!$B$7,IF(AF10="",Constants!$B$13,AF10),"") | AP10: =IF($AJ10=Constants!$B$7,IF(AH10="",Constants!$B$13,AH10),"") | AQ10: =IF($AJ10=Constants!$B$7,IF(SUMPRODUCT(--($AL10:$AP10>AL10))+SUMPRODUCT(--($AL10:AL10=AL10))=1,1,IF(SUMPRODUCT(--($AL10:$AP10>AM10))+SUMPRODUCT(--($AL10:AM10=AM10))=1,2,IF(SUMPRODUCT(--($AL10:$AP10>AN10))+SUMPRODUCT(--($AL10:AN10=AN10))=1,3,IF(SUMPRODUCT(--($AL10:$AP10>AO10))+SUMPRODUCT(--($AL10:AO10=AO10))=1,4,5)))),"") | AR10: =IF($AJ10=Constants!$B$7,IF(SUMPRODUCT(--($AL10:$AP10>AL10))+SUMPRODUCT(--($AL10:AL10=AL10))=2,1,IF(SUMPRODUCT(--($AL10:$AP10>AM10))+SUMPRODUCT(--($AL10:AM10=AM10))=2,2,IF(SUMPRODUCT(--($AL10:$AP10>AN10))+SUMPRODUCT(--($AL10:AN10=AN10))=2,3,IF(SUMPRODUCT(--($AL10:$AP10>AO10))+SUMPRODUCT(--($AL10:AO10=AO10))=2,4,5)))),"") | AS10: =IF($AJ10=Constants!$B$7,IF(SUMPRODUCT(--($AL10:$AP10>AL10))+SUMPRODUCT(--($AL10:AL10=AL10))=3,1,IF(SUMPRODUCT(--($AL10:$AP10>AM10))+SUMPRODUCT(--($AL10:AM10=AM10))=3,2,IF(SUMPRODUCT(--($AL10:$AP10>AN10))+SUMPRODUCT(--($AL10:AN10=AN10))=3,3,IF(SUMPRODUCT(--($AL10:$AP10>AO10))+SUMPRODUCT(--($AL10:AO10=AO10))=3,4,5)))),"") | AT10: =IF($AJ10=Constants!$B$7,LARGE(AL10:AP10,1)+LARGE(AL10:AP10,2)+LARGE(AL10:AP10,3),"") | AU10: =IF(ISBLANK($C10),"",IF($AJ10<>Constants!$B$7,$AJ10,AT10*W10)) | AV10: =IF(ISBLANK($C10),"",IF($AJ10=Constants!$B$7,IF(ISNUMBER(AU10),RANK(AU10,$AU$8:$AU$507),Constants!$B$14),$AJ10)) | AW10: =IF(ISBLANK($C10),"",IF($AJ10=Constants!$B$7,IF(ISNUMBER(AV10),COUNTIFS($AK$8:$AK$507,"<"&$AK10)+COUNTIFS($AK$8:$AK$507,$AK10,$AV$8:$AV$507,"<"&$AV10)+1,Constants!$B$14),$AJ10)) | AX10: =IF(ISBLANK($C10),"",IF($AJ10=Constants!$B$7,LARGE(AL10:AP10,4)*W10,"")) | AY10: =IF(ISBLANK($C10),"",IF($AJ10=Constants!$B$7,RANK(AX10,$AX$8:$AX$507),$AJ10)) | AZ10: =IF(ISBLANK($C10),"",IF($AJ10=Constants!$B$7,IF(ISNUMBER(AV10),COUNTIFS($AK$8:$AK$507,"<"&$AK10)+COUNTIFS($AK$8:$AK$507,$AK10,$AV$8:$AV$507,"<"&$AV10)+COUNTIFS($AK$8:$AK$507,$AK10,$AV$8:$AV$507,$AV10,$AY$8:$AY$507,"<"&$AY10)+1,Constants!$B$14),$AJ10)) | BA10: =IF(ISBLANK($C10),"",IF($AJ10=Constants!$B$7,IF(ISNUMBER(AW10),AW10-AZ10,Constants!$B$14),$AJ10)) | BC10: =IF(ISBLANK($C10),"",IF($AJ10<>Constants!$B$7,$AJ10,SMALL(AQ10:AS10,1)&", "&SMALL(AQ10:AS10,2)&", "&SMALL(AQ10:AS10,3))) | BD10: =IF(ISBLANK($C10),"",IF($AJ10<>Constants!$B$7,$AJ10,W10)) | BE10: =IF(ISBLANK($C10),"",IF($AJ10<>Constants!$B$7,$AJ10,AU10)) | BF10: =IF(ISBLANK($C10),"",IF($AJ10<>Constants!$B$7,$AJ10,AK10)) | BG10: =IF(ISBLANK($C10),"",BA10) | BH10: =IF(ISBLANK($C10),"",AZ10) | BI10: =IF(ISBLANK($C10),"",IF(BH10=Constants!$B$4,COUNTA($C$8:$C$507)+2,IF(BH10=Constants!$B$5,COUNTA($C$8:$C$507)+1,IF(BH10=Constants!$B$6,COUNTA($C$8:$C$507),BH10)))) | BK10: =IF(OR(ISNUMBER(BH10),BH10=Constants!$B$4,BH10=Constants!$B$6,BH10=Constants!$B$5),1,0) -> 0 | BL10: 3 | BM10: =IF(ISBLANK($C10),"",IF(ISNUMBER(BI10),BI10+ROW($B10)/1000,"")) | BN10: =IF(ISNUMBER(BM10),RANK(BM10,$BM$8:$BM$507,1),"") | BO10: =IF(ISBLANK($C10),"",$B10) | BP10: =IF(ISBLANK($C10),"",$C10) | BQ10: =IF(ISBLANK($C10),"",$D10) | BR10: =BF10 | BS10: =BE10 | BT10: =IF(ISBLANK($C10),"",BH10) | BU10: =IF($BL10>$BK$7,"",VLOOKUP($BL10,$BN$8:$BT$507,7,FALSE())) | BV10: =IF($BL10>$BK$7,"",VLOOKUP($BL10,$BN$8:$BT$507,2,FALSE())) | BW10: =IF($BL10>$BK$7,"",VLOOKUP($BL10,$BN$8:$BT$507,3,FALSE())) | BX10: =IF($BL10>$BK$7,"",VLOOKUP($BL10,$BN$8:$BT$507,4,FALSE())) | BY10: =IF($BL10>$BK$7,"",VLOOKUP($BL10,$BN$8:$BT$507,5,FALSE())) | BZ10: =IF($BL10>$BK$7,"",VLOOKUP($BL10,$BN$8:$BT$507,6,FALSE()))
U11: =IF(ISBLANK($C11),"",IF(E11=Constants!$B$2, TRUE(), IF(E11=Constants!$B$3, FALSE(), TRUE()))) | V11: =IF(ISBLANK($C11),"",IF(F11=Constants!$B$2, TRUE(), IF(F11=Constants!$B$3, FALSE(), TRUE()))) | W11: =IF(ISBLANK($C11),"",IF(G11=Constants!$B$15,Constants!$B$8,IF(G11=Constants!$B$16,Constants!$B$9,Constants!$B$10))) | X11: =IF(ISBLANK($C11),"",IF(H11=Constants!$B$2, TRUE(), IF(H11=Constants!$B$3, FALSE(), TRUE()))) | Y11: =IF(ISBLANK($C11),"",IF(I11=Constants!$B$19,Constants!$B$19,Constants!$B$18)) | Z11: =IF(ISBLANK($C11),"",IF(ISNUMBER(J11),IF(J11>=0,J11,""),"")) | AA11: =IF(ISBLANK($C11),"",IF(K11=Constants!$B$19,Constants!$B$19,Constants!$B$18)) | AB11: =IF(ISBLANK($C11),"",IF(ISNUMBER(L11),IF(L11>=0,L11,""),"")) | AC11: =IF(ISBLANK($C11),"",IF(M11=Constants!$B$19,Constants!$B$19,Constants!$B$18)) | AD11: =IF(ISBLANK($C11),"",IF(ISNUMBER(N11),IF(N11>=0,N11,""),"")) | AE11: =IF(ISBLANK($C11),"",IF(O11=Constants!$B$19,Constants!$B$19,Constants!$B$18)) | AF11: =IF(ISBLANK($C11),"",IF(ISNUMBER(P11),IF(P11>=0,P11,""),"")) | AG11: =IF(ISBLANK($C11),"",IF(Q11=Constants!$B$19,Constants!$B$19,Constants!$B$18)) | AH11: =IF(ISBLANK($C11),"",IF(ISNUMBER(R11),IF(R11>=0,R11,""),"")) | AI11: =IF(ISBLANK($C11),"",IF(S11=Constants!$B$2, TRUE(), IF(S11=Constants!$B$3, FALSE(), FALSE()))) | AJ11: =IF(ISBLANK($C11),"",IF(AI11,Constants!$B$4,IF(COUNTA(E11:R11)=0,Constants!$B$5,IF(COUNTA(J11,L11,N11,P11,R11)=0,Constants!$B$6,Constants!$B$7)))) | AK11: =IF(ISBLANK($C11),"",IF($AJ11<>Constants!$B$7,$AJ11,IF(OR(NOT(X11),AND(NOT(U11),COUNTIFS(Y11:AG11,Constants!$B$18,Z11:AH11,">=0")>0),AND(NOT(V11),COUNTIFS(Y11:AG11,Constants!$B$19,Z11:AH11,">=0")>0)),Constants!$B$12,Constants!$B$11))) | AL11: =IF($AJ11=Constants!$B$7,IF(Z11="",Constants!$B$13,Z11),"") | AM11: =IF($AJ11=Constants!$B$7,IF(AB11="",Constants!$B$13,AB11),"") | AN11: =IF($AJ11=Constants!$B$7,IF(AD11="",Constants!$B$13,AD11),"") | AO11: =IF($AJ11=Constants!$B$7,IF(AF11="",Constants!$B$13,AF11),"") | AP11: =IF($AJ11=Constants!$B$7,IF(AH11="",Constants!$B$13,AH11),"") | AQ11: =IF($AJ11=Constants!$B$7,IF(SUMPRODUCT(--($AL11:$AP11>AL11))+SUMPRODUCT(--($AL11:AL11=AL11))=1,1,IF(SUMPRODUCT(--($AL11:$AP11>AM11))+SUMPRODUCT(--($AL11:AM11=AM11))=1,2,IF(SUMPRODUCT(--($AL11:$AP11>AN11))+SUMPRODUCT(--($AL11:AN11=AN11))=1,3,IF(SUMPRODUCT(--($AL11:$AP11>AO11))+SUMPRODUCT(--($AL11:AO11=AO11))=1,4,5)))),"") | AR11: =IF($AJ11=Constants!$B$7,IF(SUMPRODUCT(--($AL11:$AP11>AL11))+SUMPRODUCT(--($AL11:AL11=AL11))=2,1,IF(SUMPRODUCT(--($AL11:$AP11>AM11))+SUMPRODUCT(--($AL11:AM11=AM11))=2,2,IF(SUMPRODUCT(--($AL11:$AP11>AN11))+SUMPRODUCT(--($AL11:AN11=AN11))=2,3,IF(SUMPRODUCT(--($AL11:$AP11>AO11))+SUMPRODUCT(--($AL11:AO11=AO11))=2,4,5)))),"") | AS11: =IF($AJ11=Constants!$B$7,IF(SUMPRODUCT(--($AL11:$AP11>AL11))+SUMPRODUCT(--($AL11:AL11=AL11))=3,1,IF(SUMPRODUCT(--($AL11:$AP11>AM11))+SUMPRODUCT(--($AL11:AM11=AM11))=3,2,IF(SUMPRODUCT(--($AL11:$AP11>AN11))+SUMPRODUCT(--($AL11:AN11=AN11))=3,3,IF(SUMPRODUCT(--($AL11:$AP11>AO11))+SUMPRODUCT(--($AL11:AO11=AO11))=3,4,5)))),"") | AT11: =IF($AJ11=Constants!$B$7,LARGE(AL11:AP11,1)+LARGE(AL11:AP11,2)+LARGE(AL11:AP11,3),"") | AU11: =IF(ISBLANK($C11),"",IF($AJ11<>Constants!$B$7,$AJ11,AT11*W11)) | AV11: =IF(ISBLANK($C11),"",IF($AJ11=Constants!$B$7,IF(ISNUMBER(AU11),RANK(AU11,$AU$8:$AU$507),Constants!$B$14),$AJ11)) | AW11: =IF(ISBLANK($C11),"",IF($AJ11=Constants!$B$7,IF(ISNUMBER(AV11),COUNTIFS($AK$8:$AK$507,"<"&$AK11)+COUNTIFS($AK$8:$AK$507,$AK11,$AV$8:$AV$507,"<"&$AV11)+1,Constants!$B$14),$AJ11)) | AX11: =IF(ISBLANK($C11),"",IF($AJ11=Constants!$B$7,LARGE(AL11:AP11,4)*W11,"")) | AY11: =IF(ISBLANK($C11),"",IF($AJ11=Constants!$B$7,RANK(AX11,$AX$8:$AX$507),$AJ11)) | AZ11: =IF(ISBLANK($C11),"",IF($AJ11=Constants!$B$7,IF(ISNUMBER(AV11),COUNTIFS($AK$8:$AK$507,"<"&$AK11)+COUNTIFS($AK$8:$AK$507,$AK11,$AV$8:$AV$507,"<"&$AV11)+COUNTIFS($AK$8:$AK$507,$AK11,$AV$8:$AV$507,$AV11,$AY$8:$AY$507,"<"&$AY11)+1,Constants!$B$14),$AJ11)) | BA11: =IF(ISBLANK($C11),"",IF($AJ11=Constants!$B$7,IF(ISNUMBER(AW11),AW11-AZ11,Constants!$B$14),$AJ11)) | BC11: =IF(ISBLANK($C11),"",IF($AJ11<>Constants!$B$7,$AJ11,SMALL(AQ11:AS11,1)&", "&SMALL(AQ11:AS11,2)&", "&SMALL(AQ11:AS11,3))) | BD11: =IF(ISBLANK($C11),"",IF($AJ11<>Constants!$B$7,$AJ11,W11)) | BE11: =IF(ISBLANK($C11),"",IF($AJ11<>Constants!$B$7,$AJ11,AU11)) | BF11: =IF(ISBLANK($C11),"",IF($AJ11<>Constants!$B$7,$AJ11,AK11)) | BG11: =IF(ISBLANK($C11),"",BA11) | BH11: =IF(ISBLANK($C11),"",AZ11) | BI11: =IF(ISBLANK($C11),"",IF(BH11=Constants!$B$4,COUNTA($C$8:$C$507)+2,IF(BH11=Constants!$B$5,COUNTA($C$8:$C$507)+1,IF(BH11=Constants!$B$6,COUNTA($C$8:$C$507),BH11)))) | BK11: =IF(OR(ISNUMBER(BH11),BH11=Constants!$B$4,BH11=Constants!$B$6,BH11=Constants!$B$5),1,0) -> 0 | BL11: 4 | BM11: =IF(ISBLANK($C11),"",IF(ISNUMBER(BI11),BI11+ROW($B11)/1000,"")) | BN11: =IF(ISNUMBER(BM11),RANK(BM11,$BM$8:$BM$507,1),"") | BO11: =IF(ISBLANK($C11),"",$B11) | BP11: =IF(ISBLANK($C11),"",$C11) | BQ11: =IF(ISBLANK($C11),"",$D11) | BR11: =BF11 | BS11: =BE11 | BT11: =IF(ISBLANK($C11),"",BH11) | BU11: =IF($BL11>$BK$7,"",VLOOKUP($BL11,$BN$8:$BT$507,7,FALSE())) | BV11: =IF($BL11>$BK$7,"",VLOOKUP($BL11,$BN$8:$BT$507,2,FALSE())) | BW11: =IF($BL11>$BK$7,"",VLOOKUP($BL11,$BN$8:$BT$507,3,FALSE())) | BX11: =IF($BL11>$BK$7,"",VLOOKUP($BL11,$BN$8:$BT$507,4,FALSE())) | BY11: =IF($BL11>$BK$7,"",VLOOKUP($BL11,$BN$8:$BT$507,5,FALSE())) | BZ11: =IF($BL11>$BK$7,"",VLOOKUP($BL11,$BN$8:$BT$507,6,FALSE()))
U12: =IF(ISBLANK($C12),"",IF(E12=Constants!$B$2, TRUE(), IF(E12=Constants!$B$3, FALSE(), TRUE()))) | V12: =IF(ISBLANK($C12),"",IF(F12=Constants!$B$2, TRUE(), IF(F12=Constants!$B$3, FALSE(), TRUE()))) | W12: =IF(ISBLANK($C12),"",IF(G12=Constants!$B$15,Constants!$B$8,IF(G12=Constants!$B$16,Constants!$B$9,Constants!$B$10))) | X12: =IF(ISBLANK($C12),"",IF(H12=Constants!$B$2, TRUE(), IF(H12=Constants!$B$3, FALSE(), TRUE()))) | Y12: =IF(ISBLANK($C12),"",IF(I12=Constants!$B$19,Constants!$B$19,Constants!$B$18)) | Z12: =IF(ISBLANK($C12),"",IF(ISNUMBER(J12),IF(J12>=0,J12,""),"")) | AA12: =IF(ISBLANK($C12),"",IF(K12=Constants!$B$19,Constants!$B$19,Constants!$B$18)) | AB12: =IF(ISBLANK($C12),"",IF(ISNUMBER(L12),IF(L12>=0,L12,""),"")) | AC12: =IF(ISBLANK($C12),"",IF(M12=Constants!$B$19,Constants!$B$19,Constants!$B$18)) | AD12: =IF(ISBLANK($C12),"",IF(ISNUMBER(N12),IF(N12>=0,N12,""),"")) | AE12: =IF(ISBLANK($C12),"",IF(O12=Constants!$B$19,Constants!$B$19,Constants!$B$18)) | AF12: =IF(ISBLANK($C12),"",IF(ISNUMBER(P12),IF(P12>=0,P12,""),"")) | AG12: =IF(ISBLANK($C12),"",IF(Q12=Constants!$B$19,Constants!$B$19,Constants!$B$18)) | AH12: =IF(ISBLANK($C12),"",IF(ISNUMBER(R12),IF(R12>=0,R12,""),"")) | AI12: =IF(ISBLANK($C12),"",IF(S12=Constants!$B$2, TRUE(), IF(S12=Constants!$B$3, FALSE(), FALSE()))) | AJ12: =IF(ISBLANK($C12),"",IF(AI12,Constants!$B$4,IF(COUNTA(E12:R12)=0,Constants!$B$5,IF(COUNTA(J12,L12,N12,P12,R12)=0,Constants!$B$6,Constants!$B$7)))) | AK12: =IF(ISBLANK($C12),"",IF($AJ12<>Constants!$B$7,$AJ12,IF(OR(NOT(X12),AND(NOT(U12),COUNTIFS(Y12:AG12,Constants!$B$18,Z12:AH12,">=0")>0),AND(NOT(V12),COUNTIFS(Y12:AG12,Constants!$B$19,Z12:AH12,">=0")>0)),Constants!$B$12,Constants!$B$11))) | AL12: =IF($AJ12=Constants!$B$7,IF(Z12="",Constants!$B$13,Z12),"") | AM12: =IF($AJ12=Constants!$B$7,IF(AB12="",Constants!$B$13,AB12),"") | AN12: =IF($AJ12=Constants!$B$7,IF(AD12="",Constants!$B$13,AD12),"") | AO12: =IF($AJ12=Constants!$B$7,IF(AF12="",Constants!$B$13,AF12),"") | AP12: =IF($AJ12=Constants!$B$7,IF(AH12="",Constants!$B$13,AH12),"") | AQ12: =IF($AJ12=Constants!$B$7,IF(SUMPRODUCT(--($AL12:$AP12>AL12))+SUMPRODUCT(--($AL12:AL12=AL12))=1,1,IF(SUMPRODUCT(--($AL12:$AP12>AM12))+SUMPRODUCT(--($AL12:AM12=AM12))=1,2,IF(SUMPRODUCT(--($AL12:$AP12>AN12))+SUMPRODUCT(--($AL12:AN12=AN12))=1,3,IF(SUMPRODUCT(--($AL12:$AP12>AO12))+SUMPRODUCT(--($AL12:AO12=AO12))=1,4,5)))),"") | AR12: =IF($AJ12=Constants!$B$7,IF(SUMPRODUCT(--($AL12:$AP12>AL12))+SUMPRODUCT(--($AL12:AL12=AL12))=2,1,IF(SUMPRODUCT(--($AL12:$AP12>AM12))+SUMPRODUCT(--($AL12:AM12=AM12))=2,2,IF(SUMPRODUCT(--($AL12:$AP12>AN12))+SUMPRODUCT(--($AL12:AN12=AN12))=2,3,IF(SUMPRODUCT(--($AL12:$AP12>AO12))+SUMPRODUCT(--($AL12:AO12=AO12))=2,4,5)))),"") | AS12: =IF($AJ12=Constants!$B$7,IF(SUMPRODUCT(--($AL12:$AP12>AL12))+SUMPRODUCT(--($AL12:AL12=AL12))=3,1,IF(SUMPRODUCT(--($AL12:$AP12>AM12))+SUMPRODUCT(--($AL12:AM12=AM12))=3,2,IF(SUMPRODUCT(--($AL12:$AP12>AN12))+SUMPRODUCT(--($AL12:AN12=AN12))=3,3,IF(SUMPRODUCT(--($AL12:$AP12>AO12))+SUMPRODUCT(--($AL12:AO12=AO12))=3,4,5)))),"") | AT12: =IF($AJ12=Constants!$B$7,LARGE(AL12:AP12,1)+LARGE(AL12:AP12,2)+LARGE(AL12:AP12,3),"") | AU12: =IF(ISBLANK($C12),"",IF($AJ12<>Constants!$B$7,$AJ12,AT12*W12)) | AV12: =IF(ISBLANK($C12),"",IF($AJ12=Constants!$B$7,IF(ISNUMBER(AU12),RANK(AU12,$AU$8:$AU$507),Constants!$B$14),$AJ12)) | AW12: =IF(ISBLANK($C12),"",IF($AJ12=Constants!$B$7,IF(ISNUMBER(AV12),COUNTIFS($AK$8:$AK$507,"<"&$AK12)+COUNTIFS($AK$8:$AK$507,$AK12,$AV$8:$AV$507,"<"&$AV12)+1,Constants!$B$14),$AJ12)) | AX12: =IF(ISBLANK($C12),"",IF($AJ12=Constants!$B$7,LARGE(AL12:AP12,4)*W12,"")) | AY12: =IF(ISBLANK($C12),"",IF($AJ12=Constants!$B$7,RANK(AX12,$AX$8:$AX$507),$AJ12)) | AZ12: =IF(ISBLANK($C12),"",IF($AJ12=Constants!$B$7,IF(ISNUMBER(AV12),COUNTIFS($AK$8:$AK$507,"<"&$AK12)+COUNTIFS($AK$8:$AK$507,$AK12,$AV$8:$AV$507,"<"&$AV12)+COUNTIFS($AK$8:$AK$507,$AK12,$AV$8:$AV$507,$AV12,$AY$8:$AY$507,"<"&$AY12)+1,Constants!$B$14),$AJ12)) | BA12: =IF(ISBLANK($C12),"",IF($AJ12=Constants!$B$7,IF(ISNUMBER(AW12),AW12-AZ12,Constants!$B$14),$AJ12)) | BC12: =IF(ISBLANK($C12),"",IF($AJ12<>Constants!$B$7,$AJ12,SMALL(AQ12:AS12,1)&", "&SMALL(AQ12:AS12,2)&", "&SMALL(AQ12:AS12,3))) | BD12: =IF(ISBLANK($C12),"",IF($AJ12<>Constants!$B$7,$AJ12,W12)) | BE12: =IF(ISBLANK($C12),"",IF($AJ12<>Constants!$B$7,$AJ12,AU12)) | BF12: =IF(ISBLANK($C12),"",IF($AJ12<>Constants!$B$7,$AJ12,AK12)) | BG12: =IF(ISBLANK($C12),"",BA12) | BH12: =IF(ISBLANK($C12),"",AZ12) | BI12: =IF(ISBLANK($C12),"",IF(BH12=Constants!$B$4,COUNTA($C$8:$C$507)+2,IF(BH12=Constants!$B$5,COUNTA($C$8:$C$507)+1,IF(BH12=Constants!$B$6,COUNTA($C$8:$C$507),BH12)))) | BK12: =IF(OR(ISNUMBER(BH12),BH12=Constants!$B$4,BH12=Constants!$B$6,BH12=Constants!$B$5),1,0) -> 0 | BL12: 5 | BM12: =IF(ISBLANK($C12),"",IF(ISNUMBER(BI12),BI12+ROW($B12)/1000,"")) | BN12: =IF(ISNUMBER(BM12),RANK(BM12,$BM$8:$BM$507,1),"") | BO12: =IF(ISBLANK($C12),"",$B12) | BP12: =IF(ISBLANK($C12),"",$C12) | BQ12: =IF(ISBLANK($C12),"",$D12) | BR12: =BF12 | BS12: =BE12 | BT12: =IF(ISBLANK($C12),"",BH12) | BU12: =IF($BL12>$BK$7,"",VLOOKUP($BL12,$BN$8:$BT$507,7,FALSE())) | BV12: =IF($BL12>$BK$7,"",VLOOKUP($BL12,$BN$8:$BT$507,2,FALSE())) | BW12: =IF($BL12>$BK$7,"",VLOOKUP($BL12,$BN$8:$BT$507,3,FALSE())) | BX12: =IF($BL12>$BK$7,"",VLOOKUP($BL12,$BN$8:$BT$507,4,FALSE())) | BY12: =IF($BL12>$BK$7,"",VLOOKUP($BL12,$BN$8:$BT$507,5,FALSE())) | BZ12: =IF($BL12>$BK$7,"",VLOOKUP($BL12,$BN$8:$BT$507,6,FALSE()))
U13: =IF(ISBLANK($C13),"",IF(E13=Constants!$B$2, TRUE(), IF(E13=Constants!$B$3, FALSE(), TRUE()))) | V13: =IF(ISBLANK($C13),"",IF(F13=Constants!$B$2, TRUE(), IF(F13=Constants!$B$3, FALSE(), TRUE()))) | W13: =IF(ISBLANK($C13),"",IF(G13=Constants!$B$15,Constants!$B$8,IF(G13=Constants!$B$16,Constants!$B$9,Constants!$B$10))) | X13: =IF(ISBLANK($C13),"",IF(H13=Constants!$B$2, TRUE(), IF(H13=Constants!$B$3, FALSE(), TRUE()))) | Y13: =IF(ISBLANK($C13),"",IF(I13=Constants!$B$19,Constants!$B$19,Constants!$B$18)) | Z13: =IF(ISBLANK($C13),"",IF(ISNUMBER(J13),IF(J13>=0,J13,""),"")) | AA13: =IF(ISBLANK($C13),"",IF(K13=Constants!$B$19,Constants!$B$19,Constants!$B$18)) | AB13: =IF(ISBLANK($C13),"",IF(ISNUMBER(L13),IF(L13>=0,L13,""),"")) | AC13: =IF(ISBLANK($C13),"",IF(M13=Constants!$B$19,Constants!$B$19,Constants!$B$18)) | AD13: =IF(ISBLANK($C13),"",IF(ISNUMBER(N13),IF(N13>=0,N13,""),"")) | AE13: =IF(ISBLANK($C13),"",IF(O13=Constants!$B$19,Constants!$B$19,Constants!$B$18)) | AF13: =IF(ISBLANK($C13),"",IF(ISNUMBER(P13),IF(P13>=0,P13,""),"")) | AG13: =IF(ISBLANK($C13),"",IF(Q13=Constants!$B$19,Constants!$B$19,Constants!$B$18)) | AH13: =IF(ISBLANK($C13),"",IF(ISNUMBER(R13),IF(R13>=0,R13,""),"")) | AI13: =IF(ISBLANK($C13),"",IF(S13=Constants!$B$2, TRUE(), IF(S13=Constants!$B$3, FALSE(), FALSE()))) | AJ13: =IF(ISBLANK($C13),"",IF(AI13,Constants!$B$4,IF(COUNTA(E13:R13)=0,Constants!$B$5,IF(COUNTA(J13,L13,N13,P13,R13)=0,Constants!$B$6,Constants!$B$7)))) | AK13: =IF(ISBLANK($C13),"",IF($AJ13<>Constants!$B$7,$AJ13,IF(OR(NOT(X13),AND(NOT(U13),COUNTIFS(Y13:AG13,Constants!$B$18,Z13:AH13,">=0")>0),AND(NOT(V13),COUNTIFS(Y13:AG13,Constants!$B$19,Z13:AH13,">=0")>0)),Constants!$B$12,Constants!$B$11))) | AL13: =IF($AJ13=Constants!$B$7,IF(Z13="",Constants!$B$13,Z13),"") | AM13: =IF($AJ13=Constants!$B$7,IF(AB13="",Constants!$B$13,AB13),"") | AN13: =IF($AJ13=Constants!$B$7,IF(AD13="",Constants!$B$13,AD13),"") | AO13: =IF($AJ13=Constants!$B$7,IF(AF13="",Constants!$B$13,AF13),"") | AP13: =IF($AJ13=Constants!$B$7,IF(AH13="",Constants!$B$13,AH13),"") | AQ13: =IF($AJ13=Constants!$B$7,IF(SUMPRODUCT(--($AL13:$AP13>AL13))+SUMPRODUCT(--($AL13:AL13=AL13))=1,1,IF(SUMPRODUCT(--($AL13:$AP13>AM13))+SUMPRODUCT(--($AL13:AM13=AM13))=1,2,IF(SUMPRODUCT(--($AL13:$AP13>AN13))+SUMPRODUCT(--($AL13:AN13=AN13))=1,3,IF(SUMPRODUCT(--($AL13:$AP13>AO13))+SUMPRODUCT(--($AL13:AO13=AO13))=1,4,5)))),"") | AR13: =IF($AJ13=Constants!$B$7,IF(SUMPRODUCT(--($AL13:$AP13>AL13))+SUMPRODUCT(--($AL13:AL13=AL13))=2,1,IF(SUMPRODUCT(--($AL13:$AP13>AM13))+SUMPRODUCT(--($AL13:AM13=AM13))=2,2,IF(SUMPRODUCT(--($AL13:$AP13>AN13))+SUMPRODUCT(--($AL13:AN13=AN13))=2,3,IF(SUMPRODUCT(--($AL13:$AP13>AO13))+SUMPRODUCT(--($AL13:AO13=AO13))=2,4,5)))),"") | AS13: =IF($AJ13=Constants!$B$7,IF(SUMPRODUCT(--($AL13:$AP13>AL13))+SUMPRODUCT(--($AL13:AL13=AL13))=3,1,IF(SUMPRODUCT(--($AL13:$AP13>AM13))+SUMPRODUCT(--($AL13:AM13=AM13))=3,2,IF(SUMPRODUCT(--($AL13:$AP13>AN13))+SUMPRODUCT(--($AL13:AN13=AN13))=3,3,IF(SUMPRODUCT(--($AL13:$AP13>AO13))+SUMPRODUCT(--($AL13:AO13=AO13))=3,4,5)))),"") | AT13: =IF($AJ13=Constants!$B$7,LARGE(AL13:AP13,1)+LARGE(AL13:AP13,2)+LARGE(AL13:AP13,3),"") | AU13: =IF(ISBLANK($C13),"",IF($AJ13<>Constants!$B$7,$AJ13,AT13*W13)) | AV13: =IF(ISBLANK($C13),"",IF($AJ13=Constants!$B$7,IF(ISNUMBER(AU13),RANK(AU13,$AU$8:$AU$507),Constants!$B$14),$AJ13)) | AW13: =IF(ISBLANK($C13),"",IF($AJ13=Constants!$B$7,IF(ISNUMBER(AV13),COUNTIFS($AK$8:$AK$507,"<"&$AK13)+COUNTIFS($AK$8:$AK$507,$AK13,$AV$8:$AV$507,"<"&$AV13)+1,Constants!$B$14),$AJ13)) | AX13: =IF(ISBLANK($C13),"",IF($AJ13=Constants!$B$7,LARGE(AL13:AP13,4)*W13,"")) | AY13: =IF(ISBLANK($C13),"",IF($AJ13=Constants!$B$7,RANK(AX13,$AX$8:$AX$507),$AJ13)) | AZ13: =IF(ISBLANK($C13),"",IF($AJ13=Constants!$B$7,IF(ISNUMBER(AV13),COUNTIFS($AK$8:$AK$507,"<"&$AK13)+COUNTIFS($AK$8:$AK$507,$AK13,$AV$8:$AV$507,"<"&$AV13)+COUNTIFS($AK$8:$AK$507,$AK13,$AV$8:$AV$507,$AV13,$AY$8:$AY$507,"<"&$AY13)+1,Constants!$B$14),$AJ13)) | BA13: =IF(ISBLANK($C13),"",IF($AJ13=Constants!$B$7,IF(ISNUMBER(AW13),AW13-AZ13,Constants!$B$14),$AJ13)) | BC13: =IF(ISBLANK($C13),"",IF($AJ13<>Constants!$B$7,$AJ13,SMALL(AQ13:AS13,1)&", "&SMALL(AQ13:AS13,2)&", "&SMALL(AQ13:AS13,3))) | BD13: =IF(ISBLANK($C13),"",IF($AJ13<>Constants!$B$7,$AJ13,W13)) | BE13: =IF(ISBLANK($C13),"",IF($AJ13<>Constants!$B$7,$AJ13,AU13)) | BF13: =IF(ISBLANK($C13),"",IF($AJ13<>Constants!$B$7,$AJ13,AK13)) | BG13: =IF(ISBLANK($C13),"",BA13) | BH13: =IF(ISBLANK($C13),"",AZ13) | BI13: =IF(ISBLANK($C13),"",IF(BH13=Constants!$B$4,COUNTA($C$8:$C$507)+2,IF(BH13=Constants!$B$5,COUNTA($C$8:$C$507)+1,IF(BH13=Constants!$B$6,COUNTA($C$8:$C$507),BH13)))) | BK13: =IF(OR(ISNUMBER(BH13),BH13=Constants!$B$4,BH13=Constants!$B$6,BH13=Constants!$B$5),1,0) -> 0 | BL13: 6 | BM13: =IF(ISBLANK($C13),"",IF(ISNUMBER(BI13),BI13+ROW($B13)/1000,"")) | BN13: =IF(ISNUMBER(BM13),RANK(BM13,$BM$8:$BM$507,1),"") | BO13: =IF(ISBLANK($C13),"",$B13) | BP13: =IF(ISBLANK($C13),"",$C13) | BQ13: =IF(ISBLANK($C13),"",$D13) | BR13: =BF13 | BS13: =BE13 | BT13: =IF(ISBLANK($C13),"",BH13) | BU13: =IF($BL13>$BK$7,"",VLOOKUP($BL13,$BN$8:$BT$507,7,FALSE())) | BV13: =IF($BL13>$BK$7,"",VLOOKUP($BL13,$BN$8:$BT$507,2,FALSE())) | BW13: =IF($BL13>$BK$7,"",VLOOKUP($BL13,$BN$8:$BT$507,3,FALSE())) | BX13: =IF($BL13>$BK$7,"",VLOOKUP($BL13,$BN$8:$BT$507,4,FALSE())) | BY13: =IF($BL13>$BK$7,"",VLOOKUP($BL13,$BN$8:$BT$507,5,FALSE())) | BZ13: =IF($BL13>$BK$7,"",VLOOKUP($BL13,$BN$8:$BT$507,6,FALSE()))
U14: =IF(ISBLANK($C14),"",IF(E14=Constants!$B$2, TRUE(), IF(E14=Constants!$B$3, FALSE(), TRUE()))) | V14: =IF(ISBLANK($C14),"",IF(F14=Constants!$B$2, TRUE(), IF(F14=Constants!$B$3, FALSE(), TRUE()))) | W14: =IF(ISBLANK($C14),"",IF(G14=Constants!$B$15,Constants!$B$8,IF(G14=Constants!$B$16,Constants!$B$9,Constants!$B$10))) | X14: =IF(ISBLANK($C14),"",IF(H14=Constants!$B$2, TRUE(), IF(H14=Constants!$B$3, FALSE(), TRUE()))) | Y14: =IF(ISBLANK($C14),"",IF(I14=Constants!$B$19,Constants!$B$19,Constants!$B$18)) | Z14: =IF(ISBLANK($C14),"",IF(ISNUMBER(J14),IF(J14>=0,J14,""),"")) | AA14: =IF(ISBLANK($C14),"",IF(K14=Constants!$B$19,Constants!$B$19,Constants!$B$18)) | AB14: =IF(ISBLANK($C14),"",IF(ISNUMBER(L14),IF(L14>=0,L14,""),"")) | AC14: =IF(ISBLANK($C14),"",IF(M14=Constants!$B$19,Constants!$B$19,Constants!$B$18)) | AD14: =IF(ISBLANK($C14),"",IF(ISNUMBER(N14),IF(N14>=0,N14,""),"")) | AE14: =IF(ISBLANK($C14),"",IF(O14=Constants!$B$19,Constants!$B$19,Constants!$B$18)) | AF14: =IF(ISBLANK($C14),"",IF(ISNUMBER(P14),IF(P14>=0,P14,""),"")) | AG14: =IF(ISBLANK($C14),"",IF(Q14=Constants!$B$19,Constants!$B$19,Constants!$B$18)) | AH14: =IF(ISBLANK($C14),"",IF(ISNUMBER(R14),IF(R14>=0,R14,""),"")) | AI14: =IF(ISBLANK($C14),"",IF(S14=Constants!$B$2, TRUE(), IF(S14=Constants!$B$3, FALSE(), FALSE()))) | AJ14: =IF(ISBLANK($C14),"",IF(AI14,Constants!$B$4,IF(COUNTA(E14:R14)=0,Constants!$B$5,IF(COUNTA(J14,L14,N14,P14,R14)=0,Constants!$B$6,Constants!$B$7)))) | AK14: =IF(ISBLANK($C14),"",IF($AJ14<>Constants!$B$7,$AJ14,IF(OR(NOT(X14),AND(NOT(U14),COUNTIFS(Y14:AG14,Constants!$B$18,Z14:AH14,">=0")>0),AND(NOT(V14),COUNTIFS(Y14:AG14,Constants!$B$19,Z14:AH14,">=0")>0)),Constants!$B$12,Constants!$B$11))) | AL14: =IF($AJ14=Constants!$B$7,IF(Z14="",Constants!$B$13,Z14),"") | AM14: =IF($AJ14=Constants!$B$7,IF(AB14="",Constants!$B$13,AB14),"") | AN14: =IF($AJ14=Constants!$B$7,IF(AD14="",Constants!$B$13,AD14),"") | AO14: =IF($AJ14=Constants!$B$7,IF(AF14="",Constants!$B$13,AF14),"") | AP14: =IF($AJ14=Constants!$B$7,IF(AH14="",Constants!$B$13,AH14),"") | AQ14: =IF($AJ14=Constants!$B$7,IF(SUMPRODUCT(--($AL14:$AP14>AL14))+SUMPRODUCT(--($AL14:AL14=AL14))=1,1,IF(SUMPRODUCT(--($AL14:$AP14>AM14))+SUMPRODUCT(--($AL14:AM14=AM14))=1,2,IF(SUMPRODUCT(--($AL14:$AP14>AN14))+SUMPRODUCT(--($AL14:AN14=AN14))=1,3,IF(SUMPRODUCT(--($AL14:$AP14>AO14))+SUMPRODUCT(--($AL14:AO14=AO14))=1,4,5)))),"") | AR14: =IF($AJ14=Constants!$B$7,IF(SUMPRODUCT(--($AL14:$AP14>AL14))+SUMPRODUCT(--($AL14:AL14=AL14))=2,1,IF(SUMPRODUCT(--($AL14:$AP14>AM14))+SUMPRODUCT(--($AL14:AM14=AM14))=2,2,IF(SUMPRODUCT(--($AL14:$AP14>AN14))+SUMPRODUCT(--($AL14:AN14=AN14))=2,3,IF(SUMPRODUCT(--($AL14:$AP14>AO14))+SUMPRODUCT(--($AL14:AO14=AO14))=2,4,5)))),"") | AS14: =IF($AJ14=Constants!$B$7,IF(SUMPRODUCT(--($AL14:$AP14>AL14))+SUMPRODUCT(--($AL14:AL14=AL14))=3,1,IF(SUMPRODUCT(--($AL14:$AP14>AM14))+SUMPRODUCT(--($AL14:AM14=AM14))=3,2,IF(SUMPRODUCT(--($AL14:$AP14>AN14))+SUMPRODUCT(--($AL14:AN14=AN14))=3,3,IF(SUMPRODUCT(--($AL14:$AP14>AO14))+SUMPRODUCT(--($AL14:AO14=AO14))=3,4,5)))),"") | AT14: =IF($AJ14=Constants!$B$7,LARGE(AL14:AP14,1)+LARGE(AL14:AP14,2)+LARGE(AL14:AP14,3),"") | AU14: =IF(ISBLANK($C14),"",IF($AJ14<>Constants!$B$7,$AJ14,AT14*W14)) | AV14: =IF(ISBLANK($C14),"",IF($AJ14=Constants!$B$7,IF(ISNUMBER(AU14),RANK(AU14,$AU$8:$AU$507),Constants!$B$14),$AJ14)) | AW14: =IF(ISBLANK($C14),"",IF($AJ14=Constants!$B$7,IF(ISNUMBER(AV14),COUNTIFS($AK$8:$AK$507,"<"&$AK14)+COUNTIFS($AK$8:$AK$507,$AK14,$AV$8:$AV$507,"<"&$AV14)+1,Constants!$B$14),$AJ14)) | AX14: =IF(ISBLANK($C14),"",IF($AJ14=Constants!$B$7,LARGE(AL14:AP14,4)*W14,"")) | AY14: =IF(ISBLANK($C14),"",IF($AJ14=Constants!$B$7,RANK(AX14,$AX$8:$AX$507),$AJ14)) | AZ14: =IF(ISBLANK($C14),"",IF($AJ14=Constants!$B$7,IF(ISNUMBER(AV14),COUNTIFS($AK$8:$AK$507,"<"&$AK14)+COUNTIFS($AK$8:$AK$507,$AK14,$AV$8:$AV$507,"<"&$AV14)+COUNTIFS($AK$8:$AK$507,$AK14,$AV$8:$AV$507,$AV14,$AY$8:$AY$507,"<"&$AY14)+1,Constants!$B$14),$AJ14)) | BA14: =IF(ISBLANK($C14),"",IF($AJ14=Constants!$B$7,IF(ISNUMBER(AW14),AW14-AZ14,Constants!$B$14),$AJ14)) | BC14: =IF(ISBLANK($C14),"",IF($AJ14<>Constants!$B$7,$AJ14,SMALL(AQ14:AS14,1)&", "&SMALL(AQ14:AS14,2)&", "&SMALL(AQ14:AS14,3))) | BD14: =IF(ISBLANK($C14),"",IF($AJ14<>Constants!$B$7,$AJ14,W14)) | BE14: =IF(ISBLANK($C14),"",IF($AJ14<>Constants!$B$7,$AJ14,AU14)) | BF14: =IF(ISBLANK($C14),"",IF($AJ14<>Constants!$B$7,$AJ14,AK14)) | BG14: =IF(ISBLANK($C14),"",BA14) | BH14: =IF(ISBLANK($C14),"",AZ14) | BI14: =IF(ISBLANK($C14),"",IF(BH14=Constants!$B$4,COUNTA($C$8:$C$507)+2,IF(BH14=Constants!$B$5,COUNTA($C$8:$C$507)+1,IF(BH14=Constants!$B$6,COUNTA($C$8:$C$507),BH14)))) | BK14: =IF(OR(ISNUMBER(BH14),BH14=Constants!$B$4,BH14=Constants!$B$6,BH14=Constants!$B$5),1,0) -> 0 | BL14: 7 | BM14: =IF(ISBLANK($C14),"",IF(ISNUMBER(BI14),BI14+ROW($B14)/1000,"")) | BN14: =IF(ISNUMBER(BM14),RANK(BM14,$BM$8:$BM$507,1),"") | BO14: =IF(ISBLANK($C14),"",$B14) | BP14: =IF(ISBLANK($C14),"",$C14) | BQ14: =IF(ISBLANK($C14),"",$D14) | BR14: =BF14 | BS14: =BE14 | BT14: =IF(ISBLANK($C14),"",BH14) | BU14: =IF($BL14>$BK$7,"",VLOOKUP($BL14,$BN$8:$BT$507,7,FALSE())) | BV14: =IF($BL14>$BK$7,"",VLOOKUP($BL14,$BN$8:$BT$507,2,FALSE())) | BW14: =IF($BL14>$BK$7,"",VLOOKUP($BL14,$BN$8:$BT$507,3,FALSE())) | BX14: =IF($BL14>$BK$7,"",VLOOKUP($BL14,$BN$8:$BT$507,4,FALSE())) | BY14: =IF($BL14>$BK$7,"",VLOOKUP($BL14,$BN$8:$BT$507,5,FALSE())) | BZ14: =IF($BL14>$BK$7,"",VLOOKUP($BL14,$BN$8:$BT$507,6,FALSE()))
U15: =IF(ISBLANK($C15),"",IF(E15=Constants!$B$2, TRUE(), IF(E15=Constants!$B$3, FALSE(), TRUE()))) | V15: =IF(ISBLANK($C15),"",IF(F15=Constants!$B$2, TRUE(), IF(F15=Constants!$B$3, FALSE(), TRUE()))) | W15: =IF(ISBLANK($C15),"",IF(G15=Constants!$B$15,Constants!$B$8,IF(G15=Constants!$B$16,Constants!$B$9,Constants!$B$10))) | X15: =IF(ISBLANK($C15),"",IF(H15=Constants!$B$2, TRUE(), IF(H15=Constants!$B$3, FALSE(), TRUE()))) | Y15: =IF(ISBLANK($C15),"",IF(I15=Constants!$B$19,Constants!$B$19,Constants!$B$18)) | Z15: =IF(ISBLANK($C15),"",IF(ISNUMBER(J15),IF(J15>=0,J15,""),"")) | AA15: =IF(ISBLANK($C15),"",IF(K15=Constants!$B$19,Constants!$B$19,Constants!$B$18)) | AB15: =IF(ISBLANK($C15),"",IF(ISNUMBER(L15),IF(L15>=0,L15,""),"")) | AC15: =IF(ISBLANK($C15),"",IF(M15=Constants!$B$19,Constants!$B$19,Constants!$B$18)) | AD15: =IF(ISBLANK($C15),"",IF(ISNUMBER(N15),IF(N15>=0,N15,""),"")) | AE15: =IF(ISBLANK($C15),"",IF(O15=Constants!$B$19,Constants!$B$19,Constants!$B$18)) | AF15: =IF(ISBLANK($C15),"",IF(ISNUMBER(P15),IF(P15>=0,P15,""),"")) | AG15: =IF(ISBLANK($C15),"",IF(Q15=Constants!$B$19,Constants!$B$19,Constants!$B$18)) | AH15: =IF(ISBLANK($C15),"",IF(ISNUMBER(R15),IF(R15>=0,R15,""),"")) | AI15: =IF(ISBLANK($C15),"",IF(S15=Constants!$B$2, TRUE(), IF(S15=Constants!$B$3, FALSE(), FALSE()))) | AJ15: =IF(ISBLANK($C15),"",IF(AI15,Constants!$B$4,IF(COUNTA(E15:R15)=0,Constants!$B$5,IF(COUNTA(J15,L15,N15,P15,R15)=0,Constants!$B$6,Constants!$B$7)))) | AK15: =IF(ISBLANK($C15),"",IF($AJ15<>Constants!$B$7,$AJ15,IF(OR(NOT(X15),AND(NOT(U15),COUNTIFS(Y15:AG15,Constants!$B$18,Z15:AH15,">=0")>0),AND(NOT(V15),COUNTIFS(Y15:AG15,Constants!$B$19,Z15:AH15,">=0")>0)),Constants!$B$12,Constants!$B$11))) | AL15: =IF($AJ15=Constants!$B$7,IF(Z15="",Constants!$B$13,Z15),"") | AM15: =IF($AJ15=Constants!$B$7,IF(AB15="",Constants!$B$13,AB15),"") | AN15: =IF($AJ15=Constants!$B$7,IF(AD15="",Constants!$B$13,AD15),"") | AO15: =IF($AJ15=Constants!$B$7,IF(AF15="",Constants!$B$13,AF15),"") | AP15: =IF($AJ15=Constants!$B$7,IF(AH15="",Constants!$B$13,AH15),"") | AQ15: =IF($AJ15=Constants!$B$7,IF(SUMPRODUCT(--($AL15:$AP15>AL15))+SUMPRODUCT(--($AL15:AL15=AL15))=1,1,IF(SUMPRODUCT(--($AL15:$AP15>AM15))+SUMPRODUCT(--($AL15:AM15=AM15))=1,2,IF(SUMPRODUCT(--($AL15:$AP15>AN15))+SUMPRODUCT(--($AL15:AN15=AN15))=1,3,IF(SUMPRODUCT(--($AL15:$AP15>AO15))+SUMPRODUCT(--($AL15:AO15=AO15))=1,4,5)))),"") | AR15: =IF($AJ15=Constants!$B$7,IF(SUMPRODUCT(--($AL15:$AP15>AL15))+SUMPRODUCT(--($AL15:AL15=AL15))=2,1,IF(SUMPRODUCT(--($AL15:$AP15>AM15))+SUMPRODUCT(--($AL15:AM15=AM15))=2,2,IF(SUMPRODUCT(--($AL15:$AP15>AN15))+SUMPRODUCT(--($AL15:AN15=AN15))=2,3,IF(SUMPRODUCT(--($AL15:$AP15>AO15))+SUMPRODUCT(--($AL15:AO15=AO15))=2,4,5)))),"") | AS15: =IF($AJ15=Constants!$B$7,IF(SUMPRODUCT(--($AL15:$AP15>AL15))+SUMPRODUCT(--($AL15:AL15=AL15))=3,1,IF(SUMPRODUCT(--($AL15:$AP15>AM15))+SUMPRODUCT(--($AL15:AM15=AM15))=3,2,IF(SUMPRODUCT(--($AL15:$AP15>AN15))+SUMPRODUCT(--($AL15:AN15=AN15))=3,3,IF(SUMPRODUCT(--($AL15:$AP15>AO15))+SUMPRODUCT(--($AL15:AO15=AO15))=3,4,5)))),"") | AT15: =IF($AJ15=Constants!$B$7,LARGE(AL15:AP15,1)+LARGE(AL15:AP15,2)+LARGE(AL15:AP15,3),"") | AU15: =IF(ISBLANK($C15),"",IF($AJ15<>Constants!$B$7,$AJ15,AT15*W15)) | AV15: =IF(ISBLANK($C15),"",IF($AJ15=Constants!$B$7,IF(ISNUMBER(AU15),RANK(AU15,$AU$8:$AU$507),Constants!$B$14),$AJ15)) | AW15: =IF(ISBLANK($C15),"",IF($AJ15=Constants!$B$7,IF(ISNUMBER(AV15),COUNTIFS($AK$8:$AK$507,"<"&$AK15)+COUNTIFS($AK$8:$AK$507,$AK15,$AV$8:$AV$507,"<"&$AV15)+1,Constants!$B$14),$AJ15)) | AX15: =IF(ISBLANK($C15),"",IF($AJ15=Constants!$B$7,LARGE(AL15:AP15,4)*W15,"")) | AY15: =IF(ISBLANK($C15),"",IF($AJ15=Constants!$B$7,RANK(AX15,$AX$8:$AX$507),$AJ15)) | AZ15: =IF(ISBLANK($C15),"",IF($AJ15=Constants!$B$7,IF(ISNUMBER(AV15),COUNTIFS($AK$8:$AK$507,"<"&$AK15)+COUNTIFS($AK$8:$AK$507,$AK15,$AV$8:$AV$507,"<"&$AV15)+COUNTIFS($AK$8:$AK$507,$AK15,$AV$8:$AV$507,$AV15,$AY$8:$AY$507,"<"&$AY15)+1,Constants!$B$14),$AJ15)) | BA15: =IF(ISBLANK($C15),"",IF($AJ15=Constants!$B$7,IF(ISNUMBER(AW15),AW15-AZ15,Constants!$B$14),$AJ15)) | BC15: =IF(ISBLANK($C15),"",IF($AJ15<>Constants!$B$7,$AJ15,SMALL(AQ15:AS15,1)&", "&SMALL(AQ15:AS15,2)&", "&SMALL(AQ15:AS15,3))) | BD15: =IF(ISBLANK($C15),"",IF($AJ15<>Constants!$B$7,$AJ15,W15)) | BE15: =IF(ISBLANK($C15),"",IF($AJ15<>Constants!$B$7,$AJ15,AU15)) | BF15: =IF(ISBLANK($C15),"",IF($AJ15<>Constants!$B$7,$AJ15,AK15)) | BG15: =IF(ISBLANK($C15),"",BA15) | BH15: =IF(ISBLANK($C15),"",AZ15) | BI15: =IF(ISBLANK($C15),"",IF(BH15=Constants!$B$4,COUNTA($C$8:$C$507)+2,IF(BH15=Constants!$B$5,COUNTA($C$8:$C$507)+1,IF(BH15=Constants!$B$6,COUNTA($C$8:$C$507),BH15)))) | BK15: =IF(OR(ISNUMBER(BH15),BH15=Constants!$B$4,BH15=Constants!$B$6,BH15=Constants!$B$5),1,0) -> 0 | BL15: 8 | BM15: =IF(ISBLANK($C15),"",IF(ISNUMBER(BI15),BI15+ROW($B15)/1000,"")) | BN15: =IF(ISNUMBER(BM15),RANK(BM15,$BM$8:$BM$507,1),"") | BO15: =IF(ISBLANK($C15),"",$B15) | BP15: =IF(ISBLANK($C15),"",$C15) | BQ15: =IF(ISBLANK($C15),"",$D15) | BR15: =BF15 | BS15: =BE15 | BT15: =IF(ISBLANK($C15),"",BH15) | BU15: =IF($BL15>$BK$7,"",VLOOKUP($BL15,$BN$8:$BT$507,7,FALSE())) | BV15: =IF($BL15>$BK$7,"",VLOOKUP($BL15,$BN$8:$BT$507,2,FALSE())) | BW15: =IF($BL15>$BK$7,"",VLOOKUP($BL15,$BN$8:$BT$507,3,FALSE())) | BX15: =IF($BL15>$BK$7,"",VLOOKUP($BL15,$BN$8:$BT$507,4,FALSE())) | BY15: =IF($BL15>$BK$7,"",VLOOKUP($BL15,$BN$8:$BT$507,5,FALSE())) | BZ15: =IF($BL15>$BK$7,"",VLOOKUP($BL15,$BN$8:$BT$507,6,FALSE()))
U16: =IF(ISBLANK($C16),"",IF(E16=Constants!$B$2, TRUE(), IF(E16=Constants!$B$3, FALSE(), TRUE()))) | V16: =IF(ISBLANK($C16),"",IF(F16=Constants!$B$2, TRUE(), IF(F16=Constants!$B$3, FALSE(), TRUE()))) | W16: =IF(ISBLANK($C16),"",IF(G16=Constants!$B$15,Constants!$B$8,IF(G16=Constants!$B$16,Constants!$B$9,Constants!$B$10))) | X16: =IF(ISBLANK($C16),"",IF(H16=Constants!$B$2, TRUE(), IF(H16=Constants!$B$3, FALSE(), TRUE()))) | Y16: =IF(ISBLANK($C16),"",IF(I16=Constants!$B$19,Constants!$B$19,Constants!$B$18)) | Z16: =IF(ISBLANK($C16),"",IF(ISNUMBER(J16),IF(J16>=0,J16,""),"")) | AA16: =IF(ISBLANK($C16),"",IF(K16=Constants!$B$19,Constants!$B$19,Constants!$B$18)) | AB16: =IF(ISBLANK($C16),"",IF(ISNUMBER(L16),IF(L16>=0,L16,""),"")) | AC16: =IF(ISBLANK($C16),"",IF(M16=Constants!$B$19,Constants!$B$19,Constants!$B$18)) | AD16: =IF(ISBLANK($C16),"",IF(ISNUMBER(N16),IF(N16>=0,N16,""),"")) | AE16: =IF(ISBLANK($C16),"",IF(O16=Constants!$B$19,Constants!$B$19,Constants!$B$18)) | AF16: =IF(ISBLANK($C16),"",IF(ISNUMBER(P16),IF(P16>=0,P16,""),"")) | AG16: =IF(ISBLANK($C16),"",IF(Q16=Constants!$B$19,Constants!$B$19,Constants!$B$18)) | AH16: =IF(ISBLANK($C16),"",IF(ISNUMBER(R16),IF(R16>=0,R16,""),"")) | AI16: =IF(ISBLANK($C16),"",IF(S16=Constants!$B$2, TRUE(), IF(S16=Constants!$B$3, FALSE(), FALSE()))) | AJ16: =IF(ISBLANK($C16),"",IF(AI16,Constants!$B$4,IF(COUNTA(E16:R16)=0,Constants!$B$5,IF(COUNTA(J16,L16,N16,P16,R16)=0,Constants!$B$6,Constants!$B$7)))) | AK16: =IF(ISBLANK($C16),"",IF($AJ16<>Constants!$B$7,$AJ16,IF(OR(NOT(X16),AND(NOT(U16),COUNTIFS(Y16:AG16,Constants!$B$18,Z16:AH16,">=0")>0),AND(NOT(V16),COUNTIFS(Y16:AG16,Constants!$B$19,Z16:AH16,">=0")>0)),Constants!$B$12,Constants!$B$11))) | AL16: =IF($AJ16=Constants!$B$7,IF(Z16="",Constants!$B$13,Z16),"") | AM16: =IF($AJ16=Constants!$B$7,IF(AB16="",Constants!$B$13,AB16),"") | AN16: =IF($AJ16=Constants!$B$7,IF(AD16="",Constants!$B$13,AD16),"") | AO16: =IF($AJ16=Constants!$B$7,IF(AF16="",Constants!$B$13,AF16),"") | AP16: =IF($AJ16=Constants!$B$7,IF(AH16="",Constants!$B$13,AH16),"") | AQ16: =IF($AJ16=Constants!$B$7,IF(SUMPRODUCT(--($AL16:$AP16>AL16))+SUMPRODUCT(--($AL16:AL16=AL16))=1,1,IF(SUMPRODUCT(--($AL16:$AP16>AM16))+SUMPRODUCT(--($AL16:AM16=AM16))=1,2,IF(SUMPRODUCT(--($AL16:$AP16>AN16))+SUMPRODUCT(--($AL16:AN16=AN16))=1,3,IF(SUMPRODUCT(--($AL16:$AP16>AO16))+SUMPRODUCT(--($AL16:AO16=AO16))=1,4,5)))),"") | AR16: =IF($AJ16=Constants!$B$7,IF(SUMPRODUCT(--($AL16:$AP16>AL16))+SUMPRODUCT(--($AL16:AL16=AL16))=2,1,IF(SUMPRODUCT(--($AL16:$AP16>AM16))+SUMPRODUCT(--($AL16:AM16=AM16))=2,2,IF(SUMPRODUCT(--($AL16:$AP16>AN16))+SUMPRODUCT(--($AL16:AN16=AN16))=2,3,IF(SUMPRODUCT(--($AL16:$AP16>AO16))+SUMPRODUCT(--($AL16:AO16=AO16))=2,4,5)))),"") | AS16: =IF($AJ16=Constants!$B$7,IF(SUMPRODUCT(--($AL16:$AP16>AL16))+SUMPRODUCT(--($AL16:AL16=AL16))=3,1,IF(SUMPRODUCT(--($AL16:$AP16>AM16))+SUMPRODUCT(--($AL16:AM16=AM16))=3,2,IF(SUMPRODUCT(--($AL16:$AP16>AN16))+SUMPRODUCT(--($AL16:AN16=AN16))=3,3,IF(SUMPRODUCT(--($AL16:$AP16>AO16))+SUMPRODUCT(--($AL16:AO16=AO16))=3,4,5)))),"") | AT16: =IF($AJ16=Constants!$B$7,LARGE(AL16:AP16,1)+LARGE(AL16:AP16,2)+LARGE(AL16:AP16,3),"") | AU16: =IF(ISBLANK($C16),"",IF($AJ16<>Constants!$B$7,$AJ16,AT16*W16)) | AV16: =IF(ISBLANK($C16),"",IF($AJ16=Constants!$B$7,IF(ISNUMBER(AU16),RANK(AU16,$AU$8:$AU$507),Constants!$B$14),$AJ16)) | AW16: =IF(ISBLANK($C16),"",IF($AJ16=Constants!$B$7,IF(ISNUMBER(AV16),COUNTIFS($AK$8:$AK$507,"<"&$AK16)+COUNTIFS($AK$8:$AK$507,$AK16,$AV$8:$AV$507,"<"&$AV16)+1,Constants!$B$14),$AJ16)) | AX16: =IF(ISBLANK($C16),"",IF($AJ16=Constants!$B$7,LARGE(AL16:AP16,4)*W16,"")) | AY16: =IF(ISBLANK($C16),"",IF($AJ16=Constants!$B$7,RANK(AX16,$AX$8:$AX$507),$AJ16)) | AZ16: =IF(ISBLANK($C16),"",IF($AJ16=Constants!$B$7,IF(ISNUMBER(AV16),COUNTIFS($AK$8:$AK$507,"<"&$AK16)+COUNTIFS($AK$8:$AK$507,$AK16,$AV$8:$AV$507,"<"&$AV16)+COUNTIFS($AK$8:$AK$507,$AK16,$AV$8:$AV$507,$AV16,$AY$8:$AY$507,"<"&$AY16)+1,Constants!$B$14),$AJ16)) | BA16: =IF(ISBLANK($C16),"",IF($AJ16=Constants!$B$7,IF(ISNUMBER(AW16),AW16-AZ16,Constants!$B$14),$AJ16)) | BC16: =IF(ISBLANK($C16),"",IF($AJ16<>Constants!$B$7,$AJ16,SMALL(AQ16:AS16,1)&", "&SMALL(AQ16:AS16,2)&", "&SMALL(AQ16:AS16,3))) | BD16: =IF(ISBLANK($C16),"",IF($AJ16<>Constants!$B$7,$AJ16,W16)) | BE16: =IF(ISBLANK($C16),"",IF($AJ16<>Constants!$B$7,$AJ16,AU16)) | BF16: =IF(ISBLANK($C16),"",IF($AJ16<>Constants!$B$7,$AJ16,AK16)) | BG16: =IF(ISBLANK($C16),"",BA16) | BH16: =IF(ISBLANK($C16),"",AZ16) | BI16: =IF(ISBLANK($C16),"",IF(BH16=Constants!$B$4,COUNTA($C$8:$C$507)+2,IF(BH16=Constants!$B$5,COUNTA($C$8:$C$507)+1,IF(BH16=Constants!$B$6,COUNTA($C$8:$C$507),BH16)))) | BK16: =IF(OR(ISNUMBER(BH16),BH16=Constants!$B$4,BH16=Constants!$B$6,BH16=Constants!$B$5),1,0) -> 0 | BL16: 9 | BM16: =IF(ISBLANK($C16),"",IF(ISNUMBER(BI16),BI16+ROW($B16)/1000,"")) | BN16: =IF(ISNUMBER(BM16),RANK(BM16,$BM$8:$BM$507,1),"") | BO16: =IF(ISBLANK($C16),"",$B16) | BP16: =IF(ISBLANK($C16),"",$C16) | BQ16: =IF(ISBLANK($C16),"",$D16) | BR16: =BF16 | BS16: =BE16 | BT16: =IF(ISBLANK($C16),"",BH16) | BU16: =IF($BL16>$BK$7,"",VLOOKUP($BL16,$BN$8:$BT$507,7,FALSE())) | BV16: =IF($BL16>$BK$7,"",VLOOKUP($BL16,$BN$8:$BT$507,2,FALSE())) | BW16: =IF($BL16>$BK$7,"",VLOOKUP($BL16,$BN$8:$BT$507,3,FALSE())) | BX16: =IF($BL16>$BK$7,"",VLOOKUP($BL16,$BN$8:$BT$507,4,FALSE())) | BY16: =IF($BL16>$BK$7,"",VLOOKUP($BL16,$BN$8:$BT$507,5,FALSE())) | BZ16: =IF($BL16>$BK$7,"",VLOOKUP($BL16,$BN$8:$BT$507,6,FALSE()))
U17: =IF(ISBLANK($C17),"",IF(E17=Constants!$B$2, TRUE(), IF(E17=Constants!$B$3, FALSE(), TRUE()))) | V17: =IF(ISBLANK($C17),"",IF(F17=Constants!$B$2, TRUE(), IF(F17=Constants!$B$3, FALSE(), TRUE()))) | W17: =IF(ISBLANK($C17),"",IF(G17=Constants!$B$15,Constants!$B$8,IF(G17=Constants!$B$16,Constants!$B$9,Constants!$B$10))) | X17: =IF(ISBLANK($C17),"",IF(H17=Constants!$B$2, TRUE(), IF(H17=Constants!$B$3, FALSE(), TRUE()))) | Y17: =IF(ISBLANK($C17),"",IF(I17=Constants!$B$19,Constants!$B$19,Constants!$B$18)) | Z17: =IF(ISBLANK($C17),"",IF(ISNUMBER(J17),IF(J17>=0,J17,""),"")) | AA17: =IF(ISBLANK($C17),"",IF(K17=Constants!$B$19,Constants!$B$19,Constants!$B$18)) | AB17: =IF(ISBLANK($C17),"",IF(ISNUMBER(L17),IF(L17>=0,L17,""),"")) | AC17: =IF(ISBLANK($C17),"",IF(M17=Constants!$B$19,Constants!$B$19,Constants!$B$18)) | AD17: =IF(ISBLANK($C17),"",IF(ISNUMBER(N17),IF(N17>=0,N17,""),"")) | AE17: =IF(ISBLANK($C17),"",IF(O17=Constants!$B$19,Constants!$B$19,Constants!$B$18)) | AF17: =IF(ISBLANK($C17),"",IF(ISNUMBER(P17),IF(P17>=0,P17,""),"")) | AG17: =IF(ISBLANK($C17),"",IF(Q17=Constants!$B$19,Constants!$B$19,Constants!$B$18)) | AH17: =IF(ISBLANK($C17),"",IF(ISNUMBER(R17),IF(R17>=0,R17,""),"")) | AI17: =IF(ISBLANK($C17),"",IF(S17=Constants!$B$2, TRUE(), IF(S17=Constants!$B$3, FALSE(), FALSE()))) | AJ17: =IF(ISBLANK($C17),"",IF(AI17,Constants!$B$4,IF(COUNTA(E17:R17)=0,Constants!$B$5,IF(COUNTA(J17,L17,N17,P17,R17)=0,Constants!$B$6,Constants!$B$7)))) | AK17: =IF(ISBLANK($C17),"",IF($AJ17<>Constants!$B$7,$AJ17,IF(OR(NOT(X17),AND(NOT(U17),COUNTIFS(Y17:AG17,Constants!$B$18,Z17:AH17,">=0")>0),AND(NOT(V17),COUNTIFS(Y17:AG17,Constants!$B$19,Z17:AH17,">=0")>0)),Constants!$B$12,Constants!$B$11))) | AL17: =IF($AJ17=Constants!$B$7,IF(Z17="",Constants!$B$13,Z17),"") | AM17: =IF($AJ17=Constants!$B$7,IF(AB17="",Constants!$B$13,AB17),"") | AN17: =IF($AJ17=Constants!$B$7,IF(AD17="",Constants!$B$13,AD17),"") | AO17: =IF($AJ17=Constants!$B$7,IF(AF17="",Constants!$B$13,AF17),"") | AP17: =IF($AJ17=Constants!$B$7,IF(AH17="",Constants!$B$13,AH17),"") | AQ17: =IF($AJ17=Constants!$B$7,IF(SUMPRODUCT(--($AL17:$AP17>AL17))+SUMPRODUCT(--($AL17:AL17=AL17))=1,1,IF(SUMPRODUCT(--($AL17:$AP17>AM17))+SUMPRODUCT(--($AL17:AM17=AM17))=1,2,IF(SUMPRODUCT(--($AL17:$AP17>AN17))+SUMPRODUCT(--($AL17:AN17=AN17))=1,3,IF(SUMPRODUCT(--($AL17:$AP17>AO17))+SUMPRODUCT(--($AL17:AO17=AO17))=1,4,5)))),"") | AR17: =IF($AJ17=Constants!$B$7,IF(SUMPRODUCT(--($AL17:$AP17>AL17))+SUMPRODUCT(--($AL17:AL17=AL17))=2,1,IF(SUMPRODUCT(--($AL17:$AP17>AM17))+SUMPRODUCT(--($AL17:AM17=AM17))=2,2,IF(SUMPRODUCT(--($AL17:$AP17>AN17))+SUMPRODUCT(--($AL17:AN17=AN17))=2,3,IF(SUMPRODUCT(--($AL17:$AP17>AO17))+SUMPRODUCT(--($AL17:AO17=AO17))=2,4,5)))),"") | AS17: =IF($AJ17=Constants!$B$7,IF(SUMPRODUCT(--($AL17:$AP17>AL17))+SUMPRODUCT(--($AL17:AL17=AL17))=3,1,IF(SUMPRODUCT(--($AL17:$AP17>AM17))+SUMPRODUCT(--($AL17:AM17=AM17))=3,2,IF(SUMPRODUCT(--($AL17:$AP17>AN17))+SUMPRODUCT(--($AL17:AN17=AN17))=3,3,IF(SUMPRODUCT(--($AL17:$AP17>AO17))+SUMPRODUCT(--($AL17:AO17=AO17))=3,4,5)))),"") | AT17: =IF($AJ17=Constants!$B$7,LARGE(AL17:AP17,1)+LARGE(AL17:AP17,2)+LARGE(AL17:AP17,3),"") | AU17: =IF(ISBLANK($C17),"",IF($AJ17<>Constants!$B$7,$AJ17,AT17*W17)) | AV17: =IF(ISBLANK($C17),"",IF($AJ17=Constants!$B$7,IF(ISNUMBER(AU17),RANK(AU17,$AU$8:$AU$507),Constants!$B$14),$AJ17)) | AW17: =IF(ISBLANK($C17),"",IF($AJ17=Constants!$B$7,IF(ISNUMBER(AV17),COUNTIFS($AK$8:$AK$507,"<"&$AK17)+COUNTIFS($AK$8:$AK$507,$AK17,$AV$8:$AV$507,"<"&$AV17)+1,Constants!$B$14),$AJ17)) | AX17: =IF(ISBLANK($C17),"",IF($AJ17=Constants!$B$7,LARGE(AL17:AP17,4)*W17,"")) | AY17: =IF(ISBLANK($C17),"",IF($AJ17=Constants!$B$7,RANK(AX17,$AX$8:$AX$507),$AJ17)) | AZ17: =IF(ISBLANK($C17),"",IF($AJ17=Constants!$B$7,IF(ISNUMBER(AV17),COUNTIFS($AK$8:$AK$507,"<"&$AK17)+COUNTIFS($AK$8:$AK$507,$AK17,$AV$8:$AV$507,"<"&$AV17)+COUNTIFS($AK$8:$AK$507,$AK17,$AV$8:$AV$507,$AV17,$AY$8:$AY$507,"<"&$AY17)+1,Constants!$B$14),$AJ17)) | BA17: =IF(ISBLANK($C17),"",IF($AJ17=Constants!$B$7,IF(ISNUMBER(AW17),AW17-AZ17,Constants!$B$14),$AJ17)) | BC17: =IF(ISBLANK($C17),"",IF($AJ17<>Constants!$B$7,$AJ17,SMALL(AQ17:AS17,1)&", "&SMALL(AQ17:AS17,2)&", "&SMALL(AQ17:AS17,3))) | BD17: =IF(ISBLANK($C17),"",IF($AJ17<>Constants!$B$7,$AJ17,W17)) | BE17: =IF(ISBLANK($C17),"",IF($AJ17<>Constants!$B$7,$AJ17,AU17)) | BF17: =IF(ISBLANK($C17),"",IF($AJ17<>Constants!$B$7,$AJ17,AK17)) | BG17: =IF(ISBLANK($C17),"",BA17) | BH17: =IF(ISBLANK($C17),"",AZ17) | BI17: =IF(ISBLANK($C17),"",IF(BH17=Constants!$B$4,COUNTA($C$8:$C$507)+2,IF(BH17=Constants!$B$5,COUNTA($C$8:$C$507)+1,IF(BH17=Constants!$B$6,COUNTA($C$8:$C$507),BH17)))) | BK17: =IF(OR(ISNUMBER(BH17),BH17=Constants!$B$4,BH17=Constants!$B$6,BH17=Constants!$B$5),1,0) -> 0 | BL17: 10 | BM17: =IF(ISBLANK($C17),"",IF(ISNUMBER(BI17),BI17+ROW($B17)/1000,"")) | BN17: =IF(ISNUMBER(BM17),RANK(BM17,$BM$8:$BM$507,1),"") | BO17: =IF(ISBLANK($C17),"",$B17) | BP17: =IF(ISBLANK($C17),"",$C17) | BQ17: =IF(ISBLANK($C17),"",$D17) | BR17: =BF17 | BS17: =BE17 | BT17: =IF(ISBLANK($C17),"",BH17) | BU17: =IF($BL17>$BK$7,"",VLOOKUP($BL17,$BN$8:$BT$507,7,FALSE())) | BV17: =IF($BL17>$BK$7,"",VLOOKUP($BL17,$BN$8:$BT$507,2,FALSE())) | BW17: =IF($BL17>$BK$7,"",VLOOKUP($BL17,$BN$8:$BT$507,3,FALSE())) | BX17: =IF($BL17>$BK$7,"",VLOOKUP($BL17,$BN$8:$BT$507,4,FALSE())) | BY17: =IF($BL17>$BK$7,"",VLOOKUP($BL17,$BN$8:$BT$507,5,FALSE())) | BZ17: =IF($BL17>$BK$7,"",VLOOKUP($BL17,$BN$8:$BT$507,6,FALSE()))
