Workbook

Sheet Scoring
B2: ='Info.'!B1&" "&'Info.'!B4 -> Scrambler B | F2: Check-In | H2: Event Time | T2: 16. Disqualify (T/F) | W2: Check In | Z2: Run 1 | AF2: Run 2 | BV2: Breakdown | CI2: Rank for this team with row() bump | CJ2: Rank for this team with same ranks split | CK2: Team Number of this team | CL2: Name of this schoo | CM2: Name of this team | CN2: Tier for this Team | CO2: Score for this team | CP2: Actual Rank for this team | CQ2: Final Rankings
E3: 1. Impounded (T/F) | F3: 2. Participants use proper eyewear (T/F) | G3: 3. Conforms to kit modification requirements (T/F) | H3: Run 1 | N3: Run 2 | W3: =E3 -> 1. Impounded (T/F) | X3: =F3 -> 2. Participants use proper eyewear (T/F) | Y3: =G3 -> 3. Conforms to kit modification requirements (T/F) | Z3: =H4 -> 4. Met all const params (T/F) | AA3: =I4 -> 5. Met all comp params (T/F) | AB3: =J4 -> 6. Successful / Failed Run | AC3: =K4 -> 7. Run Time (s) | AD3: =L4 -> 8. Vehicle Distance (cm) | AE3: =M4 -> 9. Inside Can Dist (cm) | AF3: =N4 -> 10. Met all const params (T/F) | AG3: =O4 -> 11. Met all comp params (T/F) | ... AK3: =S4 -> 15. Inside Can Dist (cm) | AL3: =T2 -> 16. Disqualify (T/F) | AM3: Run 1 | AU3: Scored Run | AV3: Run 2 | BE3: Final Score | BV3: Scored Run | BW3: Distance Score | BX3: Time Score | BY3: Bonus Score | BZ3: Penalty Score | CA3: Score | CB3: Tier | CC3: Tiebreaker | CD3: Rank | CE3: Points | CQ3: Rank | CR3: Team # | CS3: School Name | CT3: Team Name | CU3: Tier | CV3: Score
B4: ="Event Scoresheet - "&'Info.'!B5&IF('Info.'!B8="T"," The scoresheet has been updated; please download version v"&'Info.'!B7&" from soinc.org/scoresheets.","") -> Event Scoresheet - 2027 | H4: 4. Met all const params (T/F) | I4: 5. Met all comp params (T/F) | J4: 6. Successful / Failed Run | K4: 7. Run Time (s) | L4: 8. Vehicle Distance (cm) | M4: 9. Inside Can Dist (cm) | N4: 10. Met all const params (T/F) | O4: 11. Met all comp params (T/F) | P4: 12. Successful / Failed Run | Q4: 13. Run Time (s) | R4: 14. Vehicle Distance (cm) | S4: 15. Inside Can Dist (cm) | AM4: Run 1 Error | AN4: Distance Score | AO4: Time Score | AP4: Can Bonus | AQ4: Run Penalties | AR4: Run Score | AS4: Run 1 TB1: Vehicle Distance | AT4: Run 1 TB2: Time Score | AV4: Run 2 Error | AW4: Distance Score | AX4: Time Score | AY4: Can Bonus | AZ4: Run Penalties | BA4: Run Score | BB4: Run 2 TB1: Vehicle Distance | BC4: Run 2 TB2: Time Score
B6: ="Last Updated: "&TEXT('Info.'!B2, "mm/dd/yyyy")&" (v"&'Info.'!B3&") Direct all questions to scoresheets@soinc.org." -> Last Updated: 10/01/2026 (v0.1.0) Direct all questions to scoresheets@soinc.org.
BJ7: Tiebreaks
B8: Team # | C8: School Name | D8: Team Name | BD8: Status | BE8: Tier | BF8: Scored Run Score | BG8: Final Score Penalties | BH8: Final Score | BI8: Rank | BJ8: Vehicle Dist of scored run (TB1) | BK8: TB1 Rank | BL8: Time Score of scored run (TB2) | BM8: TB2 Rank | BN8: Vehicle Dist of non-scored run (TB3) | BO8: TB3 Rank | BP8: Time Score of non-scored run (TB4) | BQ8: TB4 Rank | BR8: Rank w/ TB | BS8: Rank Diff | CG8: =SUM($CG$9:$CG$508) -> 0
W9: =IF(ISBLANK($C9),"",IF(E9=Constants!$B$2,TRUE(),IF(E9=Constants!$B$3,FALSE(),TRUE()))) | X9: =IF(ISBLANK($C9),"",IF(F9=Constants!$B$2,TRUE(),IF(F9=Constants!$B$3,FALSE(),TRUE()))) | Y9: =IF(ISBLANK($C9),"",IF(G9=Constants!$B$2,TRUE(),IF(G9=Constants!$B$3,FALSE(),TRUE()))) | Z9: =IF(ISBLANK($C9),"",IF(H9=Constants!$B$2,TRUE(),IF(H9=Constants!$B$3,FALSE(),TRUE()))) | AA9: =IF(ISBLANK($C9),"",IF(I9=Constants!$B$2,TRUE(),IF(I9=Constants!$B$3,FALSE(),TRUE()))) | AB9: =IF(ISBLANK($C9),"",IF(J9=Constants!$B$4,TRUE(),IF(J9=Constants!$B$5,FALSE(),COUNTA(K9:M9)>0))) | AC9: =IF(ISBLANK($C9),"",IF(ISNUMBER(K9),IF(K9>=0,K9,""),"")) | AD9: =IF(ISBLANK($C9),"",IF(ISNUMBER(L9),IF(L9>=0,L9,""),"")) | AE9: =IF(ISBLANK($C9),"",IF(ISNUMBER(M9),IF(M9>=0,MIN(M9,Constants!$B$22),""),"")) | AF9: =IF(ISBLANK($C9),"",IF(N9=Constants!$B$2,TRUE(),IF(N9=Constants!$B$3,FALSE(),TRUE()))) | AG9: =IF(ISBLANK($C9),"",IF(O9=Constants!$B$2,TRUE(),IF(O9=Constants!$B$3,FALSE(),TRUE()))) | AH9: =IF(ISBLANK($C9),"",IF(P9=Constants!$B$4,TRUE(),IF(P9=Constants!$B$5,FALSE(),COUNTA(Q9:S9)>0))) | AI9: =IF(ISBLANK($C9),"",IF(ISNUMBER(Q9),IF(Q9>=0,Q9,""),"")) | AJ9: =IF(ISBLANK($C9),"",IF(ISNUMBER(R9),IF(R9>=0,R9,""),"")) | AK9: =IF(ISBLANK($C9),"",IF(ISNUMBER(S9),IF(S9>=0,MIN(S9,Constants!$B$22),""),"")) | AL9: =IF(ISBLANK($C9),"",IF(T9=Constants!$B$2,TRUE(),IF(T9=Constants!$B$3,FALSE(),FALSE()))) | AM9: =IF(ISBLANK($C9),"",AND($AB9,OR($AC9="",$AD9="",AND(NOT(ISBLANK($M9)),$AE9="")))) | AN9: =IF($BD9<>Constants!$B$6,"",IF($AB9,Constants!$B$17*$AD9,Constants!$B$18)) | AO9: =IF($BD9<>Constants!$B$6,"",Constants!$B$19*IF($AB9,$AC9,0)) | AP9: =IF($BD9<>Constants!$B$6,"",IF(AND($AB9,ISNUMBER($AE9)),Constants!$B$20*(Constants!$B$21-$AE9),0)) | AQ9: =IF($BD9<>Constants!$B$6,"",IF($AA9,0,Constants!$B$12)+IF($Z9,0,Constants!$B$13)+IF($Y9,0,Constants!$B$14)) | AR9: =IF($BD9<>Constants!$B$6,"",Constants!$B$16+SUM($AN9:$AQ9)) | AS9: =IF($BD9<>Constants!$B$6,"",IF($AB9,$AD9,"")) | AT9: =IF($BD9<>Constants!$B$6,"",$AO9) | AU9: =IF($BD9<>Constants!$B$6,"",IF(OR($BA9<$AR9,AND($BA9=$AR9,OR(AND(ISNUMBER($BB9),OR(NOT(ISNUMBER($AS9)),$BB9<$AS9)),AND(OR(AND($BB9="",$AS9=""),AND(ISNUMBER($BB9),ISNUMBER($AS9),$BB9=$AS9)),$BC9<$AT9)))),"->","<-")) | AV9: =IF(ISBLANK($C9),"",AND($AH9,OR($AI9="",$AJ9="",AND(NOT(ISBLANK($S9)),$AK9="")))) | AW9: =IF($BD9<>Constants!$B$6,"",IF($AH9,Constants!$B$17*$AJ9,Constants!$B$18)) | AX9: =IF($BD9<>Constants!$B$6,"",Constants!$B$19*IF($AH9,$AI9,0)) | AY9: =IF($BD9<>Constants!$B$6,"",IF(AND($AH9,ISNUMBER($AK9)),Constants!$B$20*(Constants!$B$21-$AK9),0)) | AZ9: =IF($BD9<>Constants!$B$6,"",IF($AG9,0,Constants!$B$12)+IF($AF9,0,Constants!$B$13)+IF($Y9,0,Constants!$B$14)) | BA9: =IF($BD9<>Constants!$B$6,"",Constants!$B$16+SUM($AW9:$AZ9)) | BB9: =IF($BD9<>Constants!$B$6,"",IF($AH9,$AJ9,"")) | BC9: =IF($BD9<>Constants!$B$6,"",$AX9) | BD9: =IF(ISBLANK($C9),"",IF($AL9,Constants!$B$9,IF(COUNTA($E9:$T9)=0,Constants!$B$8,IF(NOT($X9),Constants!$B$7,IF(OR($AM9,$AV9),Constants!$B$10,Constants!$B$6))))) | BE9: =IF(ISBLANK($C9),"",IF($BD9<>Constants!$B$6,$BD9,Constants!$B$11)) | BF9: =IF($BD9<>Constants!$B$6,"",IF($AU9="->",$BA9,$AR9)) | BG9: =IF($BD9<>Constants!$B$6,"",IF($W9,0,Constants!$B$15)) | BH9: =IF(ISBLANK($C9),"",IF($BD9<>Constants!$B$6,$BD9,SUM($BF9:$BG9))) | BI9: =IF(ISBLANK($C9),"",IF($BD9<>Constants!$B$6,$BD9,RANK($BH9,$BH$9:$BH$508,1))) | BJ9: =IF($BD9<>Constants!$B$6,"",IF($AU9="->",$BB9,$AS9)) | BK9: =IF(ISBLANK($C9),"",IF($BD9<>Constants!$B$6,$BD9,IF(ISNUMBER($BJ9),RANK($BJ9,$BJ$9:$BJ$508,1),COUNT($BJ$9:$BJ$508)+1))) | BL9: =IF($BD9<>Constants!$B$6,"",IF($AU9="->",$BC9,$AT9)) | BM9: =IF(ISBLANK($C9),"",IF($BD9<>Constants!$B$6,$BD9,IF(ISNUMBER($BL9),RANK($BL9,$BL$9:$BL$508,1),COUNT($BL$9:$BL$508)+1))) | BN9: =IF($BD9<>Constants!$B$6,"",IF($AU9="->",$AS9,$BB9)) | BO9: =IF(ISBLANK($C9),"",IF($BD9<>Constants!$B$6,$BD9,IF(ISNUMBER($BN9),RANK($BN9,$BN$9:$BN$508,1),COUNT($BN$9:$BN$508)+1))) | BP9: =IF($BD9<>Constants!$B$6,"",IF($AU9="->",$AT9,$BC9)) | BQ9: =IF(ISBLANK($C9),"",IF($BD9<>Constants!$B$6,$BD9,IF(ISNUMBER($BP9),RANK($BP9,$BP$9:$BP$508,1),COUNT($BP$9:$BP$508)+1))) | BR9: =IF(ISBLANK($C9),"",IF($BD9<>Constants!$B$6,$BD9,COUNTIFS($BI$9:$BI$508,"<"&$BI9)+COUNTIFS($BI$9:$BI$508,$BI9,$BK$9:$BK$508,"<"&$BK9)+COUNTIFS($BI$9:$BI$508,$BI9,$BK$9:$BK$508,$BK9,$BM$9:$BM$508,"<"&$BM9)+COUNTIFS($BI$9:$BI$508,$BI9,$BK$9:$BK$508,$BK9,$BM$9:$BM$508,$BM9,$BO$9:$BO$508,"<"&$BO9)+COUNTIFS($BI$9:$BI$508,$BI9,$BK$9:$BK$508,$BK9,$BM$9:$BM$508,$BM9,$BO$9:$BO$508,$BO9,$BQ$9:$BQ$508,"<"&$BQ9)+1)) | BS9: =IF(ISBLANK($C9),"",IF($BD9<>Constants!$B$6,$BD9,$BI9-$BR9)) | BV9: =IF(ISBLANK($C9),"",IF($BD9<>Constants!$B$6,"",IF($AU9="->",2,1))) | BW9: =IF(ISBLANK($C9),"",IF($BD9<>Constants!$B$6,"",IF($AU9="->",$AW9,$AN9))) | BX9: =IF(ISBLANK($C9),"",IF($BD9<>Constants!$B$6,"",IF($AU9="->",$AX9,$AO9))) | BY9: =IF(ISBLANK($C9),"",IF($BD9<>Constants!$B$6,"",IF($AU9="->",$AY9,$AP9))) | BZ9: =IF(ISBLANK($C9),"",IF($BD9<>Constants!$B$6,"",IF($AU9="->",$AZ9,$AQ9)+$BG9)) | CA9: =IF(ISBLANK($C9),"",IF($BD9<>Constants!$B$6,$BD9,$BH9)) | CB9: =IF(ISBLANK($C9),"",$BE9) | CC9: =IF(ISBLANK($C9),"",$BS9) | CD9: =IF(ISBLANK($C9),"",$BR9) | CE9: =IF(ISBLANK($C9),"",IF($CD9=Constants!$B$9,COUNTA($C$9:$C$508)+2,IF($CD9=Constants!$B$8,COUNTA($C$9:$C$508)+1,IF($CD9=Constants!$B$7,COUNTA($C$9:$C$508),$CD9)))) | CG9: =IF(OR(ISNUMBER($CD9),$CD9=Constants!$B$9,$CD9=Constants!$B$7,$CD9=Constants!$B$8),1,0) -> 0 | CH9: 1 | CI9: =IF(ISBLANK($C9),"",IF(ISNUMBER($CE9),$CE9+ROW($B9)/1000,"")) | CJ9: =IF(ISNUMBER($CI9),RANK($CI9,$CI$9:$CI$508,1),"") | CK9: =IF(ISBLANK($C9),"",$B9) | CL9: =IF(ISBLANK($C9),"",$C9) | CM9: =IF(ISBLANK($C9),"",$D9) | CN9: =$CB9 | CO9: =$CA9 | CP9: =IF(ISBLANK($C9),"",$CD9) | CQ9: =IF($CH9>$CG$8,"",VLOOKUP($CH9,$CJ$9:$CP$508,7,FALSE())) | CR9: =IF($CH9>$CG$8,"",VLOOKUP($CH9,$CJ$9:$CP$508,2,FALSE())) | CS9: =IF($CH9>$CG$8,"",VLOOKUP($CH9,$CJ$9:$CP$508,3,FALSE())) | CT9: =IF($CH9>$CG$8,"",VLOOKUP($CH9,$CJ$9:$CP$508,4,FALSE())) | CU9: =IF($CH9>$CG$8,"",VLOOKUP($CH9,$CJ$9:$CP$508,5,FALSE())) | CV9: =IF($CH9>$CG$8,"",VLOOKUP($CH9,$CJ$9:$CP$508,6,FALSE()))
W10: =IF(ISBLANK($C10),"",IF(E10=Constants!$B$2,TRUE(),IF(E10=Constants!$B$3,FALSE(),TRUE()))) | X10: =IF(ISBLANK($C10),"",IF(F10=Constants!$B$2,TRUE(),IF(F10=Constants!$B$3,FALSE(),TRUE()))) | Y10: =IF(ISBLANK($C10),"",IF(G10=Constants!$B$2,TRUE(),IF(G10=Constants!$B$3,FALSE(),TRUE()))) | Z10: =IF(ISBLANK($C10),"",IF(H10=Constants!$B$2,TRUE(),IF(H10=Constants!$B$3,FALSE(),TRUE()))) | AA10: =IF(ISBLANK($C10),"",IF(I10=Constants!$B$2,TRUE(),IF(I10=Constants!$B$3,FALSE(),TRUE()))) | AB10: =IF(ISBLANK($C10),"",IF(J10=Constants!$B$4,TRUE(),IF(J10=Constants!$B$5,FALSE(),COUNTA(K10:M10)>0))) | AC10: =IF(ISBLANK($C10),"",IF(ISNUMBER(K10),IF(K10>=0,K10,""),"")) | AD10: =IF(ISBLANK($C10),"",IF(ISNUMBER(L10),IF(L10>=0,L10,""),"")) | AE10: =IF(ISBLANK($C10),"",IF(ISNUMBER(M10),IF(M10>=0,MIN(M10,Constants!$B$22),""),"")) | AF10: =IF(ISBLANK($C10),"",IF(N10=Constants!$B$2,TRUE(),IF(N10=Constants!$B$3,FALSE(),TRUE()))) | AG10: =IF(ISBLANK($C10),"",IF(O10=Constants!$B$2,TRUE(),IF(O10=Constants!$B$3,FALSE(),TRUE()))) | AH10: =IF(ISBLANK($C10),"",IF(P10=Constants!$B$4,TRUE(),IF(P10=Constants!$B$5,FALSE(),COUNTA(Q10:S10)>0))) | AI10: =IF(ISBLANK($C10),"",IF(ISNUMBER(Q10),IF(Q10>=0,Q10,""),"")) | AJ10: =IF(ISBLANK($C10),"",IF(ISNUMBER(R10),IF(R10>=0,R10,""),"")) | AK10: =IF(ISBLANK($C10),"",IF(ISNUMBER(S10),IF(S10>=0,MIN(S10,Constants!$B$22),""),"")) | AL10: =IF(ISBLANK($C10),"",IF(T10=Constants!$B$2,TRUE(),IF(T10=Constants!$B$3,FALSE(),FALSE()))) | AM10: =IF(ISBLANK($C10),"",AND($AB10,OR($AC10="",$AD10="",AND(NOT(ISBLANK($M10)),$AE10="")))) | AN10: =IF($BD10<>Constants!$B$6,"",IF($AB10,Constants!$B$17*$AD10,Constants!$B$18)) | AO10: =IF($BD10<>Constants!$B$6,"",Constants!$B$19*IF($AB10,$AC10,0)) | AP10: =IF($BD10<>Constants!$B$6,"",IF(AND($AB10,ISNUMBER($AE10)),Constants!$B$20*(Constants!$B$21-$AE10),0)) | AQ10: =IF($BD10<>Constants!$B$6,"",IF($AA10,0,Constants!$B$12)+IF($Z10,0,Constants!$B$13)+IF($Y10,0,Constants!$B$14)) | AR10: =IF($BD10<>Constants!$B$6,"",Constants!$B$16+SUM($AN10:$AQ10)) | AS10: =IF($BD10<>Constants!$B$6,"",IF($AB10,$AD10,"")) | AT10: =IF($BD10<>Constants!$B$6,"",$AO10) | AU10: =IF($BD10<>Constants!$B$6,"",IF(OR($BA10<$AR10,AND($BA10=$AR10,OR(AND(ISNUMBER($BB10),OR(NOT(ISNUMBER($AS10)),$BB10<$AS10)),AND(OR(AND($BB10="",$AS10=""),AND(ISNUMBER($BB10),ISNUMBER($AS10),$BB10=$AS10)),$BC10<$AT10)))),"->","<-")) | AV10: =IF(ISBLANK($C10),"",AND($AH10,OR($AI10="",$AJ10="",AND(NOT(ISBLANK($S10)),$AK10="")))) | AW10: =IF($BD10<>Constants!$B$6,"",IF($AH10,Constants!$B$17*$AJ10,Constants!$B$18)) | AX10: =IF($BD10<>Constants!$B$6,"",Constants!$B$19*IF($AH10,$AI10,0)) | AY10: =IF($BD10<>Constants!$B$6,"",IF(AND($AH10,ISNUMBER($AK10)),Constants!$B$20*(Constants!$B$21-$AK10),0)) | AZ10: =IF($BD10<>Constants!$B$6,"",IF($AG10,0,Constants!$B$12)+IF($AF10,0,Constants!$B$13)+IF($Y10,0,Constants!$B$14)) | BA10: =IF($BD10<>Constants!$B$6,"",Constants!$B$16+SUM($AW10:$AZ10)) | BB10: =IF($BD10<>Constants!$B$6,"",IF($AH10,$AJ10,"")) | BC10: =IF($BD10<>Constants!$B$6,"",$AX10) | BD10: =IF(ISBLANK($C10),"",IF($AL10,Constants!$B$9,IF(COUNTA($E10:$T10)=0,Constants!$B$8,IF(NOT($X10),Constants!$B$7,IF(OR($AM10,$AV10),Constants!$B$10,Constants!$B$6))))) | BE10: =IF(ISBLANK($C10),"",IF($BD10<>Constants!$B$6,$BD10,Constants!$B$11)) | BF10: =IF($BD10<>Constants!$B$6,"",IF($AU10="->",$BA10,$AR10)) | BG10: =IF($BD10<>Constants!$B$6,"",IF($W10,0,Constants!$B$15)) | BH10: =IF(ISBLANK($C10),"",IF($BD10<>Constants!$B$6,$BD10,SUM($BF10:$BG10))) | BI10: =IF(ISBLANK($C10),"",IF($BD10<>Constants!$B$6,$BD10,RANK($BH10,$BH$9:$BH$508,1))) | BJ10: =IF($BD10<>Constants!$B$6,"",IF($AU10="->",$BB10,$AS10)) | BK10: =IF(ISBLANK($C10),"",IF($BD10<>Constants!$B$6,$BD10,IF(ISNUMBER($BJ10),RANK($BJ10,$BJ$9:$BJ$508,1),COUNT($BJ$9:$BJ$508)+1))) | BL10: =IF($BD10<>Constants!$B$6,"",IF($AU10="->",$BC10,$AT10)) | BM10: =IF(ISBLANK($C10),"",IF($BD10<>Constants!$B$6,$BD10,IF(ISNUMBER($BL10),RANK($BL10,$BL$9:$BL$508,1),COUNT($BL$9:$BL$508)+1))) | BN10: =IF($BD10<>Constants!$B$6,"",IF($AU10="->",$AS10,$BB10)) | BO10: =IF(ISBLANK($C10),"",IF($BD10<>Constants!$B$6,$BD10,IF(ISNUMBER($BN10),RANK($BN10,$BN$9:$BN$508,1),COUNT($BN$9:$BN$508)+1))) | BP10: =IF($BD10<>Constants!$B$6,"",IF($AU10="->",$AT10,$BC10)) | BQ10: =IF(ISBLANK($C10),"",IF($BD10<>Constants!$B$6,$BD10,IF(ISNUMBER($BP10),RANK($BP10,$BP$9:$BP$508,1),COUNT($BP$9:$BP$508)+1))) | BR10: =IF(ISBLANK($C10),"",IF($BD10<>Constants!$B$6,$BD10,COUNTIFS($BI$9:$BI$508,"<"&$BI10)+COUNTIFS($BI$9:$BI$508,$BI10,$BK$9:$BK$508,"<"&$BK10)+COUNTIFS($BI$9:$BI$508,$BI10,$BK$9:$BK$508,$BK10,$BM$9:$BM$508,"<"&$BM10)+COUNTIFS($BI$9:$BI$508,$BI10,$BK$9:$BK$508,$BK10,$BM$9:$BM$508,$BM10,$BO$9:$BO$508,"<"&$BO10)+COUNTIFS($BI$9:$BI$508,$BI10,$BK$9:$BK$508,$BK10,$BM$9:$BM$508,$BM10,$BO$9:$BO$508,$BO10,$BQ$9:$BQ$508,"<"&$BQ10)+1)) | BS10: =IF(ISBLANK($C10),"",IF($BD10<>Constants!$B$6,$BD10,$BI10-$BR10)) | BV10: =IF(ISBLANK($C10),"",IF($BD10<>Constants!$B$6,"",IF($AU10="->",2,1))) | BW10: =IF(ISBLANK($C10),"",IF($BD10<>Constants!$B$6,"",IF($AU10="->",$AW10,$AN10))) | BX10: =IF(ISBLANK($C10),"",IF($BD10<>Constants!$B$6,"",IF($AU10="->",$AX10,$AO10))) | BY10: =IF(ISBLANK($C10),"",IF($BD10<>Constants!$B$6,"",IF($AU10="->",$AY10,$AP10))) | BZ10: =IF(ISBLANK($C10),"",IF($BD10<>Constants!$B$6,"",IF($AU10="->",$AZ10,$AQ10)+$BG10)) | CA10: =IF(ISBLANK($C10),"",IF($BD10<>Constants!$B$6,$BD10,$BH10)) | CB10: =IF(ISBLANK($C10),"",$BE10) | CC10: =IF(ISBLANK($C10),"",$BS10) | CD10: =IF(ISBLANK($C10),"",$BR10) | CE10: =IF(ISBLANK($C10),"",IF($CD10=Constants!$B$9,COUNTA($C$9:$C$508)+2,IF($CD10=Constants!$B$8,COUNTA($C$9:$C$508)+1,IF($CD10=Constants!$B$7,COUNTA($C$9:$C$508),$CD10)))) | CG10: =IF(OR(ISNUMBER($CD10),$CD10=Constants!$B$9,$CD10=Constants!$B$7,$CD10=Constants!$B$8),1,0) -> 0 | CH10: 2 | CI10: =IF(ISBLANK($C10),"",IF(ISNUMBER($CE10),$CE10+ROW($B10)/1000,"")) | CJ10: =IF(ISNUMBER($CI10),RANK($CI10,$CI$9:$CI$508,1),"") | CK10: =IF(ISBLANK($C10),"",$B10) | CL10: =IF(ISBLANK($C10),"",$C10) | CM10: =IF(ISBLANK($C10),"",$D10) | CN10: =$CB10 | CO10: =$CA10 | CP10: =IF(ISBLANK($C10),"",$CD10) | CQ10: =IF($CH10>$CG$8,"",VLOOKUP($CH10,$CJ$9:$CP$508,7,FALSE())) | CR10: =IF($CH10>$CG$8,"",VLOOKUP($CH10,$CJ$9:$CP$508,2,FALSE())) | CS10: =IF($CH10>$CG$8,"",VLOOKUP($CH10,$CJ$9:$CP$508,3,FALSE())) | CT10: =IF($CH10>$CG$8,"",VLOOKUP($CH10,$CJ$9:$CP$508,4,FALSE())) | CU10: =IF($CH10>$CG$8,"",VLOOKUP($CH10,$CJ$9:$CP$508,5,FALSE())) | CV10: =IF($CH10>$CG$8,"",VLOOKUP($CH10,$CJ$9:$CP$508,6,FALSE()))
W11: =IF(ISBLANK($C11),"",IF(E11=Constants!$B$2,TRUE(),IF(E11=Constants!$B$3,FALSE(),TRUE()))) | X11: =IF(ISBLANK($C11),"",IF(F11=Constants!$B$2,TRUE(),IF(F11=Constants!$B$3,FALSE(),TRUE()))) | Y11: =IF(ISBLANK($C11),"",IF(G11=Constants!$B$2,TRUE(),IF(G11=Constants!$B$3,FALSE(),TRUE()))) | Z11: =IF(ISBLANK($C11),"",IF(H11=Constants!$B$2,TRUE(),IF(H11=Constants!$B$3,FALSE(),TRUE()))) | AA11: =IF(ISBLANK($C11),"",IF(I11=Constants!$B$2,TRUE(),IF(I11=Constants!$B$3,FALSE(),TRUE()))) | AB11: =IF(ISBLANK($C11),"",IF(J11=Constants!$B$4,TRUE(),IF(J11=Constants!$B$5,FALSE(),COUNTA(K11:M11)>0))) | AC11: =IF(ISBLANK($C11),"",IF(ISNUMBER(K11),IF(K11>=0,K11,""),"")) | AD11: =IF(ISBLANK($C11),"",IF(ISNUMBER(L11),IF(L11>=0,L11,""),"")) | AE11: =IF(ISBLANK($C11),"",IF(ISNUMBER(M11),IF(M11>=0,MIN(M11,Constants!$B$22),""),"")) | AF11: =IF(ISBLANK($C11),"",IF(N11=Constants!$B$2,TRUE(),IF(N11=Constants!$B$3,FALSE(),TRUE()))) | AG11: =IF(ISBLANK($C11),"",IF(O11=Constants!$B$2,TRUE(),IF(O11=Constants!$B$3,FALSE(),TRUE()))) | AH11: =IF(ISBLANK($C11),"",IF(P11=Constants!$B$4,TRUE(),IF(P11=Constants!$B$5,FALSE(),COUNTA(Q11:S11)>0))) | AI11: =IF(ISBLANK($C11),"",IF(ISNUMBER(Q11),IF(Q11>=0,Q11,""),"")) | AJ11: =IF(ISBLANK($C11),"",IF(ISNUMBER(R11),IF(R11>=0,R11,""),"")) | AK11: =IF(ISBLANK($C11),"",IF(ISNUMBER(S11),IF(S11>=0,MIN(S11,Constants!$B$22),""),"")) | AL11: =IF(ISBLANK($C11),"",IF(T11=Constants!$B$2,TRUE(),IF(T11=Constants!$B$3,FALSE(),FALSE()))) | AM11: =IF(ISBLANK($C11),"",AND($AB11,OR($AC11="",$AD11="",AND(NOT(ISBLANK($M11)),$AE11="")))) | AN11: =IF($BD11<>Constants!$B$6,"",IF($AB11,Constants!$B$17*$AD11,Constants!$B$18)) | AO11: =IF($BD11<>Constants!$B$6,"",Constants!$B$19*IF($AB11,$AC11,0)) | AP11: =IF($BD11<>Constants!$B$6,"",IF(AND($AB11,ISNUMBER($AE11)),Constants!$B$20*(Constants!$B$21-$AE11),0)) | AQ11: =IF($BD11<>Constants!$B$6,"",IF($AA11,0,Constants!$B$12)+IF($Z11,0,Constants!$B$13)+IF($Y11,0,Constants!$B$14)) | AR11: =IF($BD11<>Constants!$B$6,"",Constants!$B$16+SUM($AN11:$AQ11)) | AS11: =IF($BD11<>Constants!$B$6,"",IF($AB11,$AD11,"")) | AT11: =IF($BD11<>Constants!$B$6,"",$AO11) | AU11: =IF($BD11<>Constants!$B$6,"",IF(OR($BA11<$AR11,AND($BA11=$AR11,OR(AND(ISNUMBER($BB11),OR(NOT(ISNUMBER($AS11)),$BB11<$AS11)),AND(OR(AND($BB11="",$AS11=""),AND(ISNUMBER($BB11),ISNUMBER($AS11),$BB11=$AS11)),$BC11<$AT11)))),"->","<-")) | AV11: =IF(ISBLANK($C11),"",AND($AH11,OR($AI11="",$AJ11="",AND(NOT(ISBLANK($S11)),$AK11="")))) | AW11: =IF($BD11<>Constants!$B$6,"",IF($AH11,Constants!$B$17*$AJ11,Constants!$B$18)) | AX11: =IF($BD11<>Constants!$B$6,"",Constants!$B$19*IF($AH11,$AI11,0)) | AY11: =IF($BD11<>Constants!$B$6,"",IF(AND($AH11,ISNUMBER($AK11)),Constants!$B$20*(Constants!$B$21-$AK11),0)) | AZ11: =IF($BD11<>Constants!$B$6,"",IF($AG11,0,Constants!$B$12)+IF($AF11,0,Constants!$B$13)+IF($Y11,0,Constants!$B$14)) | BA11: =IF($BD11<>Constants!$B$6,"",Constants!$B$16+SUM($AW11:$AZ11)) | BB11: =IF($BD11<>Constants!$B$6,"",IF($AH11,$AJ11,"")) | BC11: =IF($BD11<>Constants!$B$6,"",$AX11) | BD11: =IF(ISBLANK($C11),"",IF($AL11,Constants!$B$9,IF(COUNTA($E11:$T11)=0,Constants!$B$8,IF(NOT($X11),Constants!$B$7,IF(OR($AM11,$AV11),Constants!$B$10,Constants!$B$6))))) | BE11: =IF(ISBLANK($C11),"",IF($BD11<>Constants!$B$6,$BD11,Constants!$B$11)) | BF11: =IF($BD11<>Constants!$B$6,"",IF($AU11="->",$BA11,$AR11)) | BG11: =IF($BD11<>Constants!$B$6,"",IF($W11,0,Constants!$B$15)) | BH11: =IF(ISBLANK($C11),"",IF($BD11<>Constants!$B$6,$BD11,SUM($BF11:$BG11))) | BI11: =IF(ISBLANK($C11),"",IF($BD11<>Constants!$B$6,$BD11,RANK($BH11,$BH$9:$BH$508,1))) | BJ11: =IF($BD11<>Constants!$B$6,"",IF($AU11="->",$BB11,$AS11)) | BK11: =IF(ISBLANK($C11),"",IF($BD11<>Constants!$B$6,$BD11,IF(ISNUMBER($BJ11),RANK($BJ11,$BJ$9:$BJ$508,1),COUNT($BJ$9:$BJ$508)+1))) | BL11: =IF($BD11<>Constants!$B$6,"",IF($AU11="->",$BC11,$AT11)) | BM11: =IF(ISBLANK($C11),"",IF($BD11<>Constants!$B$6,$BD11,IF(ISNUMBER($BL11),RANK($BL11,$BL$9:$BL$508,1),COUNT($BL$9:$BL$508)+1))) | BN11: =IF($BD11<>Constants!$B$6,"",IF($AU11="->",$AS11,$BB11)) | BO11: =IF(ISBLANK($C11),"",IF($BD11<>Constants!$B$6,$BD11,IF(ISNUMBER($BN11),RANK($BN11,$BN$9:$BN$508,1),COUNT($BN$9:$BN$508)+1))) | BP11: =IF($BD11<>Constants!$B$6,"",IF($AU11="->",$AT11,$BC11)) | BQ11: =IF(ISBLANK($C11),"",IF($BD11<>Constants!$B$6,$BD11,IF(ISNUMBER($BP11),RANK($BP11,$BP$9:$BP$508,1),COUNT($BP$9:$BP$508)+1))) | BR11: =IF(ISBLANK($C11),"",IF($BD11<>Constants!$B$6,$BD11,COUNTIFS($BI$9:$BI$508,"<"&$BI11)+COUNTIFS($BI$9:$BI$508,$BI11,$BK$9:$BK$508,"<"&$BK11)+COUNTIFS($BI$9:$BI$508,$BI11,$BK$9:$BK$508,$BK11,$BM$9:$BM$508,"<"&$BM11)+COUNTIFS($BI$9:$BI$508,$BI11,$BK$9:$BK$508,$BK11,$BM$9:$BM$508,$BM11,$BO$9:$BO$508,"<"&$BO11)+COUNTIFS($BI$9:$BI$508,$BI11,$BK$9:$BK$508,$BK11,$BM$9:$BM$508,$BM11,$BO$9:$BO$508,$BO11,$BQ$9:$BQ$508,"<"&$BQ11)+1)) | BS11: =IF(ISBLANK($C11),"",IF($BD11<>Constants!$B$6,$BD11,$BI11-$BR11)) | BV11: =IF(ISBLANK($C11),"",IF($BD11<>Constants!$B$6,"",IF($AU11="->",2,1))) | BW11: =IF(ISBLANK($C11),"",IF($BD11<>Constants!$B$6,"",IF($AU11="->",$AW11,$AN11))) | BX11: =IF(ISBLANK($C11),"",IF($BD11<>Constants!$B$6,"",IF($AU11="->",$AX11,$AO11))) | BY11: =IF(ISBLANK($C11),"",IF($BD11<>Constants!$B$6,"",IF($AU11="->",$AY11,$AP11))) | BZ11: =IF(ISBLANK($C11),"",IF($BD11<>Constants!$B$6,"",IF($AU11="->",$AZ11,$AQ11)+$BG11)) | CA11: =IF(ISBLANK($C11),"",IF($BD11<>Constants!$B$6,$BD11,$BH11)) | CB11: =IF(ISBLANK($C11),"",$BE11) | CC11: =IF(ISBLANK($C11),"",$BS11) | CD11: =IF(ISBLANK($C11),"",$BR11) | CE11: =IF(ISBLANK($C11),"",IF($CD11=Constants!$B$9,COUNTA($C$9:$C$508)+2,IF($CD11=Constants!$B$8,COUNTA($C$9:$C$508)+1,IF($CD11=Constants!$B$7,COUNTA($C$9:$C$508),$CD11)))) | CG11: =IF(OR(ISNUMBER($CD11),$CD11=Constants!$B$9,$CD11=Constants!$B$7,$CD11=Constants!$B$8),1,0) -> 0 | CH11: 3 | CI11: =IF(ISBLANK($C11),"",IF(ISNUMBER($CE11),$CE11+ROW($B11)/1000,"")) | CJ11: =IF(ISNUMBER($CI11),RANK($CI11,$CI$9:$CI$508,1),"") | CK11: =IF(ISBLANK($C11),"",$B11) | CL11: =IF(ISBLANK($C11),"",$C11) | CM11: =IF(ISBLANK($C11),"",$D11) | CN11: =$CB11 | CO11: =$CA11 | CP11: =IF(ISBLANK($C11),"",$CD11) | CQ11: =IF($CH11>$CG$8,"",VLOOKUP($CH11,$CJ$9:$CP$508,7,FALSE())) | CR11: =IF($CH11>$CG$8,"",VLOOKUP($CH11,$CJ$9:$CP$508,2,FALSE())) | CS11: =IF($CH11>$CG$8,"",VLOOKUP($CH11,$CJ$9:$CP$508,3,FALSE())) | CT11: =IF($CH11>$CG$8,"",VLOOKUP($CH11,$CJ$9:$CP$508,4,FALSE())) | CU11: =IF($CH11>$CG$8,"",VLOOKUP($CH11,$CJ$9:$CP$508,5,FALSE())) | CV11: =IF($CH11>$CG$8,"",VLOOKUP($CH11,$CJ$9:$CP$508,6,FALSE()))
W12: =IF(ISBLANK($C12),"",IF(E12=Constants!$B$2,TRUE(),IF(E12=Constants!$B$3,FALSE(),TRUE()))) | X12: =IF(ISBLANK($C12),"",IF(F12=Constants!$B$2,TRUE(),IF(F12=Constants!$B$3,FALSE(),TRUE()))) | Y12: =IF(ISBLANK($C12),"",IF(G12=Constants!$B$2,TRUE(),IF(G12=Constants!$B$3,FALSE(),TRUE()))) | Z12: =IF(ISBLANK($C12),"",IF(H12=Constants!$B$2,TRUE(),IF(H12=Constants!$B$3,FALSE(),TRUE()))) | AA12: =IF(ISBLANK($C12),"",IF(I12=Constants!$B$2,TRUE(),IF(I12=Constants!$B$3,FALSE(),TRUE()))) | AB12: =IF(ISBLANK($C12),"",IF(J12=Constants!$B$4,TRUE(),IF(J12=Constants!$B$5,FALSE(),COUNTA(K12:M12)>0))) | AC12: =IF(ISBLANK($C12),"",IF(ISNUMBER(K12),IF(K12>=0,K12,""),"")) | AD12: =IF(ISBLANK($C12),"",IF(ISNUMBER(L12),IF(L12>=0,L12,""),"")) | AE12: =IF(ISBLANK($C12),"",IF(ISNUMBER(M12),IF(M12>=0,MIN(M12,Constants!$B$22),""),"")) | AF12: =IF(ISBLANK($C12),"",IF(N12=Constants!$B$2,TRUE(),IF(N12=Constants!$B$3,FALSE(),TRUE()))) | AG12: =IF(ISBLANK($C12),"",IF(O12=Constants!$B$2,TRUE(),IF(O12=Constants!$B$3,FALSE(),TRUE()))) | AH12: =IF(ISBLANK($C12),"",IF(P12=Constants!$B$4,TRUE(),IF(P12=Constants!$B$5,FALSE(),COUNTA(Q12:S12)>0))) | AI12: =IF(ISBLANK($C12),"",IF(ISNUMBER(Q12),IF(Q12>=0,Q12,""),"")) | AJ12: =IF(ISBLANK($C12),"",IF(ISNUMBER(R12),IF(R12>=0,R12,""),"")) | AK12: =IF(ISBLANK($C12),"",IF(ISNUMBER(S12),IF(S12>=0,MIN(S12,Constants!$B$22),""),"")) | AL12: =IF(ISBLANK($C12),"",IF(T12=Constants!$B$2,TRUE(),IF(T12=Constants!$B$3,FALSE(),FALSE()))) | AM12: =IF(ISBLANK($C12),"",AND($AB12,OR($AC12="",$AD12="",AND(NOT(ISBLANK($M12)),$AE12="")))) | AN12: =IF($BD12<>Constants!$B$6,"",IF($AB12,Constants!$B$17*$AD12,Constants!$B$18)) | AO12: =IF($BD12<>Constants!$B$6,"",Constants!$B$19*IF($AB12,$AC12,0)) | AP12: =IF($BD12<>Constants!$B$6,"",IF(AND($AB12,ISNUMBER($AE12)),Constants!$B$20*(Constants!$B$21-$AE12),0)) | AQ12: =IF($BD12<>Constants!$B$6,"",IF($AA12,0,Constants!$B$12)+IF($Z12,0,Constants!$B$13)+IF($Y12,0,Constants!$B$14)) | AR12: =IF($BD12<>Constants!$B$6,"",Constants!$B$16+SUM($AN12:$AQ12)) | AS12: =IF($BD12<>Constants!$B$6,"",IF($AB12,$AD12,"")) | AT12: =IF($BD12<>Constants!$B$6,"",$AO12) | AU12: =IF($BD12<>Constants!$B$6,"",IF(OR($BA12<$AR12,AND($BA12=$AR12,OR(AND(ISNUMBER($BB12),OR(NOT(ISNUMBER($AS12)),$BB12<$AS12)),AND(OR(AND($BB12="",$AS12=""),AND(ISNUMBER($BB12),ISNUMBER($AS12),$BB12=$AS12)),$BC12<$AT12)))),"->","<-")) | AV12: =IF(ISBLANK($C12),"",AND($AH12,OR($AI12="",$AJ12="",AND(NOT(ISBLANK($S12)),$AK12="")))) | AW12: =IF($BD12<>Constants!$B$6,"",IF($AH12,Constants!$B$17*$AJ12,Constants!$B$18)) | AX12: =IF($BD12<>Constants!$B$6,"",Constants!$B$19*IF($AH12,$AI12,0)) | AY12: =IF($BD12<>Constants!$B$6,"",IF(AND($AH12,ISNUMBER($AK12)),Constants!$B$20*(Constants!$B$21-$AK12),0)) | AZ12: =IF($BD12<>Constants!$B$6,"",IF($AG12,0,Constants!$B$12)+IF($AF12,0,Constants!$B$13)+IF($Y12,0,Constants!$B$14)) | BA12: =IF($BD12<>Constants!$B$6,"",Constants!$B$16+SUM($AW12:$AZ12)) | BB12: =IF($BD12<>Constants!$B$6,"",IF($AH12,$AJ12,"")) | BC12: =IF($BD12<>Constants!$B$6,"",$AX12) | BD12: =IF(ISBLANK($C12),"",IF($AL12,Constants!$B$9,IF(COUNTA($E12:$T12)=0,Constants!$B$8,IF(NOT($X12),Constants!$B$7,IF(OR($AM12,$AV12),Constants!$B$10,Constants!$B$6))))) | BE12: =IF(ISBLANK($C12),"",IF($BD12<>Constants!$B$6,$BD12,Constants!$B$11)) | BF12: =IF($BD12<>Constants!$B$6,"",IF($AU12="->",$BA12,$AR12)) | BG12: =IF($BD12<>Constants!$B$6,"",IF($W12,0,Constants!$B$15)) | BH12: =IF(ISBLANK($C12),"",IF($BD12<>Constants!$B$6,$BD12,SUM($BF12:$BG12))) | BI12: =IF(ISBLANK($C12),"",IF($BD12<>Constants!$B$6,$BD12,RANK($BH12,$BH$9:$BH$508,1))) | BJ12: =IF($BD12<>Constants!$B$6,"",IF($AU12="->",$BB12,$AS12)) | BK12: =IF(ISBLANK($C12),"",IF($BD12<>Constants!$B$6,$BD12,IF(ISNUMBER($BJ12),RANK($BJ12,$BJ$9:$BJ$508,1),COUNT($BJ$9:$BJ$508)+1))) | BL12: =IF($BD12<>Constants!$B$6,"",IF($AU12="->",$BC12,$AT12)) | BM12: =IF(ISBLANK($C12),"",IF($BD12<>Constants!$B$6,$BD12,IF(ISNUMBER($BL12),RANK($BL12,$BL$9:$BL$508,1),COUNT($BL$9:$BL$508)+1))) | BN12: =IF($BD12<>Constants!$B$6,"",IF($AU12="->",$AS12,$BB12)) | BO12: =IF(ISBLANK($C12),"",IF($BD12<>Constants!$B$6,$BD12,IF(ISNUMBER($BN12),RANK($BN12,$BN$9:$BN$508,1),COUNT($BN$9:$BN$508)+1))) | BP12: =IF($BD12<>Constants!$B$6,"",IF($AU12="->",$AT12,$BC12)) | BQ12: =IF(ISBLANK($C12),"",IF($BD12<>Constants!$B$6,$BD12,IF(ISNUMBER($BP12),RANK($BP12,$BP$9:$BP$508,1),COUNT($BP$9:$BP$508)+1))) | BR12: =IF(ISBLANK($C12),"",IF($BD12<>Constants!$B$6,$BD12,COUNTIFS($BI$9:$BI$508,"<"&$BI12)+COUNTIFS($BI$9:$BI$508,$BI12,$BK$9:$BK$508,"<"&$BK12)+COUNTIFS($BI$9:$BI$508,$BI12,$BK$9:$BK$508,$BK12,$BM$9:$BM$508,"<"&$BM12)+COUNTIFS($BI$9:$BI$508,$BI12,$BK$9:$BK$508,$BK12,$BM$9:$BM$508,$BM12,$BO$9:$BO$508,"<"&$BO12)+COUNTIFS($BI$9:$BI$508,$BI12,$BK$9:$BK$508,$BK12,$BM$9:$BM$508,$BM12,$BO$9:$BO$508,$BO12,$BQ$9:$BQ$508,"<"&$BQ12)+1)) | BS12: =IF(ISBLANK($C12),"",IF($BD12<>Constants!$B$6,$BD12,$BI12-$BR12)) | BV12: =IF(ISBLANK($C12),"",IF($BD12<>Constants!$B$6,"",IF($AU12="->",2,1))) | BW12: =IF(ISBLANK($C12),"",IF($BD12<>Constants!$B$6,"",IF($AU12="->",$AW12,$AN12))) | BX12: =IF(ISBLANK($C12),"",IF($BD12<>Constants!$B$6,"",IF($AU12="->",$AX12,$AO12))) | BY12: =IF(ISBLANK($C12),"",IF($BD12<>Constants!$B$6,"",IF($AU12="->",$AY12,$AP12))) | BZ12: =IF(ISBLANK($C12),"",IF($BD12<>Constants!$B$6,"",IF($AU12="->",$AZ12,$AQ12)+$BG12)) | CA12: =IF(ISBLANK($C12),"",IF($BD12<>Constants!$B$6,$BD12,$BH12)) | CB12: =IF(ISBLANK($C12),"",$BE12) | CC12: =IF(ISBLANK($C12),"",$BS12) | CD12: =IF(ISBLANK($C12),"",$BR12) | CE12: =IF(ISBLANK($C12),"",IF($CD12=Constants!$B$9,COUNTA($C$9:$C$508)+2,IF($CD12=Constants!$B$8,COUNTA($C$9:$C$508)+1,IF($CD12=Constants!$B$7,COUNTA($C$9:$C$508),$CD12)))) | CG12: =IF(OR(ISNUMBER($CD12),$CD12=Constants!$B$9,$CD12=Constants!$B$7,$CD12=Constants!$B$8),1,0) -> 0 | CH12: 4 | CI12: =IF(ISBLANK($C12),"",IF(ISNUMBER($CE12),$CE12+ROW($B12)/1000,"")) | CJ12: =IF(ISNUMBER($CI12),RANK($CI12,$CI$9:$CI$508,1),"") | CK12: =IF(ISBLANK($C12),"",$B12) | CL12: =IF(ISBLANK($C12),"",$C12) | CM12: =IF(ISBLANK($C12),"",$D12) | CN12: =$CB12 | CO12: =$CA12 | CP12: =IF(ISBLANK($C12),"",$CD12) | CQ12: =IF($CH12>$CG$8,"",VLOOKUP($CH12,$CJ$9:$CP$508,7,FALSE())) | CR12: =IF($CH12>$CG$8,"",VLOOKUP($CH12,$CJ$9:$CP$508,2,FALSE())) | CS12: =IF($CH12>$CG$8,"",VLOOKUP($CH12,$CJ$9:$CP$508,3,FALSE())) | CT12: =IF($CH12>$CG$8,"",VLOOKUP($CH12,$CJ$9:$CP$508,4,FALSE())) | CU12: =IF($CH12>$CG$8,"",VLOOKUP($CH12,$CJ$9:$CP$508,5,FALSE())) | CV12: =IF($CH12>$CG$8,"",VLOOKUP($CH12,$CJ$9:$CP$508,6,FALSE()))
W13: =IF(ISBLANK($C13),"",IF(E13=Constants!$B$2,TRUE(),IF(E13=Constants!$B$3,FALSE(),TRUE()))) | X13: =IF(ISBLANK($C13),"",IF(F13=Constants!$B$2,TRUE(),IF(F13=Constants!$B$3,FALSE(),TRUE()))) | Y13: =IF(ISBLANK($C13),"",IF(G13=Constants!$B$2,TRUE(),IF(G13=Constants!$B$3,FALSE(),TRUE()))) | Z13: =IF(ISBLANK($C13),"",IF(H13=Constants!$B$2,TRUE(),IF(H13=Constants!$B$3,FALSE(),TRUE()))) | AA13: =IF(ISBLANK($C13),"",IF(I13=Constants!$B$2,TRUE(),IF(I13=Constants!$B$3,FALSE(),TRUE()))) | AB13: =IF(ISBLANK($C13),"",IF(J13=Constants!$B$4,TRUE(),IF(J13=Constants!$B$5,FALSE(),COUNTA(K13:M13)>0))) | AC13: =IF(ISBLANK($C13),"",IF(ISNUMBER(K13),IF(K13>=0,K13,""),"")) | AD13: =IF(ISBLANK($C13),"",IF(ISNUMBER(L13),IF(L13>=0,L13,""),"")) | AE13: =IF(ISBLANK($C13),"",IF(ISNUMBER(M13),IF(M13>=0,MIN(M13,Constants!$B$22),""),"")) | AF13: =IF(ISBLANK($C13),"",IF(N13=Constants!$B$2,TRUE(),IF(N13=Constants!$B$3,FALSE(),TRUE()))) | AG13: =IF(ISBLANK($C13),"",IF(O13=Constants!$B$2,TRUE(),IF(O13=Constants!$B$3,FALSE(),TRUE()))) | AH13: =IF(ISBLANK($C13),"",IF(P13=Constants!$B$4,TRUE(),IF(P13=Constants!$B$5,FALSE(),COUNTA(Q13:S13)>0))) | AI13: =IF(ISBLANK($C13),"",IF(ISNUMBER(Q13),IF(Q13>=0,Q13,""),"")) | AJ13: =IF(ISBLANK($C13),"",IF(ISNUMBER(R13),IF(R13>=0,R13,""),"")) | AK13: =IF(ISBLANK($C13),"",IF(ISNUMBER(S13),IF(S13>=0,MIN(S13,Constants!$B$22),""),"")) | AL13: =IF(ISBLANK($C13),"",IF(T13=Constants!$B$2,TRUE(),IF(T13=Constants!$B$3,FALSE(),FALSE()))) | AM13: =IF(ISBLANK($C13),"",AND($AB13,OR($AC13="",$AD13="",AND(NOT(ISBLANK($M13)),$AE13="")))) | AN13: =IF($BD13<>Constants!$B$6,"",IF($AB13,Constants!$B$17*$AD13,Constants!$B$18)) | AO13: =IF($BD13<>Constants!$B$6,"",Constants!$B$19*IF($AB13,$AC13,0)) | AP13: =IF($BD13<>Constants!$B$6,"",IF(AND($AB13,ISNUMBER($AE13)),Constants!$B$20*(Constants!$B$21-$AE13),0)) | AQ13: =IF($BD13<>Constants!$B$6,"",IF($AA13,0,Constants!$B$12)+IF($Z13,0,Constants!$B$13)+IF($Y13,0,Constants!$B$14)) | AR13: =IF($BD13<>Constants!$B$6,"",Constants!$B$16+SUM($AN13:$AQ13)) | AS13: =IF($BD13<>Constants!$B$6,"",IF($AB13,$AD13,"")) | AT13: =IF($BD13<>Constants!$B$6,"",$AO13) | AU13: =IF($BD13<>Constants!$B$6,"",IF(OR($BA13<$AR13,AND($BA13=$AR13,OR(AND(ISNUMBER($BB13),OR(NOT(ISNUMBER($AS13)),$BB13<$AS13)),AND(OR(AND($BB13="",$AS13=""),AND(ISNUMBER($BB13),ISNUMBER($AS13),$BB13=$AS13)),$BC13<$AT13)))),"->","<-")) | AV13: =IF(ISBLANK($C13),"",AND($AH13,OR($AI13="",$AJ13="",AND(NOT(ISBLANK($S13)),$AK13="")))) | AW13: =IF($BD13<>Constants!$B$6,"",IF($AH13,Constants!$B$17*$AJ13,Constants!$B$18)) | AX13: =IF($BD13<>Constants!$B$6,"",Constants!$B$19*IF($AH13,$AI13,0)) | AY13: =IF($BD13<>Constants!$B$6,"",IF(AND($AH13,ISNUMBER($AK13)),Constants!$B$20*(Constants!$B$21-$AK13),0)) | AZ13: =IF($BD13<>Constants!$B$6,"",IF($AG13,0,Constants!$B$12)+IF($AF13,0,Constants!$B$13)+IF($Y13,0,Constants!$B$14)) | BA13: =IF($BD13<>Constants!$B$6,"",Constants!$B$16+SUM($AW13:$AZ13)) | BB13: =IF($BD13<>Constants!$B$6,"",IF($AH13,$AJ13,"")) | BC13: =IF($BD13<>Constants!$B$6,"",$AX13) | BD13: =IF(ISBLANK($C13),"",IF($AL13,Constants!$B$9,IF(COUNTA($E13:$T13)=0,Constants!$B$8,IF(NOT($X13),Constants!$B$7,IF(OR($AM13,$AV13),Constants!$B$10,Constants!$B$6))))) | BE13: =IF(ISBLANK($C13),"",IF($BD13<>Constants!$B$6,$BD13,Constants!$B$11)) | BF13: =IF($BD13<>Constants!$B$6,"",IF($AU13="->",$BA13,$AR13)) | BG13: =IF($BD13<>Constants!$B$6,"",IF($W13,0,Constants!$B$15)) | BH13: =IF(ISBLANK($C13),"",IF($BD13<>Constants!$B$6,$BD13,SUM($BF13:$BG13))) | BI13: =IF(ISBLANK($C13),"",IF($BD13<>Constants!$B$6,$BD13,RANK($BH13,$BH$9:$BH$508,1))) | BJ13: =IF($BD13<>Constants!$B$6,"",IF($AU13="->",$BB13,$AS13)) | BK13: =IF(ISBLANK($C13),"",IF($BD13<>Constants!$B$6,$BD13,IF(ISNUMBER($BJ13),RANK($BJ13,$BJ$9:$BJ$508,1),COUNT($BJ$9:$BJ$508)+1))) | BL13: =IF($BD13<>Constants!$B$6,"",IF($AU13="->",$BC13,$AT13)) | BM13: =IF(ISBLANK($C13),"",IF($BD13<>Constants!$B$6,$BD13,IF(ISNUMBER($BL13),RANK($BL13,$BL$9:$BL$508,1),COUNT($BL$9:$BL$508)+1))) | BN13: =IF($BD13<>Constants!$B$6,"",IF($AU13="->",$AS13,$BB13)) | BO13: =IF(ISBLANK($C13),"",IF($BD13<>Constants!$B$6,$BD13,IF(ISNUMBER($BN13),RANK($BN13,$BN$9:$BN$508,1),COUNT($BN$9:$BN$508)+1))) | BP13: =IF($BD13<>Constants!$B$6,"",IF($AU13="->",$AT13,$BC13)) | BQ13: =IF(ISBLANK($C13),"",IF($BD13<>Constants!$B$6,$BD13,IF(ISNUMBER($BP13),RANK($BP13,$BP$9:$BP$508,1),COUNT($BP$9:$BP$508)+1))) | BR13: =IF(ISBLANK($C13),"",IF($BD13<>Constants!$B$6,$BD13,COUNTIFS($BI$9:$BI$508,"<"&$BI13)+COUNTIFS($BI$9:$BI$508,$BI13,$BK$9:$BK$508,"<"&$BK13)+COUNTIFS($BI$9:$BI$508,$BI13,$BK$9:$BK$508,$BK13,$BM$9:$BM$508,"<"&$BM13)+COUNTIFS($BI$9:$BI$508,$BI13,$BK$9:$BK$508,$BK13,$BM$9:$BM$508,$BM13,$BO$9:$BO$508,"<"&$BO13)+COUNTIFS($BI$9:$BI$508,$BI13,$BK$9:$BK$508,$BK13,$BM$9:$BM$508,$BM13,$BO$9:$BO$508,$BO13,$BQ$9:$BQ$508,"<"&$BQ13)+1)) | BS13: =IF(ISBLANK($C13),"",IF($BD13<>Constants!$B$6,$BD13,$BI13-$BR13)) | BV13: =IF(ISBLANK($C13),"",IF($BD13<>Constants!$B$6,"",IF($AU13="->",2,1))) | BW13: =IF(ISBLANK($C13),"",IF($BD13<>Constants!$B$6,"",IF($AU13="->",$AW13,$AN13))) | BX13: =IF(ISBLANK($C13),"",IF($BD13<>Constants!$B$6,"",IF($AU13="->",$AX13,$AO13))) | BY13: =IF(ISBLANK($C13),"",IF($BD13<>Constants!$B$6,"",IF($AU13="->",$AY13,$AP13))) | BZ13: =IF(ISBLANK($C13),"",IF($BD13<>Constants!$B$6,"",IF($AU13="->",$AZ13,$AQ13)+$BG13)) | CA13: =IF(ISBLANK($C13),"",IF($BD13<>Constants!$B$6,$BD13,$BH13)) | CB13: =IF(ISBLANK($C13),"",$BE13) | CC13: =IF(ISBLANK($C13),"",$BS13) | CD13: =IF(ISBLANK($C13),"",$BR13) | CE13: =IF(ISBLANK($C13),"",IF($CD13=Constants!$B$9,COUNTA($C$9:$C$508)+2,IF($CD13=Constants!$B$8,COUNTA($C$9:$C$508)+1,IF($CD13=Constants!$B$7,COUNTA($C$9:$C$508),$CD13)))) | CG13: =IF(OR(ISNUMBER($CD13),$CD13=Constants!$B$9,$CD13=Constants!$B$7,$CD13=Constants!$B$8),1,0) -> 0 | CH13: 5 | CI13: =IF(ISBLANK($C13),"",IF(ISNUMBER($CE13),$CE13+ROW($B13)/1000,"")) | CJ13: =IF(ISNUMBER($CI13),RANK($CI13,$CI$9:$CI$508,1),"") | CK13: =IF(ISBLANK($C13),"",$B13) | CL13: =IF(ISBLANK($C13),"",$C13) | CM13: =IF(ISBLANK($C13),"",$D13) | CN13: =$CB13 | CO13: =$CA13 | CP13: =IF(ISBLANK($C13),"",$CD13) | CQ13: =IF($CH13>$CG$8,"",VLOOKUP($CH13,$CJ$9:$CP$508,7,FALSE())) | CR13: =IF($CH13>$CG$8,"",VLOOKUP($CH13,$CJ$9:$CP$508,2,FALSE())) | CS13: =IF($CH13>$CG$8,"",VLOOKUP($CH13,$CJ$9:$CP$508,3,FALSE())) | CT13: =IF($CH13>$CG$8,"",VLOOKUP($CH13,$CJ$9:$CP$508,4,FALSE())) | CU13: =IF($CH13>$CG$8,"",VLOOKUP($CH13,$CJ$9:$CP$508,5,FALSE())) | CV13: =IF($CH13>$CG$8,"",VLOOKUP($CH13,$CJ$9:$CP$508,6,FALSE()))
W14: =IF(ISBLANK($C14),"",IF(E14=Constants!$B$2,TRUE(),IF(E14=Constants!$B$3,FALSE(),TRUE()))) | X14: =IF(ISBLANK($C14),"",IF(F14=Constants!$B$2,TRUE(),IF(F14=Constants!$B$3,FALSE(),TRUE()))) | Y14: =IF(ISBLANK($C14),"",IF(G14=Constants!$B$2,TRUE(),IF(G14=Constants!$B$3,FALSE(),TRUE()))) | Z14: =IF(ISBLANK($C14),"",IF(H14=Constants!$B$2,TRUE(),IF(H14=Constants!$B$3,FALSE(),TRUE()))) | AA14: =IF(ISBLANK($C14),"",IF(I14=Constants!$B$2,TRUE(),IF(I14=Constants!$B$3,FALSE(),TRUE()))) | AB14: =IF(ISBLANK($C14),"",IF(J14=Constants!$B$4,TRUE(),IF(J14=Constants!$B$5,FALSE(),COUNTA(K14:M14)>0))) | AC14: =IF(ISBLANK($C14),"",IF(ISNUMBER(K14),IF(K14>=0,K14,""),"")) | AD14: =IF(ISBLANK($C14),"",IF(ISNUMBER(L14),IF(L14>=0,L14,""),"")) | AE14: =IF(ISBLANK($C14),"",IF(ISNUMBER(M14),IF(M14>=0,MIN(M14,Constants!$B$22),""),"")) | AF14: =IF(ISBLANK($C14),"",IF(N14=Constants!$B$2,TRUE(),IF(N14=Constants!$B$3,FALSE(),TRUE()))) | AG14: =IF(ISBLANK($C14),"",IF(O14=Constants!$B$2,TRUE(),IF(O14=Constants!$B$3,FALSE(),TRUE()))) | AH14: =IF(ISBLANK($C14),"",IF(P14=Constants!$B$4,TRUE(),IF(P14=Constants!$B$5,FALSE(),COUNTA(Q14:S14)>0))) | AI14: =IF(ISBLANK($C14),"",IF(ISNUMBER(Q14),IF(Q14>=0,Q14,""),"")) | AJ14: =IF(ISBLANK($C14),"",IF(ISNUMBER(R14),IF(R14>=0,R14,""),"")) | AK14: =IF(ISBLANK($C14),"",IF(ISNUMBER(S14),IF(S14>=0,MIN(S14,Constants!$B$22),""),"")) | AL14: =IF(ISBLANK($C14),"",IF(T14=Constants!$B$2,TRUE(),IF(T14=Constants!$B$3,FALSE(),FALSE()))) | AM14: =IF(ISBLANK($C14),"",AND($AB14,OR($AC14="",$AD14="",AND(NOT(ISBLANK($M14)),$AE14="")))) | AN14: =IF($BD14<>Constants!$B$6,"",IF($AB14,Constants!$B$17*$AD14,Constants!$B$18)) | AO14: =IF($BD14<>Constants!$B$6,"",Constants!$B$19*IF($AB14,$AC14,0)) | AP14: =IF($BD14<>Constants!$B$6,"",IF(AND($AB14,ISNUMBER($AE14)),Constants!$B$20*(Constants!$B$21-$AE14),0)) | AQ14: =IF($BD14<>Constants!$B$6,"",IF($AA14,0,Constants!$B$12)+IF($Z14,0,Constants!$B$13)+IF($Y14,0,Constants!$B$14)) | AR14: =IF($BD14<>Constants!$B$6,"",Constants!$B$16+SUM($AN14:$AQ14)) | AS14: =IF($BD14<>Constants!$B$6,"",IF($AB14,$AD14,"")) | AT14: =IF($BD14<>Constants!$B$6,"",$AO14) | AU14: =IF($BD14<>Constants!$B$6,"",IF(OR($BA14<$AR14,AND($BA14=$AR14,OR(AND(ISNUMBER($BB14),OR(NOT(ISNUMBER($AS14)),$BB14<$AS14)),AND(OR(AND($BB14="",$AS14=""),AND(ISNUMBER($BB14),ISNUMBER($AS14),$BB14=$AS14)),$BC14<$AT14)))),"->","<-")) | AV14: =IF(ISBLANK($C14),"",AND($AH14,OR($AI14="",$AJ14="",AND(NOT(ISBLANK($S14)),$AK14="")))) | AW14: =IF($BD14<>Constants!$B$6,"",IF($AH14,Constants!$B$17*$AJ14,Constants!$B$18)) | AX14: =IF($BD14<>Constants!$B$6,"",Constants!$B$19*IF($AH14,$AI14,0)) | AY14: =IF($BD14<>Constants!$B$6,"",IF(AND($AH14,ISNUMBER($AK14)),Constants!$B$20*(Constants!$B$21-$AK14),0)) | AZ14: =IF($BD14<>Constants!$B$6,"",IF($AG14,0,Constants!$B$12)+IF($AF14,0,Constants!$B$13)+IF($Y14,0,Constants!$B$14)) | BA14: =IF($BD14<>Constants!$B$6,"",Constants!$B$16+SUM($AW14:$AZ14)) | BB14: =IF($BD14<>Constants!$B$6,"",IF($AH14,$AJ14,"")) | BC14: =IF($BD14<>Constants!$B$6,"",$AX14) | BD14: =IF(ISBLANK($C14),"",IF($AL14,Constants!$B$9,IF(COUNTA($E14:$T14)=0,Constants!$B$8,IF(NOT($X14),Constants!$B$7,IF(OR($AM14,$AV14),Constants!$B$10,Constants!$B$6))))) | BE14: =IF(ISBLANK($C14),"",IF($BD14<>Constants!$B$6,$BD14,Constants!$B$11)) | BF14: =IF($BD14<>Constants!$B$6,"",IF($AU14="->",$BA14,$AR14)) | BG14: =IF($BD14<>Constants!$B$6,"",IF($W14,0,Constants!$B$15)) | BH14: =IF(ISBLANK($C14),"",IF($BD14<>Constants!$B$6,$BD14,SUM($BF14:$BG14))) | BI14: =IF(ISBLANK($C14),"",IF($BD14<>Constants!$B$6,$BD14,RANK($BH14,$BH$9:$BH$508,1))) | BJ14: =IF($BD14<>Constants!$B$6,"",IF($AU14="->",$BB14,$AS14)) | BK14: =IF(ISBLANK($C14),"",IF($BD14<>Constants!$B$6,$BD14,IF(ISNUMBER($BJ14),RANK($BJ14,$BJ$9:$BJ$508,1),COUNT($BJ$9:$BJ$508)+1))) | BL14: =IF($BD14<>Constants!$B$6,"",IF($AU14="->",$BC14,$AT14)) | BM14: =IF(ISBLANK($C14),"",IF($BD14<>Constants!$B$6,$BD14,IF(ISNUMBER($BL14),RANK($BL14,$BL$9:$BL$508,1),COUNT($BL$9:$BL$508)+1))) | BN14: =IF($BD14<>Constants!$B$6,"",IF($AU14="->",$AS14,$BB14)) | BO14: =IF(ISBLANK($C14),"",IF($BD14<>Constants!$B$6,$BD14,IF(ISNUMBER($BN14),RANK($BN14,$BN$9:$BN$508,1),COUNT($BN$9:$BN$508)+1))) | BP14: =IF($BD14<>Constants!$B$6,"",IF($AU14="->",$AT14,$BC14)) | BQ14: =IF(ISBLANK($C14),"",IF($BD14<>Constants!$B$6,$BD14,IF(ISNUMBER($BP14),RANK($BP14,$BP$9:$BP$508,1),COUNT($BP$9:$BP$508)+1))) | BR14: =IF(ISBLANK($C14),"",IF($BD14<>Constants!$B$6,$BD14,COUNTIFS($BI$9:$BI$508,"<"&$BI14)+COUNTIFS($BI$9:$BI$508,$BI14,$BK$9:$BK$508,"<"&$BK14)+COUNTIFS($BI$9:$BI$508,$BI14,$BK$9:$BK$508,$BK14,$BM$9:$BM$508,"<"&$BM14)+COUNTIFS($BI$9:$BI$508,$BI14,$BK$9:$BK$508,$BK14,$BM$9:$BM$508,$BM14,$BO$9:$BO$508,"<"&$BO14)+COUNTIFS($BI$9:$BI$508,$BI14,$BK$9:$BK$508,$BK14,$BM$9:$BM$508,$BM14,$BO$9:$BO$508,$BO14,$BQ$9:$BQ$508,"<"&$BQ14)+1)) | BS14: =IF(ISBLANK($C14),"",IF($BD14<>Constants!$B$6,$BD14,$BI14-$BR14)) | BV14: =IF(ISBLANK($C14),"",IF($BD14<>Constants!$B$6,"",IF($AU14="->",2,1))) | BW14: =IF(ISBLANK($C14),"",IF($BD14<>Constants!$B$6,"",IF($AU14="->",$AW14,$AN14))) | BX14: =IF(ISBLANK($C14),"",IF($BD14<>Constants!$B$6,"",IF($AU14="->",$AX14,$AO14))) | BY14: =IF(ISBLANK($C14),"",IF($BD14<>Constants!$B$6,"",IF($AU14="->",$AY14,$AP14))) | BZ14: =IF(ISBLANK($C14),"",IF($BD14<>Constants!$B$6,"",IF($AU14="->",$AZ14,$AQ14)+$BG14)) | CA14: =IF(ISBLANK($C14),"",IF($BD14<>Constants!$B$6,$BD14,$BH14)) | CB14: =IF(ISBLANK($C14),"",$BE14) | CC14: =IF(ISBLANK($C14),"",$BS14) | CD14: =IF(ISBLANK($C14),"",$BR14) | CE14: =IF(ISBLANK($C14),"",IF($CD14=Constants!$B$9,COUNTA($C$9:$C$508)+2,IF($CD14=Constants!$B$8,COUNTA($C$9:$C$508)+1,IF($CD14=Constants!$B$7,COUNTA($C$9:$C$508),$CD14)))) | CG14: =IF(OR(ISNUMBER($CD14),$CD14=Constants!$B$9,$CD14=Constants!$B$7,$CD14=Constants!$B$8),1,0) -> 0 | CH14: 6 | CI14: =IF(ISBLANK($C14),"",IF(ISNUMBER($CE14),$CE14+ROW($B14)/1000,"")) | CJ14: =IF(ISNUMBER($CI14),RANK($CI14,$CI$9:$CI$508,1),"") | CK14: =IF(ISBLANK($C14),"",$B14) | CL14: =IF(ISBLANK($C14),"",$C14) | CM14: =IF(ISBLANK($C14),"",$D14) | CN14: =$CB14 | CO14: =$CA14 | CP14: =IF(ISBLANK($C14),"",$CD14) | CQ14: =IF($CH14>$CG$8,"",VLOOKUP($CH14,$CJ$9:$CP$508,7,FALSE())) | CR14: =IF($CH14>$CG$8,"",VLOOKUP($CH14,$CJ$9:$CP$508,2,FALSE())) | CS14: =IF($CH14>$CG$8,"",VLOOKUP($CH14,$CJ$9:$CP$508,3,FALSE())) | CT14: =IF($CH14>$CG$8,"",VLOOKUP($CH14,$CJ$9:$CP$508,4,FALSE())) | CU14: =IF($CH14>$CG$8,"",VLOOKUP($CH14,$CJ$9:$CP$508,5,FALSE())) | CV14: =IF($CH14>$CG$8,"",VLOOKUP($CH14,$CJ$9:$CP$508,6,FALSE()))
W15: =IF(ISBLANK($C15),"",IF(E15=Constants!$B$2,TRUE(),IF(E15=Constants!$B$3,FALSE(),TRUE()))) | X15: =IF(ISBLANK($C15),"",IF(F15=Constants!$B$2,TRUE(),IF(F15=Constants!$B$3,FALSE(),TRUE()))) | Y15: =IF(ISBLANK($C15),"",IF(G15=Constants!$B$2,TRUE(),IF(G15=Constants!$B$3,FALSE(),TRUE()))) | Z15: =IF(ISBLANK($C15),"",IF(H15=Constants!$B$2,TRUE(),IF(H15=Constants!$B$3,FALSE(),TRUE()))) | AA15: =IF(ISBLANK($C15),"",IF(I15=Constants!$B$2,TRUE(),IF(I15=Constants!$B$3,FALSE(),TRUE()))) | AB15: =IF(ISBLANK($C15),"",IF(J15=Constants!$B$4,TRUE(),IF(J15=Constants!$B$5,FALSE(),COUNTA(K15:M15)>0))) | AC15: =IF(ISBLANK($C15),"",IF(ISNUMBER(K15),IF(K15>=0,K15,""),"")) | AD15: =IF(ISBLANK($C15),"",IF(ISNUMBER(L15),IF(L15>=0,L15,""),"")) | AE15: =IF(ISBLANK($C15),"",IF(ISNUMBER(M15),IF(M15>=0,MIN(M15,Constants!$B$22),""),"")) | AF15: =IF(ISBLANK($C15),"",IF(N15=Constants!$B$2,TRUE(),IF(N15=Constants!$B$3,FALSE(),TRUE()))) | AG15: =IF(ISBLANK($C15),"",IF(O15=Constants!$B$2,TRUE(),IF(O15=Constants!$B$3,FALSE(),TRUE()))) | AH15: =IF(ISBLANK($C15),"",IF(P15=Constants!$B$4,TRUE(),IF(P15=Constants!$B$5,FALSE(),COUNTA(Q15:S15)>0))) | AI15: =IF(ISBLANK($C15),"",IF(ISNUMBER(Q15),IF(Q15>=0,Q15,""),"")) | AJ15: =IF(ISBLANK($C15),"",IF(ISNUMBER(R15),IF(R15>=0,R15,""),"")) | AK15: =IF(ISBLANK($C15),"",IF(ISNUMBER(S15),IF(S15>=0,MIN(S15,Constants!$B$22),""),"")) | AL15: =IF(ISBLANK($C15),"",IF(T15=Constants!$B$2,TRUE(),IF(T15=Constants!$B$3,FALSE(),FALSE()))) | AM15: =IF(ISBLANK($C15),"",AND($AB15,OR($AC15="",$AD15="",AND(NOT(ISBLANK($M15)),$AE15="")))) | AN15: =IF($BD15<>Constants!$B$6,"",IF($AB15,Constants!$B$17*$AD15,Constants!$B$18)) | AO15: =IF($BD15<>Constants!$B$6,"",Constants!$B$19*IF($AB15,$AC15,0)) | AP15: =IF($BD15<>Constants!$B$6,"",IF(AND($AB15,ISNUMBER($AE15)),Constants!$B$20*(Constants!$B$21-$AE15),0)) | AQ15: =IF($BD15<>Constants!$B$6,"",IF($AA15,0,Constants!$B$12)+IF($Z15,0,Constants!$B$13)+IF($Y15,0,Constants!$B$14)) | AR15: =IF($BD15<>Constants!$B$6,"",Constants!$B$16+SUM($AN15:$AQ15)) | AS15: =IF($BD15<>Constants!$B$6,"",IF($AB15,$AD15,"")) | AT15: =IF($BD15<>Constants!$B$6,"",$AO15) | AU15: =IF($BD15<>Constants!$B$6,"",IF(OR($BA15<$AR15,AND($BA15=$AR15,OR(AND(ISNUMBER($BB15),OR(NOT(ISNUMBER($AS15)),$BB15<$AS15)),AND(OR(AND($BB15="",$AS15=""),AND(ISNUMBER($BB15),ISNUMBER($AS15),$BB15=$AS15)),$BC15<$AT15)))),"->","<-")) | AV15: =IF(ISBLANK($C15),"",AND($AH15,OR($AI15="",$AJ15="",AND(NOT(ISBLANK($S15)),$AK15="")))) | AW15: =IF($BD15<>Constants!$B$6,"",IF($AH15,Constants!$B$17*$AJ15,Constants!$B$18)) | AX15: =IF($BD15<>Constants!$B$6,"",Constants!$B$19*IF($AH15,$AI15,0)) | AY15: =IF($BD15<>Constants!$B$6,"",IF(AND($AH15,ISNUMBER($AK15)),Constants!$B$20*(Constants!$B$21-$AK15),0)) | AZ15: =IF($BD15<>Constants!$B$6,"",IF($AG15,0,Constants!$B$12)+IF($AF15,0,Constants!$B$13)+IF($Y15,0,Constants!$B$14)) | BA15: =IF($BD15<>Constants!$B$6,"",Constants!$B$16+SUM($AW15:$AZ15)) | BB15: =IF($BD15<>Constants!$B$6,"",IF($AH15,$AJ15,"")) | BC15: =IF($BD15<>Constants!$B$6,"",$AX15) | BD15: =IF(ISBLANK($C15),"",IF($AL15,Constants!$B$9,IF(COUNTA($E15:$T15)=0,Constants!$B$8,IF(NOT($X15),Constants!$B$7,IF(OR($AM15,$AV15),Constants!$B$10,Constants!$B$6))))) | BE15: =IF(ISBLANK($C15),"",IF($BD15<>Constants!$B$6,$BD15,Constants!$B$11)) | BF15: =IF($BD15<>Constants!$B$6,"",IF($AU15="->",$BA15,$AR15)) | BG15: =IF($BD15<>Constants!$B$6,"",IF($W15,0,Constants!$B$15)) | BH15: =IF(ISBLANK($C15),"",IF($BD15<>Constants!$B$6,$BD15,SUM($BF15:$BG15))) | BI15: =IF(ISBLANK($C15),"",IF($BD15<>Constants!$B$6,$BD15,RANK($BH15,$BH$9:$BH$508,1))) | BJ15: =IF($BD15<>Constants!$B$6,"",IF($AU15="->",$BB15,$AS15)) | BK15: =IF(ISBLANK($C15),"",IF($BD15<>Constants!$B$6,$BD15,IF(ISNUMBER($BJ15),RANK($BJ15,$BJ$9:$BJ$508,1),COUNT($BJ$9:$BJ$508)+1))) | BL15: =IF($BD15<>Constants!$B$6,"",IF($AU15="->",$BC15,$AT15)) | BM15: =IF(ISBLANK($C15),"",IF($BD15<>Constants!$B$6,$BD15,IF(ISNUMBER($BL15),RANK($BL15,$BL$9:$BL$508,1),COUNT($BL$9:$BL$508)+1))) | BN15: =IF($BD15<>Constants!$B$6,"",IF($AU15="->",$AS15,$BB15)) | BO15: =IF(ISBLANK($C15),"",IF($BD15<>Constants!$B$6,$BD15,IF(ISNUMBER($BN15),RANK($BN15,$BN$9:$BN$508,1),COUNT($BN$9:$BN$508)+1))) | BP15: =IF($BD15<>Constants!$B$6,"",IF($AU15="->",$AT15,$BC15)) | BQ15: =IF(ISBLANK($C15),"",IF($BD15<>Constants!$B$6,$BD15,IF(ISNUMBER($BP15),RANK($BP15,$BP$9:$BP$508,1),COUNT($BP$9:$BP$508)+1))) | BR15: =IF(ISBLANK($C15),"",IF($BD15<>Constants!$B$6,$BD15,COUNTIFS($BI$9:$BI$508,"<"&$BI15)+COUNTIFS($BI$9:$BI$508,$BI15,$BK$9:$BK$508,"<"&$BK15)+COUNTIFS($BI$9:$BI$508,$BI15,$BK$9:$BK$508,$BK15,$BM$9:$BM$508,"<"&$BM15)+COUNTIFS($BI$9:$BI$508,$BI15,$BK$9:$BK$508,$BK15,$BM$9:$BM$508,$BM15,$BO$9:$BO$508,"<"&$BO15)+COUNTIFS($BI$9:$BI$508,$BI15,$BK$9:$BK$508,$BK15,$BM$9:$BM$508,$BM15,$BO$9:$BO$508,$BO15,$BQ$9:$BQ$508,"<"&$BQ15)+1)) | BS15: =IF(ISBLANK($C15),"",IF($BD15<>Constants!$B$6,$BD15,$BI15-$BR15)) | BV15: =IF(ISBLANK($C15),"",IF($BD15<>Constants!$B$6,"",IF($AU15="->",2,1))) | BW15: =IF(ISBLANK($C15),"",IF($BD15<>Constants!$B$6,"",IF($AU15="->",$AW15,$AN15))) | BX15: =IF(ISBLANK($C15),"",IF($BD15<>Constants!$B$6,"",IF($AU15="->",$AX15,$AO15))) | BY15: =IF(ISBLANK($C15),"",IF($BD15<>Constants!$B$6,"",IF($AU15="->",$AY15,$AP15))) | BZ15: =IF(ISBLANK($C15),"",IF($BD15<>Constants!$B$6,"",IF($AU15="->",$AZ15,$AQ15)+$BG15)) | CA15: =IF(ISBLANK($C15),"",IF($BD15<>Constants!$B$6,$BD15,$BH15)) | CB15: =IF(ISBLANK($C15),"",$BE15) | CC15: =IF(ISBLANK($C15),"",$BS15) | CD15: =IF(ISBLANK($C15),"",$BR15) | CE15: =IF(ISBLANK($C15),"",IF($CD15=Constants!$B$9,COUNTA($C$9:$C$508)+2,IF($CD15=Constants!$B$8,COUNTA($C$9:$C$508)+1,IF($CD15=Constants!$B$7,COUNTA($C$9:$C$508),$CD15)))) | CG15: =IF(OR(ISNUMBER($CD15),$CD15=Constants!$B$9,$CD15=Constants!$B$7,$CD15=Constants!$B$8),1,0) -> 0 | CH15: 7 | CI15: =IF(ISBLANK($C15),"",IF(ISNUMBER($CE15),$CE15+ROW($B15)/1000,"")) | CJ15: =IF(ISNUMBER($CI15),RANK($CI15,$CI$9:$CI$508,1),"") | CK15: =IF(ISBLANK($C15),"",$B15) | CL15: =IF(ISBLANK($C15),"",$C15) | CM15: =IF(ISBLANK($C15),"",$D15) | CN15: =$CB15 | CO15: =$CA15 | CP15: =IF(ISBLANK($C15),"",$CD15) | CQ15: =IF($CH15>$CG$8,"",VLOOKUP($CH15,$CJ$9:$CP$508,7,FALSE())) | CR15: =IF($CH15>$CG$8,"",VLOOKUP($CH15,$CJ$9:$CP$508,2,FALSE())) | CS15: =IF($CH15>$CG$8,"",VLOOKUP($CH15,$CJ$9:$CP$508,3,FALSE())) | CT15: =IF($CH15>$CG$8,"",VLOOKUP($CH15,$CJ$9:$CP$508,4,FALSE())) | CU15: =IF($CH15>$CG$8,"",VLOOKUP($CH15,$CJ$9:$CP$508,5,FALSE())) | CV15: =IF($CH15>$CG$8,"",VLOOKUP($CH15,$CJ$9:$CP$508,6,FALSE()))
W16: =IF(ISBLANK($C16),"",IF(E16=Constants!$B$2,TRUE(),IF(E16=Constants!$B$3,FALSE(),TRUE()))) | X16: =IF(ISBLANK($C16),"",IF(F16=Constants!$B$2,TRUE(),IF(F16=Constants!$B$3,FALSE(),TRUE()))) | Y16: =IF(ISBLANK($C16),"",IF(G16=Constants!$B$2,TRUE(),IF(G16=Constants!$B$3,FALSE(),TRUE()))) | Z16: =IF(ISBLANK($C16),"",IF(H16=Constants!$B$2,TRUE(),IF(H16=Constants!$B$3,FALSE(),TRUE()))) | AA16: =IF(ISBLANK($C16),"",IF(I16=Constants!$B$2,TRUE(),IF(I16=Constants!$B$3,FALSE(),TRUE()))) | AB16: =IF(ISBLANK($C16),"",IF(J16=Constants!$B$4,TRUE(),IF(J16=Constants!$B$5,FALSE(),COUNTA(K16:M16)>0))) | AC16: =IF(ISBLANK($C16),"",IF(ISNUMBER(K16),IF(K16>=0,K16,""),"")) | AD16: =IF(ISBLANK($C16),"",IF(ISNUMBER(L16),IF(L16>=0,L16,""),"")) | AE16: =IF(ISBLANK($C16),"",IF(ISNUMBER(M16),IF(M16>=0,MIN(M16,Constants!$B$22),""),"")) | AF16: =IF(ISBLANK($C16),"",IF(N16=Constants!$B$2,TRUE(),IF(N16=Constants!$B$3,FALSE(),TRUE()))) | AG16: =IF(ISBLANK($C16),"",IF(O16=Constants!$B$2,TRUE(),IF(O16=Constants!$B$3,FALSE(),TRUE()))) | AH16: =IF(ISBLANK($C16),"",IF(P16=Constants!$B$4,TRUE(),IF(P16=Constants!$B$5,FALSE(),COUNTA(Q16:S16)>0))) | AI16: =IF(ISBLANK($C16),"",IF(ISNUMBER(Q16),IF(Q16>=0,Q16,""),"")) | AJ16: =IF(ISBLANK($C16),"",IF(ISNUMBER(R16),IF(R16>=0,R16,""),"")) | AK16: =IF(ISBLANK($C16),"",IF(ISNUMBER(S16),IF(S16>=0,MIN(S16,Constants!$B$22),""),"")) | AL16: =IF(ISBLANK($C16),"",IF(T16=Constants!$B$2,TRUE(),IF(T16=Constants!$B$3,FALSE(),FALSE()))) | AM16: =IF(ISBLANK($C16),"",AND($AB16,OR($AC16="",$AD16="",AND(NOT(ISBLANK($M16)),$AE16="")))) | AN16: =IF($BD16<>Constants!$B$6,"",IF($AB16,Constants!$B$17*$AD16,Constants!$B$18)) | AO16: =IF($BD16<>Constants!$B$6,"",Constants!$B$19*IF($AB16,$AC16,0)) | AP16: =IF($BD16<>Constants!$B$6,"",IF(AND($AB16,ISNUMBER($AE16)),Constants!$B$20*(Constants!$B$21-$AE16),0)) | AQ16: =IF($BD16<>Constants!$B$6,"",IF($AA16,0,Constants!$B$12)+IF($Z16,0,Constants!$B$13)+IF($Y16,0,Constants!$B$14)) | AR16: =IF($BD16<>Constants!$B$6,"",Constants!$B$16+SUM($AN16:$AQ16)) | AS16: =IF($BD16<>Constants!$B$6,"",IF($AB16,$AD16,"")) | AT16: =IF($BD16<>Constants!$B$6,"",$AO16) | AU16: =IF($BD16<>Constants!$B$6,"",IF(OR($BA16<$AR16,AND($BA16=$AR16,OR(AND(ISNUMBER($BB16),OR(NOT(ISNUMBER($AS16)),$BB16<$AS16)),AND(OR(AND($BB16="",$AS16=""),AND(ISNUMBER($BB16),ISNUMBER($AS16),$BB16=$AS16)),$BC16<$AT16)))),"->","<-")) | AV16: =IF(ISBLANK($C16),"",AND($AH16,OR($AI16="",$AJ16="",AND(NOT(ISBLANK($S16)),$AK16="")))) | AW16: =IF($BD16<>Constants!$B$6,"",IF($AH16,Constants!$B$17*$AJ16,Constants!$B$18)) | AX16: =IF($BD16<>Constants!$B$6,"",Constants!$B$19*IF($AH16,$AI16,0)) | AY16: =IF($BD16<>Constants!$B$6,"",IF(AND($AH16,ISNUMBER($AK16)),Constants!$B$20*(Constants!$B$21-$AK16),0)) | AZ16: =IF($BD16<>Constants!$B$6,"",IF($AG16,0,Constants!$B$12)+IF($AF16,0,Constants!$B$13)+IF($Y16,0,Constants!$B$14)) | BA16: =IF($BD16<>Constants!$B$6,"",Constants!$B$16+SUM($AW16:$AZ16)) | BB16: =IF($BD16<>Constants!$B$6,"",IF($AH16,$AJ16,"")) | BC16: =IF($BD16<>Constants!$B$6,"",$AX16) | BD16: =IF(ISBLANK($C16),"",IF($AL16,Constants!$B$9,IF(COUNTA($E16:$T16)=0,Constants!$B$8,IF(NOT($X16),Constants!$B$7,IF(OR($AM16,$AV16),Constants!$B$10,Constants!$B$6))))) | BE16: =IF(ISBLANK($C16),"",IF($BD16<>Constants!$B$6,$BD16,Constants!$B$11)) | BF16: =IF($BD16<>Constants!$B$6,"",IF($AU16="->",$BA16,$AR16)) | BG16: =IF($BD16<>Constants!$B$6,"",IF($W16,0,Constants!$B$15)) | BH16: =IF(ISBLANK($C16),"",IF($BD16<>Constants!$B$6,$BD16,SUM($BF16:$BG16))) | BI16: =IF(ISBLANK($C16),"",IF($BD16<>Constants!$B$6,$BD16,RANK($BH16,$BH$9:$BH$508,1))) | BJ16: =IF($BD16<>Constants!$B$6,"",IF($AU16="->",$BB16,$AS16)) | BK16: =IF(ISBLANK($C16),"",IF($BD16<>Constants!$B$6,$BD16,IF(ISNUMBER($BJ16),RANK($BJ16,$BJ$9:$BJ$508,1),COUNT($BJ$9:$BJ$508)+1))) | BL16: =IF($BD16<>Constants!$B$6,"",IF($AU16="->",$BC16,$AT16)) | BM16: =IF(ISBLANK($C16),"",IF($BD16<>Constants!$B$6,$BD16,IF(ISNUMBER($BL16),RANK($BL16,$BL$9:$BL$508,1),COUNT($BL$9:$BL$508)+1))) | BN16: =IF($BD16<>Constants!$B$6,"",IF($AU16="->",$AS16,$BB16)) | BO16: =IF(ISBLANK($C16),"",IF($BD16<>Constants!$B$6,$BD16,IF(ISNUMBER($BN16),RANK($BN16,$BN$9:$BN$508,1),COUNT($BN$9:$BN$508)+1))) | BP16: =IF($BD16<>Constants!$B$6,"",IF($AU16="->",$AT16,$BC16)) | BQ16: =IF(ISBLANK($C16),"",IF($BD16<>Constants!$B$6,$BD16,IF(ISNUMBER($BP16),RANK($BP16,$BP$9:$BP$508,1),COUNT($BP$9:$BP$508)+1))) | BR16: =IF(ISBLANK($C16),"",IF($BD16<>Constants!$B$6,$BD16,COUNTIFS($BI$9:$BI$508,"<"&$BI16)+COUNTIFS($BI$9:$BI$508,$BI16,$BK$9:$BK$508,"<"&$BK16)+COUNTIFS($BI$9:$BI$508,$BI16,$BK$9:$BK$508,$BK16,$BM$9:$BM$508,"<"&$BM16)+COUNTIFS($BI$9:$BI$508,$BI16,$BK$9:$BK$508,$BK16,$BM$9:$BM$508,$BM16,$BO$9:$BO$508,"<"&$BO16)+COUNTIFS($BI$9:$BI$508,$BI16,$BK$9:$BK$508,$BK16,$BM$9:$BM$508,$BM16,$BO$9:$BO$508,$BO16,$BQ$9:$BQ$508,"<"&$BQ16)+1)) | BS16: =IF(ISBLANK($C16),"",IF($BD16<>Constants!$B$6,$BD16,$BI16-$BR16)) | BV16: =IF(ISBLANK($C16),"",IF($BD16<>Constants!$B$6,"",IF($AU16="->",2,1))) | BW16: =IF(ISBLANK($C16),"",IF($BD16<>Constants!$B$6,"",IF($AU16="->",$AW16,$AN16))) | BX16: =IF(ISBLANK($C16),"",IF($BD16<>Constants!$B$6,"",IF($AU16="->",$AX16,$AO16))) | BY16: =IF(ISBLANK($C16),"",IF($BD16<>Constants!$B$6,"",IF($AU16="->",$AY16,$AP16))) | BZ16: =IF(ISBLANK($C16),"",IF($BD16<>Constants!$B$6,"",IF($AU16="->",$AZ16,$AQ16)+$BG16)) | CA16: =IF(ISBLANK($C16),"",IF($BD16<>Constants!$B$6,$BD16,$BH16)) | CB16: =IF(ISBLANK($C16),"",$BE16) | CC16: =IF(ISBLANK($C16),"",$BS16) | CD16: =IF(ISBLANK($C16),"",$BR16) | CE16: =IF(ISBLANK($C16),"",IF($CD16=Constants!$B$9,COUNTA($C$9:$C$508)+2,IF($CD16=Constants!$B$8,COUNTA($C$9:$C$508)+1,IF($CD16=Constants!$B$7,COUNTA($C$9:$C$508),$CD16)))) | CG16: =IF(OR(ISNUMBER($CD16),$CD16=Constants!$B$9,$CD16=Constants!$B$7,$CD16=Constants!$B$8),1,0) -> 0 | CH16: 8 | CI16: =IF(ISBLANK($C16),"",IF(ISNUMBER($CE16),$CE16+ROW($B16)/1000,"")) | CJ16: =IF(ISNUMBER($CI16),RANK($CI16,$CI$9:$CI$508,1),"") | CK16: =IF(ISBLANK($C16),"",$B16) | CL16: =IF(ISBLANK($C16),"",$C16) | CM16: =IF(ISBLANK($C16),"",$D16) | CN16: =$CB16 | CO16: =$CA16 | CP16: =IF(ISBLANK($C16),"",$CD16) | CQ16: =IF($CH16>$CG$8,"",VLOOKUP($CH16,$CJ$9:$CP$508,7,FALSE())) | CR16: =IF($CH16>$CG$8,"",VLOOKUP($CH16,$CJ$9:$CP$508,2,FALSE())) | CS16: =IF($CH16>$CG$8,"",VLOOKUP($CH16,$CJ$9:$CP$508,3,FALSE())) | CT16: =IF($CH16>$CG$8,"",VLOOKUP($CH16,$CJ$9:$CP$508,4,FALSE())) | CU16: =IF($CH16>$CG$8,"",VLOOKUP($CH16,$CJ$9:$CP$508,5,FALSE())) | CV16: =IF($CH16>$CG$8,"",VLOOKUP($CH16,$CJ$9:$CP$508,6,FALSE()))
