Workbook

Sheet Scoring
B2: ='Info.'!B1&" "&'Info.'!B4 -> Roller Coaster B | E2: Check-In | J2: Event Time | V2: 18. Disqualify (T/F) | X2: Check In | AC2: Run 1 | AI2: Run 2 | CD2: Breakdown | CQ2: Rank for this team with row() bump | CR2: Rank for this team with same ranks split | CS2: Team Number of this team | CT2: Name of this schoo | CU2: Name of this team | CV2: Tier for this Team | CW2: Score for this team | CX2: Actual Rank for this team | CY2: Final Rankings
E3: 1. Impounded (T/F) | F3: 2. Safety params met (T/F) | G3: 3. Device Width (cm) | H3: 4. Device Length (cm) | I3: 5. Device Height (cm) | J3: Run 1 | P3: Run 2 | X3: =E3 -> 1. Impounded (T/F) | Y3: =F3 -> 2. Safety params met (T/F) | Z3: =G3 -> 3. Device Width (cm) | AA3: =H3 -> 4. Device Length (cm) | AB3: =I3 -> 5. Device Height (cm) | AC3: =J4 -> 6. Met all const params (T/F) | AD3: =K4 -> 7. Met all comp params (T/F) | AE3: =L4 -> 8. Crossed Finish Line (T/F) | AF3: =M4 -> 9. Run Time (s) | AG3: =N4 -> 10. Elevator Bonus (0-2) | AH3: =O4 -> 11. Loop Height (cm) | AI3: =P4 -> 12. Met all const params (T/F) | AJ3: =Q4 -> 13. Met all comp params (T/F) | ... AN3: =U4 -> 17. Loop Height (cm) | AO3: =V2 -> 18. Disqualify (T/F) | AP3: Global: Target Time | AQ3: Dimension Error | AS3: Run 1 | BB3: Scored Run | BC3: Run 2 | BM3: Final Score | CD3: Scored Run | CE3: Size Score | CF3: Time Score | CG3: Elevator Score | CH3: Loop Score | CI3: Score | CJ3: Tier | CK3: Tiebreaker | CL3: Rank | CM3: Points | CY3: Rank | CZ3: Team # | DA3: School Name | DB3: Team Name | DC3: Tier | DD3: Score
B4: ="Event Scoresheet - "&'Info.'!B5&IF('Info.'!B8="T"," The scoresheet has been updated; please download version v"&'Info.'!B7&" from soinc.org/scoresheets.","") -> Event Scoresheet - 2027 | J4: 6. Met all const params (T/F) | K4: 7. Met all comp params (T/F) | L4: 8. Crossed Finish Line (T/F) | M4: 9. Run Time (s) | N4: 10. Elevator Bonus (0-2) | O4: 11. Loop Height (cm) | P4: 12. Met all const params (T/F) | Q4: 13. Met all comp params (T/F) | R4: 14. Crossed Finish Line (T/F) | S4: 15. Run Time (s) | T4: 16. Elevator Bonus (0-2) | U4: 17. Loop Height (cm) | AS4: Run 1 Used | AT4: Run 1 Error | AU4: Size Score | AV4: Time Score | AW4: Elevator Score | AX4: Loop Score | AY4: Run Tier | AZ4: Run Score | BA4: Run 1 TB4: Run Time | BC4: Run 2 Used | BD4: Run 2 Error | BE4: Size Score | BF4: Time Score | BG4: Elevator Score | BH4: Loop Score | BI4: Run Tier | BJ4: Run Score | BK4: Run 2 TB4: Run Time
AR5: ERROR: Set Target Time in cell D7
B6: ="Last Updated: "&TEXT('Info.'!B2, "mm/dd/yyyy")&" (v"&'Info.'!B3&") Direct all questions to scoresheets@soinc.org." -> Last Updated: 10/01/2026 (v1.0.0) Direct all questions to scoresheets@soinc.org. | AR6: ERROR: Target Time in cell D7 must be a whole number from 30 to 60
B7: Target Time (s): | BR7: Tiebreaks
B8: Team # | C8: School Name | D8: Team Name | AR8: Target Time Error | BL8: Status | BM8: Tier | BN8: Scored Run Score | BO8: Final Score | BP8: Score Rank | BQ8: Rank (Tier, Score) | BR8: Loop Score of scored run (TB1) | BS8: TB1 Rank | BT8: Size Score of scored run (TB2) | BU8: TB2 Rank | BV8: Time Score of scored run (TB3) | BW8: TB3 Rank | BX8: Run Time of scored run (TB4) | BY8: TB4 Rank | BZ8: Rank w/ TB | CA8: Rank Diff | CC8: Errors | CO8: =SUM($CO$9:$CO$508) -> 0
X9: =IF(ISBLANK($C9),"",IF($E9=Constants!$B$2,TRUE(),IF($E9=Constants!$B$3,FALSE(),TRUE()))) | Y9: =IF(ISBLANK($C9),"",IF($F9=Constants!$B$2,TRUE(),IF($F9=Constants!$B$3,FALSE(),TRUE()))) | Z9: =IF(ISBLANK($C9),"",IF(ISNUMBER($G9),IF($G9>=0,$G9,""),"")) | AA9: =IF(ISBLANK($C9),"",IF(ISNUMBER($H9),IF($H9>=0,$H9,""),"")) | AB9: =IF(ISBLANK($C9),"",IF(ISNUMBER($I9),IF($I9>=0,$I9,""),"")) | AC9: =IF(ISBLANK($C9),"",IF($J9=Constants!$B$2,TRUE(),IF($J9=Constants!$B$3,FALSE(),TRUE()))) | AD9: =IF(ISBLANK($C9),"",IF($K9=Constants!$B$2,TRUE(),IF($K9=Constants!$B$3,FALSE(),TRUE()))) | AE9: =IF(ISBLANK($C9),"",IF($L9=Constants!$B$2,TRUE(),IF($L9=Constants!$B$3,FALSE(),TRUE()))) | AF9: =IF(ISBLANK($C9),"",IF(ISNUMBER($M9),IF($M9>=0,$M9,""),"")) | AG9: =IF(ISBLANK($C9),"",IF(ISBLANK($N9),0,IF(ISNUMBER($N9),IF(AND($N9>=0,$N9<=Constants!$B$17,$N9=INT($N9)),$N9,""),""))) | AH9: =IF(ISBLANK($C9),"",IF(ISBLANK($O9),0,IF(ISNUMBER($O9),IF($O9>=0,$O9,""),""))) | AI9: =IF(ISBLANK($C9),"",IF($P9=Constants!$B$2,TRUE(),IF($P9=Constants!$B$3,FALSE(),TRUE()))) | AJ9: =IF(ISBLANK($C9),"",IF($Q9=Constants!$B$2,TRUE(),IF($Q9=Constants!$B$3,FALSE(),TRUE()))) | AK9: =IF(ISBLANK($C9),"",IF($R9=Constants!$B$2,TRUE(),IF($R9=Constants!$B$3,FALSE(),TRUE()))) | AL9: =IF(ISBLANK($C9),"",IF(ISNUMBER($S9),IF($S9>=0,$S9,""),"")) | AM9: =IF(ISBLANK($C9),"",IF(ISBLANK($T9),0,IF(ISNUMBER($T9),IF(AND($T9>=0,$T9<=Constants!$B$17,$T9=INT($T9)),$T9,""),""))) | AN9: =IF(ISBLANK($C9),"",IF(ISBLANK($U9),0,IF(ISNUMBER($U9),IF($U9>=0,$U9,""),""))) | AO9: =IF(ISBLANK($C9),"",IF($V9=Constants!$B$2,TRUE(),IF($V9=Constants!$B$3,FALSE(),FALSE()))) | AP9: =IF(ISNUMBER($D$7),IF(AND($D$7>=Constants!$B$19,$D$7<=Constants!$B$20,$D$7=INT($D$7)),$D$7,""),"") | AQ9: =IF(ISBLANK($C9),"",AND($Y9,OR($AS9,$BC9),OR($Z9="",$AA9="",$AB9=""))) | AR9: =IF(ISBLANK($C9),"",IF(OR(NOT($Y9),NOT(OR($AS9,$BC9))),"",IF(ISBLANK($D$7),$AR$5,IF($AP$9="",$AR$6,"")))) | AS9: =IF(ISBLANK($C9),"",COUNTA($J9:$O9)>0) | AT9: =IF(ISBLANK($C9),"",AND($AS9,OR(AND($AF9="",OR($AE9,NOT(ISBLANK($M9)))),$AG9="",$AH9=""))) | AU9: =IF($BL9<>Constants!$B$4,"",IF(NOT($AS9),"",ROUND((Constants!$B$12-$AB9)+(Constants!$B$13-$Z9)+(Constants!$B$14-$AA9),1))) | AV9: =IF($BL9<>Constants!$B$4,"",IF(NOT($AS9),"",IF(NOT($AE9),0,Constants!$B$15*(INT(ROUND(MIN($AF9,$AP$9),6))-INT(ROUND(MAX(0,MIN($AF9,2*$AP$9)-$AP$9),6)))))) | AW9: =IF($BL9<>Constants!$B$4,"",IF(NOT($AS9),"",Constants!$B$16*$AG9)) | AX9: =IF($BL9<>Constants!$B$4,"",IF(NOT($AS9),"",Constants!$B$18*INT(ROUND($AH9,6)))) | AY9: =IF($BL9<>Constants!$B$4,"",IF(NOT($AS9),"",IF(NOT($X9),Constants!$B$11,IF(OR(NOT($AC9),NOT($AD9),ROUND($AB9,1)>Constants!$B$12,ROUND($Z9,1)>Constants!$B$13,ROUND($AA9,1)>Constants!$B$14),Constants!$B$10,Constants!$B$9)))) | AZ9: =IF($BL9<>Constants!$B$4,"",IF(NOT($AS9),"",ROUND($AU9+$AV9+$AW9+$AX9,1))) | BA9: =IF($BL9<>Constants!$B$4,"",IF(NOT($AS9),"",IF(ISNUMBER($AF9),$AF9,0))) | BB9: =IF($BL9<>Constants!$B$4,"",IF(NOT($BC9),"<-",IF(NOT($AS9),"->",IF(OR($BI9<$AY9,AND($BI9=$AY9,OR($BJ9>$AZ9,AND($BJ9=$AZ9,OR($BH9>$AX9,AND($BH9=$AX9,OR($BE9>$AU9,AND($BE9=$AU9,OR($BF9>$AV9,AND($BF9=$AV9,$BK9>$BA9)))))))))),"->","<-")))) | BC9: =IF(ISBLANK($C9),"",COUNTA($P9:$U9)>0) | BD9: =IF(ISBLANK($C9),"",AND($BC9,OR(AND($AL9="",OR($AK9,NOT(ISBLANK($S9)))),$AM9="",$AN9=""))) | BE9: =IF($BL9<>Constants!$B$4,"",IF(NOT($BC9),"",ROUND((Constants!$B$12-$AB9)+(Constants!$B$13-$Z9)+(Constants!$B$14-$AA9),1))) | BF9: =IF($BL9<>Constants!$B$4,"",IF(NOT($BC9),"",IF(NOT($AK9),0,Constants!$B$15*(INT(ROUND(MIN($AL9,$AP$9),6))-INT(ROUND(MAX(0,MIN($AL9,2*$AP$9)-$AP$9),6)))))) | BG9: =IF($BL9<>Constants!$B$4,"",IF(NOT($BC9),"",Constants!$B$16*$AM9)) | BH9: =IF($BL9<>Constants!$B$4,"",IF(NOT($BC9),"",Constants!$B$18*INT(ROUND($AN9,6)))) | BI9: =IF($BL9<>Constants!$B$4,"",IF(NOT($BC9),"",IF(NOT($X9),Constants!$B$11,IF(OR(NOT($AI9),NOT($AJ9),ROUND($AB9,1)>Constants!$B$12,ROUND($Z9,1)>Constants!$B$13,ROUND($AA9,1)>Constants!$B$14),Constants!$B$10,Constants!$B$9)))) | BJ9: =IF($BL9<>Constants!$B$4,"",IF(NOT($BC9),"",ROUND($BE9+$BF9+$BG9+$BH9,1))) | BK9: =IF($BL9<>Constants!$B$4,"",IF(NOT($BC9),"",IF(ISNUMBER($AL9),$AL9,0))) | BL9: =IF(ISBLANK($C9),"",IF($AO9,Constants!$B$7,IF(COUNTA($E9:$V9)=0,Constants!$B$6,IF(NOT($Y9),Constants!$B$5,IF(NOT(OR($AS9,$BC9)),Constants!$B$5,IF(OR($AT9,$BD9,$AQ9,$AR9<>""),Constants!$B$8,Constants!$B$4)))))) | BM9: =IF(ISBLANK($C9),"",IF($BL9<>Constants!$B$4,$BL9,IF($BB9="->",$BI9,$AY9))) | BN9: =IF($BL9<>Constants!$B$4,"",IF($BB9="->",$BJ9,$AZ9)) | BO9: =IF(ISBLANK($C9),"",IF($BL9<>Constants!$B$4,$BL9,$BN9)) | BP9: =IF(ISBLANK($C9),"",IF($BL9<>Constants!$B$4,$BL9,RANK($BO9,$BO$9:$BO$508,0))) | BQ9: =IF(ISBLANK($C9),"",IF($BL9<>Constants!$B$4,$BL9,COUNTIFS($BM$9:$BM$508,"<"&$BM9)+COUNTIFS($BM$9:$BM$508,$BM9,$BP$9:$BP$508,"<"&$BP9)+1)) | BR9: =IF($BL9<>Constants!$B$4,"",IF($BB9="->",$BH9,$AX9)) | BS9: =IF(ISBLANK($C9),"",IF($BL9<>Constants!$B$4,$BL9,IF(ISNUMBER($BR9),RANK($BR9,$BR$9:$BR$508,0),COUNT($BR$9:$BR$508)+1))) | BT9: =IF($BL9<>Constants!$B$4,"",IF($BB9="->",$BE9,$AU9)) | BU9: =IF(ISBLANK($C9),"",IF($BL9<>Constants!$B$4,$BL9,IF(ISNUMBER($BT9),RANK($BT9,$BT$9:$BT$508,0),COUNT($BT$9:$BT$508)+1))) | BV9: =IF($BL9<>Constants!$B$4,"",IF($BB9="->",$BF9,$AV9)) | BW9: =IF(ISBLANK($C9),"",IF($BL9<>Constants!$B$4,$BL9,IF(ISNUMBER($BV9),RANK($BV9,$BV$9:$BV$508,0),COUNT($BV$9:$BV$508)+1))) | BX9: =IF($BL9<>Constants!$B$4,"",IF($BB9="->",$BK9,$BA9)) | BY9: =IF(ISBLANK($C9),"",IF($BL9<>Constants!$B$4,$BL9,IF(ISNUMBER($BX9),RANK($BX9,$BX$9:$BX$508,0),COUNT($BX$9:$BX$508)+1))) | BZ9: =IF(ISBLANK($C9),"",IF($BL9<>Constants!$B$4,$BL9,COUNTIFS($BM$9:$BM$508,"<"&$BM9)+COUNTIFS($BM$9:$BM$508,$BM9,$BP$9:$BP$508,"<"&$BP9)+COUNTIFS($BM$9:$BM$508,$BM9,$BP$9:$BP$508,$BP9,$BS$9:$BS$508,"<"&$BS9)+COUNTIFS($BM$9:$BM$508,$BM9,$BP$9:$BP$508,$BP9,$BS$9:$BS$508,$BS9,$BU$9:$BU$508,"<"&$BU9)+COUNTIFS($BM$9:$BM$508,$BM9,$BP$9:$BP$508,$BP9,$BS$9:$BS$508,$BS9,$BU$9:$BU$508,$BU9,$BW$9:$BW$508,"<"&$BW9)+COUNTIFS($BM$9:$BM$508,$BM9,$BP$9:$BP$508,$BP9,$BS$9:$BS$508,$BS9,$BU$9:$BU$508,$BU9,$BW$9:$BW$508,$BW9,$BY$9:$BY$508,"<"&$BY9)+1)) | CA9: =IF(ISBLANK($C9),"",IF($BL9<>Constants!$B$4,$BL9,$BQ9-$BZ9)) | CC9: =IF(ISBLANK($C9),"",IF($BL9=Constants!$B$8,$AR9,"")) | CD9: =IF(ISBLANK($C9),"",IF($BL9<>Constants!$B$4,"",IF($BB9="->",2,1))) | CE9: =IF(ISBLANK($C9),"",IF($BL9<>Constants!$B$4,"",IF($BB9="->",$BE9,$AU9))) | CF9: =IF(ISBLANK($C9),"",IF($BL9<>Constants!$B$4,"",IF($BB9="->",$BF9,$AV9))) | CG9: =IF(ISBLANK($C9),"",IF($BL9<>Constants!$B$4,"",IF($BB9="->",$BG9,$AW9))) | CH9: =IF(ISBLANK($C9),"",IF($BL9<>Constants!$B$4,"",IF($BB9="->",$BH9,$AX9))) | CI9: =IF(ISBLANK($C9),"",$BO9) | CJ9: =IF(ISBLANK($C9),"",$BM9) | CK9: =IF(ISBLANK($C9),"",$CA9) | CL9: =IF(ISBLANK($C9),"",$BZ9) | CM9: =IF(ISBLANK($C9),"",IF($CL9=Constants!$B$7,COUNTA($C$9:$C$508)+2,IF($CL9=Constants!$B$6,COUNTA($C$9:$C$508)+1,IF($CL9=Constants!$B$5,COUNTA($C$9:$C$508),$CL9)))) | CO9: =IF(OR(ISNUMBER($CL9),$CL9=Constants!$B$7,$CL9=Constants!$B$5,$CL9=Constants!$B$6),1,0) -> 0 | CP9: 1 | CQ9: =IF(ISBLANK($C9),"",IF(ISNUMBER($CM9),$CM9+ROW($B9)/1000,"")) | CR9: =IF(ISNUMBER($CQ9),RANK($CQ9,$CQ$9:$CQ$508,1),"") | CS9: =IF(ISBLANK($C9),"",$B9) | CT9: =IF(ISBLANK($C9),"",$C9) | CU9: =IF(ISBLANK($C9),"",$D9) | CV9: =$CJ9 | CW9: =$CI9 | CX9: =IF(ISBLANK($C9),"",$CL9) | CY9: =IF($CP9>$CO$8,"",VLOOKUP($CP9,$CR$9:$CX$508,7,FALSE())) | CZ9: =IF($CP9>$CO$8,"",VLOOKUP($CP9,$CR$9:$CX$508,2,FALSE())) | DA9: =IF($CP9>$CO$8,"",VLOOKUP($CP9,$CR$9:$CX$508,3,FALSE())) | DB9: =IF($CP9>$CO$8,"",VLOOKUP($CP9,$CR$9:$CX$508,4,FALSE())) | DC9: =IF($CP9>$CO$8,"",VLOOKUP($CP9,$CR$9:$CX$508,5,FALSE())) | DD9: =IF($CP9>$CO$8,"",VLOOKUP($CP9,$CR$9:$CX$508,6,FALSE()))
X10: =IF(ISBLANK($C10),"",IF($E10=Constants!$B$2,TRUE(),IF($E10=Constants!$B$3,FALSE(),TRUE()))) | Y10: =IF(ISBLANK($C10),"",IF($F10=Constants!$B$2,TRUE(),IF($F10=Constants!$B$3,FALSE(),TRUE()))) | Z10: =IF(ISBLANK($C10),"",IF(ISNUMBER($G10),IF($G10>=0,$G10,""),"")) | AA10: =IF(ISBLANK($C10),"",IF(ISNUMBER($H10),IF($H10>=0,$H10,""),"")) | AB10: =IF(ISBLANK($C10),"",IF(ISNUMBER($I10),IF($I10>=0,$I10,""),"")) | AC10: =IF(ISBLANK($C10),"",IF($J10=Constants!$B$2,TRUE(),IF($J10=Constants!$B$3,FALSE(),TRUE()))) | AD10: =IF(ISBLANK($C10),"",IF($K10=Constants!$B$2,TRUE(),IF($K10=Constants!$B$3,FALSE(),TRUE()))) | AE10: =IF(ISBLANK($C10),"",IF($L10=Constants!$B$2,TRUE(),IF($L10=Constants!$B$3,FALSE(),TRUE()))) | AF10: =IF(ISBLANK($C10),"",IF(ISNUMBER($M10),IF($M10>=0,$M10,""),"")) | AG10: =IF(ISBLANK($C10),"",IF(ISBLANK($N10),0,IF(ISNUMBER($N10),IF(AND($N10>=0,$N10<=Constants!$B$17,$N10=INT($N10)),$N10,""),""))) | AH10: =IF(ISBLANK($C10),"",IF(ISBLANK($O10),0,IF(ISNUMBER($O10),IF($O10>=0,$O10,""),""))) | AI10: =IF(ISBLANK($C10),"",IF($P10=Constants!$B$2,TRUE(),IF($P10=Constants!$B$3,FALSE(),TRUE()))) | AJ10: =IF(ISBLANK($C10),"",IF($Q10=Constants!$B$2,TRUE(),IF($Q10=Constants!$B$3,FALSE(),TRUE()))) | AK10: =IF(ISBLANK($C10),"",IF($R10=Constants!$B$2,TRUE(),IF($R10=Constants!$B$3,FALSE(),TRUE()))) | AL10: =IF(ISBLANK($C10),"",IF(ISNUMBER($S10),IF($S10>=0,$S10,""),"")) | AM10: =IF(ISBLANK($C10),"",IF(ISBLANK($T10),0,IF(ISNUMBER($T10),IF(AND($T10>=0,$T10<=Constants!$B$17,$T10=INT($T10)),$T10,""),""))) | AN10: =IF(ISBLANK($C10),"",IF(ISBLANK($U10),0,IF(ISNUMBER($U10),IF($U10>=0,$U10,""),""))) | AO10: =IF(ISBLANK($C10),"",IF($V10=Constants!$B$2,TRUE(),IF($V10=Constants!$B$3,FALSE(),FALSE()))) | AQ10: =IF(ISBLANK($C10),"",AND($Y10,OR($AS10,$BC10),OR($Z10="",$AA10="",$AB10=""))) | AR10: =IF(ISBLANK($C10),"",IF(OR(NOT($Y10),NOT(OR($AS10,$BC10))),"",IF(ISBLANK($D$7),$AR$5,IF($AP$9="",$AR$6,"")))) | AS10: =IF(ISBLANK($C10),"",COUNTA($J10:$O10)>0) | AT10: =IF(ISBLANK($C10),"",AND($AS10,OR(AND($AF10="",OR($AE10,NOT(ISBLANK($M10)))),$AG10="",$AH10=""))) | AU10: =IF($BL10<>Constants!$B$4,"",IF(NOT($AS10),"",ROUND((Constants!$B$12-$AB10)+(Constants!$B$13-$Z10)+(Constants!$B$14-$AA10),1))) | AV10: =IF($BL10<>Constants!$B$4,"",IF(NOT($AS10),"",IF(NOT($AE10),0,Constants!$B$15*(INT(ROUND(MIN($AF10,$AP$9),6))-INT(ROUND(MAX(0,MIN($AF10,2*$AP$9)-$AP$9),6)))))) | AW10: =IF($BL10<>Constants!$B$4,"",IF(NOT($AS10),"",Constants!$B$16*$AG10)) | AX10: =IF($BL10<>Constants!$B$4,"",IF(NOT($AS10),"",Constants!$B$18*INT(ROUND($AH10,6)))) | AY10: =IF($BL10<>Constants!$B$4,"",IF(NOT($AS10),"",IF(NOT($X10),Constants!$B$11,IF(OR(NOT($AC10),NOT($AD10),ROUND($AB10,1)>Constants!$B$12,ROUND($Z10,1)>Constants!$B$13,ROUND($AA10,1)>Constants!$B$14),Constants!$B$10,Constants!$B$9)))) | AZ10: =IF($BL10<>Constants!$B$4,"",IF(NOT($AS10),"",ROUND($AU10+$AV10+$AW10+$AX10,1))) | BA10: =IF($BL10<>Constants!$B$4,"",IF(NOT($AS10),"",IF(ISNUMBER($AF10),$AF10,0))) | BB10: =IF($BL10<>Constants!$B$4,"",IF(NOT($BC10),"<-",IF(NOT($AS10),"->",IF(OR($BI10<$AY10,AND($BI10=$AY10,OR($BJ10>$AZ10,AND($BJ10=$AZ10,OR($BH10>$AX10,AND($BH10=$AX10,OR($BE10>$AU10,AND($BE10=$AU10,OR($BF10>$AV10,AND($BF10=$AV10,$BK10>$BA10)))))))))),"->","<-")))) | BC10: =IF(ISBLANK($C10),"",COUNTA($P10:$U10)>0) | BD10: =IF(ISBLANK($C10),"",AND($BC10,OR(AND($AL10="",OR($AK10,NOT(ISBLANK($S10)))),$AM10="",$AN10=""))) | BE10: =IF($BL10<>Constants!$B$4,"",IF(NOT($BC10),"",ROUND((Constants!$B$12-$AB10)+(Constants!$B$13-$Z10)+(Constants!$B$14-$AA10),1))) | BF10: =IF($BL10<>Constants!$B$4,"",IF(NOT($BC10),"",IF(NOT($AK10),0,Constants!$B$15*(INT(ROUND(MIN($AL10,$AP$9),6))-INT(ROUND(MAX(0,MIN($AL10,2*$AP$9)-$AP$9),6)))))) | BG10: =IF($BL10<>Constants!$B$4,"",IF(NOT($BC10),"",Constants!$B$16*$AM10)) | BH10: =IF($BL10<>Constants!$B$4,"",IF(NOT($BC10),"",Constants!$B$18*INT(ROUND($AN10,6)))) | BI10: =IF($BL10<>Constants!$B$4,"",IF(NOT($BC10),"",IF(NOT($X10),Constants!$B$11,IF(OR(NOT($AI10),NOT($AJ10),ROUND($AB10,1)>Constants!$B$12,ROUND($Z10,1)>Constants!$B$13,ROUND($AA10,1)>Constants!$B$14),Constants!$B$10,Constants!$B$9)))) | BJ10: =IF($BL10<>Constants!$B$4,"",IF(NOT($BC10),"",ROUND($BE10+$BF10+$BG10+$BH10,1))) | BK10: =IF($BL10<>Constants!$B$4,"",IF(NOT($BC10),"",IF(ISNUMBER($AL10),$AL10,0))) | BL10: =IF(ISBLANK($C10),"",IF($AO10,Constants!$B$7,IF(COUNTA($E10:$V10)=0,Constants!$B$6,IF(NOT($Y10),Constants!$B$5,IF(NOT(OR($AS10,$BC10)),Constants!$B$5,IF(OR($AT10,$BD10,$AQ10,$AR10<>""),Constants!$B$8,Constants!$B$4)))))) | BM10: =IF(ISBLANK($C10),"",IF($BL10<>Constants!$B$4,$BL10,IF($BB10="->",$BI10,$AY10))) | BN10: =IF($BL10<>Constants!$B$4,"",IF($BB10="->",$BJ10,$AZ10)) | BO10: =IF(ISBLANK($C10),"",IF($BL10<>Constants!$B$4,$BL10,$BN10)) | BP10: =IF(ISBLANK($C10),"",IF($BL10<>Constants!$B$4,$BL10,RANK($BO10,$BO$9:$BO$508,0))) | BQ10: =IF(ISBLANK($C10),"",IF($BL10<>Constants!$B$4,$BL10,COUNTIFS($BM$9:$BM$508,"<"&$BM10)+COUNTIFS($BM$9:$BM$508,$BM10,$BP$9:$BP$508,"<"&$BP10)+1)) | BR10: =IF($BL10<>Constants!$B$4,"",IF($BB10="->",$BH10,$AX10)) | BS10: =IF(ISBLANK($C10),"",IF($BL10<>Constants!$B$4,$BL10,IF(ISNUMBER($BR10),RANK($BR10,$BR$9:$BR$508,0),COUNT($BR$9:$BR$508)+1))) | BT10: =IF($BL10<>Constants!$B$4,"",IF($BB10="->",$BE10,$AU10)) | BU10: =IF(ISBLANK($C10),"",IF($BL10<>Constants!$B$4,$BL10,IF(ISNUMBER($BT10),RANK($BT10,$BT$9:$BT$508,0),COUNT($BT$9:$BT$508)+1))) | BV10: =IF($BL10<>Constants!$B$4,"",IF($BB10="->",$BF10,$AV10)) | BW10: =IF(ISBLANK($C10),"",IF($BL10<>Constants!$B$4,$BL10,IF(ISNUMBER($BV10),RANK($BV10,$BV$9:$BV$508,0),COUNT($BV$9:$BV$508)+1))) | BX10: =IF($BL10<>Constants!$B$4,"",IF($BB10="->",$BK10,$BA10)) | BY10: =IF(ISBLANK($C10),"",IF($BL10<>Constants!$B$4,$BL10,IF(ISNUMBER($BX10),RANK($BX10,$BX$9:$BX$508,0),COUNT($BX$9:$BX$508)+1))) | BZ10: =IF(ISBLANK($C10),"",IF($BL10<>Constants!$B$4,$BL10,COUNTIFS($BM$9:$BM$508,"<"&$BM10)+COUNTIFS($BM$9:$BM$508,$BM10,$BP$9:$BP$508,"<"&$BP10)+COUNTIFS($BM$9:$BM$508,$BM10,$BP$9:$BP$508,$BP10,$BS$9:$BS$508,"<"&$BS10)+COUNTIFS($BM$9:$BM$508,$BM10,$BP$9:$BP$508,$BP10,$BS$9:$BS$508,$BS10,$BU$9:$BU$508,"<"&$BU10)+COUNTIFS($BM$9:$BM$508,$BM10,$BP$9:$BP$508,$BP10,$BS$9:$BS$508,$BS10,$BU$9:$BU$508,$BU10,$BW$9:$BW$508,"<"&$BW10)+COUNTIFS($BM$9:$BM$508,$BM10,$BP$9:$BP$508,$BP10,$BS$9:$BS$508,$BS10,$BU$9:$BU$508,$BU10,$BW$9:$BW$508,$BW10,$BY$9:$BY$508,"<"&$BY10)+1)) | CA10: =IF(ISBLANK($C10),"",IF($BL10<>Constants!$B$4,$BL10,$BQ10-$BZ10)) | CC10: =IF(ISBLANK($C10),"",IF($BL10=Constants!$B$8,$AR10,"")) | CD10: =IF(ISBLANK($C10),"",IF($BL10<>Constants!$B$4,"",IF($BB10="->",2,1))) | CE10: =IF(ISBLANK($C10),"",IF($BL10<>Constants!$B$4,"",IF($BB10="->",$BE10,$AU10))) | CF10: =IF(ISBLANK($C10),"",IF($BL10<>Constants!$B$4,"",IF($BB10="->",$BF10,$AV10))) | CG10: =IF(ISBLANK($C10),"",IF($BL10<>Constants!$B$4,"",IF($BB10="->",$BG10,$AW10))) | CH10: =IF(ISBLANK($C10),"",IF($BL10<>Constants!$B$4,"",IF($BB10="->",$BH10,$AX10))) | CI10: =IF(ISBLANK($C10),"",$BO10) | CJ10: =IF(ISBLANK($C10),"",$BM10) | CK10: =IF(ISBLANK($C10),"",$CA10) | CL10: =IF(ISBLANK($C10),"",$BZ10) | CM10: =IF(ISBLANK($C10),"",IF($CL10=Constants!$B$7,COUNTA($C$9:$C$508)+2,IF($CL10=Constants!$B$6,COUNTA($C$9:$C$508)+1,IF($CL10=Constants!$B$5,COUNTA($C$9:$C$508),$CL10)))) | CO10: =IF(OR(ISNUMBER($CL10),$CL10=Constants!$B$7,$CL10=Constants!$B$5,$CL10=Constants!$B$6),1,0) -> 0 | CP10: 2 | CQ10: =IF(ISBLANK($C10),"",IF(ISNUMBER($CM10),$CM10+ROW($B10)/1000,"")) | CR10: =IF(ISNUMBER($CQ10),RANK($CQ10,$CQ$9:$CQ$508,1),"") | CS10: =IF(ISBLANK($C10),"",$B10) | CT10: =IF(ISBLANK($C10),"",$C10) | CU10: =IF(ISBLANK($C10),"",$D10) | CV10: =$CJ10 | CW10: =$CI10 | CX10: =IF(ISBLANK($C10),"",$CL10) | CY10: =IF($CP10>$CO$8,"",VLOOKUP($CP10,$CR$9:$CX$508,7,FALSE())) | CZ10: =IF($CP10>$CO$8,"",VLOOKUP($CP10,$CR$9:$CX$508,2,FALSE())) | DA10: =IF($CP10>$CO$8,"",VLOOKUP($CP10,$CR$9:$CX$508,3,FALSE())) | DB10: =IF($CP10>$CO$8,"",VLOOKUP($CP10,$CR$9:$CX$508,4,FALSE())) | DC10: =IF($CP10>$CO$8,"",VLOOKUP($CP10,$CR$9:$CX$508,5,FALSE())) | DD10: =IF($CP10>$CO$8,"",VLOOKUP($CP10,$CR$9:$CX$508,6,FALSE()))
X11: =IF(ISBLANK($C11),"",IF($E11=Constants!$B$2,TRUE(),IF($E11=Constants!$B$3,FALSE(),TRUE()))) | Y11: =IF(ISBLANK($C11),"",IF($F11=Constants!$B$2,TRUE(),IF($F11=Constants!$B$3,FALSE(),TRUE()))) | Z11: =IF(ISBLANK($C11),"",IF(ISNUMBER($G11),IF($G11>=0,$G11,""),"")) | AA11: =IF(ISBLANK($C11),"",IF(ISNUMBER($H11),IF($H11>=0,$H11,""),"")) | AB11: =IF(ISBLANK($C11),"",IF(ISNUMBER($I11),IF($I11>=0,$I11,""),"")) | AC11: =IF(ISBLANK($C11),"",IF($J11=Constants!$B$2,TRUE(),IF($J11=Constants!$B$3,FALSE(),TRUE()))) | AD11: =IF(ISBLANK($C11),"",IF($K11=Constants!$B$2,TRUE(),IF($K11=Constants!$B$3,FALSE(),TRUE()))) | AE11: =IF(ISBLANK($C11),"",IF($L11=Constants!$B$2,TRUE(),IF($L11=Constants!$B$3,FALSE(),TRUE()))) | AF11: =IF(ISBLANK($C11),"",IF(ISNUMBER($M11),IF($M11>=0,$M11,""),"")) | AG11: =IF(ISBLANK($C11),"",IF(ISBLANK($N11),0,IF(ISNUMBER($N11),IF(AND($N11>=0,$N11<=Constants!$B$17,$N11=INT($N11)),$N11,""),""))) | AH11: =IF(ISBLANK($C11),"",IF(ISBLANK($O11),0,IF(ISNUMBER($O11),IF($O11>=0,$O11,""),""))) | AI11: =IF(ISBLANK($C11),"",IF($P11=Constants!$B$2,TRUE(),IF($P11=Constants!$B$3,FALSE(),TRUE()))) | AJ11: =IF(ISBLANK($C11),"",IF($Q11=Constants!$B$2,TRUE(),IF($Q11=Constants!$B$3,FALSE(),TRUE()))) | AK11: =IF(ISBLANK($C11),"",IF($R11=Constants!$B$2,TRUE(),IF($R11=Constants!$B$3,FALSE(),TRUE()))) | AL11: =IF(ISBLANK($C11),"",IF(ISNUMBER($S11),IF($S11>=0,$S11,""),"")) | AM11: =IF(ISBLANK($C11),"",IF(ISBLANK($T11),0,IF(ISNUMBER($T11),IF(AND($T11>=0,$T11<=Constants!$B$17,$T11=INT($T11)),$T11,""),""))) | AN11: =IF(ISBLANK($C11),"",IF(ISBLANK($U11),0,IF(ISNUMBER($U11),IF($U11>=0,$U11,""),""))) | AO11: =IF(ISBLANK($C11),"",IF($V11=Constants!$B$2,TRUE(),IF($V11=Constants!$B$3,FALSE(),FALSE()))) | AQ11: =IF(ISBLANK($C11),"",AND($Y11,OR($AS11,$BC11),OR($Z11="",$AA11="",$AB11=""))) | AR11: =IF(ISBLANK($C11),"",IF(OR(NOT($Y11),NOT(OR($AS11,$BC11))),"",IF(ISBLANK($D$7),$AR$5,IF($AP$9="",$AR$6,"")))) | AS11: =IF(ISBLANK($C11),"",COUNTA($J11:$O11)>0) | AT11: =IF(ISBLANK($C11),"",AND($AS11,OR(AND($AF11="",OR($AE11,NOT(ISBLANK($M11)))),$AG11="",$AH11=""))) | AU11: =IF($BL11<>Constants!$B$4,"",IF(NOT($AS11),"",ROUND((Constants!$B$12-$AB11)+(Constants!$B$13-$Z11)+(Constants!$B$14-$AA11),1))) | AV11: =IF($BL11<>Constants!$B$4,"",IF(NOT($AS11),"",IF(NOT($AE11),0,Constants!$B$15*(INT(ROUND(MIN($AF11,$AP$9),6))-INT(ROUND(MAX(0,MIN($AF11,2*$AP$9)-$AP$9),6)))))) | AW11: =IF($BL11<>Constants!$B$4,"",IF(NOT($AS11),"",Constants!$B$16*$AG11)) | AX11: =IF($BL11<>Constants!$B$4,"",IF(NOT($AS11),"",Constants!$B$18*INT(ROUND($AH11,6)))) | AY11: =IF($BL11<>Constants!$B$4,"",IF(NOT($AS11),"",IF(NOT($X11),Constants!$B$11,IF(OR(NOT($AC11),NOT($AD11),ROUND($AB11,1)>Constants!$B$12,ROUND($Z11,1)>Constants!$B$13,ROUND($AA11,1)>Constants!$B$14),Constants!$B$10,Constants!$B$9)))) | AZ11: =IF($BL11<>Constants!$B$4,"",IF(NOT($AS11),"",ROUND($AU11+$AV11+$AW11+$AX11,1))) | BA11: =IF($BL11<>Constants!$B$4,"",IF(NOT($AS11),"",IF(ISNUMBER($AF11),$AF11,0))) | BB11: =IF($BL11<>Constants!$B$4,"",IF(NOT($BC11),"<-",IF(NOT($AS11),"->",IF(OR($BI11<$AY11,AND($BI11=$AY11,OR($BJ11>$AZ11,AND($BJ11=$AZ11,OR($BH11>$AX11,AND($BH11=$AX11,OR($BE11>$AU11,AND($BE11=$AU11,OR($BF11>$AV11,AND($BF11=$AV11,$BK11>$BA11)))))))))),"->","<-")))) | BC11: =IF(ISBLANK($C11),"",COUNTA($P11:$U11)>0) | BD11: =IF(ISBLANK($C11),"",AND($BC11,OR(AND($AL11="",OR($AK11,NOT(ISBLANK($S11)))),$AM11="",$AN11=""))) | BE11: =IF($BL11<>Constants!$B$4,"",IF(NOT($BC11),"",ROUND((Constants!$B$12-$AB11)+(Constants!$B$13-$Z11)+(Constants!$B$14-$AA11),1))) | BF11: =IF($BL11<>Constants!$B$4,"",IF(NOT($BC11),"",IF(NOT($AK11),0,Constants!$B$15*(INT(ROUND(MIN($AL11,$AP$9),6))-INT(ROUND(MAX(0,MIN($AL11,2*$AP$9)-$AP$9),6)))))) | BG11: =IF($BL11<>Constants!$B$4,"",IF(NOT($BC11),"",Constants!$B$16*$AM11)) | BH11: =IF($BL11<>Constants!$B$4,"",IF(NOT($BC11),"",Constants!$B$18*INT(ROUND($AN11,6)))) | BI11: =IF($BL11<>Constants!$B$4,"",IF(NOT($BC11),"",IF(NOT($X11),Constants!$B$11,IF(OR(NOT($AI11),NOT($AJ11),ROUND($AB11,1)>Constants!$B$12,ROUND($Z11,1)>Constants!$B$13,ROUND($AA11,1)>Constants!$B$14),Constants!$B$10,Constants!$B$9)))) | BJ11: =IF($BL11<>Constants!$B$4,"",IF(NOT($BC11),"",ROUND($BE11+$BF11+$BG11+$BH11,1))) | BK11: =IF($BL11<>Constants!$B$4,"",IF(NOT($BC11),"",IF(ISNUMBER($AL11),$AL11,0))) | BL11: =IF(ISBLANK($C11),"",IF($AO11,Constants!$B$7,IF(COUNTA($E11:$V11)=0,Constants!$B$6,IF(NOT($Y11),Constants!$B$5,IF(NOT(OR($AS11,$BC11)),Constants!$B$5,IF(OR($AT11,$BD11,$AQ11,$AR11<>""),Constants!$B$8,Constants!$B$4)))))) | BM11: =IF(ISBLANK($C11),"",IF($BL11<>Constants!$B$4,$BL11,IF($BB11="->",$BI11,$AY11))) | BN11: =IF($BL11<>Constants!$B$4,"",IF($BB11="->",$BJ11,$AZ11)) | BO11: =IF(ISBLANK($C11),"",IF($BL11<>Constants!$B$4,$BL11,$BN11)) | BP11: =IF(ISBLANK($C11),"",IF($BL11<>Constants!$B$4,$BL11,RANK($BO11,$BO$9:$BO$508,0))) | BQ11: =IF(ISBLANK($C11),"",IF($BL11<>Constants!$B$4,$BL11,COUNTIFS($BM$9:$BM$508,"<"&$BM11)+COUNTIFS($BM$9:$BM$508,$BM11,$BP$9:$BP$508,"<"&$BP11)+1)) | BR11: =IF($BL11<>Constants!$B$4,"",IF($BB11="->",$BH11,$AX11)) | BS11: =IF(ISBLANK($C11),"",IF($BL11<>Constants!$B$4,$BL11,IF(ISNUMBER($BR11),RANK($BR11,$BR$9:$BR$508,0),COUNT($BR$9:$BR$508)+1))) | BT11: =IF($BL11<>Constants!$B$4,"",IF($BB11="->",$BE11,$AU11)) | BU11: =IF(ISBLANK($C11),"",IF($BL11<>Constants!$B$4,$BL11,IF(ISNUMBER($BT11),RANK($BT11,$BT$9:$BT$508,0),COUNT($BT$9:$BT$508)+1))) | BV11: =IF($BL11<>Constants!$B$4,"",IF($BB11="->",$BF11,$AV11)) | BW11: =IF(ISBLANK($C11),"",IF($BL11<>Constants!$B$4,$BL11,IF(ISNUMBER($BV11),RANK($BV11,$BV$9:$BV$508,0),COUNT($BV$9:$BV$508)+1))) | BX11: =IF($BL11<>Constants!$B$4,"",IF($BB11="->",$BK11,$BA11)) | BY11: =IF(ISBLANK($C11),"",IF($BL11<>Constants!$B$4,$BL11,IF(ISNUMBER($BX11),RANK($BX11,$BX$9:$BX$508,0),COUNT($BX$9:$BX$508)+1))) | BZ11: =IF(ISBLANK($C11),"",IF($BL11<>Constants!$B$4,$BL11,COUNTIFS($BM$9:$BM$508,"<"&$BM11)+COUNTIFS($BM$9:$BM$508,$BM11,$BP$9:$BP$508,"<"&$BP11)+COUNTIFS($BM$9:$BM$508,$BM11,$BP$9:$BP$508,$BP11,$BS$9:$BS$508,"<"&$BS11)+COUNTIFS($BM$9:$BM$508,$BM11,$BP$9:$BP$508,$BP11,$BS$9:$BS$508,$BS11,$BU$9:$BU$508,"<"&$BU11)+COUNTIFS($BM$9:$BM$508,$BM11,$BP$9:$BP$508,$BP11,$BS$9:$BS$508,$BS11,$BU$9:$BU$508,$BU11,$BW$9:$BW$508,"<"&$BW11)+COUNTIFS($BM$9:$BM$508,$BM11,$BP$9:$BP$508,$BP11,$BS$9:$BS$508,$BS11,$BU$9:$BU$508,$BU11,$BW$9:$BW$508,$BW11,$BY$9:$BY$508,"<"&$BY11)+1)) | CA11: =IF(ISBLANK($C11),"",IF($BL11<>Constants!$B$4,$BL11,$BQ11-$BZ11)) | CC11: =IF(ISBLANK($C11),"",IF($BL11=Constants!$B$8,$AR11,"")) | CD11: =IF(ISBLANK($C11),"",IF($BL11<>Constants!$B$4,"",IF($BB11="->",2,1))) | CE11: =IF(ISBLANK($C11),"",IF($BL11<>Constants!$B$4,"",IF($BB11="->",$BE11,$AU11))) | CF11: =IF(ISBLANK($C11),"",IF($BL11<>Constants!$B$4,"",IF($BB11="->",$BF11,$AV11))) | CG11: =IF(ISBLANK($C11),"",IF($BL11<>Constants!$B$4,"",IF($BB11="->",$BG11,$AW11))) | CH11: =IF(ISBLANK($C11),"",IF($BL11<>Constants!$B$4,"",IF($BB11="->",$BH11,$AX11))) | CI11: =IF(ISBLANK($C11),"",$BO11) | CJ11: =IF(ISBLANK($C11),"",$BM11) | CK11: =IF(ISBLANK($C11),"",$CA11) | CL11: =IF(ISBLANK($C11),"",$BZ11) | CM11: =IF(ISBLANK($C11),"",IF($CL11=Constants!$B$7,COUNTA($C$9:$C$508)+2,IF($CL11=Constants!$B$6,COUNTA($C$9:$C$508)+1,IF($CL11=Constants!$B$5,COUNTA($C$9:$C$508),$CL11)))) | CO11: =IF(OR(ISNUMBER($CL11),$CL11=Constants!$B$7,$CL11=Constants!$B$5,$CL11=Constants!$B$6),1,0) -> 0 | CP11: 3 | CQ11: =IF(ISBLANK($C11),"",IF(ISNUMBER($CM11),$CM11+ROW($B11)/1000,"")) | CR11: =IF(ISNUMBER($CQ11),RANK($CQ11,$CQ$9:$CQ$508,1),"") | CS11: =IF(ISBLANK($C11),"",$B11) | CT11: =IF(ISBLANK($C11),"",$C11) | CU11: =IF(ISBLANK($C11),"",$D11) | CV11: =$CJ11 | CW11: =$CI11 | CX11: =IF(ISBLANK($C11),"",$CL11) | CY11: =IF($CP11>$CO$8,"",VLOOKUP($CP11,$CR$9:$CX$508,7,FALSE())) | CZ11: =IF($CP11>$CO$8,"",VLOOKUP($CP11,$CR$9:$CX$508,2,FALSE())) | DA11: =IF($CP11>$CO$8,"",VLOOKUP($CP11,$CR$9:$CX$508,3,FALSE())) | DB11: =IF($CP11>$CO$8,"",VLOOKUP($CP11,$CR$9:$CX$508,4,FALSE())) | DC11: =IF($CP11>$CO$8,"",VLOOKUP($CP11,$CR$9:$CX$508,5,FALSE())) | DD11: =IF($CP11>$CO$8,"",VLOOKUP($CP11,$CR$9:$CX$508,6,FALSE()))
X12: =IF(ISBLANK($C12),"",IF($E12=Constants!$B$2,TRUE(),IF($E12=Constants!$B$3,FALSE(),TRUE()))) | Y12: =IF(ISBLANK($C12),"",IF($F12=Constants!$B$2,TRUE(),IF($F12=Constants!$B$3,FALSE(),TRUE()))) | Z12: =IF(ISBLANK($C12),"",IF(ISNUMBER($G12),IF($G12>=0,$G12,""),"")) | AA12: =IF(ISBLANK($C12),"",IF(ISNUMBER($H12),IF($H12>=0,$H12,""),"")) | AB12: =IF(ISBLANK($C12),"",IF(ISNUMBER($I12),IF($I12>=0,$I12,""),"")) | AC12: =IF(ISBLANK($C12),"",IF($J12=Constants!$B$2,TRUE(),IF($J12=Constants!$B$3,FALSE(),TRUE()))) | AD12: =IF(ISBLANK($C12),"",IF($K12=Constants!$B$2,TRUE(),IF($K12=Constants!$B$3,FALSE(),TRUE()))) | AE12: =IF(ISBLANK($C12),"",IF($L12=Constants!$B$2,TRUE(),IF($L12=Constants!$B$3,FALSE(),TRUE()))) | AF12: =IF(ISBLANK($C12),"",IF(ISNUMBER($M12),IF($M12>=0,$M12,""),"")) | AG12: =IF(ISBLANK($C12),"",IF(ISBLANK($N12),0,IF(ISNUMBER($N12),IF(AND($N12>=0,$N12<=Constants!$B$17,$N12=INT($N12)),$N12,""),""))) | AH12: =IF(ISBLANK($C12),"",IF(ISBLANK($O12),0,IF(ISNUMBER($O12),IF($O12>=0,$O12,""),""))) | AI12: =IF(ISBLANK($C12),"",IF($P12=Constants!$B$2,TRUE(),IF($P12=Constants!$B$3,FALSE(),TRUE()))) | AJ12: =IF(ISBLANK($C12),"",IF($Q12=Constants!$B$2,TRUE(),IF($Q12=Constants!$B$3,FALSE(),TRUE()))) | AK12: =IF(ISBLANK($C12),"",IF($R12=Constants!$B$2,TRUE(),IF($R12=Constants!$B$3,FALSE(),TRUE()))) | AL12: =IF(ISBLANK($C12),"",IF(ISNUMBER($S12),IF($S12>=0,$S12,""),"")) | AM12: =IF(ISBLANK($C12),"",IF(ISBLANK($T12),0,IF(ISNUMBER($T12),IF(AND($T12>=0,$T12<=Constants!$B$17,$T12=INT($T12)),$T12,""),""))) | AN12: =IF(ISBLANK($C12),"",IF(ISBLANK($U12),0,IF(ISNUMBER($U12),IF($U12>=0,$U12,""),""))) | AO12: =IF(ISBLANK($C12),"",IF($V12=Constants!$B$2,TRUE(),IF($V12=Constants!$B$3,FALSE(),FALSE()))) | AQ12: =IF(ISBLANK($C12),"",AND($Y12,OR($AS12,$BC12),OR($Z12="",$AA12="",$AB12=""))) | AR12: =IF(ISBLANK($C12),"",IF(OR(NOT($Y12),NOT(OR($AS12,$BC12))),"",IF(ISBLANK($D$7),$AR$5,IF($AP$9="",$AR$6,"")))) | AS12: =IF(ISBLANK($C12),"",COUNTA($J12:$O12)>0) | AT12: =IF(ISBLANK($C12),"",AND($AS12,OR(AND($AF12="",OR($AE12,NOT(ISBLANK($M12)))),$AG12="",$AH12=""))) | AU12: =IF($BL12<>Constants!$B$4,"",IF(NOT($AS12),"",ROUND((Constants!$B$12-$AB12)+(Constants!$B$13-$Z12)+(Constants!$B$14-$AA12),1))) | AV12: =IF($BL12<>Constants!$B$4,"",IF(NOT($AS12),"",IF(NOT($AE12),0,Constants!$B$15*(INT(ROUND(MIN($AF12,$AP$9),6))-INT(ROUND(MAX(0,MIN($AF12,2*$AP$9)-$AP$9),6)))))) | AW12: =IF($BL12<>Constants!$B$4,"",IF(NOT($AS12),"",Constants!$B$16*$AG12)) | AX12: =IF($BL12<>Constants!$B$4,"",IF(NOT($AS12),"",Constants!$B$18*INT(ROUND($AH12,6)))) | AY12: =IF($BL12<>Constants!$B$4,"",IF(NOT($AS12),"",IF(NOT($X12),Constants!$B$11,IF(OR(NOT($AC12),NOT($AD12),ROUND($AB12,1)>Constants!$B$12,ROUND($Z12,1)>Constants!$B$13,ROUND($AA12,1)>Constants!$B$14),Constants!$B$10,Constants!$B$9)))) | AZ12: =IF($BL12<>Constants!$B$4,"",IF(NOT($AS12),"",ROUND($AU12+$AV12+$AW12+$AX12,1))) | BA12: =IF($BL12<>Constants!$B$4,"",IF(NOT($AS12),"",IF(ISNUMBER($AF12),$AF12,0))) | BB12: =IF($BL12<>Constants!$B$4,"",IF(NOT($BC12),"<-",IF(NOT($AS12),"->",IF(OR($BI12<$AY12,AND($BI12=$AY12,OR($BJ12>$AZ12,AND($BJ12=$AZ12,OR($BH12>$AX12,AND($BH12=$AX12,OR($BE12>$AU12,AND($BE12=$AU12,OR($BF12>$AV12,AND($BF12=$AV12,$BK12>$BA12)))))))))),"->","<-")))) | BC12: =IF(ISBLANK($C12),"",COUNTA($P12:$U12)>0) | BD12: =IF(ISBLANK($C12),"",AND($BC12,OR(AND($AL12="",OR($AK12,NOT(ISBLANK($S12)))),$AM12="",$AN12=""))) | BE12: =IF($BL12<>Constants!$B$4,"",IF(NOT($BC12),"",ROUND((Constants!$B$12-$AB12)+(Constants!$B$13-$Z12)+(Constants!$B$14-$AA12),1))) | BF12: =IF($BL12<>Constants!$B$4,"",IF(NOT($BC12),"",IF(NOT($AK12),0,Constants!$B$15*(INT(ROUND(MIN($AL12,$AP$9),6))-INT(ROUND(MAX(0,MIN($AL12,2*$AP$9)-$AP$9),6)))))) | BG12: =IF($BL12<>Constants!$B$4,"",IF(NOT($BC12),"",Constants!$B$16*$AM12)) | BH12: =IF($BL12<>Constants!$B$4,"",IF(NOT($BC12),"",Constants!$B$18*INT(ROUND($AN12,6)))) | BI12: =IF($BL12<>Constants!$B$4,"",IF(NOT($BC12),"",IF(NOT($X12),Constants!$B$11,IF(OR(NOT($AI12),NOT($AJ12),ROUND($AB12,1)>Constants!$B$12,ROUND($Z12,1)>Constants!$B$13,ROUND($AA12,1)>Constants!$B$14),Constants!$B$10,Constants!$B$9)))) | BJ12: =IF($BL12<>Constants!$B$4,"",IF(NOT($BC12),"",ROUND($BE12+$BF12+$BG12+$BH12,1))) | BK12: =IF($BL12<>Constants!$B$4,"",IF(NOT($BC12),"",IF(ISNUMBER($AL12),$AL12,0))) | BL12: =IF(ISBLANK($C12),"",IF($AO12,Constants!$B$7,IF(COUNTA($E12:$V12)=0,Constants!$B$6,IF(NOT($Y12),Constants!$B$5,IF(NOT(OR($AS12,$BC12)),Constants!$B$5,IF(OR($AT12,$BD12,$AQ12,$AR12<>""),Constants!$B$8,Constants!$B$4)))))) | BM12: =IF(ISBLANK($C12),"",IF($BL12<>Constants!$B$4,$BL12,IF($BB12="->",$BI12,$AY12))) | BN12: =IF($BL12<>Constants!$B$4,"",IF($BB12="->",$BJ12,$AZ12)) | BO12: =IF(ISBLANK($C12),"",IF($BL12<>Constants!$B$4,$BL12,$BN12)) | BP12: =IF(ISBLANK($C12),"",IF($BL12<>Constants!$B$4,$BL12,RANK($BO12,$BO$9:$BO$508,0))) | BQ12: =IF(ISBLANK($C12),"",IF($BL12<>Constants!$B$4,$BL12,COUNTIFS($BM$9:$BM$508,"<"&$BM12)+COUNTIFS($BM$9:$BM$508,$BM12,$BP$9:$BP$508,"<"&$BP12)+1)) | BR12: =IF($BL12<>Constants!$B$4,"",IF($BB12="->",$BH12,$AX12)) | BS12: =IF(ISBLANK($C12),"",IF($BL12<>Constants!$B$4,$BL12,IF(ISNUMBER($BR12),RANK($BR12,$BR$9:$BR$508,0),COUNT($BR$9:$BR$508)+1))) | BT12: =IF($BL12<>Constants!$B$4,"",IF($BB12="->",$BE12,$AU12)) | BU12: =IF(ISBLANK($C12),"",IF($BL12<>Constants!$B$4,$BL12,IF(ISNUMBER($BT12),RANK($BT12,$BT$9:$BT$508,0),COUNT($BT$9:$BT$508)+1))) | BV12: =IF($BL12<>Constants!$B$4,"",IF($BB12="->",$BF12,$AV12)) | BW12: =IF(ISBLANK($C12),"",IF($BL12<>Constants!$B$4,$BL12,IF(ISNUMBER($BV12),RANK($BV12,$BV$9:$BV$508,0),COUNT($BV$9:$BV$508)+1))) | BX12: =IF($BL12<>Constants!$B$4,"",IF($BB12="->",$BK12,$BA12)) | BY12: =IF(ISBLANK($C12),"",IF($BL12<>Constants!$B$4,$BL12,IF(ISNUMBER($BX12),RANK($BX12,$BX$9:$BX$508,0),COUNT($BX$9:$BX$508)+1))) | BZ12: =IF(ISBLANK($C12),"",IF($BL12<>Constants!$B$4,$BL12,COUNTIFS($BM$9:$BM$508,"<"&$BM12)+COUNTIFS($BM$9:$BM$508,$BM12,$BP$9:$BP$508,"<"&$BP12)+COUNTIFS($BM$9:$BM$508,$BM12,$BP$9:$BP$508,$BP12,$BS$9:$BS$508,"<"&$BS12)+COUNTIFS($BM$9:$BM$508,$BM12,$BP$9:$BP$508,$BP12,$BS$9:$BS$508,$BS12,$BU$9:$BU$508,"<"&$BU12)+COUNTIFS($BM$9:$BM$508,$BM12,$BP$9:$BP$508,$BP12,$BS$9:$BS$508,$BS12,$BU$9:$BU$508,$BU12,$BW$9:$BW$508,"<"&$BW12)+COUNTIFS($BM$9:$BM$508,$BM12,$BP$9:$BP$508,$BP12,$BS$9:$BS$508,$BS12,$BU$9:$BU$508,$BU12,$BW$9:$BW$508,$BW12,$BY$9:$BY$508,"<"&$BY12)+1)) | CA12: =IF(ISBLANK($C12),"",IF($BL12<>Constants!$B$4,$BL12,$BQ12-$BZ12)) | CC12: =IF(ISBLANK($C12),"",IF($BL12=Constants!$B$8,$AR12,"")) | CD12: =IF(ISBLANK($C12),"",IF($BL12<>Constants!$B$4,"",IF($BB12="->",2,1))) | CE12: =IF(ISBLANK($C12),"",IF($BL12<>Constants!$B$4,"",IF($BB12="->",$BE12,$AU12))) | CF12: =IF(ISBLANK($C12),"",IF($BL12<>Constants!$B$4,"",IF($BB12="->",$BF12,$AV12))) | CG12: =IF(ISBLANK($C12),"",IF($BL12<>Constants!$B$4,"",IF($BB12="->",$BG12,$AW12))) | CH12: =IF(ISBLANK($C12),"",IF($BL12<>Constants!$B$4,"",IF($BB12="->",$BH12,$AX12))) | CI12: =IF(ISBLANK($C12),"",$BO12) | CJ12: =IF(ISBLANK($C12),"",$BM12) | CK12: =IF(ISBLANK($C12),"",$CA12) | CL12: =IF(ISBLANK($C12),"",$BZ12) | CM12: =IF(ISBLANK($C12),"",IF($CL12=Constants!$B$7,COUNTA($C$9:$C$508)+2,IF($CL12=Constants!$B$6,COUNTA($C$9:$C$508)+1,IF($CL12=Constants!$B$5,COUNTA($C$9:$C$508),$CL12)))) | CO12: =IF(OR(ISNUMBER($CL12),$CL12=Constants!$B$7,$CL12=Constants!$B$5,$CL12=Constants!$B$6),1,0) -> 0 | CP12: 4 | CQ12: =IF(ISBLANK($C12),"",IF(ISNUMBER($CM12),$CM12+ROW($B12)/1000,"")) | CR12: =IF(ISNUMBER($CQ12),RANK($CQ12,$CQ$9:$CQ$508,1),"") | CS12: =IF(ISBLANK($C12),"",$B12) | CT12: =IF(ISBLANK($C12),"",$C12) | CU12: =IF(ISBLANK($C12),"",$D12) | CV12: =$CJ12 | CW12: =$CI12 | CX12: =IF(ISBLANK($C12),"",$CL12) | CY12: =IF($CP12>$CO$8,"",VLOOKUP($CP12,$CR$9:$CX$508,7,FALSE())) | CZ12: =IF($CP12>$CO$8,"",VLOOKUP($CP12,$CR$9:$CX$508,2,FALSE())) | DA12: =IF($CP12>$CO$8,"",VLOOKUP($CP12,$CR$9:$CX$508,3,FALSE())) | DB12: =IF($CP12>$CO$8,"",VLOOKUP($CP12,$CR$9:$CX$508,4,FALSE())) | DC12: =IF($CP12>$CO$8,"",VLOOKUP($CP12,$CR$9:$CX$508,5,FALSE())) | DD12: =IF($CP12>$CO$8,"",VLOOKUP($CP12,$CR$9:$CX$508,6,FALSE()))
X13: =IF(ISBLANK($C13),"",IF($E13=Constants!$B$2,TRUE(),IF($E13=Constants!$B$3,FALSE(),TRUE()))) | Y13: =IF(ISBLANK($C13),"",IF($F13=Constants!$B$2,TRUE(),IF($F13=Constants!$B$3,FALSE(),TRUE()))) | Z13: =IF(ISBLANK($C13),"",IF(ISNUMBER($G13),IF($G13>=0,$G13,""),"")) | AA13: =IF(ISBLANK($C13),"",IF(ISNUMBER($H13),IF($H13>=0,$H13,""),"")) | AB13: =IF(ISBLANK($C13),"",IF(ISNUMBER($I13),IF($I13>=0,$I13,""),"")) | AC13: =IF(ISBLANK($C13),"",IF($J13=Constants!$B$2,TRUE(),IF($J13=Constants!$B$3,FALSE(),TRUE()))) | AD13: =IF(ISBLANK($C13),"",IF($K13=Constants!$B$2,TRUE(),IF($K13=Constants!$B$3,FALSE(),TRUE()))) | AE13: =IF(ISBLANK($C13),"",IF($L13=Constants!$B$2,TRUE(),IF($L13=Constants!$B$3,FALSE(),TRUE()))) | AF13: =IF(ISBLANK($C13),"",IF(ISNUMBER($M13),IF($M13>=0,$M13,""),"")) | AG13: =IF(ISBLANK($C13),"",IF(ISBLANK($N13),0,IF(ISNUMBER($N13),IF(AND($N13>=0,$N13<=Constants!$B$17,$N13=INT($N13)),$N13,""),""))) | AH13: =IF(ISBLANK($C13),"",IF(ISBLANK($O13),0,IF(ISNUMBER($O13),IF($O13>=0,$O13,""),""))) | AI13: =IF(ISBLANK($C13),"",IF($P13=Constants!$B$2,TRUE(),IF($P13=Constants!$B$3,FALSE(),TRUE()))) | AJ13: =IF(ISBLANK($C13),"",IF($Q13=Constants!$B$2,TRUE(),IF($Q13=Constants!$B$3,FALSE(),TRUE()))) | AK13: =IF(ISBLANK($C13),"",IF($R13=Constants!$B$2,TRUE(),IF($R13=Constants!$B$3,FALSE(),TRUE()))) | AL13: =IF(ISBLANK($C13),"",IF(ISNUMBER($S13),IF($S13>=0,$S13,""),"")) | AM13: =IF(ISBLANK($C13),"",IF(ISBLANK($T13),0,IF(ISNUMBER($T13),IF(AND($T13>=0,$T13<=Constants!$B$17,$T13=INT($T13)),$T13,""),""))) | AN13: =IF(ISBLANK($C13),"",IF(ISBLANK($U13),0,IF(ISNUMBER($U13),IF($U13>=0,$U13,""),""))) | AO13: =IF(ISBLANK($C13),"",IF($V13=Constants!$B$2,TRUE(),IF($V13=Constants!$B$3,FALSE(),FALSE()))) | AQ13: =IF(ISBLANK($C13),"",AND($Y13,OR($AS13,$BC13),OR($Z13="",$AA13="",$AB13=""))) | AR13: =IF(ISBLANK($C13),"",IF(OR(NOT($Y13),NOT(OR($AS13,$BC13))),"",IF(ISBLANK($D$7),$AR$5,IF($AP$9="",$AR$6,"")))) | AS13: =IF(ISBLANK($C13),"",COUNTA($J13:$O13)>0) | AT13: =IF(ISBLANK($C13),"",AND($AS13,OR(AND($AF13="",OR($AE13,NOT(ISBLANK($M13)))),$AG13="",$AH13=""))) | AU13: =IF($BL13<>Constants!$B$4,"",IF(NOT($AS13),"",ROUND((Constants!$B$12-$AB13)+(Constants!$B$13-$Z13)+(Constants!$B$14-$AA13),1))) | AV13: =IF($BL13<>Constants!$B$4,"",IF(NOT($AS13),"",IF(NOT($AE13),0,Constants!$B$15*(INT(ROUND(MIN($AF13,$AP$9),6))-INT(ROUND(MAX(0,MIN($AF13,2*$AP$9)-$AP$9),6)))))) | AW13: =IF($BL13<>Constants!$B$4,"",IF(NOT($AS13),"",Constants!$B$16*$AG13)) | AX13: =IF($BL13<>Constants!$B$4,"",IF(NOT($AS13),"",Constants!$B$18*INT(ROUND($AH13,6)))) | AY13: =IF($BL13<>Constants!$B$4,"",IF(NOT($AS13),"",IF(NOT($X13),Constants!$B$11,IF(OR(NOT($AC13),NOT($AD13),ROUND($AB13,1)>Constants!$B$12,ROUND($Z13,1)>Constants!$B$13,ROUND($AA13,1)>Constants!$B$14),Constants!$B$10,Constants!$B$9)))) | AZ13: =IF($BL13<>Constants!$B$4,"",IF(NOT($AS13),"",ROUND($AU13+$AV13+$AW13+$AX13,1))) | BA13: =IF($BL13<>Constants!$B$4,"",IF(NOT($AS13),"",IF(ISNUMBER($AF13),$AF13,0))) | BB13: =IF($BL13<>Constants!$B$4,"",IF(NOT($BC13),"<-",IF(NOT($AS13),"->",IF(OR($BI13<$AY13,AND($BI13=$AY13,OR($BJ13>$AZ13,AND($BJ13=$AZ13,OR($BH13>$AX13,AND($BH13=$AX13,OR($BE13>$AU13,AND($BE13=$AU13,OR($BF13>$AV13,AND($BF13=$AV13,$BK13>$BA13)))))))))),"->","<-")))) | BC13: =IF(ISBLANK($C13),"",COUNTA($P13:$U13)>0) | BD13: =IF(ISBLANK($C13),"",AND($BC13,OR(AND($AL13="",OR($AK13,NOT(ISBLANK($S13)))),$AM13="",$AN13=""))) | BE13: =IF($BL13<>Constants!$B$4,"",IF(NOT($BC13),"",ROUND((Constants!$B$12-$AB13)+(Constants!$B$13-$Z13)+(Constants!$B$14-$AA13),1))) | BF13: =IF($BL13<>Constants!$B$4,"",IF(NOT($BC13),"",IF(NOT($AK13),0,Constants!$B$15*(INT(ROUND(MIN($AL13,$AP$9),6))-INT(ROUND(MAX(0,MIN($AL13,2*$AP$9)-$AP$9),6)))))) | BG13: =IF($BL13<>Constants!$B$4,"",IF(NOT($BC13),"",Constants!$B$16*$AM13)) | BH13: =IF($BL13<>Constants!$B$4,"",IF(NOT($BC13),"",Constants!$B$18*INT(ROUND($AN13,6)))) | BI13: =IF($BL13<>Constants!$B$4,"",IF(NOT($BC13),"",IF(NOT($X13),Constants!$B$11,IF(OR(NOT($AI13),NOT($AJ13),ROUND($AB13,1)>Constants!$B$12,ROUND($Z13,1)>Constants!$B$13,ROUND($AA13,1)>Constants!$B$14),Constants!$B$10,Constants!$B$9)))) | BJ13: =IF($BL13<>Constants!$B$4,"",IF(NOT($BC13),"",ROUND($BE13+$BF13+$BG13+$BH13,1))) | BK13: =IF($BL13<>Constants!$B$4,"",IF(NOT($BC13),"",IF(ISNUMBER($AL13),$AL13,0))) | BL13: =IF(ISBLANK($C13),"",IF($AO13,Constants!$B$7,IF(COUNTA($E13:$V13)=0,Constants!$B$6,IF(NOT($Y13),Constants!$B$5,IF(NOT(OR($AS13,$BC13)),Constants!$B$5,IF(OR($AT13,$BD13,$AQ13,$AR13<>""),Constants!$B$8,Constants!$B$4)))))) | BM13: =IF(ISBLANK($C13),"",IF($BL13<>Constants!$B$4,$BL13,IF($BB13="->",$BI13,$AY13))) | BN13: =IF($BL13<>Constants!$B$4,"",IF($BB13="->",$BJ13,$AZ13)) | BO13: =IF(ISBLANK($C13),"",IF($BL13<>Constants!$B$4,$BL13,$BN13)) | BP13: =IF(ISBLANK($C13),"",IF($BL13<>Constants!$B$4,$BL13,RANK($BO13,$BO$9:$BO$508,0))) | BQ13: =IF(ISBLANK($C13),"",IF($BL13<>Constants!$B$4,$BL13,COUNTIFS($BM$9:$BM$508,"<"&$BM13)+COUNTIFS($BM$9:$BM$508,$BM13,$BP$9:$BP$508,"<"&$BP13)+1)) | BR13: =IF($BL13<>Constants!$B$4,"",IF($BB13="->",$BH13,$AX13)) | BS13: =IF(ISBLANK($C13),"",IF($BL13<>Constants!$B$4,$BL13,IF(ISNUMBER($BR13),RANK($BR13,$BR$9:$BR$508,0),COUNT($BR$9:$BR$508)+1))) | BT13: =IF($BL13<>Constants!$B$4,"",IF($BB13="->",$BE13,$AU13)) | BU13: =IF(ISBLANK($C13),"",IF($BL13<>Constants!$B$4,$BL13,IF(ISNUMBER($BT13),RANK($BT13,$BT$9:$BT$508,0),COUNT($BT$9:$BT$508)+1))) | BV13: =IF($BL13<>Constants!$B$4,"",IF($BB13="->",$BF13,$AV13)) | BW13: =IF(ISBLANK($C13),"",IF($BL13<>Constants!$B$4,$BL13,IF(ISNUMBER($BV13),RANK($BV13,$BV$9:$BV$508,0),COUNT($BV$9:$BV$508)+1))) | BX13: =IF($BL13<>Constants!$B$4,"",IF($BB13="->",$BK13,$BA13)) | BY13: =IF(ISBLANK($C13),"",IF($BL13<>Constants!$B$4,$BL13,IF(ISNUMBER($BX13),RANK($BX13,$BX$9:$BX$508,0),COUNT($BX$9:$BX$508)+1))) | BZ13: =IF(ISBLANK($C13),"",IF($BL13<>Constants!$B$4,$BL13,COUNTIFS($BM$9:$BM$508,"<"&$BM13)+COUNTIFS($BM$9:$BM$508,$BM13,$BP$9:$BP$508,"<"&$BP13)+COUNTIFS($BM$9:$BM$508,$BM13,$BP$9:$BP$508,$BP13,$BS$9:$BS$508,"<"&$BS13)+COUNTIFS($BM$9:$BM$508,$BM13,$BP$9:$BP$508,$BP13,$BS$9:$BS$508,$BS13,$BU$9:$BU$508,"<"&$BU13)+COUNTIFS($BM$9:$BM$508,$BM13,$BP$9:$BP$508,$BP13,$BS$9:$BS$508,$BS13,$BU$9:$BU$508,$BU13,$BW$9:$BW$508,"<"&$BW13)+COUNTIFS($BM$9:$BM$508,$BM13,$BP$9:$BP$508,$BP13,$BS$9:$BS$508,$BS13,$BU$9:$BU$508,$BU13,$BW$9:$BW$508,$BW13,$BY$9:$BY$508,"<"&$BY13)+1)) | CA13: =IF(ISBLANK($C13),"",IF($BL13<>Constants!$B$4,$BL13,$BQ13-$BZ13)) | CC13: =IF(ISBLANK($C13),"",IF($BL13=Constants!$B$8,$AR13,"")) | CD13: =IF(ISBLANK($C13),"",IF($BL13<>Constants!$B$4,"",IF($BB13="->",2,1))) | CE13: =IF(ISBLANK($C13),"",IF($BL13<>Constants!$B$4,"",IF($BB13="->",$BE13,$AU13))) | CF13: =IF(ISBLANK($C13),"",IF($BL13<>Constants!$B$4,"",IF($BB13="->",$BF13,$AV13))) | CG13: =IF(ISBLANK($C13),"",IF($BL13<>Constants!$B$4,"",IF($BB13="->",$BG13,$AW13))) | CH13: =IF(ISBLANK($C13),"",IF($BL13<>Constants!$B$4,"",IF($BB13="->",$BH13,$AX13))) | CI13: =IF(ISBLANK($C13),"",$BO13) | CJ13: =IF(ISBLANK($C13),"",$BM13) | CK13: =IF(ISBLANK($C13),"",$CA13) | CL13: =IF(ISBLANK($C13),"",$BZ13) | CM13: =IF(ISBLANK($C13),"",IF($CL13=Constants!$B$7,COUNTA($C$9:$C$508)+2,IF($CL13=Constants!$B$6,COUNTA($C$9:$C$508)+1,IF($CL13=Constants!$B$5,COUNTA($C$9:$C$508),$CL13)))) | CO13: =IF(OR(ISNUMBER($CL13),$CL13=Constants!$B$7,$CL13=Constants!$B$5,$CL13=Constants!$B$6),1,0) -> 0 | CP13: 5 | CQ13: =IF(ISBLANK($C13),"",IF(ISNUMBER($CM13),$CM13+ROW($B13)/1000,"")) | CR13: =IF(ISNUMBER($CQ13),RANK($CQ13,$CQ$9:$CQ$508,1),"") | CS13: =IF(ISBLANK($C13),"",$B13) | CT13: =IF(ISBLANK($C13),"",$C13) | CU13: =IF(ISBLANK($C13),"",$D13) | CV13: =$CJ13 | CW13: =$CI13 | CX13: =IF(ISBLANK($C13),"",$CL13) | CY13: =IF($CP13>$CO$8,"",VLOOKUP($CP13,$CR$9:$CX$508,7,FALSE())) | CZ13: =IF($CP13>$CO$8,"",VLOOKUP($CP13,$CR$9:$CX$508,2,FALSE())) | DA13: =IF($CP13>$CO$8,"",VLOOKUP($CP13,$CR$9:$CX$508,3,FALSE())) | DB13: =IF($CP13>$CO$8,"",VLOOKUP($CP13,$CR$9:$CX$508,4,FALSE())) | DC13: =IF($CP13>$CO$8,"",VLOOKUP($CP13,$CR$9:$CX$508,5,FALSE())) | DD13: =IF($CP13>$CO$8,"",VLOOKUP($CP13,$CR$9:$CX$508,6,FALSE()))
X14: =IF(ISBLANK($C14),"",IF($E14=Constants!$B$2,TRUE(),IF($E14=Constants!$B$3,FALSE(),TRUE()))) | Y14: =IF(ISBLANK($C14),"",IF($F14=Constants!$B$2,TRUE(),IF($F14=Constants!$B$3,FALSE(),TRUE()))) | Z14: =IF(ISBLANK($C14),"",IF(ISNUMBER($G14),IF($G14>=0,$G14,""),"")) | AA14: =IF(ISBLANK($C14),"",IF(ISNUMBER($H14),IF($H14>=0,$H14,""),"")) | AB14: =IF(ISBLANK($C14),"",IF(ISNUMBER($I14),IF($I14>=0,$I14,""),"")) | AC14: =IF(ISBLANK($C14),"",IF($J14=Constants!$B$2,TRUE(),IF($J14=Constants!$B$3,FALSE(),TRUE()))) | AD14: =IF(ISBLANK($C14),"",IF($K14=Constants!$B$2,TRUE(),IF($K14=Constants!$B$3,FALSE(),TRUE()))) | AE14: =IF(ISBLANK($C14),"",IF($L14=Constants!$B$2,TRUE(),IF($L14=Constants!$B$3,FALSE(),TRUE()))) | AF14: =IF(ISBLANK($C14),"",IF(ISNUMBER($M14),IF($M14>=0,$M14,""),"")) | AG14: =IF(ISBLANK($C14),"",IF(ISBLANK($N14),0,IF(ISNUMBER($N14),IF(AND($N14>=0,$N14<=Constants!$B$17,$N14=INT($N14)),$N14,""),""))) | AH14: =IF(ISBLANK($C14),"",IF(ISBLANK($O14),0,IF(ISNUMBER($O14),IF($O14>=0,$O14,""),""))) | AI14: =IF(ISBLANK($C14),"",IF($P14=Constants!$B$2,TRUE(),IF($P14=Constants!$B$3,FALSE(),TRUE()))) | AJ14: =IF(ISBLANK($C14),"",IF($Q14=Constants!$B$2,TRUE(),IF($Q14=Constants!$B$3,FALSE(),TRUE()))) | AK14: =IF(ISBLANK($C14),"",IF($R14=Constants!$B$2,TRUE(),IF($R14=Constants!$B$3,FALSE(),TRUE()))) | AL14: =IF(ISBLANK($C14),"",IF(ISNUMBER($S14),IF($S14>=0,$S14,""),"")) | AM14: =IF(ISBLANK($C14),"",IF(ISBLANK($T14),0,IF(ISNUMBER($T14),IF(AND($T14>=0,$T14<=Constants!$B$17,$T14=INT($T14)),$T14,""),""))) | AN14: =IF(ISBLANK($C14),"",IF(ISBLANK($U14),0,IF(ISNUMBER($U14),IF($U14>=0,$U14,""),""))) | AO14: =IF(ISBLANK($C14),"",IF($V14=Constants!$B$2,TRUE(),IF($V14=Constants!$B$3,FALSE(),FALSE()))) | AQ14: =IF(ISBLANK($C14),"",AND($Y14,OR($AS14,$BC14),OR($Z14="",$AA14="",$AB14=""))) | AR14: =IF(ISBLANK($C14),"",IF(OR(NOT($Y14),NOT(OR($AS14,$BC14))),"",IF(ISBLANK($D$7),$AR$5,IF($AP$9="",$AR$6,"")))) | AS14: =IF(ISBLANK($C14),"",COUNTA($J14:$O14)>0) | AT14: =IF(ISBLANK($C14),"",AND($AS14,OR(AND($AF14="",OR($AE14,NOT(ISBLANK($M14)))),$AG14="",$AH14=""))) | AU14: =IF($BL14<>Constants!$B$4,"",IF(NOT($AS14),"",ROUND((Constants!$B$12-$AB14)+(Constants!$B$13-$Z14)+(Constants!$B$14-$AA14),1))) | AV14: =IF($BL14<>Constants!$B$4,"",IF(NOT($AS14),"",IF(NOT($AE14),0,Constants!$B$15*(INT(ROUND(MIN($AF14,$AP$9),6))-INT(ROUND(MAX(0,MIN($AF14,2*$AP$9)-$AP$9),6)))))) | AW14: =IF($BL14<>Constants!$B$4,"",IF(NOT($AS14),"",Constants!$B$16*$AG14)) | AX14: =IF($BL14<>Constants!$B$4,"",IF(NOT($AS14),"",Constants!$B$18*INT(ROUND($AH14,6)))) | AY14: =IF($BL14<>Constants!$B$4,"",IF(NOT($AS14),"",IF(NOT($X14),Constants!$B$11,IF(OR(NOT($AC14),NOT($AD14),ROUND($AB14,1)>Constants!$B$12,ROUND($Z14,1)>Constants!$B$13,ROUND($AA14,1)>Constants!$B$14),Constants!$B$10,Constants!$B$9)))) | AZ14: =IF($BL14<>Constants!$B$4,"",IF(NOT($AS14),"",ROUND($AU14+$AV14+$AW14+$AX14,1))) | BA14: =IF($BL14<>Constants!$B$4,"",IF(NOT($AS14),"",IF(ISNUMBER($AF14),$AF14,0))) | BB14: =IF($BL14<>Constants!$B$4,"",IF(NOT($BC14),"<-",IF(NOT($AS14),"->",IF(OR($BI14<$AY14,AND($BI14=$AY14,OR($BJ14>$AZ14,AND($BJ14=$AZ14,OR($BH14>$AX14,AND($BH14=$AX14,OR($BE14>$AU14,AND($BE14=$AU14,OR($BF14>$AV14,AND($BF14=$AV14,$BK14>$BA14)))))))))),"->","<-")))) | BC14: =IF(ISBLANK($C14),"",COUNTA($P14:$U14)>0) | BD14: =IF(ISBLANK($C14),"",AND($BC14,OR(AND($AL14="",OR($AK14,NOT(ISBLANK($S14)))),$AM14="",$AN14=""))) | BE14: =IF($BL14<>Constants!$B$4,"",IF(NOT($BC14),"",ROUND((Constants!$B$12-$AB14)+(Constants!$B$13-$Z14)+(Constants!$B$14-$AA14),1))) | BF14: =IF($BL14<>Constants!$B$4,"",IF(NOT($BC14),"",IF(NOT($AK14),0,Constants!$B$15*(INT(ROUND(MIN($AL14,$AP$9),6))-INT(ROUND(MAX(0,MIN($AL14,2*$AP$9)-$AP$9),6)))))) | BG14: =IF($BL14<>Constants!$B$4,"",IF(NOT($BC14),"",Constants!$B$16*$AM14)) | BH14: =IF($BL14<>Constants!$B$4,"",IF(NOT($BC14),"",Constants!$B$18*INT(ROUND($AN14,6)))) | BI14: =IF($BL14<>Constants!$B$4,"",IF(NOT($BC14),"",IF(NOT($X14),Constants!$B$11,IF(OR(NOT($AI14),NOT($AJ14),ROUND($AB14,1)>Constants!$B$12,ROUND($Z14,1)>Constants!$B$13,ROUND($AA14,1)>Constants!$B$14),Constants!$B$10,Constants!$B$9)))) | BJ14: =IF($BL14<>Constants!$B$4,"",IF(NOT($BC14),"",ROUND($BE14+$BF14+$BG14+$BH14,1))) | BK14: =IF($BL14<>Constants!$B$4,"",IF(NOT($BC14),"",IF(ISNUMBER($AL14),$AL14,0))) | BL14: =IF(ISBLANK($C14),"",IF($AO14,Constants!$B$7,IF(COUNTA($E14:$V14)=0,Constants!$B$6,IF(NOT($Y14),Constants!$B$5,IF(NOT(OR($AS14,$BC14)),Constants!$B$5,IF(OR($AT14,$BD14,$AQ14,$AR14<>""),Constants!$B$8,Constants!$B$4)))))) | BM14: =IF(ISBLANK($C14),"",IF($BL14<>Constants!$B$4,$BL14,IF($BB14="->",$BI14,$AY14))) | BN14: =IF($BL14<>Constants!$B$4,"",IF($BB14="->",$BJ14,$AZ14)) | BO14: =IF(ISBLANK($C14),"",IF($BL14<>Constants!$B$4,$BL14,$BN14)) | BP14: =IF(ISBLANK($C14),"",IF($BL14<>Constants!$B$4,$BL14,RANK($BO14,$BO$9:$BO$508,0))) | BQ14: =IF(ISBLANK($C14),"",IF($BL14<>Constants!$B$4,$BL14,COUNTIFS($BM$9:$BM$508,"<"&$BM14)+COUNTIFS($BM$9:$BM$508,$BM14,$BP$9:$BP$508,"<"&$BP14)+1)) | BR14: =IF($BL14<>Constants!$B$4,"",IF($BB14="->",$BH14,$AX14)) | BS14: =IF(ISBLANK($C14),"",IF($BL14<>Constants!$B$4,$BL14,IF(ISNUMBER($BR14),RANK($BR14,$BR$9:$BR$508,0),COUNT($BR$9:$BR$508)+1))) | BT14: =IF($BL14<>Constants!$B$4,"",IF($BB14="->",$BE14,$AU14)) | BU14: =IF(ISBLANK($C14),"",IF($BL14<>Constants!$B$4,$BL14,IF(ISNUMBER($BT14),RANK($BT14,$BT$9:$BT$508,0),COUNT($BT$9:$BT$508)+1))) | BV14: =IF($BL14<>Constants!$B$4,"",IF($BB14="->",$BF14,$AV14)) | BW14: =IF(ISBLANK($C14),"",IF($BL14<>Constants!$B$4,$BL14,IF(ISNUMBER($BV14),RANK($BV14,$BV$9:$BV$508,0),COUNT($BV$9:$BV$508)+1))) | BX14: =IF($BL14<>Constants!$B$4,"",IF($BB14="->",$BK14,$BA14)) | BY14: =IF(ISBLANK($C14),"",IF($BL14<>Constants!$B$4,$BL14,IF(ISNUMBER($BX14),RANK($BX14,$BX$9:$BX$508,0),COUNT($BX$9:$BX$508)+1))) | BZ14: =IF(ISBLANK($C14),"",IF($BL14<>Constants!$B$4,$BL14,COUNTIFS($BM$9:$BM$508,"<"&$BM14)+COUNTIFS($BM$9:$BM$508,$BM14,$BP$9:$BP$508,"<"&$BP14)+COUNTIFS($BM$9:$BM$508,$BM14,$BP$9:$BP$508,$BP14,$BS$9:$BS$508,"<"&$BS14)+COUNTIFS($BM$9:$BM$508,$BM14,$BP$9:$BP$508,$BP14,$BS$9:$BS$508,$BS14,$BU$9:$BU$508,"<"&$BU14)+COUNTIFS($BM$9:$BM$508,$BM14,$BP$9:$BP$508,$BP14,$BS$9:$BS$508,$BS14,$BU$9:$BU$508,$BU14,$BW$9:$BW$508,"<"&$BW14)+COUNTIFS($BM$9:$BM$508,$BM14,$BP$9:$BP$508,$BP14,$BS$9:$BS$508,$BS14,$BU$9:$BU$508,$BU14,$BW$9:$BW$508,$BW14,$BY$9:$BY$508,"<"&$BY14)+1)) | CA14: =IF(ISBLANK($C14),"",IF($BL14<>Constants!$B$4,$BL14,$BQ14-$BZ14)) | CC14: =IF(ISBLANK($C14),"",IF($BL14=Constants!$B$8,$AR14,"")) | CD14: =IF(ISBLANK($C14),"",IF($BL14<>Constants!$B$4,"",IF($BB14="->",2,1))) | CE14: =IF(ISBLANK($C14),"",IF($BL14<>Constants!$B$4,"",IF($BB14="->",$BE14,$AU14))) | CF14: =IF(ISBLANK($C14),"",IF($BL14<>Constants!$B$4,"",IF($BB14="->",$BF14,$AV14))) | CG14: =IF(ISBLANK($C14),"",IF($BL14<>Constants!$B$4,"",IF($BB14="->",$BG14,$AW14))) | CH14: =IF(ISBLANK($C14),"",IF($BL14<>Constants!$B$4,"",IF($BB14="->",$BH14,$AX14))) | CI14: =IF(ISBLANK($C14),"",$BO14) | CJ14: =IF(ISBLANK($C14),"",$BM14) | CK14: =IF(ISBLANK($C14),"",$CA14) | CL14: =IF(ISBLANK($C14),"",$BZ14) | CM14: =IF(ISBLANK($C14),"",IF($CL14=Constants!$B$7,COUNTA($C$9:$C$508)+2,IF($CL14=Constants!$B$6,COUNTA($C$9:$C$508)+1,IF($CL14=Constants!$B$5,COUNTA($C$9:$C$508),$CL14)))) | CO14: =IF(OR(ISNUMBER($CL14),$CL14=Constants!$B$7,$CL14=Constants!$B$5,$CL14=Constants!$B$6),1,0) -> 0 | CP14: 6 | CQ14: =IF(ISBLANK($C14),"",IF(ISNUMBER($CM14),$CM14+ROW($B14)/1000,"")) | CR14: =IF(ISNUMBER($CQ14),RANK($CQ14,$CQ$9:$CQ$508,1),"") | CS14: =IF(ISBLANK($C14),"",$B14) | CT14: =IF(ISBLANK($C14),"",$C14) | CU14: =IF(ISBLANK($C14),"",$D14) | CV14: =$CJ14 | CW14: =$CI14 | CX14: =IF(ISBLANK($C14),"",$CL14) | CY14: =IF($CP14>$CO$8,"",VLOOKUP($CP14,$CR$9:$CX$508,7,FALSE())) | CZ14: =IF($CP14>$CO$8,"",VLOOKUP($CP14,$CR$9:$CX$508,2,FALSE())) | DA14: =IF($CP14>$CO$8,"",VLOOKUP($CP14,$CR$9:$CX$508,3,FALSE())) | DB14: =IF($CP14>$CO$8,"",VLOOKUP($CP14,$CR$9:$CX$508,4,FALSE())) | DC14: =IF($CP14>$CO$8,"",VLOOKUP($CP14,$CR$9:$CX$508,5,FALSE())) | DD14: =IF($CP14>$CO$8,"",VLOOKUP($CP14,$CR$9:$CX$508,6,FALSE()))
X15: =IF(ISBLANK($C15),"",IF($E15=Constants!$B$2,TRUE(),IF($E15=Constants!$B$3,FALSE(),TRUE()))) | Y15: =IF(ISBLANK($C15),"",IF($F15=Constants!$B$2,TRUE(),IF($F15=Constants!$B$3,FALSE(),TRUE()))) | Z15: =IF(ISBLANK($C15),"",IF(ISNUMBER($G15),IF($G15>=0,$G15,""),"")) | AA15: =IF(ISBLANK($C15),"",IF(ISNUMBER($H15),IF($H15>=0,$H15,""),"")) | AB15: =IF(ISBLANK($C15),"",IF(ISNUMBER($I15),IF($I15>=0,$I15,""),"")) | AC15: =IF(ISBLANK($C15),"",IF($J15=Constants!$B$2,TRUE(),IF($J15=Constants!$B$3,FALSE(),TRUE()))) | AD15: =IF(ISBLANK($C15),"",IF($K15=Constants!$B$2,TRUE(),IF($K15=Constants!$B$3,FALSE(),TRUE()))) | AE15: =IF(ISBLANK($C15),"",IF($L15=Constants!$B$2,TRUE(),IF($L15=Constants!$B$3,FALSE(),TRUE()))) | AF15: =IF(ISBLANK($C15),"",IF(ISNUMBER($M15),IF($M15>=0,$M15,""),"")) | AG15: =IF(ISBLANK($C15),"",IF(ISBLANK($N15),0,IF(ISNUMBER($N15),IF(AND($N15>=0,$N15<=Constants!$B$17,$N15=INT($N15)),$N15,""),""))) | AH15: =IF(ISBLANK($C15),"",IF(ISBLANK($O15),0,IF(ISNUMBER($O15),IF($O15>=0,$O15,""),""))) | AI15: =IF(ISBLANK($C15),"",IF($P15=Constants!$B$2,TRUE(),IF($P15=Constants!$B$3,FALSE(),TRUE()))) | AJ15: =IF(ISBLANK($C15),"",IF($Q15=Constants!$B$2,TRUE(),IF($Q15=Constants!$B$3,FALSE(),TRUE()))) | AK15: =IF(ISBLANK($C15),"",IF($R15=Constants!$B$2,TRUE(),IF($R15=Constants!$B$3,FALSE(),TRUE()))) | AL15: =IF(ISBLANK($C15),"",IF(ISNUMBER($S15),IF($S15>=0,$S15,""),"")) | AM15: =IF(ISBLANK($C15),"",IF(ISBLANK($T15),0,IF(ISNUMBER($T15),IF(AND($T15>=0,$T15<=Constants!$B$17,$T15=INT($T15)),$T15,""),""))) | AN15: =IF(ISBLANK($C15),"",IF(ISBLANK($U15),0,IF(ISNUMBER($U15),IF($U15>=0,$U15,""),""))) | AO15: =IF(ISBLANK($C15),"",IF($V15=Constants!$B$2,TRUE(),IF($V15=Constants!$B$3,FALSE(),FALSE()))) | AQ15: =IF(ISBLANK($C15),"",AND($Y15,OR($AS15,$BC15),OR($Z15="",$AA15="",$AB15=""))) | AR15: =IF(ISBLANK($C15),"",IF(OR(NOT($Y15),NOT(OR($AS15,$BC15))),"",IF(ISBLANK($D$7),$AR$5,IF($AP$9="",$AR$6,"")))) | AS15: =IF(ISBLANK($C15),"",COUNTA($J15:$O15)>0) | AT15: =IF(ISBLANK($C15),"",AND($AS15,OR(AND($AF15="",OR($AE15,NOT(ISBLANK($M15)))),$AG15="",$AH15=""))) | AU15: =IF($BL15<>Constants!$B$4,"",IF(NOT($AS15),"",ROUND((Constants!$B$12-$AB15)+(Constants!$B$13-$Z15)+(Constants!$B$14-$AA15),1))) | AV15: =IF($BL15<>Constants!$B$4,"",IF(NOT($AS15),"",IF(NOT($AE15),0,Constants!$B$15*(INT(ROUND(MIN($AF15,$AP$9),6))-INT(ROUND(MAX(0,MIN($AF15,2*$AP$9)-$AP$9),6)))))) | AW15: =IF($BL15<>Constants!$B$4,"",IF(NOT($AS15),"",Constants!$B$16*$AG15)) | AX15: =IF($BL15<>Constants!$B$4,"",IF(NOT($AS15),"",Constants!$B$18*INT(ROUND($AH15,6)))) | AY15: =IF($BL15<>Constants!$B$4,"",IF(NOT($AS15),"",IF(NOT($X15),Constants!$B$11,IF(OR(NOT($AC15),NOT($AD15),ROUND($AB15,1)>Constants!$B$12,ROUND($Z15,1)>Constants!$B$13,ROUND($AA15,1)>Constants!$B$14),Constants!$B$10,Constants!$B$9)))) | AZ15: =IF($BL15<>Constants!$B$4,"",IF(NOT($AS15),"",ROUND($AU15+$AV15+$AW15+$AX15,1))) | BA15: =IF($BL15<>Constants!$B$4,"",IF(NOT($AS15),"",IF(ISNUMBER($AF15),$AF15,0))) | BB15: =IF($BL15<>Constants!$B$4,"",IF(NOT($BC15),"<-",IF(NOT($AS15),"->",IF(OR($BI15<$AY15,AND($BI15=$AY15,OR($BJ15>$AZ15,AND($BJ15=$AZ15,OR($BH15>$AX15,AND($BH15=$AX15,OR($BE15>$AU15,AND($BE15=$AU15,OR($BF15>$AV15,AND($BF15=$AV15,$BK15>$BA15)))))))))),"->","<-")))) | BC15: =IF(ISBLANK($C15),"",COUNTA($P15:$U15)>0) | BD15: =IF(ISBLANK($C15),"",AND($BC15,OR(AND($AL15="",OR($AK15,NOT(ISBLANK($S15)))),$AM15="",$AN15=""))) | BE15: =IF($BL15<>Constants!$B$4,"",IF(NOT($BC15),"",ROUND((Constants!$B$12-$AB15)+(Constants!$B$13-$Z15)+(Constants!$B$14-$AA15),1))) | BF15: =IF($BL15<>Constants!$B$4,"",IF(NOT($BC15),"",IF(NOT($AK15),0,Constants!$B$15*(INT(ROUND(MIN($AL15,$AP$9),6))-INT(ROUND(MAX(0,MIN($AL15,2*$AP$9)-$AP$9),6)))))) | BG15: =IF($BL15<>Constants!$B$4,"",IF(NOT($BC15),"",Constants!$B$16*$AM15)) | BH15: =IF($BL15<>Constants!$B$4,"",IF(NOT($BC15),"",Constants!$B$18*INT(ROUND($AN15,6)))) | BI15: =IF($BL15<>Constants!$B$4,"",IF(NOT($BC15),"",IF(NOT($X15),Constants!$B$11,IF(OR(NOT($AI15),NOT($AJ15),ROUND($AB15,1)>Constants!$B$12,ROUND($Z15,1)>Constants!$B$13,ROUND($AA15,1)>Constants!$B$14),Constants!$B$10,Constants!$B$9)))) | BJ15: =IF($BL15<>Constants!$B$4,"",IF(NOT($BC15),"",ROUND($BE15+$BF15+$BG15+$BH15,1))) | BK15: =IF($BL15<>Constants!$B$4,"",IF(NOT($BC15),"",IF(ISNUMBER($AL15),$AL15,0))) | BL15: =IF(ISBLANK($C15),"",IF($AO15,Constants!$B$7,IF(COUNTA($E15:$V15)=0,Constants!$B$6,IF(NOT($Y15),Constants!$B$5,IF(NOT(OR($AS15,$BC15)),Constants!$B$5,IF(OR($AT15,$BD15,$AQ15,$AR15<>""),Constants!$B$8,Constants!$B$4)))))) | BM15: =IF(ISBLANK($C15),"",IF($BL15<>Constants!$B$4,$BL15,IF($BB15="->",$BI15,$AY15))) | BN15: =IF($BL15<>Constants!$B$4,"",IF($BB15="->",$BJ15,$AZ15)) | BO15: =IF(ISBLANK($C15),"",IF($BL15<>Constants!$B$4,$BL15,$BN15)) | BP15: =IF(ISBLANK($C15),"",IF($BL15<>Constants!$B$4,$BL15,RANK($BO15,$BO$9:$BO$508,0))) | BQ15: =IF(ISBLANK($C15),"",IF($BL15<>Constants!$B$4,$BL15,COUNTIFS($BM$9:$BM$508,"<"&$BM15)+COUNTIFS($BM$9:$BM$508,$BM15,$BP$9:$BP$508,"<"&$BP15)+1)) | BR15: =IF($BL15<>Constants!$B$4,"",IF($BB15="->",$BH15,$AX15)) | BS15: =IF(ISBLANK($C15),"",IF($BL15<>Constants!$B$4,$BL15,IF(ISNUMBER($BR15),RANK($BR15,$BR$9:$BR$508,0),COUNT($BR$9:$BR$508)+1))) | BT15: =IF($BL15<>Constants!$B$4,"",IF($BB15="->",$BE15,$AU15)) | BU15: =IF(ISBLANK($C15),"",IF($BL15<>Constants!$B$4,$BL15,IF(ISNUMBER($BT15),RANK($BT15,$BT$9:$BT$508,0),COUNT($BT$9:$BT$508)+1))) | BV15: =IF($BL15<>Constants!$B$4,"",IF($BB15="->",$BF15,$AV15)) | BW15: =IF(ISBLANK($C15),"",IF($BL15<>Constants!$B$4,$BL15,IF(ISNUMBER($BV15),RANK($BV15,$BV$9:$BV$508,0),COUNT($BV$9:$BV$508)+1))) | BX15: =IF($BL15<>Constants!$B$4,"",IF($BB15="->",$BK15,$BA15)) | BY15: =IF(ISBLANK($C15),"",IF($BL15<>Constants!$B$4,$BL15,IF(ISNUMBER($BX15),RANK($BX15,$BX$9:$BX$508,0),COUNT($BX$9:$BX$508)+1))) | BZ15: =IF(ISBLANK($C15),"",IF($BL15<>Constants!$B$4,$BL15,COUNTIFS($BM$9:$BM$508,"<"&$BM15)+COUNTIFS($BM$9:$BM$508,$BM15,$BP$9:$BP$508,"<"&$BP15)+COUNTIFS($BM$9:$BM$508,$BM15,$BP$9:$BP$508,$BP15,$BS$9:$BS$508,"<"&$BS15)+COUNTIFS($BM$9:$BM$508,$BM15,$BP$9:$BP$508,$BP15,$BS$9:$BS$508,$BS15,$BU$9:$BU$508,"<"&$BU15)+COUNTIFS($BM$9:$BM$508,$BM15,$BP$9:$BP$508,$BP15,$BS$9:$BS$508,$BS15,$BU$9:$BU$508,$BU15,$BW$9:$BW$508,"<"&$BW15)+COUNTIFS($BM$9:$BM$508,$BM15,$BP$9:$BP$508,$BP15,$BS$9:$BS$508,$BS15,$BU$9:$BU$508,$BU15,$BW$9:$BW$508,$BW15,$BY$9:$BY$508,"<"&$BY15)+1)) | CA15: =IF(ISBLANK($C15),"",IF($BL15<>Constants!$B$4,$BL15,$BQ15-$BZ15)) | CC15: =IF(ISBLANK($C15),"",IF($BL15=Constants!$B$8,$AR15,"")) | CD15: =IF(ISBLANK($C15),"",IF($BL15<>Constants!$B$4,"",IF($BB15="->",2,1))) | CE15: =IF(ISBLANK($C15),"",IF($BL15<>Constants!$B$4,"",IF($BB15="->",$BE15,$AU15))) | CF15: =IF(ISBLANK($C15),"",IF($BL15<>Constants!$B$4,"",IF($BB15="->",$BF15,$AV15))) | CG15: =IF(ISBLANK($C15),"",IF($BL15<>Constants!$B$4,"",IF($BB15="->",$BG15,$AW15))) | CH15: =IF(ISBLANK($C15),"",IF($BL15<>Constants!$B$4,"",IF($BB15="->",$BH15,$AX15))) | CI15: =IF(ISBLANK($C15),"",$BO15) | CJ15: =IF(ISBLANK($C15),"",$BM15) | CK15: =IF(ISBLANK($C15),"",$CA15) | CL15: =IF(ISBLANK($C15),"",$BZ15) | CM15: =IF(ISBLANK($C15),"",IF($CL15=Constants!$B$7,COUNTA($C$9:$C$508)+2,IF($CL15=Constants!$B$6,COUNTA($C$9:$C$508)+1,IF($CL15=Constants!$B$5,COUNTA($C$9:$C$508),$CL15)))) | CO15: =IF(OR(ISNUMBER($CL15),$CL15=Constants!$B$7,$CL15=Constants!$B$5,$CL15=Constants!$B$6),1,0) -> 0 | CP15: 7 | CQ15: =IF(ISBLANK($C15),"",IF(ISNUMBER($CM15),$CM15+ROW($B15)/1000,"")) | CR15: =IF(ISNUMBER($CQ15),RANK($CQ15,$CQ$9:$CQ$508,1),"") | CS15: =IF(ISBLANK($C15),"",$B15) | CT15: =IF(ISBLANK($C15),"",$C15) | CU15: =IF(ISBLANK($C15),"",$D15) | CV15: =$CJ15 | CW15: =$CI15 | CX15: =IF(ISBLANK($C15),"",$CL15) | CY15: =IF($CP15>$CO$8,"",VLOOKUP($CP15,$CR$9:$CX$508,7,FALSE())) | CZ15: =IF($CP15>$CO$8,"",VLOOKUP($CP15,$CR$9:$CX$508,2,FALSE())) | DA15: =IF($CP15>$CO$8,"",VLOOKUP($CP15,$CR$9:$CX$508,3,FALSE())) | DB15: =IF($CP15>$CO$8,"",VLOOKUP($CP15,$CR$9:$CX$508,4,FALSE())) | DC15: =IF($CP15>$CO$8,"",VLOOKUP($CP15,$CR$9:$CX$508,5,FALSE())) | DD15: =IF($CP15>$CO$8,"",VLOOKUP($CP15,$CR$9:$CX$508,6,FALSE()))
