Workbook

Sheet Scoring
B2: ='Info.'!B1&" "&'Info.'!B4 -> Electric Vehicle C | F2: Check-In | I2: Event Time | Y2: 21. Nats Only: Event Time Left (If Regional/State-level, leave blank) | AA2: 22. Disqualify (T/F) | AF2: Check In | AJ2: Run 1 | AR2: Run 2 | CR2: Breakdown | DE2: Rank for this team with row() bump | DF2: Rank for this team with same ranks split | DG2: Team Number of this team | DH2: Name of this schoo | DI2: Name of this team | DJ2: Tier for this Team | DK2: Score for this team | DL2: Actual Rank for this team | DM2: Final Rankings
E3: 1. Impounded (T/F) | F3: 2. No batteries containing lithium or lead (T/F) | G3: 3. Conforms to kit modification requirements (T/F) | H3: 4. Bottle Pusher Width (cm) | I3: Run 1 | Q3: Run 2 | AD3: Global: Target Time | AE3: Is valid Target Time? (copied as data validation script for D7) | AF3: =E3 -> 1. Impounded (T/F) | AG3: =F3 -> 2. No batteries containing lithium or lead (T/F) | AH3: =G3 -> 3. Conforms to kit modification requirements (T/F) | AI3: =H3 -> 4. Bottle Pusher Width (cm) | AJ3: =I4 -> 5. Met all const params (T/F) | AK3: =J4 -> 6. Met all comp params (T/F) | AL3: =K4 -> 7. Successful / Failed Run | AM3: =L4 -> 8. Run Time (s) | AN3: =M4 -> 9. Vehicle Distance (cm) | AO3: =N4 -> 10. Bottle past Target Pt & Moving Water Bottle Restrictions Upheld (T/F) | AP3: =O4 -> 11. Bottle Distance (cm) | AQ3: =P4 -> 12. Bottle Bonus (T/F) | ... AY3: =X4 -> 20. Bottle Bonus (T/F) | AZ3: =Y2 -> 21. Nats Only: Event Time Left (If Regional/State-level, leave blank) | BA3: =AA2 -> 22. Disqualify (T/F) | BB3: Run 1 | BL3: Scored Run | BM3: Run 2 | BY3: Final Score | CR3: Scored Run | CS3: Distance Score | CT3: Time Score | CU3: Bonus Score | CV3: Penalty Score | CW3: Score | CX3: Tier | CY3: Tiebreaker | CZ3: Rank | DA3: Points | DM3: Rank | DN3: Team # | DO3: School Name | DP3: Team Name | DQ3: Tier | DR3: Score
B4: ="Event Scoresheet - "&'Info.'!B5&IF('Info.'!B8="T"," The scoresheet has been updated; please download version v"&'Info.'!B7&" from soinc.org/scoresheets.","") -> Event Scoresheet - 2027 | I4: 5. Met all const params (T/F) | J4: 6. Met all comp params (T/F) | K4: 7. Successful / Failed Run | L4: 8. Run Time (s) | M4: 9. Vehicle Distance (cm) | N4: 10. Bottle past Target Pt & Moving Water Bottle Restrictions Upheld (T/F) | O4: 11. Bottle Distance (cm) | P4: 12. Bottle Bonus (T/F) | Q4: 13. Met all const params (T/F) | R4: 14. Met all comp params (T/F) | S4: 15. Successful / Failed Run | T4: 16. Run Time (s) | U4: 17. Vehicle Distance (cm) | V4: 18. Bottle past Target Pt & Moving Water Bottle Restrictions Upheld (T/F) | W4: 19. Bottle Distance (cm) | X4: 20. Bottle Bonus (T/F) | BB4: Run 1 Error | BC4: Distance Score | BD4: Time Score | BE4: Bottle Bonus | BF4: Pusher Bonus | BG4: Run Penalties | BH4: Run Score | BI4: Run 1 TB1: Distance Score | BJ4: Run 1 TB2: Time Score | BK4: Run 1 TB3: Vehicle Distance | BM4: Run 2 Error | BN4: Distance Score | BO4: Time Score | BP4: Bottle Bonus | BQ4: Pusher Bonus | BR4: Run Penalties | BS4: Run Score | BT4: Run 2 TB1: Distance Score | BU4: Run 2 TB2: Time Score | BV4: Run 2 TB3: Vehicle Distance
BW5: ERROR: Set Target Time in cell D7
B6: ="Last Updated: "&TEXT('Info.'!B2, "mm/dd/yyyy")&" (v"&'Info.'!B3&") Direct all questions to scoresheets@soinc.org." -> Last Updated: 09/26/2026 (v0.1.0) Direct all questions to scoresheets@soinc.org. | BW6: ERROR: Target Time in cell D7 must be a number
B7: Target Time (s): | CE7: Tiebreaks
B8: Team # | C8: School Name | D8: Team Name | Y8: Mins | Z8: Seconds | BW8: Target Time Error | BX8: Status | BY8: Tier | BZ8: Scored Run Score | CA8: Final Score Penalties | CB8: Event Time Bonus | CC8: Final Score | CD8: Rank | CE8: Dist Score of scored run (TB1) | CF8: TB1 Rank | CG8: Time Score of scored run (TB2) | CH8: TB2 Rank | CI8: Vehicle Dist of scored run (TB3) | CJ8: TB3 Rank | CK8: Bottle Pusher Opening (TB4) | CL8: TB4 Rank | CM8: Rank w/ TB | CN8: Rank Diff | CQ8: Errors | DC8: =SUM($DC$9:$DC$508) -> 0
AD9: =IF(ISNUMBER($D$7),$D$7,"") | AE9: =IF(ISBLANK($D$7), "", IF(NOT(ISNUMBER($D$7)), FALSE(), IF($D$7<Constants!$B$27, FALSE(), IF($D$7>Constants!$B$28, FALSE(), MOD($D$7,Constants!$B$29)=0 )))) | AF9: =IF(ISBLANK($C9),"",IF(E9=Constants!$B$2,TRUE(),IF(E9=Constants!$B$3,FALSE(),TRUE()))) | AG9: =IF(ISBLANK($C9),"",IF(F9=Constants!$B$2,TRUE(),IF(F9=Constants!$B$3,FALSE(),TRUE()))) | AH9: =IF(ISBLANK($C9),"",IF(G9=Constants!$B$2,TRUE(),IF(G9=Constants!$B$3,FALSE(),TRUE()))) | AI9: =IF(ISBLANK($C9),"",IF(AND(ISNUMBER(H9),H9>=0),H9,Constants!$B$24)) | AJ9: =IF(ISBLANK($C9),"",IF(I9=Constants!$B$2,TRUE(),IF(I9=Constants!$B$3,FALSE(),TRUE()))) | AK9: =IF(ISBLANK($C9),"",IF(J9=Constants!$B$2,TRUE(),IF(J9=Constants!$B$3,FALSE(),TRUE()))) | AL9: =IF(ISBLANK($C9),"",IF(K9=Constants!$B$4,TRUE(),IF(K9=Constants!$B$5,FALSE(),COUNTA(L9:P9)>0))) | AM9: =IF(ISBLANK($C9),"",IF(ISNUMBER(L9),IF(L9>=0,L9,""),"")) | AN9: =IF(ISBLANK($C9),"",IF(ISNUMBER(M9),IF(M9>=0,M9,""),"")) | AO9: =IF(ISBLANK($C9),"",IF(N9=Constants!$B$2,TRUE(),IF(N9=Constants!$B$3,FALSE(),TRUE()))) | AP9: =IF(ISBLANK($C9),"",IF(ISNUMBER(O9),IF(O9>=0,O9,""),"")) | AQ9: =IF(ISBLANK($C9),"",IF(P9=Constants!$B$2,TRUE(),IF(P9=Constants!$B$3,FALSE(),FALSE()))) | AR9: =IF(ISBLANK($C9),"",IF(Q9=Constants!$B$2,TRUE(),IF(Q9=Constants!$B$3,FALSE(),TRUE()))) | AS9: =IF(ISBLANK($C9),"",IF(R9=Constants!$B$2,TRUE(),IF(R9=Constants!$B$3,FALSE(),TRUE()))) | AT9: =IF(ISBLANK($C9),"",IF(S9=Constants!$B$4,TRUE(),IF(S9=Constants!$B$5,FALSE(),COUNTA(T9:X9)>0))) | AU9: =IF(ISBLANK($C9),"",IF(ISNUMBER(T9),IF(T9>=0,T9,""),"")) | AV9: =IF(ISBLANK($C9),"",IF(ISNUMBER(U9),IF(U9>=0,U9,""),"")) | AW9: =IF(ISBLANK($C9),"",IF(V9=Constants!$B$2,TRUE(),IF(V9=Constants!$B$3,FALSE(),TRUE()))) | AX9: =IF(ISBLANK($C9),"",IF(ISNUMBER(W9),IF(W9>=0,W9,""),"")) | AY9: =IF(ISBLANK($C9),"",IF(X9=Constants!$B$2,TRUE(),IF(X9=Constants!$B$3,FALSE(),FALSE()))) | AZ9: =IF(ISBLANK($C9),"",MIN(Constants!$B$25,MAX(0,IF(ISNUMBER(Y9),Y9*60,0)+IF(ISNUMBER(Z9),Z9,0)))) | BA9: =IF(ISBLANK($C9),"",IF(AA9=Constants!$B$2,TRUE(),IF(AA9=Constants!$B$3,FALSE(),FALSE()))) | BB9: =IF(ISBLANK($C9),"",AND($AL9,OR($AM9="",$AN9="",AND($AO9,$AP9="")))) | BC9: =IF($BX9<>Constants!$B$6,"",IF($AL9,Constants!$B$17*$AN9+Constants!$B$18*IF($AO9,$AP9,Constants!$B$19),Constants!$B$20)) | BD9: =IF($BX9<>Constants!$B$6,"",Constants!$B$21*ABS($AD$9-IF($AL9,$AM9,0))) | BE9: =IF($BX9<>Constants!$B$6,"",IF(AND($AL9,$AQ9,$AO9),Constants!$B$22,0)) | BF9: =IF($BX9<>Constants!$B$6,"",IF($AL9,($AI9-Constants!$B$24)*Constants!$B$23,0)) | BG9: =IF($BX9<>Constants!$B$6,"",IF($AK9,0,Constants!$B$12)+IF($AJ9,0,Constants!$B$13)+IF($AH9,0,Constants!$B$14)) | BH9: =IF($BX9<>Constants!$B$6,"",Constants!$B$16+SUM($BC9:$BG9)) | BI9: =IF($BX9<>Constants!$B$6,"",$BC9) | BJ9: =IF($BX9<>Constants!$B$6,"",$BD9) | BK9: =IF($BX9<>Constants!$B$6,"",IF($AL9,$AN9,"")) | BL9: =IF($BX9<>Constants!$B$6,"",IF(OR($BS9<$BH9,AND($BS9=$BH9,OR($BT9<$BI9,AND($BT9=$BI9,OR($BU9<$BJ9,AND($BU9=$BJ9,AND(ISNUMBER($BV9),OR(NOT(ISNUMBER($BK9)),$BV9<$BK9)))))))),"->","<-")) | BM9: =IF(ISBLANK($C9),"",AND($AT9,OR($AU9="",$AV9="",AND($AW9,$AX9="")))) | BN9: =IF($BX9<>Constants!$B$6,"",IF($AT9,Constants!$B$17*$AV9+Constants!$B$18*IF($AW9,$AX9,Constants!$B$19),Constants!$B$20)) | BO9: =IF($BX9<>Constants!$B$6,"",Constants!$B$21*ABS($AD$9-IF($AT9,$AU9,0))) | BP9: =IF($BX9<>Constants!$B$6,"",IF(AND($AT9,$AY9,$AW9),Constants!$B$22,0)) | BQ9: =IF($BX9<>Constants!$B$6,"",IF($AT9,($AI9-Constants!$B$24)*Constants!$B$23,0)) | BR9: =IF($BX9<>Constants!$B$6,"",IF($AS9,0,Constants!$B$12)+IF($AR9,0,Constants!$B$13)+IF($AH9,0,Constants!$B$14)) | BS9: =IF($BX9<>Constants!$B$6,"",Constants!$B$16+SUM($BN9:$BR9)) | BT9: =IF($BX9<>Constants!$B$6,"",$BN9) | BU9: =IF($BX9<>Constants!$B$6,"",$BO9) | BV9: =IF($BX9<>Constants!$B$6,"",IF($AT9,$AV9,"")) | BW9: =IF(ISBLANK($C9),"",IF(ISBLANK($D$7),$BW$5,IF(NOT(ISNUMBER($D$7)),$BW$6,""))) | BX9: =IF(ISBLANK($C9),"",IF($BA9,Constants!$B$9,IF(COUNTA($E9:$AA9)=0,Constants!$B$8,IF(NOT($AG9),Constants!$B$7,IF(OR($BW9<>"",$BB9,$BM9),Constants!$B$10,Constants!$B$6))))) | BY9: =IF(ISBLANK($C9),"",IF($BX9<>Constants!$B$6,$BX9,Constants!$B$11)) | BZ9: =IF($BX9<>Constants!$B$6,"",IF($BL9="->",$BS9,$BH9)) | CA9: =IF($BX9<>Constants!$B$6,"",IF($AF9,0,Constants!$B$15)) | CB9: =IF($BX9<>Constants!$B$6,"",((Constants!$B$25-$AZ9)-Constants!$B$25)/Constants!$B$26) | CC9: =IF(ISBLANK($C9),"",IF($BX9<>Constants!$B$6,$BX9,SUM($BZ9:$CB9))) | CD9: =IF(ISBLANK($C9),"",IF($BX9<>Constants!$B$6,$BX9,RANK($CC9,$CC$9:$CC$508,1))) | CE9: =IF($BX9<>Constants!$B$6,"",IF($BL9="->",$BT9,$BI9)) | CF9: =IF(ISBLANK($C9),"",IF($BX9<>Constants!$B$6,$BX9,IF(ISNUMBER($CE9),RANK($CE9,$CE$9:$CE$508,1),COUNT($CE$9:$CE$508)+1))) | CG9: =IF($BX9<>Constants!$B$6,"",IF($BL9="->",$BU9,$BJ9)) | CH9: =IF(ISBLANK($C9),"",IF($BX9<>Constants!$B$6,$BX9,IF(ISNUMBER($CG9),RANK($CG9,$CG$9:$CG$508,1),COUNT($CG$9:$CG$508)+1))) | CI9: =IF($BX9<>Constants!$B$6,"",IF($BL9="->",$BV9,$BK9)) | CJ9: =IF(ISBLANK($C9),"",IF($BX9<>Constants!$B$6,$BX9,IF(ISNUMBER($CI9),RANK($CI9,$CI$9:$CI$508,1),COUNT($CI$9:$CI$508)+1))) | CK9: =IF($BX9<>Constants!$B$6,"",$AI9) | CL9: =IF(ISBLANK($C9),"",IF($BX9<>Constants!$B$6,$BX9,IF(ISNUMBER($CK9),RANK($CK9,$CK$9:$CK$508,1),COUNT($CK$9:$CK$508)+1))) | CM9: =IF(ISBLANK($C9),"",IF($BX9<>Constants!$B$6,$BX9,COUNTIFS($CD$9:$CD$508,"<"&$CD9)+COUNTIFS($CD$9:$CD$508,$CD9,$CF$9:$CF$508,"<"&$CF9)+COUNTIFS($CD$9:$CD$508,$CD9,$CF$9:$CF$508,$CF9,$CH$9:$CH$508,"<"&$CH9)+COUNTIFS($CD$9:$CD$508,$CD9,$CF$9:$CF$508,$CF9,$CH$9:$CH$508,$CH9,$CJ$9:$CJ$508,"<"&$CJ9)+COUNTIFS($CD$9:$CD$508,$CD9,$CF$9:$CF$508,$CF9,$CH$9:$CH$508,$CH9,$CJ$9:$CJ$508,$CJ9,$CL$9:$CL$508,"<"&$CL9)+1)) | CN9: =IF(ISBLANK($C9),"",IF($BX9<>Constants!$B$6,$BX9,$CD9-$CM9)) | CQ9: =IF(ISBLANK($C9),"",IF($BX9=Constants!$B$10,$BW9,"")) | CR9: =IF(ISBLANK($C9),"",IF($BX9<>Constants!$B$6,"",IF($BL9="->",2,1))) | CS9: =IF(ISBLANK($C9),"",IF($BX9<>Constants!$B$6,"",IF($BL9="->",$BN9,$BC9))) | CT9: =IF(ISBLANK($C9),"",IF($BX9<>Constants!$B$6,"",IF($BL9="->",$BO9,$BD9))) | CU9: =IF(ISBLANK($C9),"",IF($BX9<>Constants!$B$6,"",IF($BL9="->",$BP9+$BQ9,$BE9+$BF9)+$CB9)) | CV9: =IF(ISBLANK($C9),"",IF($BX9<>Constants!$B$6,"",IF($BL9="->",$BR9,$BG9)+$CA9)) | CW9: =IF(ISBLANK($C9),"",IF($BX9<>Constants!$B$6,$BX9,$CC9)) | CX9: =IF(ISBLANK($C9),"",$BY9) | CY9: =IF(ISBLANK($C9),"",$CN9) | CZ9: =IF(ISBLANK($C9),"",$CM9) | DA9: =IF(ISBLANK($C9),"",IFERROR(_xlfn.SWITCH($CZ9,Constants!$B$9,COUNTA($C$9:$C$508)+2,Constants!$B$8,COUNTA($C$9:$C$508)+1,Constants!$B$7,COUNTA($C$9:$C$508)),$CZ9)) | DC9: =IF(OR(ISNUMBER($CZ9),$CZ9=Constants!$B$9,$CZ9=Constants!$B$7,$CZ9=Constants!$B$8),1,0) -> 0 | DD9: 1 | DE9: =IF(ISBLANK($C9),"",IF(ISNUMBER($DA9),$DA9+ROW($B9)/1000,"")) | DF9: =IF(ISNUMBER($DE9),RANK($DE9,$DE$9:$DE$508,1),"") | DG9: =IF(ISBLANK($C9),"",$B9) | DH9: =IF(ISBLANK($C9),"",$C9) | DI9: =IF(ISBLANK($C9),"",$D9) | DJ9: =$CX9 | DK9: =$CW9 | DL9: =IF(ISBLANK($C9),"",$CZ9) | DM9: =IF($DD9>$DC$8,"",VLOOKUP($DD9,$DF$9:$DL$508,7,FALSE())) | DN9: =IF($DD9>$DC$8,"",VLOOKUP($DD9,$DF$9:$DL$508,2,FALSE())) | DO9: =IF($DD9>$DC$8,"",VLOOKUP($DD9,$DF$9:$DL$508,3,FALSE())) | DP9: =IF($DD9>$DC$8,"",VLOOKUP($DD9,$DF$9:$DL$508,4,FALSE())) | DQ9: =IF($DD9>$DC$8,"",VLOOKUP($DD9,$DF$9:$DL$508,5,FALSE())) | DR9: =IF($DD9>$DC$8,"",VLOOKUP($DD9,$DF$9:$DL$508,6,FALSE()))
AF10: =IF(ISBLANK($C10),"",IF(E10=Constants!$B$2,TRUE(),IF(E10=Constants!$B$3,FALSE(),TRUE()))) | AG10: =IF(ISBLANK($C10),"",IF(F10=Constants!$B$2,TRUE(),IF(F10=Constants!$B$3,FALSE(),TRUE()))) | AH10: =IF(ISBLANK($C10),"",IF(G10=Constants!$B$2,TRUE(),IF(G10=Constants!$B$3,FALSE(),TRUE()))) | AI10: =IF(ISBLANK($C10),"",IF(AND(ISNUMBER(H10),H10>=0),H10,Constants!$B$24)) | AJ10: =IF(ISBLANK($C10),"",IF(I10=Constants!$B$2,TRUE(),IF(I10=Constants!$B$3,FALSE(),TRUE()))) | AK10: =IF(ISBLANK($C10),"",IF(J10=Constants!$B$2,TRUE(),IF(J10=Constants!$B$3,FALSE(),TRUE()))) | AL10: =IF(ISBLANK($C10),"",IF(K10=Constants!$B$4,TRUE(),IF(K10=Constants!$B$5,FALSE(),COUNTA(L10:P10)>0))) | AM10: =IF(ISBLANK($C10),"",IF(ISNUMBER(L10),IF(L10>=0,L10,""),"")) | AN10: =IF(ISBLANK($C10),"",IF(ISNUMBER(M10),IF(M10>=0,M10,""),"")) | AO10: =IF(ISBLANK($C10),"",IF(N10=Constants!$B$2,TRUE(),IF(N10=Constants!$B$3,FALSE(),TRUE()))) | AP10: =IF(ISBLANK($C10),"",IF(ISNUMBER(O10),IF(O10>=0,O10,""),"")) | AQ10: =IF(ISBLANK($C10),"",IF(P10=Constants!$B$2,TRUE(),IF(P10=Constants!$B$3,FALSE(),FALSE()))) | AR10: =IF(ISBLANK($C10),"",IF(Q10=Constants!$B$2,TRUE(),IF(Q10=Constants!$B$3,FALSE(),TRUE()))) | AS10: =IF(ISBLANK($C10),"",IF(R10=Constants!$B$2,TRUE(),IF(R10=Constants!$B$3,FALSE(),TRUE()))) | AT10: =IF(ISBLANK($C10),"",IF(S10=Constants!$B$4,TRUE(),IF(S10=Constants!$B$5,FALSE(),COUNTA(T10:X10)>0))) | AU10: =IF(ISBLANK($C10),"",IF(ISNUMBER(T10),IF(T10>=0,T10,""),"")) | AV10: =IF(ISBLANK($C10),"",IF(ISNUMBER(U10),IF(U10>=0,U10,""),"")) | AW10: =IF(ISBLANK($C10),"",IF(V10=Constants!$B$2,TRUE(),IF(V10=Constants!$B$3,FALSE(),TRUE()))) | AX10: =IF(ISBLANK($C10),"",IF(ISNUMBER(W10),IF(W10>=0,W10,""),"")) | AY10: =IF(ISBLANK($C10),"",IF(X10=Constants!$B$2,TRUE(),IF(X10=Constants!$B$3,FALSE(),FALSE()))) | AZ10: =IF(ISBLANK($C10),"",MIN(Constants!$B$25,MAX(0,IF(ISNUMBER(Y10),Y10*60,0)+IF(ISNUMBER(Z10),Z10,0)))) | BA10: =IF(ISBLANK($C10),"",IF(AA10=Constants!$B$2,TRUE(),IF(AA10=Constants!$B$3,FALSE(),FALSE()))) | BB10: =IF(ISBLANK($C10),"",AND($AL10,OR($AM10="",$AN10="",AND($AO10,$AP10="")))) | BC10: =IF($BX10<>Constants!$B$6,"",IF($AL10,Constants!$B$17*$AN10+Constants!$B$18*IF($AO10,$AP10,Constants!$B$19),Constants!$B$20)) | BD10: =IF($BX10<>Constants!$B$6,"",Constants!$B$21*ABS($AD$9-IF($AL10,$AM10,0))) | BE10: =IF($BX10<>Constants!$B$6,"",IF(AND($AL10,$AQ10,$AO10),Constants!$B$22,0)) | BF10: =IF($BX10<>Constants!$B$6,"",IF($AL10,($AI10-Constants!$B$24)*Constants!$B$23,0)) | BG10: =IF($BX10<>Constants!$B$6,"",IF($AK10,0,Constants!$B$12)+IF($AJ10,0,Constants!$B$13)+IF($AH10,0,Constants!$B$14)) | BH10: =IF($BX10<>Constants!$B$6,"",Constants!$B$16+SUM($BC10:$BG10)) | BI10: =IF($BX10<>Constants!$B$6,"",$BC10) | BJ10: =IF($BX10<>Constants!$B$6,"",$BD10) | BK10: =IF($BX10<>Constants!$B$6,"",IF($AL10,$AN10,"")) | BL10: =IF($BX10<>Constants!$B$6,"",IF(OR($BS10<$BH10,AND($BS10=$BH10,OR($BT10<$BI10,AND($BT10=$BI10,OR($BU10<$BJ10,AND($BU10=$BJ10,AND(ISNUMBER($BV10),OR(NOT(ISNUMBER($BK10)),$BV10<$BK10)))))))),"->","<-")) | BM10: =IF(ISBLANK($C10),"",AND($AT10,OR($AU10="",$AV10="",AND($AW10,$AX10="")))) | BN10: =IF($BX10<>Constants!$B$6,"",IF($AT10,Constants!$B$17*$AV10+Constants!$B$18*IF($AW10,$AX10,Constants!$B$19),Constants!$B$20)) | BO10: =IF($BX10<>Constants!$B$6,"",Constants!$B$21*ABS($AD$9-IF($AT10,$AU10,0))) | BP10: =IF($BX10<>Constants!$B$6,"",IF(AND($AT10,$AY10,$AW10),Constants!$B$22,0)) | BQ10: =IF($BX10<>Constants!$B$6,"",IF($AT10,($AI10-Constants!$B$24)*Constants!$B$23,0)) | BR10: =IF($BX10<>Constants!$B$6,"",IF($AS10,0,Constants!$B$12)+IF($AR10,0,Constants!$B$13)+IF($AH10,0,Constants!$B$14)) | BS10: =IF($BX10<>Constants!$B$6,"",Constants!$B$16+SUM($BN10:$BR10)) | BT10: =IF($BX10<>Constants!$B$6,"",$BN10) | BU10: =IF($BX10<>Constants!$B$6,"",$BO10) | BV10: =IF($BX10<>Constants!$B$6,"",IF($AT10,$AV10,"")) | BW10: =IF(ISBLANK($C10),"",IF(ISBLANK($D$7),$BW$5,IF(NOT(ISNUMBER($D$7)),$BW$6,""))) | BX10: =IF(ISBLANK($C10),"",IF($BA10,Constants!$B$9,IF(COUNTA($E10:$AA10)=0,Constants!$B$8,IF(NOT($AG10),Constants!$B$7,IF(OR($BW10<>"",$BB10,$BM10),Constants!$B$10,Constants!$B$6))))) | BY10: =IF(ISBLANK($C10),"",IF($BX10<>Constants!$B$6,$BX10,Constants!$B$11)) | BZ10: =IF($BX10<>Constants!$B$6,"",IF($BL10="->",$BS10,$BH10)) | CA10: =IF($BX10<>Constants!$B$6,"",IF($AF10,0,Constants!$B$15)) | CB10: =IF($BX10<>Constants!$B$6,"",((Constants!$B$25-$AZ10)-Constants!$B$25)/Constants!$B$26) | CC10: =IF(ISBLANK($C10),"",IF($BX10<>Constants!$B$6,$BX10,SUM($BZ10:$CB10))) | CD10: =IF(ISBLANK($C10),"",IF($BX10<>Constants!$B$6,$BX10,RANK($CC10,$CC$9:$CC$508,1))) | CE10: =IF($BX10<>Constants!$B$6,"",IF($BL10="->",$BT10,$BI10)) | CF10: =IF(ISBLANK($C10),"",IF($BX10<>Constants!$B$6,$BX10,IF(ISNUMBER($CE10),RANK($CE10,$CE$9:$CE$508,1),COUNT($CE$9:$CE$508)+1))) | CG10: =IF($BX10<>Constants!$B$6,"",IF($BL10="->",$BU10,$BJ10)) | CH10: =IF(ISBLANK($C10),"",IF($BX10<>Constants!$B$6,$BX10,IF(ISNUMBER($CG10),RANK($CG10,$CG$9:$CG$508,1),COUNT($CG$9:$CG$508)+1))) | CI10: =IF($BX10<>Constants!$B$6,"",IF($BL10="->",$BV10,$BK10)) | CJ10: =IF(ISBLANK($C10),"",IF($BX10<>Constants!$B$6,$BX10,IF(ISNUMBER($CI10),RANK($CI10,$CI$9:$CI$508,1),COUNT($CI$9:$CI$508)+1))) | CK10: =IF($BX10<>Constants!$B$6,"",$AI10) | CL10: =IF(ISBLANK($C10),"",IF($BX10<>Constants!$B$6,$BX10,IF(ISNUMBER($CK10),RANK($CK10,$CK$9:$CK$508,1),COUNT($CK$9:$CK$508)+1))) | CM10: =IF(ISBLANK($C10),"",IF($BX10<>Constants!$B$6,$BX10,COUNTIFS($CD$9:$CD$508,"<"&$CD10)+COUNTIFS($CD$9:$CD$508,$CD10,$CF$9:$CF$508,"<"&$CF10)+COUNTIFS($CD$9:$CD$508,$CD10,$CF$9:$CF$508,$CF10,$CH$9:$CH$508,"<"&$CH10)+COUNTIFS($CD$9:$CD$508,$CD10,$CF$9:$CF$508,$CF10,$CH$9:$CH$508,$CH10,$CJ$9:$CJ$508,"<"&$CJ10)+COUNTIFS($CD$9:$CD$508,$CD10,$CF$9:$CF$508,$CF10,$CH$9:$CH$508,$CH10,$CJ$9:$CJ$508,$CJ10,$CL$9:$CL$508,"<"&$CL10)+1)) | CN10: =IF(ISBLANK($C10),"",IF($BX10<>Constants!$B$6,$BX10,$CD10-$CM10)) | CQ10: =IF(ISBLANK($C10),"",IF($BX10=Constants!$B$10,$BW10,"")) | CR10: =IF(ISBLANK($C10),"",IF($BX10<>Constants!$B$6,"",IF($BL10="->",2,1))) | CS10: =IF(ISBLANK($C10),"",IF($BX10<>Constants!$B$6,"",IF($BL10="->",$BN10,$BC10))) | CT10: =IF(ISBLANK($C10),"",IF($BX10<>Constants!$B$6,"",IF($BL10="->",$BO10,$BD10))) | CU10: =IF(ISBLANK($C10),"",IF($BX10<>Constants!$B$6,"",IF($BL10="->",$BP10+$BQ10,$BE10+$BF10)+$CB10)) | CV10: =IF(ISBLANK($C10),"",IF($BX10<>Constants!$B$6,"",IF($BL10="->",$BR10,$BG10)+$CA10)) | CW10: =IF(ISBLANK($C10),"",IF($BX10<>Constants!$B$6,$BX10,$CC10)) | CX10: =IF(ISBLANK($C10),"",$BY10) | CY10: =IF(ISBLANK($C10),"",$CN10) | CZ10: =IF(ISBLANK($C10),"",$CM10) | DA10: =IF(ISBLANK($C10),"",IFERROR(_xlfn.SWITCH($CZ10,Constants!$B$9,COUNTA($C$9:$C$508)+2,Constants!$B$8,COUNTA($C$9:$C$508)+1,Constants!$B$7,COUNTA($C$9:$C$508)),$CZ10)) | DC10: =IF(OR(ISNUMBER($CZ10),$CZ10=Constants!$B$9,$CZ10=Constants!$B$7,$CZ10=Constants!$B$8),1,0) -> 0 | DD10: 2 | DE10: =IF(ISBLANK($C10),"",IF(ISNUMBER($DA10),$DA10+ROW($B10)/1000,"")) | DF10: =IF(ISNUMBER($DE10),RANK($DE10,$DE$9:$DE$508,1),"") | DG10: =IF(ISBLANK($C10),"",$B10) | DH10: =IF(ISBLANK($C10),"",$C10) | DI10: =IF(ISBLANK($C10),"",$D10) | DJ10: =$CX10 | DK10: =$CW10 | DL10: =IF(ISBLANK($C10),"",$CZ10) | DM10: =IF($DD10>$DC$8,"",VLOOKUP($DD10,$DF$9:$DL$508,7,FALSE())) | DN10: =IF($DD10>$DC$8,"",VLOOKUP($DD10,$DF$9:$DL$508,2,FALSE())) | DO10: =IF($DD10>$DC$8,"",VLOOKUP($DD10,$DF$9:$DL$508,3,FALSE())) | DP10: =IF($DD10>$DC$8,"",VLOOKUP($DD10,$DF$9:$DL$508,4,FALSE())) | DQ10: =IF($DD10>$DC$8,"",VLOOKUP($DD10,$DF$9:$DL$508,5,FALSE())) | DR10: =IF($DD10>$DC$8,"",VLOOKUP($DD10,$DF$9:$DL$508,6,FALSE()))
AF11: =IF(ISBLANK($C11),"",IF(E11=Constants!$B$2,TRUE(),IF(E11=Constants!$B$3,FALSE(),TRUE()))) | AG11: =IF(ISBLANK($C11),"",IF(F11=Constants!$B$2,TRUE(),IF(F11=Constants!$B$3,FALSE(),TRUE()))) | AH11: =IF(ISBLANK($C11),"",IF(G11=Constants!$B$2,TRUE(),IF(G11=Constants!$B$3,FALSE(),TRUE()))) | AI11: =IF(ISBLANK($C11),"",IF(AND(ISNUMBER(H11),H11>=0),H11,Constants!$B$24)) | AJ11: =IF(ISBLANK($C11),"",IF(I11=Constants!$B$2,TRUE(),IF(I11=Constants!$B$3,FALSE(),TRUE()))) | AK11: =IF(ISBLANK($C11),"",IF(J11=Constants!$B$2,TRUE(),IF(J11=Constants!$B$3,FALSE(),TRUE()))) | AL11: =IF(ISBLANK($C11),"",IF(K11=Constants!$B$4,TRUE(),IF(K11=Constants!$B$5,FALSE(),COUNTA(L11:P11)>0))) | AM11: =IF(ISBLANK($C11),"",IF(ISNUMBER(L11),IF(L11>=0,L11,""),"")) | AN11: =IF(ISBLANK($C11),"",IF(ISNUMBER(M11),IF(M11>=0,M11,""),"")) | AO11: =IF(ISBLANK($C11),"",IF(N11=Constants!$B$2,TRUE(),IF(N11=Constants!$B$3,FALSE(),TRUE()))) | AP11: =IF(ISBLANK($C11),"",IF(ISNUMBER(O11),IF(O11>=0,O11,""),"")) | AQ11: =IF(ISBLANK($C11),"",IF(P11=Constants!$B$2,TRUE(),IF(P11=Constants!$B$3,FALSE(),FALSE()))) | AR11: =IF(ISBLANK($C11),"",IF(Q11=Constants!$B$2,TRUE(),IF(Q11=Constants!$B$3,FALSE(),TRUE()))) | AS11: =IF(ISBLANK($C11),"",IF(R11=Constants!$B$2,TRUE(),IF(R11=Constants!$B$3,FALSE(),TRUE()))) | AT11: =IF(ISBLANK($C11),"",IF(S11=Constants!$B$4,TRUE(),IF(S11=Constants!$B$5,FALSE(),COUNTA(T11:X11)>0))) | AU11: =IF(ISBLANK($C11),"",IF(ISNUMBER(T11),IF(T11>=0,T11,""),"")) | AV11: =IF(ISBLANK($C11),"",IF(ISNUMBER(U11),IF(U11>=0,U11,""),"")) | AW11: =IF(ISBLANK($C11),"",IF(V11=Constants!$B$2,TRUE(),IF(V11=Constants!$B$3,FALSE(),TRUE()))) | AX11: =IF(ISBLANK($C11),"",IF(ISNUMBER(W11),IF(W11>=0,W11,""),"")) | AY11: =IF(ISBLANK($C11),"",IF(X11=Constants!$B$2,TRUE(),IF(X11=Constants!$B$3,FALSE(),FALSE()))) | AZ11: =IF(ISBLANK($C11),"",MIN(Constants!$B$25,MAX(0,IF(ISNUMBER(Y11),Y11*60,0)+IF(ISNUMBER(Z11),Z11,0)))) | BA11: =IF(ISBLANK($C11),"",IF(AA11=Constants!$B$2,TRUE(),IF(AA11=Constants!$B$3,FALSE(),FALSE()))) | BB11: =IF(ISBLANK($C11),"",AND($AL11,OR($AM11="",$AN11="",AND($AO11,$AP11="")))) | BC11: =IF($BX11<>Constants!$B$6,"",IF($AL11,Constants!$B$17*$AN11+Constants!$B$18*IF($AO11,$AP11,Constants!$B$19),Constants!$B$20)) | BD11: =IF($BX11<>Constants!$B$6,"",Constants!$B$21*ABS($AD$9-IF($AL11,$AM11,0))) | BE11: =IF($BX11<>Constants!$B$6,"",IF(AND($AL11,$AQ11,$AO11),Constants!$B$22,0)) | BF11: =IF($BX11<>Constants!$B$6,"",IF($AL11,($AI11-Constants!$B$24)*Constants!$B$23,0)) | BG11: =IF($BX11<>Constants!$B$6,"",IF($AK11,0,Constants!$B$12)+IF($AJ11,0,Constants!$B$13)+IF($AH11,0,Constants!$B$14)) | BH11: =IF($BX11<>Constants!$B$6,"",Constants!$B$16+SUM($BC11:$BG11)) | BI11: =IF($BX11<>Constants!$B$6,"",$BC11) | BJ11: =IF($BX11<>Constants!$B$6,"",$BD11) | BK11: =IF($BX11<>Constants!$B$6,"",IF($AL11,$AN11,"")) | BL11: =IF($BX11<>Constants!$B$6,"",IF(OR($BS11<$BH11,AND($BS11=$BH11,OR($BT11<$BI11,AND($BT11=$BI11,OR($BU11<$BJ11,AND($BU11=$BJ11,AND(ISNUMBER($BV11),OR(NOT(ISNUMBER($BK11)),$BV11<$BK11)))))))),"->","<-")) | BM11: =IF(ISBLANK($C11),"",AND($AT11,OR($AU11="",$AV11="",AND($AW11,$AX11="")))) | BN11: =IF($BX11<>Constants!$B$6,"",IF($AT11,Constants!$B$17*$AV11+Constants!$B$18*IF($AW11,$AX11,Constants!$B$19),Constants!$B$20)) | BO11: =IF($BX11<>Constants!$B$6,"",Constants!$B$21*ABS($AD$9-IF($AT11,$AU11,0))) | BP11: =IF($BX11<>Constants!$B$6,"",IF(AND($AT11,$AY11,$AW11),Constants!$B$22,0)) | BQ11: =IF($BX11<>Constants!$B$6,"",IF($AT11,($AI11-Constants!$B$24)*Constants!$B$23,0)) | BR11: =IF($BX11<>Constants!$B$6,"",IF($AS11,0,Constants!$B$12)+IF($AR11,0,Constants!$B$13)+IF($AH11,0,Constants!$B$14)) | BS11: =IF($BX11<>Constants!$B$6,"",Constants!$B$16+SUM($BN11:$BR11)) | BT11: =IF($BX11<>Constants!$B$6,"",$BN11) | BU11: =IF($BX11<>Constants!$B$6,"",$BO11) | BV11: =IF($BX11<>Constants!$B$6,"",IF($AT11,$AV11,"")) | BW11: =IF(ISBLANK($C11),"",IF(ISBLANK($D$7),$BW$5,IF(NOT(ISNUMBER($D$7)),$BW$6,""))) | BX11: =IF(ISBLANK($C11),"",IF($BA11,Constants!$B$9,IF(COUNTA($E11:$AA11)=0,Constants!$B$8,IF(NOT($AG11),Constants!$B$7,IF(OR($BW11<>"",$BB11,$BM11),Constants!$B$10,Constants!$B$6))))) | BY11: =IF(ISBLANK($C11),"",IF($BX11<>Constants!$B$6,$BX11,Constants!$B$11)) | BZ11: =IF($BX11<>Constants!$B$6,"",IF($BL11="->",$BS11,$BH11)) | CA11: =IF($BX11<>Constants!$B$6,"",IF($AF11,0,Constants!$B$15)) | CB11: =IF($BX11<>Constants!$B$6,"",((Constants!$B$25-$AZ11)-Constants!$B$25)/Constants!$B$26) | CC11: =IF(ISBLANK($C11),"",IF($BX11<>Constants!$B$6,$BX11,SUM($BZ11:$CB11))) | CD11: =IF(ISBLANK($C11),"",IF($BX11<>Constants!$B$6,$BX11,RANK($CC11,$CC$9:$CC$508,1))) | CE11: =IF($BX11<>Constants!$B$6,"",IF($BL11="->",$BT11,$BI11)) | CF11: =IF(ISBLANK($C11),"",IF($BX11<>Constants!$B$6,$BX11,IF(ISNUMBER($CE11),RANK($CE11,$CE$9:$CE$508,1),COUNT($CE$9:$CE$508)+1))) | CG11: =IF($BX11<>Constants!$B$6,"",IF($BL11="->",$BU11,$BJ11)) | CH11: =IF(ISBLANK($C11),"",IF($BX11<>Constants!$B$6,$BX11,IF(ISNUMBER($CG11),RANK($CG11,$CG$9:$CG$508,1),COUNT($CG$9:$CG$508)+1))) | CI11: =IF($BX11<>Constants!$B$6,"",IF($BL11="->",$BV11,$BK11)) | CJ11: =IF(ISBLANK($C11),"",IF($BX11<>Constants!$B$6,$BX11,IF(ISNUMBER($CI11),RANK($CI11,$CI$9:$CI$508,1),COUNT($CI$9:$CI$508)+1))) | CK11: =IF($BX11<>Constants!$B$6,"",$AI11) | CL11: =IF(ISBLANK($C11),"",IF($BX11<>Constants!$B$6,$BX11,IF(ISNUMBER($CK11),RANK($CK11,$CK$9:$CK$508,1),COUNT($CK$9:$CK$508)+1))) | CM11: =IF(ISBLANK($C11),"",IF($BX11<>Constants!$B$6,$BX11,COUNTIFS($CD$9:$CD$508,"<"&$CD11)+COUNTIFS($CD$9:$CD$508,$CD11,$CF$9:$CF$508,"<"&$CF11)+COUNTIFS($CD$9:$CD$508,$CD11,$CF$9:$CF$508,$CF11,$CH$9:$CH$508,"<"&$CH11)+COUNTIFS($CD$9:$CD$508,$CD11,$CF$9:$CF$508,$CF11,$CH$9:$CH$508,$CH11,$CJ$9:$CJ$508,"<"&$CJ11)+COUNTIFS($CD$9:$CD$508,$CD11,$CF$9:$CF$508,$CF11,$CH$9:$CH$508,$CH11,$CJ$9:$CJ$508,$CJ11,$CL$9:$CL$508,"<"&$CL11)+1)) | CN11: =IF(ISBLANK($C11),"",IF($BX11<>Constants!$B$6,$BX11,$CD11-$CM11)) | CQ11: =IF(ISBLANK($C11),"",IF($BX11=Constants!$B$10,$BW11,"")) | CR11: =IF(ISBLANK($C11),"",IF($BX11<>Constants!$B$6,"",IF($BL11="->",2,1))) | CS11: =IF(ISBLANK($C11),"",IF($BX11<>Constants!$B$6,"",IF($BL11="->",$BN11,$BC11))) | CT11: =IF(ISBLANK($C11),"",IF($BX11<>Constants!$B$6,"",IF($BL11="->",$BO11,$BD11))) | CU11: =IF(ISBLANK($C11),"",IF($BX11<>Constants!$B$6,"",IF($BL11="->",$BP11+$BQ11,$BE11+$BF11)+$CB11)) | CV11: =IF(ISBLANK($C11),"",IF($BX11<>Constants!$B$6,"",IF($BL11="->",$BR11,$BG11)+$CA11)) | CW11: =IF(ISBLANK($C11),"",IF($BX11<>Constants!$B$6,$BX11,$CC11)) | CX11: =IF(ISBLANK($C11),"",$BY11) | CY11: =IF(ISBLANK($C11),"",$CN11) | CZ11: =IF(ISBLANK($C11),"",$CM11) | DA11: =IF(ISBLANK($C11),"",IFERROR(_xlfn.SWITCH($CZ11,Constants!$B$9,COUNTA($C$9:$C$508)+2,Constants!$B$8,COUNTA($C$9:$C$508)+1,Constants!$B$7,COUNTA($C$9:$C$508)),$CZ11)) | DC11: =IF(OR(ISNUMBER($CZ11),$CZ11=Constants!$B$9,$CZ11=Constants!$B$7,$CZ11=Constants!$B$8),1,0) -> 0 | DD11: 3 | DE11: =IF(ISBLANK($C11),"",IF(ISNUMBER($DA11),$DA11+ROW($B11)/1000,"")) | DF11: =IF(ISNUMBER($DE11),RANK($DE11,$DE$9:$DE$508,1),"") | DG11: =IF(ISBLANK($C11),"",$B11) | DH11: =IF(ISBLANK($C11),"",$C11) | DI11: =IF(ISBLANK($C11),"",$D11) | DJ11: =$CX11 | DK11: =$CW11 | DL11: =IF(ISBLANK($C11),"",$CZ11) | DM11: =IF($DD11>$DC$8,"",VLOOKUP($DD11,$DF$9:$DL$508,7,FALSE())) | DN11: =IF($DD11>$DC$8,"",VLOOKUP($DD11,$DF$9:$DL$508,2,FALSE())) | DO11: =IF($DD11>$DC$8,"",VLOOKUP($DD11,$DF$9:$DL$508,3,FALSE())) | DP11: =IF($DD11>$DC$8,"",VLOOKUP($DD11,$DF$9:$DL$508,4,FALSE())) | DQ11: =IF($DD11>$DC$8,"",VLOOKUP($DD11,$DF$9:$DL$508,5,FALSE())) | DR11: =IF($DD11>$DC$8,"",VLOOKUP($DD11,$DF$9:$DL$508,6,FALSE()))
AF12: =IF(ISBLANK($C12),"",IF(E12=Constants!$B$2,TRUE(),IF(E12=Constants!$B$3,FALSE(),TRUE()))) | AG12: =IF(ISBLANK($C12),"",IF(F12=Constants!$B$2,TRUE(),IF(F12=Constants!$B$3,FALSE(),TRUE()))) | AH12: =IF(ISBLANK($C12),"",IF(G12=Constants!$B$2,TRUE(),IF(G12=Constants!$B$3,FALSE(),TRUE()))) | AI12: =IF(ISBLANK($C12),"",IF(AND(ISNUMBER(H12),H12>=0),H12,Constants!$B$24)) | AJ12: =IF(ISBLANK($C12),"",IF(I12=Constants!$B$2,TRUE(),IF(I12=Constants!$B$3,FALSE(),TRUE()))) | AK12: =IF(ISBLANK($C12),"",IF(J12=Constants!$B$2,TRUE(),IF(J12=Constants!$B$3,FALSE(),TRUE()))) | AL12: =IF(ISBLANK($C12),"",IF(K12=Constants!$B$4,TRUE(),IF(K12=Constants!$B$5,FALSE(),COUNTA(L12:P12)>0))) | AM12: =IF(ISBLANK($C12),"",IF(ISNUMBER(L12),IF(L12>=0,L12,""),"")) | AN12: =IF(ISBLANK($C12),"",IF(ISNUMBER(M12),IF(M12>=0,M12,""),"")) | AO12: =IF(ISBLANK($C12),"",IF(N12=Constants!$B$2,TRUE(),IF(N12=Constants!$B$3,FALSE(),TRUE()))) | AP12: =IF(ISBLANK($C12),"",IF(ISNUMBER(O12),IF(O12>=0,O12,""),"")) | AQ12: =IF(ISBLANK($C12),"",IF(P12=Constants!$B$2,TRUE(),IF(P12=Constants!$B$3,FALSE(),FALSE()))) | AR12: =IF(ISBLANK($C12),"",IF(Q12=Constants!$B$2,TRUE(),IF(Q12=Constants!$B$3,FALSE(),TRUE()))) | AS12: =IF(ISBLANK($C12),"",IF(R12=Constants!$B$2,TRUE(),IF(R12=Constants!$B$3,FALSE(),TRUE()))) | AT12: =IF(ISBLANK($C12),"",IF(S12=Constants!$B$4,TRUE(),IF(S12=Constants!$B$5,FALSE(),COUNTA(T12:X12)>0))) | AU12: =IF(ISBLANK($C12),"",IF(ISNUMBER(T12),IF(T12>=0,T12,""),"")) | AV12: =IF(ISBLANK($C12),"",IF(ISNUMBER(U12),IF(U12>=0,U12,""),"")) | AW12: =IF(ISBLANK($C12),"",IF(V12=Constants!$B$2,TRUE(),IF(V12=Constants!$B$3,FALSE(),TRUE()))) | AX12: =IF(ISBLANK($C12),"",IF(ISNUMBER(W12),IF(W12>=0,W12,""),"")) | AY12: =IF(ISBLANK($C12),"",IF(X12=Constants!$B$2,TRUE(),IF(X12=Constants!$B$3,FALSE(),FALSE()))) | AZ12: =IF(ISBLANK($C12),"",MIN(Constants!$B$25,MAX(0,IF(ISNUMBER(Y12),Y12*60,0)+IF(ISNUMBER(Z12),Z12,0)))) | BA12: =IF(ISBLANK($C12),"",IF(AA12=Constants!$B$2,TRUE(),IF(AA12=Constants!$B$3,FALSE(),FALSE()))) | BB12: =IF(ISBLANK($C12),"",AND($AL12,OR($AM12="",$AN12="",AND($AO12,$AP12="")))) | BC12: =IF($BX12<>Constants!$B$6,"",IF($AL12,Constants!$B$17*$AN12+Constants!$B$18*IF($AO12,$AP12,Constants!$B$19),Constants!$B$20)) | BD12: =IF($BX12<>Constants!$B$6,"",Constants!$B$21*ABS($AD$9-IF($AL12,$AM12,0))) | BE12: =IF($BX12<>Constants!$B$6,"",IF(AND($AL12,$AQ12,$AO12),Constants!$B$22,0)) | BF12: =IF($BX12<>Constants!$B$6,"",IF($AL12,($AI12-Constants!$B$24)*Constants!$B$23,0)) | BG12: =IF($BX12<>Constants!$B$6,"",IF($AK12,0,Constants!$B$12)+IF($AJ12,0,Constants!$B$13)+IF($AH12,0,Constants!$B$14)) | BH12: =IF($BX12<>Constants!$B$6,"",Constants!$B$16+SUM($BC12:$BG12)) | BI12: =IF($BX12<>Constants!$B$6,"",$BC12) | BJ12: =IF($BX12<>Constants!$B$6,"",$BD12) | BK12: =IF($BX12<>Constants!$B$6,"",IF($AL12,$AN12,"")) | BL12: =IF($BX12<>Constants!$B$6,"",IF(OR($BS12<$BH12,AND($BS12=$BH12,OR($BT12<$BI12,AND($BT12=$BI12,OR($BU12<$BJ12,AND($BU12=$BJ12,AND(ISNUMBER($BV12),OR(NOT(ISNUMBER($BK12)),$BV12<$BK12)))))))),"->","<-")) | BM12: =IF(ISBLANK($C12),"",AND($AT12,OR($AU12="",$AV12="",AND($AW12,$AX12="")))) | BN12: =IF($BX12<>Constants!$B$6,"",IF($AT12,Constants!$B$17*$AV12+Constants!$B$18*IF($AW12,$AX12,Constants!$B$19),Constants!$B$20)) | BO12: =IF($BX12<>Constants!$B$6,"",Constants!$B$21*ABS($AD$9-IF($AT12,$AU12,0))) | BP12: =IF($BX12<>Constants!$B$6,"",IF(AND($AT12,$AY12,$AW12),Constants!$B$22,0)) | BQ12: =IF($BX12<>Constants!$B$6,"",IF($AT12,($AI12-Constants!$B$24)*Constants!$B$23,0)) | BR12: =IF($BX12<>Constants!$B$6,"",IF($AS12,0,Constants!$B$12)+IF($AR12,0,Constants!$B$13)+IF($AH12,0,Constants!$B$14)) | BS12: =IF($BX12<>Constants!$B$6,"",Constants!$B$16+SUM($BN12:$BR12)) | BT12: =IF($BX12<>Constants!$B$6,"",$BN12) | BU12: =IF($BX12<>Constants!$B$6,"",$BO12) | BV12: =IF($BX12<>Constants!$B$6,"",IF($AT12,$AV12,"")) | BW12: =IF(ISBLANK($C12),"",IF(ISBLANK($D$7),$BW$5,IF(NOT(ISNUMBER($D$7)),$BW$6,""))) | BX12: =IF(ISBLANK($C12),"",IF($BA12,Constants!$B$9,IF(COUNTA($E12:$AA12)=0,Constants!$B$8,IF(NOT($AG12),Constants!$B$7,IF(OR($BW12<>"",$BB12,$BM12),Constants!$B$10,Constants!$B$6))))) | BY12: =IF(ISBLANK($C12),"",IF($BX12<>Constants!$B$6,$BX12,Constants!$B$11)) | BZ12: =IF($BX12<>Constants!$B$6,"",IF($BL12="->",$BS12,$BH12)) | CA12: =IF($BX12<>Constants!$B$6,"",IF($AF12,0,Constants!$B$15)) | CB12: =IF($BX12<>Constants!$B$6,"",((Constants!$B$25-$AZ12)-Constants!$B$25)/Constants!$B$26) | CC12: =IF(ISBLANK($C12),"",IF($BX12<>Constants!$B$6,$BX12,SUM($BZ12:$CB12))) | CD12: =IF(ISBLANK($C12),"",IF($BX12<>Constants!$B$6,$BX12,RANK($CC12,$CC$9:$CC$508,1))) | CE12: =IF($BX12<>Constants!$B$6,"",IF($BL12="->",$BT12,$BI12)) | CF12: =IF(ISBLANK($C12),"",IF($BX12<>Constants!$B$6,$BX12,IF(ISNUMBER($CE12),RANK($CE12,$CE$9:$CE$508,1),COUNT($CE$9:$CE$508)+1))) | CG12: =IF($BX12<>Constants!$B$6,"",IF($BL12="->",$BU12,$BJ12)) | CH12: =IF(ISBLANK($C12),"",IF($BX12<>Constants!$B$6,$BX12,IF(ISNUMBER($CG12),RANK($CG12,$CG$9:$CG$508,1),COUNT($CG$9:$CG$508)+1))) | CI12: =IF($BX12<>Constants!$B$6,"",IF($BL12="->",$BV12,$BK12)) | CJ12: =IF(ISBLANK($C12),"",IF($BX12<>Constants!$B$6,$BX12,IF(ISNUMBER($CI12),RANK($CI12,$CI$9:$CI$508,1),COUNT($CI$9:$CI$508)+1))) | CK12: =IF($BX12<>Constants!$B$6,"",$AI12) | CL12: =IF(ISBLANK($C12),"",IF($BX12<>Constants!$B$6,$BX12,IF(ISNUMBER($CK12),RANK($CK12,$CK$9:$CK$508,1),COUNT($CK$9:$CK$508)+1))) | CM12: =IF(ISBLANK($C12),"",IF($BX12<>Constants!$B$6,$BX12,COUNTIFS($CD$9:$CD$508,"<"&$CD12)+COUNTIFS($CD$9:$CD$508,$CD12,$CF$9:$CF$508,"<"&$CF12)+COUNTIFS($CD$9:$CD$508,$CD12,$CF$9:$CF$508,$CF12,$CH$9:$CH$508,"<"&$CH12)+COUNTIFS($CD$9:$CD$508,$CD12,$CF$9:$CF$508,$CF12,$CH$9:$CH$508,$CH12,$CJ$9:$CJ$508,"<"&$CJ12)+COUNTIFS($CD$9:$CD$508,$CD12,$CF$9:$CF$508,$CF12,$CH$9:$CH$508,$CH12,$CJ$9:$CJ$508,$CJ12,$CL$9:$CL$508,"<"&$CL12)+1)) | CN12: =IF(ISBLANK($C12),"",IF($BX12<>Constants!$B$6,$BX12,$CD12-$CM12)) | CQ12: =IF(ISBLANK($C12),"",IF($BX12=Constants!$B$10,$BW12,"")) | CR12: =IF(ISBLANK($C12),"",IF($BX12<>Constants!$B$6,"",IF($BL12="->",2,1))) | CS12: =IF(ISBLANK($C12),"",IF($BX12<>Constants!$B$6,"",IF($BL12="->",$BN12,$BC12))) | CT12: =IF(ISBLANK($C12),"",IF($BX12<>Constants!$B$6,"",IF($BL12="->",$BO12,$BD12))) | CU12: =IF(ISBLANK($C12),"",IF($BX12<>Constants!$B$6,"",IF($BL12="->",$BP12+$BQ12,$BE12+$BF12)+$CB12)) | CV12: =IF(ISBLANK($C12),"",IF($BX12<>Constants!$B$6,"",IF($BL12="->",$BR12,$BG12)+$CA12)) | CW12: =IF(ISBLANK($C12),"",IF($BX12<>Constants!$B$6,$BX12,$CC12)) | CX12: =IF(ISBLANK($C12),"",$BY12) | CY12: =IF(ISBLANK($C12),"",$CN12) | CZ12: =IF(ISBLANK($C12),"",$CM12) | DA12: =IF(ISBLANK($C12),"",IFERROR(_xlfn.SWITCH($CZ12,Constants!$B$9,COUNTA($C$9:$C$508)+2,Constants!$B$8,COUNTA($C$9:$C$508)+1,Constants!$B$7,COUNTA($C$9:$C$508)),$CZ12)) | DC12: =IF(OR(ISNUMBER($CZ12),$CZ12=Constants!$B$9,$CZ12=Constants!$B$7,$CZ12=Constants!$B$8),1,0) -> 0 | DD12: 4 | DE12: =IF(ISBLANK($C12),"",IF(ISNUMBER($DA12),$DA12+ROW($B12)/1000,"")) | DF12: =IF(ISNUMBER($DE12),RANK($DE12,$DE$9:$DE$508,1),"") | DG12: =IF(ISBLANK($C12),"",$B12) | DH12: =IF(ISBLANK($C12),"",$C12) | DI12: =IF(ISBLANK($C12),"",$D12) | DJ12: =$CX12 | DK12: =$CW12 | DL12: =IF(ISBLANK($C12),"",$CZ12) | DM12: =IF($DD12>$DC$8,"",VLOOKUP($DD12,$DF$9:$DL$508,7,FALSE())) | DN12: =IF($DD12>$DC$8,"",VLOOKUP($DD12,$DF$9:$DL$508,2,FALSE())) | DO12: =IF($DD12>$DC$8,"",VLOOKUP($DD12,$DF$9:$DL$508,3,FALSE())) | DP12: =IF($DD12>$DC$8,"",VLOOKUP($DD12,$DF$9:$DL$508,4,FALSE())) | DQ12: =IF($DD12>$DC$8,"",VLOOKUP($DD12,$DF$9:$DL$508,5,FALSE())) | DR12: =IF($DD12>$DC$8,"",VLOOKUP($DD12,$DF$9:$DL$508,6,FALSE()))
AF13: =IF(ISBLANK($C13),"",IF(E13=Constants!$B$2,TRUE(),IF(E13=Constants!$B$3,FALSE(),TRUE()))) | AG13: =IF(ISBLANK($C13),"",IF(F13=Constants!$B$2,TRUE(),IF(F13=Constants!$B$3,FALSE(),TRUE()))) | AH13: =IF(ISBLANK($C13),"",IF(G13=Constants!$B$2,TRUE(),IF(G13=Constants!$B$3,FALSE(),TRUE()))) | AI13: =IF(ISBLANK($C13),"",IF(AND(ISNUMBER(H13),H13>=0),H13,Constants!$B$24)) | AJ13: =IF(ISBLANK($C13),"",IF(I13=Constants!$B$2,TRUE(),IF(I13=Constants!$B$3,FALSE(),TRUE()))) | AK13: =IF(ISBLANK($C13),"",IF(J13=Constants!$B$2,TRUE(),IF(J13=Constants!$B$3,FALSE(),TRUE()))) | AL13: =IF(ISBLANK($C13),"",IF(K13=Constants!$B$4,TRUE(),IF(K13=Constants!$B$5,FALSE(),COUNTA(L13:P13)>0))) | AM13: =IF(ISBLANK($C13),"",IF(ISNUMBER(L13),IF(L13>=0,L13,""),"")) | AN13: =IF(ISBLANK($C13),"",IF(ISNUMBER(M13),IF(M13>=0,M13,""),"")) | AO13: =IF(ISBLANK($C13),"",IF(N13=Constants!$B$2,TRUE(),IF(N13=Constants!$B$3,FALSE(),TRUE()))) | AP13: =IF(ISBLANK($C13),"",IF(ISNUMBER(O13),IF(O13>=0,O13,""),"")) | AQ13: =IF(ISBLANK($C13),"",IF(P13=Constants!$B$2,TRUE(),IF(P13=Constants!$B$3,FALSE(),FALSE()))) | AR13: =IF(ISBLANK($C13),"",IF(Q13=Constants!$B$2,TRUE(),IF(Q13=Constants!$B$3,FALSE(),TRUE()))) | AS13: =IF(ISBLANK($C13),"",IF(R13=Constants!$B$2,TRUE(),IF(R13=Constants!$B$3,FALSE(),TRUE()))) | AT13: =IF(ISBLANK($C13),"",IF(S13=Constants!$B$4,TRUE(),IF(S13=Constants!$B$5,FALSE(),COUNTA(T13:X13)>0))) | AU13: =IF(ISBLANK($C13),"",IF(ISNUMBER(T13),IF(T13>=0,T13,""),"")) | AV13: =IF(ISBLANK($C13),"",IF(ISNUMBER(U13),IF(U13>=0,U13,""),"")) | AW13: =IF(ISBLANK($C13),"",IF(V13=Constants!$B$2,TRUE(),IF(V13=Constants!$B$3,FALSE(),TRUE()))) | AX13: =IF(ISBLANK($C13),"",IF(ISNUMBER(W13),IF(W13>=0,W13,""),"")) | AY13: =IF(ISBLANK($C13),"",IF(X13=Constants!$B$2,TRUE(),IF(X13=Constants!$B$3,FALSE(),FALSE()))) | AZ13: =IF(ISBLANK($C13),"",MIN(Constants!$B$25,MAX(0,IF(ISNUMBER(Y13),Y13*60,0)+IF(ISNUMBER(Z13),Z13,0)))) | BA13: =IF(ISBLANK($C13),"",IF(AA13=Constants!$B$2,TRUE(),IF(AA13=Constants!$B$3,FALSE(),FALSE()))) | BB13: =IF(ISBLANK($C13),"",AND($AL13,OR($AM13="",$AN13="",AND($AO13,$AP13="")))) | BC13: =IF($BX13<>Constants!$B$6,"",IF($AL13,Constants!$B$17*$AN13+Constants!$B$18*IF($AO13,$AP13,Constants!$B$19),Constants!$B$20)) | BD13: =IF($BX13<>Constants!$B$6,"",Constants!$B$21*ABS($AD$9-IF($AL13,$AM13,0))) | BE13: =IF($BX13<>Constants!$B$6,"",IF(AND($AL13,$AQ13,$AO13),Constants!$B$22,0)) | BF13: =IF($BX13<>Constants!$B$6,"",IF($AL13,($AI13-Constants!$B$24)*Constants!$B$23,0)) | BG13: =IF($BX13<>Constants!$B$6,"",IF($AK13,0,Constants!$B$12)+IF($AJ13,0,Constants!$B$13)+IF($AH13,0,Constants!$B$14)) | BH13: =IF($BX13<>Constants!$B$6,"",Constants!$B$16+SUM($BC13:$BG13)) | BI13: =IF($BX13<>Constants!$B$6,"",$BC13) | BJ13: =IF($BX13<>Constants!$B$6,"",$BD13) | BK13: =IF($BX13<>Constants!$B$6,"",IF($AL13,$AN13,"")) | BL13: =IF($BX13<>Constants!$B$6,"",IF(OR($BS13<$BH13,AND($BS13=$BH13,OR($BT13<$BI13,AND($BT13=$BI13,OR($BU13<$BJ13,AND($BU13=$BJ13,AND(ISNUMBER($BV13),OR(NOT(ISNUMBER($BK13)),$BV13<$BK13)))))))),"->","<-")) | BM13: =IF(ISBLANK($C13),"",AND($AT13,OR($AU13="",$AV13="",AND($AW13,$AX13="")))) | BN13: =IF($BX13<>Constants!$B$6,"",IF($AT13,Constants!$B$17*$AV13+Constants!$B$18*IF($AW13,$AX13,Constants!$B$19),Constants!$B$20)) | BO13: =IF($BX13<>Constants!$B$6,"",Constants!$B$21*ABS($AD$9-IF($AT13,$AU13,0))) | BP13: =IF($BX13<>Constants!$B$6,"",IF(AND($AT13,$AY13,$AW13),Constants!$B$22,0)) | BQ13: =IF($BX13<>Constants!$B$6,"",IF($AT13,($AI13-Constants!$B$24)*Constants!$B$23,0)) | BR13: =IF($BX13<>Constants!$B$6,"",IF($AS13,0,Constants!$B$12)+IF($AR13,0,Constants!$B$13)+IF($AH13,0,Constants!$B$14)) | BS13: =IF($BX13<>Constants!$B$6,"",Constants!$B$16+SUM($BN13:$BR13)) | BT13: =IF($BX13<>Constants!$B$6,"",$BN13) | BU13: =IF($BX13<>Constants!$B$6,"",$BO13) | BV13: =IF($BX13<>Constants!$B$6,"",IF($AT13,$AV13,"")) | BW13: =IF(ISBLANK($C13),"",IF(ISBLANK($D$7),$BW$5,IF(NOT(ISNUMBER($D$7)),$BW$6,""))) | BX13: =IF(ISBLANK($C13),"",IF($BA13,Constants!$B$9,IF(COUNTA($E13:$AA13)=0,Constants!$B$8,IF(NOT($AG13),Constants!$B$7,IF(OR($BW13<>"",$BB13,$BM13),Constants!$B$10,Constants!$B$6))))) | BY13: =IF(ISBLANK($C13),"",IF($BX13<>Constants!$B$6,$BX13,Constants!$B$11)) | BZ13: =IF($BX13<>Constants!$B$6,"",IF($BL13="->",$BS13,$BH13)) | CA13: =IF($BX13<>Constants!$B$6,"",IF($AF13,0,Constants!$B$15)) | CB13: =IF($BX13<>Constants!$B$6,"",((Constants!$B$25-$AZ13)-Constants!$B$25)/Constants!$B$26) | CC13: =IF(ISBLANK($C13),"",IF($BX13<>Constants!$B$6,$BX13,SUM($BZ13:$CB13))) | CD13: =IF(ISBLANK($C13),"",IF($BX13<>Constants!$B$6,$BX13,RANK($CC13,$CC$9:$CC$508,1))) | CE13: =IF($BX13<>Constants!$B$6,"",IF($BL13="->",$BT13,$BI13)) | CF13: =IF(ISBLANK($C13),"",IF($BX13<>Constants!$B$6,$BX13,IF(ISNUMBER($CE13),RANK($CE13,$CE$9:$CE$508,1),COUNT($CE$9:$CE$508)+1))) | CG13: =IF($BX13<>Constants!$B$6,"",IF($BL13="->",$BU13,$BJ13)) | CH13: =IF(ISBLANK($C13),"",IF($BX13<>Constants!$B$6,$BX13,IF(ISNUMBER($CG13),RANK($CG13,$CG$9:$CG$508,1),COUNT($CG$9:$CG$508)+1))) | CI13: =IF($BX13<>Constants!$B$6,"",IF($BL13="->",$BV13,$BK13)) | CJ13: =IF(ISBLANK($C13),"",IF($BX13<>Constants!$B$6,$BX13,IF(ISNUMBER($CI13),RANK($CI13,$CI$9:$CI$508,1),COUNT($CI$9:$CI$508)+1))) | CK13: =IF($BX13<>Constants!$B$6,"",$AI13) | CL13: =IF(ISBLANK($C13),"",IF($BX13<>Constants!$B$6,$BX13,IF(ISNUMBER($CK13),RANK($CK13,$CK$9:$CK$508,1),COUNT($CK$9:$CK$508)+1))) | CM13: =IF(ISBLANK($C13),"",IF($BX13<>Constants!$B$6,$BX13,COUNTIFS($CD$9:$CD$508,"<"&$CD13)+COUNTIFS($CD$9:$CD$508,$CD13,$CF$9:$CF$508,"<"&$CF13)+COUNTIFS($CD$9:$CD$508,$CD13,$CF$9:$CF$508,$CF13,$CH$9:$CH$508,"<"&$CH13)+COUNTIFS($CD$9:$CD$508,$CD13,$CF$9:$CF$508,$CF13,$CH$9:$CH$508,$CH13,$CJ$9:$CJ$508,"<"&$CJ13)+COUNTIFS($CD$9:$CD$508,$CD13,$CF$9:$CF$508,$CF13,$CH$9:$CH$508,$CH13,$CJ$9:$CJ$508,$CJ13,$CL$9:$CL$508,"<"&$CL13)+1)) | CN13: =IF(ISBLANK($C13),"",IF($BX13<>Constants!$B$6,$BX13,$CD13-$CM13)) | CQ13: =IF(ISBLANK($C13),"",IF($BX13=Constants!$B$10,$BW13,"")) | CR13: =IF(ISBLANK($C13),"",IF($BX13<>Constants!$B$6,"",IF($BL13="->",2,1))) | CS13: =IF(ISBLANK($C13),"",IF($BX13<>Constants!$B$6,"",IF($BL13="->",$BN13,$BC13))) | CT13: =IF(ISBLANK($C13),"",IF($BX13<>Constants!$B$6,"",IF($BL13="->",$BO13,$BD13))) | CU13: =IF(ISBLANK($C13),"",IF($BX13<>Constants!$B$6,"",IF($BL13="->",$BP13+$BQ13,$BE13+$BF13)+$CB13)) | CV13: =IF(ISBLANK($C13),"",IF($BX13<>Constants!$B$6,"",IF($BL13="->",$BR13,$BG13)+$CA13)) | CW13: =IF(ISBLANK($C13),"",IF($BX13<>Constants!$B$6,$BX13,$CC13)) | CX13: =IF(ISBLANK($C13),"",$BY13) | CY13: =IF(ISBLANK($C13),"",$CN13) | CZ13: =IF(ISBLANK($C13),"",$CM13) | DA13: =IF(ISBLANK($C13),"",IFERROR(_xlfn.SWITCH($CZ13,Constants!$B$9,COUNTA($C$9:$C$508)+2,Constants!$B$8,COUNTA($C$9:$C$508)+1,Constants!$B$7,COUNTA($C$9:$C$508)),$CZ13)) | DC13: =IF(OR(ISNUMBER($CZ13),$CZ13=Constants!$B$9,$CZ13=Constants!$B$7,$CZ13=Constants!$B$8),1,0) -> 0 | DD13: 5 | DE13: =IF(ISBLANK($C13),"",IF(ISNUMBER($DA13),$DA13+ROW($B13)/1000,"")) | DF13: =IF(ISNUMBER($DE13),RANK($DE13,$DE$9:$DE$508,1),"") | DG13: =IF(ISBLANK($C13),"",$B13) | DH13: =IF(ISBLANK($C13),"",$C13) | DI13: =IF(ISBLANK($C13),"",$D13) | DJ13: =$CX13 | DK13: =$CW13 | DL13: =IF(ISBLANK($C13),"",$CZ13) | DM13: =IF($DD13>$DC$8,"",VLOOKUP($DD13,$DF$9:$DL$508,7,FALSE())) | DN13: =IF($DD13>$DC$8,"",VLOOKUP($DD13,$DF$9:$DL$508,2,FALSE())) | DO13: =IF($DD13>$DC$8,"",VLOOKUP($DD13,$DF$9:$DL$508,3,FALSE())) | DP13: =IF($DD13>$DC$8,"",VLOOKUP($DD13,$DF$9:$DL$508,4,FALSE())) | DQ13: =IF($DD13>$DC$8,"",VLOOKUP($DD13,$DF$9:$DL$508,5,FALSE())) | DR13: =IF($DD13>$DC$8,"",VLOOKUP($DD13,$DF$9:$DL$508,6,FALSE()))
AF14: =IF(ISBLANK($C14),"",IF(E14=Constants!$B$2,TRUE(),IF(E14=Constants!$B$3,FALSE(),TRUE()))) | AG14: =IF(ISBLANK($C14),"",IF(F14=Constants!$B$2,TRUE(),IF(F14=Constants!$B$3,FALSE(),TRUE()))) | AH14: =IF(ISBLANK($C14),"",IF(G14=Constants!$B$2,TRUE(),IF(G14=Constants!$B$3,FALSE(),TRUE()))) | AI14: =IF(ISBLANK($C14),"",IF(AND(ISNUMBER(H14),H14>=0),H14,Constants!$B$24)) | AJ14: =IF(ISBLANK($C14),"",IF(I14=Constants!$B$2,TRUE(),IF(I14=Constants!$B$3,FALSE(),TRUE()))) | AK14: =IF(ISBLANK($C14),"",IF(J14=Constants!$B$2,TRUE(),IF(J14=Constants!$B$3,FALSE(),TRUE()))) | AL14: =IF(ISBLANK($C14),"",IF(K14=Constants!$B$4,TRUE(),IF(K14=Constants!$B$5,FALSE(),COUNTA(L14:P14)>0))) | AM14: =IF(ISBLANK($C14),"",IF(ISNUMBER(L14),IF(L14>=0,L14,""),"")) | AN14: =IF(ISBLANK($C14),"",IF(ISNUMBER(M14),IF(M14>=0,M14,""),"")) | AO14: =IF(ISBLANK($C14),"",IF(N14=Constants!$B$2,TRUE(),IF(N14=Constants!$B$3,FALSE(),TRUE()))) | AP14: =IF(ISBLANK($C14),"",IF(ISNUMBER(O14),IF(O14>=0,O14,""),"")) | AQ14: =IF(ISBLANK($C14),"",IF(P14=Constants!$B$2,TRUE(),IF(P14=Constants!$B$3,FALSE(),FALSE()))) | AR14: =IF(ISBLANK($C14),"",IF(Q14=Constants!$B$2,TRUE(),IF(Q14=Constants!$B$3,FALSE(),TRUE()))) | AS14: =IF(ISBLANK($C14),"",IF(R14=Constants!$B$2,TRUE(),IF(R14=Constants!$B$3,FALSE(),TRUE()))) | AT14: =IF(ISBLANK($C14),"",IF(S14=Constants!$B$4,TRUE(),IF(S14=Constants!$B$5,FALSE(),COUNTA(T14:X14)>0))) | AU14: =IF(ISBLANK($C14),"",IF(ISNUMBER(T14),IF(T14>=0,T14,""),"")) | AV14: =IF(ISBLANK($C14),"",IF(ISNUMBER(U14),IF(U14>=0,U14,""),"")) | AW14: =IF(ISBLANK($C14),"",IF(V14=Constants!$B$2,TRUE(),IF(V14=Constants!$B$3,FALSE(),TRUE()))) | AX14: =IF(ISBLANK($C14),"",IF(ISNUMBER(W14),IF(W14>=0,W14,""),"")) | AY14: =IF(ISBLANK($C14),"",IF(X14=Constants!$B$2,TRUE(),IF(X14=Constants!$B$3,FALSE(),FALSE()))) | AZ14: =IF(ISBLANK($C14),"",MIN(Constants!$B$25,MAX(0,IF(ISNUMBER(Y14),Y14*60,0)+IF(ISNUMBER(Z14),Z14,0)))) | BA14: =IF(ISBLANK($C14),"",IF(AA14=Constants!$B$2,TRUE(),IF(AA14=Constants!$B$3,FALSE(),FALSE()))) | BB14: =IF(ISBLANK($C14),"",AND($AL14,OR($AM14="",$AN14="",AND($AO14,$AP14="")))) | BC14: =IF($BX14<>Constants!$B$6,"",IF($AL14,Constants!$B$17*$AN14+Constants!$B$18*IF($AO14,$AP14,Constants!$B$19),Constants!$B$20)) | BD14: =IF($BX14<>Constants!$B$6,"",Constants!$B$21*ABS($AD$9-IF($AL14,$AM14,0))) | BE14: =IF($BX14<>Constants!$B$6,"",IF(AND($AL14,$AQ14,$AO14),Constants!$B$22,0)) | BF14: =IF($BX14<>Constants!$B$6,"",IF($AL14,($AI14-Constants!$B$24)*Constants!$B$23,0)) | BG14: =IF($BX14<>Constants!$B$6,"",IF($AK14,0,Constants!$B$12)+IF($AJ14,0,Constants!$B$13)+IF($AH14,0,Constants!$B$14)) | BH14: =IF($BX14<>Constants!$B$6,"",Constants!$B$16+SUM($BC14:$BG14)) | BI14: =IF($BX14<>Constants!$B$6,"",$BC14) | BJ14: =IF($BX14<>Constants!$B$6,"",$BD14) | BK14: =IF($BX14<>Constants!$B$6,"",IF($AL14,$AN14,"")) | BL14: =IF($BX14<>Constants!$B$6,"",IF(OR($BS14<$BH14,AND($BS14=$BH14,OR($BT14<$BI14,AND($BT14=$BI14,OR($BU14<$BJ14,AND($BU14=$BJ14,AND(ISNUMBER($BV14),OR(NOT(ISNUMBER($BK14)),$BV14<$BK14)))))))),"->","<-")) | BM14: =IF(ISBLANK($C14),"",AND($AT14,OR($AU14="",$AV14="",AND($AW14,$AX14="")))) | BN14: =IF($BX14<>Constants!$B$6,"",IF($AT14,Constants!$B$17*$AV14+Constants!$B$18*IF($AW14,$AX14,Constants!$B$19),Constants!$B$20)) | BO14: =IF($BX14<>Constants!$B$6,"",Constants!$B$21*ABS($AD$9-IF($AT14,$AU14,0))) | BP14: =IF($BX14<>Constants!$B$6,"",IF(AND($AT14,$AY14,$AW14),Constants!$B$22,0)) | BQ14: =IF($BX14<>Constants!$B$6,"",IF($AT14,($AI14-Constants!$B$24)*Constants!$B$23,0)) | BR14: =IF($BX14<>Constants!$B$6,"",IF($AS14,0,Constants!$B$12)+IF($AR14,0,Constants!$B$13)+IF($AH14,0,Constants!$B$14)) | BS14: =IF($BX14<>Constants!$B$6,"",Constants!$B$16+SUM($BN14:$BR14)) | BT14: =IF($BX14<>Constants!$B$6,"",$BN14) | BU14: =IF($BX14<>Constants!$B$6,"",$BO14) | BV14: =IF($BX14<>Constants!$B$6,"",IF($AT14,$AV14,"")) | BW14: =IF(ISBLANK($C14),"",IF(ISBLANK($D$7),$BW$5,IF(NOT(ISNUMBER($D$7)),$BW$6,""))) | BX14: =IF(ISBLANK($C14),"",IF($BA14,Constants!$B$9,IF(COUNTA($E14:$AA14)=0,Constants!$B$8,IF(NOT($AG14),Constants!$B$7,IF(OR($BW14<>"",$BB14,$BM14),Constants!$B$10,Constants!$B$6))))) | BY14: =IF(ISBLANK($C14),"",IF($BX14<>Constants!$B$6,$BX14,Constants!$B$11)) | BZ14: =IF($BX14<>Constants!$B$6,"",IF($BL14="->",$BS14,$BH14)) | CA14: =IF($BX14<>Constants!$B$6,"",IF($AF14,0,Constants!$B$15)) | CB14: =IF($BX14<>Constants!$B$6,"",((Constants!$B$25-$AZ14)-Constants!$B$25)/Constants!$B$26) | CC14: =IF(ISBLANK($C14),"",IF($BX14<>Constants!$B$6,$BX14,SUM($BZ14:$CB14))) | CD14: =IF(ISBLANK($C14),"",IF($BX14<>Constants!$B$6,$BX14,RANK($CC14,$CC$9:$CC$508,1))) | CE14: =IF($BX14<>Constants!$B$6,"",IF($BL14="->",$BT14,$BI14)) | CF14: =IF(ISBLANK($C14),"",IF($BX14<>Constants!$B$6,$BX14,IF(ISNUMBER($CE14),RANK($CE14,$CE$9:$CE$508,1),COUNT($CE$9:$CE$508)+1))) | CG14: =IF($BX14<>Constants!$B$6,"",IF($BL14="->",$BU14,$BJ14)) | CH14: =IF(ISBLANK($C14),"",IF($BX14<>Constants!$B$6,$BX14,IF(ISNUMBER($CG14),RANK($CG14,$CG$9:$CG$508,1),COUNT($CG$9:$CG$508)+1))) | CI14: =IF($BX14<>Constants!$B$6,"",IF($BL14="->",$BV14,$BK14)) | CJ14: =IF(ISBLANK($C14),"",IF($BX14<>Constants!$B$6,$BX14,IF(ISNUMBER($CI14),RANK($CI14,$CI$9:$CI$508,1),COUNT($CI$9:$CI$508)+1))) | CK14: =IF($BX14<>Constants!$B$6,"",$AI14) | CL14: =IF(ISBLANK($C14),"",IF($BX14<>Constants!$B$6,$BX14,IF(ISNUMBER($CK14),RANK($CK14,$CK$9:$CK$508,1),COUNT($CK$9:$CK$508)+1))) | CM14: =IF(ISBLANK($C14),"",IF($BX14<>Constants!$B$6,$BX14,COUNTIFS($CD$9:$CD$508,"<"&$CD14)+COUNTIFS($CD$9:$CD$508,$CD14,$CF$9:$CF$508,"<"&$CF14)+COUNTIFS($CD$9:$CD$508,$CD14,$CF$9:$CF$508,$CF14,$CH$9:$CH$508,"<"&$CH14)+COUNTIFS($CD$9:$CD$508,$CD14,$CF$9:$CF$508,$CF14,$CH$9:$CH$508,$CH14,$CJ$9:$CJ$508,"<"&$CJ14)+COUNTIFS($CD$9:$CD$508,$CD14,$CF$9:$CF$508,$CF14,$CH$9:$CH$508,$CH14,$CJ$9:$CJ$508,$CJ14,$CL$9:$CL$508,"<"&$CL14)+1)) | CN14: =IF(ISBLANK($C14),"",IF($BX14<>Constants!$B$6,$BX14,$CD14-$CM14)) | CQ14: =IF(ISBLANK($C14),"",IF($BX14=Constants!$B$10,$BW14,"")) | CR14: =IF(ISBLANK($C14),"",IF($BX14<>Constants!$B$6,"",IF($BL14="->",2,1))) | CS14: =IF(ISBLANK($C14),"",IF($BX14<>Constants!$B$6,"",IF($BL14="->",$BN14,$BC14))) | CT14: =IF(ISBLANK($C14),"",IF($BX14<>Constants!$B$6,"",IF($BL14="->",$BO14,$BD14))) | CU14: =IF(ISBLANK($C14),"",IF($BX14<>Constants!$B$6,"",IF($BL14="->",$BP14+$BQ14,$BE14+$BF14)+$CB14)) | CV14: =IF(ISBLANK($C14),"",IF($BX14<>Constants!$B$6,"",IF($BL14="->",$BR14,$BG14)+$CA14)) | CW14: =IF(ISBLANK($C14),"",IF($BX14<>Constants!$B$6,$BX14,$CC14)) | CX14: =IF(ISBLANK($C14),"",$BY14) | CY14: =IF(ISBLANK($C14),"",$CN14) | CZ14: =IF(ISBLANK($C14),"",$CM14) | DA14: =IF(ISBLANK($C14),"",IFERROR(_xlfn.SWITCH($CZ14,Constants!$B$9,COUNTA($C$9:$C$508)+2,Constants!$B$8,COUNTA($C$9:$C$508)+1,Constants!$B$7,COUNTA($C$9:$C$508)),$CZ14)) | DC14: =IF(OR(ISNUMBER($CZ14),$CZ14=Constants!$B$9,$CZ14=Constants!$B$7,$CZ14=Constants!$B$8),1,0) -> 0 | DD14: 6 | DE14: =IF(ISBLANK($C14),"",IF(ISNUMBER($DA14),$DA14+ROW($B14)/1000,"")) | DF14: =IF(ISNUMBER($DE14),RANK($DE14,$DE$9:$DE$508,1),"") | DG14: =IF(ISBLANK($C14),"",$B14) | DH14: =IF(ISBLANK($C14),"",$C14) | DI14: =IF(ISBLANK($C14),"",$D14) | DJ14: =$CX14 | DK14: =$CW14 | DL14: =IF(ISBLANK($C14),"",$CZ14) | DM14: =IF($DD14>$DC$8,"",VLOOKUP($DD14,$DF$9:$DL$508,7,FALSE())) | DN14: =IF($DD14>$DC$8,"",VLOOKUP($DD14,$DF$9:$DL$508,2,FALSE())) | DO14: =IF($DD14>$DC$8,"",VLOOKUP($DD14,$DF$9:$DL$508,3,FALSE())) | DP14: =IF($DD14>$DC$8,"",VLOOKUP($DD14,$DF$9:$DL$508,4,FALSE())) | DQ14: =IF($DD14>$DC$8,"",VLOOKUP($DD14,$DF$9:$DL$508,5,FALSE())) | DR14: =IF($DD14>$DC$8,"",VLOOKUP($DD14,$DF$9:$DL$508,6,FALSE()))
AF15: =IF(ISBLANK($C15),"",IF(E15=Constants!$B$2,TRUE(),IF(E15=Constants!$B$3,FALSE(),TRUE()))) | AG15: =IF(ISBLANK($C15),"",IF(F15=Constants!$B$2,TRUE(),IF(F15=Constants!$B$3,FALSE(),TRUE()))) | AH15: =IF(ISBLANK($C15),"",IF(G15=Constants!$B$2,TRUE(),IF(G15=Constants!$B$3,FALSE(),TRUE()))) | AI15: =IF(ISBLANK($C15),"",IF(AND(ISNUMBER(H15),H15>=0),H15,Constants!$B$24)) | AJ15: =IF(ISBLANK($C15),"",IF(I15=Constants!$B$2,TRUE(),IF(I15=Constants!$B$3,FALSE(),TRUE()))) | AK15: =IF(ISBLANK($C15),"",IF(J15=Constants!$B$2,TRUE(),IF(J15=Constants!$B$3,FALSE(),TRUE()))) | AL15: =IF(ISBLANK($C15),"",IF(K15=Constants!$B$4,TRUE(),IF(K15=Constants!$B$5,FALSE(),COUNTA(L15:P15)>0))) | AM15: =IF(ISBLANK($C15),"",IF(ISNUMBER(L15),IF(L15>=0,L15,""),"")) | AN15: =IF(ISBLANK($C15),"",IF(ISNUMBER(M15),IF(M15>=0,M15,""),"")) | AO15: =IF(ISBLANK($C15),"",IF(N15=Constants!$B$2,TRUE(),IF(N15=Constants!$B$3,FALSE(),TRUE()))) | AP15: =IF(ISBLANK($C15),"",IF(ISNUMBER(O15),IF(O15>=0,O15,""),"")) | AQ15: =IF(ISBLANK($C15),"",IF(P15=Constants!$B$2,TRUE(),IF(P15=Constants!$B$3,FALSE(),FALSE()))) | AR15: =IF(ISBLANK($C15),"",IF(Q15=Constants!$B$2,TRUE(),IF(Q15=Constants!$B$3,FALSE(),TRUE()))) | AS15: =IF(ISBLANK($C15),"",IF(R15=Constants!$B$2,TRUE(),IF(R15=Constants!$B$3,FALSE(),TRUE()))) | AT15: =IF(ISBLANK($C15),"",IF(S15=Constants!$B$4,TRUE(),IF(S15=Constants!$B$5,FALSE(),COUNTA(T15:X15)>0))) | AU15: =IF(ISBLANK($C15),"",IF(ISNUMBER(T15),IF(T15>=0,T15,""),"")) | AV15: =IF(ISBLANK($C15),"",IF(ISNUMBER(U15),IF(U15>=0,U15,""),"")) | AW15: =IF(ISBLANK($C15),"",IF(V15=Constants!$B$2,TRUE(),IF(V15=Constants!$B$3,FALSE(),TRUE()))) | AX15: =IF(ISBLANK($C15),"",IF(ISNUMBER(W15),IF(W15>=0,W15,""),"")) | AY15: =IF(ISBLANK($C15),"",IF(X15=Constants!$B$2,TRUE(),IF(X15=Constants!$B$3,FALSE(),FALSE()))) | AZ15: =IF(ISBLANK($C15),"",MIN(Constants!$B$25,MAX(0,IF(ISNUMBER(Y15),Y15*60,0)+IF(ISNUMBER(Z15),Z15,0)))) | BA15: =IF(ISBLANK($C15),"",IF(AA15=Constants!$B$2,TRUE(),IF(AA15=Constants!$B$3,FALSE(),FALSE()))) | BB15: =IF(ISBLANK($C15),"",AND($AL15,OR($AM15="",$AN15="",AND($AO15,$AP15="")))) | BC15: =IF($BX15<>Constants!$B$6,"",IF($AL15,Constants!$B$17*$AN15+Constants!$B$18*IF($AO15,$AP15,Constants!$B$19),Constants!$B$20)) | BD15: =IF($BX15<>Constants!$B$6,"",Constants!$B$21*ABS($AD$9-IF($AL15,$AM15,0))) | BE15: =IF($BX15<>Constants!$B$6,"",IF(AND($AL15,$AQ15,$AO15),Constants!$B$22,0)) | BF15: =IF($BX15<>Constants!$B$6,"",IF($AL15,($AI15-Constants!$B$24)*Constants!$B$23,0)) | BG15: =IF($BX15<>Constants!$B$6,"",IF($AK15,0,Constants!$B$12)+IF($AJ15,0,Constants!$B$13)+IF($AH15,0,Constants!$B$14)) | BH15: =IF($BX15<>Constants!$B$6,"",Constants!$B$16+SUM($BC15:$BG15)) | BI15: =IF($BX15<>Constants!$B$6,"",$BC15) | BJ15: =IF($BX15<>Constants!$B$6,"",$BD15) | BK15: =IF($BX15<>Constants!$B$6,"",IF($AL15,$AN15,"")) | BL15: =IF($BX15<>Constants!$B$6,"",IF(OR($BS15<$BH15,AND($BS15=$BH15,OR($BT15<$BI15,AND($BT15=$BI15,OR($BU15<$BJ15,AND($BU15=$BJ15,AND(ISNUMBER($BV15),OR(NOT(ISNUMBER($BK15)),$BV15<$BK15)))))))),"->","<-")) | BM15: =IF(ISBLANK($C15),"",AND($AT15,OR($AU15="",$AV15="",AND($AW15,$AX15="")))) | BN15: =IF($BX15<>Constants!$B$6,"",IF($AT15,Constants!$B$17*$AV15+Constants!$B$18*IF($AW15,$AX15,Constants!$B$19),Constants!$B$20)) | BO15: =IF($BX15<>Constants!$B$6,"",Constants!$B$21*ABS($AD$9-IF($AT15,$AU15,0))) | BP15: =IF($BX15<>Constants!$B$6,"",IF(AND($AT15,$AY15,$AW15),Constants!$B$22,0)) | BQ15: =IF($BX15<>Constants!$B$6,"",IF($AT15,($AI15-Constants!$B$24)*Constants!$B$23,0)) | BR15: =IF($BX15<>Constants!$B$6,"",IF($AS15,0,Constants!$B$12)+IF($AR15,0,Constants!$B$13)+IF($AH15,0,Constants!$B$14)) | BS15: =IF($BX15<>Constants!$B$6,"",Constants!$B$16+SUM($BN15:$BR15)) | BT15: =IF($BX15<>Constants!$B$6,"",$BN15) | BU15: =IF($BX15<>Constants!$B$6,"",$BO15) | BV15: =IF($BX15<>Constants!$B$6,"",IF($AT15,$AV15,"")) | BW15: =IF(ISBLANK($C15),"",IF(ISBLANK($D$7),$BW$5,IF(NOT(ISNUMBER($D$7)),$BW$6,""))) | BX15: =IF(ISBLANK($C15),"",IF($BA15,Constants!$B$9,IF(COUNTA($E15:$AA15)=0,Constants!$B$8,IF(NOT($AG15),Constants!$B$7,IF(OR($BW15<>"",$BB15,$BM15),Constants!$B$10,Constants!$B$6))))) | BY15: =IF(ISBLANK($C15),"",IF($BX15<>Constants!$B$6,$BX15,Constants!$B$11)) | BZ15: =IF($BX15<>Constants!$B$6,"",IF($BL15="->",$BS15,$BH15)) | CA15: =IF($BX15<>Constants!$B$6,"",IF($AF15,0,Constants!$B$15)) | CB15: =IF($BX15<>Constants!$B$6,"",((Constants!$B$25-$AZ15)-Constants!$B$25)/Constants!$B$26) | CC15: =IF(ISBLANK($C15),"",IF($BX15<>Constants!$B$6,$BX15,SUM($BZ15:$CB15))) | CD15: =IF(ISBLANK($C15),"",IF($BX15<>Constants!$B$6,$BX15,RANK($CC15,$CC$9:$CC$508,1))) | CE15: =IF($BX15<>Constants!$B$6,"",IF($BL15="->",$BT15,$BI15)) | CF15: =IF(ISBLANK($C15),"",IF($BX15<>Constants!$B$6,$BX15,IF(ISNUMBER($CE15),RANK($CE15,$CE$9:$CE$508,1),COUNT($CE$9:$CE$508)+1))) | CG15: =IF($BX15<>Constants!$B$6,"",IF($BL15="->",$BU15,$BJ15)) | CH15: =IF(ISBLANK($C15),"",IF($BX15<>Constants!$B$6,$BX15,IF(ISNUMBER($CG15),RANK($CG15,$CG$9:$CG$508,1),COUNT($CG$9:$CG$508)+1))) | CI15: =IF($BX15<>Constants!$B$6,"",IF($BL15="->",$BV15,$BK15)) | CJ15: =IF(ISBLANK($C15),"",IF($BX15<>Constants!$B$6,$BX15,IF(ISNUMBER($CI15),RANK($CI15,$CI$9:$CI$508,1),COUNT($CI$9:$CI$508)+1))) | CK15: =IF($BX15<>Constants!$B$6,"",$AI15) | CL15: =IF(ISBLANK($C15),"",IF($BX15<>Constants!$B$6,$BX15,IF(ISNUMBER($CK15),RANK($CK15,$CK$9:$CK$508,1),COUNT($CK$9:$CK$508)+1))) | CM15: =IF(ISBLANK($C15),"",IF($BX15<>Constants!$B$6,$BX15,COUNTIFS($CD$9:$CD$508,"<"&$CD15)+COUNTIFS($CD$9:$CD$508,$CD15,$CF$9:$CF$508,"<"&$CF15)+COUNTIFS($CD$9:$CD$508,$CD15,$CF$9:$CF$508,$CF15,$CH$9:$CH$508,"<"&$CH15)+COUNTIFS($CD$9:$CD$508,$CD15,$CF$9:$CF$508,$CF15,$CH$9:$CH$508,$CH15,$CJ$9:$CJ$508,"<"&$CJ15)+COUNTIFS($CD$9:$CD$508,$CD15,$CF$9:$CF$508,$CF15,$CH$9:$CH$508,$CH15,$CJ$9:$CJ$508,$CJ15,$CL$9:$CL$508,"<"&$CL15)+1)) | CN15: =IF(ISBLANK($C15),"",IF($BX15<>Constants!$B$6,$BX15,$CD15-$CM15)) | CQ15: =IF(ISBLANK($C15),"",IF($BX15=Constants!$B$10,$BW15,"")) | CR15: =IF(ISBLANK($C15),"",IF($BX15<>Constants!$B$6,"",IF($BL15="->",2,1))) | CS15: =IF(ISBLANK($C15),"",IF($BX15<>Constants!$B$6,"",IF($BL15="->",$BN15,$BC15))) | CT15: =IF(ISBLANK($C15),"",IF($BX15<>Constants!$B$6,"",IF($BL15="->",$BO15,$BD15))) | CU15: =IF(ISBLANK($C15),"",IF($BX15<>Constants!$B$6,"",IF($BL15="->",$BP15+$BQ15,$BE15+$BF15)+$CB15)) | CV15: =IF(ISBLANK($C15),"",IF($BX15<>Constants!$B$6,"",IF($BL15="->",$BR15,$BG15)+$CA15)) | CW15: =IF(ISBLANK($C15),"",IF($BX15<>Constants!$B$6,$BX15,$CC15)) | CX15: =IF(ISBLANK($C15),"",$BY15) | CY15: =IF(ISBLANK($C15),"",$CN15) | CZ15: =IF(ISBLANK($C15),"",$CM15) | DA15: =IF(ISBLANK($C15),"",IFERROR(_xlfn.SWITCH($CZ15,Constants!$B$9,COUNTA($C$9:$C$508)+2,Constants!$B$8,COUNTA($C$9:$C$508)+1,Constants!$B$7,COUNTA($C$9:$C$508)),$CZ15)) | DC15: =IF(OR(ISNUMBER($CZ15),$CZ15=Constants!$B$9,$CZ15=Constants!$B$7,$CZ15=Constants!$B$8),1,0) -> 0 | DD15: 7 | DE15: =IF(ISBLANK($C15),"",IF(ISNUMBER($DA15),$DA15+ROW($B15)/1000,"")) | DF15: =IF(ISNUMBER($DE15),RANK($DE15,$DE$9:$DE$508,1),"") | DG15: =IF(ISBLANK($C15),"",$B15) | DH15: =IF(ISBLANK($C15),"",$C15) | DI15: =IF(ISBLANK($C15),"",$D15) | DJ15: =$CX15 | DK15: =$CW15 | DL15: =IF(ISBLANK($C15),"",$CZ15) | DM15: =IF($DD15>$DC$8,"",VLOOKUP($DD15,$DF$9:$DL$508,7,FALSE())) | DN15: =IF($DD15>$DC$8,"",VLOOKUP($DD15,$DF$9:$DL$508,2,FALSE())) | DO15: =IF($DD15>$DC$8,"",VLOOKUP($DD15,$DF$9:$DL$508,3,FALSE())) | DP15: =IF($DD15>$DC$8,"",VLOOKUP($DD15,$DF$9:$DL$508,4,FALSE())) | DQ15: =IF($DD15>$DC$8,"",VLOOKUP($DD15,$DF$9:$DL$508,5,FALSE())) | DR15: =IF($DD15>$DC$8,"",VLOOKUP($DD15,$DF$9:$DL$508,6,FALSE()))
